{
  "version": 8,
  "blockIdVersion": 11,
  "anchorX": 0,
  "anchorY": 0,
  "anchorZ": 0,
  "blocks": [
    {
      "x": -12,
      "y": 81,
      "z": -3,
      "name": "Rock_Volcanic_Brick_Stairs",
      "rotation": 9
    },
    {
      "x": -12,
      "y": 82,
      "z": -3,
      "name": "Rock_Volcanic_Brick_Stairs",
      "rotation": 3
    },
    {
      "x": -11,
      "y": 80,
      "z": -3,
      "name": "Rock_Volcanic_Brick",
      "rotation": 3
    },
    {
      "x": -11,
      "y": 81,
      "z": -3,
      "name": "Rock_Volcanic_Brick",
      "rotation": 3
    },
    {
      "x": -11,
      "y": 82,
      "z": -3,
      "name": "Rock_Volcanic_Brick",
      "rotation": 3
    },
    {
      "x": -10,
      "y": 80,
      "z": -6,
      "name": "Rock_Volcanic_Brick_Half",
      "rotation": 8
    },
    {
      "x": -10,
      "y": 81,
      "z": -6,
      "name": "*Rock_Volcanic_Brick_Wall_State_Definitions_Corner",
      "rotation": 1
    },
    {
      "x": -10,
      "y": 80,
      "z": -5,
      "name": "Rock_Volcanic_Brick_Half",
      "rotation": 8
    },
    {
      "x": -10,
      "y": 81,
      "z": -5,
      "name": "Rock_Volcanic_Brick_Wall",
      "rotation": 3
    },
    {
      "x": -10,
      "y": 81,
      "z": -4,
      "name": "Rock_Volcanic_Brick_Half",
      "rotation": 8
    },
    {
      "x": -10,
      "y": 82,
      "z": -4,
      "name": "Rock_Volcanic_Brick_Wall",
      "rotation": 3
    },
    {
      "x": -10,
      "y": 79,
      "z": -3,
      "name": "Rock_Volcanic_Brick",
      "rotation": 3
    },
    {
      "x": -10,
      "y": 80,
      "z": -3,
      "name": "Rock_Volcanic_Brick",
      "rotation": 3
    },
    {
      "x": -10,
      "y": 81,
      "z": -3,
      "name": "Rock_Volcanic_Brick",
      "rotation": 3
    },
    {
      "x": -10,
      "y": 82,
      "z": -3,
      "name": "Rock_Volcanic_Brick",
      "rotation": 3
    },
    {
      "x": -10,
      "y": 83,
      "z": -3,
      "name": "Rock_Volcanic_Brick",
      "rotation": 3
    },
    {
      "x": -10,
      "y": 81,
      "z": -2,
      "name": "Rock_Volcanic_Brick_Half",
      "rotation": 9
    },
    {
      "x": -10,
      "y": 82,
      "z": -2,
      "name": "Rock_Volcanic_Brick_Wall",
      "rotation": 3
    },
    {
      "x": -10,
      "y": 81,
      "z": -1,
      "name": "Rock_Volcanic_Brick_Half",
      "rotation": 9
    },
    {
      "x": -10,
      "y": 82,
      "z": -1,
      "name": "Rock_Volcanic_Brick_Wall",
      "rotation": 3
    },
    {
      "x": -10,
      "y": 81,
      "z": 0,
      "name": "Rock_Volcanic_Brick_Half",
      "rotation": 9
    },
    {
      "x": -10,
      "y": 82,
      "z": 0,
      "name": "*Rock_Volcanic_Brick_Wall_State_Definitions_Corner",
      "rotation": 2
    },
    {
      "x": -9,
      "y": 80,
      "z": -8,
      "name": "Rock_Volcanic_Brick_Half",
      "rotation": 8
    },
    {
      "x": -9,
      "y": 81,
      "z": -8,
      "name": "*Rock_Volcanic_Brick_Wall_State_Definitions_Corner",
      "rotation": 1
    },
    {
      "x": -9,
      "y": 80,
      "z": -7,
      "name": "Rock_Volcanic_Brick_Half",
      "rotation": 8
    },
    {
      "x": -9,
      "y": 81,
      "z": -7,
      "name": "Rock_Volcanic_Brick_Wall",
      "rotation": 3
    },
    {
      "x": -9,
      "y": 80,
      "z": -6,
      "name": "Rock_Volcanic_Brick_Half",
      "rotation": 8
    },
    {
      "x": -9,
      "y": 81,
      "z": -6,
      "name": "*Rock_Volcanic_Brick_Wall_State_Definitions_Corner",
      "rotation": 3
    },
    {
      "x": -9,
      "y": 84,
      "z": -4,
      "name": "Rock_Volcanic_Brick",
      "rotation": 3
    },
    {
      "x": -9,
      "y": 85,
      "z": -4,
      "name": "Rock_Volcanic_Brick_Half",
      "rotation": 7
    },
    {
      "x": -9,
      "y": 86,
      "z": -4,
      "name": "Rock_Volcanic_Brick_Half",
      "rotation": 7
    },
    {
      "x": -9,
      "y": 78,
      "z": -3,
      "name": "Rock_Volcanic_Brick",
      "rotation": 3
    },
    {
      "x": -9,
      "y": 79,
      "z": -3,
      "name": "Rock_Volcanic_Brick",
      "rotation": 3
    },
    {
      "x": -9,
      "y": 80,
      "z": -3,
      "name": "Rock_Volcanic_Brick",
      "rotation": 3
    },
    {
      "x": -9,
      "y": 82,
      "z": -3,
      "name": "Rock_Volcanic_Brick",
      "rotation": 3
    },
    {
      "x": -9,
      "y": 83,
      "z": -3,
      "name": "Rock_Volcanic_Brick",
      "rotation": 3
    },
    {
      "x": -9,
      "y": 76,
      "z": -2,
      "name": "Rock_Volcanic_Brick_Half",
      "rotation": 7
    },
    {
      "x": -9,
      "y": 77,
      "z": -2,
      "name": "Rock_Volcanic_Brick_Half",
      "rotation": 7
    },
    {
      "x": -9,
      "y": 81,
      "z": 0,
      "name": "Rock_Volcanic_Brick_Half",
      "rotation": 9
    },
    {
      "x": -9,
      "y": 82,
      "z": 0,
      "name": "*Rock_Volcanic_Brick_Wall_State_Definitions_Corner"
    },
    {
      "x": -9,
      "y": 81,
      "z": 1,
      "name": "Rock_Volcanic_Brick_Half",
      "rotation": 9
    },
    {
      "x": -9,
      "y": 82,
      "z": 1,
      "name": "Rock_Volcanic_Brick_Wall",
      "rotation": 3
    },
    {
      "x": -9,
      "y": 83,
      "z": 1,
      "name": "Rock_Volcanic_Brick_Wall",
      "rotation": 3
    },
    {
      "x": -9,
      "y": 82,
      "z": 2,
      "name": "Rock_Volcanic_Brick_Half",
      "rotation": 9
    },
    {
      "x": -9,
      "y": 83,
      "z": 2,
      "name": "*Rock_Volcanic_Brick_Wall_State_Definitions_Corner",
      "rotation": 2
    },
    {
      "x": -8,
      "y": 80,
      "z": -10,
      "name": "Rock_Volcanic_Brick_Half",
      "rotation": 8
    },
    {
      "x": -8,
      "y": 81,
      "z": -10,
      "name": "Rock_Volcanic_Brick_Wall",
      "rotation": 3
    },
    {
      "x": -8,
      "y": 80,
      "z": -9,
      "name": "Rock_Volcanic_Brick_Half",
      "rotation": 8
    },
    {
      "x": -8,
      "y": 81,
      "z": -9,
      "name": "Rock_Volcanic_Brick_Wall",
      "rotation": 3
    },
    {
      "x": -8,
      "y": 80,
      "z": -8,
      "name": "Rock_Volcanic_Brick_Half",
      "rotation": 8
    },
    {
      "x": -8,
      "y": 81,
      "z": -8,
      "name": "*Rock_Volcanic_Brick_Wall_State_Definitions_Corner",
      "rotation": 3
    },
    {
      "x": -8,
      "y": 84,
      "z": -4,
      "name": "Rock_Volcanic_Brick",
      "rotation": 3
    },
    {
      "x": -8,
      "y": 85,
      "z": -4,
      "name": "Rock_Volcanic_Brick",
      "rotation": 3
    },
    {
      "x": -8,
      "y": 86,
      "z": -4,
      "name": "Rock_Volcanic_Brick",
      "rotation": 3
    },
    {
      "x": -8,
      "y": 87,
      "z": -4,
      "name": "Rock_Volcanic_Brick",
      "rotation": 3
    },
    {
      "x": -8,
      "y": 88,
      "z": -4,
      "name": "Rock_Volcanic_Brick",
      "rotation": 3
    },
    {
      "x": -8,
      "y": 78,
      "z": -3,
      "name": "Rock_Volcanic_Brick",
      "rotation": 3
    },
    {
      "x": -8,
      "y": 79,
      "z": -3,
      "name": "Rock_Volcanic_Brick_Stairs",
      "rotation": 1
    },
    {
      "x": -8,
      "y": 83,
      "z": -3,
      "name": "Rock_Volcanic_Brick_Stairs",
      "rotation": 11
    },
    {
      "x": -8,
      "y": 73,
      "z": -2,
      "name": "Rock_Volcanic_Brick_Half",
      "rotation": 7
    },
    {
      "x": -8,
      "y": 74,
      "z": -2,
      "name": "Rock_Volcanic_Brick",
      "rotation": 3
    },
    {
      "x": -8,
      "y": 75,
      "z": -2,
      "name": "Rock_Volcanic_Brick",
      "rotation": 3
    },
    {
      "x": -8,
      "y": 76,
      "z": -2,
      "name": "Rock_Volcanic_Brick",
      "rotation": 3
    },
    {
      "x": -8,
      "y": 77,
      "z": -2,
      "name": "Rock_Volcanic_Brick",
      "rotation": 3
    },
    {
      "x": -8,
      "y": 72,
      "z": -1,
      "name": "Rock_Volcanic_Brick_Half",
      "rotation": 7
    },
    {
      "x": -8,
      "y": 82,
      "z": 2,
      "name": "Rock_Volcanic_Brick_Half",
      "rotation": 9
    },
    {
      "x": -8,
      "y": 83,
      "z": 2,
      "name": "*Rock_Volcanic_Brick_Wall_State_Definitions_Corner"
    },
    {
      "x": -8,
      "y": 82,
      "z": 3,
      "name": "Rock_Volcanic_Brick_Half",
      "rotation": 9
    },
    {
      "x": -8,
      "y": 83,
      "z": 3,
      "name": "Rock_Volcanic_Brick_Wall",
      "rotation": 3
    },
    {
      "x": -8,
      "y": 82,
      "z": 4,
      "name": "Rock_Volcanic_Brick_Half",
      "rotation": 9
    },
    {
      "x": -8,
      "y": 83,
      "z": 4,
      "name": "Rock_Volcanic_Brick_Wall",
      "rotation": 3
    },
    {
      "x": -7,
      "y": 79,
      "z": -11,
      "name": "Rock_Volcanic_Brick_Half",
      "rotation": 8
    },
    {
      "x": -7,
      "y": 80,
      "z": -11,
      "name": "Rock_Volcanic_Brick_Wall",
      "rotation": 2
    },
    {
      "x": -7,
      "y": 83,
      "z": -11,
      "name": "Rock_Volcanic_Brick_Beam"
    },
    {
      "x": -7,
      "y": 84,
      "z": -11,
      "name": "Rock_Volcanic_Brick_Beam"
    },
    {
      "x": -7,
      "y": 85,
      "z": -11,
      "name": "Rock_Volcanic_Brick_Beam"
    },
    {
      "x": -7,
      "y": 86,
      "z": -11,
      "name": "Wood_Deadwood_Beam"
    },
    {
      "x": -7,
      "y": 87,
      "z": -11,
      "name": "Wood_Deadwood_Beam"
    },
    {
      "x": -7,
      "y": 88,
      "z": -11,
      "name": "Wood_Deadwood_Beam"
    },
    {
      "x": -7,
      "y": 78,
      "z": -10,
      "name": "Rock_Volcanic_Brick_Pillar_Middle"
    },
    {
      "x": -7,
      "y": 79,
      "z": -10,
      "name": "Rock_Volcanic_Brick"
    },
    {
      "x": -7,
      "y": 80,
      "z": -10,
      "name": "Rock_Volcanic_Brick"
    },
    {
      "x": -7,
      "y": 81,
      "z": -10,
      "name": "Rock_Volcanic_Brick"
    },
    {
      "x": -7,
      "y": 82,
      "z": -10,
      "name": "Rock_Volcanic_Brick_Pillar_Middle"
    },
    {
      "x": -7,
      "y": 72,
      "z": -9,
      "name": "Wood_Deadwood_Beam"
    },
    {
      "x": -7,
      "y": 73,
      "z": -9,
      "name": "Wood_Deadwood_Beam"
    },
    {
      "x": -7,
      "y": 74,
      "z": -9,
      "name": "Rock_Volcanic_Brick_Beam"
    },
    {
      "x": -7,
      "y": 75,
      "z": -9,
      "name": "Rock_Volcanic_Brick_Beam"
    },
    {
      "x": -7,
      "y": 76,
      "z": -9,
      "name": "Rock_Volcanic_Brick_Beam"
    },
    {
      "x": -7,
      "y": 77,
      "z": -9,
      "name": "Rock_Volcanic_Brick_Pillar_Middle"
    },
    {
      "x": -7,
      "y": 71,
      "z": -8,
      "name": "Wood_Deadwood_Beam"
    },
    {
      "x": -7,
      "y": 95,
      "z": -6,
      "name": "Rock_Volcanic_Brick_Half",
      "rotation": 7
    },
    {
      "x": -7,
      "y": 90,
      "z": -5,
      "name": "Rock_Volcanic_Brick",
      "rotation": 3
    },
    {
      "x": -7,
      "y": 91,
      "z": -5,
      "name": "Rock_Volcanic_Brick",
      "rotation": 3
    },
    {
      "x": -7,
      "y": 92,
      "z": -5,
      "name": "Rock_Volcanic_Brick",
      "rotation": 3
    },
    {
      "x": -7,
      "y": 93,
      "z": -5,
      "name": "Rock_Volcanic_Brick_Stairs",
      "rotation": 3
    },
    {
      "x": -7,
      "y": 94,
      "z": -5,
      "name": "Rock_Volcanic_Brick_Half",
      "rotation": 7
    },
    {
      "x": -7,
      "y": 87,
      "z": -4,
      "name": "Rock_Volcanic_Brick_Stairs",
      "rotation": 11
    },
    {
      "x": -7,
      "y": 88,
      "z": -4,
      "name": "Rock_Volcanic_Brick",
      "rotation": 3
    },
    {
      "x": -7,
      "y": 89,
      "z": -4,
      "name": "Rock_Volcanic_Brick",
      "rotation": 3
    },
    {
      "x": -7,
      "y": 73,
      "z": -2,
      "name": "Rock_Volcanic_Brick",
      "rotation": 3
    },
    {
      "x": -7,
      "y": 74,
      "z": -2,
      "name": "Rock_Volcanic_Brick",
      "rotation": 3
    },
    {
      "x": -7,
      "y": 75,
      "z": -2,
      "name": "Rock_Volcanic_Brick_Stairs",
      "rotation": 1
    },
    {
      "x": -7,
      "y": 67,
      "z": -1,
      "name": "Rock_Volcanic_Brick_Half",
      "rotation": 7
    },
    {
      "x": -7,
      "y": 68,
      "z": -1,
      "name": "Rock_Volcanic_Brick_Half",
      "rotation": 7
    },
    {
      "x": -7,
      "y": 69,
      "z": -1,
      "name": "Rock_Volcanic_Brick_Stairs",
      "rotation": 9
    },
    {
      "x": -7,
      "y": 70,
      "z": -1,
      "name": "Rock_Volcanic_Brick",
      "rotation": 3
    },
    {
      "x": -7,
      "y": 71,
      "z": -1,
      "name": "Rock_Volcanic_Brick",
      "rotation": 3
    },
    {
      "x": -7,
      "y": 72,
      "z": -1,
      "name": "Rock_Volcanic_Brick",
      "rotation": 3
    },
    {
      "x": -7,
      "y": 66,
      "z": 0,
      "name": "Rock_Volcanic_Brick_Half",
      "rotation": 7
    },
    {
      "x": -7,
      "y": 90,
      "z": 2,
      "name": "Wood_Deadwood_Beam",
      "rotation": 1
    },
    {
      "x": -7,
      "y": 91,
      "z": 2,
      "name": "Wood_Deadwood_Beam",
      "rotation": 1
    },
    {
      "x": -7,
      "y": 85,
      "z": 3,
      "name": "Rock_Volcanic_Brick_Pillar_Middle",
      "rotation": 1
    },
    {
      "x": -7,
      "y": 86,
      "z": 3,
      "name": "Rock_Volcanic_Brick_Beam",
      "rotation": 1
    },
    {
      "x": -7,
      "y": 87,
      "z": 3,
      "name": "Rock_Volcanic_Brick_Beam",
      "rotation": 1
    },
    {
      "x": -7,
      "y": 88,
      "z": 3,
      "name": "Rock_Volcanic_Brick_Beam",
      "rotation": 1
    },
    {
      "x": -7,
      "y": 89,
      "z": 3,
      "name": "Wood_Deadwood_Beam",
      "rotation": 1
    },
    {
      "x": -7,
      "y": 79,
      "z": 4,
      "name": "Rock_Volcanic_Brick_Pillar_Middle",
      "rotation": 1
    },
    {
      "x": -7,
      "y": 80,
      "z": 4,
      "name": "Rock_Volcanic_Brick_Pillar_Middle",
      "rotation": 1
    },
    {
      "x": -7,
      "y": 81,
      "z": 4,
      "name": "Rock_Volcanic_Brick",
      "rotation": 1
    },
    {
      "x": -7,
      "y": 82,
      "z": 4,
      "name": "Rock_Volcanic_Brick",
      "rotation": 1
    },
    {
      "x": -7,
      "y": 83,
      "z": 4,
      "name": "Rock_Volcanic_Brick",
      "rotation": 1
    },
    {
      "x": -7,
      "y": 84,
      "z": 4,
      "name": "Rock_Volcanic_Brick_Pillar_Middle",
      "rotation": 1
    },
    {
      "x": -7,
      "y": 73,
      "z": 5,
      "name": "Wood_Deadwood_Beam",
      "rotation": 1
    },
    {
      "x": -7,
      "y": 74,
      "z": 5,
      "name": "Wood_Deadwood_Beam",
      "rotation": 1
    },
    {
      "x": -7,
      "y": 75,
      "z": 5,
      "name": "Wood_Deadwood_Beam",
      "rotation": 1
    },
    {
      "x": -7,
      "y": 76,
      "z": 5,
      "name": "Rock_Volcanic_Brick_Beam",
      "rotation": 1
    },
    {
      "x": -7,
      "y": 77,
      "z": 5,
      "name": "Rock_Volcanic_Brick_Beam",
      "rotation": 1
    },
    {
      "x": -7,
      "y": 78,
      "z": 5,
      "name": "Rock_Volcanic_Brick_Beam",
      "rotation": 1
    },
    {
      "x": -7,
      "y": 82,
      "z": 5,
      "name": "Rock_Volcanic_Brick_Half",
      "rotation": 9
    },
    {
      "x": -7,
      "y": 83,
      "z": 5,
      "name": "Rock_Volcanic_Brick_Wall"
    },
    {
      "x": -6,
      "y": 79,
      "z": -11,
      "name": "Rock_Volcanic_Brick_Half",
      "rotation": 8
    },
    {
      "x": -6,
      "y": 80,
      "z": -11,
      "name": "Rock_Volcanic_Brick_Wall",
      "rotation": 2
    },
    {
      "x": -6,
      "y": 101,
      "z": -7,
      "name": "Rock_Volcanic_Brick_Half",
      "rotation": 7
    },
    {
      "x": -6,
      "y": 102,
      "z": -7,
      "name": "Rock_Volcanic_Brick_Half",
      "rotation": 7
    },
    {
      "x": -6,
      "y": 103,
      "z": -7,
      "name": "Rock_Volcanic_Brick_Half",
      "rotation": 7
    },
    {
      "x": -6,
      "y": 95,
      "z": -6,
      "name": "Rock_Volcanic_Brick",
      "rotation": 3
    },
    {
      "x": -6,
      "y": 96,
      "z": -6,
      "name": "Rock_Volcanic_Brick",
      "rotation": 3
    },
    {
      "x": -6,
      "y": 97,
      "z": -6,
      "name": "Rock_Volcanic_Brick",
      "rotation": 3
    },
    {
      "x": -6,
      "y": 98,
      "z": -6,
      "name": "Rock_Volcanic_Brick",
      "rotation": 3
    },
    {
      "x": -6,
      "y": 99,
      "z": -6,
      "name": "Rock_Volcanic_Brick",
      "rotation": 3
    },
    {
      "x": -6,
      "y": 100,
      "z": -6,
      "name": "Rock_Volcanic_Brick",
      "rotation": 3
    },
    {
      "x": -6,
      "y": 90,
      "z": -5,
      "name": "Rock_Volcanic_Brick",
      "rotation": 3
    },
    {
      "x": -6,
      "y": 91,
      "z": -5,
      "name": "Rock_Volcanic_Brick",
      "rotation": 3
    },
    {
      "x": -6,
      "y": 92,
      "z": -5,
      "name": "Rock_Volcanic_Brick",
      "rotation": 3
    },
    {
      "x": -6,
      "y": 93,
      "z": -5,
      "name": "Rock_Volcanic_Brick",
      "rotation": 3
    },
    {
      "x": -6,
      "y": 94,
      "z": -5,
      "name": "Rock_Volcanic_Brick",
      "rotation": 3
    },
    {
      "x": -6,
      "y": 89,
      "z": -4,
      "name": "Rock_Volcanic_Brick_Stairs",
      "rotation": 11
    },
    {
      "x": -6,
      "y": 73,
      "z": -2,
      "name": "Rock_Volcanic_Brick_Stairs",
      "rotation": 1
    },
    {
      "x": -6,
      "y": 60,
      "z": -1,
      "name": "Rock_Aqua_Cobble_Half",
      "rotation": 7
    },
    {
      "x": -6,
      "y": 67,
      "z": -1,
      "name": "Rock_Volcanic_Brick",
      "rotation": 3
    },
    {
      "x": -6,
      "y": 68,
      "z": -1,
      "name": "Rock_Volcanic_Brick",
      "rotation": 3
    },
    {
      "x": -6,
      "y": 69,
      "z": -1,
      "name": "Rock_Volcanic_Brick",
      "rotation": 3
    },
    {
      "x": -6,
      "y": 70,
      "z": -1,
      "name": "Rock_Volcanic_Brick",
      "rotation": 3
    },
    {
      "x": -6,
      "y": 71,
      "z": -1,
      "name": "Rock_Volcanic_Brick",
      "rotation": 3
    },
    {
      "x": -6,
      "y": 72,
      "z": -1,
      "name": "Rock_Volcanic_Brick",
      "rotation": 3
    },
    {
      "x": -6,
      "y": 60,
      "z": 0,
      "name": "Rock_Aqua_Cobble_Half",
      "rotation": 7
    },
    {
      "x": -6,
      "y": 61,
      "z": 0,
      "name": "Rock_Volcanic_Brick",
      "rotation": 3
    },
    {
      "x": -6,
      "y": 62,
      "z": 0,
      "name": "Rock_Volcanic_Brick",
      "rotation": 3
    },
    {
      "x": -6,
      "y": 63,
      "z": 0,
      "name": "Rock_Volcanic_Brick",
      "rotation": 3
    },
    {
      "x": -6,
      "y": 64,
      "z": 0,
      "name": "Rock_Volcanic_Brick",
      "rotation": 3
    },
    {
      "x": -6,
      "y": 65,
      "z": 0,
      "name": "Rock_Volcanic_Brick",
      "rotation": 3
    },
    {
      "x": -6,
      "y": 66,
      "z": 0,
      "name": "Rock_Volcanic_Brick",
      "rotation": 3
    },
    {
      "x": -6,
      "y": 58,
      "z": 1,
      "name": "Rock_Volcanic_Brick_Half",
      "rotation": 7
    },
    {
      "x": -6,
      "y": 59,
      "z": 1,
      "name": "Rock_Volcanic_Brick_Half",
      "rotation": 7
    },
    {
      "x": -6,
      "y": 60,
      "z": 1,
      "name": "Rock_Volcanic_Brick_Half",
      "rotation": 7
    },
    {
      "x": -6,
      "y": 60,
      "z": 2,
      "name": "Rock_Aqua_Cobble_Half",
      "rotation": 7
    },
    {
      "x": -6,
      "y": 82,
      "z": 5,
      "name": "Rock_Volcanic_Brick_Half",
      "rotation": 9
    },
    {
      "x": -6,
      "y": 83,
      "z": 5,
      "name": "Rock_Volcanic_Brick_Wall"
    },
    {
      "x": -5,
      "y": 79,
      "z": -12,
      "name": "Rock_Volcanic_Brick_Half",
      "rotation": 8
    },
    {
      "x": -5,
      "y": 80,
      "z": -12,
      "name": "*Rock_Volcanic_Brick_Wall_State_Definitions_Corner",
      "rotation": 1
    },
    {
      "x": -5,
      "y": 79,
      "z": -11,
      "name": "Rock_Volcanic_Brick_Half",
      "rotation": 8
    },
    {
      "x": -5,
      "y": 80,
      "z": -11,
      "name": "*Rock_Volcanic_Brick_Wall_State_Definitions_Corner",
      "rotation": 3
    },
    {
      "x": -5,
      "y": 89,
      "z": -7,
      "name": "Rock_Volcanic_Brick",
      "rotation": 1
    },
    {
      "x": -5,
      "y": 90,
      "z": -7,
      "name": "Rock_Volcanic_Cobble",
      "rotation": 1
    },
    {
      "x": -5,
      "y": 91,
      "z": -7,
      "name": "*Rock_Volcanic_Brick_Wall_State_Definitions_Corner",
      "rotation": 1
    },
    {
      "x": -5,
      "y": 85,
      "z": -6,
      "name": "*Rock_Volcanic_Brick_Wall_State_Definitions_Corner",
      "rotation": 1
    },
    {
      "x": -5,
      "y": 86,
      "z": -6,
      "name": "Rock_Volcanic_Brick",
      "rotation": 1
    },
    {
      "x": -5,
      "y": 87,
      "z": -6,
      "name": "Rock_Volcanic_Brick",
      "rotation": 1
    },
    {
      "x": -5,
      "y": 88,
      "z": -6,
      "name": "Rock_Volcanic_Brick",
      "rotation": 1
    },
    {
      "x": -5,
      "y": 89,
      "z": -6,
      "name": "Rock_Volcanic_Cobble",
      "rotation": 1
    },
    {
      "x": -5,
      "y": 90,
      "z": -6,
      "name": "Rock_Volcanic_Brick",
      "rotation": 1
    },
    {
      "x": -5,
      "y": 91,
      "z": -6,
      "name": "Rock_Volcanic_Brick_Wall",
      "rotation": 1
    },
    {
      "x": -5,
      "y": 80,
      "z": -5,
      "name": "Rock_Crystal_Green_Block"
    },
    {
      "x": -5,
      "y": 85,
      "z": -5,
      "name": "Rock_Volcanic_Brick_Wall",
      "rotation": 3
    },
    {
      "x": -5,
      "y": 86,
      "z": -5,
      "name": "Rock_Volcanic_Brick_Wall",
      "rotation": 3
    },
    {
      "x": -5,
      "y": 87,
      "z": -5,
      "name": "Rock_Volcanic_Brick",
      "rotation": 1
    },
    {
      "x": -5,
      "y": 88,
      "z": -5,
      "name": "Rock_Volcanic_Brick",
      "rotation": 1
    },
    {
      "x": -5,
      "y": 89,
      "z": -5,
      "name": "Rock_Volcanic_Cobble",
      "rotation": 1
    },
    {
      "x": -5,
      "y": 90,
      "z": -5,
      "name": "Rock_Volcanic_Cobble",
      "rotation": 2
    },
    {
      "x": -5,
      "y": 91,
      "z": -5,
      "name": "Rock_Volcanic_Brick",
      "rotation": 2
    },
    {
      "x": -5,
      "y": 92,
      "z": -5,
      "name": "Rock_Volcanic_Brick_Wall",
      "rotation": 1
    },
    {
      "x": -5,
      "y": 72,
      "z": -4,
      "name": "Rock_Volcanic_Brick"
    },
    {
      "x": -5,
      "y": 73,
      "z": -4,
      "name": "Rock_Volcanic_Cobble"
    },
    {
      "x": -5,
      "y": 74,
      "z": -4,
      "name": "Rock_Volcanic_Cobble"
    },
    {
      "x": -5,
      "y": 75,
      "z": -4,
      "name": "Rock_Volcanic_Brick"
    },
    {
      "x": -5,
      "y": 76,
      "z": -4,
      "name": "*Rock_Volcanic_Brick_Wall_State_Definitions_Corner",
      "rotation": 1
    },
    {
      "x": -5,
      "y": 80,
      "z": -4,
      "name": "Rock_Crystal_Green_Block"
    },
    {
      "x": -5,
      "y": 81,
      "z": -4,
      "name": "Rock_Crystal_Green_Block"
    },
    {
      "x": -5,
      "y": 82,
      "z": -4,
      "name": "Rock_Crystal_Green_Block"
    },
    {
      "x": -5,
      "y": 86,
      "z": -4,
      "name": "Rock_Volcanic_Brick_Wall",
      "rotation": 3
    },
    {
      "x": -5,
      "y": 87,
      "z": -4,
      "name": "Rock_Volcanic_Brick",
      "rotation": 2
    },
    {
      "x": -5,
      "y": 88,
      "z": -4,
      "name": "Rock_Volcanic_Brick",
      "rotation": 2
    },
    {
      "x": -5,
      "y": 89,
      "z": -4,
      "name": "Rock_Volcanic_Brick",
      "rotation": 2
    },
    {
      "x": -5,
      "y": 90,
      "z": -4,
      "name": "Rock_Volcanic_Brick",
      "rotation": 2
    },
    {
      "x": -5,
      "y": 91,
      "z": -4,
      "name": "Rock_Volcanic_Cobble",
      "rotation": 2
    },
    {
      "x": -5,
      "y": 92,
      "z": -4,
      "name": "Rock_Volcanic_Brick_Wall",
      "rotation": 1
    },
    {
      "x": -5,
      "y": 59,
      "z": -3,
      "name": "Rock_Aqua_Cobble_Half",
      "rotation": 7
    },
    {
      "x": -5,
      "y": 67,
      "z": -3,
      "name": "Rock_Volcanic_Brick"
    },
    {
      "x": -5,
      "y": 68,
      "z": -3,
      "name": "Rock_Volcanic_Cobble"
    },
    {
      "x": -5,
      "y": 69,
      "z": -3,
      "name": "Rock_Volcanic_Brick"
    },
    {
      "x": -5,
      "y": 70,
      "z": -3,
      "name": "Rock_Volcanic_Brick"
    },
    {
      "x": -5,
      "y": 71,
      "z": -3,
      "name": "Rock_Volcanic_Brick"
    },
    {
      "x": -5,
      "y": 72,
      "z": -3,
      "name": "Rock_Volcanic_Brick"
    },
    {
      "x": -5,
      "y": 73,
      "z": -3,
      "name": "Rock_Volcanic_Cobble"
    },
    {
      "x": -5,
      "y": 74,
      "z": -3,
      "name": "Rock_Volcanic_Cobble"
    },
    {
      "x": -5,
      "y": 75,
      "z": -3,
      "name": "Rock_Volcanic_Brick"
    },
    {
      "x": -5,
      "y": 76,
      "z": -3,
      "name": "Rock_Volcanic_Brick_Wall",
      "rotation": 3
    },
    {
      "x": -5,
      "y": 79,
      "z": -3,
      "name": "Rock_Crystal_Green_Block",
      "rotation": 1
    },
    {
      "x": -5,
      "y": 80,
      "z": -3,
      "name": "Rock_Crystal_Green_Block",
      "rotation": 1
    },
    {
      "x": -5,
      "y": 81,
      "z": -3,
      "name": "Rock_Crystal_Green_Block",
      "rotation": 1
    },
    {
      "x": -5,
      "y": 82,
      "z": -3,
      "name": "Rock_Crystal_Green_Block",
      "rotation": 1
    },
    {
      "x": -5,
      "y": 83,
      "z": -3,
      "name": "Rock_Crystal_Green_Block",
      "rotation": 1
    },
    {
      "x": -5,
      "y": 86,
      "z": -3,
      "name": "Rock_Volcanic_Brick_Wall",
      "rotation": 3
    },
    {
      "x": -5,
      "y": 87,
      "z": -3,
      "name": "Rock_Volcanic_Brick",
      "rotation": 2
    },
    {
      "x": -5,
      "y": 88,
      "z": -3,
      "name": "Rock_Volcanic_Brick",
      "rotation": 2
    },
    {
      "x": -5,
      "y": 89,
      "z": -3,
      "name": "Rock_Volcanic_Brick",
      "rotation": 2
    },
    {
      "x": -5,
      "y": 90,
      "z": -3,
      "name": "Rock_Volcanic_Cobble",
      "rotation": 2
    },
    {
      "x": -5,
      "y": 91,
      "z": -3,
      "name": "Rock_Volcanic_Brick",
      "rotation": 2
    },
    {
      "x": -5,
      "y": 92,
      "z": -3,
      "name": "*Rock_Volcanic_Brick_Wall_State_Definitions_Corner",
      "rotation": 2
    },
    {
      "x": -5,
      "y": 60,
      "z": -2,
      "name": "Rock_Aqua_Cobble_Half",
      "rotation": 7
    },
    {
      "x": -5,
      "y": 61,
      "z": -2,
      "name": "Rock_Volcanic_Brick"
    },
    {
      "x": -5,
      "y": 62,
      "z": -2,
      "name": "Rock_Volcanic_Cobble"
    },
    {
      "x": -5,
      "y": 63,
      "z": -2,
      "name": "Rock_Volcanic_Cobble"
    },
    {
      "x": -5,
      "y": 64,
      "z": -2,
      "name": "Rock_Volcanic_Brick"
    },
    {
      "x": -5,
      "y": 65,
      "z": -2,
      "name": "Rock_Volcanic_Brick"
    },
    {
      "x": -5,
      "y": 66,
      "z": -2,
      "name": "Rock_Volcanic_Brick"
    },
    {
      "x": -5,
      "y": 67,
      "z": -2,
      "name": "Rock_Volcanic_Cobble"
    },
    {
      "x": -5,
      "y": 68,
      "z": -2,
      "name": "Rock_Volcanic_Cobble"
    },
    {
      "x": -5,
      "y": 69,
      "z": -2,
      "name": "Rock_Volcanic_Cobble"
    },
    {
      "x": -5,
      "y": 70,
      "z": -2,
      "name": "Rock_Volcanic_Brick"
    },
    {
      "x": -5,
      "y": 71,
      "z": -2,
      "name": "Rock_Volcanic_Cobble"
    },
    {
      "x": -5,
      "y": 72,
      "z": -2,
      "name": "Rock_Volcanic_Brick"
    },
    {
      "x": -5,
      "y": 73,
      "z": -2,
      "name": "Rock_Volcanic_Cobble",
      "rotation": 1
    },
    {
      "x": -5,
      "y": 74,
      "z": -2,
      "name": "Rock_Volcanic_Brick",
      "rotation": 1
    },
    {
      "x": -5,
      "y": 75,
      "z": -2,
      "name": "Rock_Volcanic_Brick",
      "rotation": 1
    },
    {
      "x": -5,
      "y": 76,
      "z": -2,
      "name": "Rock_Volcanic_Brick_Wall",
      "rotation": 3
    },
    {
      "x": -5,
      "y": 80,
      "z": -2,
      "name": "Rock_Crystal_Green_Block",
      "rotation": 1
    },
    {
      "x": -5,
      "y": 81,
      "z": -2,
      "name": "Rock_Crystal_Green_Block",
      "rotation": 1
    },
    {
      "x": -5,
      "y": 82,
      "z": -2,
      "name": "Rock_Crystal_Green_Block",
      "rotation": 1
    },
    {
      "x": -5,
      "y": 86,
      "z": -2,
      "name": "*Rock_Volcanic_Brick_Wall_State_Definitions_Corner",
      "rotation": 2
    },
    {
      "x": -5,
      "y": 87,
      "z": -2,
      "name": "Rock_Volcanic_Brick",
      "rotation": 2
    },
    {
      "x": -5,
      "y": 88,
      "z": -2,
      "name": "Rock_Volcanic_Brick",
      "rotation": 2
    },
    {
      "x": -5,
      "y": 89,
      "z": -2,
      "name": "Rock_Volcanic_Brick",
      "rotation": 2
    },
    {
      "x": -5,
      "y": 55,
      "z": -1,
      "name": "Rock_Volcanic_Brick"
    },
    {
      "x": -5,
      "y": 56,
      "z": -1,
      "name": "Rock_Volcanic_Cobble"
    },
    {
      "x": -5,
      "y": 57,
      "z": -1,
      "name": "Rock_Volcanic_Brick"
    },
    {
      "x": -5,
      "y": 58,
      "z": -1,
      "name": "Rock_Volcanic_Cobble"
    },
    {
      "x": -5,
      "y": 59,
      "z": -1,
      "name": "Rock_Volcanic_Brick"
    },
    {
      "x": -5,
      "y": 60,
      "z": -1,
      "name": "Rock_Aqua_Cobble"
    },
    {
      "x": -5,
      "y": 61,
      "z": -1,
      "name": "Rock_Volcanic_Brick"
    },
    {
      "x": -5,
      "y": 62,
      "z": -1,
      "name": "Rock_Volcanic_Brick"
    },
    {
      "x": -5,
      "y": 63,
      "z": -1,
      "name": "Rock_Volcanic_Brick"
    },
    {
      "x": -5,
      "y": 64,
      "z": -1,
      "name": "Rock_Volcanic_Cobble"
    },
    {
      "x": -5,
      "y": 65,
      "z": -1,
      "name": "Rock_Volcanic_Cobble"
    },
    {
      "x": -5,
      "y": 66,
      "z": -1,
      "name": "Rock_Volcanic_Brick"
    },
    {
      "x": -5,
      "y": 67,
      "z": -1,
      "name": "Rock_Volcanic_Brick"
    },
    {
      "x": -5,
      "y": 68,
      "z": -1,
      "name": "Rock_Volcanic_Cobble"
    },
    {
      "x": -5,
      "y": 69,
      "z": -1,
      "name": "Rock_Volcanic_Brick"
    },
    {
      "x": -5,
      "y": 70,
      "z": -1,
      "name": "Rock_Volcanic_Brick"
    },
    {
      "x": -5,
      "y": 71,
      "z": -1,
      "name": "Rock_Volcanic_Cobble"
    },
    {
      "x": -5,
      "y": 72,
      "z": -1,
      "name": "Rock_Volcanic_Brick",
      "rotation": 1
    },
    {
      "x": -5,
      "y": 73,
      "z": -1,
      "name": "Rock_Volcanic_Brick",
      "rotation": 1
    },
    {
      "x": -5,
      "y": 74,
      "z": -1,
      "name": "Rock_Volcanic_Brick",
      "rotation": 1
    },
    {
      "x": -5,
      "y": 75,
      "z": -1,
      "name": "Rock_Volcanic_Cobble",
      "rotation": 1
    },
    {
      "x": -5,
      "y": 76,
      "z": -1,
      "name": "Rock_Volcanic_Brick_Wall",
      "rotation": 3
    },
    {
      "x": -5,
      "y": 81,
      "z": -1,
      "name": "Rock_Crystal_Green_Block",
      "rotation": 1
    },
    {
      "x": -5,
      "y": 50,
      "z": 0,
      "name": "Rock_Volcanic_Cobble"
    },
    {
      "x": -5,
      "y": 51,
      "z": 0,
      "name": "Rock_Volcanic_Cobble"
    },
    {
      "x": -5,
      "y": 52,
      "z": 0,
      "name": "Rock_Volcanic_Cobble"
    },
    {
      "x": -5,
      "y": 53,
      "z": 0,
      "name": "Rock_Volcanic_Cobble"
    },
    {
      "x": -5,
      "y": 54,
      "z": 0,
      "name": "Rock_Volcanic_Brick"
    },
    {
      "x": -5,
      "y": 55,
      "z": 0,
      "name": "Rock_Volcanic_Cobble"
    },
    {
      "x": -5,
      "y": 56,
      "z": 0,
      "name": "Rock_Volcanic_Cobble"
    },
    {
      "x": -5,
      "y": 57,
      "z": 0,
      "name": "Rock_Volcanic_Cobble"
    },
    {
      "x": -5,
      "y": 58,
      "z": 0,
      "name": "Rock_Volcanic_Cobble"
    },
    {
      "x": -5,
      "y": 59,
      "z": 0,
      "name": "Rock_Volcanic_Cobble"
    },
    {
      "x": -5,
      "y": 60,
      "z": 0,
      "name": "Rock_Volcanic_Cobble"
    },
    {
      "x": -5,
      "y": 61,
      "z": 0,
      "name": "Rock_Volcanic_Brick"
    },
    {
      "x": -5,
      "y": 62,
      "z": 0,
      "name": "Rock_Volcanic_Brick"
    },
    {
      "x": -5,
      "y": 63,
      "z": 0,
      "name": "Rock_Volcanic_Brick"
    },
    {
      "x": -5,
      "y": 64,
      "z": 0,
      "name": "Rock_Volcanic_Brick"
    },
    {
      "x": -5,
      "y": 65,
      "z": 0,
      "name": "Rock_Volcanic_Cobble"
    },
    {
      "x": -5,
      "y": 66,
      "z": 0,
      "name": "Rock_Volcanic_Cobble"
    },
    {
      "x": -5,
      "y": 67,
      "z": 0,
      "name": "Rock_Volcanic_Brick"
    },
    {
      "x": -5,
      "y": 68,
      "z": 0,
      "name": "Rock_Volcanic_Cobble"
    },
    {
      "x": -5,
      "y": 69,
      "z": 0,
      "name": "Rock_Volcanic_Brick"
    },
    {
      "x": -5,
      "y": 70,
      "z": 0,
      "name": "Rock_Volcanic_Brick"
    },
    {
      "x": -5,
      "y": 71,
      "z": 0,
      "name": "Rock_Volcanic_Cobble"
    },
    {
      "x": -5,
      "y": 72,
      "z": 0,
      "name": "Rock_Volcanic_Brick",
      "rotation": 1
    },
    {
      "x": -5,
      "y": 73,
      "z": 0,
      "name": "Rock_Volcanic_Cobble",
      "rotation": 1
    },
    {
      "x": -5,
      "y": 74,
      "z": 0,
      "name": "Rock_Volcanic_Cobble",
      "rotation": 1
    },
    {
      "x": -5,
      "y": 75,
      "z": 0,
      "name": "Rock_Volcanic_Cobble",
      "rotation": 1
    },
    {
      "x": -5,
      "y": 76,
      "z": 0,
      "name": "*Rock_Volcanic_Brick_Wall_State_Definitions_Corner",
      "rotation": 2
    },
    {
      "x": -5,
      "y": 44,
      "z": 1,
      "name": "Rock_Volcanic_Brick"
    },
    {
      "x": -5,
      "y": 45,
      "z": 1,
      "name": "Rock_Volcanic_Cobble"
    },
    {
      "x": -5,
      "y": 46,
      "z": 1,
      "name": "Rock_Volcanic_Cobble"
    },
    {
      "x": -5,
      "y": 47,
      "z": 1,
      "name": "Rock_Volcanic_Cobble"
    },
    {
      "x": -5,
      "y": 48,
      "z": 1,
      "name": "Rock_Volcanic_Cobble"
    },
    {
      "x": -5,
      "y": 49,
      "z": 1,
      "name": "Rock_Volcanic_Brick"
    },
    {
      "x": -5,
      "y": 50,
      "z": 1,
      "name": "Rock_Volcanic_Cobble"
    },
    {
      "x": -5,
      "y": 51,
      "z": 1,
      "name": "Rock_Volcanic_Cobble"
    },
    {
      "x": -5,
      "y": 52,
      "z": 1,
      "name": "Rock_Volcanic_Brick"
    },
    {
      "x": -5,
      "y": 53,
      "z": 1,
      "name": "Rock_Volcanic_Cobble"
    },
    {
      "x": -5,
      "y": 54,
      "z": 1,
      "name": "Rock_Volcanic_Cobble"
    },
    {
      "x": -5,
      "y": 55,
      "z": 1,
      "name": "Rock_Volcanic_Cobble"
    },
    {
      "x": -5,
      "y": 56,
      "z": 1,
      "name": "Rock_Volcanic_Brick"
    },
    {
      "x": -5,
      "y": 57,
      "z": 1,
      "name": "Rock_Volcanic_Brick"
    },
    {
      "x": -5,
      "y": 58,
      "z": 1,
      "name": "Rock_Volcanic_Cobble"
    },
    {
      "x": -5,
      "y": 59,
      "z": 1,
      "name": "Rock_Volcanic_Brick"
    },
    {
      "x": -5,
      "y": 60,
      "z": 1,
      "name": "Rock_Volcanic_Brick"
    },
    {
      "x": -5,
      "y": 61,
      "z": 1,
      "name": "Rock_Volcanic_Brick"
    },
    {
      "x": -5,
      "y": 62,
      "z": 1,
      "name": "Rock_Volcanic_Cobble"
    },
    {
      "x": -5,
      "y": 63,
      "z": 1,
      "name": "Rock_Volcanic_Brick"
    },
    {
      "x": -5,
      "y": 64,
      "z": 1,
      "name": "Rock_Volcanic_Brick"
    },
    {
      "x": -5,
      "y": 65,
      "z": 1,
      "name": "Rock_Volcanic_Brick"
    },
    {
      "x": -5,
      "y": 66,
      "z": 1,
      "name": "Rock_Volcanic_Cobble"
    },
    {
      "x": -5,
      "y": 67,
      "z": 1,
      "name": "Rock_Volcanic_Brick"
    },
    {
      "x": -5,
      "y": 68,
      "z": 1,
      "name": "Rock_Volcanic_Cobble"
    },
    {
      "x": -5,
      "y": 69,
      "z": 1,
      "name": "Rock_Volcanic_Brick"
    },
    {
      "x": -5,
      "y": 70,
      "z": 1,
      "name": "Rock_Volcanic_Brick"
    },
    {
      "x": -5,
      "y": 71,
      "z": 1,
      "name": "Rock_Volcanic_Brick"
    },
    {
      "x": -5,
      "y": 72,
      "z": 1,
      "name": "Rock_Volcanic_Brick",
      "rotation": 1
    },
    {
      "x": -5,
      "y": 38,
      "z": 2,
      "name": "Rock_Volcanic_Cobble"
    },
    {
      "x": -5,
      "y": 39,
      "z": 2,
      "name": "Rock_Volcanic_Cobble"
    },
    {
      "x": -5,
      "y": 40,
      "z": 2,
      "name": "Rock_Volcanic_Cobble"
    },
    {
      "x": -5,
      "y": 41,
      "z": 2,
      "name": "Rock_Volcanic_Cobble"
    },
    {
      "x": -5,
      "y": 42,
      "z": 2,
      "name": "Rock_Volcanic_Cobble"
    },
    {
      "x": -5,
      "y": 43,
      "z": 2,
      "name": "Rock_Volcanic_Cobble"
    },
    {
      "x": -5,
      "y": 44,
      "z": 2,
      "name": "Rock_Volcanic_Cobble"
    },
    {
      "x": -5,
      "y": 45,
      "z": 2,
      "name": "Rock_Volcanic_Brick"
    },
    {
      "x": -5,
      "y": 46,
      "z": 2,
      "name": "Rock_Volcanic_Cobble"
    },
    {
      "x": -5,
      "y": 47,
      "z": 2,
      "name": "Rock_Volcanic_Brick"
    },
    {
      "x": -5,
      "y": 48,
      "z": 2,
      "name": "Rock_Volcanic_Cobble"
    },
    {
      "x": -5,
      "y": 49,
      "z": 2,
      "name": "Rock_Volcanic_Cobble"
    },
    {
      "x": -5,
      "y": 50,
      "z": 2,
      "name": "Rock_Volcanic_Cobble"
    },
    {
      "x": -5,
      "y": 51,
      "z": 2,
      "name": "Rock_Volcanic_Brick"
    },
    {
      "x": -5,
      "y": 52,
      "z": 2,
      "name": "Rock_Volcanic_Brick"
    },
    {
      "x": -5,
      "y": 53,
      "z": 2,
      "name": "Rock_Volcanic_Brick"
    },
    {
      "x": -5,
      "y": 54,
      "z": 2,
      "name": "Rock_Volcanic_Brick"
    },
    {
      "x": -5,
      "y": 55,
      "z": 2,
      "name": "Rock_Volcanic_Cobble"
    },
    {
      "x": -5,
      "y": 56,
      "z": 2,
      "name": "Rock_Volcanic_Cobble"
    },
    {
      "x": -5,
      "y": 57,
      "z": 2,
      "name": "Rock_Volcanic_Brick"
    },
    {
      "x": -5,
      "y": 58,
      "z": 2,
      "name": "Rock_Volcanic_Cobble"
    },
    {
      "x": -5,
      "y": 59,
      "z": 2,
      "name": "Rock_Volcanic_Cobble"
    },
    {
      "x": -5,
      "y": 60,
      "z": 2,
      "name": "Rock_Volcanic_Cobble"
    },
    {
      "x": -5,
      "y": 61,
      "z": 2,
      "name": "Rock_Volcanic_Cobble"
    },
    {
      "x": -5,
      "y": 62,
      "z": 2,
      "name": "Rock_Volcanic_Cobble"
    },
    {
      "x": -5,
      "y": 63,
      "z": 2,
      "name": "Rock_Volcanic_Cobble"
    },
    {
      "x": -5,
      "y": 64,
      "z": 2,
      "name": "Rock_Volcanic_Cobble"
    },
    {
      "x": -5,
      "y": 65,
      "z": 2,
      "name": "Rock_Volcanic_Brick"
    },
    {
      "x": -5,
      "y": 66,
      "z": 2,
      "name": "Rock_Volcanic_Cobble"
    },
    {
      "x": -5,
      "y": 33,
      "z": 3,
      "name": "Rock_Volcanic_Brick"
    },
    {
      "x": -5,
      "y": 34,
      "z": 3,
      "name": "Rock_Volcanic_Cobble"
    },
    {
      "x": -5,
      "y": 35,
      "z": 3,
      "name": "Rock_Volcanic_Cobble"
    },
    {
      "x": -5,
      "y": 36,
      "z": 3,
      "name": "Rock_Volcanic_Cobble"
    },
    {
      "x": -5,
      "y": 37,
      "z": 3,
      "name": "Rock_Volcanic_Cobble"
    },
    {
      "x": -5,
      "y": 38,
      "z": 3,
      "name": "Rock_Volcanic_Cobble"
    },
    {
      "x": -5,
      "y": 39,
      "z": 3,
      "name": "Rock_Volcanic_Cobble"
    },
    {
      "x": -5,
      "y": 40,
      "z": 3,
      "name": "Rock_Volcanic_Cobble"
    },
    {
      "x": -5,
      "y": 41,
      "z": 3,
      "name": "Rock_Volcanic_Cobble"
    },
    {
      "x": -5,
      "y": 42,
      "z": 3,
      "name": "Rock_Volcanic_Brick"
    },
    {
      "x": -5,
      "y": 43,
      "z": 3,
      "name": "Rock_Volcanic_Brick"
    },
    {
      "x": -5,
      "y": 44,
      "z": 3,
      "name": "Rock_Volcanic_Brick"
    },
    {
      "x": -5,
      "y": 45,
      "z": 3,
      "name": "Rock_Volcanic_Brick"
    },
    {
      "x": -5,
      "y": 46,
      "z": 3,
      "name": "Rock_Volcanic_Cobble"
    },
    {
      "x": -5,
      "y": 47,
      "z": 3,
      "name": "Rock_Volcanic_Cobble"
    },
    {
      "x": -5,
      "y": 48,
      "z": 3,
      "name": "Rock_Volcanic_Brick"
    },
    {
      "x": -5,
      "y": 49,
      "z": 3,
      "name": "Rock_Volcanic_Brick"
    },
    {
      "x": -5,
      "y": 50,
      "z": 3,
      "name": "Rock_Volcanic_Brick"
    },
    {
      "x": -5,
      "y": 51,
      "z": 3,
      "name": "Rock_Volcanic_Brick"
    },
    {
      "x": -5,
      "y": 52,
      "z": 3,
      "name": "Rock_Volcanic_Brick"
    },
    {
      "x": -5,
      "y": 53,
      "z": 3,
      "name": "Rock_Volcanic_Cobble"
    },
    {
      "x": -5,
      "y": 54,
      "z": 3,
      "name": "Rock_Volcanic_Cobble"
    },
    {
      "x": -5,
      "y": 55,
      "z": 3,
      "name": "Rock_Volcanic_Brick"
    },
    {
      "x": -5,
      "y": 56,
      "z": 3,
      "name": "Rock_Volcanic_Brick"
    },
    {
      "x": -5,
      "y": 57,
      "z": 3,
      "name": "Rock_Volcanic_Brick"
    },
    {
      "x": -5,
      "y": 58,
      "z": 3,
      "name": "Rock_Volcanic_Cobble"
    },
    {
      "x": -5,
      "y": 59,
      "z": 3,
      "name": "Rock_Volcanic_Brick"
    },
    {
      "x": -5,
      "y": 60,
      "z": 3,
      "name": "Rock_Volcanic_Brick"
    },
    {
      "x": -5,
      "y": 61,
      "z": 3,
      "name": "Rock_Aqua_Cobble_Half",
      "rotation": 7
    },
    {
      "x": -5,
      "y": 27,
      "z": 4,
      "name": "Rock_Volcanic_Cobble"
    },
    {
      "x": -5,
      "y": 28,
      "z": 4,
      "name": "Rock_Volcanic_Brick"
    },
    {
      "x": -5,
      "y": 29,
      "z": 4,
      "name": "Rock_Volcanic_Cobble"
    },
    {
      "x": -5,
      "y": 30,
      "z": 4,
      "name": "Rock_Volcanic_Cobble"
    },
    {
      "x": -5,
      "y": 31,
      "z": 4,
      "name": "Rock_Volcanic_Cobble"
    },
    {
      "x": -5,
      "y": 32,
      "z": 4,
      "name": "Rock_Volcanic_Brick"
    },
    {
      "x": -5,
      "y": 33,
      "z": 4,
      "name": "Rock_Volcanic_Cobble"
    },
    {
      "x": -5,
      "y": 34,
      "z": 4,
      "name": "Rock_Volcanic_Cobble"
    },
    {
      "x": -5,
      "y": 35,
      "z": 4,
      "name": "Rock_Volcanic_Cobble"
    },
    {
      "x": -5,
      "y": 36,
      "z": 4,
      "name": "Rock_Volcanic_Brick"
    },
    {
      "x": -5,
      "y": 37,
      "z": 4,
      "name": "Rock_Volcanic_Cobble"
    },
    {
      "x": -5,
      "y": 38,
      "z": 4,
      "name": "Rock_Volcanic_Brick"
    },
    {
      "x": -5,
      "y": 39,
      "z": 4,
      "name": "Rock_Volcanic_Brick"
    },
    {
      "x": -5,
      "y": 40,
      "z": 4,
      "name": "Rock_Volcanic_Cobble"
    },
    {
      "x": -5,
      "y": 41,
      "z": 4,
      "name": "Rock_Volcanic_Cobble"
    },
    {
      "x": -5,
      "y": 42,
      "z": 4,
      "name": "Rock_Volcanic_Brick"
    },
    {
      "x": -5,
      "y": 43,
      "z": 4,
      "name": "Rock_Volcanic_Cobble"
    },
    {
      "x": -5,
      "y": 44,
      "z": 4,
      "name": "Rock_Volcanic_Brick"
    },
    {
      "x": -5,
      "y": 45,
      "z": 4,
      "name": "Rock_Volcanic_Brick"
    },
    {
      "x": -5,
      "y": 46,
      "z": 4,
      "name": "Rock_Volcanic_Cobble"
    },
    {
      "x": -5,
      "y": 47,
      "z": 4,
      "name": "Rock_Volcanic_Brick"
    },
    {
      "x": -5,
      "y": 48,
      "z": 4,
      "name": "Rock_Volcanic_Brick"
    },
    {
      "x": -5,
      "y": 49,
      "z": 4,
      "name": "Rock_Volcanic_Brick"
    },
    {
      "x": -5,
      "y": 50,
      "z": 4,
      "name": "Rock_Volcanic_Cobble"
    },
    {
      "x": -5,
      "y": 51,
      "z": 4,
      "name": "Rock_Volcanic_Cobble"
    },
    {
      "x": -5,
      "y": 52,
      "z": 4,
      "name": "Rock_Volcanic_Cobble"
    },
    {
      "x": -5,
      "y": 53,
      "z": 4,
      "name": "Rock_Volcanic_Brick"
    },
    {
      "x": -5,
      "y": 54,
      "z": 4,
      "name": "Rock_Volcanic_Cobble"
    },
    {
      "x": -5,
      "y": 55,
      "z": 4,
      "name": "Rock_Volcanic_Brick"
    },
    {
      "x": -5,
      "y": 61,
      "z": 4,
      "name": "Rock_Aqua_Cobble_Half",
      "rotation": 7
    },
    {
      "x": -5,
      "y": 21,
      "z": 5,
      "name": "Rock_Volcanic_Brick"
    },
    {
      "x": -5,
      "y": 22,
      "z": 5,
      "name": "Rock_Volcanic_Cobble"
    },
    {
      "x": -5,
      "y": 23,
      "z": 5,
      "name": "Rock_Volcanic_Brick"
    },
    {
      "x": -5,
      "y": 24,
      "z": 5,
      "name": "Rock_Volcanic_Cobble"
    },
    {
      "x": -5,
      "y": 25,
      "z": 5,
      "name": "Rock_Volcanic_Brick"
    },
    {
      "x": -5,
      "y": 26,
      "z": 5,
      "name": "Rock_Volcanic_Cobble"
    },
    {
      "x": -5,
      "y": 27,
      "z": 5,
      "name": "Rock_Volcanic_Cobble"
    },
    {
      "x": -5,
      "y": 28,
      "z": 5,
      "name": "Rock_Volcanic_Brick"
    },
    {
      "x": -5,
      "y": 29,
      "z": 5,
      "name": "Rock_Volcanic_Cobble"
    },
    {
      "x": -5,
      "y": 30,
      "z": 5,
      "name": "Rock_Volcanic_Cobble"
    },
    {
      "x": -5,
      "y": 31,
      "z": 5,
      "name": "Rock_Volcanic_Cobble"
    },
    {
      "x": -5,
      "y": 32,
      "z": 5,
      "name": "Rock_Volcanic_Cobble"
    },
    {
      "x": -5,
      "y": 33,
      "z": 5,
      "name": "Rock_Volcanic_Brick"
    },
    {
      "x": -5,
      "y": 34,
      "z": 5,
      "name": "Rock_Volcanic_Brick"
    },
    {
      "x": -5,
      "y": 35,
      "z": 5,
      "name": "Rock_Volcanic_Brick"
    },
    {
      "x": -5,
      "y": 36,
      "z": 5,
      "name": "Rock_Volcanic_Cobble"
    },
    {
      "x": -5,
      "y": 37,
      "z": 5,
      "name": "Rock_Volcanic_Cobble"
    },
    {
      "x": -5,
      "y": 38,
      "z": 5,
      "name": "Rock_Volcanic_Brick"
    },
    {
      "x": -5,
      "y": 39,
      "z": 5,
      "name": "Rock_Volcanic_Brick"
    },
    {
      "x": -5,
      "y": 40,
      "z": 5,
      "name": "Rock_Volcanic_Cobble"
    },
    {
      "x": -5,
      "y": 41,
      "z": 5,
      "name": "Rock_Volcanic_Cobble"
    },
    {
      "x": -5,
      "y": 42,
      "z": 5,
      "name": "Rock_Volcanic_Brick"
    },
    {
      "x": -5,
      "y": 43,
      "z": 5,
      "name": "Rock_Volcanic_Brick"
    },
    {
      "x": -5,
      "y": 44,
      "z": 5,
      "name": "Rock_Volcanic_Cobble"
    },
    {
      "x": -5,
      "y": 45,
      "z": 5,
      "name": "Rock_Volcanic_Cobble"
    },
    {
      "x": -5,
      "y": 46,
      "z": 5,
      "name": "Rock_Volcanic_Brick"
    },
    {
      "x": -5,
      "y": 47,
      "z": 5,
      "name": "Rock_Volcanic_Brick"
    },
    {
      "x": -5,
      "y": 48,
      "z": 5,
      "name": "Rock_Volcanic_Cobble"
    },
    {
      "x": -5,
      "y": 49,
      "z": 5,
      "name": "Rock_Volcanic_Cobble"
    },
    {
      "x": -5,
      "y": 61,
      "z": 5,
      "name": "Rock_Aqua_Cobble_Half",
      "rotation": 7
    },
    {
      "x": -5,
      "y": 82,
      "z": 5,
      "name": "Rock_Volcanic_Brick_Half",
      "rotation": 9
    },
    {
      "x": -5,
      "y": 83,
      "z": 5,
      "name": "*Rock_Volcanic_Brick_Wall_State_Definitions_Corner"
    },
    {
      "x": -5,
      "y": 15,
      "z": 6,
      "name": "Rock_Volcanic_Cobble"
    },
    {
      "x": -5,
      "y": 16,
      "z": 6,
      "name": "Rock_Volcanic_Brick"
    },
    {
      "x": -5,
      "y": 17,
      "z": 6,
      "name": "Rock_Volcanic_Cobble"
    },
    {
      "x": -5,
      "y": 18,
      "z": 6,
      "name": "Rock_Volcanic_Brick"
    },
    {
      "x": -5,
      "y": 19,
      "z": 6,
      "name": "Rock_Volcanic_Cobble"
    },
    {
      "x": -5,
      "y": 20,
      "z": 6,
      "name": "Rock_Volcanic_Cobble"
    },
    {
      "x": -5,
      "y": 21,
      "z": 6,
      "name": "Rock_Volcanic_Cobble"
    },
    {
      "x": -5,
      "y": 22,
      "z": 6,
      "name": "Rock_Volcanic_Cobble"
    },
    {
      "x": -5,
      "y": 23,
      "z": 6,
      "name": "Rock_Volcanic_Brick"
    },
    {
      "x": -5,
      "y": 24,
      "z": 6,
      "name": "Rock_Volcanic_Brick"
    },
    {
      "x": -5,
      "y": 25,
      "z": 6,
      "name": "Rock_Volcanic_Cobble"
    },
    {
      "x": -5,
      "y": 26,
      "z": 6,
      "name": "Rock_Volcanic_Cobble"
    },
    {
      "x": -5,
      "y": 27,
      "z": 6,
      "name": "Rock_Volcanic_Brick"
    },
    {
      "x": -5,
      "y": 28,
      "z": 6,
      "name": "Rock_Volcanic_Cobble"
    },
    {
      "x": -5,
      "y": 29,
      "z": 6,
      "name": "Rock_Volcanic_Cobble"
    },
    {
      "x": -5,
      "y": 30,
      "z": 6,
      "name": "Rock_Volcanic_Brick"
    },
    {
      "x": -5,
      "y": 31,
      "z": 6,
      "name": "Rock_Volcanic_Cobble"
    },
    {
      "x": -5,
      "y": 32,
      "z": 6,
      "name": "Rock_Volcanic_Cobble"
    },
    {
      "x": -5,
      "y": 33,
      "z": 6,
      "name": "Rock_Volcanic_Brick"
    },
    {
      "x": -5,
      "y": 34,
      "z": 6,
      "name": "Rock_Volcanic_Brick"
    },
    {
      "x": -5,
      "y": 35,
      "z": 6,
      "name": "Rock_Volcanic_Cobble"
    },
    {
      "x": -5,
      "y": 36,
      "z": 6,
      "name": "Rock_Volcanic_Brick"
    },
    {
      "x": -5,
      "y": 37,
      "z": 6,
      "name": "Rock_Volcanic_Brick"
    },
    {
      "x": -5,
      "y": 38,
      "z": 6,
      "name": "Rock_Volcanic_Brick"
    },
    {
      "x": -5,
      "y": 39,
      "z": 6,
      "name": "Rock_Volcanic_Brick"
    },
    {
      "x": -5,
      "y": 40,
      "z": 6,
      "name": "Rock_Volcanic_Brick"
    },
    {
      "x": -5,
      "y": 41,
      "z": 6,
      "name": "Rock_Volcanic_Cobble"
    },
    {
      "x": -5,
      "y": 42,
      "z": 6,
      "name": "Rock_Volcanic_Brick"
    },
    {
      "x": -5,
      "y": 43,
      "z": 6,
      "name": "Rock_Volcanic_Cobble"
    },
    {
      "x": -5,
      "y": 82,
      "z": 6,
      "name": "Rock_Volcanic_Brick_Half",
      "rotation": 9
    },
    {
      "x": -5,
      "y": 83,
      "z": 6,
      "name": "*Rock_Volcanic_Brick_Wall_State_Definitions_Corner",
      "rotation": 2
    },
    {
      "x": -5,
      "y": 10,
      "z": 7,
      "name": "Rock_Volcanic_Cobble"
    },
    {
      "x": -5,
      "y": 11,
      "z": 7,
      "name": "Rock_Volcanic_Brick"
    },
    {
      "x": -5,
      "y": 12,
      "z": 7,
      "name": "Rock_Volcanic_Brick"
    },
    {
      "x": -5,
      "y": 13,
      "z": 7,
      "name": "Rock_Volcanic_Cobble"
    },
    {
      "x": -5,
      "y": 14,
      "z": 7,
      "name": "Rock_Volcanic_Cobble"
    },
    {
      "x": -5,
      "y": 15,
      "z": 7,
      "name": "Rock_Volcanic_Cobble"
    },
    {
      "x": -5,
      "y": 16,
      "z": 7,
      "name": "Rock_Volcanic_Brick"
    },
    {
      "x": -5,
      "y": 17,
      "z": 7,
      "name": "Rock_Volcanic_Brick"
    },
    {
      "x": -5,
      "y": 18,
      "z": 7,
      "name": "Rock_Volcanic_Cobble"
    },
    {
      "x": -5,
      "y": 19,
      "z": 7,
      "name": "Rock_Volcanic_Cobble"
    },
    {
      "x": -5,
      "y": 20,
      "z": 7,
      "name": "Rock_Volcanic_Brick"
    },
    {
      "x": -5,
      "y": 21,
      "z": 7,
      "name": "Rock_Volcanic_Brick"
    },
    {
      "x": -5,
      "y": 22,
      "z": 7,
      "name": "Rock_Volcanic_Cobble"
    },
    {
      "x": -5,
      "y": 23,
      "z": 7,
      "name": "Rock_Volcanic_Brick"
    },
    {
      "x": -5,
      "y": 24,
      "z": 7,
      "name": "Rock_Volcanic_Cobble"
    },
    {
      "x": -5,
      "y": 25,
      "z": 7,
      "name": "Rock_Volcanic_Brick"
    },
    {
      "x": -5,
      "y": 26,
      "z": 7,
      "name": "Rock_Volcanic_Cobble"
    },
    {
      "x": -5,
      "y": 27,
      "z": 7,
      "name": "Rock_Volcanic_Brick"
    },
    {
      "x": -5,
      "y": 28,
      "z": 7,
      "name": "Rock_Volcanic_Brick"
    },
    {
      "x": -5,
      "y": 29,
      "z": 7,
      "name": "Rock_Volcanic_Brick"
    },
    {
      "x": -5,
      "y": 30,
      "z": 7,
      "name": "Rock_Volcanic_Brick"
    },
    {
      "x": -5,
      "y": 31,
      "z": 7,
      "name": "Rock_Volcanic_Cobble"
    },
    {
      "x": -5,
      "y": 32,
      "z": 7,
      "name": "Rock_Volcanic_Brick"
    },
    {
      "x": -5,
      "y": 33,
      "z": 7,
      "name": "Rock_Volcanic_Brick"
    },
    {
      "x": -5,
      "y": 34,
      "z": 7,
      "name": "Rock_Volcanic_Brick"
    },
    {
      "x": -5,
      "y": 35,
      "z": 7,
      "name": "Rock_Volcanic_Brick"
    },
    {
      "x": -5,
      "y": 36,
      "z": 7,
      "name": "Rock_Volcanic_Cobble"
    },
    {
      "x": -5,
      "y": 37,
      "z": 7,
      "name": "Rock_Volcanic_Brick"
    },
    {
      "x": -5,
      "y": 38,
      "z": 7,
      "name": "Rock_Volcanic_Brick"
    },
    {
      "x": -5,
      "y": 4,
      "z": 8,
      "name": "Rock_Volcanic_Brick"
    },
    {
      "x": -5,
      "y": 5,
      "z": 8,
      "name": "Rock_Volcanic_Brick"
    },
    {
      "x": -5,
      "y": 6,
      "z": 8,
      "name": "Rock_Volcanic_Brick"
    },
    {
      "x": -5,
      "y": 7,
      "z": 8,
      "name": "Rock_Volcanic_Brick"
    },
    {
      "x": -5,
      "y": 8,
      "z": 8,
      "name": "Rock_Volcanic_Cobble"
    },
    {
      "x": -5,
      "y": 9,
      "z": 8,
      "name": "Rock_Volcanic_Brick"
    },
    {
      "x": -5,
      "y": 10,
      "z": 8,
      "name": "Rock_Volcanic_Brick"
    },
    {
      "x": -5,
      "y": 11,
      "z": 8,
      "name": "Rock_Volcanic_Brick"
    },
    {
      "x": -5,
      "y": 12,
      "z": 8,
      "name": "Rock_Volcanic_Brick"
    },
    {
      "x": -5,
      "y": 13,
      "z": 8,
      "name": "Rock_Volcanic_Cobble"
    },
    {
      "x": -5,
      "y": 14,
      "z": 8,
      "name": "Rock_Volcanic_Brick"
    },
    {
      "x": -5,
      "y": 15,
      "z": 8,
      "name": "Rock_Volcanic_Brick"
    },
    {
      "x": -5,
      "y": 16,
      "z": 8,
      "name": "Rock_Volcanic_Brick"
    },
    {
      "x": -5,
      "y": 17,
      "z": 8,
      "name": "Rock_Volcanic_Brick"
    },
    {
      "x": -5,
      "y": 18,
      "z": 8,
      "name": "Rock_Volcanic_Cobble"
    },
    {
      "x": -5,
      "y": 19,
      "z": 8,
      "name": "Rock_Volcanic_Cobble"
    },
    {
      "x": -5,
      "y": 20,
      "z": 8,
      "name": "Rock_Volcanic_Brick"
    },
    {
      "x": -5,
      "y": 21,
      "z": 8,
      "name": "Rock_Volcanic_Brick"
    },
    {
      "x": -5,
      "y": 22,
      "z": 8,
      "name": "Rock_Volcanic_Brick"
    },
    {
      "x": -5,
      "y": 23,
      "z": 8,
      "name": "Rock_Volcanic_Brick"
    },
    {
      "x": -5,
      "y": 24,
      "z": 8,
      "name": "Rock_Volcanic_Brick"
    },
    {
      "x": -5,
      "y": 25,
      "z": 8,
      "name": "Rock_Volcanic_Cobble"
    },
    {
      "x": -5,
      "y": 26,
      "z": 8,
      "name": "Rock_Volcanic_Brick"
    },
    {
      "x": -5,
      "y": 27,
      "z": 8,
      "name": "Rock_Volcanic_Cobble"
    },
    {
      "x": -5,
      "y": 28,
      "z": 8,
      "name": "Rock_Volcanic_Cobble"
    },
    {
      "x": -5,
      "y": 29,
      "z": 8,
      "name": "Rock_Volcanic_Brick"
    },
    {
      "x": -5,
      "y": 30,
      "z": 8,
      "name": "Rock_Volcanic_Brick"
    },
    {
      "x": -5,
      "y": 31,
      "z": 8,
      "name": "Rock_Volcanic_Cobble"
    },
    {
      "x": -5,
      "y": 32,
      "z": 8,
      "name": "Rock_Volcanic_Cobble"
    },
    {
      "x": -5,
      "y": 1,
      "z": 9,
      "name": "Rock_Volcanic_Cobble"
    },
    {
      "x": -5,
      "y": 2,
      "z": 9,
      "name": "Rock_Volcanic_Brick"
    },
    {
      "x": -5,
      "y": 3,
      "z": 9,
      "name": "Rock_Volcanic_Cobble"
    },
    {
      "x": -5,
      "y": 4,
      "z": 9,
      "name": "Rock_Volcanic_Brick"
    },
    {
      "x": -5,
      "y": 5,
      "z": 9,
      "name": "Rock_Volcanic_Cobble"
    },
    {
      "x": -5,
      "y": 6,
      "z": 9,
      "name": "Rock_Volcanic_Cobble"
    },
    {
      "x": -5,
      "y": 7,
      "z": 9,
      "name": "Rock_Volcanic_Brick"
    },
    {
      "x": -5,
      "y": 8,
      "z": 9,
      "name": "Rock_Volcanic_Brick"
    },
    {
      "x": -5,
      "y": 9,
      "z": 9,
      "name": "Rock_Volcanic_Cobble"
    },
    {
      "x": -5,
      "y": 10,
      "z": 9,
      "name": "Rock_Volcanic_Cobble"
    },
    {
      "x": -5,
      "y": 11,
      "z": 9,
      "name": "Rock_Volcanic_Cobble"
    },
    {
      "x": -5,
      "y": 12,
      "z": 9,
      "name": "Rock_Volcanic_Cobble"
    },
    {
      "x": -5,
      "y": 13,
      "z": 9,
      "name": "Rock_Volcanic_Cobble"
    },
    {
      "x": -5,
      "y": 14,
      "z": 9,
      "name": "Rock_Volcanic_Brick"
    },
    {
      "x": -5,
      "y": 15,
      "z": 9,
      "name": "Rock_Volcanic_Brick"
    },
    {
      "x": -5,
      "y": 16,
      "z": 9,
      "name": "Rock_Volcanic_Cobble"
    },
    {
      "x": -5,
      "y": 17,
      "z": 9,
      "name": "Rock_Volcanic_Brick"
    },
    {
      "x": -5,
      "y": 18,
      "z": 9,
      "name": "Rock_Volcanic_Cobble"
    },
    {
      "x": -5,
      "y": 19,
      "z": 9,
      "name": "Rock_Volcanic_Brick"
    },
    {
      "x": -5,
      "y": 20,
      "z": 9,
      "name": "Rock_Volcanic_Brick"
    },
    {
      "x": -5,
      "y": 21,
      "z": 9,
      "name": "Rock_Volcanic_Brick"
    },
    {
      "x": -5,
      "y": 22,
      "z": 9,
      "name": "Rock_Volcanic_Cobble"
    },
    {
      "x": -5,
      "y": 23,
      "z": 9,
      "name": "Rock_Volcanic_Cobble"
    },
    {
      "x": -5,
      "y": 24,
      "z": 9,
      "name": "Rock_Volcanic_Brick"
    },
    {
      "x": -5,
      "y": 25,
      "z": 9,
      "name": "Rock_Volcanic_Cobble"
    },
    {
      "x": -5,
      "y": 26,
      "z": 9,
      "name": "Rock_Volcanic_Brick"
    },
    {
      "x": -5,
      "y": 1,
      "z": 10,
      "name": "Rock_Volcanic_Cobble"
    },
    {
      "x": -5,
      "y": 2,
      "z": 10,
      "name": "Rock_Volcanic_Brick"
    },
    {
      "x": -5,
      "y": 3,
      "z": 10,
      "name": "Rock_Volcanic_Cobble"
    },
    {
      "x": -5,
      "y": 4,
      "z": 10,
      "name": "Rock_Volcanic_Brick"
    },
    {
      "x": -5,
      "y": 5,
      "z": 10,
      "name": "Rock_Volcanic_Brick"
    },
    {
      "x": -5,
      "y": 6,
      "z": 10,
      "name": "Rock_Volcanic_Brick"
    },
    {
      "x": -5,
      "y": 7,
      "z": 10,
      "name": "Rock_Volcanic_Brick"
    },
    {
      "x": -5,
      "y": 8,
      "z": 10,
      "name": "Rock_Volcanic_Brick"
    },
    {
      "x": -5,
      "y": 9,
      "z": 10,
      "name": "Rock_Volcanic_Brick"
    },
    {
      "x": -5,
      "y": 10,
      "z": 10,
      "name": "Rock_Volcanic_Brick"
    },
    {
      "x": -5,
      "y": 11,
      "z": 10,
      "name": "Rock_Volcanic_Brick"
    },
    {
      "x": -5,
      "y": 12,
      "z": 10,
      "name": "Rock_Volcanic_Brick"
    },
    {
      "x": -5,
      "y": 13,
      "z": 10,
      "name": "Rock_Volcanic_Brick"
    },
    {
      "x": -5,
      "y": 14,
      "z": 10,
      "name": "Rock_Volcanic_Brick"
    },
    {
      "x": -5,
      "y": 15,
      "z": 10,
      "name": "Rock_Volcanic_Cobble"
    },
    {
      "x": -5,
      "y": 16,
      "z": 10,
      "name": "Rock_Volcanic_Cobble"
    },
    {
      "x": -5,
      "y": 17,
      "z": 10,
      "name": "Rock_Volcanic_Cobble"
    },
    {
      "x": -5,
      "y": 18,
      "z": 10,
      "name": "Rock_Volcanic_Cobble"
    },
    {
      "x": -5,
      "y": 19,
      "z": 10,
      "name": "Rock_Volcanic_Brick"
    },
    {
      "x": -5,
      "y": 20,
      "z": 10,
      "name": "Rock_Volcanic_Brick"
    },
    {
      "x": -5,
      "y": 21,
      "z": 10,
      "name": "Rock_Volcanic_Brick"
    },
    {
      "x": -5,
      "y": 1,
      "z": 11,
      "name": "Rock_Volcanic_Brick"
    },
    {
      "x": -5,
      "y": 2,
      "z": 11,
      "name": "Rock_Volcanic_Cobble"
    },
    {
      "x": -5,
      "y": 3,
      "z": 11,
      "name": "Rock_Volcanic_Cobble"
    },
    {
      "x": -5,
      "y": 4,
      "z": 11,
      "name": "Rock_Volcanic_Cobble"
    },
    {
      "x": -5,
      "y": 5,
      "z": 11,
      "name": "Rock_Volcanic_Cobble"
    },
    {
      "x": -5,
      "y": 6,
      "z": 11,
      "name": "Rock_Volcanic_Cobble"
    },
    {
      "x": -5,
      "y": 7,
      "z": 11,
      "name": "Rock_Volcanic_Brick"
    },
    {
      "x": -5,
      "y": 8,
      "z": 11,
      "name": "Rock_Volcanic_Cobble"
    },
    {
      "x": -5,
      "y": 9,
      "z": 11,
      "name": "Rock_Volcanic_Cobble"
    },
    {
      "x": -5,
      "y": 10,
      "z": 11,
      "name": "Rock_Volcanic_Brick"
    },
    {
      "x": -5,
      "y": 11,
      "z": 11,
      "name": "Rock_Volcanic_Cobble"
    },
    {
      "x": -5,
      "y": 12,
      "z": 11,
      "name": "Rock_Volcanic_Cobble"
    },
    {
      "x": -5,
      "y": 13,
      "z": 11,
      "name": "Rock_Volcanic_Brick"
    },
    {
      "x": -5,
      "y": 14,
      "z": 11,
      "name": "Rock_Volcanic_Cobble"
    },
    {
      "x": -5,
      "y": 15,
      "z": 11,
      "name": "Rock_Volcanic_Brick"
    },
    {
      "x": -5,
      "y": 1,
      "z": 12,
      "name": "Rock_Volcanic_Cobble"
    },
    {
      "x": -5,
      "y": 2,
      "z": 12,
      "name": "Rock_Volcanic_Cobble"
    },
    {
      "x": -5,
      "y": 3,
      "z": 12,
      "name": "Rock_Volcanic_Brick"
    },
    {
      "x": -5,
      "y": 4,
      "z": 12,
      "name": "Rock_Volcanic_Cobble"
    },
    {
      "x": -5,
      "y": 5,
      "z": 12,
      "name": "Rock_Volcanic_Cobble"
    },
    {
      "x": -5,
      "y": 6,
      "z": 12,
      "name": "Rock_Volcanic_Cobble"
    },
    {
      "x": -5,
      "y": 7,
      "z": 12,
      "name": "Rock_Volcanic_Cobble"
    },
    {
      "x": -5,
      "y": 8,
      "z": 12,
      "name": "Rock_Volcanic_Cobble"
    },
    {
      "x": -5,
      "y": 9,
      "z": 12,
      "name": "Rock_Volcanic_Brick"
    },
    {
      "x": -5,
      "y": 1,
      "z": 13,
      "name": "Rock_Volcanic_Cobble"
    },
    {
      "x": -5,
      "y": 2,
      "z": 13,
      "name": "Rock_Volcanic_Brick"
    },
    {
      "x": -5,
      "y": 3,
      "z": 13,
      "name": "Rock_Volcanic_Cobble"
    },
    {
      "x": -5,
      "y": 4,
      "z": 13,
      "name": "Rock_Volcanic_Cobble"
    },
    {
      "x": -4,
      "y": 79,
      "z": -12,
      "name": "Rock_Volcanic_Brick_Half",
      "rotation": 8
    },
    {
      "x": -4,
      "y": 80,
      "z": -12,
      "name": "Rock_Volcanic_Brick_Wall",
      "rotation": 2
    },
    {
      "x": -4,
      "y": 89,
      "z": -8,
      "name": "Rock_Volcanic_Cobble",
      "rotation": 1
    },
    {
      "x": -4,
      "y": 90,
      "z": -8,
      "name": "Rock_Volcanic_Cobble",
      "rotation": 1
    },
    {
      "x": -4,
      "y": 91,
      "z": -8,
      "name": "*Rock_Volcanic_Brick_Wall_State_Definitions_Corner",
      "rotation": 1
    },
    {
      "x": -4,
      "y": 85,
      "z": -7,
      "name": "*Rock_Volcanic_Brick_Wall_State_Definitions_Corner",
      "rotation": 1
    },
    {
      "x": -4,
      "y": 86,
      "z": -7,
      "name": "Rock_Volcanic_Brick",
      "rotation": 1
    },
    {
      "x": -4,
      "y": 87,
      "z": -7,
      "name": "Rock_Volcanic_Cobble",
      "rotation": 1
    },
    {
      "x": -4,
      "y": 88,
      "z": -7,
      "name": "Rock_Volcanic_Cobble",
      "rotation": 1
    },
    {
      "x": -4,
      "y": 89,
      "z": -7,
      "name": "Rock_Volcanic_Cobble",
      "rotation": 1
    },
    {
      "x": -4,
      "y": 90,
      "z": -7,
      "name": "Rock_Volcanic_Cobble",
      "rotation": 1
    },
    {
      "x": -4,
      "y": 91,
      "z": -7,
      "name": "*Rock_Volcanic_Brick_Wall_State_Definitions_Corner",
      "rotation": 3
    },
    {
      "x": -4,
      "y": 78,
      "z": -6,
      "name": "Rock_Crystal_Green_Block"
    },
    {
      "x": -4,
      "y": 79,
      "z": -6,
      "name": "Rock_Crystal_Green_Block"
    },
    {
      "x": -4,
      "y": 80,
      "z": -6,
      "name": "Rock_Crystal_Green_Block"
    },
    {
      "x": -4,
      "y": 81,
      "z": -6,
      "name": "Rock_Crystal_Green_Block"
    },
    {
      "x": -4,
      "y": 82,
      "z": -6,
      "name": "Rock_Crystal_Green_Block"
    },
    {
      "x": -4,
      "y": 85,
      "z": -6,
      "name": "*Rock_Volcanic_Brick_Wall_State_Definitions_Corner",
      "rotation": 3
    },
    {
      "x": -4,
      "y": 86,
      "z": -6,
      "name": "Rock_Volcanic_Cobble",
      "rotation": 1
    },
    {
      "x": -4,
      "y": 87,
      "z": -6,
      "name": "Rock_Volcanic_Cobble",
      "rotation": 1
    },
    {
      "x": -4,
      "y": 88,
      "z": -6,
      "name": "Rock_Volcanic_Brick",
      "rotation": 1
    },
    {
      "x": -4,
      "y": 89,
      "z": -6,
      "name": "Rock_Volcanic_Brick",
      "rotation": 1
    },
    {
      "x": -4,
      "y": 90,
      "z": -6,
      "name": "Rock_Volcanic_Brick",
      "rotation": 1
    },
    {
      "x": -4,
      "y": 66,
      "z": -5,
      "name": "Wood_Deadwood_Beam"
    },
    {
      "x": -4,
      "y": 67,
      "z": -5,
      "name": "Wood_Deadwood_Beam"
    },
    {
      "x": -4,
      "y": 68,
      "z": -5,
      "name": "Wood_Deadwood_Beam"
    },
    {
      "x": -4,
      "y": 72,
      "z": -5,
      "name": "Rock_Volcanic_Brick"
    },
    {
      "x": -4,
      "y": 73,
      "z": -5,
      "name": "Rock_Volcanic_Cobble"
    },
    {
      "x": -4,
      "y": 74,
      "z": -5,
      "name": "Rock_Volcanic_Cobble"
    },
    {
      "x": -4,
      "y": 75,
      "z": -5,
      "name": "*Rock_Volcanic_Brick_Wall_State_Definitions_Corner",
      "rotation": 1
    },
    {
      "x": -4,
      "y": 78,
      "z": -5,
      "name": "Rock_Crystal_Green_Block"
    },
    {
      "x": -4,
      "y": 79,
      "z": -5,
      "name": "Rock_Crystal_Green_Block"
    },
    {
      "x": -4,
      "y": 80,
      "z": -5,
      "name": "Rock_Crystal_Green_Block"
    },
    {
      "x": -4,
      "y": 81,
      "z": -5,
      "name": "Rock_Crystal_Green_Block"
    },
    {
      "x": -4,
      "y": 82,
      "z": -5,
      "name": "Rock_Crystal_Green_Block"
    },
    {
      "x": -4,
      "y": 83,
      "z": -5,
      "name": "Rock_Crystal_Green_Block"
    },
    {
      "x": -4,
      "y": 87,
      "z": -5,
      "name": "Rock_Volcanic_Cobble",
      "rotation": 1
    },
    {
      "x": -4,
      "y": 88,
      "z": -5,
      "name": "Rock_Volcanic_Cobble",
      "rotation": 1
    },
    {
      "x": -4,
      "y": 89,
      "z": -5,
      "name": "Rock_Volcanic_Cobble",
      "rotation": 1
    },
    {
      "x": -4,
      "y": 90,
      "z": -5,
      "name": "Rock_Volcanic_Cobble",
      "rotation": 2
    },
    {
      "x": -4,
      "y": 91,
      "z": -5,
      "name": "Rock_Volcanic_Brick",
      "rotation": 2
    },
    {
      "x": -4,
      "y": 59,
      "z": -4,
      "name": "Rock_Aqua_Cobble_Half",
      "rotation": 6
    },
    {
      "x": -4,
      "y": 61,
      "z": -4,
      "name": "Rock_Volcanic_Brick_Pillar_Middle"
    },
    {
      "x": -4,
      "y": 62,
      "z": -4,
      "name": "Rock_Volcanic_Brick_Pillar_Middle"
    },
    {
      "x": -4,
      "y": 63,
      "z": -4,
      "name": "Rock_Volcanic_Brick_Beam"
    },
    {
      "x": -4,
      "y": 64,
      "z": -4,
      "name": "Rock_Volcanic_Brick_Beam"
    },
    {
      "x": -4,
      "y": 65,
      "z": -4,
      "name": "Rock_Volcanic_Brick_Beam"
    },
    {
      "x": -4,
      "y": 66,
      "z": -4,
      "name": "Wood_Deadwood_Beam"
    },
    {
      "x": -4,
      "y": 67,
      "z": -4,
      "name": "Rock_Volcanic_Cobble"
    },
    {
      "x": -4,
      "y": 68,
      "z": -4,
      "name": "Rock_Volcanic_Brick"
    },
    {
      "x": -4,
      "y": 69,
      "z": -4,
      "name": "Rock_Volcanic_Brick"
    },
    {
      "x": -4,
      "y": 70,
      "z": -4,
      "name": "Rock_Volcanic_Cobble"
    },
    {
      "x": -4,
      "y": 71,
      "z": -4,
      "name": "Rock_Volcanic_Cobble"
    },
    {
      "x": -4,
      "y": 72,
      "z": -4,
      "name": "Rock_Volcanic_Cobble"
    },
    {
      "x": -4,
      "y": 73,
      "z": -4,
      "name": "Rock_Volcanic_Cobble"
    },
    {
      "x": -4,
      "y": 74,
      "z": -4,
      "name": "Rock_Volcanic_Cobble"
    },
    {
      "x": -4,
      "y": 75,
      "z": -4,
      "name": "Rock_Volcanic_Cobble"
    },
    {
      "x": -4,
      "y": 76,
      "z": -4,
      "name": "*Rock_Volcanic_Brick_Wall_State_Definitions_Corner",
      "rotation": 3
    },
    {
      "x": -4,
      "y": 78,
      "z": -4,
      "name": "Rock_Crystal_Green_Block"
    },
    {
      "x": -4,
      "y": 79,
      "z": -4,
      "name": "Rock_Crystal_Green_Block"
    },
    {
      "x": -4,
      "y": 80,
      "z": -4,
      "name": "Rock_Crystal_Green_Block"
    },
    {
      "x": -4,
      "y": 81,
      "z": -4,
      "name": "Rock_Crystal_Green_Block"
    },
    {
      "x": -4,
      "y": 82,
      "z": -4,
      "name": "Rock_Crystal_Green_Block"
    },
    {
      "x": -4,
      "y": 83,
      "z": -4,
      "name": "Rock_Crystal_Green_Block"
    },
    {
      "x": -4,
      "y": 84,
      "z": -4,
      "name": "Rock_Crystal_Green_Block",
      "rotation": 1
    },
    {
      "x": -4,
      "y": 87,
      "z": -4,
      "name": "Rock_Volcanic_Brick",
      "rotation": 2
    },
    {
      "x": -4,
      "y": 88,
      "z": -4,
      "name": "Rock_Volcanic_Brick",
      "rotation": 2
    },
    {
      "x": -4,
      "y": 89,
      "z": -4,
      "name": "Rock_Volcanic_Brick",
      "rotation": 2
    },
    {
      "x": -4,
      "y": 90,
      "z": -4,
      "name": "Rock_Volcanic_Brick",
      "rotation": 2
    },
    {
      "x": -4,
      "y": 91,
      "z": -4,
      "name": "Rock_Volcanic_Brick",
      "rotation": 2
    },
    {
      "x": -4,
      "y": 55,
      "z": -3,
      "name": "Rock_Volcanic_Brick_Beam"
    },
    {
      "x": -4,
      "y": 56,
      "z": -3,
      "name": "Rock_Volcanic_Brick_Pillar_Middle"
    },
    {
      "x": -4,
      "y": 57,
      "z": -3,
      "name": "Rock_Volcanic_Brick_Pillar_Middle"
    },
    {
      "x": -4,
      "y": 58,
      "z": -3,
      "name": "Rock_Volcanic_Brick"
    },
    {
      "x": -4,
      "y": 59,
      "z": -3,
      "name": "Rock_Volcanic_Brick"
    },
    {
      "x": -4,
      "y": 60,
      "z": -3,
      "name": "Rock_Volcanic_Brick"
    },
    {
      "x": -4,
      "y": 61,
      "z": -3,
      "name": "Rock_Volcanic_Cobble"
    },
    {
      "x": -4,
      "y": 62,
      "z": -3,
      "name": "Rock_Volcanic_Cobble"
    },
    {
      "x": -4,
      "y": 63,
      "z": -3,
      "name": "Rock_Volcanic_Cobble"
    },
    {
      "x": -4,
      "y": 64,
      "z": -3,
      "name": "Rock_Volcanic_Brick"
    },
    {
      "x": -4,
      "y": 65,
      "z": -3,
      "name": "Rock_Volcanic_Cobble"
    },
    {
      "x": -4,
      "y": 66,
      "z": -3,
      "name": "Rock_Volcanic_Brick"
    },
    {
      "x": -4,
      "y": 67,
      "z": -3,
      "name": "Rock_Volcanic_Cobble"
    },
    {
      "x": -4,
      "y": 68,
      "z": -3,
      "name": "Rock_Volcanic_Cobble"
    },
    {
      "x": -4,
      "y": 69,
      "z": -3,
      "name": "Rock_Volcanic_Cobble"
    },
    {
      "x": -4,
      "y": 70,
      "z": -3,
      "name": "Rock_Volcanic_Cobble"
    },
    {
      "x": -4,
      "y": 71,
      "z": -3,
      "name": "Rock_Volcanic_Brick"
    },
    {
      "x": -4,
      "y": 72,
      "z": -3,
      "name": "Rock_Volcanic_Cobble"
    },
    {
      "x": -4,
      "y": 73,
      "z": -3,
      "name": "Rock_Volcanic_Brick"
    },
    {
      "x": -4,
      "y": 74,
      "z": -3,
      "name": "Rock_Volcanic_Cobble"
    },
    {
      "x": -4,
      "y": 75,
      "z": -3,
      "name": "Rock_Volcanic_Cobble"
    },
    {
      "x": -4,
      "y": 78,
      "z": -3,
      "name": "Rock_Crystal_Green_Block",
      "rotation": 1
    },
    {
      "x": -4,
      "y": 79,
      "z": -3,
      "name": "Rock_Crystal_Green_Block",
      "rotation": 1
    },
    {
      "x": -4,
      "y": 80,
      "z": -3,
      "name": "Rock_Crystal_Green_Block",
      "rotation": 1
    },
    {
      "x": -4,
      "y": 81,
      "z": -3,
      "name": "Rock_Crystal_Green_Block",
      "rotation": 1
    },
    {
      "x": -4,
      "y": 82,
      "z": -3,
      "name": "Rock_Crystal_Green_Block",
      "rotation": 1
    },
    {
      "x": -4,
      "y": 83,
      "z": -3,
      "name": "Rock_Crystal_Green_Block",
      "rotation": 1
    },
    {
      "x": -4,
      "y": 84,
      "z": -3,
      "name": "Rock_Crystal_Green_Block",
      "rotation": 1
    },
    {
      "x": -4,
      "y": 87,
      "z": -3,
      "name": "Rock_Volcanic_Cobble",
      "rotation": 2
    },
    {
      "x": -4,
      "y": 88,
      "z": -3,
      "name": "Rock_Volcanic_Cobble",
      "rotation": 2
    },
    {
      "x": -4,
      "y": 89,
      "z": -3,
      "name": "Rock_Volcanic_Brick",
      "rotation": 2
    },
    {
      "x": -4,
      "y": 90,
      "z": -3,
      "name": "Rock_Volcanic_Cobble",
      "rotation": 2
    },
    {
      "x": -4,
      "y": 91,
      "z": -3,
      "name": "Rock_Volcanic_Cobble",
      "rotation": 2
    },
    {
      "x": -4,
      "y": 92,
      "z": -3,
      "name": "*Rock_Volcanic_Brick_Wall_State_Definitions_Corner"
    },
    {
      "x": -4,
      "y": 50,
      "z": -2,
      "name": "Wood_Deadwood_Beam"
    },
    {
      "x": -4,
      "y": 51,
      "z": -2,
      "name": "Wood_Deadwood_Beam"
    },
    {
      "x": -4,
      "y": 52,
      "z": -2,
      "name": "Wood_Deadwood_Beam"
    },
    {
      "x": -4,
      "y": 53,
      "z": -2,
      "name": "Wood_Deadwood_Beam"
    },
    {
      "x": -4,
      "y": 54,
      "z": -2,
      "name": "Rock_Volcanic_Brick_Beam"
    },
    {
      "x": -4,
      "y": 55,
      "z": -2,
      "name": "Rock_Volcanic_Brick"
    },
    {
      "x": -4,
      "y": 56,
      "z": -2,
      "name": "Rock_Volcanic_Brick"
    },
    {
      "x": -4,
      "y": 57,
      "z": -2,
      "name": "Rock_Volcanic_Cobble"
    },
    {
      "x": -4,
      "y": 58,
      "z": -2,
      "name": "Rock_Volcanic_Cobble"
    },
    {
      "x": -4,
      "y": 59,
      "z": -2,
      "name": "Rock_Volcanic_Cobble"
    },
    {
      "x": -4,
      "y": 60,
      "z": -2,
      "name": "Rock_Volcanic_Brick"
    },
    {
      "x": -4,
      "y": 61,
      "z": -2,
      "name": "Rock_Volcanic_Cobble"
    },
    {
      "x": -4,
      "y": 62,
      "z": -2,
      "name": "Rock_Volcanic_Brick"
    },
    {
      "x": -4,
      "y": 63,
      "z": -2,
      "name": "Rock_Volcanic_Brick"
    },
    {
      "x": -4,
      "y": 64,
      "z": -2,
      "name": "Rock_Volcanic_Brick"
    },
    {
      "x": -4,
      "y": 65,
      "z": -2,
      "name": "Rock_Volcanic_Cobble"
    },
    {
      "x": -4,
      "y": 66,
      "z": -2,
      "name": "Rock_Volcanic_Cobble"
    },
    {
      "x": -4,
      "y": 67,
      "z": -2,
      "name": "Rock_Volcanic_Brick"
    },
    {
      "x": -4,
      "y": 68,
      "z": -2,
      "name": "Rock_Volcanic_Cobble"
    },
    {
      "x": -4,
      "y": 69,
      "z": -2,
      "name": "Rock_Volcanic_Cobble"
    },
    {
      "x": -4,
      "y": 70,
      "z": -2,
      "name": "Rock_Volcanic_Brick"
    },
    {
      "x": -4,
      "y": 71,
      "z": -2,
      "name": "Rock_Volcanic_Cobble"
    },
    {
      "x": -4,
      "y": 72,
      "z": -2,
      "name": "Rock_Volcanic_Cobble"
    },
    {
      "x": -4,
      "y": 73,
      "z": -2,
      "name": "Rock_Volcanic_Cobble",
      "rotation": 1
    },
    {
      "x": -4,
      "y": 74,
      "z": -2,
      "name": "Rock_Volcanic_Cobble",
      "rotation": 1
    },
    {
      "x": -4,
      "y": 75,
      "z": -2,
      "name": "Rock_Volcanic_Cobble",
      "rotation": 1
    },
    {
      "x": -4,
      "y": 78,
      "z": -2,
      "name": "Rock_Crystal_Green_Block",
      "rotation": 1
    },
    {
      "x": -4,
      "y": 79,
      "z": -2,
      "name": "Rock_Crystal_Green_Block",
      "rotation": 1
    },
    {
      "x": -4,
      "y": 80,
      "z": -2,
      "name": "Rock_Crystal_Green_Block",
      "rotation": 1
    },
    {
      "x": -4,
      "y": 81,
      "z": -2,
      "name": "Rock_Crystal_Green_Block",
      "rotation": 1
    },
    {
      "x": -4,
      "y": 82,
      "z": -2,
      "name": "Rock_Crystal_Green_Block",
      "rotation": 1
    },
    {
      "x": -4,
      "y": 83,
      "z": -2,
      "name": "Rock_Crystal_Green_Block",
      "rotation": 1
    },
    {
      "x": -4,
      "y": 84,
      "z": -2,
      "name": "Rock_Crystal_Green_Block",
      "rotation": 1
    },
    {
      "x": -4,
      "y": 86,
      "z": -2,
      "name": "*Rock_Volcanic_Brick_Wall_State_Definitions_Corner"
    },
    {
      "x": -4,
      "y": 87,
      "z": -2,
      "name": "Rock_Volcanic_Brick",
      "rotation": 2
    },
    {
      "x": -4,
      "y": 88,
      "z": -2,
      "name": "Rock_Volcanic_Cobble",
      "rotation": 2
    },
    {
      "x": -4,
      "y": 89,
      "z": -2,
      "name": "Rock_Volcanic_Brick",
      "rotation": 2
    },
    {
      "x": -4,
      "y": 90,
      "z": -2,
      "name": "Rock_Volcanic_Brick",
      "rotation": 2
    },
    {
      "x": -4,
      "y": 91,
      "z": -2,
      "name": "Rock_Volcanic_Brick",
      "rotation": 2
    },
    {
      "x": -4,
      "y": 92,
      "z": -2,
      "name": "*Rock_Volcanic_Brick_Wall_State_Definitions_Corner",
      "rotation": 2
    },
    {
      "x": -4,
      "y": 50,
      "z": -1,
      "name": "Rock_Volcanic_Brick"
    },
    {
      "x": -4,
      "y": 51,
      "z": -1,
      "name": "Rock_Volcanic_Cobble"
    },
    {
      "x": -4,
      "y": 52,
      "z": -1,
      "name": "Rock_Volcanic_Brick"
    },
    {
      "x": -4,
      "y": 53,
      "z": -1,
      "name": "Rock_Volcanic_Cobble"
    },
    {
      "x": -4,
      "y": 54,
      "z": -1,
      "name": "Rock_Volcanic_Cobble"
    },
    {
      "x": -4,
      "y": 55,
      "z": -1,
      "name": "Rock_Volcanic_Brick"
    },
    {
      "x": -4,
      "y": 56,
      "z": -1,
      "name": "Rock_Volcanic_Brick"
    },
    {
      "x": -4,
      "y": 57,
      "z": -1,
      "name": "Rock_Volcanic_Brick"
    },
    {
      "x": -4,
      "y": 58,
      "z": -1,
      "name": "Rock_Volcanic_Brick"
    },
    {
      "x": -4,
      "y": 59,
      "z": -1,
      "name": "Rock_Volcanic_Cobble"
    },
    {
      "x": -4,
      "y": 60,
      "z": -1,
      "name": "Rock_Volcanic_Brick"
    },
    {
      "x": -4,
      "y": 61,
      "z": -1,
      "name": "Rock_Volcanic_Cobble"
    },
    {
      "x": -4,
      "y": 62,
      "z": -1,
      "name": "Rock_Volcanic_Brick"
    },
    {
      "x": -4,
      "y": 63,
      "z": -1,
      "name": "Rock_Volcanic_Brick"
    },
    {
      "x": -4,
      "y": 64,
      "z": -1,
      "name": "Rock_Volcanic_Cobble"
    },
    {
      "x": -4,
      "y": 65,
      "z": -1,
      "name": "Rock_Volcanic_Brick"
    },
    {
      "x": -4,
      "y": 66,
      "z": -1,
      "name": "Rock_Volcanic_Brick"
    },
    {
      "x": -4,
      "y": 67,
      "z": -1,
      "name": "Rock_Volcanic_Brick"
    },
    {
      "x": -4,
      "y": 68,
      "z": -1,
      "name": "Rock_Volcanic_Brick"
    },
    {
      "x": -4,
      "y": 69,
      "z": -1,
      "name": "Rock_Volcanic_Cobble"
    },
    {
      "x": -4,
      "y": 70,
      "z": -1,
      "name": "Rock_Volcanic_Brick"
    },
    {
      "x": -4,
      "y": 71,
      "z": -1,
      "name": "Rock_Volcanic_Brick"
    },
    {
      "x": -4,
      "y": 72,
      "z": -1,
      "name": "Rock_Volcanic_Cobble",
      "rotation": 1
    },
    {
      "x": -4,
      "y": 73,
      "z": -1,
      "name": "Rock_Volcanic_Brick",
      "rotation": 1
    },
    {
      "x": -4,
      "y": 74,
      "z": -1,
      "name": "Rock_Volcanic_Cobble",
      "rotation": 1
    },
    {
      "x": -4,
      "y": 75,
      "z": -1,
      "name": "Rock_Volcanic_Brick",
      "rotation": 1
    },
    {
      "x": -4,
      "y": 78,
      "z": -1,
      "name": "Rock_Crystal_Green_Block",
      "rotation": 1
    },
    {
      "x": -4,
      "y": 79,
      "z": -1,
      "name": "Rock_Crystal_Green_Block",
      "rotation": 1
    },
    {
      "x": -4,
      "y": 80,
      "z": -1,
      "name": "Rock_Crystal_Green_Block",
      "rotation": 1
    },
    {
      "x": -4,
      "y": 81,
      "z": -1,
      "name": "Rock_Crystal_Green_Block",
      "rotation": 1
    },
    {
      "x": -4,
      "y": 82,
      "z": -1,
      "name": "Rock_Crystal_Green_Block",
      "rotation": 1
    },
    {
      "x": -4,
      "y": 83,
      "z": -1,
      "name": "Rock_Crystal_Green_Block",
      "rotation": 1
    },
    {
      "x": -4,
      "y": 86,
      "z": -1,
      "name": "*Rock_Volcanic_Brick_Wall_State_Definitions_Corner",
      "rotation": 2
    },
    {
      "x": -4,
      "y": 87,
      "z": -1,
      "name": "Rock_Volcanic_Brick",
      "rotation": 2
    },
    {
      "x": -4,
      "y": 88,
      "z": -1,
      "name": "Rock_Volcanic_Brick",
      "rotation": 2
    },
    {
      "x": -4,
      "y": 89,
      "z": -1,
      "name": "Rock_Volcanic_Brick",
      "rotation": 2
    },
    {
      "x": -4,
      "y": 44,
      "z": 0,
      "name": "Rock_Volcanic_Cobble"
    },
    {
      "x": -4,
      "y": 45,
      "z": 0,
      "name": "Rock_Volcanic_Brick"
    },
    {
      "x": -4,
      "y": 46,
      "z": 0,
      "name": "Rock_Volcanic_Brick"
    },
    {
      "x": -4,
      "y": 47,
      "z": 0,
      "name": "Rock_Volcanic_Cobble"
    },
    {
      "x": -4,
      "y": 48,
      "z": 0,
      "name": "Rock_Volcanic_Brick"
    },
    {
      "x": -4,
      "y": 49,
      "z": 0,
      "name": "Rock_Volcanic_Cobble"
    },
    {
      "x": -4,
      "y": 50,
      "z": 0,
      "name": "Rock_Volcanic_Cobble"
    },
    {
      "x": -4,
      "y": 51,
      "z": 0,
      "name": "Rock_Volcanic_Cobble"
    },
    {
      "x": -4,
      "y": 52,
      "z": 0,
      "name": "Rock_Volcanic_Brick"
    },
    {
      "x": -4,
      "y": 53,
      "z": 0,
      "name": "Rock_Volcanic_Cobble"
    },
    {
      "x": -4,
      "y": 54,
      "z": 0,
      "name": "Rock_Volcanic_Cobble"
    },
    {
      "x": -4,
      "y": 55,
      "z": 0,
      "name": "Rock_Volcanic_Brick"
    },
    {
      "x": -4,
      "y": 56,
      "z": 0,
      "name": "Rock_Volcanic_Brick"
    },
    {
      "x": -4,
      "y": 57,
      "z": 0,
      "name": "Rock_Volcanic_Brick"
    },
    {
      "x": -4,
      "y": 58,
      "z": 0,
      "name": "Rock_Volcanic_Brick"
    },
    {
      "x": -4,
      "y": 59,
      "z": 0,
      "name": "Rock_Volcanic_Brick"
    },
    {
      "x": -4,
      "y": 60,
      "z": 0,
      "name": "Rock_Volcanic_Brick"
    },
    {
      "x": -4,
      "y": 61,
      "z": 0,
      "name": "Rock_Volcanic_Brick"
    },
    {
      "x": -4,
      "y": 62,
      "z": 0,
      "name": "Rock_Volcanic_Cobble"
    },
    {
      "x": -4,
      "y": 63,
      "z": 0,
      "name": "Rock_Volcanic_Cobble"
    },
    {
      "x": -4,
      "y": 64,
      "z": 0,
      "name": "Rock_Volcanic_Brick"
    },
    {
      "x": -4,
      "y": 65,
      "z": 0,
      "name": "Rock_Volcanic_Cobble"
    },
    {
      "x": -4,
      "y": 66,
      "z": 0,
      "name": "Rock_Volcanic_Cobble"
    },
    {
      "x": -4,
      "y": 67,
      "z": 0,
      "name": "Rock_Volcanic_Brick"
    },
    {
      "x": -4,
      "y": 68,
      "z": 0,
      "name": "Rock_Volcanic_Cobble"
    },
    {
      "x": -4,
      "y": 69,
      "z": 0,
      "name": "Rock_Volcanic_Brick"
    },
    {
      "x": -4,
      "y": 70,
      "z": 0,
      "name": "Rock_Volcanic_Brick"
    },
    {
      "x": -4,
      "y": 71,
      "z": 0,
      "name": "Rock_Volcanic_Brick"
    },
    {
      "x": -4,
      "y": 72,
      "z": 0,
      "name": "Rock_Volcanic_Cobble",
      "rotation": 1
    },
    {
      "x": -4,
      "y": 73,
      "z": 0,
      "name": "Rock_Volcanic_Cobble",
      "rotation": 1
    },
    {
      "x": -4,
      "y": 74,
      "z": 0,
      "name": "Rock_Volcanic_Brick",
      "rotation": 1
    },
    {
      "x": -4,
      "y": 75,
      "z": 0,
      "name": "Rock_Volcanic_Brick",
      "rotation": 1
    },
    {
      "x": -4,
      "y": 76,
      "z": 0,
      "name": "*Rock_Volcanic_Brick_Wall_State_Definitions_Corner"
    },
    {
      "x": -4,
      "y": 79,
      "z": 0,
      "name": "Rock_Crystal_Green_Block",
      "rotation": 1
    },
    {
      "x": -4,
      "y": 80,
      "z": 0,
      "name": "Rock_Crystal_Green_Block",
      "rotation": 1
    },
    {
      "x": -4,
      "y": 81,
      "z": 0,
      "name": "Rock_Crystal_Green_Block",
      "rotation": 1
    },
    {
      "x": -4,
      "y": 82,
      "z": 0,
      "name": "Rock_Crystal_Green_Block",
      "rotation": 1
    },
    {
      "x": -4,
      "y": 83,
      "z": 0,
      "name": "Rock_Crystal_Green_Block",
      "rotation": 1
    },
    {
      "x": -4,
      "y": 38,
      "z": 1,
      "name": "Rock_Volcanic_Cobble"
    },
    {
      "x": -4,
      "y": 39,
      "z": 1,
      "name": "Rock_Volcanic_Cobble"
    },
    {
      "x": -4,
      "y": 40,
      "z": 1,
      "name": "Rock_Volcanic_Brick"
    },
    {
      "x": -4,
      "y": 41,
      "z": 1,
      "name": "Rock_Volcanic_Brick"
    },
    {
      "x": -4,
      "y": 42,
      "z": 1,
      "name": "Rock_Volcanic_Cobble"
    },
    {
      "x": -4,
      "y": 43,
      "z": 1,
      "name": "Rock_Volcanic_Cobble"
    },
    {
      "x": -4,
      "y": 44,
      "z": 1,
      "name": "Rock_Volcanic_Brick"
    },
    {
      "x": -4,
      "y": 45,
      "z": 1,
      "name": "Rock_Volcanic_Cobble"
    },
    {
      "x": -4,
      "y": 46,
      "z": 1,
      "name": "Rock_Volcanic_Cobble"
    },
    {
      "x": -4,
      "y": 47,
      "z": 1,
      "name": "Rock_Volcanic_Cobble"
    },
    {
      "x": -4,
      "y": 48,
      "z": 1,
      "name": "Rock_Volcanic_Cobble"
    },
    {
      "x": -4,
      "y": 49,
      "z": 1,
      "name": "Rock_Volcanic_Brick"
    },
    {
      "x": -4,
      "y": 50,
      "z": 1,
      "name": "Rock_Volcanic_Cobble"
    },
    {
      "x": -4,
      "y": 51,
      "z": 1,
      "name": "Rock_Volcanic_Brick"
    },
    {
      "x": -4,
      "y": 52,
      "z": 1,
      "name": "Rock_Volcanic_Cobble"
    },
    {
      "x": -4,
      "y": 53,
      "z": 1,
      "name": "Rock_Volcanic_Brick"
    },
    {
      "x": -4,
      "y": 54,
      "z": 1,
      "name": "Rock_Volcanic_Brick"
    },
    {
      "x": -4,
      "y": 55,
      "z": 1,
      "name": "Rock_Volcanic_Cobble"
    },
    {
      "x": -4,
      "y": 56,
      "z": 1,
      "name": "Rock_Volcanic_Cobble"
    },
    {
      "x": -4,
      "y": 57,
      "z": 1,
      "name": "Rock_Volcanic_Brick"
    },
    {
      "x": -4,
      "y": 58,
      "z": 1,
      "name": "Rock_Volcanic_Cobble"
    },
    {
      "x": -4,
      "y": 59,
      "z": 1,
      "name": "Rock_Volcanic_Brick"
    },
    {
      "x": -4,
      "y": 60,
      "z": 1,
      "name": "Rock_Volcanic_Brick"
    },
    {
      "x": -4,
      "y": 61,
      "z": 1,
      "name": "Rock_Volcanic_Cobble"
    },
    {
      "x": -4,
      "y": 62,
      "z": 1,
      "name": "Rock_Volcanic_Brick"
    },
    {
      "x": -4,
      "y": 63,
      "z": 1,
      "name": "Rock_Volcanic_Cobble"
    },
    {
      "x": -4,
      "y": 64,
      "z": 1,
      "name": "Rock_Volcanic_Brick"
    },
    {
      "x": -4,
      "y": 65,
      "z": 1,
      "name": "Rock_Volcanic_Cobble"
    },
    {
      "x": -4,
      "y": 66,
      "z": 1,
      "name": "Rock_Volcanic_Brick"
    },
    {
      "x": -4,
      "y": 67,
      "z": 1,
      "name": "Rock_Volcanic_Cobble"
    },
    {
      "x": -4,
      "y": 68,
      "z": 1,
      "name": "Rock_Volcanic_Cobble"
    },
    {
      "x": -4,
      "y": 69,
      "z": 1,
      "name": "Rock_Volcanic_Brick"
    },
    {
      "x": -4,
      "y": 70,
      "z": 1,
      "name": "Rock_Volcanic_Brick"
    },
    {
      "x": -4,
      "y": 71,
      "z": 1,
      "name": "Rock_Volcanic_Brick"
    },
    {
      "x": -4,
      "y": 72,
      "z": 1,
      "name": "Rock_Volcanic_Cobble",
      "rotation": 1
    },
    {
      "x": -4,
      "y": 73,
      "z": 1,
      "name": "Rock_Volcanic_Cobble",
      "rotation": 1
    },
    {
      "x": -4,
      "y": 74,
      "z": 1,
      "name": "Rock_Volcanic_Brick",
      "rotation": 1
    },
    {
      "x": -4,
      "y": 75,
      "z": 1,
      "name": "Rock_Volcanic_Cobble",
      "rotation": 1
    },
    {
      "x": -4,
      "y": 76,
      "z": 1,
      "name": "*Rock_Volcanic_Brick_Wall_State_Definitions_Corner",
      "rotation": 2
    },
    {
      "x": -4,
      "y": 32,
      "z": 2,
      "name": "Rock_Volcanic_Cobble"
    },
    {
      "x": -4,
      "y": 33,
      "z": 2,
      "name": "Rock_Volcanic_Cobble"
    },
    {
      "x": -4,
      "y": 34,
      "z": 2,
      "name": "Rock_Volcanic_Cobble"
    },
    {
      "x": -4,
      "y": 35,
      "z": 2,
      "name": "Rock_Volcanic_Cobble"
    },
    {
      "x": -4,
      "y": 36,
      "z": 2,
      "name": "Rock_Volcanic_Brick"
    },
    {
      "x": -4,
      "y": 37,
      "z": 2,
      "name": "Rock_Volcanic_Brick"
    },
    {
      "x": -4,
      "y": 38,
      "z": 2,
      "name": "Rock_Volcanic_Brick"
    },
    {
      "x": -4,
      "y": 39,
      "z": 2,
      "name": "Rock_Volcanic_Cobble"
    },
    {
      "x": -4,
      "y": 40,
      "z": 2,
      "name": "Rock_Volcanic_Brick"
    },
    {
      "x": -4,
      "y": 41,
      "z": 2,
      "name": "Rock_Volcanic_Brick"
    },
    {
      "x": -4,
      "y": 42,
      "z": 2,
      "name": "Rock_Volcanic_Cobble"
    },
    {
      "x": -4,
      "y": 43,
      "z": 2,
      "name": "Rock_Volcanic_Brick"
    },
    {
      "x": -4,
      "y": 44,
      "z": 2,
      "name": "Rock_Volcanic_Brick"
    },
    {
      "x": -4,
      "y": 45,
      "z": 2,
      "name": "Rock_Volcanic_Cobble"
    },
    {
      "x": -4,
      "y": 46,
      "z": 2,
      "name": "Rock_Volcanic_Brick"
    },
    {
      "x": -4,
      "y": 47,
      "z": 2,
      "name": "Rock_Volcanic_Brick"
    },
    {
      "x": -4,
      "y": 48,
      "z": 2,
      "name": "Rock_Volcanic_Cobble"
    },
    {
      "x": -4,
      "y": 49,
      "z": 2,
      "name": "Rock_Volcanic_Brick"
    },
    {
      "x": -4,
      "y": 50,
      "z": 2,
      "name": "Rock_Volcanic_Brick"
    },
    {
      "x": -4,
      "y": 51,
      "z": 2,
      "name": "Rock_Volcanic_Cobble"
    },
    {
      "x": -4,
      "y": 52,
      "z": 2,
      "name": "Rock_Volcanic_Brick"
    },
    {
      "x": -4,
      "y": 53,
      "z": 2,
      "name": "Rock_Volcanic_Brick"
    },
    {
      "x": -4,
      "y": 54,
      "z": 2,
      "name": "Rock_Volcanic_Brick"
    },
    {
      "x": -4,
      "y": 55,
      "z": 2,
      "name": "Rock_Volcanic_Cobble"
    },
    {
      "x": -4,
      "y": 56,
      "z": 2,
      "name": "Rock_Volcanic_Cobble"
    },
    {
      "x": -4,
      "y": 57,
      "z": 2,
      "name": "Rock_Volcanic_Cobble"
    },
    {
      "x": -4,
      "y": 58,
      "z": 2,
      "name": "Rock_Volcanic_Brick"
    },
    {
      "x": -4,
      "y": 59,
      "z": 2,
      "name": "Rock_Volcanic_Cobble"
    },
    {
      "x": -4,
      "y": 60,
      "z": 2,
      "name": "Rock_Volcanic_Cobble"
    },
    {
      "x": -4,
      "y": 61,
      "z": 2,
      "name": "Rock_Volcanic_Cobble"
    },
    {
      "x": -4,
      "y": 62,
      "z": 2,
      "name": "Rock_Volcanic_Cobble"
    },
    {
      "x": -4,
      "y": 63,
      "z": 2,
      "name": "Rock_Volcanic_Brick"
    },
    {
      "x": -4,
      "y": 64,
      "z": 2,
      "name": "Rock_Volcanic_Brick"
    },
    {
      "x": -4,
      "y": 65,
      "z": 2,
      "name": "Rock_Volcanic_Brick"
    },
    {
      "x": -4,
      "y": 66,
      "z": 2,
      "name": "Rock_Volcanic_Brick"
    },
    {
      "x": -4,
      "y": 67,
      "z": 2,
      "name": "Rock_Volcanic_Brick"
    },
    {
      "x": -4,
      "y": 68,
      "z": 2,
      "name": "Rock_Volcanic_Brick"
    },
    {
      "x": -4,
      "y": 69,
      "z": 2,
      "name": "Rock_Volcanic_Brick"
    },
    {
      "x": -4,
      "y": 70,
      "z": 2,
      "name": "Rock_Volcanic_Cobble"
    },
    {
      "x": -4,
      "y": 71,
      "z": 2,
      "name": "Rock_Volcanic_Brick"
    },
    {
      "x": -4,
      "y": 72,
      "z": 2,
      "name": "Rock_Volcanic_Brick"
    },
    {
      "x": -4,
      "y": 27,
      "z": 3,
      "name": "Rock_Volcanic_Brick"
    },
    {
      "x": -4,
      "y": 28,
      "z": 3,
      "name": "Rock_Volcanic_Brick"
    },
    {
      "x": -4,
      "y": 29,
      "z": 3,
      "name": "Rock_Volcanic_Brick"
    },
    {
      "x": -4,
      "y": 30,
      "z": 3,
      "name": "Rock_Volcanic_Brick"
    },
    {
      "x": -4,
      "y": 31,
      "z": 3,
      "name": "Rock_Volcanic_Cobble"
    },
    {
      "x": -4,
      "y": 32,
      "z": 3,
      "name": "Rock_Volcanic_Cobble"
    },
    {
      "x": -4,
      "y": 33,
      "z": 3,
      "name": "Rock_Volcanic_Brick"
    },
    {
      "x": -4,
      "y": 34,
      "z": 3,
      "name": "Rock_Volcanic_Brick"
    },
    {
      "x": -4,
      "y": 35,
      "z": 3,
      "name": "Rock_Volcanic_Cobble"
    },
    {
      "x": -4,
      "y": 36,
      "z": 3,
      "name": "Rock_Volcanic_Cobble"
    },
    {
      "x": -4,
      "y": 37,
      "z": 3,
      "name": "Rock_Volcanic_Brick"
    },
    {
      "x": -4,
      "y": 38,
      "z": 3,
      "name": "Rock_Volcanic_Brick"
    },
    {
      "x": -4,
      "y": 39,
      "z": 3,
      "name": "Rock_Volcanic_Cobble"
    },
    {
      "x": -4,
      "y": 40,
      "z": 3,
      "name": "Rock_Volcanic_Brick"
    },
    {
      "x": -4,
      "y": 41,
      "z": 3,
      "name": "Rock_Volcanic_Brick"
    },
    {
      "x": -4,
      "y": 42,
      "z": 3,
      "name": "Rock_Volcanic_Brick"
    },
    {
      "x": -4,
      "y": 43,
      "z": 3,
      "name": "Rock_Volcanic_Brick"
    },
    {
      "x": -4,
      "y": 44,
      "z": 3,
      "name": "Rock_Volcanic_Brick"
    },
    {
      "x": -4,
      "y": 45,
      "z": 3,
      "name": "Rock_Volcanic_Brick"
    },
    {
      "x": -4,
      "y": 46,
      "z": 3,
      "name": "Rock_Volcanic_Brick"
    },
    {
      "x": -4,
      "y": 47,
      "z": 3,
      "name": "Rock_Volcanic_Brick"
    },
    {
      "x": -4,
      "y": 48,
      "z": 3,
      "name": "Rock_Volcanic_Brick"
    },
    {
      "x": -4,
      "y": 49,
      "z": 3,
      "name": "Rock_Volcanic_Brick"
    },
    {
      "x": -4,
      "y": 50,
      "z": 3,
      "name": "Rock_Volcanic_Brick"
    },
    {
      "x": -4,
      "y": 51,
      "z": 3,
      "name": "Rock_Volcanic_Cobble"
    },
    {
      "x": -4,
      "y": 52,
      "z": 3,
      "name": "Rock_Volcanic_Cobble"
    },
    {
      "x": -4,
      "y": 53,
      "z": 3,
      "name": "Rock_Volcanic_Brick"
    },
    {
      "x": -4,
      "y": 54,
      "z": 3,
      "name": "Rock_Volcanic_Brick"
    },
    {
      "x": -4,
      "y": 55,
      "z": 3,
      "name": "Rock_Volcanic_Cobble"
    },
    {
      "x": -4,
      "y": 56,
      "z": 3,
      "name": "Rock_Volcanic_Cobble"
    },
    {
      "x": -4,
      "y": 57,
      "z": 3,
      "name": "Rock_Volcanic_Brick"
    },
    {
      "x": -4,
      "y": 58,
      "z": 3,
      "name": "Rock_Volcanic_Brick"
    },
    {
      "x": -4,
      "y": 59,
      "z": 3,
      "name": "Rock_Volcanic_Cobble"
    },
    {
      "x": -4,
      "y": 60,
      "z": 3,
      "name": "Rock_Volcanic_Cobble"
    },
    {
      "x": -4,
      "y": 61,
      "z": 3,
      "name": "Rock_Volcanic_Brick"
    },
    {
      "x": -4,
      "y": 62,
      "z": 3,
      "name": "Rock_Volcanic_Brick"
    },
    {
      "x": -4,
      "y": 63,
      "z": 3,
      "name": "Rock_Volcanic_Cobble"
    },
    {
      "x": -4,
      "y": 64,
      "z": 3,
      "name": "Rock_Volcanic_Brick"
    },
    {
      "x": -4,
      "y": 65,
      "z": 3,
      "name": "Rock_Volcanic_Brick"
    },
    {
      "x": -4,
      "y": 66,
      "z": 3,
      "name": "Rock_Volcanic_Cobble"
    },
    {
      "x": -4,
      "y": 67,
      "z": 3,
      "name": "Rock_Volcanic_Brick_Beam"
    },
    {
      "x": -4,
      "y": 68,
      "z": 3,
      "name": "Wood_Deadwood_Beam"
    },
    {
      "x": -4,
      "y": 69,
      "z": 3,
      "name": "Wood_Deadwood_Beam"
    },
    {
      "x": -4,
      "y": 70,
      "z": 3,
      "name": "Wood_Deadwood_Beam"
    },
    {
      "x": -4,
      "y": 21,
      "z": 4,
      "name": "Rock_Volcanic_Cobble"
    },
    {
      "x": -4,
      "y": 22,
      "z": 4,
      "name": "Rock_Volcanic_Cobble"
    },
    {
      "x": -4,
      "y": 23,
      "z": 4,
      "name": "Rock_Volcanic_Brick"
    },
    {
      "x": -4,
      "y": 24,
      "z": 4,
      "name": "Rock_Volcanic_Cobble"
    },
    {
      "x": -4,
      "y": 25,
      "z": 4,
      "name": "Rock_Volcanic_Brick"
    },
    {
      "x": -4,
      "y": 26,
      "z": 4,
      "name": "Rock_Volcanic_Brick"
    },
    {
      "x": -4,
      "y": 27,
      "z": 4,
      "name": "Rock_Volcanic_Cobble"
    },
    {
      "x": -4,
      "y": 28,
      "z": 4,
      "name": "Rock_Volcanic_Brick"
    },
    {
      "x": -4,
      "y": 29,
      "z": 4,
      "name": "Rock_Volcanic_Brick"
    },
    {
      "x": -4,
      "y": 30,
      "z": 4,
      "name": "Rock_Volcanic_Brick"
    },
    {
      "x": -4,
      "y": 31,
      "z": 4,
      "name": "Rock_Volcanic_Cobble"
    },
    {
      "x": -4,
      "y": 32,
      "z": 4,
      "name": "Rock_Volcanic_Cobble"
    },
    {
      "x": -4,
      "y": 33,
      "z": 4,
      "name": "Rock_Volcanic_Brick"
    },
    {
      "x": -4,
      "y": 34,
      "z": 4,
      "name": "Rock_Volcanic_Brick"
    },
    {
      "x": -4,
      "y": 35,
      "z": 4,
      "name": "Rock_Volcanic_Brick"
    },
    {
      "x": -4,
      "y": 36,
      "z": 4,
      "name": "Rock_Volcanic_Brick"
    },
    {
      "x": -4,
      "y": 37,
      "z": 4,
