{
  "version": 8,
  "blockIdVersion": 11,
  "anchorX": 0,
  "anchorY": -10,
  "anchorZ": 0,
  "blocks": [
    {
      "x": -12,
      "y": 56,
      "z": -1,
      "name": "Rock_Volcanic_Brick_Stairs",
      "rotation": 9
    },
    {
      "x": -12,
      "y": 57,
      "z": -1,
      "name": "Rock_Volcanic_Brick_Stairs",
      "rotation": 3
    },
    {
      "x": -11,
      "y": 55,
      "z": -1,
      "name": "Rock_Volcanic_Brick",
      "rotation": 3
    },
    {
      "x": -11,
      "y": 56,
      "z": -1,
      "name": "Rock_Volcanic_Brick",
      "rotation": 3
    },
    {
      "x": -11,
      "y": 57,
      "z": -1,
      "name": "Rock_Volcanic_Brick",
      "rotation": 3
    },
    {
      "x": -10,
      "y": 56,
      "z": -4,
      "name": "Rock_Volcanic_Brick_Half",
      "rotation": 8
    },
    {
      "x": -10,
      "y": 57,
      "z": -4,
      "name": "*Rock_Volcanic_Brick_Wall_State_Definitions_Corner",
      "rotation": 1
    },
    {
      "x": -10,
      "y": 56,
      "z": -3,
      "name": "Rock_Volcanic_Brick_Half",
      "rotation": 8
    },
    {
      "x": -10,
      "y": 57,
      "z": -3,
      "name": "Rock_Volcanic_Brick_Wall",
      "rotation": 3
    },
    {
      "x": -10,
      "y": 56,
      "z": -2,
      "name": "Rock_Volcanic_Brick_Half",
      "rotation": 8
    },
    {
      "x": -10,
      "y": 57,
      "z": -2,
      "name": "Rock_Volcanic_Brick_Wall",
      "rotation": 3
    },
    {
      "x": -10,
      "y": 54,
      "z": -1,
      "name": "Rock_Volcanic_Brick",
      "rotation": 3
    },
    {
      "x": -10,
      "y": 55,
      "z": -1,
      "name": "Rock_Volcanic_Brick",
      "rotation": 3
    },
    {
      "x": -10,
      "y": 56,
      "z": -1,
      "name": "Rock_Volcanic_Brick",
      "rotation": 3
    },
    {
      "x": -10,
      "y": 57,
      "z": -1,
      "name": "Rock_Volcanic_Brick",
      "rotation": 3
    },
    {
      "x": -10,
      "y": 58,
      "z": -1,
      "name": "Rock_Volcanic_Brick",
      "rotation": 3
    },
    {
      "x": -10,
      "y": 56,
      "z": 0,
      "name": "Rock_Volcanic_Brick_Half",
      "rotation": 9
    },
    {
      "x": -10,
      "y": 57,
      "z": 0,
      "name": "Rock_Volcanic_Brick_Wall",
      "rotation": 3
    },
    {
      "x": -10,
      "y": 56,
      "z": 1,
      "name": "Rock_Volcanic_Brick_Half",
      "rotation": 9
    },
    {
      "x": -10,
      "y": 57,
      "z": 1,
      "name": "Rock_Volcanic_Brick_Wall",
      "rotation": 3
    },
    {
      "x": -10,
      "y": 56,
      "z": 2,
      "name": "Rock_Volcanic_Brick_Half",
      "rotation": 9
    },
    {
      "x": -10,
      "y": 57,
      "z": 2,
      "name": "*Rock_Volcanic_Brick_Wall_State_Definitions_Corner",
      "rotation": 2
    },
    {
      "x": -9,
      "y": 56,
      "z": -6,
      "name": "Rock_Volcanic_Brick_Half",
      "rotation": 8
    },
    {
      "x": -9,
      "y": 57,
      "z": -6,
      "name": "*Rock_Volcanic_Brick_Wall_State_Definitions_Corner",
      "rotation": 1
    },
    {
      "x": -9,
      "y": 56,
      "z": -5,
      "name": "Rock_Volcanic_Brick_Half",
      "rotation": 8
    },
    {
      "x": -9,
      "y": 57,
      "z": -5,
      "name": "Rock_Volcanic_Brick_Wall",
      "rotation": 3
    },
    {
      "x": -9,
      "y": 56,
      "z": -4,
      "name": "Rock_Volcanic_Brick_Half",
      "rotation": 8
    },
    {
      "x": -9,
      "y": 57,
      "z": -4,
      "name": "*Rock_Volcanic_Brick_Wall_State_Definitions_Corner",
      "rotation": 3
    },
    {
      "x": -9,
      "y": 51,
      "z": -1,
      "name": "Rock_Volcanic_Brick_Half",
      "rotation": 7
    },
    {
      "x": -9,
      "y": 52,
      "z": -1,
      "name": "Rock_Volcanic_Brick_Half",
      "rotation": 7
    },
    {
      "x": -9,
      "y": 53,
      "z": -1,
      "name": "Rock_Volcanic_Brick",
      "rotation": 3
    },
    {
      "x": -9,
      "y": 54,
      "z": -1,
      "name": "Rock_Volcanic_Brick",
      "rotation": 3
    },
    {
      "x": -9,
      "y": 55,
      "z": -1,
      "name": "Rock_Volcanic_Brick",
      "rotation": 3
    },
    {
      "x": -9,
      "y": 57,
      "z": -1,
      "name": "Rock_Volcanic_Brick",
      "rotation": 3
    },
    {
      "x": -9,
      "y": 58,
      "z": -1,
      "name": "Rock_Volcanic_Brick",
      "rotation": 3
    },
    {
      "x": -9,
      "y": 59,
      "z": -1,
      "name": "Rock_Volcanic_Brick",
      "rotation": 3
    },
    {
      "x": -9,
      "y": 60,
      "z": -1,
      "name": "Rock_Volcanic_Brick_Half",
      "rotation": 7
    },
    {
      "x": -9,
      "y": 61,
      "z": -1,
      "name": "Rock_Volcanic_Brick_Half",
      "rotation": 7
    },
    {
      "x": -9,
      "y": 56,
      "z": 2,
      "name": "Rock_Volcanic_Brick_Half",
      "rotation": 9
    },
    {
      "x": -9,
      "y": 57,
      "z": 2,
      "name": "*Rock_Volcanic_Brick_Wall_State_Definitions_Corner"
    },
    {
      "x": -9,
      "y": 56,
      "z": 3,
      "name": "Rock_Volcanic_Brick_Half",
      "rotation": 9
    },
    {
      "x": -9,
      "y": 57,
      "z": 3,
      "name": "Rock_Volcanic_Brick_Wall",
      "rotation": 3
    },
    {
      "x": -9,
      "y": 56,
      "z": 4,
      "name": "Rock_Volcanic_Brick_Half",
      "rotation": 9
    },
    {
      "x": -9,
      "y": 57,
      "z": 4,
      "name": "*Rock_Volcanic_Brick_Wall_State_Definitions_Corner",
      "rotation": 2
    },
    {
      "x": -8,
      "y": 56,
      "z": -8,
      "name": "Rock_Volcanic_Brick_Half",
      "rotation": 8
    },
    {
      "x": -8,
      "y": 57,
      "z": -8,
      "name": "Rock_Volcanic_Brick_Wall",
      "rotation": 3
    },
    {
      "x": -8,
      "y": 56,
      "z": -7,
      "name": "Rock_Volcanic_Brick_Half",
      "rotation": 8
    },
    {
      "x": -8,
      "y": 57,
      "z": -7,
      "name": "Rock_Volcanic_Brick_Wall",
      "rotation": 3
    },
    {
      "x": -8,
      "y": 56,
      "z": -6,
      "name": "Rock_Volcanic_Brick_Half",
      "rotation": 8
    },
    {
      "x": -8,
      "y": 57,
      "z": -6,
      "name": "*Rock_Volcanic_Brick_Wall_State_Definitions_Corner",
      "rotation": 3
    },
    {
      "x": -8,
      "y": 47,
      "z": -1,
      "name": "Rock_Volcanic_Brick_Half",
      "rotation": 7
    },
    {
      "x": -8,
      "y": 48,
      "z": -1,
      "name": "Rock_Volcanic_Brick_Half",
      "rotation": 7
    },
    {
      "x": -8,
      "y": 49,
      "z": -1,
      "name": "Rock_Volcanic_Brick",
      "rotation": 3
    },
    {
      "x": -8,
      "y": 50,
      "z": -1,
      "name": "Rock_Volcanic_Brick",
      "rotation": 3
    },
    {
      "x": -8,
      "y": 51,
      "z": -1,
      "name": "Rock_Volcanic_Brick",
      "rotation": 3
    },
    {
      "x": -8,
      "y": 52,
      "z": -1,
      "name": "Rock_Volcanic_Brick",
      "rotation": 3
    },
    {
      "x": -8,
      "y": 53,
      "z": -1,
      "name": "Rock_Volcanic_Brick",
      "rotation": 3
    },
    {
      "x": -8,
      "y": 54,
      "z": -1,
      "name": "Rock_Volcanic_Brick_Stairs",
      "rotation": 1
    },
    {
      "x": -8,
      "y": 58,
      "z": -1,
      "name": "Rock_Volcanic_Brick_Stairs",
      "rotation": 11
    },
    {
      "x": -8,
      "y": 59,
      "z": -1,
      "name": "Rock_Volcanic_Brick",
      "rotation": 3
    },
    {
      "x": -8,
      "y": 60,
      "z": -1,
      "name": "Rock_Volcanic_Brick",
      "rotation": 3
    },
    {
      "x": -8,
      "y": 61,
      "z": -1,
      "name": "Rock_Volcanic_Brick",
      "rotation": 3
    },
    {
      "x": -8,
      "y": 62,
      "z": -1,
      "name": "Rock_Volcanic_Brick",
      "rotation": 3
    },
    {
      "x": -8,
      "y": 63,
      "z": -1,
      "name": "Rock_Volcanic_Brick",
      "rotation": 3
    },
    {
      "x": -8,
      "y": 56,
      "z": 4,
      "name": "Rock_Volcanic_Brick_Half",
      "rotation": 9
    },
    {
      "x": -8,
      "y": 57,
      "z": 4,
      "name": "*Rock_Volcanic_Brick_Wall_State_Definitions_Corner"
    },
    {
      "x": -8,
      "y": 56,
      "z": 5,
      "name": "Rock_Volcanic_Brick_Half",
      "rotation": 9
    },
    {
      "x": -8,
      "y": 57,
      "z": 5,
      "name": "Rock_Volcanic_Brick_Wall",
      "rotation": 3
    },
    {
      "x": -8,
      "y": 56,
      "z": 6,
      "name": "Rock_Volcanic_Brick_Half",
      "rotation": 9
    },
    {
      "x": -8,
      "y": 57,
      "z": 6,
      "name": "Rock_Volcanic_Brick_Wall",
      "rotation": 3
    },
    {
      "x": -7,
      "y": 56,
      "z": -9,
      "name": "Rock_Volcanic_Brick_Half",
      "rotation": 8
    },
    {
      "x": -7,
      "y": 57,
      "z": -9,
      "name": "Rock_Volcanic_Brick_Wall",
      "rotation": 2
    },
    {
      "x": -7,
      "y": 47,
      "z": -8,
      "name": "Wood_Deadwood_Beam"
    },
    {
      "x": -7,
      "y": 48,
      "z": -8,
      "name": "Wood_Deadwood_Beam"
    },
    {
      "x": -7,
      "y": 49,
      "z": -8,
      "name": "Wood_Deadwood_Beam"
    },
    {
      "x": -7,
      "y": 50,
      "z": -8,
      "name": "Rock_Volcanic_Brick_Beam"
    },
    {
      "x": -7,
      "y": 51,
      "z": -8,
      "name": "Rock_Volcanic_Brick_Beam"
    },
    {
      "x": -7,
      "y": 52,
      "z": -8,
      "name": "Rock_Volcanic_Brick_Beam"
    },
    {
      "x": -7,
      "y": 53,
      "z": -8,
      "name": "Rock_Volcanic_Brick_Pillar_Middle"
    },
    {
      "x": -7,
      "y": 54,
      "z": -8,
      "name": "Rock_Volcanic_Brick_Pillar_Middle"
    },
    {
      "x": -7,
      "y": 55,
      "z": -8,
      "name": "Rock_Volcanic_Brick"
    },
    {
      "x": -7,
      "y": 56,
      "z": -8,
      "name": "Rock_Volcanic_Brick"
    },
    {
      "x": -7,
      "y": 57,
      "z": -8,
      "name": "Rock_Volcanic_Brick"
    },
    {
      "x": -7,
      "y": 58,
      "z": -8,
      "name": "Rock_Volcanic_Brick_Pillar_Middle"
    },
    {
      "x": -7,
      "y": 59,
      "z": -8,
      "name": "Rock_Volcanic_Brick_Pillar_Middle"
    },
    {
      "x": -7,
      "y": 60,
      "z": -8,
      "name": "Rock_Volcanic_Brick_Beam"
    },
    {
      "x": -7,
      "y": 61,
      "z": -8,
      "name": "Rock_Volcanic_Brick_Beam"
    },
    {
      "x": -7,
      "y": 62,
      "z": -8,
      "name": "Rock_Volcanic_Brick_Beam"
    },
    {
      "x": -7,
      "y": 63,
      "z": -8,
      "name": "Wood_Deadwood_Beam"
    },
    {
      "x": -7,
      "y": 64,
      "z": -8,
      "name": "Wood_Deadwood_Beam"
    },
    {
      "x": -7,
      "y": 65,
      "z": -8,
      "name": "Wood_Deadwood_Beam"
    },
    {
      "x": -7,
      "y": 41,
      "z": -1,
      "name": "Rock_Volcanic_Brick_Half",
      "rotation": 7
    },
    {
      "x": -7,
      "y": 42,
      "z": -1,
      "name": "Rock_Volcanic_Brick_Half",
      "rotation": 7
    },
    {
      "x": -7,
      "y": 43,
      "z": -1,
      "name": "Rock_Volcanic_Brick_Half",
      "rotation": 7
    },
    {
      "x": -7,
      "y": 44,
      "z": -1,
      "name": "Rock_Volcanic_Brick_Stairs",
      "rotation": 9
    },
    {
      "x": -7,
      "y": 45,
      "z": -1,
      "name": "Rock_Volcanic_Brick",
      "rotation": 3
    },
    {
      "x": -7,
      "y": 46,
      "z": -1,
      "name": "Rock_Volcanic_Brick",
      "rotation": 3
    },
    {
      "x": -7,
      "y": 47,
      "z": -1,
      "name": "Rock_Volcanic_Brick",
      "rotation": 3
    },
    {
      "x": -7,
      "y": 48,
      "z": -1,
      "name": "Rock_Volcanic_Brick",
      "rotation": 3
    },
    {
      "x": -7,
      "y": 49,
      "z": -1,
      "name": "Rock_Volcanic_Brick",
      "rotation": 3
    },
    {
      "x": -7,
      "y": 50,
      "z": -1,
      "name": "Rock_Volcanic_Brick_Stairs",
      "rotation": 1
    },
    {
      "x": -7,
      "y": 62,
      "z": -1,
      "name": "Rock_Volcanic_Brick_Stairs",
      "rotation": 11
    },
    {
      "x": -7,
      "y": 63,
      "z": -1,
      "name": "Rock_Volcanic_Brick",
      "rotation": 3
    },
    {
      "x": -7,
      "y": 64,
      "z": -1,
      "name": "Rock_Volcanic_Brick",
      "rotation": 3
    },
    {
      "x": -7,
      "y": 65,
      "z": -1,
      "name": "Rock_Volcanic_Brick",
      "rotation": 3
    },
    {
      "x": -7,
      "y": 66,
      "z": -1,
      "name": "Rock_Volcanic_Brick",
      "rotation": 3
    },
    {
      "x": -7,
      "y": 67,
      "z": -1,
      "name": "Rock_Volcanic_Brick",
      "rotation": 3
    },
    {
      "x": -7,
      "y": 68,
      "z": -1,
      "name": "Rock_Volcanic_Brick_Stairs",
      "rotation": 3
    },
    {
      "x": -7,
      "y": 69,
      "z": -1,
      "name": "Rock_Volcanic_Brick_Half",
      "rotation": 7
    },
    {
      "x": -7,
      "y": 70,
      "z": -1,
      "name": "Rock_Volcanic_Brick_Half",
      "rotation": 7
    },
    {
      "x": -7,
      "y": 71,
      "z": -1,
      "name": "Rock_Volcanic_Brick_Half",
      "rotation": 7
    },
    {
      "x": -7,
      "y": 47,
      "z": 6,
      "name": "Wood_Deadwood_Beam",
      "rotation": 1
    },
    {
      "x": -7,
      "y": 48,
      "z": 6,
      "name": "Wood_Deadwood_Beam",
      "rotation": 1
    },
    {
      "x": -7,
      "y": 49,
      "z": 6,
      "name": "Wood_Deadwood_Beam",
      "rotation": 1
    },
    {
      "x": -7,
      "y": 50,
      "z": 6,
      "name": "Rock_Volcanic_Brick_Beam",
      "rotation": 1
    },
    {
      "x": -7,
      "y": 51,
      "z": 6,
      "name": "Rock_Volcanic_Brick_Beam",
      "rotation": 1
    },
    {
      "x": -7,
      "y": 52,
      "z": 6,
      "name": "Rock_Volcanic_Brick_Beam",
      "rotation": 1
    },
    {
      "x": -7,
      "y": 53,
      "z": 6,
      "name": "Rock_Volcanic_Brick_Pillar_Middle",
      "rotation": 1
    },
    {
      "x": -7,
      "y": 54,
      "z": 6,
      "name": "Rock_Volcanic_Brick_Pillar_Middle",
      "rotation": 1
    },
    {
      "x": -7,
      "y": 55,
      "z": 6,
      "name": "Rock_Volcanic_Brick",
      "rotation": 1
    },
    {
      "x": -7,
      "y": 56,
      "z": 6,
      "name": "Rock_Volcanic_Brick",
      "rotation": 1
    },
    {
      "x": -7,
      "y": 57,
      "z": 6,
      "name": "Rock_Volcanic_Brick",
      "rotation": 1
    },
    {
      "x": -7,
      "y": 58,
      "z": 6,
      "name": "Rock_Volcanic_Brick_Pillar_Middle",
      "rotation": 1
    },
    {
      "x": -7,
      "y": 59,
      "z": 6,
      "name": "Rock_Volcanic_Brick_Pillar_Middle",
      "rotation": 1
    },
    {
      "x": -7,
      "y": 60,
      "z": 6,
      "name": "Rock_Volcanic_Brick_Beam",
      "rotation": 1
    },
    {
      "x": -7,
      "y": 61,
      "z": 6,
      "name": "Rock_Volcanic_Brick_Beam",
      "rotation": 1
    },
    {
      "x": -7,
      "y": 62,
      "z": 6,
      "name": "Rock_Volcanic_Brick_Beam",
      "rotation": 1
    },
    {
      "x": -7,
      "y": 63,
      "z": 6,
      "name": "Wood_Deadwood_Beam",
      "rotation": 1
    },
    {
      "x": -7,
      "y": 64,
      "z": 6,
      "name": "Wood_Deadwood_Beam",
      "rotation": 1
    },
    {
      "x": -7,
      "y": 65,
      "z": 6,
      "name": "Wood_Deadwood_Beam",
      "rotation": 1
    },
    {
      "x": -7,
      "y": 56,
      "z": 7,
      "name": "Rock_Volcanic_Brick_Half",
      "rotation": 9
    },
    {
      "x": -7,
      "y": 57,
      "z": 7,
      "name": "Rock_Volcanic_Brick_Wall"
    },
    {
      "x": -6,
      "y": 56,
      "z": -9,
      "name": "Rock_Volcanic_Brick_Half",
      "rotation": 8
    },
    {
      "x": -6,
      "y": 57,
      "z": -9,
      "name": "Rock_Volcanic_Brick_Wall",
      "rotation": 2
    },
    {
      "x": -6,
      "y": 35,
      "z": -3,
      "name": "Rock_Aqua_Cobble_Half",
      "rotation": 7
    },
    {
      "x": -6,
      "y": 35,
      "z": -2,
      "name": "Rock_Aqua_Cobble_Half",
      "rotation": 7
    },
    {
      "x": -6,
      "y": 33,
      "z": -1,
      "name": "Rock_Volcanic_Brick_Half",
      "rotation": 7
    },
    {
      "x": -6,
      "y": 34,
      "z": -1,
      "name": "Rock_Volcanic_Brick_Half",
      "rotation": 7
    },
    {
      "x": -6,
      "y": 35,
      "z": -1,
      "name": "Rock_Volcanic_Brick_Half",
      "rotation": 7
    },
    {
      "x": -6,
      "y": 36,
      "z": -1,
      "name": "Rock_Volcanic_Brick",
      "rotation": 3
    },
    {
      "x": -6,
      "y": 37,
      "z": -1,
      "name": "Rock_Volcanic_Brick",
      "rotation": 3
    },
    {
      "x": -6,
      "y": 38,
      "z": -1,
      "name": "Rock_Volcanic_Brick",
      "rotation": 3
    },
    {
      "x": -6,
      "y": 39,
      "z": -1,
      "name": "Rock_Volcanic_Brick",
      "rotation": 3
    },
    {
      "x": -6,
      "y": 40,
      "z": -1,
      "name": "Rock_Volcanic_Brick",
      "rotation": 3
    },
    {
      "x": -6,
      "y": 41,
      "z": -1,
      "name": "Rock_Volcanic_Brick",
      "rotation": 3
    },
    {
      "x": -6,
      "y": 42,
      "z": -1,
      "name": "Rock_Volcanic_Brick",
      "rotation": 3
    },
    {
      "x": -6,
      "y": 43,
      "z": -1,
      "name": "Rock_Volcanic_Brick",
      "rotation": 3
    },
    {
      "x": -6,
      "y": 44,
      "z": -1,
      "name": "Rock_Volcanic_Brick",
      "rotation": 3
    },
    {
      "x": -6,
      "y": 45,
      "z": -1,
      "name": "Rock_Volcanic_Brick",
      "rotation": 3
    },
    {
      "x": -6,
      "y": 46,
      "z": -1,
      "name": "Rock_Volcanic_Brick",
      "rotation": 3
    },
    {
      "x": -6,
      "y": 47,
      "z": -1,
      "name": "Rock_Volcanic_Brick",
      "rotation": 3
    },
    {
      "x": -6,
      "y": 48,
      "z": -1,
      "name": "Rock_Volcanic_Brick_Stairs",
      "rotation": 1
    },
    {
      "x": -6,
      "y": 64,
      "z": -1,
      "name": "Rock_Volcanic_Brick_Stairs",
      "rotation": 11
    },
    {
      "x": -6,
      "y": 65,
      "z": -1,
      "name": "Rock_Volcanic_Brick",
      "rotation": 3
    },
    {
      "x": -6,
      "y": 66,
      "z": -1,
      "name": "Rock_Volcanic_Brick",
      "rotation": 3
    },
    {
      "x": -6,
      "y": 67,
      "z": -1,
      "name": "Rock_Volcanic_Brick",
      "rotation": 3
    },
    {
      "x": -6,
      "y": 68,
      "z": -1,
      "name": "Rock_Volcanic_Brick",
      "rotation": 3
    },
    {
      "x": -6,
      "y": 69,
      "z": -1,
      "name": "Rock_Volcanic_Brick",
      "rotation": 3
    },
    {
      "x": -6,
      "y": 70,
      "z": -1,
      "name": "Rock_Volcanic_Brick",
      "rotation": 3
    },
    {
      "x": -6,
      "y": 71,
      "z": -1,
      "name": "Rock_Volcanic_Brick",
      "rotation": 3
    },
    {
      "x": -6,
      "y": 72,
      "z": -1,
      "name": "Rock_Volcanic_Brick",
      "rotation": 3
    },
    {
      "x": -6,
      "y": 73,
      "z": -1,
      "name": "Rock_Volcanic_Brick",
      "rotation": 3
    },
    {
      "x": -6,
      "y": 74,
      "z": -1,
      "name": "Rock_Volcanic_Brick",
      "rotation": 3
    },
    {
      "x": -6,
      "y": 75,
      "z": -1,
      "name": "Rock_Volcanic_Brick",
      "rotation": 3
    },
    {
      "x": -6,
      "y": 76,
      "z": -1,
      "name": "Rock_Volcanic_Brick",
      "rotation": 3
    },
    {
      "x": -6,
      "y": 77,
      "z": -1,
      "name": "Rock_Volcanic_Brick_Half",
      "rotation": 7
    },
    {
      "x": -6,
      "y": 78,
      "z": -1,
      "name": "Rock_Volcanic_Brick_Half",
      "rotation": 7
    },
    {
      "x": -6,
      "y": 79,
      "z": -1,
      "name": "Rock_Volcanic_Brick_Half",
      "rotation": 7
    },
    {
      "x": -6,
      "y": 35,
      "z": 0,
      "name": "Rock_Aqua_Cobble_Half",
      "rotation": 7
    },
    {
      "x": -6,
      "y": 35,
      "z": 1,
      "name": "Rock_Aqua_Cobble_Half",
      "rotation": 7
    },
    {
      "x": -6,
      "y": 56,
      "z": 7,
      "name": "Rock_Volcanic_Brick_Half",
      "rotation": 9
    },
    {
      "x": -6,
      "y": 57,
      "z": 7,
      "name": "Rock_Volcanic_Brick_Wall"
    },
    {
      "x": -5,
      "y": 56,
      "z": -10,
      "name": "Rock_Volcanic_Brick_Half",
      "rotation": 8
    },
    {
      "x": -5,
      "y": 57,
      "z": -10,
      "name": "*Rock_Volcanic_Brick_Wall_State_Definitions_Corner",
      "rotation": 1
    },
    {
      "x": -5,
      "y": 56,
      "z": -9,
      "name": "Rock_Volcanic_Brick_Half",
      "rotation": 8
    },
    {
      "x": -5,
      "y": 57,
      "z": -9,
      "name": "*Rock_Volcanic_Brick_Wall_State_Definitions_Corner",
      "rotation": 3
    },
    {
      "x": -5,
      "y": 35,
      "z": -5,
      "name": "Rock_Aqua_Cobble_Half",
      "rotation": 7
    },
    {
      "x": -5,
      "y": 35,
      "z": -4,
      "name": "Rock_Aqua_Cobble_Half",
      "rotation": 7
    },
    {
      "x": -5,
      "y": -25,
      "z": -3,
      "name": "Rock_Volcanic_Cobble"
    },
    {
      "x": -5,
      "y": -24,
      "z": -3,
      "name": "Rock_Volcanic_Brick"
    },
    {
      "x": -5,
      "y": -23,
      "z": -3,
      "name": "Rock_Volcanic_Cobble"
    },
    {
      "x": -5,
      "y": -22,
      "z": -3,
      "name": "Rock_Volcanic_Brick"
    },
    {
      "x": -5,
      "y": -21,
      "z": -3,
      "name": "Rock_Volcanic_Brick"
    },
    {
      "x": -5,
      "y": -20,
      "z": -3,
      "name": "Rock_Volcanic_Brick"
    },
    {
      "x": -5,
      "y": -19,
      "z": -3,
      "name": "Rock_Volcanic_Brick"
    },
    {
      "x": -5,
      "y": -18,
      "z": -3,
      "name": "Rock_Volcanic_Cobble"
    },
    {
      "x": -5,
      "y": -17,
      "z": -3,
      "name": "Rock_Volcanic_Brick"
    },
    {
      "x": -5,
      "y": -16,
      "z": -3,
      "name": "Rock_Volcanic_Cobble"
    },
    {
      "x": -5,
      "y": -15,
      "z": -3,
      "name": "Rock_Volcanic_Cobble"
    },
    {
      "x": -5,
      "y": -14,
      "z": -3,
      "name": "Rock_Volcanic_Brick"
    },
    {
      "x": -5,
      "y": -13,
      "z": -3,
      "name": "Rock_Volcanic_Brick"
    },
    {
      "x": -5,
      "y": -12,
      "z": -3,
      "name": "Rock_Volcanic_Cobble"
    },
    {
      "x": -5,
      "y": -11,
      "z": -3,
      "name": "Rock_Volcanic_Cobble"
    },
    {
      "x": -5,
      "y": -10,
      "z": -3,
      "name": "Rock_Volcanic_Cobble"
    },
    {
      "x": -5,
      "y": -9,
      "z": -3,
      "name": "Rock_Volcanic_Brick"
    },
    {
      "x": -5,
      "y": -8,
      "z": -3,
      "name": "Rock_Volcanic_Cobble"
    },
    {
      "x": -5,
      "y": -7,
      "z": -3,
      "name": "Rock_Volcanic_Brick"
    },
    {
      "x": -5,
      "y": -6,
      "z": -3,
      "name": "Rock_Volcanic_Cobble"
    },
    {
      "x": -5,
      "y": -5,
      "z": -3,
      "name": "Rock_Volcanic_Cobble"
    },
    {
      "x": -5,
      "y": -4,
      "z": -3,
      "name": "Rock_Volcanic_Brick"
    },
    {
      "x": -5,
      "y": -3,
      "z": -3,
      "name": "Rock_Volcanic_Cobble"
    },
    {
      "x": -5,
      "y": -2,
      "z": -3,
      "name": "Rock_Volcanic_Brick"
    },
    {
      "x": -5,
      "y": -1,
      "z": -3,
      "name": "Rock_Volcanic_Cobble"
    },
    {
      "x": -5,
      "y": 0,
      "z": -3,
      "name": "Rock_Volcanic_Brick"
    },
    {
      "x": -5,
      "y": 1,
      "z": -3,
      "name": "Rock_Volcanic_Cobble"
    },
    {
      "x": -5,
      "y": 2,
      "z": -3,
      "name": "Rock_Volcanic_Cobble"
    },
    {
      "x": -5,
      "y": 3,
      "z": -3,
      "name": "Rock_Volcanic_Brick"
    },
    {
      "x": -5,
      "y": 4,
      "z": -3,
      "name": "Rock_Volcanic_Cobble"
    },
    {
      "x": -5,
      "y": 5,
      "z": -3,
      "name": "Rock_Volcanic_Cobble"
    },
    {
      "x": -5,
      "y": 6,
      "z": -3,
      "name": "Rock_Volcanic_Cobble"
    },
    {
      "x": -5,
      "y": 7,
      "z": -3,
      "name": "Rock_Volcanic_Brick"
    },
    {
      "x": -5,
      "y": 8,
      "z": -3,
      "name": "Rock_Volcanic_Brick"
    },
    {
      "x": -5,
      "y": 9,
      "z": -3,
      "name": "Rock_Volcanic_Cobble"
    },
    {
      "x": -5,
      "y": 10,
      "z": -3,
      "name": "Rock_Volcanic_Cobble"
    },
    {
      "x": -5,
      "y": 11,
      "z": -3,
      "name": "Rock_Volcanic_Cobble"
    },
    {
      "x": -5,
      "y": 12,
      "z": -3,
      "name": "Rock_Volcanic_Cobble"
    },
    {
      "x": -5,
      "y": 13,
      "z": -3,
      "name": "Rock_Volcanic_Cobble"
    },
    {
      "x": -5,
      "y": 14,
      "z": -3,
      "name": "Rock_Volcanic_Cobble"
    },
    {
      "x": -5,
      "y": 15,
      "z": -3,
      "name": "Rock_Volcanic_Cobble"
    },
    {
      "x": -5,
      "y": 16,
      "z": -3,
      "name": "Rock_Volcanic_Cobble"
    },
    {
      "x": -5,
      "y": 17,
      "z": -3,
      "name": "Rock_Volcanic_Cobble"
    },
    {
      "x": -5,
      "y": 18,
      "z": -3,
      "name": "Rock_Volcanic_Cobble"
    },
    {
      "x": -5,
      "y": 19,
      "z": -3,
      "name": "Rock_Volcanic_Brick"
    },
    {
      "x": -5,
      "y": 20,
      "z": -3,
      "name": "Rock_Volcanic_Cobble"
    },
    {
      "x": -5,
      "y": 21,
      "z": -3,
      "name": "Rock_Volcanic_Cobble"
    },
    {
      "x": -5,
      "y": 22,
      "z": -3,
      "name": "Rock_Volcanic_Cobble"
    },
    {
      "x": -5,
      "y": 23,
      "z": -3,
      "name": "Rock_Volcanic_Cobble"
    },
    {
      "x": -5,
      "y": 24,
      "z": -3,
      "name": "Rock_Volcanic_Brick"
    },
    {
      "x": -5,
      "y": 25,
      "z": -3,
      "name": "Rock_Volcanic_Cobble"
    },
    {
      "x": -5,
      "y": 26,
      "z": -3,
      "name": "Rock_Volcanic_Cobble"
    },
    {
      "x": -5,
      "y": 27,
      "z": -3,
      "name": "Rock_Volcanic_Cobble"
    },
    {
      "x": -5,
      "y": 28,
      "z": -3,
      "name": "Rock_Volcanic_Cobble"
    },
    {
      "x": -5,
      "y": 29,
      "z": -3,
      "name": "Rock_Volcanic_Brick"
    },
    {
      "x": -5,
      "y": 30,
      "z": -3,
      "name": "Rock_Volcanic_Brick"
    },
    {
      "x": -5,
      "y": 31,
      "z": -3,
      "name": "Rock_Volcanic_Cobble"
    },
    {
      "x": -5,
      "y": 32,
      "z": -3,
      "name": "Rock_Volcanic_Brick"
    },
    {
      "x": -5,
      "y": 33,
      "z": -3,
      "name": "Rock_Volcanic_Cobble"
    },
    {
      "x": -5,
      "y": 34,
      "z": -3,
      "name": "Rock_Volcanic_Brick"
    },
    {
      "x": -5,
      "y": 35,
      "z": -3,
      "name": "Rock_Aqua_Cobble"
    },
    {
      "x": -5,
      "y": 36,
      "z": -3,
      "name": "Rock_Volcanic_Brick"
    },
    {
      "x": -5,
      "y": 37,
      "z": -3,
      "name": "Rock_Volcanic_Cobble"
    },
    {
      "x": -5,
      "y": 38,
      "z": -3,
      "name": "Rock_Volcanic_Cobble"
    },
    {
      "x": -5,
      "y": 39,
      "z": -3,
      "name": "Rock_Volcanic_Brick"
    },
    {
      "x": -5,
      "y": 40,
      "z": -3,
      "name": "Rock_Volcanic_Brick"
    },
    {
      "x": -5,
      "y": 41,
      "z": -3,
      "name": "Rock_Volcanic_Brick"
    },
    {
      "x": -5,
      "y": 42,
      "z": -3,
      "name": "Rock_Volcanic_Brick"
    },
    {
      "x": -5,
      "y": 43,
      "z": -3,
      "name": "Rock_Volcanic_Cobble"
    },
    {
      "x": -5,
      "y": 44,
      "z": -3,
      "name": "Rock_Volcanic_Brick"
    },
    {
      "x": -5,
      "y": 45,
      "z": -3,
      "name": "Rock_Volcanic_Brick"
    },
    {
      "x": -5,
      "y": 46,
      "z": -3,
      "name": "Rock_Volcanic_Brick"
    },
    {
      "x": -5,
      "y": 47,
      "z": -3,
      "name": "Rock_Volcanic_Cobble"
    },
    {
      "x": -5,
      "y": 48,
      "z": -3,
      "name": "Rock_Volcanic_Brick"
    },
    {
      "x": -5,
      "y": 49,
      "z": -3,
      "name": "Rock_Volcanic_Cobble"
    },
    {
      "x": -5,
      "y": 50,
      "z": -3,
      "name": "Rock_Volcanic_Brick"
    },
    {
      "x": -5,
      "y": 51,
      "z": -3,
      "name": "*Rock_Volcanic_Brick_Wall_State_Definitions_Corner",
      "rotation": 1
    },
    {
      "x": -5,
      "y": 56,
      "z": -3,
      "name": "Rock_Crystal_Green_Block"
    },
    {
      "x": -5,
      "y": 61,
      "z": -3,
      "name": "*Rock_Volcanic_Brick_Wall_State_Definitions_Corner",
      "rotation": 1
    },
    {
      "x": -5,
      "y": 62,
      "z": -3,
      "name": "Rock_Volcanic_Brick",
      "rotation": 1
    },
    {
      "x": -5,
      "y": 63,
      "z": -3,
      "name": "Rock_Volcanic_Brick",
      "rotation": 1
    },
    {
      "x": -5,
      "y": 64,
      "z": -3,
      "name": "Rock_Volcanic_Brick",
      "rotation": 1
    },
    {
      "x": -5,
      "y": 65,
      "z": -3,
      "name": "Rock_Volcanic_Brick",
      "rotation": 1
    },
    {
      "x": -5,
      "y": 66,
      "z": -3,
      "name": "Rock_Volcanic_Cobble",
      "rotation": 1
    },
    {
      "x": -5,
      "y": 67,
      "z": -3,
      "name": "*Rock_Volcanic_Brick_Wall_State_Definitions_Corner",
      "rotation": 1
    },
    {
      "x": -5,
      "y": -25,
      "z": -2,
      "name": "Rock_Volcanic_Cobble"
    },
    {
      "x": -5,
      "y": -24,
      "z": -2,
      "name": "Rock_Volcanic_Brick"
    },
    {
      "x": -5,
      "y": -23,
      "z": -2,
      "name": "Rock_Volcanic_Cobble"
    },
    {
      "x": -5,
      "y": -22,
      "z": -2,
      "name": "Rock_Volcanic_Brick"
    },
    {
      "x": -5,
      "y": -21,
      "z": -2,
      "name": "Rock_Volcanic_Cobble"
    },
    {
      "x": -5,
      "y": -20,
      "z": -2,
      "name": "Rock_Volcanic_Cobble"
    },
    {
      "x": -5,
      "y": -19,
      "z": -2,
      "name": "Rock_Volcanic_Brick"
    },
    {
      "x": -5,
      "y": -18,
      "z": -2,
      "name": "Rock_Volcanic_Brick"
    },
    {
      "x": -5,
      "y": -17,
      "z": -2,
      "name": "Rock_Volcanic_Cobble"
    },
    {
      "x": -5,
      "y": -16,
      "z": -2,
      "name": "Rock_Volcanic_Brick"
    },
    {
      "x": -5,
      "y": -15,
      "z": -2,
      "name": "Rock_Volcanic_Brick"
    },
    {
      "x": -5,
      "y": -14,
      "z": -2,
      "name": "Rock_Volcanic_Brick"
    },
    {
      "x": -5,
      "y": -13,
      "z": -2,
      "name": "Rock_Volcanic_Cobble"
    },
    {
      "x": -5,
      "y": -12,
      "z": -2,
      "name": "Rock_Volcanic_Brick"
    },
    {
      "x": -5,
      "y": -11,
      "z": -2,
      "name": "Rock_Volcanic_Brick"
    },
    {
      "x": -5,
      "y": -10,
      "z": -2,
      "name": "Rock_Volcanic_Brick"
    },
    {
      "x": -5,
      "y": -9,
      "z": -2,
      "name": "Rock_Volcanic_Brick"
    },
    {
      "x": -5,
      "y": -8,
      "z": -2,
      "name": "Rock_Volcanic_Cobble"
    },
    {
      "x": -5,
      "y": -7,
      "z": -2,
      "name": "Rock_Volcanic_Cobble"
    },
    {
      "x": -5,
      "y": -6,
      "z": -2,
      "name": "Rock_Volcanic_Brick"
    },
    {
      "x": -5,
      "y": -5,
      "z": -2,
      "name": "Rock_Volcanic_Cobble"
    },
    {
      "x": -5,
      "y": -4,
      "z": -2,
      "name": "Rock_Volcanic_Cobble"
    },
    {
      "x": -5,
      "y": -3,
      "z": -2,
      "name": "Rock_Volcanic_Cobble"
    },
    {
      "x": -5,
      "y": -2,
      "z": -2,
      "name": "Rock_Volcanic_Brick"
    },
    {
      "x": -5,
      "y": -1,
      "z": -2,
      "name": "Rock_Volcanic_Brick"
    },
    {
      "x": -5,
      "y": 0,
      "z": -2,
      "name": "Rock_Volcanic_Cobble"
    },
    {
      "x": -5,
      "y": 1,
      "z": -2,
      "name": "Rock_Volcanic_Cobble"
    },
    {
      "x": -5,
      "y": 2,
      "z": -2,
      "name": "Rock_Volcanic_Cobble"
    },
    {
      "x": -5,
      "y": 3,
      "z": -2,
      "name": "Rock_Volcanic_Brick"
    },
    {
      "x": -5,
      "y": 4,
      "z": -2,
      "name": "Rock_Volcanic_Cobble"
    },
    {
      "x": -5,
      "y": 5,
      "z": -2,
      "name": "Rock_Volcanic_Cobble"
    },
    {
      "x": -5,
      "y": 6,
      "z": -2,
      "name": "Rock_Volcanic_Cobble"
    },
    {
      "x": -5,
      "y": 7,
      "z": -2,
      "name": "Rock_Volcanic_Cobble"
    },
    {
      "x": -5,
      "y": 8,
      "z": -2,
      "name": "Rock_Volcanic_Cobble"
    },
    {
      "x": -5,
      "y": 9,
      "z": -2,
      "name": "Rock_Volcanic_Cobble"
    },
    {
      "x": -5,
      "y": 10,
      "z": -2,
      "name": "Rock_Volcanic_Cobble"
    },
    {
      "x": -5,
      "y": 11,
      "z": -2,
      "name": "Rock_Volcanic_Brick"
    },
    {
      "x": -5,
      "y": 12,
      "z": -2,
      "name": "Rock_Volcanic_Cobble"
    },
    {
      "x": -5,
      "y": 13,
      "z": -2,
      "name": "Rock_Volcanic_Cobble"
    },
    {
      "x": -5,
      "y": 14,
      "z": -2,
      "name": "Rock_Volcanic_Cobble"
    },
    {
      "x": -5,
      "y": 15,
      "z": -2,
      "name": "Rock_Volcanic_Cobble"
    },
    {
      "x": -5,
      "y": 16,
      "z": -2,
      "name": "Rock_Volcanic_Cobble"
    },
    {
      "x": -5,
      "y": 17,
      "z": -2,
      "name": "Rock_Volcanic_Brick"
    },
    {
      "x": -5,
      "y": 18,
      "z": -2,
      "name": "Rock_Volcanic_Brick"
    },
    {
      "x": -5,
      "y": 19,
      "z": -2,
      "name": "Rock_Volcanic_Cobble"
    },
    {
      "x": -5,
      "y": 20,
      "z": -2,
      "name": "Rock_Volcanic_Brick"
    },
    {
      "x": -5,
      "y": 21,
      "z": -2,
      "name": "Rock_Volcanic_Cobble"
    },
    {
      "x": -5,
      "y": 22,
      "z": -2,
      "name": "Rock_Volcanic_Brick"
    },
    {
      "x": -5,
      "y": 23,
      "z": -2,
      "name": "Rock_Volcanic_Cobble"
    },
    {
      "x": -5,
      "y": 24,
      "z": -2,
      "name": "Rock_Volcanic_Cobble"
    },
    {
      "x": -5,
      "y": 25,
      "z": -2,
      "name": "Rock_Volcanic_Cobble"
    },
    {
      "x": -5,
      "y": 26,
      "z": -2,
      "name": "Rock_Volcanic_Cobble"
    },
    {
      "x": -5,
      "y": 27,
      "z": -2,
      "name": "Rock_Volcanic_Brick"
    },
    {
      "x": -5,
      "y": 28,
      "z": -2,
      "name": "Rock_Volcanic_Cobble"
    },
    {
      "x": -5,
      "y": 29,
      "z": -2,
      "name": "Rock_Volcanic_Cobble"
    },
    {
      "x": -5,
      "y": 30,
      "z": -2,
      "name": "Rock_Volcanic_Cobble"
    },
    {
      "x": -5,
      "y": 31,
      "z": -2,
      "name": "Rock_Volcanic_Cobble"
    },
    {
      "x": -5,
      "y": 32,
      "z": -2,
      "name": "Rock_Volcanic_Cobble"
    },
    {
      "x": -5,
      "y": 33,
      "z": -2,
      "name": "Rock_Volcanic_Cobble"
    },
    {
      "x": -5,
      "y": 34,
      "z": -2,
      "name": "Rock_Volcanic_Cobble"
    },
    {
      "x": -5,
      "y": 35,
      "z": -2,
      "name": "Rock_Volcanic_Cobble"
    },
    {
      "x": -5,
      "y": 36,
      "z": -2,
      "name": "Rock_Volcanic_Brick"
    },
    {
      "x": -5,
      "y": 37,
      "z": -2,
      "name": "Rock_Volcanic_Brick"
    },
    {
      "x": -5,
      "y": 38,
      "z": -2,
      "name": "Rock_Volcanic_Brick"
    },
    {
      "x": -5,
      "y": 39,
      "z": -2,
      "name": "Rock_Volcanic_Cobble"
    },
    {
      "x": -5,
      "y": 40,
      "z": -2,
      "name": "Rock_Volcanic_Cobble"
    },
    {
      "x": -5,
      "y": 41,
      "z": -2,
      "name": "Rock_Volcanic_Brick"
    },
    {
      "x": -5,
      "y": 42,
      "z": -2,
      "name": "Rock_Volcanic_Cobble"
    },
    {
      "x": -5,
      "y": 43,
      "z": -2,
      "name": "Rock_Volcanic_Cobble"
    },
    {
      "x": -5,
      "y": 44,
      "z": -2,
      "name": "Rock_Volcanic_Cobble"
    },
    {
      "x": -5,
      "y": 45,
      "z": -2,
      "name": "Rock_Volcanic_Brick"
    },
    {
      "x": -5,
      "y": 46,
      "z": -2,
      "name": "Rock_Volcanic_Cobble"
    },
    {
      "x": -5,
      "y": 47,
      "z": -2,
      "name": "Rock_Volcanic_Brick"
    },
    {
      "x": -5,
      "y": 48,
      "z": -2,
      "name": "Rock_Volcanic_Cobble"
    },
    {
      "x": -5,
      "y": 49,
      "z": -2,
      "name": "Rock_Volcanic_Cobble"
    },
    {
      "x": -5,
      "y": 50,
      "z": -2,
      "name": "Rock_Volcanic_Brick"
    },
    {
      "x": -5,
      "y": 51,
      "z": -2,
      "name": "Rock_Volcanic_Brick_Wall",
      "rotation": 3
    },
    {
      "x": -5,
      "y": 55,
      "z": -2,
      "name": "Rock_Crystal_Green_Block"
    },
    {
      "x": -5,
      "y": 56,
      "z": -2,
      "name": "Rock_Crystal_Green_Block"
    },
    {
      "x": -5,
      "y": 57,
      "z": -2,
      "name": "Rock_Crystal_Green_Block"
    },
    {
      "x": -5,
      "y": 61,
      "z": -2,
      "name": "Rock_Volcanic_Brick_Wall",
      "rotation": 3
    },
    {
      "x": -5,
      "y": 62,
      "z": -2,
      "name": "Rock_Volcanic_Brick",
      "rotation": 1
    },
    {
      "x": -5,
      "y": 63,
      "z": -2,
      "name": "Rock_Volcanic_Brick",
      "rotation": 1
    },
    {
      "x": -5,
      "y": 64,
      "z": -2,
      "name": "Rock_Volcanic_Cobble",
      "rotation": 1
    },
    {
      "x": -5,
      "y": 65,
      "z": -2,
      "name": "Rock_Volcanic_Cobble",
      "rotation": 1
    },
    {
      "x": -5,
      "y": 66,
      "z": -2,
      "name": "Rock_Volcanic_Brick",
      "rotation": 1
    },
    {
      "x": -5,
      "y": 67,
      "z": -2,
      "name": "Rock_Volcanic_Brick_Wall",
      "rotation": 1
    },
    {
      "x": -5,
      "y": -25,
      "z": -1,
      "name": "Rock_Volcanic_Brick"
    },
    {
      "x": -5,
      "y": -24,
      "z": -1,
      "name": "Rock_Volcanic_Cobble"
    },
    {
      "x": -5,
      "y": -23,
      "z": -1,
      "name": "Rock_Volcanic_Cobble"
    },
    {
      "x": -5,
      "y": -22,
      "z": -1,
      "name": "Rock_Volcanic_Brick"
    },
    {
      "x": -5,
      "y": -21,
      "z": -1,
      "name": "Rock_Volcanic_Brick"
    },
    {
      "x": -5,
      "y": -20,
      "z": -1,
      "name": "Rock_Volcanic_Brick"
    },
    {
      "x": -5,
      "y": -19,
      "z": -1,
      "name": "Rock_Volcanic_Brick"
    },
    {
      "x": -5,
      "y": -18,
      "z": -1,
      "name": "Rock_Volcanic_Brick"
    },
    {
      "x": -5,
      "y": -17,
      "z": -1,
      "name": "Rock_Volcanic_Brick"
    },
    {
      "x": -5,
      "y": -16,
      "z": -1,
      "name": "Rock_Volcanic_Cobble"
    },
    {
      "x": -5,
      "y": -15,
      "z": -1,
      "name": "Rock_Volcanic_Cobble"
    },
    {
      "x": -5,
      "y": -14,
      "z": -1,
      "name": "Rock_Volcanic_Cobble"
    },
    {
      "x": -5,
      "y": -13,
      "z": -1,
      "name": "Rock_Volcanic_Cobble"
    },
    {
      "x": -5,
      "y": -12,
      "z": -1,
      "name": "Rock_Volcanic_Brick"
    },
    {
      "x": -5,
      "y": -11,
      "z": -1,
      "name": "Rock_Volcanic_Brick"
    },
    {
      "x": -5,
      "y": -10,
      "z": -1,
      "name": "Rock_Volcanic_Brick"
    },
    {
      "x": -5,
      "y": -9,
      "z": -1,
      "name": "Rock_Volcanic_Brick"
    },
    {
      "x": -5,
      "y": -8,
      "z": -1,
      "name": "Rock_Volcanic_Cobble"
    },
    {
      "x": -5,
      "y": -7,
      "z": -1,
      "name": "Rock_Volcanic_Cobble"
    },
    {
      "x": -5,
      "y": -6,
      "z": -1,
      "name": "Rock_Volcanic_Brick"
    },
    {
      "x": -5,
      "y": -5,
      "z": -1,
      "name": "Rock_Volcanic_Brick"
    },
    {
      "x": -5,
      "y": -4,
      "z": -1,
      "name": "Rock_Volcanic_Cobble"
    },
    {
      "x": -5,
      "y": -3,
      "z": -1,
      "name": "Rock_Volcanic_Brick"
    },
    {
      "x": -5,
      "y": -2,
      "z": -1,
      "name": "Rock_Volcanic_Cobble"
    },
    {
      "x": -5,
      "y": -1,
      "z": -1,
      "name": "Rock_Volcanic_Brick"
    },
    {
      "x": -5,
      "y": 0,
      "z": -1,
      "name": "Rock_Volcanic_Cobble"
    },
    {
      "x": -5,
      "y": 1,
      "z": -1,
      "name": "Rock_Volcanic_Brick"
    },
    {
      "x": -5,
      "y": 2,
      "z": -1,
      "name": "Rock_Volcanic_Cobble"
    },
    {
      "x": -5,
      "y": 3,
      "z": -1,
      "name": "Rock_Volcanic_Cobble"
    },
    {
      "x": -5,
      "y": 4,
      "z": -1,
      "name": "Rock_Volcanic_Brick"
    },
    {
      "x": -5,
      "y": 5,
      "z": -1,
      "name": "Rock_Volcanic_Cobble"
    },
    {
      "x": -5,
      "y": 6,
      "z": -1,
      "name": "Rock_Volcanic_Cobble"
    },
    {
      "x": -5,
      "y": 7,
      "z": -1,
      "name": "Rock_Volcanic_Brick"
    },
    {
      "x": -5,
      "y": 8,
      "z": -1,
      "name": "Rock_Volcanic_Brick"
    },
    {
      "x": -5,
      "y": 9,
      "z": -1,
      "name": "Rock_Volcanic_Brick"
    },
    {
      "x": -5,
      "y": 10,
      "z": -1,
      "name": "Rock_Volcanic_Brick"
    },
    {
      "x": -5,
      "y": 11,
      "z": -1,
      "name": "Rock_Volcanic_Cobble"
    },
    {
      "x": -5,
      "y": 12,
      "z": -1,
      "name": "Rock_Volcanic_Cobble"
    },
    {
      "x": -5,
      "y": 13,
      "z": -1,
      "name": "Rock_Volcanic_Brick"
    },
    {
      "x": -5,
      "y": 14,
      "z": -1,
      "name": "Rock_Volcanic_Brick"
    },
    {
      "x": -5,
      "y": 15,
      "z": -1,
      "name": "Rock_Volcanic_Cobble"
    },
    {
      "x": -5,
      "y": 16,
      "z": -1,
      "name": "Rock_Volcanic_Cobble"
    },
    {
      "x": -5,
      "y": 17,
      "z": -1,
      "name": "Rock_Volcanic_Brick"
    },
    {
      "x": -5,
      "y": 18,
      "z": -1,
      "name": "Rock_Volcanic_Cobble"
    },
    {
      "x": -5,
      "y": 19,
      "z": -1,
      "name": "Rock_Volcanic_Brick"
    },
    {
      "x": -5,
      "y": 20,
      "z": -1,
      "name": "Rock_Volcanic_Brick"
    },
    {
      "x": -5,
      "y": 21,
      "z": -1,
      "name": "Rock_Volcanic_Cobble"
    },
    {
      "x": -5,
      "y": 22,
      "z": -1,
      "name": "Rock_Volcanic_Cobble"
    },
    {
      "x": -5,
      "y": 23,
      "z": -1,
      "name": "Rock_Volcanic_Brick"
    },
    {
      "x": -5,
      "y": 24,
      "z": -1,
      "name": "Rock_Volcanic_Brick"
    },
    {
      "x": -5,
      "y": 25,
      "z": -1,
      "name": "Rock_Volcanic_Cobble"
    },
    {
      "x": -5,
      "y": 26,
      "z": -1,
      "name": "Rock_Volcanic_Brick"
    },
    {
      "x": -5,
      "y": 27,
      "z": -1,
      "name": "Rock_Volcanic_Brick"
    },
    {
      "x": -5,
      "y": 28,
      "z": -1,
      "name": "Rock_Volcanic_Brick"
    },
    {
      "x": -5,
      "y": 29,
      "z": -1,
      "name": "Rock_Volcanic_Brick"
    },
    {
      "x": -5,
      "y": 30,
      "z": -1,
      "name": "Rock_Volcanic_Cobble"
    },
    {
      "x": -5,
      "y": 31,
      "z": -1,
      "name": "Rock_Volcanic_Brick"
    },
    {
      "x": -5,
      "y": 32,
      "z": -1,
      "name": "Rock_Volcanic_Brick"
    },
    {
      "x": -5,
      "y": 33,
      "z": -1,
      "name": "Rock_Volcanic_Cobble"
    },
    {
      "x": -5,
      "y": 34,
      "z": -1,
      "name": "Rock_Volcanic_Brick"
    },
    {
      "x": -5,
      "y": 35,
      "z": -1,
      "name": "Rock_Volcanic_Brick"
    },
    {
      "x": -5,
      "y": 36,
      "z": -1,
      "name": "Rock_Volcanic_Brick"
    },
    {
      "x": -5,
      "y": 37,
      "z": -1,
      "name": "Rock_Volcanic_Brick"
    },
    {
      "x": -5,
      "y": 38,
      "z": -1,
      "name": "Rock_Volcanic_Brick"
    },
    {
      "x": -5,
      "y": 39,
      "z": -1,
      "name": "Rock_Volcanic_Brick"
    },
    {
      "x": -5,
      "y": 40,
      "z": -1,
      "name": "Rock_Volcanic_Cobble"
    },
    {
      "x": -5,
      "y": 41,
      "z": -1,
      "name": "Rock_Volcanic_Cobble"
    },
    {
      "x": -5,
      "y": 42,
      "z": -1,
      "name": "Rock_Volcanic_Brick"
    },
    {
      "x": -5,
      "y": 43,
      "z": -1,
      "name": "Rock_Volcanic_Cobble"
    },
    {
      "x": -5,
      "y": 44,
      "z": -1,
      "name": "Rock_Volcanic_Brick"
    },
    {
      "x": -5,
      "y": 45,
      "z": -1,
      "name": "Rock_Volcanic_Brick"
    },
    {
      "x": -5,
      "y": 46,
      "z": -1,
      "name": "Rock_Volcanic_Cobble"
    },
    {
      "x": -5,
      "y": 47,
      "z": -1,
      "name": "Rock_Volcanic_Brick",
      "rotation": 1
    },
    {
      "x": -5,
      "y": 48,
      "z": -1,
      "name": "Rock_Volcanic_Cobble",
      "rotation": 1
    },
    {
      "x": -5,
      "y": 49,
      "z": -1,
      "name": "Rock_Volcanic_Brick",
      "rotation": 1
    },
    {
      "x": -5,
      "y": 50,
      "z": -1,
      "name": "Rock_Volcanic_Brick",
      "rotation": 1
    },
    {
      "x": -5,
      "y": 51,
      "z": -1,
      "name": "Rock_Volcanic_Brick_Wall",
      "rotation": 3
    },
    {
      "x": -5,
      "y": 54,
      "z": -1,
      "name": "Rock_Crystal_Green_Block",
      "rotation": 1
    },
    {
      "x": -5,
      "y": 55,
      "z": -1,
      "name": "Rock_Crystal_Green_Block",
      "rotation": 1
    },
    {
      "x": -5,
      "y": 56,
      "z": -1,
      "name": "Rock_Crystal_Green_Block",
      "rotation": 1
    },
    {
      "x": -5,
      "y": 57,
      "z": -1,
      "name": "Rock_Crystal_Green_Block",
      "rotation": 1
    },
    {
      "x": -5,
      "y": 58,
      "z": -1,
      "name": "Rock_Crystal_Green_Block",
      "rotation": 1
    },
    {
      "x": -5,
      "y": 61,
      "z": -1,
      "name": "Rock_Volcanic_Brick_Wall",
      "rotation": 3
    },
    {
      "x": -5,
      "y": 62,
      "z": -1,
      "name": "Rock_Volcanic_Brick",
      "rotation": 2
    },
    {
      "x": -5,
      "y": 63,
      "z": -1,
      "name": "Rock_Volcanic_Brick",
      "rotation": 2
    },
    {
      "x": -5,
      "y": 64,
      "z": -1,
      "name": "Rock_Volcanic_Brick",
      "rotation": 2
    },
    {
      "x": -5,
      "y": 65,
      "z": -1,
      "name": "Rock_Volcanic_Cobble",
      "rotation": 2
    },
    {
      "x": -5,
      "y": 66,
      "z": -1,
      "name": "Rock_Volcanic_Brick",
      "rotation": 2
    },
    {
      "x": -5,
      "y": 67,
      "z": -1,
      "name": "Rock_Volcanic_Brick_Wall",
      "rotation": 1
    },
    {
      "x": -5,
      "y": -25,
      "z": 0,
      "name": "Rock_Volcanic_Cobble"
    },
    {
      "x": -5,
      "y": -24,
      "z": 0,
      "name": "Rock_Volcanic_Cobble"
    },
    {
      "x": -5,
      "y": -23,
      "z": 0,
      "name": "Rock_Volcanic_Brick"
    },
    {
      "x": -5,
      "y": -22,
      "z": 0,
      "name": "Rock_Volcanic_Cobble"
    },
    {
      "x": -5,
      "y": -21,
      "z": 0,
      "name": "Rock_Volcanic_Cobble"
    },
    {
      "x": -5,
      "y": -20,
      "z": 0,
      "name": "Rock_Volcanic_Cobble"
    },
    {
      "x": -5,
      "y": -19,
      "z": 0,
      "name": "Rock_Volcanic_Brick"
    },
    {
      "x": -5,
      "y": -18,
      "z": 0,
      "name": "Rock_Volcanic_Cobble"
    },
    {
      "x": -5,
      "y": -17,
      "z": 0,
      "name": "Rock_Volcanic_Cobble"
    },
    {
      "x": -5,
      "y": -16,
      "z": 0,
      "name": "Rock_Volcanic_Brick"
    },
    {
      "x": -5,
      "y": -15,
      "z": 0,
      "name": "Rock_Volcanic_Brick"
    },
    {
      "x": -5,
      "y": -14,
      "z": 0,
      "name": "Rock_Volcanic_Brick"
    },
    {
      "x": -5,
      "y": -13,
      "z": 0,
      "name": "Rock_Volcanic_Brick"
    },
    {
      "x": -5,
      "y": -12,
      "z": 0,
      "name": "Rock_Volcanic_Brick"
    },
    {
      "x": -5,
      "y": -11,
      "z": 0,
      "name": "Rock_Volcanic_Cobble"
    },
    {
      "x": -5,
      "y": -10,
      "z": 0,
      "name": "Rock_Volcanic_Cobble"
    },
    {
      "x": -5,
      "y": -9,
      "z": 0,
      "name": "Rock_Volcanic_Brick"
    },
    {
      "x": -5,
      "y": -8,
      "z": 0,
      "name": "Rock_Volcanic_Cobble"
    },
    {
      "x": -5,
      "y": -7,
      "z": 0,
      "name": "Rock_Volcanic_Brick"
    },
    {
      "x": -5,
      "y": -6,
      "z": 0,
      "name": "Rock_Volcanic_Brick"
    },
    {
      "x": -5,
      "y": -5,
      "z": 0,
      "name": "Rock_Volcanic_Brick"
    },
    {
      "x": -5,
      "y": -4,
      "z": 0,
      "name": "Rock_Volcanic_Brick"
    },
    {
      "x": -5,
      "y": -3,
      "z": 0,
      "name": "Rock_Volcanic_Brick"
    },
    {
      "x": -5,
      "y": -2,
      "z": 0,
      "name": "Rock_Volcanic_Brick"
    },
    {
      "x": -5,
      "y": -1,
      "z": 0,
      "name": "Rock_Volcanic_Cobble"
    },
    {
      "x": -5,
      "y": 0,
      "z": 0,
      "name": "Rock_Volcanic_Brick"
    },
    {
      "x": -5,
      "y": 1,
      "z": 0,
      "name": "Rock_Volcanic_Brick"
    },
    {
      "x": -5,
      "y": 2,
      "z": 0,
      "name": "Rock_Volcanic_Brick"
    },
    {
      "x": -5,
      "y": 3,
      "z": 0,
      "name": "Rock_Volcanic_Brick"
    },
    {
      "x": -5,
      "y": 4,
      "z": 0,
      "name": "Rock_Volcanic_Brick"
    },
    {
      "x": -5,
      "y": 5,
      "z": 0,
      "name": "Rock_Volcanic_Cobble"
    },
    {
      "x": -5,
      "y": 6,
      "z": 0,
      "name": "Rock_Volcanic_Brick"
    },
    {
      "x": -5,
      "y": 7,
      "z": 0,
      "name": "Rock_Volcanic_Brick"
    },
    {
      "x": -5,
      "y": 8,
      "z": 0,
      "name": "Rock_Volcanic_Brick"
    },
    {
      "x": -5,
      "y": 9,
      "z": 0,
      "name": "Rock_Volcanic_Cobble"
    },
    {
      "x": -5,
      "y": 10,
      "z": 0,
      "name": "Rock_Volcanic_Brick"
    },
    {
      "x": -5,
      "y": 11,
      "z": 0,
      "name": "Rock_Volcanic_Brick"
    },
    {
      "x": -5,
      "y": 12,
      "z": 0,
      "name": "Rock_Volcanic_Brick"
    },
    {
      "x": -5,
      "y": 13,
      "z": 0,
      "name": "Rock_Volcanic_Brick"
    },
    {
      "x": -5,
      "y": 14,
      "z": 0,
      "name": "Rock_Volcanic_Cobble"
    },
    {
      "x": -5,
      "y": 15,
      "z": 0,
      "name": "Rock_Volcanic_Cobble"
    },
    {
      "x": -5,
      "y": 16,
      "z": 0,
      "name": "Rock_Volcanic_Brick"
    },
    {
      "x": -5,
      "y": 17,
      "z": 0,
      "name": "Rock_Volcanic_Brick"
    },
    {
      "x": -5,
      "y": 18,
      "z": 0,
      "name": "Rock_Volcanic_Brick"
    },
    {
      "x": -5,
      "y": 19,
      "z": 0,
      "name": "Rock_Volcanic_Brick"
    },
    {
      "x": -5,
      "y": 20,
      "z": 0,
      "name": "Rock_Volcanic_Brick"
    },
    {
      "x": -5,
      "y": 21,
      "z": 0,
      "name": "Rock_Volcanic_Cobble"
    },
    {
      "x": -5,
      "y": 22,
      "z": 0,
      "name": "Rock_Volcanic_Brick"
    },
    {
      "x": -5,
      "y": 23,
      "z": 0,
      "name": "Rock_Volcanic_Brick"
    },
    {
      "x": -5,
      "y": 24,
      "z": 0,
      "name": "Rock_Volcanic_Brick"
    },
    {
      "x": -5,
      "y": 25,
      "z": 0,
      "name": "Rock_Volcanic_Brick"
    },
    {
      "x": -5,
      "y": 26,
      "z": 0,
      "name": "Rock_Volcanic_Brick"
    },
    {
      "x": -5,
      "y": 27,
      "z": 0,
      "name": "Rock_Volcanic_Brick"
    },
    {
      "x": -5,
      "y": 28,
      "z": 0,
      "name": "Rock_Volcanic_Cobble"
    },
    {
      "x": -5,
      "y": 29,
      "z": 0,
      "name": "Rock_Volcanic_Cobble"
    },
    {
      "x": -5,
      "y": 30,
      "z": 0,
      "name": "Rock_Volcanic_Brick"
    },
    {
      "x": -5,
      "y": 31,
      "z": 0,
      "name": "Rock_Volcanic_Cobble"
    },
    {
      "x": -5,
      "y": 32,
      "z": 0,
      "name": "Rock_Volcanic_Brick"
    },
    {
      "x": -5,
      "y": 33,
      "z": 0,
      "name": "Rock_Volcanic_Cobble"
    },
    {
      "x": -5,
      "y": 34,
      "z": 0,
      "name": "Rock_Volcanic_Cobble"
    },
    {
      "x": -5,
      "y": 35,
      "z": 0,
      "name": "Rock_Volcanic_Cobble"
    },
    {
      "x": -5,
      "y": 36,
      "z": 0,
      "name": "Rock_Volcanic_Brick"
    },
    {
      "x": -5,
      "y": 37,
      "z": 0,
      "name": "Rock_Volcanic_Cobble"
    },
    {
      "x": -5,
      "y": 38,
      "z": 0,
      "name": "Rock_Volcanic_Brick"
    },
    {
      "x": -5,
      "y": 39,
      "z": 0,
      "name": "Rock_Volcanic_Brick"
    },
    {
      "x": -5,
      "y": 40,
      "z": 0,
      "name": "Rock_Volcanic_Brick"
    },
    {
      "x": -5,
      "y": 41,
      "z": 0,
      "name": "Rock_Volcanic_Cobble"
    },
    {
      "x": -5,
      "y": 42,
      "z": 0,
      "name": "Rock_Volcanic_Brick"
    },
    {
      "x": -5,
      "y": 43,
      "z": 0,
      "name": "Rock_Volcanic_Cobble"
    },
    {
      "x": -5,
      "y": 44,
      "z": 0,
      "name": "Rock_Volcanic_Brick"
    },
    {
      "x": -5,
      "y": 45,
      "z": 0,
      "name": "Rock_Volcanic_Brick"
    },
    {
      "x": -5,
      "y": 46,
      "z": 0,
      "name": "Rock_Volcanic_Cobble"
    },
    {
      "x": -5,
      "y": 47,
      "z": 0,
      "name": "Rock_Volcanic_Brick",
      "rotation": 1
    },
    {
      "x": -5,
      "y": 48,
      "z": 0,
      "name": "Rock_Volcanic_Brick",
      "rotation": 1
    },
    {
      "x": -5,
      "y": 49,
      "z": 0,
      "name": "Rock_Volcanic_Brick",
      "rotation": 1
    },
    {
      "x": -5,
      "y": 50,
      "z": 0,
      "name": "Rock_Volcanic_Cobble",
      "rotation": 1
    },
    {
      "x": -5,
      "y": 51,
      "z": 0,
      "name": "Rock_Volcanic_Brick_Wall",
      "rotation": 3
    },
    {
      "x": -5,
      "y": 55,
      "z": 0,
      "name": "Rock_Crystal_Green_Block",
      "rotation": 1
    },
    {
      "x": -5,
      "y": 56,
      "z": 0,
      "name": "Rock_Crystal_Green_Block",
      "rotation": 1
    },
    {
      "x": -5,
      "y": 57,
      "z": 0,
      "name": "Rock_Crystal_Green_Block",
      "rotation": 1
    },
    {
      "x": -5,
      "y": 61,
      "z": 0,
      "name": "Rock_Volcanic_Brick_Wall",
      "rotation": 3
    },
    {
      "x": -5,
      "y": 62,
      "z": 0,
      "name": "Rock_Volcanic_Brick",
      "rotation": 2
    },
    {
      "x": -5,
      "y": 63,
      "z": 0,
      "name": "Rock_Volcanic_Brick",
      "rotation": 2
    },
    {
      "x": -5,
      "y": 64,
      "z": 0,
      "name": "Rock_Volcanic_Brick",
      "rotation": 2
    },
    {
      "x": -5,
      "y": 65,
      "z": 0,
      "name": "Rock_Volcanic_Brick",
      "rotation": 2
    },
    {
      "x": -5,
      "y": 66,
      "z": 0,
      "name": "Rock_Volcanic_Cobble",
      "rotation": 2
    },
    {
      "x": -5,
      "y": 67,
      "z": 0,
      "name": "Rock_Volcanic_Brick_Wall",
      "rotation": 1
    },
    {
      "x": -5,
      "y": -25,
      "z": 1,
      "name": "Rock_Volcanic_Cobble"
    },
    {
      "x": -5,
      "y": -24,
      "z": 1,
      "name": "Rock_Volcanic_Brick"
    },
    {
      "x": -5,
      "y": -23,
      "z": 1,
      "name": "Rock_Volcanic_Cobble"
    },
    {
      "x": -5,
      "y": -22,
      "z": 1,
      "name": "Rock_Volcanic_Cobble"
    },
    {
      "x": -5,
      "y": -21,
      "z": 1,
      "name": "Rock_Volcanic_Cobble"
    },
    {
      "x": -5,
      "y": -20,
      "z": 1,
      "name": "Rock_Volcanic_Cobble"
    },
    {
      "x": -5,
      "y": -19,
      "z": 1,
      "name": "Rock_Volcanic_Cobble"
    },
    {
      "x": -5,
      "y": -18,
      "z": 1,
      "name": "Rock_Volcanic_Cobble"
    },
    {
      "x": -5,
      "y": -17,
      "z": 1,
      "name": "Rock_Volcanic_Brick"
    },
    {
      "x": -5,
      "y": -16,
      "z": 1,
      "name": "Rock_Volcanic_Brick"
    },
    {
      "x": -5,
      "y": -15,
      "z": 1,
      "name": "Rock_Volcanic_Cobble"
    },
    {
      "x": -5,
      "y": -14,
      "z": 1,
      "name": "Rock_Volcanic_Cobble"
    },
    {
      "x": -5,
      "y": -13,
      "z": 1,
      "name": "Rock_Volcanic_Brick"
    },
    {
      "x": -5,
      "y": -12,
      "z": 1,
      "name": "Rock_Volcanic_Cobble"
    },
    {
      "x": -5,
      "y": -11,
      "z": 1,
      "name": "Rock_Volcanic_Brick"
    },
    {
      "x": -5,
      "y": -10,
      "z": 1,
      "name": "Rock_Volcanic_Cobble"
    },
    {
      "x": -5,
      "y": -9,
      "z": 1,
      "name": "Rock_Volcanic_Cobble"
    },
    {
      "x": -5,
      "y": -8,
      "z": 1,
      "name": "Rock_Volcanic_Cobble"
    },
    {
      "x": -5,
      "y": -7,
      "z": 1,
      "name": "Rock_Volcanic_Brick"
    },
    {
      "x": -5,
      "y": -6,
      "z": 1,
      "name": "Rock_Volcanic_Brick"
    },
    {
      "x": -5,
      "y": -5,
      "z": 1,
      "name": "Rock_Volcanic_Brick"
    },
    {
      "x": -5,
      "y": -4,
      "z": 1,
      "name": "Rock_Volcanic_Cobble"
    },
    {
      "x": -5,
      "y": -3,
      "z": 1,
      "name": "Rock_Volcanic_Cobble"
    },
    {
      "x": -5,
      "y": -2,
      "z": 1,
      "name": "Rock_Volcanic_Brick"
    },
    {
      "x": -5,
      "y": -1,
      "z": 1,
      "name": "Rock_Volcanic_Cobble"
    },
    {
      "x": -5,
      "y": 0,
      "z": 1,
      "name": "Rock_Volcanic_Brick"
    },
    {
      "x": -5,
      "y": 1,
      "z": 1,
      "name": "Rock_Volcanic_Cobble"
    },
    {
      "x": -5,
      "y": 2,
      "z": 1,
      "name": "Rock_Volcanic_Cobble"
    },
    {
      "x": -5,
      "y": 3,
      "z": 1,
      "name": "Rock_Volcanic_Brick"
    },
    {
      "x": -5,
      "y": 4,
      "z": 1,
      "name": "Rock_Volcanic_Brick"
    },
    {
      "x": -5,
      "y": 5,
      "z": 1,
      "name": "Rock_Volcanic_Cobble"
    },
    {
      "x": -5,
      "y": 6,
      "z": 1,
      "name": "Rock_Volcanic_Cobble"
    },
    {
      "x": -5,
      "y": 7,
      "z": 1,
      "name": "Rock_Volcanic_Brick"
    },
    {
      "x": -5,
      "y": 8,
      "z": 1,
      "name": "Rock_Volcanic_Brick"
    },
    {
      "x": -5,
      "y": 9,
      "z": 1,
      "name": "Rock_Volcanic_Brick"
    },
    {
      "x": -5,
      "y": 10,
      "z": 1,
      "name": "Rock_Volcanic_Cobble"
    },
    {
      "x": -5,
      "y": 11,
      "z": 1,
      "name": "Rock_Volcanic_Brick"
    },
    {
      "x": -5,
      "y": 12,
      "z": 1,
      "name": "Rock_Volcanic_Brick"
    },
    {
      "x": -5,
      "y": 13,
      "z": 1,
      "name": "Rock_Volcanic_Brick"
    },
    {
      "x": -5,
      "y": 14,
      "z": 1,
      "name": "Rock_Volcanic_Brick"
    },
    {
      "x": -5,
      "y": 15,
      "z": 1,
      "name": "Rock_Volcanic_Cobble"
    },
    {
      "x": -5,
      "y": 16,
      "z": 1,
      "name": "Rock_Volcanic_Brick"
    },
    {
      "x": -5,
      "y": 17,
      "z": 1,
      "name": "Rock_Volcanic_Cobble"
    },
    {
      "x": -5,
      "y": 18,
      "z": 1,
      "name": "Rock_Volcanic_Cobble"
    },
    {
      "x": -5,
      "y": 19,
      "z": 1,
      "name": "Rock_Volcanic_Cobble"
    },
    {
      "x": -5,
      "y": 20,
      "z": 1,
      "name": "Rock_Volcanic_Brick"
    },
    {
      "x": -5,
      "y": 21,
      "z": 1,
      "name": "Rock_Volcanic_Brick"
    },
    {
      "x": -5,
      "y": 22,
      "z": 1,
      "name": "Rock_Volcanic_Cobble"
    },
    {
      "x": -5,
      "y": 23,
      "z": 1,
      "name": "Rock_Volcanic_Cobble"
    },
    {
      "x": -5,
      "y": 24,
      "z": 1,
      "name": "Rock_Volcanic_Cobble"
    },
    {
      "x": -5,
      "y": 25,
      "z": 1,
      "name": "Rock_Volcanic_Cobble"
    },
    {
      "x": -5,
      "y": 26,
      "z": 1,
      "name": "Rock_Volcanic_Cobble"
    },
    {
      "x": -5,
      "y": 27,
      "z": 1,
      "name": "Rock_Volcanic_Brick"
    },
    {
      "x": -5,
      "y": 28,
      "z": 1,
      "name": "Rock_Volcanic_Cobble"
    },
    {
      "x": -5,
      "y": 29,
      "z": 1,
      "name": "Rock_Volcanic_Brick"
    },
    {
      "x": -5,
      "y": 30,
      "z": 1,
      "name": "Rock_Volcanic_Brick"
    },
    {
      "x": -5,
      "y": 31,
      "z": 1,
      "name": "Rock_Volcanic_Brick"
    },
    {
      "x": -5,
      "y": 32,
      "z": 1,
      "name": "Rock_Volcanic_Brick"
    },
    {
      "x": -5,
      "y": 33,
      "z": 1,
      "name": "Rock_Volcanic_Cobble"
    },
    {
      "x": -5,
      "y": 34,
      "z": 1,
      "name": "Rock_Volcanic_Brick"
    },
    {
      "x": -5,
      "y": 35,
      "z": 1,
      "name": "Rock_Aqua_Cobble"
    },
    {
      "x": -5,
      "y": 36,
      "z": 1,
      "name": "Rock_Volcanic_Cobble"
    },
    {
      "x": -5,
      "y": 37,
      "z": 1,
      "name": "Rock_Volcanic_Cobble"
    },
    {
      "x": -5,
      "y": 38,
      "z": 1,
      "name": "Rock_Volcanic_Cobble"
    },
    {
      "x": -5,
      "y": 39,
      "z": 1,
      "name": "Rock_Volcanic_Cobble"
    },
    {
      "x": -5,
      "y": 40,
      "z": 1,
      "name": "Rock_Volcanic_Brick"
    },
    {
      "x": -5,
      "y": 41,
      "z": 1,
      "name": "Rock_Volcanic_Cobble"
    },
    {
      "x": -5,
      "y": 42,
      "z": 1,
      "name": "Rock_Volcanic_Brick"
    },
    {
      "x": -5,
      "y": 43,
      "z": 1,
      "name": "Rock_Volcanic_Cobble"
    },
    {
      "x": -5,
      "y": 44,
      "z": 1,
      "name": "Rock_Volcanic_Brick"
    },
    {
      "x": -5,
      "y": 45,
      "z": 1,
      "name": "Rock_Volcanic_Brick"
    },
    {
      "x": -5,
      "y": 46,
      "z": 1,
      "name": "Rock_Volcanic_Brick"
    },
    {
      "x": -5,
      "y": 47,
      "z": 1,
      "name": "Rock_Volcanic_Brick",
      "rotation": 1
    },
    {
      "x": -5,
      "y": 48,
      "z": 1,
      "name": "Rock_Volcanic_Cobble",
      "rotation": 1
    },
    {
      "x": -5,
      "y": 49,
      "z": 1,
      "name": "Rock_Volcanic_Cobble",
      "rotation": 1
    },
    {
      "x": -5,
      "y": 50,
      "z": 1,
      "name": "Rock_Volcanic_Cobble",
      "rotation": 1
    },
    {
      "x": -5,
      "y": 51,
      "z": 1,
      "name": "*Rock_Volcanic_Brick_Wall_State_Definitions_Corner",
      "rotation": 2
    },
    {
      "x": -5,
      "y": 56,
      "z": 1,
      "name": "Rock_Crystal_Green_Block",
      "rotation": 1
    },
    {
      "x": -5,
      "y": 61,
      "z": 1,
      "name": "*Rock_Volcanic_Brick_Wall_State_Definitions_Corner",
      "rotation": 2
    },
    {
      "x": -5,
      "y": 62,
      "z": 1,
      "name": "Rock_Volcanic_Brick",
      "rotation": 2
    },
    {
      "x": -5,
      "y": 63,
      "z": 1,
      "name": "Rock_Volcanic_Brick",
      "rotation": 2
    },
    {
      "x": -5,
      "y": 64,
      "z": 1,
      "name": "Rock_Volcanic_Brick",
      "rotation": 2
    },
    {
      "x": -5,
      "y": 65,
      "z": 1,
      "name": "Rock_Volcanic_Cobble",
      "rotation": 2
    },
    {
      "x": -5,
      "y": 66,
      "z": 1,
      "name": "Rock_Volcanic_Brick",
      "rotation": 2
    },
    {
      "x": -5,
      "y": 67,
      "z": 1,
      "name": "*Rock_Volcanic_Brick_Wall_State_Definitions_Corner",
      "rotation": 2
    },
    {
      "x": -5,
      "y": 35,
      "z": 2,
      "name": "Rock_Aqua_Cobble_Half",
      "rotation": 7
    },
    {
      "x": -5,
      "y": 35,
      "z": 3,
      "name": "Rock_Aqua_Cobble_Half",
      "rotation": 7
    },
    {
      "x": -5,
      "y": 56,
      "z": 7,
      "name": "Rock_Volcanic_Brick_Half",
      "rotation": 9
    },
    {
      "x": -5,
      "y": 57,
      "z": 7,
      "name": "*Rock_Volcanic_Brick_Wall_State_Definitions_Corner"
    },
    {
      "x": -5,
      "y": 56,
      "z": 8,
      "name": "Rock_Volcanic_Brick_Half",
      "rotation": 9
    },
    {
      "x": -5,
      "y": 57,
      "z": 8,
      "name": "*Rock_Volcanic_Brick_Wall_State_Definitions_Corner",
      "rotation": 2
    },
    {
      "x": -4,
      "y": 56,
      "z": -10,
      "name": "Rock_Volcanic_Brick_Half",
      "rotation": 8
    },
    {
      "x": -4,
      "y": 57,
      "z": -10,
      "name": "Rock_Volcanic_Brick_Wall",
      "rotation": 2
    },
    {
      "x": -4,
      "y": 35,
      "z": -6,
      "name": "Rock_Aqua_Cobble_Half",
      "rotation": 6
    },
    {
      "x": -4,
      "y": 26,
      "z": -5,
      "name": "Wood_Deadwood_Beam"
    },
    {
      "x": -4,
      "y": 27,
      "z": -5,
      "name": "Wood_Deadwood_Beam"
    },
    {
      "x": -4,
      "y": 28,
      "z": -5,
      "name": "Wood_Deadwood_Beam"
    },
    {
      "x": -4,
      "y": 29,
      "z": -5,
      "name": "Rock_Volcanic_Brick_Beam"
    },
    {
      "x": -4,
      "y": 30,
      "z": -5,
      "name": "Rock_Volcanic_Brick_Beam"
    },
    {
      "x": -4,
      "y": 31,
      "z": -5,
      "name": "Rock_Volcanic_Brick_Beam"
    },
    {
      "x": -4,
      "y": 32,
      "z": -5,
      "name": "Rock_Volcanic_Brick_Pillar_Middle"
    },
    {
      "x": -4,
      "y": 33,
      "z": -5,
      "name": "Rock_Volcanic_Brick_Pillar_Middle"
    },
    {
      "x": -4,
      "y": 34,
      "z": -5,
      "name": "Rock_Volcanic_Brick"
    },
    {
      "x": -4,
      "y": 35,
      "z": -5,
      "name": "Rock_Volcanic_Brick"
    },
    {
      "x": -4,
      "y": 36,
      "z": -5,
      "name": "Rock_Volcanic_Brick"
    },
    {
      "x": -4,
      "y": 37,
      "z": -5,
      "name": "Rock_Volcanic_Brick_Pillar_Middle"
    },
    {
      "x": -4,
      "y": 38,
      "z": -5,
      "name": "Rock_Volcanic_Brick_Pillar_Middle"
    },
    {
      "x": -4,
      "y": 39,
      "z": -5,
      "name": "Rock_Volcanic_Brick_Beam"
    },
    {
      "x": -4,
      "y": 40,
      "z": -5,
      "name": "Rock_Volcanic_Brick_Beam"
    },
    {
      "x": -4,
      "y": 41,
      "z": -5,
      "name": "Rock_Volcanic_Brick_Beam"
    },
    {
      "x": -4,
      "y": 42,
      "z": -5,
      "name": "Wood_Deadwood_Beam"
    },
    {
      "x": -4,
      "y": 43,
      "z": -5,
      "name": "Wood_Deadwood_Beam"
    },
    {
      "x": -4,
      "y": 44,
      "z": -5,
      "name": "Wood_Deadwood_Beam"
    },
    {
      "x": -4,
      "y": -25,
      "z": -4,
      "name": "Rock_Volcanic_Cobble"
    },
    {
      "x": -4,
      "y": -24,
      "z": -4,
      "name": "Rock_Volcanic_Cobble"
    },
    {
      "x": -4,
      "y": -23,
      "z": -4,
      "name": "Rock_Volcanic_Brick"
    },
    {
      "x": -4,
      "y": -22,
      "z": -4,
      "name": "Rock_Volcanic_Cobble"
    },
    {
      "x": -4,
      "y": -21,
      "z": -4,
      "name": "Rock_Volcanic_Brick"
    },
    {
      "x": -4,
      "y": -20,
      "z": -4,
      "name": "Rock_Volcanic_Cobble"
    },
    {
      "x": -4,
      "y": -19,
      "z": -4,
      "name": "Rock_Volcanic_Cobble"
    },
    {
      "x": -4,
      "y": -18,
      "z": -4,
      "name": "Rock_Volcanic_Cobble"
    },
    {
      "x": -4,
      "y": -17,
      "z": -4,
      "name": "Rock_Volcanic_Brick"
    },
    {
      "x": -4,
      "y": -16,
      "z": -4,
      "name": "Rock_Volcanic_Brick"
    },
    {
      "x": -4,
      "y": -15,
      "z": -4,
      "name": "Rock_Volcanic_Brick"
    },
    {
      "x": -4,
      "y": -14,
      "z": -4,
      "name": "Rock_Volcanic_Brick"
    },
    {
      "x": -4,
      "y": -13,
      "z": -4,
      "name": "Rock_Volcanic_Brick"
    },
    {
      "x": -4,
      "y": -12,
      "z": -4,
      "name": "Rock_Volcanic_Brick"
    },
    {
      "x": -4,
      "y": -11,
      "z": -4,
      "name": "Rock_Volcanic_Brick"
    },
    {
      "x": -4,
      "y": -10,
      "z": -4,
      "name": "Rock_Volcanic_Brick"
    },
    {
      "x": -4,
      "y": -9,
      "z": -4,
      "name": "Rock_Volcanic_Cobble"
    },
    {
      "x": -4,
      "y": -8,
      "z": -4,
      "name": "Rock_Volcanic_Cobble"
    },
    {
      "x": -4,
      "y": -7,
      "z": -4,
      "name": "Rock_Volcanic_Brick"
    },
    {
      "x": -4,
      "y": -6,
      "z": -4,
      "name": "Rock_Volcanic_Brick"
    },
    {
      "x": -4,
      "y": -5,
      "z": -4,
      "name": "Rock_Volcanic_Cobble"
    },
    {
      "x": -4,
      "y": -4,
      "z": -4,
      "name": "Rock_Volcanic_Cobble"
    },
    {
      "x": -4,
      "y": -3,
      "z": -4,
      "name": "Rock_Volcanic_Cobble"
    },
    {
      "x": -4,
      "y": -2,
      "z": -4,
      "name": "Rock_Volcanic_Brick"
    },
    {
      "x": -4,
      "y": -1,
      "z": -4,
      "name": "Rock_Volcanic_Cobble"
    },
    {
      "x": -4,
      "y": 0,
      "z": -4,
      "name": "Rock_Volcanic_Brick"
    },
    {
      "x": -4,
      "y": 1,
      "z": -4,
      "name": "Rock_Volcanic_Brick"
    },
    {
      "x": -4,
      "y": 2,
      "z": -4,
      "name": "Rock_Volcanic_Brick"
    },
    {
      "x": -4,
      "y": 3,
      "z": -4,
      "name": "Rock_Volcanic_Brick"
    },
    {
      "x": -4,
      "y": 4,
      "z": -4,
      "name": "Rock_Volcanic_Brick"
    },
    {
      "x": -4,
      "y": 5,
      "z": -4,
      "name": "Rock_Volcanic_Brick"
    },
    {
      "x": -4,
      "y": 6,
      "z": -4,
      "name": "Rock_Volcanic_Cobble"
    },
    {
      "x": -4,
      "y": 7,
      "z": -4,
      "name": "Rock_Volcanic_Cobble"
    },
    {
      "x": -4,
      "y": 8,
      "z": -4,
      "name": "Rock_Volcanic_Cobble"
    },
    {
      "x": -4,
      "y": 9,
      "z": -4,
      "name": "Rock_Volcanic_Cobble"
    },
    {
      "x": -4,
      "y": 10,
      "z": -4,
      "name": "Rock_Volcanic_Cobble"
    },
    {
      "x": -4,
      "y": 11,
      "z": -4,
      "name": "Rock_Volcanic_Brick"
    },
    {
      "x": -4,
      "y": 12,
      "z": -4,
      "name": "Rock_Volcanic_Brick"
    },
    {
      "x": -4,
      "y": 13,
      "z": -4,
      "name": "Rock_Volcanic_Cobble"
    },
    {
      "x": -4,
      "y": 14,
      "z": -4,
      "name": "Rock_Volcanic_Cobble"
    },
    {
      "x": -4,
      "y": 15,
      "z": -4,
      "name": "Rock_Volcanic_Brick"
    },
    {
      "x": -4,
      "y": 16,
      "z": -4,
      "name": "Rock_Volcanic_Brick"
    },
    {
      "x": -4,
      "y": 17,
      "z": -4,
      "name": "Rock_Volcanic_Cobble"
    },
    {
      "x": -4,
      "y": 18,
      "z": -4,
      "name": "Rock_Volcanic_Cobble"
    },
    {
      "x": -4,
      "y": 19,
      "z": -4,
      "name": "Rock_Volcanic_Cobble"
    },
    {
      "x": -4,
      "y": 20,
      "z": -4,
      "name": "Rock_Volcanic_Brick"
    },
    {
      "x": -4,
      "y": 21,
      "z": -4,
      "name": "Rock_Volcanic_Brick"
    },
    {
      "x": -4,
      "y": 22,
      "z": -4,
      "name": "Rock_Volcanic_Cobble"
    },
    {
      "x": -4,
      "y": 23,
      "z": -4,
      "name": "Rock_Volcanic_Brick"
    },
    {
      "x": -4,
      "y": 24,
      "z": -4,
      "name": "Rock_Volcanic_Cobble"
    },
    {
      "x": -4,
      "y": 25,
      "z": -4,
      "name": "Rock_Volcanic_Brick"
    },
    {
      "x": -4,
      "y": 26,
      "z": -4,
      "name": "Rock_Volcanic_Cobble"
    },
    {
      "x": -4,
      "y": 27,
      "z": -4,
      "name": "Rock_Volcanic_Brick"
    },
    {
      "x": -4,
      "y": 28,
      "z": -4,
      "name": "Rock_Volcanic_Cobble"
    },
    {
      "x": -4,
      "y": 29,
      "z": -4,
      "name": "Rock_Volcanic_Cobble"
    },
    {
      "x": -4,
      "y": 30,
      "z": -4,
      "name": "Rock_Volcanic_Brick"
    },
    {
      "x": -4,
      "y": 31,
      "z": -4,
      "name": "Rock_Volcanic_Brick"
    },
    {
      "x": -4,
      "y": 32,
      "z": -4,
      "name": "Rock_Volcanic_Cobble"
    },
    {
      "x": -4,
      "y": 33,
      "z": -4,
      "name": "Rock_Volcanic_Cobble"
    },
    {
      "x": -4,
      "y": 34,
      "z": -4,
      "name": "Rock_Volcanic_Cobble"
    },
    {
      "x": -4,
      "y": 35,
      "z": -4,
      "name": "Rock_Volcanic_Brick"
    },
    {
      "x": -4,
      "y": 36,
      "z": -4,
      "name": "Rock_Volcanic_Brick"
    },
    {
      "x": -4,
      "y": 37,
      "z": -4,
      "name": "Rock_Volcanic_Cobble"
    },
    {
      "x": -4,
      "y": 38,
      "z": -4,
      "name": "Rock_Volcanic_Cobble"
    },
    {
      "x": -4,
      "y": 39,
      "z": -4,
      "name": "Rock_Volcanic_Brick"
    },
    {
      "x": -4,
      "y": 40,
      "z": -4,
      "name": "Rock_Volcanic_Cobble"
    },
    {
      "x": -4,
      "y": 41,
      "z": -4,
      "name": "Rock_Volcanic_Brick"
    },
    {
      "x": -4,
      "y": 42,
      "z": -4,
      "name": "Rock_Volcanic_Cobble"
    },
    {
      "x": -4,
      "y": 43,
      "z": -4,
      "name": "Rock_Volcanic_Cobble"
    },
    {
      "x": -4,
      "y": 44,
      "z": -4,
      "name": "Rock_Volcanic_Brick"
    },
    {
      "x": -4,
      "y": 45,
      "z": -4,
      "name": "Rock_Volcanic_Brick"
    },
    {
      "x": -4,
      "y": 46,
      "z": -4,
      "name": "Rock_Volcanic_Cobble"
    },
    {
      "x": -4,
      "y": 47,
      "z": -4,
      "name": "Rock_Volcanic_Cobble"
    },
    {
      "x": -4,
      "y": 48,
      "z": -4,
      "name": "Rock_Volcanic_Brick"
    },
    {
      "x": -4,
      "y": 49,
      "z": -4,
      "name": "Rock_Volcanic_Cobble"
    },
    {
      "x": -4,
      "y": 50,
      "z": -4,
      "name": "Rock_Volcanic_Cobble"
    },
    {
      "x": -4,
      "y": 51,
      "z": -4,
      "name": "*Rock_Volcanic_Brick_Wall_State_Definitions_Corner",
      "rotation": 1
    },
    {
      "x": -4,
      "y": 54,
      "z": -4,
      "name": "Rock_Crystal_Green_Block"
    },
    {
      "x": -4,
      "y": 55,
      "z": -4,
      "name": "Rock_Crystal_Green_Block"
    },
    {
      "x": -4,
      "y": 56,
      "z": -4,
      "name": "Rock_Crystal_Green_Block"
    },
    {
      "x": -4,
      "y": 57,
      "z": -4,
      "name": "Rock_Crystal_Green_Block"
    },
    {
      "x": -4,
      "y": 58,
      "z": -4,
      "name": "Rock_Crystal_Green_Block"
    },
    {
      "x": -4,
      "y": 61,
      "z": -4,
      "name": "*Rock_Volcanic_Brick_Wall_State_Definitions_Corner",
      "rotation": 1
    },
    {
      "x": -4,
      "y": 62,
      "z": -4,
      "name": "Rock_Volcanic_Brick",
      "rotation": 1
    },
    {
      "x": -4,
      "y": 63,
      "z": -4,
      "name": "Rock_Volcanic_Cobble",
      "rotation": 1
    },
    {
      "x": -4,
      "y": 64,
      "z": -4,
      "name": "Rock_Volcanic_Cobble",
      "rotation": 1
    },
    {
      "x": -4,
      "y": 65,
      "z": -4,
      "name": "Rock_Volcanic_Cobble",
      "rotation": 1
    },
    {
      "x": -4,
      "y": 66,
      "z": -4,
      "name": "Rock_Volcanic_Cobble",
      "rotation": 1
    },
    {
      "x": -4,
      "y": 67,
      "z": -4,
      "name": "*Rock_Volcanic_Brick_Wall_State_Definitions_Corner",
      "rotation": 1
    },
    {
      "x": -4,
      "y": -25,
      "z": -3,
      "name": "Rock_Volcanic_Brick"
    },
    {
      "x": -4,
      "y": -24,
      "z": -3,
      "name": "Rock_Volcanic_Brick"
    },
    {
      "x": -4,
      "y": -23,
      "z": -3,
      "name": "Rock_Volcanic_Brick"
    },
    {
      "x": -4,
      "y": -22,
      "z": -3,
      "name": "Rock_Volcanic_Cobble"
    },
    {
      "x": -4,
      "y": -21,
      "z": -3,
      "name": "Rock_Volcanic_Cobble"
    },
    {
      "x": -4,
      "y": -20,
      "z": -3,
      "name": "Rock_Volcanic_Brick"
    },
    {
      "x": -4,
      "y": -19,
      "z": -3,
      "name": "Rock_Volcanic_Brick"
    },
    {
      "x": -4,
      "y": -18,
      "z": -3,
      "name": "Rock_Volcanic_Brick"
    },
    {
      "x": -4,
      "y": -17,
      "z": -3,
      "name": "Rock_Volcanic_Brick"
    },
    {
      "x": -4,
      "y": -16,
      "z": -3,
      "name": "Rock_Volcanic_Brick"
    },
    {
      "x": -4,
      "y": -15,
      "z": -3,
      "name": "Rock_Volcanic_Cobble"
    },
    {
      "x": -4,
      "y": -14,
      "z": -3,
      "name": "Rock_Volcanic_Cobble"
    },
    {
      "x": -4,
      "y": -13,
      "z": -3,
      "name": "Rock_Volcanic_Brick"
    },
    {
      "x": -4,
      "y": -12,
      "z": -3,
      "name": "Rock_Volcanic_Cobble"
    },
    {
      "x": -4,
      "y": -11,
      "z": -3,
      "name": "Rock_Volcanic_Brick"
    },
    {
      "x": -4,
      "y": -10,
      "z": -3,
      "name": "Rock_Volcanic_Cobble"
    },
    {
      "x": -4,
      "y": -9,
      "z": -3,
      "name": "Rock_Volcanic_Brick"
    },
    {
      "x": -4,
      "y": -8,
      "z": -3,
      "name": "Rock_Volcanic_Cobble"
    },
    {
      "x": -4,
      "y": -7,
      "z": -3,
      "name": "Rock_Volcanic_Cobble"
    },
    {
      "x": -4,
      "y": -6,
      "z": -3,
      "name": "Rock_Volcanic_Brick"
    },
    {
      "x": -4,
      "y": -5,
      "z": -3,
      "name": "Rock_Volcanic_Brick"
    },
    {
      "x": -4,
      "y": -4,
      "z": -3,
      "name": "Rock_Volcanic_Cobble"
    },
    {
      "x": -4,
      "y": -3,
      "z": -3,
      "name": "Rock_Volcanic_Cobble"
    },
    {
      "x": -4,
      "y": -2,
      "z": -3,
      "name": "Rock_Volcanic_Brick"
    },
    {
      "x": -4,
      "y": -1,
      "z": -3,
      "name": "Rock_Volcanic_Cobble"
    },
    {
      "x": -4,
      "y": 0,
      "z": -3,
      "name": "Rock_Volcanic_Cobble"
    },
    {
      "x": -4,
      "y": 1,
      "z": -3,
      "name": "Rock_Volcanic_Cobble"
    },
    {
      "x": -4,
      "y": 2,
      "z": -3,
      "name": "Rock_Volcanic_Cobble"
    },
    {
      "x": -4,
      "y": 3,
      "z": -3,
      "name": "Rock_Volcanic_Brick"
    },
    {
      "x": -4,
      "y": 4,
      "z": -3,
      "name": "Rock_Volcanic_Brick"
    },
    {
      "x": -4,
      "y": 5,
      "z": -3,
      "name": "Rock_Volcanic_Brick"
    },
    {
      "x": -4,
      "y": 6,
      "z": -3,
      "name": "Rock_Volcanic_Cobble"
    },
    {
      "x": -4,
      "y": 7,
      "z": -3,
      "name": "Rock_Volcanic_Cobble"
    },
    {
      "x": -4,
      "y": 8,
      "z": -3,
      "name": "Rock_Volcanic_Brick"
    },
    {
      "x": -4,
      "y": 9,
      "z": -3,
      "name": "Rock_Volcanic_Brick"
    },
    {
      "x": -4,
      "y": 10,
      "z": -3,
      "name": "Rock_Volcanic_Cobble"
    },
    {
      "x": -4,
      "y": 11,
      "z": -3,
      "name": "Rock_Volcanic_Cobble"
    },
    {
      "x": -4,
      "y": 12,
      "z": -3,
      "name": "Rock_Volcanic_Brick"
    },
    {
      "x": -4,
      "y": 13,
      "z": -3,
      "name": "Rock_Volcanic_Brick"
    },
    {
      "x": -4,
      "y": 14,
      "z": -3,
      "name": "Rock_Volcanic_Cobble"
    },
    {
      "x": -4,
      "y": 15,
      "z": -3,
      "name": "Rock_Volcanic_Brick"
    },
    {
      "x": -4,
      "y": 16,
      "z": -3,
      "name": "Rock_Volcanic_Brick"
    },
    {
      "x": -4,
      "y": 17,
      "z": -3,
      "name": "Rock_Volcanic_Cobble"
    },
    {
      "x": -4,
      "y": 18,
      "z": -3,
      "name": "Rock_Volcanic_Brick"
    },
    {
      "x": -4,
      "y": 19,
      "z": -3,
      "name": "Rock_Volcanic_Brick"
    },
    {
      "x": -4,
      "y": 20,
      "z": -3,
      "name": "Rock_Volcanic_Cobble"
    },
    {
      "x": -4,
      "y": 21,
      "z": -3,
      "name": "Rock_Volcanic_Cobble"
    },
    {
      "x": -4,
      "y": 22,
      "z": -3,
      "name": "Rock_Volcanic_Cobble"
    },
    {
      "x": -4,
      "y": 23,
      "z": -3,
      "name": "Rock_Volcanic_Cobble"
    },
    {
      "x": -4,
      "y": 24,
      "z": -3,
      "name": "Rock_Volcanic_Brick"
    },
    {
      "x": -4,
      "y": 25,
      "z": -3,
      "name": "Rock_Volcanic_Cobble"
    },
    {
      "x": -4,
      "y": 26,
      "z": -3,
      "name": "Rock_Volcanic_Cobble"
    },
    {
      "x": -4,
      "y": 27,
      "z": -3,
      "name": "Rock_Volcanic_Brick"
    },
    {
      "x": -4,
      "y": 28,
      "z": -3,
      "name": "Rock_Volcanic_Cobble"
    },
    {
      "x": -4,
      "y": 29,
      "z": -3,
      "name": "Rock_Volcanic_Cobble"
    },
    {
      "x": -4,
      "y": 30,
      "z": -3,
      "name": "Rock_Volcanic_Brick"
    },
    {
      "x": -4,
      "y": 31,
      "z": -3,
      "name": "Rock_Volcanic_Brick"
    },
    {
      "x": -4,
      "y": 32,
      "z": -3,
      "name": "Rock_Volcanic_Brick"
    },
    {
      "x": -4,
      "y": 33,
      "z": -3,
      "name": "Rock_Volcanic_Brick"
    },
    {
      "x": -4,
      "y": 34,
      "z": -3,
      "name": "Rock_Volcanic_Cobble"
    },
    {
      "x": -4,
      "y": 35,
      "z": -3,
      "name": "Rock_Volcanic_Brick"
    },
    {
      "x": -4,
      "y": 36,
      "z": -3,
      "name": "Rock_Volcanic_Cobble"
    },
    {
      "x": -4,
      "y": 37,
      "z": -3,
      "name": "Rock_Volcanic_Brick"
    },
    {
      "x": -4,
      "y": 38,
      "z": -3,
      "name": "Rock_Volcanic_Brick"
    },
    {
      "x": -4,
      "y": 39,
      "z": -3,
      "name": "Rock_Volcanic_Brick"
    },
    {
      "x": -4,
      "y": 40,
      "z": -3,
      "name": "Rock_Volcanic_Cobble"
    },
    {
      "x": -4,
      "y": 41,
      "z": -3,
      "name": "Rock_Volcanic_Cobble"
    },
    {
      "x": -4,
      "y": 42,
      "z": -3,
      "name": "Rock_Volcanic_Cobble"
    },
    {
      "x": -4,
      "y": 43,
      "z": -3,
      "name": "Rock_Volcanic_Cobble"
    },
    {
      "x": -4,
      "y": 44,
      "z": -3,
      "name": "Rock_Volcanic_Cobble"
    },
    {
      "x": -4,
      "y": 45,
      "z": -3,
      "name": "Rock_Volcanic_Cobble"
    },
    {
      "x": -4,
      "y": 46,
      "z": -3,
      "name": "Rock_Volcanic_Brick"
    },
    {
      "x": -4,
      "y": 47,
      "z": -3,
      "name": "Rock_Volcanic_Cobble"
    },
    {
      "x": -4,
      "y": 48,
      "z": -3,
      "name": "Rock_Volcanic_Cobble"
    },
    {
      "x": -4,
      "y": 49,
      "z": -3,
      "name": "Rock_Volcanic_Cobble"
    },
    {
      "x": -4,
      "y": 50,
      "z": -3,
      "name": "Rock_Volcanic_Cobble"
    },
    {
      "x": -4,
      "y": 51,
      "z": -3,
      "name": "*Rock_Volcanic_Brick_Wall_State_Definitions_Corner",
      "rotation": 3
    },
    {
      "x": -4,
      "y": 53,
      "z": -3,
      "name": "Rock_Crystal_Green_Block"
    },
    {
      "x": -4,
      "y": 54,
      "z": -3,
      "name": "Rock_Crystal_Green_Block"
    },
    {
      "x": -4,
      "y": 55,
      "z": -3,
      "name": "Rock_Crystal_Green_Block"
    },
    {
      "x": -4,
      "y": 56,
      "z": -3,
      "name": "Rock_Crystal_Green_Block"
    },
    {
      "x": -4,
      "y": 57,
      "z": -3,
      "name": "Rock_Crystal_Green_Block"
    },
    {
      "x": -4,
      "y": 58,
      "z": -3,
      "name": "Rock_Crystal_Green_Block"
    },
    {
      "x": -4,
      "y": 59,
      "z": -3,
      "name": "Rock_Crystal_Green_Block"
    },
    {
      "x": -4,
      "y": 61,
      "z": -3,
      "name": "*Rock_Volcanic_Brick_Wall_State_Definitions_Corner",
      "rotation": 3
    },
    {
      "x": -4,
      "y": 62,
      "z": -3,
      "name": "Rock_Volcanic_Cobble",
      "rotation": 1
    },
    {
      "x": -4,
      "y": 63,
      "z": -3,
      "name": "Rock_Volcanic_Cobble",
      "rotation": 1
    },
    {
      "x": -4,
      "y": 64,
      "z": -3,
      "name": "Rock_Volcanic_Brick",
      "rotation": 1
    },
    {
      "x": -4,
      "y": 65,
      "z": -3,
      "name": "Rock_Volcanic_Cobble",
      "rotation": 1
    },
    {
      "x": -4,
      "y": 66,
      "z": -3,
      "name": "Rock_Volcanic_Cobble",
      "rotation": 1
    },
    {
      "x": -4,
      "y": 67,
      "z": -3,
      "name": "*Rock_Volcanic_Brick_Wall_State_Definitions_Corner",
      "rotation": 3
    },
    {
      "x": -4,
      "y": -25,
      "z": -2,
      "name": "Rock_Volcanic_Brick"
    },
    {
      "x": -4,
      "y": -24,
      "z": -2,
      "name": "Rock_Volcanic_Cobble"
    },
    {
      "x": -4,
      "y": -23,
      "z": -2,
      "name": "Rock_Volcanic_Brick"
    },
    {
      "x": -4,
      "y": -22,
      "z": -2,
      "name": "Rock_Volcanic_Cobble"
    },
    {
      "x": -4,
      "y": -21,
      "z": -2,
      "name": "Rock_Volcanic_Brick"
    },
    {
      "x": -4,
      "y": -20,
      "z": -2,
      "name": "Rock_Volcanic_Brick"
    },
    {
      "x": -4,
      "y": -19,
      "z": -2,
      "name": "Rock_Volcanic_Brick"
    },
    {
      "x": -4,
      "y": -18,
      "z": -2,
      "name": "Rock_Volcanic_Brick"
    },
    {
      "x": -4,
      "y": -17,
      "z": -2,
      "name": "Rock_Volcanic_Brick"
    },
    {
      "x": -4,
      "y": -16,
      "z": -2,
      "name": "Rock_Volcanic_Cobble"
    },
    {
      "x": -4,
      "y": -15,
      "z": -2,
      "name": "Rock_Volcanic_Cobble"
    },
    {
      "x": -4,
      "y": -14,
      "z": -2,
      "name": "Rock_Volcanic_Brick"
    },
    {
      "x": -4,
      "y": -13,
      "z": -2,
      "name": "Rock_Volcanic_Brick"
    },
    {
      "x": -4,
      "y": -12,
      "z": -2,
      "name": "Rock_Volcanic_Cobble"
    },
    {
      "x": -4,
      "y": -11,
      "z": -2,
      "name": "Rock_Volcanic_Brick"
    },
    {
      "x": -4,
      "y": -10,
      "z": -2,
      "name": "Rock_Volcanic_Cobble"
    },
    {
      "x": -4,
      "y": -9,
      "z": -2,
      "name": "Rock_Volcanic_Cobble"
    },
    {
      "x": -4,
      "y": -8,
      "z": -2,
      "name": "Rock_Volcanic_Brick"
    },
    {
      "x": -4,
      "y": -7,
      "z": -2,
      "name": "Rock_Volcanic_Cobble"
    },
    {
      "x": -4,
      "y": -6,
      "z": -2,
      "name": "Rock_Volcanic_Cobble"
    },
    {
      "x": -4,
      "y": -5,
      "z": -2,
      "name": "Rock_Volcanic_Cobble"
    },
    {
      "x": -4,
      "y": -4,
      "z": -2,
      "name": "Rock_Volcanic_Cobble"
    },
    {
      "x": -4,
      "y": -3,
      "z": -2,
      "name": "Rock_Volcanic_Cobble"
    },
    {
      "x": -4,
      "y": -2,
      "z": -2,
      "name": "Rock_Volcanic_Brick"
    },
    {
      "x": -4,
      "y": -1,
      "z": -2,
      "name": "Rock_Volcanic_Brick"
    },
    {
      "x": -4,
      "y": 0,
      "z": -2,
      "name": "Rock_Volcanic_Cobble"
    },
    {
      "x": -4,
      "y": 1,
      "z": -2,
      "name": "Rock_Volcanic_Brick"
    },
    {
      "x": -4,
      "y": 2,
      "z": -2,
      "name": "Rock_Volcanic_Cobble"
    },
    {
      "x": -4,
      "y": 3,
      "z": -2,
      "name": "Rock_Volcanic_Cobble"
    },
    {
      "x": -4,
      "y": 4,
      "z": -2,
      "name": "Rock_Volcanic_Brick"
    },
    {
      "x": -4,
      "y": 5,
      "z": -2,
      "name": "Rock_Volcanic_Cobble"
    },
    {
      "x": -4,
      "y": 6,
      "z": -2,
      "name": "Rock_Volcanic_Cobble"
    },
    {
      "x": -4,
      "y": 7,
      "z": -2,
      "name": "Rock_Volcanic_Brick"
    },
    {
      "x": -4,
      "y": 8,
      "z": -2,
      "name": "Rock_Volcanic_Brick"
    },
    {
      "x": -4,
      "y": 9,
      "z": -2,
      "name": "Rock_Volcanic_Brick"
    },
    {
      "x": -4,
      "y": 10,
      "z": -2,
      "name": "Rock_Volcanic_Brick"
    },
    {
      "x": -4,
      "y": 11,
      "z": -2,
      "name": "Rock_Volcanic_Brick"
    },
    {
      "x": -4,
      "y": 12,
      "z": -2,
      "name": "Rock_Volcanic_Brick"
    },
    {
      "x": -4,
      "y": 13,
      "z": -2,
      "name": "Rock_Volcanic_Brick"
    },
    {
      "x": -4,
      "y": 14,
      "z": -2,
      "name": "Rock_Volcanic_Cobble"
    },
    {
      "x": -4,
      "y": 15,
      "z": -2,
      "name": "Rock_Volcanic_Brick"
    },
    {
      "x": -4,
      "y": 16,
      "z": -2,
      "name": "Rock_Volcanic_Brick"
    },
    {
      "x": -4,
      "y": 17,
      "z": -2,
      "name": "Rock_Volcanic_Brick"
    },
    {
      "x": -4,
      "y": 18,
      "z": -2,
      "name": "Rock_Volcanic_Brick"
    },
    {
      "x": -4,
      "y": 19,
      "z": -2,
      "name": "Rock_Volcanic_Brick"
    },
    {
      "x": -4,
      "y": 20,
      "z": -2,
      "name": "Rock_Volcanic_Cobble"
    },
    {
      "x": -4,
      "y": 21,
      "z": -2,
      "name": "Rock_Volcanic_Brick"
    },
    {
      "x": -4,
      "y": 22,
      "z": -2,
      "name": "Rock_Volcanic_Brick"
    },
    {
      "x": -4,
      "y": 23,
      "z": -2,
      "name": "Rock_Volcanic_Cobble"
    },
    {
      "x": -4,
      "y": 24,
      "z": -2,
      "name": "Rock_Volcanic_Brick"
    },
    {
      "x": -4,
      "y": 25,
      "z": -2,
      "name": "Rock_Volcanic_Cobble"
    },
    {
      "x": -4,
      "y": 26,
      "z": -2,
      "name": "Rock_Volcanic_Brick"
    },
    {
      "x": -4,
      "y": 27,
      "z": -2,
      "name": "Rock_Volcanic_Cobble"
    },
    {
      "x": -4,
      "y": 28,
      "z": -2,
      "name": "Rock_Volcanic_Brick"
    },
    {
      "x": -4,
      "y": 29,
      "z": -2,
      "name": "Rock_Volcanic_Brick"
    },
    {
      "x": -4,
      "y": 30,
      "z": -2,
      "name": "Rock_Volcanic_Brick"
    },
    {
      "x": -4,
      "y": 31,
      "z": -2,
      "name": "Rock_Volcanic_Brick"
    },
    {
      "x": -4,
      "y": 32,
      "z": -2,
      "name": "Rock_Volcanic_Brick"
    },
    {
      "x": -4,
      "y": 33,
      "z": -2,
      "name": "Rock_Volcanic_Brick"
    },
    {
      "x": -4,
      "y": 34,
      "z": -2,
      "name": "Rock_Volcanic_Brick"
    },
    {
      "x": -4,
      "y": 35,
      "z": -2,
      "name": "Rock_Volcanic_Brick"
    },
    {
      "x": -4,
      "y": 36,
      "z": -2,
      "name": "Rock_Volcanic_Cobble"
    },
    {
      "x": -4,
      "y": 37,
      "z": -2,
      "name": "Rock_Volcanic_Brick"
    },
    {
      "x": -4,
      "y": 38,
      "z": -2,
      "name": "Rock_Volcanic_Brick"
    },
    {
      "x": -4,
      "y": 39,
      "z": -2,
      "name": "Rock_Volcanic_Cobble"
    },
    {
      "x": -4,
      "y": 40,
      "z": -2,
      "name": "Rock_Volcanic_Brick"
    },
    {
      "x": -4,
      "y": 41,
      "z": -2,
      "name": "Rock_Volcanic_Brick"
    },
    {
      "x": -4,
      "y": 42,
      "z": -2,
      "name": "Rock_Volcanic_Brick"
    },
    {
      "x": -4,
      "y": 43,
      "z": -2,
      "name": "Rock_Volcanic_Cobble"
    },
    {
      "x": -4,
      "y": 44,
      "z": -2,
      "name": "Rock_Volcanic_Cobble"
    },
    {
      "x": -4,
      "y": 45,
      "z": -2,
      "name": "Rock_Volcanic_Brick"
    },
    {
      "x": -4,
      "y": 46,
      "z": -2,
      "name": "Rock_Volcanic_Cobble"
    },
    {
      "x": -4,
      "y": 47,
      "z": -2,
      "name": "Rock_Volcanic_Cobble"
    },
    {
      "x": -4,
      "y": 48,
      "z": -2,
      "name": "Rock_Volcanic_Brick"
    },
    {
      "x": -4,
      "y": 49,
      "z": -2,
      "name": "Rock_Volcanic_Cobble"
    },
    {
      "x": -4,
      "y": 50,
      "z": -2,
      "name": "Rock_Volcanic_Cobble"
    },
    {
      "x": -4,
      "y": 53,
      "z": -2,
      "name": "Rock_Crystal_Green_Block"
    },
    {
      "x": -4,
      "y": 54,
      "z": -2,
      "name": "Rock_Crystal_Green_Block"
    },
    {
      "x": -4,
      "y": 55,
      "z": -2,
      "name": "Rock_Crystal_Green_Block"
    },
    {
      "x": -4,
      "y": 56,
      "z": -2,
      "name": "Rock_Crystal_Green_Block"
    },
    {
      "x": -4,
      "y": 57,
      "z": -2,
      "name": "Rock_Crystal_Green_Block"
    },
    {
      "x": -4,
      "y": 58,
      "z": -2,
      "name": "Rock_Crystal_Green_Block"
    },
    {
      "x": -4,
      "y": 59,
      "z": -2,
      "name": "Rock_Crystal_Green_Block"
    },
    {
      "x": -4,
      "y": 62,
      "z": -2,
      "name": "Rock_Volcanic_Cobble",
      "rotation": 1
    },
    {
      "x": -4,
      "y": 63,
      "z": -2,
      "name": "Rock_Volcanic_Cobble",
      "rotation": 1
    },
    {
      "x": -4,
      "y": 64,
      "z": -2,
      "name": "Rock_Volcanic_Cobble",
      "rotation": 1
    },
    {
      "x": -4,
      "y": 65,
      "z": -2,
      "name": "Rock_Volcanic_Brick",
      "rotation": 1
    },
    {
      "x": -4,
      "y": 66,
      "z": -2,
      "name": "Rock_Volcanic_Brick",
      "rotation": 1
    },
    {
      "x": -4,
      "y": -25,
      "z": -1,
      "name": "Rock_Volcanic_Brick"
    },
    {
      "x": -4,
      "y": -24,
      "z": -1,
      "name": "Rock_Volcanic_Cobble"
    },
    {
      "x": -4,
      "y": -23,
      "z": -1,
      "name": "Rock_Volcanic_Brick"
    },
    {
      "x": -4,
      "y": -22,
      "z": -1,
      "name": "Rock_Volcanic_Brick"
    },
    {
      "x": -4,
      "y": -21,
      "z": -1,
      "name": "Rock_Volcanic_Brick"
    },
    {
      "x": -4,
      "y": -20,
      "z": -1,
      "name": "Rock_Volcanic_Brick"
    },
    {
      "x": -4,
      "y": -19,
      "z": -1,
      "name": "Rock_Volcanic_Brick"
    },
    {
      "x": -4,
      "y": -18,
      "z": -1,
      "name": "Rock_Volcanic_Brick"
    },
    {
      "x": -4,
      "y": -17,
      "z": -1,
      "name": "Rock_Volcanic_Brick"
    },
    {
      "x": -4,
      "y": -16,
      "z": -1,
      "name": "Rock_Volcanic_Cobble"
    },
    {
      "x": -4,
      "y": -15,
      "z": -1,
      "name": "Rock_Volcanic_Brick"
    },
    {
      "x": -4,
      "y": -14,
      "z": -1,
      "name": "Rock_Volcanic_Brick"
    },
    {
      "x": -4,
      "y": -13,
      "z": -1,
      "name": "Rock_Volcanic_Brick"
    },
    {
      "x": -4,
      "y": -12,
      "z": -1,
      "name": "Rock_Volcanic_Brick"
    },
    {
      "x": -4,
      "y": -11,
      "z": -1,
      "name": "Rock_Volcanic_Cobble"
    },
    {
      "x": -4,
      "y": -10,
      "z": -1,
      "name": "Rock_Volcanic_Cobble"
    },
    {
      "x": -4,
      "y": -9,
      "z": -1,
      "name": "Rock_Volcanic_Cobble"
    },
    {
      "x": -4,
      "y": -8,
      "z": -1,
      "name": "Rock_Volcanic_Cobble"
    },
    {
      "x": -4,
      "y": -7,
      "z": -1,
      "name": "Rock_Volcanic_Brick"
    },
    {
      "x": -4,
      "y": -6,
      "z": -1,
      "name": "Rock_Volcanic_Cobble"
    },
    {
      "x": -4,
      "y": -5,
      "z": -1,
      "name": "Rock_Volcanic_Cobble"
    },
    {
      "x": -4,
      "y": -4,
      "z": -1,
      "name": "Rock_Volcanic_Brick"
    },
    {
      "x": -4,
      "y": -3,
      "z": -1,
      "name": "Rock_Volcanic_Brick"
    },
    {
      "x": -4,
      "y": -2,
      "z": -1,
      "name": "Rock_Volcanic_Cobble"
    },
    {
      "x": -4,
      "y": -1,
      "z": -1,
      "name": "Rock_Volcanic_Brick"
    },
    {
      "x": -4,
      "y": 0,
      "z": -1,
      "name": "Rock_Volcanic_Cobble"
    },
    {
      "x": -4,
      "y": 1,
      "z": -1,
      "name": "Rock_Volcanic_Cobble"
    },
    {
      "x": -4,
      "y": 2,
      "z": -1,
      "name": "Rock_Volcanic_Cobble"
    },
    {
      "x": -4,
      "y": 3,
      "z": -1,
      "name": "Rock_Volcanic_Cobble"
    },
    {
      "x": -4,
      "y": 4,
      "z": -1,
      "name": "Rock_Volcanic_Brick"
    },
    {
      "x": -4,
      "y": 5,
      "z": -1,
      "name": "Rock_Volcanic_Brick"
    },
    {
      "x": -4,
      "y": 6,
      "z": -1,
      "name": "Rock_Volcanic_Brick"
    },
    {
      "x": -4,
      "y": 7,
      "z": -1,
      "name": "Rock_Volcanic_Brick"
    },
    {
      "x": -4,
      "y": 8,
      "z": -1,
      "name": "Rock_Volcanic_Brick"
    },
    {
      "x": -4,
      "y": 9,
      "z": -1,
      "name": "Rock_Volcanic_Cobble"
    },
    {
      "x": -4,
      "y": 10,
      "z": -1,
      "name": "Rock_Volcanic_Brick"
    },
    {
      "x": -4,
      "y": 11,
      "z": -1,
      "name": "Rock_Volcanic_Brick"
    },
    {
      "x": -4,
      "y": 12,
      "z": -1,
      "name": "Rock_Volcanic_Brick"
    },
    {
      "x": -4,
      "y": 13,
      "z": -1,
      "name": "Rock_Volcanic_Cobble"
    },
    {
      "x": -4,
      "y": 14,
      "z": -1,
      "name": "Rock_Volcanic_Cobble"
    },
    {
      "x": -4,
      "y": 15,
      "z": -1,
      "name": "Rock_Volcanic_Brick"
    },
    {
      "x": -4,
      "y": 16,
      "z": -1,
      "name": "Rock_Volcanic_Cobble"
    },
    {
      "x": -4,
      "y": 17,
      "z": -1,
      "name": "Rock_Volcanic_Brick"
    },
    {
      "x": -4,
      "y": 18,
      "z": -1,
      "name": "Rock_Volcanic_Brick"
    },
    {
      "x": -4,
      "y": 19,
      "z": -1,
      "name": "Rock_Volcanic_Brick"
    },
    {
      "x": -4,
      "y": 20,
      "z": -1,
      "name": "Rock_Volcanic_Brick"
    },
    {
      "x": -4,
      "y": 21,
      "z": -1,
      "name": "Rock_Volcanic_Brick"
    },
    {
      "x": -4,
      "y": 22,
      "z": -1,
      "name": "Rock_Volcanic_Brick"
    },
    {
      "x": -4,
      "y": 23,
      "z": -1,
      "name": "Rock_Volcanic_Brick"
    },
    {
      "x": -4,
      "y": 24,
      "z": -1,
      "name": "Rock_Volcanic_Brick"
    },
    {
      "x": -4,
      "y": 25,
      "z": -1,
      "name": "Rock_Volcanic_Brick"
    },
    {
      "x": -4,
      "y": 26,
      "z": -1,
      "name": "Rock_Volcanic_Cobble"
    },
    {
      "x": -4,
      "y": 27,
      "z": -1,
      "name": "Rock_Volcanic_Brick"
    },
    {
      "x": -4,
      "y": 28,
      "z": -1,
      "name": "Rock_Volcanic_Brick"
    },
    {
      "x": -4,
      "y": 29,
      "z": -1,
      "name": "Rock_Volcanic_Brick"
    },
    {
      "x": -4,
      "y": 30,
      "z": -1,
      "name": "Rock_Volcanic_Cobble"
    },
    {
      "x": -4,
      "y": 31,
      "z": -1,
      "name": "Rock_Volcanic_Cobble"
    },
    {
      "x": -4,
      "y": 32,
      "z": -1,
      "name": "Rock_Volcanic_Brick"
    },
    {
      "x": -4,
      "y": 33,
      "z": -1,
      "name": "Rock_Volcanic_Cobble"
    },
    {
      "x": -4,
      "y": 34,
      "z": -1,
      "name": "Rock_Volcanic_Brick"
    },
    {
      "x": -4,
      "y": 35,
      "z": -1,
      "name": "Rock_Volcanic_Brick"
    },
    {
      "x": -4,
      "y": 36,
      "z": -1,
      "name": "Rock_Volcanic_Brick"
    },
    {
      "x": -4,
      "y": 37,
      "z": -1,
      "name": "Rock_Volcanic_Cobble"
    },
    {
      "x": -4,
      "y": 38,
      "z": -1,
      "name": "Rock_Volcanic_Cobble"
    },
    {
      "x": -4,
      "y": 39,
      "z": -1,
      "name": "Rock_Volcanic_Brick"
    },
    {
      "x": -4,
      "y": 40,
      "z": -1,
      "name": "Rock_Volcanic_Cobble"
    },
    {
      "x": -4,
      "y": 41,
      "z": -1,
      "name": "Rock_Volcanic_Cobble"
    },
    {
      "x": -4,
      "y": 42,
      "z": -1,
      "name": "Rock_Volcanic_Brick"
    },
    {
      "x": -4,
      "y": 43,
      "z": -1,
      "name": "Rock_Volcanic_Brick"
    },
    {
      "x": -4,
      "y": 44,
      "z": -1,
      "name": "Rock_Volcanic_Cobble"
    },
    {
      "x": -4,
      "y": 45,
      "z": -1,
      "name": "Rock_Volcanic_Brick"
    },
    {
      "x": -4,
      "y": 46,
      "z": -1,
      "name": "Rock_Volcanic_Brick"
    },
    {
      "x": -4,
      "y": 47,
      "z": -1,
      "name": "Rock_Volcanic_Cobble",
      "rotation": 1
    },
    {
      "x": -4,
      "y": 48,
      "z": -1,
      "name": "Rock_Volcanic_Cobble",
      "rotation": 1
    },
    {
      "x": -4,
      "y": 49,
      "z": -1,
      "name": "Rock_Volcanic_Cobble",
      "rotation": 1
    },
    {
      "x": -4,
      "y": 50,
      "z": -1,
      "name": "Rock_Volcanic_Cobble",
      "rotation": 1
    },
    {
      "x": -4,
      "y": 53,
      "z": -1,
      "name": "Rock_Crystal_Green_Block",
      "rotation": 1
    },
    {
      "x": -4,
      "y": 54,
      "z": -1,
      "name": "Rock_Crystal_Green_Block",
      "rotation": 1
    },
    {
      "x": -4,
      "y": 55,
      "z": -1,
      "name": "Rock_Crystal_Green_Block",
      "rotation": 1
    },
    {
      "x": -4,
      "y": 56,
      "z": -1,
      "name": "Rock_Crystal_Green_Block",
      "rotation": 1
    },
