{
  "version": 8,
  "blockIdVersion": 11,
  "anchorX": 0,
  "anchorY": 30,
  "anchorZ": 0,
  "blocks": [
    {
      "x": -31,
      "y": 23,
      "z": -1,
      "name": "Deco_Bone_Full",
      "rotation": 1
    },
    {
      "x": -31,
      "y": 24,
      "z": -1,
      "name": "Deco_Bone_Full",
      "rotation": 1
    },
    {
      "x": -31,
      "y": 25,
      "z": -1,
      "name": "Deco_Bone_Full",
      "rotation": 1
    },
    {
      "x": -31,
      "y": 26,
      "z": -1,
      "name": "Deco_Bone_Full",
      "rotation": 1
    },
    {
      "x": -31,
      "y": 27,
      "z": -1,
      "name": "Soil_Roots_Poisoned",
      "rotation": 1
    },
    {
      "x": -31,
      "y": 28,
      "z": -1,
      "name": "Soil_Roots_Poisoned",
      "rotation": 1
    },
    {
      "x": -31,
      "y": 0,
      "z": 0,
      "name": "Soil_Grass"
    },
    {
      "x": -31,
      "y": 22,
      "z": 0,
      "name": "Deco_Bone_Full",
      "rotation": 1
    },
    {
      "x": -31,
      "y": 23,
      "z": 0,
      "name": "Deco_Bone_Full",
      "rotation": 1
    },
    {
      "x": -31,
      "y": 24,
      "z": 0,
      "name": "Deco_Bone_Full",
      "rotation": 1
    },
    {
      "x": -31,
      "y": 25,
      "z": 0,
      "name": "Deco_Bone_Full",
      "rotation": 1
    },
    {
      "x": -31,
      "y": 26,
      "z": 0,
      "name": "Deco_Bone_Full",
      "rotation": 1
    },
    {
      "x": -31,
      "y": 27,
      "z": 0,
      "name": "Soil_Roots_Poisoned",
      "rotation": 1
    },
    {
      "x": -31,
      "y": 28,
      "z": 0,
      "name": "Soil_Roots_Poisoned",
      "rotation": 1
    },
    {
      "x": -31,
      "y": 0,
      "z": 1,
      "name": "Soil_Grass"
    },
    {
      "x": -31,
      "y": 0,
      "z": 2,
      "name": "Soil_Grass"
    },
    {
      "x": -31,
      "y": 0,
      "z": 3,
      "name": "Soil_Grass"
    },
    {
      "x": -31,
      "y": 0,
      "z": 4,
      "name": "Soil_Grass"
    },
    {
      "x": -31,
      "y": 0,
      "z": 5,
      "name": "Soil_Grass"
    },
    {
      "x": -31,
      "y": 0,
      "z": 6,
      "name": "Soil_Grass"
    },
    {
      "x": -31,
      "y": 24,
      "z": 6,
      "name": "Deco_Bone_Full",
      "rotation": 1
    },
    {
      "x": -31,
      "y": 25,
      "z": 6,
      "name": "Soil_Hive_Corrupted",
      "rotation": 1
    },
    {
      "x": -31,
      "y": 26,
      "z": 6,
      "name": "Soil_Hive_Corrupted",
      "rotation": 1
    },
    {
      "x": -31,
      "y": 0,
      "z": 7,
      "name": "Soil_Grass"
    },
    {
      "x": -31,
      "y": 17,
      "z": 7,
      "name": "Deco_Bone_Full",
      "rotation": 1
    },
    {
      "x": -31,
      "y": 18,
      "z": 7,
      "name": "Deco_Bone_Full",
      "rotation": 1
    },
    {
      "x": -31,
      "y": 19,
      "z": 7,
      "name": "Deco_Bone_Full",
      "rotation": 1
    },
    {
      "x": -31,
      "y": 20,
      "z": 7,
      "name": "Deco_Bone_Full",
      "rotation": 1
    },
    {
      "x": -31,
      "y": 21,
      "z": 7,
      "name": "Deco_Bone_Full",
      "rotation": 1
    },
    {
      "x": -31,
      "y": 22,
      "z": 7,
      "name": "Deco_Bone_Full",
      "rotation": 1
    },
    {
      "x": -31,
      "y": 23,
      "z": 7,
      "name": "Soil_Hive_Corrupted",
      "rotation": 1
    },
    {
      "x": -31,
      "y": 24,
      "z": 7,
      "name": "Soil_Hive_Corrupted",
      "rotation": 1
    },
    {
      "x": -31,
      "y": 0,
      "z": 8,
      "name": "Soil_Grass"
    },
    {
      "x": -31,
      "y": 0,
      "z": 9,
      "name": "Soil_Grass"
    },
    {
      "x": -31,
      "y": 0,
      "z": 10,
      "name": "Soil_Grass"
    },
    {
      "x": -31,
      "y": 0,
      "z": 11,
      "name": "Soil_Grass"
    },
    {
      "x": -31,
      "y": 0,
      "z": 12,
      "name": "Soil_Grass"
    },
    {
      "x": -31,
      "y": 0,
      "z": 13,
      "name": "Soil_Grass"
    },
    {
      "x": -31,
      "y": 0,
      "z": 14,
      "name": "Soil_Grass"
    },
    {
      "x": -31,
      "y": 0,
      "z": 15,
      "name": "Soil_Grass"
    },
    {
      "x": -30,
      "y": 0,
      "z": -15,
      "name": "Soil_Grass"
    },
    {
      "x": -30,
      "y": 0,
      "z": -14,
      "name": "Soil_Grass"
    },
    {
      "x": -30,
      "y": 0,
      "z": -13,
      "name": "Soil_Grass"
    },
    {
      "x": -30,
      "y": 0,
      "z": -12,
      "name": "Soil_Grass"
    },
    {
      "x": -30,
      "y": 0,
      "z": -11,
      "name": "Soil_Grass"
    },
    {
      "x": -30,
      "y": 0,
      "z": -10,
      "name": "Soil_Grass"
    },
    {
      "x": -30,
      "y": 0,
      "z": -9,
      "name": "Soil_Grass"
    },
    {
      "x": -30,
      "y": 0,
      "z": -8,
      "name": "Soil_Grass"
    },
    {
      "x": -30,
      "y": 0,
      "z": -7,
      "name": "Soil_Grass"
    },
    {
      "x": -30,
      "y": 0,
      "z": -6,
      "name": "Soil_Grass"
    },
    {
      "x": -30,
      "y": 0,
      "z": -5,
      "name": "Soil_Grass"
    },
    {
      "x": -30,
      "y": 0,
      "z": -4,
      "name": "Soil_Grass"
    },
    {
      "x": -30,
      "y": 0,
      "z": -3,
      "name": "Soil_Grass"
    },
    {
      "x": -30,
      "y": 0,
      "z": -2,
      "name": "Soil_Grass"
    },
    {
      "x": -30,
      "y": 29,
      "z": -2,
      "name": "Deco_Bone_Full",
      "rotation": 1
    },
    {
      "x": -30,
      "y": 30,
      "z": -2,
      "name": "Deco_Bone_Full",
      "rotation": 1
    },
    {
      "x": -30,
      "y": 31,
      "z": -2,
      "name": "Deco_Bone_Full",
      "rotation": 1
    },
    {
      "x": -30,
      "y": 32,
      "z": -2,
      "name": "Deco_Bone_Full",
      "rotation": 1
    },
    {
      "x": -30,
      "y": 33,
      "z": -2,
      "name": "Soil_Hive_Corrupted",
      "rotation": 1
    },
    {
      "x": -30,
      "y": 34,
      "z": -2,
      "name": "Soil_Roots_Poisoned",
      "rotation": 1
    },
    {
      "x": -30,
      "y": 0,
      "z": -1,
      "name": "Soil_Grass"
    },
    {
      "x": -30,
      "y": 22,
      "z": -1,
      "name": "Deco_Bone_Full",
      "rotation": 1
    },
    {
      "x": -30,
      "y": 23,
      "z": -1,
      "name": "Deco_Bone_Full",
      "rotation": 1
    },
    {
      "x": -30,
      "y": 24,
      "z": -1,
      "name": "Deco_Bone_Full",
      "rotation": 1
    },
    {
      "x": -30,
      "y": 25,
      "z": -1,
      "name": "Deco_Bone_Full",
      "rotation": 1
    },
    {
      "x": -30,
      "y": 26,
      "z": -1,
      "name": "Deco_Bone_Full",
      "rotation": 1
    },
    {
      "x": -30,
      "y": 27,
      "z": -1,
      "name": "Deco_Bone_Full",
      "rotation": 1
    },
    {
      "x": -30,
      "y": 28,
      "z": -1,
      "name": "Deco_Bone_Full",
      "rotation": 1
    },
    {
      "x": -30,
      "y": 29,
      "z": -1,
      "name": "Deco_Bone_Full",
      "rotation": 1
    },
    {
      "x": -30,
      "y": 30,
      "z": -1,
      "name": "Deco_Bone_Full",
      "rotation": 1
    },
    {
      "x": -30,
      "y": 31,
      "z": -1,
      "name": "Deco_Bone_Full",
      "rotation": 1
    },
    {
      "x": -30,
      "y": 32,
      "z": -1,
      "name": "Deco_Bone_Full",
      "rotation": 1
    },
    {
      "x": -30,
      "y": 33,
      "z": -1,
      "name": "Soil_Roots_Poisoned",
      "rotation": 1
    },
    {
      "x": -30,
      "y": 34,
      "z": -1,
      "name": "Soil_Hive_Corrupted",
      "rotation": 1
    },
    {
      "x": -30,
      "y": 0,
      "z": 0,
      "name": "Soil_Grass"
    },
    {
      "x": -30,
      "y": 18,
      "z": 0,
      "name": "Deco_Bone_Full",
      "rotation": 1
    },
    {
      "x": -30,
      "y": 19,
      "z": 0,
      "name": "Deco_Bone_Full",
      "rotation": 1
    },
    {
      "x": -30,
      "y": 20,
      "z": 0,
      "name": "Deco_Bone_Full",
      "rotation": 1
    },
    {
      "x": -30,
      "y": 21,
      "z": 0,
      "name": "Deco_Bone_Full",
      "rotation": 1
    },
    {
      "x": -30,
      "y": 22,
      "z": 0,
      "name": "Deco_Bone_Full",
      "rotation": 1
    },
    {
      "x": -30,
      "y": 23,
      "z": 0,
      "name": "Deco_Bone_Full",
      "rotation": 1
    },
    {
      "x": -30,
      "y": 24,
      "z": 0,
      "name": "Deco_Bone_Full",
      "rotation": 1
    },
    {
      "x": -30,
      "y": 25,
      "z": 0,
      "name": "Deco_Bone_Full",
      "rotation": 1
    },
    {
      "x": -30,
      "y": 26,
      "z": 0,
      "name": "Deco_Bone_Full",
      "rotation": 1
    },
    {
      "x": -30,
      "y": 27,
      "z": 0,
      "name": "Deco_Bone_Full",
      "rotation": 1
    },
    {
      "x": -30,
      "y": 28,
      "z": 0,
      "name": "Deco_Bone_Full",
      "rotation": 1
    },
    {
      "x": -30,
      "y": 29,
      "z": 0,
      "name": "Deco_Bone_Full",
      "rotation": 1
    },
    {
      "x": -30,
      "y": 30,
      "z": 0,
      "name": "Deco_Bone_Full",
      "rotation": 1
    },
    {
      "x": -30,
      "y": 31,
      "z": 0,
      "name": "Deco_Bone_Full",
      "rotation": 1
    },
    {
      "x": -30,
      "y": 32,
      "z": 0,
      "name": "Soil_Roots_Poisoned",
      "rotation": 1
    },
    {
      "x": -30,
      "y": 33,
      "z": 0,
      "name": "Soil_Hive_Corrupted",
      "rotation": 1
    },
    {
      "x": -30,
      "y": 0,
      "z": 1,
      "name": "Soil_Grass"
    },
    {
      "x": -30,
      "y": 18,
      "z": 1,
      "name": "Deco_Bone_Full",
      "rotation": 1
    },
    {
      "x": -30,
      "y": 19,
      "z": 1,
      "name": "Deco_Bone_Full",
      "rotation": 1
    },
    {
      "x": -30,
      "y": 20,
      "z": 1,
      "name": "Deco_Bone_Full",
      "rotation": 1
    },
    {
      "x": -30,
      "y": 21,
      "z": 1,
      "name": "Deco_Bone_Full",
      "rotation": 1
    },
    {
      "x": -30,
      "y": 22,
      "z": 1,
      "name": "Deco_Bone_Full",
      "rotation": 1
    },
    {
      "x": -30,
      "y": 23,
      "z": 1,
      "name": "Deco_Bone_Full",
      "rotation": 1
    },
    {
      "x": -30,
      "y": 24,
      "z": 1,
      "name": "Deco_Bone_Full",
      "rotation": 1
    },
    {
      "x": -30,
      "y": 25,
      "z": 1,
      "name": "Deco_Bone_Full",
      "rotation": 1
    },
    {
      "x": -30,
      "y": 26,
      "z": 1,
      "name": "Deco_Bone_Full",
      "rotation": 1
    },
    {
      "x": -30,
      "y": 27,
      "z": 1,
      "name": "Deco_Bone_Full",
      "rotation": 1
    },
    {
      "x": -30,
      "y": 28,
      "z": 1,
      "name": "Deco_Bone_Full",
      "rotation": 1
    },
    {
      "x": -30,
      "y": 29,
      "z": 1,
      "name": "Soil_Hive_Corrupted",
      "rotation": 1
    },
    {
      "x": -30,
      "y": 30,
      "z": 1,
      "name": "Soil_Hive_Corrupted",
      "rotation": 1
    },
    {
      "x": -30,
      "y": 0,
      "z": 2,
      "name": "Soil_Grass"
    },
    {
      "x": -30,
      "y": 0,
      "z": 3,
      "name": "Soil_Grass"
    },
    {
      "x": -30,
      "y": 0,
      "z": 4,
      "name": "Soil_Grass"
    },
    {
      "x": -30,
      "y": 0,
      "z": 5,
      "name": "Soil_Grass"
    },
    {
      "x": -30,
      "y": 25,
      "z": 5,
      "name": "Deco_Bone_Full",
      "rotation": 1
    },
    {
      "x": -30,
      "y": 26,
      "z": 5,
      "name": "Deco_Bone_Full",
      "rotation": 1
    },
    {
      "x": -30,
      "y": 27,
      "z": 5,
      "name": "Deco_Bone_Full",
      "rotation": 1
    },
    {
      "x": -30,
      "y": 28,
      "z": 5,
      "name": "Deco_Bone_Full",
      "rotation": 1
    },
    {
      "x": -30,
      "y": 29,
      "z": 5,
      "name": "Deco_Bone_Full",
      "rotation": 1
    },
    {
      "x": -30,
      "y": 30,
      "z": 5,
      "name": "Soil_Hive_Corrupted",
      "rotation": 1
    },
    {
      "x": -30,
      "y": 31,
      "z": 5,
      "name": "Soil_Roots_Poisoned",
      "rotation": 1
    },
    {
      "x": -30,
      "y": 0,
      "z": 6,
      "name": "Soil_Grass"
    },
    {
      "x": -30,
      "y": 19,
      "z": 6,
      "name": "Deco_Bone_Full",
      "rotation": 1
    },
    {
      "x": -30,
      "y": 20,
      "z": 6,
      "name": "Deco_Bone_Full",
      "rotation": 1
    },
    {
      "x": -30,
      "y": 21,
      "z": 6,
      "name": "Deco_Bone_Full",
      "rotation": 1
    },
    {
      "x": -30,
      "y": 22,
      "z": 6,
      "name": "Deco_Bone_Full",
      "rotation": 1
    },
    {
      "x": -30,
      "y": 23,
      "z": 6,
      "name": "Deco_Bone_Full",
      "rotation": 1
    },
    {
      "x": -30,
      "y": 24,
      "z": 6,
      "name": "Deco_Bone_Full",
      "rotation": 1
    },
    {
      "x": -30,
      "y": 25,
      "z": 6,
      "name": "Deco_Bone_Full",
      "rotation": 1
    },
    {
      "x": -30,
      "y": 26,
      "z": 6,
      "name": "Deco_Bone_Full",
      "rotation": 1
    },
    {
      "x": -30,
      "y": 27,
      "z": 6,
      "name": "Deco_Bone_Full",
      "rotation": 1
    },
    {
      "x": -30,
      "y": 28,
      "z": 6,
      "name": "Deco_Bone_Full",
      "rotation": 1
    },
    {
      "x": -30,
      "y": 29,
      "z": 6,
      "name": "Soil_Hive_Corrupted",
      "rotation": 1
    },
    {
      "x": -30,
      "y": 30,
      "z": 6,
      "name": "Soil_Roots_Poisoned",
      "rotation": 1
    },
    {
      "x": -30,
      "y": 0,
      "z": 7,
      "name": "Soil_Grass"
    },
    {
      "x": -30,
      "y": 16,
      "z": 7,
      "name": "Deco_Bone_Full",
      "rotation": 1
    },
    {
      "x": -30,
      "y": 17,
      "z": 7,
      "name": "Deco_Bone_Full",
      "rotation": 1
    },
    {
      "x": -30,
      "y": 18,
      "z": 7,
      "name": "Deco_Bone_Full",
      "rotation": 1
    },
    {
      "x": -30,
      "y": 19,
      "z": 7,
      "name": "Deco_Bone_Full",
      "rotation": 1
    },
    {
      "x": -30,
      "y": 20,
      "z": 7,
      "name": "Deco_Bone_Full",
      "rotation": 1
    },
    {
      "x": -30,
      "y": 21,
      "z": 7,
      "name": "Deco_Bone_Full",
      "rotation": 1
    },
    {
      "x": -30,
      "y": 22,
      "z": 7,
      "name": "Deco_Bone_Full",
      "rotation": 1
    },
    {
      "x": -30,
      "y": 23,
      "z": 7,
      "name": "Deco_Bone_Full",
      "rotation": 1
    },
    {
      "x": -30,
      "y": 24,
      "z": 7,
      "name": "Deco_Bone_Full",
      "rotation": 1
    },
    {
      "x": -30,
      "y": 25,
      "z": 7,
      "name": "Deco_Bone_Full",
      "rotation": 1
    },
    {
      "x": -30,
      "y": 26,
      "z": 7,
      "name": "Deco_Bone_Full",
      "rotation": 1
    },
    {
      "x": -30,
      "y": 27,
      "z": 7,
      "name": "Deco_Bone_Full",
      "rotation": 1
    },
    {
      "x": -30,
      "y": 28,
      "z": 7,
      "name": "Soil_Roots_Poisoned",
      "rotation": 1
    },
    {
      "x": -30,
      "y": 29,
      "z": 7,
      "name": "Soil_Hive_Corrupted",
      "rotation": 1
    },
    {
      "x": -30,
      "y": 0,
      "z": 8,
      "name": "Soil_Grass"
    },
    {
      "x": -30,
      "y": 14,
      "z": 8,
      "name": "Deco_Bone_Full",
      "rotation": 1
    },
    {
      "x": -30,
      "y": 15,
      "z": 8,
      "name": "Deco_Bone_Full",
      "rotation": 1
    },
    {
      "x": -30,
      "y": 16,
      "z": 8,
      "name": "Deco_Bone_Full",
      "rotation": 1
    },
    {
      "x": -30,
      "y": 17,
      "z": 8,
      "name": "Deco_Bone_Full",
      "rotation": 1
    },
    {
      "x": -30,
      "y": 18,
      "z": 8,
      "name": "Deco_Bone_Full",
      "rotation": 1
    },
    {
      "x": -30,
      "y": 19,
      "z": 8,
      "name": "Deco_Bone_Full",
      "rotation": 1
    },
    {
      "x": -30,
      "y": 20,
      "z": 8,
      "name": "Deco_Bone_Full",
      "rotation": 1
    },
    {
      "x": -30,
      "y": 21,
      "z": 8,
      "name": "Deco_Bone_Full",
      "rotation": 1
    },
    {
      "x": -30,
      "y": 22,
      "z": 8,
      "name": "Deco_Bone_Full",
      "rotation": 1
    },
    {
      "x": -30,
      "y": 23,
      "z": 8,
      "name": "Deco_Bone_Full",
      "rotation": 1
    },
    {
      "x": -30,
      "y": 24,
      "z": 8,
      "name": "Soil_Roots_Poisoned",
      "rotation": 1
    },
    {
      "x": -30,
      "y": 25,
      "z": 8,
      "name": "Soil_Roots_Poisoned",
      "rotation": 1
    },
    {
      "x": -30,
      "y": 0,
      "z": 9,
      "name": "Soil_Grass"
    },
    {
      "x": -30,
      "y": 14,
      "z": 9,
      "name": "Deco_Bone_Full",
      "rotation": 1
    },
    {
      "x": -30,
      "y": 15,
      "z": 9,
      "name": "Deco_Bone_Full",
      "rotation": 1
    },
    {
      "x": -30,
      "y": 16,
      "z": 9,
      "name": "Deco_Bone_Full",
      "rotation": 1
    },
    {
      "x": -30,
      "y": 17,
      "z": 9,
      "name": "Deco_Bone_Full",
      "rotation": 1
    },
    {
      "x": -30,
      "y": 18,
      "z": 9,
      "name": "Deco_Bone_Full",
      "rotation": 1
    },
    {
      "x": -30,
      "y": 19,
      "z": 9,
      "name": "Deco_Bone_Full",
      "rotation": 1
    },
    {
      "x": -30,
      "y": 20,
      "z": 9,
      "name": "Soil_Roots_Poisoned",
      "rotation": 1
    },
    {
      "x": -30,
      "y": 21,
      "z": 9,
      "name": "Soil_Hive_Corrupted",
      "rotation": 1
    },
    {
      "x": -30,
      "y": 0,
      "z": 10,
      "name": "Soil_Grass"
    },
    {
      "x": -30,
      "y": 0,
      "z": 11,
      "name": "Soil_Grass"
    },
    {
      "x": -30,
      "y": 0,
      "z": 12,
      "name": "Soil_Grass"
    },
    {
      "x": -30,
      "y": 0,
      "z": 13,
      "name": "Soil_Grass"
    },
    {
      "x": -30,
      "y": 0,
      "z": 14,
      "name": "Soil_Grass"
    },
    {
      "x": -30,
      "y": 0,
      "z": 15,
      "name": "Soil_Grass"
    },
    {
      "x": -29,
      "y": 0,
      "z": -15,
      "name": "Soil_Grass"
    },
    {
      "x": -29,
      "y": 0,
      "z": -14,
      "name": "Soil_Grass"
    },
    {
      "x": -29,
      "y": 0,
      "z": -13,
      "name": "Soil_Grass"
    },
    {
      "x": -29,
      "y": 0,
      "z": -12,
      "name": "Soil_Grass"
    },
    {
      "x": -29,
      "y": 0,
      "z": -11,
      "name": "Soil_Grass"
    },
    {
      "x": -29,
      "y": 0,
      "z": -10,
      "name": "Soil_Grass"
    },
    {
      "x": -29,
      "y": 0,
      "z": -9,
      "name": "Soil_Grass"
    },
    {
      "x": -29,
      "y": 0,
      "z": -8,
      "name": "Soil_Grass"
    },
    {
      "x": -29,
      "y": 0,
      "z": -7,
      "name": "Soil_Grass"
    },
    {
      "x": -29,
      "y": 0,
      "z": -6,
      "name": "Soil_Grass"
    },
    {
      "x": -29,
      "y": 0,
      "z": -5,
      "name": "Soil_Grass"
    },
    {
      "x": -29,
      "y": 0,
      "z": -4,
      "name": "Soil_Grass"
    },
    {
      "x": -29,
      "y": 0,
      "z": -3,
      "name": "Soil_Grass"
    },
    {
      "x": -29,
      "y": 0,
      "z": -2,
      "name": "Soil_Grass"
    },
    {
      "x": -29,
      "y": 30,
      "z": -2,
      "name": "Deco_Bone_Full",
      "rotation": 1
    },
    {
      "x": -29,
      "y": 31,
      "z": -2,
      "name": "Deco_Bone_Full",
      "rotation": 1
    },
    {
      "x": -29,
      "y": 32,
      "z": -2,
      "name": "Deco_Bone_Full",
      "rotation": 1
    },
    {
      "x": -29,
      "y": 33,
      "z": -2,
      "name": "Deco_Bone_Full",
      "rotation": 1
    },
    {
      "x": -29,
      "y": 34,
      "z": -2,
      "name": "Deco_Bone_Full",
      "rotation": 1
    },
    {
      "x": -29,
      "y": 35,
      "z": -2,
      "name": "Soil_Hive_Corrupted",
      "rotation": 1
    },
    {
      "x": -29,
      "y": 36,
      "z": -2,
      "name": "Soil_Hive_Corrupted",
      "rotation": 1
    },
    {
      "x": -29,
      "y": 0,
      "z": -1,
      "name": "Soil_Grass"
    },
    {
      "x": -29,
      "y": 25,
      "z": -1,
      "name": "Deco_Bone_Full",
      "rotation": 1
    },
    {
      "x": -29,
      "y": 26,
      "z": -1,
      "name": "Deco_Bone_Full",
      "rotation": 1
    },
    {
      "x": -29,
      "y": 27,
      "z": -1,
      "name": "Deco_Bone_Full",
      "rotation": 1
    },
    {
      "x": -29,
      "y": 28,
      "z": -1,
      "name": "Deco_Bone_Full",
      "rotation": 1
    },
    {
      "x": -29,
      "y": 29,
      "z": -1,
      "name": "Deco_Bone_Full",
      "rotation": 1
    },
    {
      "x": -29,
      "y": 30,
      "z": -1,
      "name": "Deco_Bone_Full",
      "rotation": 1
    },
    {
      "x": -29,
      "y": 31,
      "z": -1,
      "name": "Deco_Bone_Full",
      "rotation": 1
    },
    {
      "x": -29,
      "y": 32,
      "z": -1,
      "name": "Deco_Bone_Full",
      "rotation": 1
    },
    {
      "x": -29,
      "y": 33,
      "z": -1,
      "name": "Deco_Bone_Full",
      "rotation": 1
    },
    {
      "x": -29,
      "y": 34,
      "z": -1,
      "name": "Deco_Bone_Full",
      "rotation": 1
    },
    {
      "x": -29,
      "y": 35,
      "z": -1,
      "name": "Soil_Roots_Poisoned",
      "rotation": 1
    },
    {
      "x": -29,
      "y": 36,
      "z": -1,
      "name": "Soil_Hive_Corrupted",
      "rotation": 1
    },
    {
      "x": -29,
      "y": 0,
      "z": 0,
      "name": "Soil_Grass"
    },
    {
      "x": -29,
      "y": 17,
      "z": 0,
      "name": "Deco_Bone_Full",
      "rotation": 1
    },
    {
      "x": -29,
      "y": 18,
      "z": 0,
      "name": "Deco_Bone_Full",
      "rotation": 1
    },
    {
      "x": -29,
      "y": 19,
      "z": 0,
      "name": "Deco_Bone_Full",
      "rotation": 1
    },
    {
      "x": -29,
      "y": 20,
      "z": 0,
      "name": "Deco_Bone_Full",
      "rotation": 1
    },
    {
      "x": -29,
      "y": 21,
      "z": 0,
      "name": "Deco_Bone_Full",
      "rotation": 1
    },
    {
      "x": -29,
      "y": 22,
      "z": 0,
      "name": "Deco_Bone_Full",
      "rotation": 1
    },
    {
      "x": -29,
      "y": 23,
      "z": 0,
      "name": "Deco_Bone_Full",
      "rotation": 1
    },
    {
      "x": -29,
      "y": 24,
      "z": 0,
      "name": "Deco_Bone_Full",
      "rotation": 1
    },
    {
      "x": -29,
      "y": 25,
      "z": 0,
      "name": "Deco_Bone_Full",
      "rotation": 1
    },
    {
      "x": -29,
      "y": 26,
      "z": 0,
      "name": "Deco_Bone_Full",
      "rotation": 1
    },
    {
      "x": -29,
      "y": 27,
      "z": 0,
      "name": "Deco_Bone_Full",
      "rotation": 1
    },
    {
      "x": -29,
      "y": 28,
      "z": 0,
      "name": "Deco_Bone_Full",
      "rotation": 1
    },
    {
      "x": -29,
      "y": 29,
      "z": 0,
      "name": "Deco_Bone_Full",
      "rotation": 1
    },
    {
      "x": -29,
      "y": 30,
      "z": 0,
      "name": "Deco_Bone_Full",
      "rotation": 1
    },
    {
      "x": -29,
      "y": 31,
      "z": 0,
      "name": "Deco_Bone_Full",
      "rotation": 1
    },
    {
      "x": -29,
      "y": 32,
      "z": 0,
      "name": "Deco_Bone_Full",
      "rotation": 1
    },
    {
      "x": -29,
      "y": 33,
      "z": 0,
      "name": "Deco_Bone_Full",
      "rotation": 1
    },
    {
      "x": -29,
      "y": 34,
      "z": 0,
      "name": "Soil_Hive_Corrupted",
      "rotation": 1
    },
    {
      "x": -29,
      "y": 35,
      "z": 0,
      "name": "Soil_Roots_Poisoned",
      "rotation": 1
    },
    {
      "x": -29,
      "y": 0,
      "z": 1,
      "name": "Soil_Grass"
    },
    {
      "x": -29,
      "y": 15,
      "z": 1,
      "name": "Deco_Bone_Full",
      "rotation": 1
    },
    {
      "x": -29,
      "y": 16,
      "z": 1,
      "name": "Deco_Bone_Full",
      "rotation": 1
    },
    {
      "x": -29,
      "y": 17,
      "z": 1,
      "name": "Deco_Bone_Full",
      "rotation": 1
    },
    {
      "x": -29,
      "y": 18,
      "z": 1,
      "name": "Deco_Bone_Full",
      "rotation": 1
    },
    {
      "x": -29,
      "y": 19,
      "z": 1,
      "name": "Deco_Bone_Full",
      "rotation": 1
    },
    {
      "x": -29,
      "y": 20,
      "z": 1,
      "name": "Deco_Bone_Full",
      "rotation": 1
    },
    {
      "x": -29,
      "y": 21,
      "z": 1,
      "name": "Deco_Bone_Full",
      "rotation": 1
    },
    {
      "x": -29,
      "y": 22,
      "z": 1,
      "name": "Deco_Bone_Full",
      "rotation": 1
    },
    {
      "x": -29,
      "y": 23,
      "z": 1,
      "name": "Deco_Bone_Full",
      "rotation": 1
    },
    {
      "x": -29,
      "y": 24,
      "z": 1,
      "name": "Deco_Bone_Full",
      "rotation": 1
    },
    {
      "x": -29,
      "y": 25,
      "z": 1,
      "name": "Deco_Bone_Full",
      "rotation": 1
    },
    {
      "x": -29,
      "y": 26,
      "z": 1,
      "name": "Deco_Bone_Full",
      "rotation": 1
    },
    {
      "x": -29,
      "y": 27,
      "z": 1,
      "name": "Deco_Bone_Full",
      "rotation": 1
    },
    {
      "x": -29,
      "y": 28,
      "z": 1,
      "name": "Deco_Bone_Full",
      "rotation": 1
    },
    {
      "x": -29,
      "y": 29,
      "z": 1,
      "name": "Deco_Bone_Full",
      "rotation": 1
    },
    {
      "x": -29,
      "y": 30,
      "z": 1,
      "name": "Deco_Bone_Full",
      "rotation": 1
    },
    {
      "x": -29,
      "y": 31,
      "z": 1,
      "name": "Soil_Roots_Poisoned",
      "rotation": 1
    },
    {
      "x": -29,
      "y": 32,
      "z": 1,
      "name": "Soil_Roots_Poisoned",
      "rotation": 1
    },
    {
      "x": -29,
      "y": 0,
      "z": 2,
      "name": "Soil_Grass"
    },
    {
      "x": -29,
      "y": 16,
      "z": 2,
      "name": "Deco_Bone_Full",
      "rotation": 1
    },
    {
      "x": -29,
      "y": 17,
      "z": 2,
      "name": "Deco_Bone_Full",
      "rotation": 1
    },
    {
      "x": -29,
      "y": 18,
      "z": 2,
      "name": "Deco_Bone_Full",
      "rotation": 1
    },
    {
      "x": -29,
      "y": 19,
      "z": 2,
      "name": "Deco_Bone_Full",
      "rotation": 1
    },
    {
      "x": -29,
      "y": 20,
      "z": 2,
      "name": "Deco_Bone_Full",
      "rotation": 1
    },
    {
      "x": -29,
      "y": 21,
      "z": 2,
      "name": "Deco_Bone_Full",
      "rotation": 1
    },
    {
      "x": -29,
      "y": 22,
      "z": 2,
      "name": "Deco_Bone_Full",
      "rotation": 1
    },
    {
      "x": -29,
      "y": 23,
      "z": 2,
      "name": "Deco_Bone_Full",
      "rotation": 1
    },
    {
      "x": -29,
      "y": 24,
      "z": 2,
      "name": "Deco_Bone_Full",
      "rotation": 1
    },
    {
      "x": -29,
      "y": 25,
      "z": 2,
      "name": "Soil_Roots_Poisoned",
      "rotation": 1
    },
    {
      "x": -29,
      "y": 26,
      "z": 2,
      "name": "Soil_Hive_Corrupted",
      "rotation": 1
    },
    {
      "x": -29,
      "y": 0,
      "z": 3,
      "name": "Soil_Grass"
    },
    {
      "x": -29,
      "y": 0,
      "z": 4,
      "name": "Soil_Grass"
    },
    {
      "x": -29,
      "y": 30,
      "z": 4,
      "name": "Deco_Bone_Full",
      "rotation": 1
    },
    {
      "x": -29,
      "y": 31,
      "z": 4,
      "name": "Deco_Bone_Full",
      "rotation": 1
    },
    {
      "x": -29,
      "y": 32,
      "z": 4,
      "name": "Deco_Bone_Full",
      "rotation": 1
    },
    {
      "x": -29,
      "y": 33,
      "z": 4,
      "name": "Soil_Roots_Poisoned",
      "rotation": 1
    },
    {
      "x": -29,
      "y": 34,
      "z": 4,
      "name": "Soil_Hive_Corrupted",
      "rotation": 1
    },
    {
      "x": -29,
      "y": 0,
      "z": 5,
      "name": "Soil_Grass"
    },
    {
      "x": -29,
      "y": 26,
      "z": 5,
      "name": "Deco_Bone_Full",
      "rotation": 1
    },
    {
      "x": -29,
      "y": 27,
      "z": 5,
      "name": "Deco_Bone_Full",
      "rotation": 1
    },
    {
      "x": -29,
      "y": 28,
      "z": 5,
      "name": "Deco_Bone_Full",
      "rotation": 1
    },
    {
      "x": -29,
      "y": 29,
      "z": 5,
      "name": "Deco_Bone_Full",
      "rotation": 1
    },
    {
      "x": -29,
      "y": 30,
      "z": 5,
      "name": "Deco_Bone_Full",
      "rotation": 1
    },
    {
      "x": -29,
      "y": 31,
      "z": 5,
      "name": "Deco_Bone_Full",
      "rotation": 1
    },
    {
      "x": -29,
      "y": 32,
      "z": 5,
      "name": "Deco_Bone_Full",
      "rotation": 1
    },
    {
      "x": -29,
      "y": 33,
      "z": 5,
      "name": "Soil_Roots_Poisoned",
      "rotation": 1
    },
    {
      "x": -29,
      "y": 34,
      "z": 5,
      "name": "Soil_Roots_Poisoned",
      "rotation": 1
    },
    {
      "x": -29,
      "y": 0,
      "z": 6,
      "name": "Soil_Grass"
    },
    {
      "x": -29,
      "y": 22,
      "z": 6,
      "name": "Deco_Bone_Full",
      "rotation": 1
    },
    {
      "x": -29,
      "y": 23,
      "z": 6,
      "name": "Deco_Bone_Full",
      "rotation": 1
    },
    {
      "x": -29,
      "y": 24,
      "z": 6,
      "name": "Deco_Bone_Full",
      "rotation": 1
    },
    {
      "x": -29,
      "y": 25,
      "z": 6,
      "name": "Deco_Bone_Full",
      "rotation": 1
    },
    {
      "x": -29,
      "y": 26,
      "z": 6,
      "name": "Deco_Bone_Full",
      "rotation": 1
    },
    {
      "x": -29,
      "y": 27,
      "z": 6,
      "name": "Deco_Bone_Full",
      "rotation": 1
    },
    {
      "x": -29,
      "y": 28,
      "z": 6,
      "name": "Deco_Bone_Full",
      "rotation": 1
    },
    {
      "x": -29,
      "y": 29,
      "z": 6,
      "name": "Deco_Bone_Full",
      "rotation": 1
    },
    {
      "x": -29,
      "y": 30,
      "z": 6,
      "name": "Deco_Bone_Full",
      "rotation": 1
    },
    {
      "x": -29,
      "y": 31,
      "z": 6,
      "name": "Deco_Bone_Full",
      "rotation": 1
    },
    {
      "x": -29,
      "y": 32,
      "z": 6,
      "name": "Soil_Roots_Poisoned",
      "rotation": 1
    },
    {
      "x": -29,
      "y": 33,
      "z": 6,
      "name": "Soil_Roots_Poisoned",
      "rotation": 1
    },
    {
      "x": -29,
      "y": 0,
      "z": 7,
      "name": "Soil_Grass"
    },
    {
      "x": -29,
      "y": 15,
      "z": 7,
      "name": "Soil_Hive_Corrupted",
      "rotation": 1
    },
    {
      "x": -29,
      "y": 17,
      "z": 7,
      "name": "Deco_Bone_Full",
      "rotation": 1
    },
    {
      "x": -29,
      "y": 18,
      "z": 7,
      "name": "Deco_Bone_Full",
      "rotation": 1
    },
    {
      "x": -29,
      "y": 19,
      "z": 7,
      "name": "Deco_Bone_Full",
      "rotation": 1
    },
    {
      "x": -29,
      "y": 20,
      "z": 7,
      "name": "Deco_Bone_Full",
      "rotation": 1
    },
    {
      "x": -29,
      "y": 21,
      "z": 7,
      "name": "Deco_Bone_Full",
      "rotation": 1
    },
    {
      "x": -29,
      "y": 22,
      "z": 7,
      "name": "Deco_Bone_Full",
      "rotation": 1
    },
    {
      "x": -29,
      "y": 23,
      "z": 7,
      "name": "Deco_Bone_Full",
      "rotation": 1
    },
    {
      "x": -29,
      "y": 24,
      "z": 7,
      "name": "Deco_Bone_Full",
      "rotation": 1
    },
    {
      "x": -29,
      "y": 25,
      "z": 7,
      "name": "Deco_Bone_Full",
      "rotation": 1
    },
    {
      "x": -29,
      "y": 26,
      "z": 7,
      "name": "Deco_Bone_Full",
      "rotation": 1
    },
    {
      "x": -29,
      "y": 27,
      "z": 7,
      "name": "Deco_Bone_Full",
      "rotation": 1
    },
    {
      "x": -29,
      "y": 28,
      "z": 7,
      "name": "Deco_Bone_Full",
      "rotation": 1
    },
    {
      "x": -29,
      "y": 29,
      "z": 7,
      "name": "Soil_Roots_Poisoned",
      "rotation": 1
    },
    {
      "x": -29,
      "y": 30,
      "z": 7,
      "name": "Soil_Roots_Poisoned",
      "rotation": 1
    },
    {
      "x": -29,
      "y": 0,
      "z": 8,
      "name": "Soil_Grass"
    },
    {
      "x": -29,
      "y": 12,
      "z": 8,
      "name": "Deco_Bone_Full",
      "rotation": 1
    },
    {
      "x": -29,
      "y": 13,
      "z": 8,
      "name": "Deco_Bone_Full",
      "rotation": 1
    },
    {
      "x": -29,
      "y": 14,
      "z": 8,
      "name": "Deco_Bone_Full",
      "rotation": 1
    },
    {
      "x": -29,
      "y": 15,
      "z": 8,
      "name": "Deco_Bone_Full",
      "rotation": 1
    },
    {
      "x": -29,
      "y": 16,
      "z": 8,
      "name": "Deco_Bone_Full",
      "rotation": 1
    },
    {
      "x": -29,
      "y": 17,
      "z": 8,
      "name": "Deco_Bone_Full",
      "rotation": 1
    },
    {
      "x": -29,
      "y": 18,
      "z": 8,
      "name": "Deco_Bone_Full",
      "rotation": 1
    },
    {
      "x": -29,
      "y": 19,
      "z": 8,
      "name": "Deco_Bone_Full",
      "rotation": 1
    },
    {
      "x": -29,
      "y": 20,
      "z": 8,
      "name": "Deco_Bone_Full",
      "rotation": 1
    },
    {
      "x": -29,
      "y": 21,
      "z": 8,
      "name": "Deco_Bone_Full",
      "rotation": 1
    },
    {
      "x": -29,
      "y": 22,
      "z": 8,
      "name": "Deco_Bone_Full",
      "rotation": 1
    },
    {
      "x": -29,
      "y": 23,
      "z": 8,
      "name": "Deco_Bone_Full",
      "rotation": 1
    },
    {
      "x": -29,
      "y": 24,
      "z": 8,
      "name": "Deco_Bone_Full",
      "rotation": 1
    },
    {
      "x": -29,
      "y": 25,
      "z": 8,
      "name": "Deco_Bone_Full",
      "rotation": 1
    },
    {
      "x": -29,
      "y": 26,
      "z": 8,
      "name": "Soil_Hive_Corrupted",
      "rotation": 1
    },
    {
      "x": -29,
      "y": 27,
      "z": 8,
      "name": "Soil_Hive_Corrupted",
      "rotation": 1
    },
    {
      "x": -29,
      "y": 0,
      "z": 9,
      "name": "Soil_Grass"
    },
    {
      "x": -29,
      "y": 10,
      "z": 9,
      "name": "Deco_Bone_Full",
      "rotation": 1
    },
    {
      "x": -29,
      "y": 11,
      "z": 9,
      "name": "Deco_Bone_Full",
      "rotation": 1
    },
    {
      "x": -29,
      "y": 12,
      "z": 9,
      "name": "Deco_Bone_Full",
      "rotation": 1
    },
    {
      "x": -29,
      "y": 13,
      "z": 9,
      "name": "Deco_Bone_Full",
      "rotation": 1
    },
    {
      "x": -29,
      "y": 14,
      "z": 9,
      "name": "Deco_Bone_Full",
      "rotation": 1
    },
    {
      "x": -29,
      "y": 15,
      "z": 9,
      "name": "Deco_Bone_Full",
      "rotation": 1
    },
    {
      "x": -29,
      "y": 16,
      "z": 9,
      "name": "Deco_Bone_Full",
      "rotation": 1
    },
    {
      "x": -29,
      "y": 17,
      "z": 9,
      "name": "Deco_Bone_Full",
      "rotation": 1
    },
    {
      "x": -29,
      "y": 18,
      "z": 9,
      "name": "Deco_Bone_Full",
      "rotation": 1
    },
    {
      "x": -29,
      "y": 19,
      "z": 9,
      "name": "Deco_Bone_Full",
      "rotation": 1
    },
    {
      "x": -29,
      "y": 20,
      "z": 9,
      "name": "Deco_Bone_Full",
      "rotation": 1
    },
    {
      "x": -29,
      "y": 21,
      "z": 9,
      "name": "Deco_Bone_Full",
      "rotation": 1
    },
    {
      "x": -29,
      "y": 22,
      "z": 9,
      "name": "Soil_Roots_Poisoned",
      "rotation": 1
    },
    {
      "x": -29,
      "y": 23,
      "z": 9,
      "name": "Soil_Roots_Poisoned",
      "rotation": 1
    },
    {
      "x": -29,
      "y": 0,
      "z": 10,
      "name": "Soil_Grass"
    },
    {
      "x": -29,
      "y": 11,
      "z": 10,
      "name": "Deco_Bone_Full",
      "rotation": 1
    },
    {
      "x": -29,
      "y": 12,
      "z": 10,
      "name": "Deco_Bone_Full",
      "rotation": 1
    },
    {
      "x": -29,
      "y": 13,
      "z": 10,
      "name": "Deco_Bone_Full",
      "rotation": 1
    },
    {
      "x": -29,
      "y": 14,
      "z": 10,
      "name": "Deco_Bone_Full",
      "rotation": 1
    },
    {
      "x": -29,
      "y": 15,
      "z": 10,
      "name": "Deco_Bone_Full",
      "rotation": 1
    },
    {
      "x": -29,
      "y": 16,
      "z": 10,
      "name": "Soil_Roots_Poisoned",
      "rotation": 1
    },
    {
      "x": -29,
      "y": 17,
      "z": 10,
      "name": "Soil_Roots_Poisoned",
      "rotation": 1
    },
    {
      "x": -29,
      "y": 0,
      "z": 11,
      "name": "Soil_Grass"
    },
    {
      "x": -29,
      "y": 0,
      "z": 12,
      "name": "Soil_Grass"
    },
    {
      "x": -29,
      "y": 0,
      "z": 13,
      "name": "Soil_Grass"
    },
    {
      "x": -29,
      "y": 0,
      "z": 14,
      "name": "Soil_Grass"
    },
    {
      "x": -29,
      "y": 0,
      "z": 15,
      "name": "Soil_Grass"
    },
    {
      "x": -28,
      "y": 0,
      "z": -15,
      "name": "Soil_Grass"
    },
    {
      "x": -28,
      "y": 0,
      "z": -14,
      "name": "Soil_Grass"
    },
    {
      "x": -28,
      "y": 0,
      "z": -13,
      "name": "Soil_Grass"
    },
    {
      "x": -28,
      "y": 0,
      "z": -12,
      "name": "Soil_Grass"
    },
    {
      "x": -28,
      "y": 0,
      "z": -11,
      "name": "Soil_Grass"
    },
    {
      "x": -28,
      "y": 0,
      "z": -10,
      "name": "Soil_Grass"
    },
    {
      "x": -28,
      "y": 0,
      "z": -9,
      "name": "Soil_Grass"
    },
    {
      "x": -28,
      "y": 0,
      "z": -8,
      "name": "Soil_Grass"
    },
    {
      "x": -28,
      "y": 0,
      "z": -7,
      "name": "Soil_Grass"
    },
    {
      "x": -28,
      "y": 0,
      "z": -6,
      "name": "Soil_Grass"
    },
    {
      "x": -28,
      "y": 0,
      "z": -5,
      "name": "Soil_Grass"
    },
    {
      "x": -28,
      "y": 0,
      "z": -4,
      "name": "Soil_Grass"
    },
    {
      "x": -28,
      "y": 0,
      "z": -3,
      "name": "Soil_Grass"
    },
    {
      "x": -28,
      "y": 0,
      "z": -2,
      "name": "Soil_Grass"
    },
    {
      "x": -28,
      "y": 33,
      "z": -2,
      "name": "Deco_Bone_Full",
      "rotation": 1
    },
    {
      "x": -28,
      "y": 34,
      "z": -2,
      "name": "Deco_Bone_Full",
      "rotation": 1
    },
    {
      "x": -28,
      "y": 35,
      "z": -2,
      "name": "Deco_Bone_Full",
      "rotation": 1
    },
    {
      "x": -28,
      "y": 36,
      "z": -2,
      "name": "Deco_Bone_Full",
      "rotation": 1
    },
    {
      "x": -28,
      "y": 37,
      "z": -2,
      "name": "Soil_Hive_Corrupted",
      "rotation": 1
    },
    {
      "x": -28,
      "y": 38,
      "z": -2,
      "name": "Soil_Roots_Poisoned",
      "rotation": 1
    },
    {
      "x": -28,
      "y": 0,
      "z": -1,
      "name": "Soil_Grass"
    },
    {
      "x": -28,
      "y": 30,
      "z": -1,
      "name": "Deco_Bone_Full",
      "rotation": 1
    },
    {
      "x": -28,
      "y": 31,
      "z": -1,
      "name": "Deco_Bone_Full",
      "rotation": 1
    },
    {
      "x": -28,
      "y": 32,
      "z": -1,
      "name": "Deco_Bone_Full",
      "rotation": 1
    },
    {
      "x": -28,
      "y": 33,
      "z": -1,
      "name": "Deco_Bone_Full",
      "rotation": 1
    },
    {
      "x": -28,
      "y": 34,
      "z": -1,
      "name": "Deco_Bone_Full",
      "rotation": 1
    },
    {
      "x": -28,
      "y": 35,
      "z": -1,
      "name": "Deco_Bone_Full",
      "rotation": 1
    },
    {
      "x": -28,
      "y": 36,
      "z": -1,
      "name": "Deco_Bone_Full",
      "rotation": 1
    },
    {
      "x": -28,
      "y": 37,
      "z": -1,
      "name": "Soil_Hive_Corrupted",
      "rotation": 1
    },
    {
      "x": -28,
      "y": 38,
      "z": -1,
      "name": "Soil_Roots_Poisoned",
      "rotation": 1
    },
    {
      "x": -28,
      "y": 0,
      "z": 0,
      "name": "Soil_Grass"
    },
    {
      "x": -28,
      "y": 17,
      "z": 0,
      "name": "Soil_Roots_Poisoned",
      "rotation": 1
    },
    {
      "x": -28,
      "y": 18,
      "z": 0,
      "name": "Soil_Hive_Corrupted",
      "rotation": 1
    },
    {
      "x": -28,
      "y": 20,
      "z": 0,
      "name": "Soil_Roots_Poisoned",
      "rotation": 1
    },
    {
      "x": -28,
      "y": 27,
      "z": 0,
      "name": "Deco_Bone_Full",
      "rotation": 1
    },
    {
      "x": -28,
      "y": 28,
      "z": 0,
      "name": "Deco_Bone_Full",
      "rotation": 1
    },
    {
      "x": -28,
      "y": 29,
      "z": 0,
      "name": "Deco_Bone_Full",
      "rotation": 1
    },
    {
      "x": -28,
      "y": 30,
      "z": 0,
      "name": "Deco_Bone_Full",
      "rotation": 1
    },
    {
      "x": -28,
      "y": 31,
      "z": 0,
      "name": "Deco_Bone_Full",
      "rotation": 1
    },
    {
      "x": -28,
      "y": 32,
      "z": 0,
      "name": "Deco_Bone_Full",
      "rotation": 1
    },
    {
      "x": -28,
      "y": 33,
      "z": 0,
      "name": "Deco_Bone_Full",
      "rotation": 1
    },
    {
      "x": -28,
      "y": 34,
      "z": 0,
      "name": "Deco_Bone_Full",
      "rotation": 1
    },
    {
      "x": -28,
      "y": 35,
      "z": 0,
      "name": "Deco_Bone_Full",
      "rotation": 1
    },
    {
      "x": -28,
      "y": 36,
      "z": 0,
      "name": "Soil_Hive_Corrupted",
      "rotation": 1
    },
    {
      "x": -28,
      "y": 37,
      "z": 0,
      "name": "Soil_Roots_Poisoned",
      "rotation": 1
    },
    {
      "x": -28,
      "y": 0,
      "z": 1,
      "name": "Soil_Grass"
    },
    {
      "x": -28,
      "y": 14,
      "z": 1,
      "name": "Deco_Bone_Full",
      "rotation": 1
    },
    {
      "x": -28,
      "y": 15,
      "z": 1,
      "name": "Deco_Bone_Full",
      "rotation": 1
    },
    {
      "x": -28,
      "y": 16,
      "z": 1,
      "name": "Deco_Bone_Full",
      "rotation": 1
    },
    {
      "x": -28,
      "y": 17,
      "z": 1,
      "name": "Deco_Bone_Full",
      "rotation": 1
    },
    {
      "x": -28,
      "y": 18,
      "z": 1,
      "name": "Deco_Bone_Full",
      "rotation": 1
    },
    {
      "x": -28,
      "y": 19,
      "z": 1,
      "name": "Deco_Bone_Full",
      "rotation": 1
    },
    {
      "x": -28,
      "y": 20,
      "z": 1,
      "name": "Deco_Bone_Full",
      "rotation": 1
    },
    {
      "x": -28,
      "y": 21,
      "z": 1,
      "name": "Deco_Bone_Full",
      "rotation": 1
    },
    {
      "x": -28,
      "y": 22,
      "z": 1,
      "name": "Deco_Bone_Full",
      "rotation": 1
    },
    {
      "x": -28,
      "y": 23,
      "z": 1,
      "name": "Deco_Bone_Full",
      "rotation": 1
    },
    {
      "x": -28,
      "y": 24,
      "z": 1,
      "name": "Deco_Bone_Full",
      "rotation": 1
    },
    {
      "x": -28,
      "y": 25,
      "z": 1,
      "name": "Deco_Bone_Full",
      "rotation": 1
    },
    {
      "x": -28,
      "y": 26,
      "z": 1,
      "name": "Deco_Bone_Full",
      "rotation": 1
    },
    {
      "x": -28,
      "y": 27,
      "z": 1,
      "name": "Deco_Bone_Full",
      "rotation": 1
    },
    {
      "x": -28,
      "y": 28,
      "z": 1,
      "name": "Deco_Bone_Full",
      "rotation": 1
    },
    {
      "x": -28,
      "y": 29,
      "z": 1,
      "name": "Deco_Bone_Full",
      "rotation": 1
    },
    {
      "x": -28,
      "y": 30,
      "z": 1,
      "name": "Deco_Bone_Full",
      "rotation": 1
    },
    {
      "x": -28,
      "y": 31,
      "z": 1,
      "name": "Deco_Bone_Full",
      "rotation": 1
    },
    {
      "x": -28,
      "y": 32,
      "z": 1,
      "name": "Soil_Roots_Poisoned",
      "rotation": 1
    },
    {
      "x": -28,
      "y": 33,
      "z": 1,
      "name": "Soil_Hive_Corrupted",
      "rotation": 1
    },
    {
      "x": -28,
      "y": 0,
      "z": 2,
      "name": "Soil_Grass"
    },
    {
      "x": -28,
      "y": 14,
      "z": 2,
      "name": "Deco_Bone_Full",
      "rotation": 1
    },
    {
      "x": -28,
      "y": 15,
      "z": 2,
      "name": "Deco_Bone_Full",
      "rotation": 1
    },
    {
      "x": -28,
      "y": 16,
      "z": 2,
      "name": "Deco_Bone_Full",
      "rotation": 1
    },
    {
      "x": -28,
      "y": 17,
      "z": 2,
      "name": "Deco_Bone_Full",
      "rotation": 1
    },
    {
      "x": -28,
      "y": 18,
      "z": 2,
      "name": "Deco_Bone_Full",
      "rotation": 1
    },
    {
      "x": -28,
      "y": 19,
      "z": 2,
      "name": "Deco_Bone_Full",
      "rotation": 1
    },
    {
      "x": -28,
      "y": 20,
      "z": 2,
      "name": "Deco_Bone_Full",
      "rotation": 1
    },
    {
      "x": -28,
      "y": 21,
      "z": 2,
      "name": "Deco_Bone_Full",
      "rotation": 1
    },
    {
      "x": -28,
      "y": 22,
      "z": 2,
      "name": "Deco_Bone_Full",
      "rotation": 1
    },
    {
      "x": -28,
      "y": 23,
      "z": 2,
      "name": "Deco_Bone_Full",
      "rotation": 1
    },
    {
      "x": -28,
      "y": 24,
      "z": 2,
      "name": "Deco_Bone_Full",
      "rotation": 1
    },
    {
      "x": -28,
      "y": 25,
      "z": 2,
      "name": "Deco_Bone_Full",
      "rotation": 1
    },
    {
      "x": -28,
      "y": 26,
      "z": 2,
      "name": "Soil_Roots_Poisoned",
      "rotation": 1
    },
    {
      "x": -28,
      "y": 27,
      "z": 2,
      "name": "Soil_Roots_Poisoned",
      "rotation": 1
    },
    {
      "x": -28,
      "y": 0,
      "z": 3,
      "name": "Soil_Grass"
    },
    {
      "x": -28,
      "y": 0,
      "z": 4,
      "name": "Soil_Grass"
    },
    {
      "x": -28,
      "y": 31,
      "z": 4,
      "name": "Deco_Bone_Full",
      "rotation": 1
    },
    {
      "x": -28,
      "y": 32,
      "z": 4,
      "name": "Deco_Bone_Full",
      "rotation": 1
    },
    {
      "x": -28,
      "y": 33,
      "z": 4,
      "name": "Deco_Bone_Full",
      "rotation": 1
    },
    {
      "x": -28,
      "y": 34,
      "z": 4,
      "name": "Deco_Bone_Full",
      "rotation": 1
    },
    {
      "x": -28,
      "y": 35,
      "z": 4,
      "name": "Soil_Hive_Corrupted",
      "rotation": 1
    },
    {
      "x": -28,
      "y": 36,
      "z": 4,
      "name": "Soil_Hive_Corrupted",
      "rotation": 1
    },
    {
      "x": -28,
      "y": 0,
      "z": 5,
      "name": "Soil_Grass"
    },
    {
      "x": -28,
      "y": 29,
      "z": 5,
      "name": "Deco_Bone_Full",
      "rotation": 1
    },
    {
      "x": -28,
      "y": 30,
      "z": 5,
      "name": "Deco_Bone_Full",
      "rotation": 1
    },
    {
      "x": -28,
      "y": 31,
      "z": 5,
      "name": "Deco_Bone_Full",
      "rotation": 1
    },
    {
      "x": -28,
      "y": 32,
      "z": 5,
      "name": "Deco_Bone_Full",
      "rotation": 1
    },
    {
      "x": -28,
      "y": 33,
      "z": 5,
      "name": "Deco_Bone_Full",
      "rotation": 1
    },
    {
      "x": -28,
      "y": 34,
      "z": 5,
      "name": "Deco_Bone_Full",
      "rotation": 1
    },
    {
      "x": -28,
      "y": 35,
      "z": 5,
      "name": "Soil_Hive_Corrupted",
      "rotation": 1
    },
    {
      "x": -28,
      "y": 36,
      "z": 5,
      "name": "Soil_Hive_Corrupted",
      "rotation": 1
    },
    {
      "x": -28,
      "y": 0,
      "z": 6,
      "name": "Soil_Grass"
    },
    {
      "x": -28,
      "y": 26,
      "z": 6,
      "name": "Deco_Bone_Full",
      "rotation": 1
    },
    {
      "x": -28,
      "y": 27,
      "z": 6,
      "name": "Deco_Bone_Full",
      "rotation": 1
    },
    {
      "x": -28,
      "y": 28,
      "z": 6,
      "name": "Deco_Bone_Full",
      "rotation": 1
    },
    {
      "x": -28,
      "y": 29,
      "z": 6,
      "name": "Deco_Bone_Full",
      "rotation": 1
    },
    {
      "x": -28,
      "y": 30,
      "z": 6,
      "name": "Deco_Bone_Full",
      "rotation": 1
    },
    {
      "x": -28,
      "y": 31,
      "z": 6,
      "name": "Deco_Bone_Full",
      "rotation": 1
    },
    {
      "x": -28,
      "y": 32,
      "z": 6,
      "name": "Deco_Bone_Full",
      "rotation": 1
    },
    {
      "x": -28,
      "y": 33,
      "z": 6,
      "name": "Deco_Bone_Full",
      "rotation": 1
    },
    {
      "x": -28,
      "y": 34,
      "z": 6,
      "name": "Soil_Roots_Poisoned",
      "rotation": 1
    },
    {
      "x": -28,
      "y": 35,
      "z": 6,
      "name": "Soil_Hive_Corrupted",
      "rotation": 1
    },
    {
      "x": -28,
      "y": 0,
      "z": 7,
      "name": "Soil_Grass"
    },
    {
      "x": -28,
      "y": 23,
      "z": 7,
      "name": "Deco_Bone_Full",
      "rotation": 1
    },
    {
      "x": -28,
      "y": 24,
      "z": 7,
      "name": "Deco_Bone_Full",
      "rotation": 1
    },
    {
      "x": -28,
      "y": 25,
      "z": 7,
      "name": "Deco_Bone_Full",
      "rotation": 1
    },
    {
      "x": -28,
      "y": 26,
      "z": 7,
      "name": "Deco_Bone_Full",
      "rotation": 1
    },
    {
      "x": -28,
      "y": 27,
      "z": 7,
      "name": "Deco_Bone_Full",
      "rotation": 1
    },
    {
      "x": -28,
      "y": 28,
      "z": 7,
      "name": "Deco_Bone_Full",
      "rotation": 1
    },
    {
      "x": -28,
      "y": 29,
      "z": 7,
      "name": "Deco_Bone_Full",
      "rotation": 1
    },
    {
      "x": -28,
      "y": 30,
      "z": 7,
      "name": "Deco_Bone_Full",
      "rotation": 1
    },
    {
      "x": -28,
      "y": 31,
      "z": 7,
      "name": "Soil_Roots_Poisoned",
      "rotation": 1
    },
    {
      "x": -28,
      "y": 32,
      "z": 7,
      "name": "Soil_Roots_Poisoned",
      "rotation": 1
    },
    {
      "x": -28,
      "y": 0,
      "z": 8,
      "name": "Soil_Grass"
    },
    {
      "x": -28,
      "y": 11,
      "z": 8,
      "name": "Deco_Bone_Full",
      "rotation": 1
    },
    {
      "x": -28,
      "y": 12,
      "z": 8,
      "name": "Deco_Bone_Full",
      "rotation": 1
    },
    {
      "x": -28,
      "y": 13,
      "z": 8,
      "name": "Deco_Bone_Full",
      "rotation": 1
    },
    {
      "x": -28,
      "y": 14,
      "z": 8,
      "name": "Deco_Bone_Full",
      "rotation": 1
    },
    {
      "x": -28,
      "y": 15,
      "z": 8,
      "name": "Deco_Bone_Full",
      "rotation": 1
    },
    {
      "x": -28,
      "y": 16,
      "z": 8,
      "name": "Deco_Bone_Full",
      "rotation": 1
    },
    {
      "x": -28,
      "y": 17,
      "z": 8,
      "name": "Deco_Bone_Full",
      "rotation": 1
    },
    {
      "x": -28,
      "y": 18,
      "z": 8,
      "name": "Deco_Bone_Full",
      "rotation": 1
    },
    {
      "x": -28,
      "y": 19,
      "z": 8,
      "name": "Deco_Bone_Full",
      "rotation": 1
    },
    {
      "x": -28,
      "y": 20,
      "z": 8,
      "name": "Deco_Bone_Full",
      "rotation": 1
    },
    {
      "x": -28,
      "y": 21,
      "z": 8,
      "name": "Deco_Bone_Full",
      "rotation": 1
    },
    {
      "x": -28,
      "y": 22,
      "z": 8,
      "name": "Deco_Bone_Full",
      "rotation": 1
    },
    {
      "x": -28,
      "y": 23,
      "z": 8,
      "name": "Deco_Bone_Full",
      "rotation": 1
    },
    {
      "x": -28,
      "y": 24,
      "z": 8,
      "name": "Deco_Bone_Full",
      "rotation": 1
    },
    {
      "x": -28,
      "y": 25,
      "z": 8,
      "name": "Deco_Bone_Full",
      "rotation": 1
    },
    {
      "x": -28,
      "y": 26,
      "z": 8,
      "name": "Deco_Bone_Full",
      "rotation": 1
    },
    {
      "x": -28,
      "y": 27,
      "z": 8,
      "name": "Deco_Bone_Full",
      "rotation": 1
    },
    {
      "x": -28,
      "y": 28,
      "z": 8,
      "name": "Soil_Roots_Poisoned",
      "rotation": 1
    },
    {
      "x": -28,
      "y": 29,
      "z": 8,
      "name": "Soil_Roots_Poisoned",
      "rotation": 1
    },
    {
      "x": -28,
      "y": 0,
      "z": 9,
      "name": "Soil_Roots_Poisoned"
    },
    {
      "x": -28,
      "y": 9,
      "z": 9,
      "name": "Deco_Bone_Full",
      "rotation": 1
    },
    {
      "x": -28,
      "y": 10,
      "z": 9,
      "name": "Deco_Bone_Full",
      "rotation": 1
    },
    {
      "x": -28,
      "y": 11,
      "z": 9,
      "name": "Deco_Bone_Full",
      "rotation": 1
    },
    {
      "x": -28,
      "y": 12,
      "z": 9,
      "name": "Deco_Bone_Full",
      "rotation": 1
    },
    {
      "x": -28,
      "y": 13,
      "z": 9,
      "name": "Deco_Bone_Full",
      "rotation": 1
    },
    {
      "x": -28,
      "y": 14,
      "z": 9,
      "name": "Deco_Bone_Full",
      "rotation": 1
    },
    {
      "x": -28,
      "y": 15,
      "z": 9,
      "name": "Deco_Bone_Full",
      "rotation": 1
    },
    {
      "x": -28,
      "y": 16,
      "z": 9,
      "name": "Deco_Bone_Full",
      "rotation": 1
    },
    {
      "x": -28,
      "y": 17,
      "z": 9,
      "name": "Deco_Bone_Full",
      "rotation": 1
    },
    {
      "x": -28,
      "y": 18,
      "z": 9,
      "name": "Deco_Bone_Full",
      "rotation": 1
    },
    {
      "x": -28,
      "y": 19,
      "z": 9,
      "name": "Deco_Bone_Full",
      "rotation": 1
    },
    {
      "x": -28,
      "y": 20,
      "z": 9,
      "name": "Deco_Bone_Full",
      "rotation": 1
    },
    {
      "x": -28,
      "y": 21,
      "z": 9,
      "name": "Soil_Roots_Poisoned",
      "rotation": 1
    },
    {
      "x": -28,
      "y": 22,
      "z": 9,
      "name": "Soil_Hive_Corrupted",
      "rotation": 1
    },
    {
      "x": -28,
      "y": 0,
      "z": 10,
      "name": "Soil_Roots_Poisoned"
    },
    {
      "x": -28,
      "y": 8,
      "z": 10,
      "name": "Deco_Bone_Full",
      "rotation": 1
    },
    {
      "x": -28,
      "y": 9,
      "z": 10,
      "name": "Deco_Bone_Full",
      "rotation": 1
    },
    {
      "x": -28,
      "y": 10,
      "z": 10,
      "name": "Deco_Bone_Full",
      "rotation": 1
    },
    {
      "x": -28,
      "y": 11,
      "z": 10,
      "name": "Deco_Bone_Full",
      "rotation": 1
    },
    {
      "x": -28,
      "y": 12,
      "z": 10,
      "name": "Deco_Bone_Full",
      "rotation": 1
    },
    {
      "x": -28,
      "y": 13,
      "z": 10,
      "name": "Deco_Bone_Full",
      "rotation": 1
    },
    {
      "x": -28,
      "y": 14,
      "z": 10,
      "name": "Deco_Bone_Full",
      "rotation": 1
    },
    {
      "x": -28,
      "y": 15,
      "z": 10,
      "name": "Deco_Bone_Full",
      "rotation": 1
    },
    {
      "x": -28,
      "y": 16,
      "z": 10,
      "name": "Soil_Hive_Corrupted",
      "rotation": 1
    },
    {
      "x": -28,
      "y": 17,
      "z": 10,
      "name": "Soil_Roots_Poisoned",
      "rotation": 1
    },
    {
      "x": -28,
      "y": 0,
      "z": 11,
      "name": "Soil_Roots_Poisoned"
    },
    {
      "x": -28,
      "y": 0,
      "z": 12,
      "name": "Soil_Roots_Poisoned"
    },
    {
      "x": -28,
      "y": 0,
      "z": 13,
      "name": "Soil_Roots_Poisoned"
    },
    {
      "x": -28,
      "y": 0,
      "z": 14,
      "name": "Soil_Grass"
    },
    {
      "x": -28,
      "y": 0,
      "z": 15,
      "name": "Soil_Grass"
    },
    {
      "x": -27,
      "y": 0,
      "z": -15,
      "name": "Soil_Grass"
    },
    {
      "x": -27,
      "y": 0,
      "z": -14,
      "name": "Soil_Grass"
    },
    {
      "x": -27,
      "y": 0,
      "z": -13,
      "name": "Soil_Grass"
    },
    {
      "x": -27,
      "y": 0,
      "z": -12,
      "name": "Soil_Grass"
    },
    {
      "x": -27,
      "y": 0,
      "z": -11,
      "name": "Soil_Grass"
    },
    {
      "x": -27,
      "y": 0,
      "z": -10,
      "name": "Soil_Grass"
    },
    {
      "x": -27,
      "y": 0,
      "z": -9,
      "name": "Soil_Grass"
    },
    {
      "x": -27,
      "y": 0,
      "z": -8,
      "name": "Soil_Grass"
    },
    {
      "x": -27,
      "y": 0,
      "z": -7,
      "name": "Soil_Grass"
    },
    {
      "x": -27,
      "y": 0,
      "z": -6,
      "name": "Soil_Grass"
    },
    {
      "x": -27,
      "y": 0,
      "z": -5,
      "name": "Soil_Grass"
    },
    {
      "x": -27,
      "y": 0,
      "z": -4,
      "name": "Soil_Grass"
    },
    {
      "x": -27,
      "y": 0,
      "z": -3,
      "name": "Soil_Grass"
    },
    {
      "x": -27,
      "y": 37,
      "z": -3,
      "name": "Deco_Bone_Full",
      "rotation": 1
    },
    {
      "x": -27,
      "y": 38,
      "z": -3,
      "name": "Deco_Bone_Full",
      "rotation": 1
    },
    {
      "x": -27,
      "y": 39,
      "z": -3,
      "name": "Soil_Roots_Poisoned",
      "rotation": 1
    },
    {
      "x": -27,
      "y": 40,
      "z": -3,
      "name": "Soil_Hive_Corrupted",
      "rotation": 1
    },
    {
      "x": -27,
      "y": 0,
      "z": -2,
      "name": "Soil_Grass"
    },
    {
      "x": -27,
      "y": 35,
      "z": -2,
      "name": "Deco_Bone_Full",
      "rotation": 1
    },
    {
      "x": -27,
      "y": 36,
      "z": -2,
      "name": "Deco_Bone_Full",
      "rotation": 1
    },
    {
      "x": -27,
      "y": 37,
      "z": -2,
      "name": "Deco_Bone_Full",
      "rotation": 1
    },
    {
      "x": -27,
      "y": 38,
      "z": -2,
      "name": "Deco_Bone_Full",
      "rotation": 1
    },
    {
      "x": -27,
      "y": 39,
      "z": -2,
      "name": "Soil_Hive_Corrupted",
      "rotation": 1
    },
    {
      "x": -27,
      "y": 40,
      "z": -2,
      "name": "Soil_Hive_Corrupted",
      "rotation": 1
    },
    {
      "x": -27,
      "y": 0,
      "z": -1,
      "name": "Soil_Grass"
    },
    {
      "x": -27,
      "y": 33,
      "z": -1,
      "name": "Deco_Bone_Full",
      "rotation": 1
    },
    {
      "x": -27,
      "y": 34,
      "z": -1,
      "name": "Deco_Bone_Full",
      "rotation": 1
    },
    {
      "x": -27,
      "y": 35,
      "z": -1,
      "name": "Deco_Bone_Full",
      "rotation": 1
    },
    {
      "x": -27,
      "y": 36,
      "z": -1,
      "name": "Deco_Bone_Full",
      "rotation": 1
    },
    {
      "x": -27,
      "y": 37,
      "z": -1,
      "name": "Deco_Bone_Full",
      "rotation": 1
    },
    {
      "x": -27,
      "y": 38,
      "z": -1,
      "name": "Deco_Bone_Full",
      "rotation": 1
    },
    {
      "x": -27,
      "y": 39,
      "z": -1,
      "name": "Soil_Roots_Poisoned",
      "rotation": 1
    },
    {
      "x": -27,
      "y": 40,
      "z": -1,
      "name": "Soil_Hive_Corrupted",
      "rotation": 1
    },
    {
      "x": -27,
      "y": 0,
      "z": 0,
      "name": "Soil_Grass"
    },
    {
      "x": -27,
      "y": 32,
      "z": 0,
      "name": "Deco_Bone_Full",
      "rotation": 1
    },
    {
      "x": -27,
      "y": 33,
      "z": 0,
      "name": "Deco_Bone_Full",
      "rotation": 1
    },
    {
      "x": -27,
      "y": 34,
      "z": 0,
      "name": "Deco_Bone_Full",
      "rotation": 1
    },
    {
      "x": -27,
      "y": 35,
      "z": 0,
      "name": "Deco_Bone_Full",
      "rotation": 1
    },
    {
      "x": -27,
      "y": 36,
      "z": 0,
      "name": "Deco_Bone_Full",
      "rotation": 1
    },
    {
      "x": -27,
      "y": 37,
      "z": 0,
      "name": "Soil_Roots_Poisoned",
      "rotation": 1
    },
    {
      "x": -27,
      "y": 38,
      "z": 0,
      "name": "Soil_Roots_Poisoned",
      "rotation": 1
    },
    {
      "x": -27,
      "y": 0,
      "z": 1,
      "name": "Soil_Grass"
    },
    {
      "x": -27,
      "y": 14,
      "z": 1,
      "name": "Deco_Bone_Full",
      "rotation": 1
    },
    {
      "x": -27,
      "y": 15,
      "z": 1,
      "name": "Deco_Bone_Full",
      "rotation": 1
    },
    {
      "x": -27,
      "y": 16,
      "z": 1,
      "name": "Deco_Bone_Full",
      "rotation": 1
    },
    {
      "x": -27,
      "y": 17,
      "z": 1,
      "name": "Soil_Roots_Poisoned",
      "rotation": 1
    },
    {
      "x": -27,
      "y": 18,
      "z": 1,
      "name": "Soil_Hive_Corrupted",
      "rotation": 1
    },
    {
      "x": -27,
      "y": 0,
      "z": 2,
      "name": "Soil_Grass"
    },
    {
      "x": -27,
      "y": 12,
      "z": 2,
      "name": "Deco_Bone_Full",
      "rotation": 1
    },
    {
      "x": -27,
      "y": 13,
      "z": 2,
      "name": "Deco_Bone_Full",
      "rotation": 1
    },
    {
      "x": -27,
      "y": 14,
      "z": 2,
      "name": "Deco_Bone_Full",
      "rotation": 1
    },
    {
      "x": -27,
      "y": 15,
      "z": 2,
      "name": "Deco_Bone_Full",
      "rotation": 1
    },
    {
      "x": -27,
      "y": 16,
      "z": 2,
      "name": "Deco_Bone_Full",
      "rotation": 1
    },
    {
      "x": -27,
      "y": 17,
      "z": 2,
      "name": "Deco_Bone_Full",
      "rotation": 1
    },
    {
      "x": -27,
      "y": 18,
      "z": 2,
      "name": "Soil_Hive_Corrupted",
      "rotation": 1
    },
    {
      "x": -27,
      "y": 19,
      "z": 2,
      "name": "Soil_Roots_Poisoned",
      "rotation": 1
    },
    {
      "x": -27,
      "y": 0,
      "z": 3,
      "name": "Soil_Grass"
    },
    {
      "x": -27,
      "y": 14,
      "z": 3,
      "name": "Deco_Bone_Full",
      "rotation": 1
    },
    {
      "x": -27,
      "y": 15,
      "z": 3,
      "name": "Deco_Bone_Full",
      "rotation": 1
    },
    {
      "x": -27,
      "y": 16,
      "z": 3,
      "name": "Soil_Roots_Poisoned",
      "rotation": 1
    },
    {
      "x": -27,
      "y": 17,
      "z": 3,
      "name": "Soil_Hive_Corrupted",
      "rotation": 1
    },
    {
      "x": -27,
      "y": 35,
      "z": 3,
      "name": "Deco_Bone_Full",
      "rotation": 1
    },
    {
      "x": -27,
      "y": 36,
      "z": 3,
      "name": "Deco_Bone_Full",
      "rotation": 1
    },
    {
      "x": -27,
      "y": 37,
      "z": 3,
      "name": "Soil_Hive_Corrupted",
      "rotation": 1
    },
    {
      "x": -27,
      "y": 38,
      "z": 3,
      "name": "Soil_Roots_Poisoned",
      "rotation": 1
    },
    {
      "x": -27,
      "y": 0,
      "z": 4,
      "name": "Soil_Grass"
    },
    {
      "x": -27,
      "y": 33,
      "z": 4,
      "name": "Deco_Bone_Full",
      "rotation": 1
    },
    {
      "x": -27,
      "y": 34,
      "z": 4,
      "name": "Deco_Bone_Full",
      "rotation": 1
    },
    {
      "x": -27,
      "y": 35,
      "z": 4,
      "name": "Deco_Bone_Full",
      "rotation": 1
    },
    {
      "x": -27,
      "y": 36,
      "z": 4,
      "name": "Deco_Bone_Full",
      "rotation": 1
    },
    {
      "x": -27,
      "y": 37,
      "z": 4,
      "name": "Deco_Bone_Full",
      "rotation": 1
    },
    {
      "x": -27,
      "y": 38,
      "z": 4,
      "name": "Soil_Hive_Corrupted",
      "rotation": 1
    },
    {
      "x": -27,
      "y": 39,
      "z": 4,
      "name": "Soil_Hive_Corrupted",
      "rotation": 1
    },
    {
      "x": -27,
      "y": 0,
      "z": 5,
      "name": "Soil_Grass"
    },
    {
      "x": -27,
      "y": 31,
      "z": 5,
      "name": "Deco_Bone_Full",
      "rotation": 1
    },
    {
      "x": -27,
      "y": 32,
      "z": 5,
      "name": "Deco_Bone_Full",
      "rotation": 1
    },
    {
      "x": -27,
      "y": 33,
      "z": 5,
      "name": "Deco_Bone_Full",
      "rotation": 1
    },
    {
      "x": -27,
      "y": 34,
      "z": 5,
      "name": "Deco_Bone_Full",
      "rotation": 1
    },
    {
      "x": -27,
      "y": 35,
      "z": 5,
      "name": "Deco_Bone_Full",
      "rotation": 1
    },
    {
      "x": -27,
      "y": 36,
      "z": 5,
      "name": "Deco_Bone_Full",
      "rotation": 1
    },
    {
      "x": -27,
      "y": 37,
      "z": 5,
      "name": "Soil_Hive_Corrupted",
      "rotation": 1
    },
    {
      "x": -27,
      "y": 38,
      "z": 5,
      "name": "Soil_Hive_Corrupted",
      "rotation": 1
    },
    {
      "x": -27,
      "y": 0,
      "z": 6,
      "name": "Soil_Grass"
    },
    {
      "x": -27,
      "y": 30,
      "z": 6,
      "name": "Deco_Bone_Full",
      "rotation": 1
    },
    {
      "x": -27,
      "y": 31,
      "z": 6,
      "name": "Deco_Bone_Full",
      "rotation": 1
    },
    {
      "x": -27,
      "y": 32,
      "z": 6,
      "name": "Deco_Bone_Full",
      "rotation": 1
    },
    {
      "x": -27,
      "y": 33,
      "z": 6,
      "name": "Deco_Bone_Full",
      "rotation": 1
    },
    {
      "x": -27,
      "y": 34,
      "z": 6,
      "name": "Deco_Bone_Full",
      "rotation": 1
    },
    {
      "x": -27,
      "y": 35,
      "z": 6,
      "name": "Soil_Hive_Corrupted",
      "rotation": 1
    },
    {
      "x": -27,
      "y": 36,
      "z": 6,
      "name": "Soil_Roots_Poisoned",
      "rotation": 1
    },
    {
      "x": -27,
      "y": 0,
      "z": 7,
      "name": "Soil_Grass"
    },
    {
      "x": -27,
      "y": 29,
      "z": 7,
      "name": "Deco_Bone_Full",
      "rotation": 1
    },
    {
      "x": -27,
      "y": 30,
      "z": 7,
      "name": "Deco_Bone_Full",
      "rotation": 1
    },
    {
      "x": -27,
      "y": 31,
      "z": 7,
      "name": "Deco_Bone_Full",
      "rotation": 1
    },
    {
      "x": -27,
      "y": 32,
      "z": 7,
      "name": "Soil_Hive_Corrupted",
      "rotation": 1
    },
    {
      "x": -27,
      "y": 33,
      "z": 7,
      "name": "Soil_Hive_Corrupted",
      "rotation": 1
    },
    {
      "x": -27,
      "y": 0,
      "z": 8,
      "name": "Soil_Grass"
    },
    {
      "x": -27,
      "y": 0,
      "z": 9,
      "name": "Soil_Roots_Poisoned"
    },
    {
      "x": -27,
      "y": 8,
      "z": 9,
      "name": "Deco_Bone_Full",
      "rotation": 1
    },
    {
      "x": -27,
      "y": 9,
      "z": 9,
      "name": "Deco_Bone_Full",
      "rotation": 1
    },
    {
      "x": -27,
      "y": 10,
      "z": 9,
      "name": "Deco_Bone_Full",
      "rotation": 1
    },
    {
      "x": -27,
      "y": 11,
      "z": 9,
      "name": "Deco_Bone_Full",
      "rotation": 1
    },
    {
      "x": -27,
      "y": 12,
      "z": 9,
      "name": "Deco_Bone_Full",
      "rotation": 1
    },
    {
      "x": -27,
      "y": 13,
      "z": 9,
      "name": "Deco_Bone_Full",
      "rotation": 1
    },
    {
      "x": -27,
      "y": 14,
      "z": 9,
      "name": "Deco_Bone_Full",
      "rotation": 1
    },
    {
      "x": -27,
      "y": 15,
      "z": 9,
      "name": "Soil_Hive_Corrupted",
      "rotation": 1
    },
    {
      "x": -27,
      "y": 16,
      "z": 9,
      "name": "Soil_Roots_Poisoned",
      "rotation": 1
    },
    {
      "x": -27,
      "y": 0,
      "z": 10,
      "name": "Soil_Hive_Corrupted"
    },
    {
      "x": -27,
      "y": 6,
      "z": 10,
      "name": "Deco_Bone_Full",
      "rotation": 1
    },
    {
      "x": -27,
      "y": 7,
      "z": 10,
      "name": "Deco_Bone_Full",
      "rotation": 1
    },
    {
      "x": -27,
      "y": 8,
      "z": 10,
      "name": "Deco_Bone_Full",
      "rotation": 1
    },
    {
      "x": -27,
      "y": 9,
      "z": 10,
      "name": "Deco_Bone_Full",
      "rotation": 1
    },
    {
      "x": -27,
      "y": 10,
      "z": 10,
      "name": "Deco_Bone_Full",
      "rotation": 1
    },
    {
      "x": -27,
      "y": 11,
      "z": 10,
      "name": "Deco_Bone_Full",
      "rotation": 1
    },
    {
      "x": -27,
      "y": 12,
      "z": 10,
      "name": "Deco_Bone_Full",
      "rotation": 1
    },
    {
      "x": -27,
      "y": 13,
      "z": 10,
      "name": "Deco_Bone_Full",
      "rotation": 1
    },
    {
      "x": -27,
      "y": 14,
      "z": 10,
      "name": "Soil_Roots_Poisoned",
      "rotation": 1
    },
    {
      "x": -27,
      "y": 15,
      "z": 10,
      "name": "Soil_Roots_Poisoned",
      "rotation": 1
    },
    {
      "x": -27,
      "y": 0,
      "z": 11,
      "name": "Soil_Roots_Poisoned"
    },
    {
      "x": -27,
      "y": 7,
      "z": 11,
      "name": "Deco_Bone_Full",
      "rotation": 1
    },
    {
      "x": -27,
      "y": 8,
      "z": 11,
      "name": "Deco_Bone_Full",
      "rotation": 1
    },
    {
      "x": -27,
      "y": 9,
      "z": 11,
      "name": "Deco_Bone_Full",
      "rotation": 1
    },
    {
      "x": -27,
      "y": 10,
      "z": 11,
      "name": "Deco_Bone_Full",
      "rotation": 1
    },
    {
      "x": -27,
      "y": 11,
      "z": 11,
      "name": "Soil_Hive_Corrupted",
      "rotation": 1
    },
    {
      "x": -27,
      "y": 12,
      "z": 11,
      "name": "Soil_Roots_Poisoned",
      "rotation": 1
    },
    {
      "x": -27,
      "y": 0,
      "z": 12,
      "name": "Soil_Roots_Poisoned"
    },
    {
      "x": -27,
      "y": 0,
      "z": 13,
      "name": "Soil_Hive_Corrupted"
    },
    {
      "x": -27,
      "y": 0,
      "z": 14,
      "name": "Soil_Grass"
    },
    {
      "x": -27,
      "y": 0,
      "z": 15,
      "name": "Soil_Grass"
    },
    {
      "x": -26,
      "y": 0,
      "z": -15,
      "name": "Soil_Grass"
    },
    {
      "x": -26,
      "y": 0,
      "z": -14,
      "name": "Soil_Grass"
    },
    {
      "x": -26,
      "y": 0,
      "z": -13,
      "name": "Soil_Grass"
    },
    {
      "x": -26,
      "y": 0,
      "z": -12,
      "name": "Soil_Grass"
    },
    {
      "x": -26,
      "y": 0,
      "z": -11,
      "name": "Soil_Grass"
    },
    {
      "x": -26,
      "y": 0,
      "z": -10,
      "name": "Soil_Grass"
    },
    {
      "x": -26,
      "y": 0,
      "z": -9,
      "name": "Soil_Grass"
    },
    {
      "x": -26,
      "y": 0,
      "z": -8,
      "name": "Soil_Grass"
    },
    {
      "x": -26,
      "y": 0,
      "z": -7,
      "name": "Soil_Grass"
    },
    {
      "x": -26,
      "y": 0,
      "z": -6,
      "name": "Soil_Grass"
    },
    {
      "x": -26,
      "y": 0,
      "z": -5,
      "name": "Soil_Grass"
    },
    {
      "x": -26,
      "y": 0,
      "z": -4,
      "name": "Soil_Grass"
    },
    {
      "x": -26,
      "y": 0,
      "z": -3,
      "name": "Soil_Grass"
    },
    {
      "x": -26,
      "y": 38,
      "z": -3,
      "name": "Deco_Bone_Full",
      "rotation": 1
    },
    {
      "x": -26,
      "y": 39,
      "z": -3,
      "name": "Deco_Bone_Full",
      "rotation": 1
    },
    {
      "x": -26,
      "y": 40,
      "z": -3,
      "name": "Deco_Bone_Full",
      "rotation": 1
    },
    {
      "x": -26,
      "y": 41,
      "z": -3,
      "name": "Soil_Hive_Corrupted",
      "rotation": 1
    },
    {
      "x": -26,
      "y": 42,
      "z": -3,
      "name": "Soil_Roots_Poisoned",
      "rotation": 1
    },
    {
      "x": -26,
      "y": 0,
      "z": -2,
      "name": "Soil_Grass"
    },
    {
      "x": -26,
      "y": 37,
      "z": -2,
      "name": "Deco_Bone_Full",
      "rotation": 1
    },
    {
      "x": -26,
      "y": 38,
      "z": -2,
      "name": "Deco_Bone_Full",
      "rotation": 1
    },
    {
      "x": -26,
      "y": 39,
      "z": -2,
      "name": "Deco_Bone_Full",
      "rotation": 1
    },
    {
      "x": -26,
      "y": 40,
      "z": -2,
      "name": "Deco_Bone_Full",
      "rotation": 1
    },
    {
      "x": -26,
      "y": 41,
      "z": -2,
      "name": "Soil_Hive_Corrupted",
      "rotation": 1
    },
    {
      "x": -26,
      "y": 42,
      "z": -2,
      "name": "Soil_Hive_Corrupted",
      "rotation": 1
    },
    {
      "x": -26,
      "y": 0,
      "z": -1,
      "name": "Soil_Grass"
    },
    {
      "x": -26,
      "y": 36,
      "z": -1,
      "name": "Deco_Bone_Full",
      "rotation": 1
    },
    {
      "x": -26,
      "y": 37,
      "z": -1,
      "name": "Deco_Bone_Full",
      "rotation": 1
    },
    {
      "x": -26,
      "y": 38,
      "z": -1,
      "name": "Deco_Bone_Full",
      "rotation": 1
    },
    {
      "x": -26,
      "y": 39,
      "z": -1,
      "name": "Deco_Bone_Full",
      "rotation": 1
    },
    {
      "x": -26,
      "y": 40,
      "z": -1,
      "name": "Deco_Bone_Full",
      "rotation": 1
    },
    {
      "x": -26,
      "y": 41,
      "z": -1,
      "name": "Soil_Roots_Poisoned",
      "rotation": 1
    },
    {
      "x": -26,
      "y": 42,
      "z": -1,
      "name": "Soil_Roots_Poisoned",
      "rotation": 1
    },
    {
      "x": -26,
      "y": 0,
      "z": 0,
      "name": "Soil_Grass"
    },
    {
      "x": -26,
      "y": 35,
      "z": 0,
      "name": "Deco_Bone_Full",
      "rotation": 1
    },
    {
      "x": -26,
      "y": 36,
      "z": 0,
      "name": "Deco_Bone_Full",
      "rotation": 1
    },
    {
      "x": -26,
      "y": 37,
      "z": 0,
      "name": "Deco_Bone_Full",
      "rotation": 1
    },
    {
      "x": -26,
      "y": 38,
      "z": 0,
      "name": "Soil_Roots_Poisoned",
      "rotation": 1
    },
    {
      "x": -26,
      "y": 39,
      "z": 0,
      "name": "Soil_Roots_Poisoned",
      "rotation": 1
    },
    {
      "x": -26,
      "y": 0,
      "z": 1,
      "name": "Soil_Grass"
    },
    {
      "x": -26,
      "y": 14,
      "z": 1,
      "name": "Soil_Roots_Poisoned",
      "rotation": 1
    },
    {
      "x": -26,
      "y": 0,
      "z": 2,
      "name": "Soil_Grass"
    },
    {
      "x": -26,
      "y": 11,
      "z": 2,
      "name": "Deco_Bone_Full",
      "rotation": 1
    },
    {
      "x": -26,
      "y": 12,
      "z": 2,
      "name": "Deco_Bone_Full",
      "rotation": 1
    },
    {
      "x": -26,
      "y": 13,
      "z": 2,
      "name": "Deco_Bone_Full",
      "rotation": 1
    },
    {
      "x": -26,
      "y": 14,
      "z": 2,
      "name": "Deco_Bone_Full",
      "rotation": 1
    },
    {
      "x": -26,
      "y": 15,
      "z": 2,
      "name": "Soil_Roots_Poisoned",
      "rotation": 1
    },
    {
      "x": -26,
      "y": 16,
      "z": 2,
      "name": "Soil_Roots_Poisoned",
      "rotation": 1
    },
    {
      "x": -26,
      "y": 0,
      "z": 3,
      "name": "Soil_Grass"
    },
    {
      "x": -26,
      "y": 11,
      "z": 3,
      "name": "Deco_Bone_Full",
      "rotation": 1
    },
    {
      "x": -26,
      "y": 12,
      "z": 3,
      "name": "Deco_Bone_Full",
      "rotation": 1
    },
    {
      "x": -26,
      "y": 13,
      "z": 3,
      "name": "Deco_Bone_Full",
      "rotation": 1
    },
    {
      "x": -26,
      "y": 14,
      "z": 3,
      "name": "Deco_Bone_Full",
      "rotation": 1
    },
    {
      "x": -26,
      "y": 15,
      "z": 3,
      "name": "Soil_Hive_Corrupted",
      "rotation": 1
    },
    {
      "x": -26,
      "y": 16,
      "z": 3,
      "name": "Soil_Hive_Corrupted",
      "rotation": 1
    },
    {
      "x": -26,
      "y": 36,
      "z": 3,
      "name": "Deco_Bone_Full",
      "rotation": 1
    },
    {
      "x": -26,
      "y": 37,
      "z": 3,
      "name": "Deco_Bone_Full",
      "rotation": 1
    },
    {
      "x": -26,
      "y": 38,
      "z": 3,
      "name": "Deco_Bone_Full",
      "rotation": 1
    },
    {
      "x": -26,
      "y": 39,
      "z": 3,
      "name": "Soil_Roots_Poisoned",
      "rotation": 1
    },
    {
      "x": -26,
      "y": 40,
      "z": 3,
      "name": "Soil_Hive_Corrupted",
      "rotation": 1
    },
    {
      "x": -26,
      "y": 0,
      "z": 4,
      "name": "Soil_Grass"
    },
    {
      "x": -26,
      "y": 34,
      "z": 4,
      "name": "Deco_Bone_Full",
      "rotation": 1
    },
    {
      "x": -26,
      "y": 35,
      "z": 4,
      "name": "Deco_Bone_Full",
      "rotation": 1
    },
    {
      "x": -26,
      "y": 36,
      "z": 4,
      "name": "Deco_Bone_Full",
      "rotation": 1
    },
    {
      "x": -26,
      "y": 37,
      "z": 4,
      "name": "Deco_Bone_Full",
      "rotation": 1
    },
    {
      "x": -26,
      "y": 38,
      "z": 4,
      "name": "Deco_Bone_Full",
      "rotation": 1
    },
    {
      "x": -26,
      "y": 39,
      "z": 4,
      "name": "Soil_Roots_Poisoned",
      "rotation": 1
    },
    {
      "x": -26,
      "y": 40,
      "z": 4,
      "name": "Soil_Roots_Poisoned",
      "rotation": 1
    },
    {
      "x": -26,
      "y": 0,
      "z": 5,
      "name": "Soil_Grass"
    },
    {
      "x": -26,
      "y": 34,
      "z": 5,
      "name": "Deco_Bone_Full",
      "rotation": 1
    },
    {
      "x": -26,
      "y": 35,
      "z": 5,
      "name": "Deco_Bone_Full",
      "rotation": 1
    },
    {
      "x": -26,
      "y": 36,
      "z": 5,
      "name": "Deco_Bone_Full",
      "rotation": 1
    },
    {
      "x": -26,
      "y": 37,
      "z": 5,
      "name": "Deco_Bone_Full",
      "rotation": 1
    },
    {
      "x": -26,
      "y": 38,
      "z": 5,
      "name": "Soil_Roots_Poisoned",
      "rotation": 1
    },
    {
      "x": -26,
      "y": 39,
      "z": 5,
      "name": "Soil_Hive_Corrupted",
      "rotation": 1
    },
    {
      "x": -26,
      "y": 0,
      "z": 6,
      "name": "Soil_Grass"
    },
    {
      "x": -26,
      "y": 33,
      "z": 6,
      "name": "Deco_Bone_Full",
      "rotation": 1
    },
    {
      "x": -26,
      "y": 34,
      "z": 6,
      "name": "Deco_Bone_Full",
      "rotation": 1
    },
    {
      "x": -26,
      "y": 35,
      "z": 6,
      "name": "Deco_Bone_Full",
      "rotation": 1
    },
    {
      "x": -26,
      "y": 36,
      "z": 6,
      "name": "Soil_Hive_Corrupted",
      "rotation": 1
    },
    {
      "x": -26,
      "y": 37,
      "z": 6,
      "name": "Soil_Hive_Corrupted",
      "rotation": 1
    },
    {
      "x": -26,
      "y": 0,
      "z": 7,
      "name": "Soil_Grass"
    },
    {
      "x": -26,
      "y": 0,
      "z": 8,
      "name": "Soil_Grass"
    },
    {
      "x": -26,
      "y": 0,
      "z": 9,
      "name": "Soil_Roots_Poisoned"
    },
    {
      "x": -26,
      "y": 0,
      "z": 10,
      "name": "Soil_Roots_Poisoned"
    },
    {
      "x": -26,
      "y": 5,
      "z": 10,
      "name": "Deco_Bone_Full",
      "rotation": 1
    },
    {
      "x": -26,
      "y": 6,
      "z": 10,
      "name": "Deco_Bone_Full",
      "rotation": 1
    },
    {
      "x": -26,
      "y": 7,
      "z": 10,
      "name": "Deco_Bone_Full",
      "rotation": 1
    },
    {
      "x": -26,
      "y": 8,
      "z": 10,
      "name": "Deco_Bone_Full",
      "rotation": 1
    },
    {
      "x": -26,
      "y": 9,
      "z": 10,
      "name": "Deco_Bone_Full",
      "rotation": 1
    },
    {
      "x": -26,
      "y": 10,
      "z": 10,
      "name": "Soil_Roots_Poisoned",
      "rotation": 1
    },
    {
      "x": -26,
      "y": 11,
      "z": 10,
      "name": "Soil_Roots_Poisoned",
      "rotation": 1
    },
    {
      "x": -26,
      "y": 0,
      "z": 11,
      "name": "Soil_Hive_Corrupted"
    },
    {
      "x": -26,
      "y": 5,
      "z": 11,
      "name": "Deco_Bone_Full",
      "rotation": 1
    },
    {
      "x": -26,
      "y": 6,
      "z": 11,
      "name": "Deco_Bone_Full",
      "rotation": 1
    },
    {
      "x": -26,
      "y": 7,
      "z": 11,
      "name": "Deco_Bone_Full",
      "rotation": 1
    },
    {
      "x": -26,
      "y": 8,
      "z": 11,
      "name": "Deco_Bone_Full",
      "rotation": 1
    },
    {
      "x": -26,
      "y": 9,
      "z": 11,
      "name": "Deco_Bone_Full",
      "rotation": 1
    },
    {
      "x": -26,
      "y": 10,
      "z": 11,
      "name": "Soil_Hive_Corrupted",
      "rotation": 1
    },
    {
      "x": -26,
      "y": 11,
      "z": 11,
      "name": "Soil_Roots_Poisoned",
      "rotation": 1
    },
    {
      "x": -26,
      "y": 0,
      "z": 12,
      "name": "Soil_Hive_Corrupted"
    },
    {
      "x": -26,
      "y": 0,
      "z": 13,
      "name": "Soil_Roots_Poisoned"
    },
    {
      "x": -26,
      "y": 0,
      "z": 14,
      "name": "Soil_Grass"
    },
    {
      "x": -26,
      "y": 0,
      "z": 15,
      "name": "Soil_Grass"
    },
    {
      "x": -25,
      "y": 0,
      "z": -15,
      "name": "Soil_Grass"
    },
    {
      "x": -25,
      "y": 0,
      "z": -14,
      "name": "Soil_Grass"
    },
    {
      "x": -25,
      "y": 0,
      "z": -13,
      "name": "Soil_Grass"
    },
    {
      "x": -25,
      "y": 0,
      "z": -12,
      "name": "Soil_Grass"
    },
    {
      "x": -25,
      "y": 0,
      "z": -11,
      "name": "Soil_Grass"
    },
    {
      "x": -25,
      "y": 0,
      "z": -10,
      "name": "Soil_Grass"
    },
    {
      "x": -25,
      "y": 0,
      "z": -9,
      "name": "Soil_Grass"
    },
    {
      "x": -25,
      "y": 0,
      "z": -8,
      "name": "Soil_Grass"
    },
    {
      "x": -25,
      "y": 0,
      "z": -7,
      "name": "Soil_Grass"
    },
    {
      "x": -25,
      "y": 0,
      "z": -6,
      "name": "Soil_Grass"
    },
    {
      "x": -25,
      "y": 0,
      "z": -5,
      "name": "Soil_Grass"
    },
    {
      "x": -25,
      "y": 0,
      "z": -4,
      "name": "Soil_Grass"
    },
    {
      "x": -25,
      "y": 0,
      "z": -3,
      "name": "Soil_Grass"
    },
    {
      "x": -25,
      "y": 40,
      "z": -3,
      "name": "Deco_Bone_Full",
      "rotation": 1
    },
    {
      "x": -25,
      "y": 41,
      "z": -3,
      "name": "Deco_Bone_Full",
      "rotation": 1
    },
    {
      "x": -25,
      "y": 42,
      "z": -3,
      "name": "Deco_Bone_Full",
      "rotation": 1
    },
    {
      "x": -25,
      "y": 43,
      "z": -3,
      "name": "Soil_Roots_Poisoned",
      "rotation": 1
    },
    {
      "x": -25,
      "y": 44,
      "z": -3,
      "name": "Soil_Hive_Corrupted",
      "rotation": 1
    },
    {
      "x": -25,
      "y": 0,
      "z": -2,
      "name": "Soil_Grass"
    },
    {
      "x": -25,
      "y": 39,
      "z": -2,
      "name": "Deco_Bone_Full",
      "rotation": 1
    },
    {
      "x": -25,
      "y": 40,
      "z": -2,
      "name": "Deco_Bone_Full",
      "rotation": 1
    },
    {
      "x": -25,
      "y": 41,
      "z": -2,
      "name": "Deco_Bone_Full",
      "rotation": 1
    },
    {
      "x": -25,
      "y": 42,
      "z": -2,
      "name": "Deco_Bone_Full",
      "rotation": 1
    },
    {
      "x": -25,
      "y": 43,
      "z": -2,
      "name": "Soil_Roots_Poisoned",
      "rotation": 1
    },
    {
      "x": -25,
      "y": 44,
      "z": -2,
      "name": "Soil_Roots_Poisoned",
      "rotation": 1
    },
    {
      "x": -25,
      "y": 0,
      "z": -1,
      "name": "Soil_Grass"
    },
    {
      "x": -25,
      "y": 38,
      "z": -1,
      "name": "Deco_Bone_Full",
      "rotation": 1
    },
    {
      "x": -25,
      "y": 39,
      "z": -1,
      "name": "Deco_Bone_Full",
      "rotation": 1
    },
    {
      "x": -25,
      "y": 40,
      "z": -1,
      "name": "Deco_Bone_Full",
      "rotation": 1
    },
    {
      "x": -25,
      "y": 41,
      "z": -1,
      "name": "Deco_Bone_Full",
      "rotation": 1
    },
    {
      "x": -25,
      "y": 42,
      "z": -1,
      "name": "Soil_Hive_Corrupted",
      "rotation": 1
    },
    {
      "x": -25,
      "y": 43,
      "z": -1,
      "name": "Soil_Hive_Corrupted",
      "rotation": 1
    },
    {
      "x": -25,
      "y": 0,
      "z": 0,
      "name": "Soil_Grass"
    },
    {
      "x": -25,
      "y": 38,
      "z": 0,
      "name": "Deco_Bone_Full",
      "rotation": 1
    },
    {
      "x": -25,
      "y": 39,
      "z": 0,
      "name": "Deco_Bone_Full",
      "rotation": 1
    },
    {
      "x": -25,
      "y": 40,
      "z": 0,
      "name": "Soil_Roots_Poisoned",
      "rotation": 1
    },
    {
      "x": -25,
      "y": 41,
      "z": 0,
      "name": "Soil_Hive_Corrupted",
      "rotation": 1
    },
    {
      "x": -25,
      "y": 0,
      "z": 1,
      "name": "Soil_Grass"
    },
    {
      "x": -25,
      "y": 0,
      "z": 2,
      "name": "Soil_Grass"
    },
    {
      "x": -25,
      "y": 9,
      "z": 2,
      "name": "Deco_Bone_Full",
      "rotation": 1
    },
    {
      "x": -25,
      "y": 10,
      "z": 2,
      "name": "Deco_Bone_Full",
      "rotation": 1
    },
    {
      "x": -25,
      "y": 11,
      "z": 2,
      "name": "Deco_Bone_Full",
      "rotation": 1
    },
    {
      "x": -25,
      "y": 12,
      "z": 2,
      "name": "Deco_Bone_Full",
      "rotation": 1
    },
    {
      "x": -25,
      "y": 13,
      "z": 2,
      "name": "Soil_Hive_Corrupted",
      "rotation": 1
    },
    {
      "x": -25,
      "y": 14,
      "z": 2,
      "name": "Soil_Hive_Corrupted",
      "rotation": 1
    },
    {
      "x": -25,
      "y": 41,
      "z": 2,
      "name": "Soil_Hive_Corrupted",
      "rotation": 1
    },
    {
      "x": -25,
      "y": 0,
      "z": 3,
      "name": "Soil_Grass"
    },
    {
      "x": -25,
      "y": 9,
      "z": 3,
      "name": "Deco_Bone_Full",
      "rotation": 1
    },
    {
      "x": -25,
      "y": 10,
      "z": 3,
      "name": "Deco_Bone_Full",
      "rotation": 1
    },
    {
      "x": -25,
      "y": 11,
      "z": 3,
      "name": "Deco_Bone_Full",
      "rotation": 1
    },
    {
      "x": -25,
      "y": 12,
      "z": 3,
      "name": "Deco_Bone_Full",
      "rotation": 1
    },
    {
      "x": -25,
      "y": 13,
      "z": 3,
      "name": "Soil_Hive_Corrupted",
      "rotation": 1
    },
    {
      "x": -25,
      "y": 14,
      "z": 3,
      "name": "Soil_Hive_Corrupted",
      "rotation": 1
    },
    {
      "x": -25,
      "y": 38,
      "z": 3,
      "name": "Deco_Bone_Full",
      "rotation": 1
    },
    {
      "x": -25,
      "y": 39,
      "z": 3,
      "name": "Deco_Bone_Full",
      "rotation": 1
    },
    {
      "x": -25,
      "y": 40,
      "z": 3,
      "name": "Deco_Bone_Full",
      "rotation": 1
    },
    {
      "x": -25,
      "y": 41,
      "z": 3,
      "name": "Soil_Hive_Corrupted",
      "rotation": 1
    },
    {
      "x": -25,
      "y": 42,
      "z": 3,
      "name": "Soil_Roots_Poisoned",
      "rotation": 1
    },
    {
      "x": -25,
      "y": 0,
      "z": 4,
      "name": "Soil_Grass"
    },
    {
      "x": -25,
      "y": 36,
      "z": 4,
      "name": "Deco_Bone_Full",
      "rotation": 1
    },
    {
      "x": -25,
      "y": 37,
      "z": 4,
      "name": "Deco_Bone_Full",
      "rotation": 1
    },
    {
      "x": -25,
      "y": 38,
      "z": 4,
      "name": "Deco_Bone_Full",
      "rotation": 1
    },
    {
      "x": -25,
      "y": 39,
      "z": 4,
      "name": "Deco_Bone_Full",
      "rotation": 1
    },
    {
      "x": -25,
      "y": 40,
      "z": 4,
      "name": "Deco_Bone_Full",
      "rotation": 1
    },
    {
      "x": -25,
      "y": 41,
      "z": 4,
      "name": "Soil_Hive_Corrupted",
      "rotation": 1
    },
    {
      "x": -25,
      "y": 42,
      "z": 4,
      "name": "Soil_Roots_Poisoned",
      "rotation": 1
    },
    {
      "x": -25,
      "y": 0,
      "z": 5,
      "name": "Soil_Grass"
    },
    {
      "x": -25,
      "y": 36,
      "z": 5,
      "name": "Deco_Bone_Full",
      "rotation": 1
    },
    {
      "x": -25,
      "y": 37,
      "z": 5,
      "name": "Deco_Bone_Full",
      "rotation": 1
    },
    {
      "x": -25,
      "y": 38,
      "z": 5,
      "name": "Deco_Bone_Full",
      "rotation": 1
    },
    {
      "x": -25,
      "y": 39,
      "z": 5,
      "name": "Deco_Bone_Full",
      "rotation": 1
    },
    {
      "x": -25,
      "y": 40,
      "z": 5,
      "name": "Soil_Hive_Corrupted",
      "rotation": 1
    },
    {
      "x": -25,
      "y": 41,
      "z": 5,
      "name": "Soil_Roots_Poisoned",
      "rotation": 1
    },
    {
      "x": -25,
      "y": 0,
      "z": 6,
      "name": "Soil_Grass"
    },
    {
      "x": -25,
      "y": 36,
      "z": 6,
      "name": "Deco_Bone_Full",
      "rotation": 1
    },
    {
      "x": -25,
      "y": 37,
      "z": 6,
      "name": "Soil_Roots_Poisoned",
      "rotation": 1
    },
    {
      "x": -25,
      "y": 38,
      "z": 6,
      "name": "Soil_Roots_Poisoned",
      "rotation": 1
    },
    {
      "x": -25,
      "y": 0,
      "z": 7,
      "name": "Soil_Grass"
    },
    {
      "x": -25,
      "y": 0,
      "z": 8,
      "name": "Soil_Grass"
    },
    {
      "x": -25,
      "y": 0,
      "z": 9,
      "name": "Soil_Roots_Poisoned"
    },
    {
      "x": -25,
      "y": 0,
      "z": 10,
      "name": "Soil_Roots_Poisoned"
    },
    {
      "x": -25,
      "y": 5,
      "z": 10,
      "name": "Deco_Bone_Full",
      "rotation": 1
    },
    {
      "x": -25,
      "y": 6,
      "z": 10,
      "name": "Deco_Bone_Full",
      "rotation": 1
    },
    {
      "x": -25,
      "y": 7,
      "z": 10,
      "name": "Soil_Roots_Poisoned",
      "rotation": 1
    },
    {
      "x": -25,
      "y": 8,
      "z": 10,
      "name": "Soil_Hive_Corrupted",
      "rotation": 1
    },
    {
      "x": -25,
      "y": 0,
      "z": 11,
      "name": "Soil_Hive_Corrupted"
    },
    {
      "x": -25,
      "y": 3,
      "z": 11,
      "name": "Deco_Bone_Full",
      "rotation": 1
    },
    {
      "x": -25,
      "y": 4,
      "z": 11,
      "name": "Deco_Bone_Full",
      "rotation": 1
    },
    {
      "x": -25,
      "y": 5,
      "z": 11,
      "name": "Deco_Bone_Full",
      "rotation": 1
    },
    {
      "x": -25,
      "y": 6,
      "z": 11,
      "name": "Deco_Bone_Full",
      "rotation": 1
    },
    {
      "x": -25,
      "y": 7,
      "z": 11,
      "name": "Soil_Hive_Corrupted",
      "rotation": 1
    },
    {
      "x": -25,
      "y": 8,
      "z": 11,
      "name": "Soil_Hive_Corrupted",
      "rotation": 1
    },
    {
      "x": -25,
      "y": 0,
      "z": 12,
      "name": "Soil_Hive_Corrupted"
    },
    {
      "x": -25,
      "y": 4,
      "z": 12,
      "name": "Deco_Bone_Full",
      "rotation": 1
    },
    {
      "x": -25,
      "y": 5,
      "z": 12,
      "name": "Deco_Bone_Full",
      "rotation": 1
    },
    {
      "x": -25,
      "y": 6,
      "z": 12,
      "name": "Soil_Roots_Poisoned",
      "rotation": 1
    },
    {
      "x": -25,
      "y": 7,
      "z": 12,
      "name": "Soil_Hive_Corrupted",
      "rotation": 1
    },
    {
      "x": -25,
      "y": 0,
      "z": 13,
      "name": "Soil_Roots_Poisoned"
    },
    {
      "x": -25,
      "y": 0,
      "z": 14,
      "name": "Soil_Grass"
    },
    {
      "x": -25,
      "y": 0,
      "z": 15,
      "name": "Soil_Grass"
    },
    {
      "x": -24,
      "y": 0,
      "z": -15,
      "name": "Soil_Grass"
    },
    {
      "x": -24,
      "y": 0,
      "z": -14,
      "name": "Soil_Grass"
    },
    {
      "x": -24,
      "y": 0,
      "z": -13,
      "name": "Soil_Grass"
    },
    {
      "x": -24,
      "y": 0,
      "z": -12,
      "name": "Soil_Grass"
    },
    {
      "x": -24,
      "y": 0,
      "z": -11,
      "name": "Soil_Grass"
    },
    {
      "x": -24,
      "y": 0,
      "z": -10,
      "name": "Soil_Grass"
    },
    {
      "x": -24,
      "y": 0,
      "z": -9,
      "name": "Soil_Grass"
    },
    {
      "x": -24,
      "y": 0,
      "z": -8,
      "name": "Soil_Grass"
    },
    {
      "x": -24,
      "y": 0,
      "z": -7,
      "name": "Soil_Grass"
    },
    {
      "x": -24,
      "y": 26,
      "z": -7,
      "name": "Deco_Bone_Full",
      "rotation": 1
    },
    {
      "x": -24,
      "y": 27,
      "z": -7,
      "name": "Deco_Bone_Full",
      "rotation": 1
    },
    {
      "x": -24,
      "y": 28,
      "z": -7,
      "name": "Deco_Bone_Full",
      "rotation": 1
    },
    {
      "x": -24,
      "y": 29,
      "z": -7,
      "name": "Deco_Bone_Full",
      "rotation": 1
    },
    {
      "x": -24,
      "y": 30,
      "z": -7,
      "name": "Deco_Bone_Full",
      "rotation": 1
    },
    {
      "x": -24,
      "y": 31,
      "z": -7,
      "name": "Deco_Bone_Full",
      "rotation": 1
    },
    {
      "x": -24,
      "y": 32,
      "z": -7,
      "name": "Deco_Bone_Full",
      "rotation": 1
    },
    {
      "x": -24,
      "y": 33,
      "z": -7,
      "name": "Deco_Bone_Full",
      "rotation": 1
    },
    {
      "x": -24,
      "y": 34,
      "z": -7,
      "name": "Deco_Bone_Full",
      "rotation": 1
    },
    {
      "x": -24,
      "y": 35,
      "z": -7,
      "name": "Deco_Bone_Full",
      "rotation": 1
    },
    {
      "x": -24,
      "y": 36,
      "z": -7,
      "name": "Soil_Roots_Poisoned",
      "rotation": 1
    },
    {
      "x": -24,
      "y": 37,
      "z": -7,
      "name": "Soil_Roots_Poisoned",
      "rotation": 1
    },
    {
      "x": -24,
      "y": 0,
      "z": -6,
      "name": "Soil_Grass"
    },
    {
      "x": -24,
      "y": 24,
      "z": -6,
      "name": "Deco_Bone_Full",
      "rotation": 1
    },
    {
      "x": -24,
      "y": 25,
      "z": -6,
      "name": "Deco_Bone_Full",
      "rotation": 1
    },
    {
      "x": -24,
      "y": 26,
      "z": -6,
      "name": "Deco_Bone_Full",
      "rotation": 1
    },
    {
      "x": -24,
      "y": 27,
      "z": -6,
      "name": "Deco_Bone_Full",
      "rotation": 1
    },
    {
      "x": -24,
      "y": 28,
      "z": -6,
      "name": "Deco_Bone_Full",
      "rotation": 1
    },
    {
      "x": -24,
      "y": 29,
      "z": -6,
      "name": "Deco_Bone_Full",
      "rotation": 1
    },
    {
      "x": -24,
      "y": 30,
      "z": -6,
      "name": "Deco_Bone_Full",
      "rotation": 1
    },
    {
      "x": -24,
      "y": 31,
      "z": -6,
      "name": "Deco_Bone_Full",
      "rotation": 1
    },
    {
      "x": -24,
      "y": 32,
      "z": -6,
      "name": "Deco_Bone_Full",
      "rotation": 1
    },
    {
      "x": -24,
      "y": 33,
      "z": -6,
      "name": "Deco_Bone_Full",
      "rotation": 1
    },
    {
      "x": -24,
      "y": 34,
      "z": -6,
      "name": "Deco_Bone_Full",
      "rotation": 1
    },
    {
      "x": -24,
      "y": 35,
      "z": -6,
      "name": "Soil_Roots_Poisoned",
      "rotation": 1
    },
    {
      "x": -24,
      "y": 36,
      "z": -6,
      "name": "Soil_Hive_Corrupted",
      "rotation": 1
    },
    {
      "x": -24,
      "y": 0,
      "z": -5,
      "name": "Soil_Grass"
    },
    {
      "x": -24,
      "y": 26,
      "z": -5,
      "name": "Deco_Bone_Full",
      "rotation": 1
    },
    {
      "x": -24,
      "y": 27,
      "z": -5,
      "name": "Deco_Bone_Full",
      "rotation": 1
    },
    {
      "x": -24,
      "y": 28,
      "z": -5,
      "name": "Deco_Bone_Full",
      "rotation": 1
    },
    {
      "x": -24,
      "y": 29,
      "z": -5,
      "name": "Deco_Bone_Full",
      "rotation": 1
    },
    {
      "x": -24,
      "y": 30,
      "z": -5,
      "name": "Deco_Bone_Full",
      "rotation": 1
    },
    {
      "x": -24,
      "y": 31,
      "z": -5,
      "name": "Deco_Bone_Full",
      "rotation": 1
    },
    {
      "x": -24,
      "y": 32,
      "z": -5,
      "name": "Deco_Bone_Full",
      "rotation": 1
    },
    {
      "x": -24,
      "y": 33,
      "z": -5,
      "name": "Soil_Hive_Corrupted",
      "rotation": 1
    },
    {
      "x": -24,
      "y": 34,
      "z": -5,
      "name": "Soil_Hive_Corrupted",
      "rotation": 1
    },
    {
      "x": -24,
      "y": 0,
      "z": -4,
      "name": "Soil_Grass"
    },
    {
      "x": -24,
      "y": 0,
      "z": -3,
      "name": "Soil_Grass"
    },
    {
      "x": -24,
      "y": 42,
      "z": -3,
      "name": "Deco_Bone_Full",
      "rotation": 1
    },
    {
      "x": -24,
      "y": 43,
      "z": -3,
      "name": "Deco_Bone_Full",
      "rotation": 1
    },
    {
      "x": -24,
      "y": 44,
      "z": -3,
      "name": "Soil_Roots_Poisoned",
      "rotation": 1
    },
    {
      "x": -24,
      "y": 45,
      "z": -3,
      "name": "Soil_Roots_Poisoned",
      "rotation": 1
    },
    {
      "x": -24,
      "y": 0,
      "z": -2,
      "name": "Soil_Grass"
    },
    {
      "x": -24,
      "y": 41,
      "z": -2,
      "name": "Deco_Bone_Full",
      "rotation": 1
    },
    {
      "x": -24,
      "y": 42,
      "z": -2,
      "name": "Deco_Bone_Full",
      "rotation": 1
    },
    {
      "x": -24,
      "y": 43,
      "z": -2,
      "name": "Deco_Bone_Full",
      "rotation": 1
    },
    {
      "x": -24,
      "y": 44,
      "z": -2,
      "name": "Soil_Hive_Corrupted",
      "rotation": 1
    },
    {
      "x": -24,
      "y": 45,
      "z": -2,
      "name": "Soil_Roots_Poisoned",
      "rotation": 1
    },
    {
      "x": -24,
      "y": 0,
      "z": -1,
      "name": "Soil_Grass"
    },
    {
      "x": -24,
      "y": 40,
      "z": -1,
      "name": "Deco_Bone_Full",
      "rotation": 1
    },
    {
      "x": -24,
      "y": 41,
      "z": -1,
      "name": "Deco_Bone_Full",
      "rotation": 1
    },
    {
      "x": -24,
      "y": 42,
      "z": -1,
      "name": "Deco_Bone_Full",
      "rotation": 1
    },
    {
      "x": -24,
      "y": 43,
      "z": -1,
      "name": "Deco_Bone_Full",
      "rotation": 1
    },
    {
      "x": -24,
      "y": 44,
      "z": -1,
      "name": "Soil_Roots_Poisoned",
      "rotation": 1
    },
    {
      "x": -24,
      "y": 45,
      "z": -1,
      "name": "Soil_Roots_Poisoned",
      "rotation": 1
    },
    {
      "x": -24,
      "y": 0,
      "z": 0,
      "name": "Soil_Grass"
    },
    {
      "x": -24,
      "y": 40,
      "z": 0,
      "name": "Deco_Bone_Full",
      "rotation": 1
    },
    {
      "x": -24,
      "y": 41,
      "z": 0,
      "name": "Soil_Hive_Corrupted",
      "rotation": 1
    },
    {
      "x": -24,
      "y": 42,
      "z": 0,
      "name": "Soil_Roots_Poisoned",
      "rotation": 1
    },
    {
      "x": -24,
      "y": 0,
      "z": 1,
      "name": "Soil_Grass"
    },
    {
      "x": -24,
      "y": 0,
      "z": 2,
      "name": "Soil_Grass"
    },
    {
      "x": -24,
      "y": 8,
      "z": 2,
      "name": "Deco_Bone_Full",
      "rotation": 1
    },
    {
      "x": -24,
      "y": 9,
      "z": 2,
      "name": "Deco_Bone_Full",
      "rotation": 1
    },
    {
      "x": -24,
      "y": 10,
      "z": 2,
      "name": "Deco_Bone_Full",
      "rotation": 1
    },
    {
      "x": -24,
      "y": 11,
      "z": 2,
      "name": "Soil_Roots_Poisoned",
      "rotation": 1
    },
    {
      "x": -24,
      "y": 12,
      "z": 2,
      "name": "Soil_Hive_Corrupted",
      "rotation": 1
    },
    {
      "x": -24,
      "y": 41,
      "z": 2,
      "name": "Soil_Roots_Poisoned",
      "rotation": 1
    },
    {
      "x": -24,
      "y": 43,
      "z": 2,
      "name": "Soil_Roots_Poisoned",
      "rotation": 1
    },
    {
      "x": -24,
      "y": 0,
      "z": 3,
      "name": "Soil_Grass"
    },
    {
      "x": -24,
      "y": 8,
      "z": 3,
      "name": "Deco_Bone_Full",
      "rotation": 1
    },
    {
      "x": -24,
      "y": 9,
      "z": 3,
      "name": "Deco_Bone_Full",
      "rotation": 1
    },
    {
      "x": -24,
      "y": 10,
      "z": 3,
      "name": "Deco_Bone_Full",
      "rotation": 1
    },
    {
      "x": -24,
      "y": 11,
      "z": 3,
      "name": "Soil_Roots_Poisoned",
      "rotation": 1
    },
    {
      "x": -24,
      "y": 12,
      "z": 3,
      "name": "Soil_Roots_Poisoned",
      "rotation": 1
    },
    {
      "x": -24,
      "y": 39,
      "z": 3,
      "name": "Deco_Bone_Full",
      "rotation": 1
    },
    {
      "x": -24,
      "y": 40,
      "z": 3,
      "name": "Deco_Bone_Full",
      "rotation": 1
    },
    {
      "x": -24,
      "y": 41,
      "z": 3,
      "name": "Deco_Bone_Full",
      "rotation": 1
    },
    {
      "x": -24,
      "y": 42,
      "z": 3,
      "name": "Deco_Bone_Full",
      "rotation": 1
    },
    {
      "x": -24,
      "y": 43,
      "z": 3,
      "name": "Soil_Roots_Poisoned",
      "rotation": 1
    },
    {
      "x": -24,
      "y": 44,
      "z": 3,
      "name": "Soil_Roots_Poisoned",
      "rotation": 1
    },
    {
      "x": -24,
      "y": 0,
      "z": 4,
      "name": "Soil_Grass"
    },
    {
      "x": -24,
      "y": 10,
      "z": 4,
      "name": "Soil_Roots_Poisoned",
      "rotation": 1
    },
    {
      "x": -24,
      "y": 11,
      "z": 4,
      "name": "Soil_Roots_Poisoned",
      "rotation": 1
    },
    {
      "x": -24,
      "y": 38,
      "z": 4,
      "name": "Deco_Bone_Full",
      "rotation": 1
    },
    {
      "x": -24,
      "y": 39,
      "z": 4,
      "name": "Deco_Bone_Full",
      "rotation": 1
    },
    {
      "x": -24,
      "y": 40,
      "z": 4,
      "name": "Deco_Bone_Full",
      "rotation": 1
    },
    {
      "x": -24,
