{
  "version": 8,
  "blockIdVersion": 11,
  "anchorX": 0,
  "anchorY": 6,
  "anchorZ": 0,
  "blocks": [
    {
      "x": -31,
      "y": 39,
      "z": 5,
      "name": "Soil_Roots_Poisoned",
      "rotation": 1
    },
    {
      "x": -31,
      "y": 0,
      "z": 6,
      "name": "Soil_Grass"
    },
    {
      "x": -31,
      "y": 37,
      "z": 6,
      "name": "Deco_Bone_Full",
      "rotation": 1
    },
    {
      "x": -31,
      "y": 38,
      "z": 6,
      "name": "Deco_Bone_Full",
      "rotation": 1
    },
    {
      "x": -31,
      "y": 39,
      "z": 6,
      "name": "Deco_Bone_Full",
      "rotation": 1
    },
    {
      "x": -31,
      "y": 40,
      "z": 6,
      "name": "Deco_Bone_Full",
      "rotation": 1
    },
    {
      "x": -31,
      "y": 41,
      "z": 6,
      "name": "Soil_Roots_Poisoned",
      "rotation": 1
    },
    {
      "x": -31,
      "y": 42,
      "z": 6,
      "name": "Soil_Hive_Corrupted",
      "rotation": 1
    },
    {
      "x": -31,
      "y": 0,
      "z": 7,
      "name": "Soil_Grass"
    },
    {
      "x": -31,
      "y": 39,
      "z": 7,
      "name": "Deco_Bone_Full",
      "rotation": 1
    },
    {
      "x": -31,
      "y": 40,
      "z": 7,
      "name": "Deco_Bone_Full",
      "rotation": 1
    },
    {
      "x": -31,
      "y": 41,
      "z": 7,
      "name": "Deco_Bone_Full",
      "rotation": 1
    },
    {
      "x": -31,
      "y": 42,
      "z": 7,
      "name": "Soil_Hive_Corrupted",
      "rotation": 1
    },
    {
      "x": -31,
      "y": 43,
      "z": 7,
      "name": "Soil_Hive_Corrupted",
      "rotation": 1
    },
    {
      "x": -31,
      "y": 0,
      "z": 8,
      "name": "Soil_Grass"
    },
    {
      "x": -31,
      "y": 0,
      "z": 9,
      "name": "Soil_Grass"
    },
    {
      "x": -31,
      "y": 0,
      "z": 10,
      "name": "Soil_Grass"
    },
    {
      "x": -31,
      "y": 0,
      "z": 11,
      "name": "Soil_Grass"
    },
    {
      "x": -31,
      "y": 0,
      "z": 12,
      "name": "Soil_Grass"
    },
    {
      "x": -31,
      "y": 0,
      "z": 13,
      "name": "Soil_Grass"
    },
    {
      "x": -31,
      "y": 0,
      "z": 14,
      "name": "Soil_Grass"
    },
    {
      "x": -31,
      "y": 0,
      "z": 15,
      "name": "Soil_Grass"
    },
    {
      "x": -30,
      "y": 0,
      "z": -15,
      "name": "Soil_Grass"
    },
    {
      "x": -30,
      "y": 0,
      "z": -14,
      "name": "Soil_Grass"
    },
    {
      "x": -30,
      "y": 0,
      "z": -13,
      "name": "Soil_Grass"
    },
    {
      "x": -30,
      "y": 0,
      "z": -12,
      "name": "Soil_Grass"
    },
    {
      "x": -30,
      "y": 0,
      "z": -11,
      "name": "Soil_Grass"
    },
    {
      "x": -30,
      "y": 0,
      "z": -10,
      "name": "Soil_Grass"
    },
    {
      "x": -30,
      "y": 0,
      "z": -9,
      "name": "Soil_Grass"
    },
    {
      "x": -30,
      "y": 0,
      "z": -8,
      "name": "Soil_Grass"
    },
    {
      "x": -30,
      "y": 0,
      "z": -7,
      "name": "Soil_Grass"
    },
    {
      "x": -30,
      "y": 0,
      "z": -6,
      "name": "Soil_Grass"
    },
    {
      "x": -30,
      "y": 0,
      "z": -5,
      "name": "Soil_Grass"
    },
    {
      "x": -30,
      "y": 0,
      "z": -4,
      "name": "Soil_Grass"
    },
    {
      "x": -30,
      "y": 0,
      "z": -3,
      "name": "Soil_Grass"
    },
    {
      "x": -30,
      "y": 31,
      "z": -3,
      "name": "Deco_Bone_Full",
      "rotation": 1
    },
    {
      "x": -30,
      "y": 32,
      "z": -3,
      "name": "Soil_Hive_Corrupted",
      "rotation": 1
    },
    {
      "x": -30,
      "y": 33,
      "z": -3,
      "name": "Soil_Roots_Poisoned",
      "rotation": 1
    },
    {
      "x": -30,
      "y": 0,
      "z": -2,
      "name": "Soil_Grass"
    },
    {
      "x": -30,
      "y": 30,
      "z": -2,
      "name": "Deco_Bone_Full",
      "rotation": 1
    },
    {
      "x": -30,
      "y": 31,
      "z": -2,
      "name": "Deco_Bone_Full",
      "rotation": 1
    },
    {
      "x": -30,
      "y": 32,
      "z": -2,
      "name": "Deco_Bone_Full",
      "rotation": 1
    },
    {
      "x": -30,
      "y": 33,
      "z": -2,
      "name": "Deco_Bone_Full",
      "rotation": 1
    },
    {
      "x": -30,
      "y": 34,
      "z": -2,
      "name": "Deco_Bone_Full",
      "rotation": 1
    },
    {
      "x": -30,
      "y": 35,
      "z": -2,
      "name": "Deco_Bone_Full",
      "rotation": 1
    },
    {
      "x": -30,
      "y": 36,
      "z": -2,
      "name": "Deco_Bone_Full",
      "rotation": 1
    },
    {
      "x": -30,
      "y": 37,
      "z": -2,
      "name": "Deco_Bone_Full",
      "rotation": 1
    },
    {
      "x": -30,
      "y": 38,
      "z": -2,
      "name": "Soil_Roots_Poisoned",
      "rotation": 1
    },
    {
      "x": -30,
      "y": 39,
      "z": -2,
      "name": "Soil_Roots_Poisoned",
      "rotation": 1
    },
    {
      "x": -30,
      "y": 0,
      "z": -1,
      "name": "Soil_Grass"
    },
    {
      "x": -30,
      "y": 32,
      "z": -1,
      "name": "Deco_Bone_Full",
      "rotation": 1
    },
    {
      "x": -30,
      "y": 33,
      "z": -1,
      "name": "Deco_Bone_Full",
      "rotation": 1
    },
    {
      "x": -30,
      "y": 34,
      "z": -1,
      "name": "Deco_Bone_Full",
      "rotation": 1
    },
    {
      "x": -30,
      "y": 35,
      "z": -1,
      "name": "Deco_Bone_Full",
      "rotation": 1
    },
    {
      "x": -30,
      "y": 36,
      "z": -1,
      "name": "Deco_Bone_Full",
      "rotation": 1
    },
    {
      "x": -30,
      "y": 37,
      "z": -1,
      "name": "Deco_Bone_Full",
      "rotation": 1
    },
    {
      "x": -30,
      "y": 38,
      "z": -1,
      "name": "Deco_Bone_Full",
      "rotation": 1
    },
    {
      "x": -30,
      "y": 39,
      "z": -1,
      "name": "Deco_Bone_Full",
      "rotation": 1
    },
    {
      "x": -30,
      "y": 40,
      "z": -1,
      "name": "Deco_Bone_Full",
      "rotation": 1
    },
    {
      "x": -30,
      "y": 41,
      "z": -1,
      "name": "Soil_Hive_Corrupted",
      "rotation": 1
    },
    {
      "x": -30,
      "y": 42,
      "z": -1,
      "name": "Soil_Roots_Poisoned",
      "rotation": 1
    },
    {
      "x": -30,
      "y": 0,
      "z": 0,
      "name": "Soil_Grass"
    },
    {
      "x": -30,
      "y": 33,
      "z": 0,
      "name": "Deco_Bone_Full",
      "rotation": 1
    },
    {
      "x": -30,
      "y": 34,
      "z": 0,
      "name": "Deco_Bone_Full",
      "rotation": 1
    },
    {
      "x": -30,
      "y": 35,
      "z": 0,
      "name": "Deco_Bone_Full",
      "rotation": 1
    },
    {
      "x": -30,
      "y": 36,
      "z": 0,
      "name": "Deco_Bone_Full",
      "rotation": 1
    },
    {
      "x": -30,
      "y": 37,
      "z": 0,
      "name": "Deco_Bone_Full",
      "rotation": 1
    },
    {
      "x": -30,
      "y": 38,
      "z": 0,
      "name": "Deco_Bone_Full",
      "rotation": 1
    },
    {
      "x": -30,
      "y": 39,
      "z": 0,
      "name": "Deco_Bone_Full",
      "rotation": 1
    },
    {
      "x": -30,
      "y": 40,
      "z": 0,
      "name": "Deco_Bone_Full",
      "rotation": 1
    },
    {
      "x": -30,
      "y": 41,
      "z": 0,
      "name": "Soil_Roots_Poisoned",
      "rotation": 1
    },
    {
      "x": -30,
      "y": 42,
      "z": 0,
      "name": "Soil_Hive_Corrupted",
      "rotation": 1
    },
    {
      "x": -30,
      "y": 0,
      "z": 1,
      "name": "Soil_Grass"
    },
    {
      "x": -30,
      "y": 0,
      "z": 2,
      "name": "Soil_Grass"
    },
    {
      "x": -30,
      "y": 0,
      "z": 3,
      "name": "Soil_Grass"
    },
    {
      "x": -30,
      "y": 0,
      "z": 4,
      "name": "Soil_Grass"
    },
    {
      "x": -30,
      "y": 33,
      "z": 4,
      "name": "Soil_Roots_Poisoned",
      "rotation": 1
    },
    {
      "x": -30,
      "y": 34,
      "z": 4,
      "name": "Soil_Roots_Poisoned",
      "rotation": 1
    },
    {
      "x": -30,
      "y": 0,
      "z": 5,
      "name": "Soil_Grass"
    },
    {
      "x": -30,
      "y": 32,
      "z": 5,
      "name": "Deco_Bone_Full",
      "rotation": 1
    },
    {
      "x": -30,
      "y": 33,
      "z": 5,
      "name": "Deco_Bone_Full",
      "rotation": 1
    },
    {
      "x": -30,
      "y": 34,
      "z": 5,
      "name": "Deco_Bone_Full",
      "rotation": 1
    },
    {
      "x": -30,
      "y": 35,
      "z": 5,
      "name": "Deco_Bone_Full",
      "rotation": 1
    },
    {
      "x": -30,
      "y": 36,
      "z": 5,
      "name": "Deco_Bone_Full",
      "rotation": 1
    },
    {
      "x": -30,
      "y": 37,
      "z": 5,
      "name": "Deco_Bone_Full",
      "rotation": 1
    },
    {
      "x": -30,
      "y": 38,
      "z": 5,
      "name": "Deco_Bone_Full",
      "rotation": 1
    },
    {
      "x": -30,
      "y": 39,
      "z": 5,
      "name": "Soil_Roots_Poisoned",
      "rotation": 1
    },
    {
      "x": -30,
      "y": 40,
      "z": 5,
      "name": "Soil_Roots_Poisoned",
      "rotation": 1
    },
    {
      "x": -30,
      "y": 0,
      "z": 6,
      "name": "Soil_Grass"
    },
    {
      "x": -30,
      "y": 33,
      "z": 6,
      "name": "Deco_Bone_Full",
      "rotation": 1
    },
    {
      "x": -30,
      "y": 34,
      "z": 6,
      "name": "Deco_Bone_Full",
      "rotation": 1
    },
    {
      "x": -30,
      "y": 35,
      "z": 6,
      "name": "Deco_Bone_Full",
      "rotation": 1
    },
    {
      "x": -30,
      "y": 36,
      "z": 6,
      "name": "Deco_Bone_Full",
      "rotation": 1
    },
    {
      "x": -30,
      "y": 37,
      "z": 6,
      "name": "Deco_Bone_Full",
      "rotation": 1
    },
    {
      "x": -30,
      "y": 38,
      "z": 6,
      "name": "Deco_Bone_Full",
      "rotation": 1
    },
    {
      "x": -30,
      "y": 39,
      "z": 6,
      "name": "Deco_Bone_Full",
      "rotation": 1
    },
    {
      "x": -30,
      "y": 40,
      "z": 6,
      "name": "Deco_Bone_Full",
      "rotation": 1
    },
    {
      "x": -30,
      "y": 41,
      "z": 6,
      "name": "Deco_Bone_Full",
      "rotation": 1
    },
    {
      "x": -30,
      "y": 42,
      "z": 6,
      "name": "Deco_Bone_Full",
      "rotation": 1
    },
    {
      "x": -30,
      "y": 43,
      "z": 6,
      "name": "Soil_Hive_Corrupted",
      "rotation": 1
    },
    {
      "x": -30,
      "y": 44,
      "z": 6,
      "name": "Soil_Hive_Corrupted",
      "rotation": 1
    },
    {
      "x": -30,
      "y": 0,
      "z": 7,
      "name": "Soil_Grass"
    },
    {
      "x": -30,
      "y": 35,
      "z": 7,
      "name": "Deco_Bone_Full",
      "rotation": 1
    },
    {
      "x": -30,
      "y": 36,
      "z": 7,
      "name": "Deco_Bone_Full",
      "rotation": 1
    },
    {
      "x": -30,
      "y": 37,
      "z": 7,
      "name": "Deco_Bone_Full",
      "rotation": 1
    },
    {
      "x": -30,
      "y": 38,
      "z": 7,
      "name": "Deco_Bone_Full",
      "rotation": 1
    },
    {
      "x": -30,
      "y": 39,
      "z": 7,
      "name": "Deco_Bone_Full",
      "rotation": 1
    },
    {
      "x": -30,
      "y": 40,
      "z": 7,
      "name": "Deco_Bone_Full",
      "rotation": 1
    },
    {
      "x": -30,
      "y": 41,
      "z": 7,
      "name": "Deco_Bone_Full",
      "rotation": 1
    },
    {
      "x": -30,
      "y": 42,
      "z": 7,
      "name": "Deco_Bone_Full",
      "rotation": 1
    },
    {
      "x": -30,
      "y": 43,
      "z": 7,
      "name": "Deco_Bone_Full",
      "rotation": 1
    },
    {
      "x": -30,
      "y": 44,
      "z": 7,
      "name": "Deco_Bone_Full",
      "rotation": 1
    },
    {
      "x": -30,
      "y": 45,
      "z": 7,
      "name": "Deco_Bone_Full",
      "rotation": 1
    },
    {
      "x": -30,
      "y": 46,
      "z": 7,
      "name": "Soil_Hive_Corrupted",
      "rotation": 1
    },
    {
      "x": -30,
      "y": 47,
      "z": 7,
      "name": "Soil_Hive_Corrupted",
      "rotation": 1
    },
    {
      "x": -30,
      "y": 0,
      "z": 8,
      "name": "Soil_Grass"
    },
    {
      "x": -30,
      "y": 38,
      "z": 8,
      "name": "Deco_Bone_Full",
      "rotation": 1
    },
    {
      "x": -30,
      "y": 39,
      "z": 8,
      "name": "Deco_Bone_Full",
      "rotation": 1
    },
    {
      "x": -30,
      "y": 40,
      "z": 8,
      "name": "Deco_Bone_Full",
      "rotation": 1
    },
    {
      "x": -30,
      "y": 41,
      "z": 8,
      "name": "Deco_Bone_Full",
      "rotation": 1
    },
    {
      "x": -30,
      "y": 42,
      "z": 8,
      "name": "Deco_Bone_Full",
      "rotation": 1
    },
    {
      "x": -30,
      "y": 43,
      "z": 8,
      "name": "Deco_Bone_Full",
      "rotation": 1
    },
    {
      "x": -30,
      "y": 44,
      "z": 8,
      "name": "Deco_Bone_Full",
      "rotation": 1
    },
    {
      "x": -30,
      "y": 45,
      "z": 8,
      "name": "Deco_Bone_Full",
      "rotation": 1
    },
    {
      "x": -30,
      "y": 46,
      "z": 8,
      "name": "Deco_Bone_Full",
      "rotation": 1
    },
    {
      "x": -30,
      "y": 47,
      "z": 8,
      "name": "Deco_Bone_Full",
      "rotation": 1
    },
    {
      "x": -30,
      "y": 48,
      "z": 8,
      "name": "Soil_Roots_Poisoned",
      "rotation": 1
    },
    {
      "x": -30,
      "y": 49,
      "z": 8,
      "name": "Soil_Roots_Poisoned",
      "rotation": 1
    },
    {
      "x": -30,
      "y": 0,
      "z": 9,
      "name": "Soil_Grass"
    },
    {
      "x": -30,
      "y": 42,
      "z": 9,
      "name": "Deco_Bone_Full",
      "rotation": 1
    },
    {
      "x": -30,
      "y": 43,
      "z": 9,
      "name": "Deco_Bone_Full",
      "rotation": 1
    },
    {
      "x": -30,
      "y": 44,
      "z": 9,
      "name": "Deco_Bone_Full",
      "rotation": 1
    },
    {
      "x": -30,
      "y": 45,
      "z": 9,
      "name": "Deco_Bone_Full",
      "rotation": 1
    },
    {
      "x": -30,
      "y": 46,
      "z": 9,
      "name": "Deco_Bone_Full",
      "rotation": 1
    },
    {
      "x": -30,
      "y": 47,
      "z": 9,
      "name": "Soil_Hive_Corrupted",
      "rotation": 1
    },
    {
      "x": -30,
      "y": 48,
      "z": 9,
      "name": "Soil_Hive_Corrupted",
      "rotation": 1
    },
    {
      "x": -30,
      "y": 0,
      "z": 10,
      "name": "Soil_Grass"
    },
    {
      "x": -30,
      "y": 0,
      "z": 11,
      "name": "Soil_Grass"
    },
    {
      "x": -30,
      "y": 0,
      "z": 12,
      "name": "Soil_Grass"
    },
    {
      "x": -30,
      "y": 0,
      "z": 13,
      "name": "Soil_Grass"
    },
    {
      "x": -30,
      "y": 0,
      "z": 14,
      "name": "Soil_Grass"
    },
    {
      "x": -30,
      "y": 0,
      "z": 15,
      "name": "Soil_Grass"
    },
    {
      "x": -29,
      "y": 0,
      "z": -15,
      "name": "Soil_Grass"
    },
    {
      "x": -29,
      "y": 0,
      "z": -14,
      "name": "Soil_Grass"
    },
    {
      "x": -29,
      "y": 0,
      "z": -13,
      "name": "Soil_Grass"
    },
    {
      "x": -29,
      "y": 0,
      "z": -12,
      "name": "Soil_Grass"
    },
    {
      "x": -29,
      "y": 0,
      "z": -11,
      "name": "Soil_Grass"
    },
    {
      "x": -29,
      "y": 0,
      "z": -10,
      "name": "Soil_Grass"
    },
    {
      "x": -29,
      "y": 0,
      "z": -9,
      "name": "Soil_Grass"
    },
    {
      "x": -29,
      "y": 0,
      "z": -8,
      "name": "Soil_Grass"
    },
    {
      "x": -29,
      "y": 0,
      "z": -7,
      "name": "Soil_Grass"
    },
    {
      "x": -29,
      "y": 0,
      "z": -6,
      "name": "Soil_Grass"
    },
    {
      "x": -29,
      "y": 0,
      "z": -5,
      "name": "Soil_Grass"
    },
    {
      "x": -29,
      "y": 0,
      "z": -4,
      "name": "Soil_Grass"
    },
    {
      "x": -29,
      "y": 0,
      "z": -3,
      "name": "Soil_Grass"
    },
    {
      "x": -29,
      "y": 28,
      "z": -3,
      "name": "Deco_Bone_Full",
      "rotation": 1
    },
    {
      "x": -29,
      "y": 29,
      "z": -3,
      "name": "Deco_Bone_Full",
      "rotation": 1
    },
    {
      "x": -29,
      "y": 30,
      "z": -3,
      "name": "Deco_Bone_Full",
      "rotation": 1
    },
    {
      "x": -29,
      "y": 31,
      "z": -3,
      "name": "Deco_Bone_Full",
      "rotation": 1
    },
    {
      "x": -29,
      "y": 32,
      "z": -3,
      "name": "Soil_Hive_Corrupted",
      "rotation": 1
    },
    {
      "x": -29,
      "y": 33,
      "z": -3,
      "name": "Soil_Hive_Corrupted",
      "rotation": 1
    },
    {
      "x": -29,
      "y": 0,
      "z": -2,
      "name": "Soil_Grass"
    },
    {
      "x": -29,
      "y": 27,
      "z": -2,
      "name": "Deco_Bone_Full",
      "rotation": 1
    },
    {
      "x": -29,
      "y": 28,
      "z": -2,
      "name": "Deco_Bone_Full",
      "rotation": 1
    },
    {
      "x": -29,
      "y": 29,
      "z": -2,
      "name": "Deco_Bone_Full",
      "rotation": 1
    },
    {
      "x": -29,
      "y": 30,
      "z": -2,
      "name": "Deco_Bone_Full",
      "rotation": 1
    },
    {
      "x": -29,
      "y": 31,
      "z": -2,
      "name": "Deco_Bone_Full",
      "rotation": 1
    },
    {
      "x": -29,
      "y": 32,
      "z": -2,
      "name": "Deco_Bone_Full",
      "rotation": 1
    },
    {
      "x": -29,
      "y": 33,
      "z": -2,
      "name": "Deco_Bone_Full",
      "rotation": 1
    },
    {
      "x": -29,
      "y": 34,
      "z": -2,
      "name": "Deco_Bone_Full",
      "rotation": 1
    },
    {
      "x": -29,
      "y": 35,
      "z": -2,
      "name": "Deco_Bone_Full",
      "rotation": 1
    },
    {
      "x": -29,
      "y": 36,
      "z": -2,
      "name": "Deco_Bone_Full",
      "rotation": 1
    },
    {
      "x": -29,
      "y": 37,
      "z": -2,
      "name": "Deco_Bone_Full",
      "rotation": 1
    },
    {
      "x": -29,
      "y": 38,
      "z": -2,
      "name": "Soil_Roots_Poisoned",
      "rotation": 1
    },
    {
      "x": -29,
      "y": 39,
      "z": -2,
      "name": "Soil_Hive_Corrupted",
      "rotation": 1
    },
    {
      "x": -29,
      "y": 0,
      "z": -1,
      "name": "Soil_Grass"
    },
    {
      "x": -29,
      "y": 28,
      "z": -1,
      "name": "Deco_Bone_Full",
      "rotation": 1
    },
    {
      "x": -29,
      "y": 29,
      "z": -1,
      "name": "Deco_Bone_Full",
      "rotation": 1
    },
    {
      "x": -29,
      "y": 30,
      "z": -1,
      "name": "Deco_Bone_Full",
      "rotation": 1
    },
    {
      "x": -29,
      "y": 31,
      "z": -1,
      "name": "Deco_Bone_Full",
      "rotation": 1
    },
    {
      "x": -29,
      "y": 32,
      "z": -1,
      "name": "Deco_Bone_Full",
      "rotation": 1
    },
    {
      "x": -29,
      "y": 33,
      "z": -1,
      "name": "Deco_Bone_Full",
      "rotation": 1
    },
    {
      "x": -29,
      "y": 34,
      "z": -1,
      "name": "Deco_Bone_Full",
      "rotation": 1
    },
    {
      "x": -29,
      "y": 35,
      "z": -1,
      "name": "Deco_Bone_Full",
      "rotation": 1
    },
    {
      "x": -29,
      "y": 36,
      "z": -1,
      "name": "Deco_Bone_Full",
      "rotation": 1
    },
    {
      "x": -29,
      "y": 37,
      "z": -1,
      "name": "Deco_Bone_Full",
      "rotation": 1
    },
    {
      "x": -29,
      "y": 38,
      "z": -1,
      "name": "Deco_Bone_Full",
      "rotation": 1
    },
    {
      "x": -29,
      "y": 39,
      "z": -1,
      "name": "Deco_Bone_Full",
      "rotation": 1
    },
    {
      "x": -29,
      "y": 40,
      "z": -1,
      "name": "Deco_Bone_Full",
      "rotation": 1
    },
    {
      "x": -29,
      "y": 41,
      "z": -1,
      "name": "Deco_Bone_Full",
      "rotation": 1
    },
    {
      "x": -29,
      "y": 42,
      "z": -1,
      "name": "Soil_Hive_Corrupted",
      "rotation": 1
    },
    {
      "x": -29,
      "y": 43,
      "z": -1,
      "name": "Soil_Roots_Poisoned",
      "rotation": 1
    },
    {
      "x": -29,
      "y": 0,
      "z": 0,
      "name": "Soil_Grass"
    },
    {
      "x": -29,
      "y": 30,
      "z": 0,
      "name": "Deco_Bone_Full",
      "rotation": 1
    },
    {
      "x": -29,
      "y": 31,
      "z": 0,
      "name": "Deco_Bone_Full",
      "rotation": 1
    },
    {
      "x": -29,
      "y": 32,
      "z": 0,
      "name": "Deco_Bone_Full",
      "rotation": 1
    },
    {
      "x": -29,
      "y": 33,
      "z": 0,
      "name": "Deco_Bone_Full",
      "rotation": 1
    },
    {
      "x": -29,
      "y": 34,
      "z": 0,
      "name": "Deco_Bone_Full",
      "rotation": 1
    },
    {
      "x": -29,
      "y": 35,
      "z": 0,
      "name": "Deco_Bone_Full",
      "rotation": 1
    },
    {
      "x": -29,
      "y": 36,
      "z": 0,
      "name": "Deco_Bone_Full",
      "rotation": 1
    },
    {
      "x": -29,
      "y": 37,
      "z": 0,
      "name": "Deco_Bone_Full",
      "rotation": 1
    },
    {
      "x": -29,
      "y": 38,
      "z": 0,
      "name": "Deco_Bone_Full",
      "rotation": 1
    },
    {
      "x": -29,
      "y": 39,
      "z": 0,
      "name": "Deco_Bone_Full",
      "rotation": 1
    },
    {
      "x": -29,
      "y": 40,
      "z": 0,
      "name": "Deco_Bone_Full",
      "rotation": 1
    },
    {
      "x": -29,
      "y": 41,
      "z": 0,
      "name": "Deco_Bone_Full",
      "rotation": 1
    },
    {
      "x": -29,
      "y": 42,
      "z": 0,
      "name": "Deco_Bone_Full",
      "rotation": 1
    },
    {
      "x": -29,
      "y": 43,
      "z": 0,
      "name": "Deco_Bone_Full",
      "rotation": 1
    },
    {
      "x": -29,
      "y": 44,
      "z": 0,
      "name": "Soil_Hive_Corrupted",
      "rotation": 1
    },
    {
      "x": -29,
      "y": 45,
      "z": 0,
      "name": "Soil_Roots_Poisoned",
      "rotation": 1
    },
    {
      "x": -29,
      "y": 0,
      "z": 1,
      "name": "Soil_Grass"
    },
    {
      "x": -29,
      "y": 35,
      "z": 1,
      "name": "Deco_Bone_Full",
      "rotation": 1
    },
    {
      "x": -29,
      "y": 36,
      "z": 1,
      "name": "Deco_Bone_Full",
      "rotation": 1
    },
    {
      "x": -29,
      "y": 37,
      "z": 1,
      "name": "Deco_Bone_Full",
      "rotation": 1
    },
    {
      "x": -29,
      "y": 38,
      "z": 1,
      "name": "Deco_Bone_Full",
      "rotation": 1
    },
    {
      "x": -29,
      "y": 39,
      "z": 1,
      "name": "Deco_Bone_Full",
      "rotation": 1
    },
    {
      "x": -29,
      "y": 40,
      "z": 1,
      "name": "Deco_Bone_Full",
      "rotation": 1
    },
    {
      "x": -29,
      "y": 41,
      "z": 1,
      "name": "Deco_Bone_Full",
      "rotation": 1
    },
    {
      "x": -29,
      "y": 42,
      "z": 1,
      "name": "Deco_Bone_Full",
      "rotation": 1
    },
    {
      "x": -29,
      "y": 43,
      "z": 1,
      "name": "Deco_Bone_Full",
      "rotation": 1
    },
    {
      "x": -29,
      "y": 44,
      "z": 1,
      "name": "Soil_Hive_Corrupted",
      "rotation": 1
    },
    {
      "x": -29,
      "y": 45,
      "z": 1,
      "name": "Soil_Hive_Corrupted",
      "rotation": 1
    },
    {
      "x": -29,
      "y": 0,
      "z": 2,
      "name": "Soil_Grass"
    },
    {
      "x": -29,
      "y": 0,
      "z": 3,
      "name": "Soil_Grass"
    },
    {
      "x": -29,
      "y": 0,
      "z": 4,
      "name": "Soil_Grass"
    },
    {
      "x": -29,
      "y": 30,
      "z": 4,
      "name": "Deco_Bone_Full",
      "rotation": 1
    },
    {
      "x": -29,
      "y": 31,
      "z": 4,
      "name": "Deco_Bone_Full",
      "rotation": 1
    },
    {
      "x": -29,
      "y": 32,
      "z": 4,
      "name": "Deco_Bone_Full",
      "rotation": 1
    },
    {
      "x": -29,
      "y": 33,
      "z": 4,
      "name": "Deco_Bone_Full",
      "rotation": 1
    },
    {
      "x": -29,
      "y": 34,
      "z": 4,
      "name": "Soil_Hive_Corrupted",
      "rotation": 1
    },
    {
      "x": -29,
      "y": 35,
      "z": 4,
      "name": "Soil_Hive_Corrupted",
      "rotation": 1
    },
    {
      "x": -29,
      "y": 0,
      "z": 5,
      "name": "Soil_Grass"
    },
    {
      "x": -29,
      "y": 30,
      "z": 5,
      "name": "Deco_Bone_Full",
      "rotation": 1
    },
    {
      "x": -29,
      "y": 31,
      "z": 5,
      "name": "Deco_Bone_Full",
      "rotation": 1
    },
    {
      "x": -29,
      "y": 32,
      "z": 5,
      "name": "Deco_Bone_Full",
      "rotation": 1
    },
    {
      "x": -29,
      "y": 33,
      "z": 5,
      "name": "Deco_Bone_Full",
      "rotation": 1
    },
    {
      "x": -29,
      "y": 34,
      "z": 5,
      "name": "Deco_Bone_Full",
      "rotation": 1
    },
    {
      "x": -29,
      "y": 35,
      "z": 5,
      "name": "Deco_Bone_Full",
      "rotation": 1
    },
    {
      "x": -29,
      "y": 36,
      "z": 5,
      "name": "Soil_Hive_Corrupted",
      "rotation": 1
    },
    {
      "x": -29,
      "y": 37,
      "z": 5,
      "name": "Soil_Hive_Corrupted",
      "rotation": 1
    },
    {
      "x": -29,
      "y": 0,
      "z": 6,
      "name": "Soil_Grass"
    },
    {
      "x": -29,
      "y": 31,
      "z": 6,
      "name": "Deco_Bone_Full",
      "rotation": 1
    },
    {
      "x": -29,
      "y": 32,
      "z": 6,
      "name": "Deco_Bone_Full",
      "rotation": 1
    },
    {
      "x": -29,
      "y": 33,
      "z": 6,
      "name": "Deco_Bone_Full",
      "rotation": 1
    },
    {
      "x": -29,
      "y": 34,
      "z": 6,
      "name": "Deco_Bone_Full",
      "rotation": 1
    },
    {
      "x": -29,
      "y": 35,
      "z": 6,
      "name": "Deco_Bone_Full",
      "rotation": 1
    },
    {
      "x": -29,
      "y": 36,
      "z": 6,
      "name": "Deco_Bone_Full",
      "rotation": 1
    },
    {
      "x": -29,
      "y": 37,
      "z": 6,
      "name": "Deco_Bone_Full",
      "rotation": 1
    },
    {
      "x": -29,
      "y": 38,
      "z": 6,
      "name": "Deco_Bone_Full",
      "rotation": 1
    },
    {
      "x": -29,
      "y": 39,
      "z": 6,
      "name": "Deco_Bone_Full",
      "rotation": 1
    },
    {
      "x": -29,
      "y": 40,
      "z": 6,
      "name": "Soil_Hive_Corrupted",
      "rotation": 1
    },
    {
      "x": -29,
      "y": 41,
      "z": 6,
      "name": "Soil_Hive_Corrupted",
      "rotation": 1
    },
    {
      "x": -29,
      "y": 0,
      "z": 7,
      "name": "Soil_Grass"
    },
    {
      "x": -29,
      "y": 33,
      "z": 7,
      "name": "Deco_Bone_Full",
      "rotation": 1
    },
    {
      "x": -29,
      "y": 34,
      "z": 7,
      "name": "Deco_Bone_Full",
      "rotation": 1
    },
    {
      "x": -29,
      "y": 35,
      "z": 7,
      "name": "Deco_Bone_Full",
      "rotation": 1
    },
    {
      "x": -29,
      "y": 36,
      "z": 7,
      "name": "Deco_Bone_Full",
      "rotation": 1
    },
    {
      "x": -29,
      "y": 37,
      "z": 7,
      "name": "Deco_Bone_Full",
      "rotation": 1
    },
    {
      "x": -29,
      "y": 38,
      "z": 7,
      "name": "Deco_Bone_Full",
      "rotation": 1
    },
    {
      "x": -29,
      "y": 39,
      "z": 7,
      "name": "Deco_Bone_Full",
      "rotation": 1
    },
    {
      "x": -29,
      "y": 40,
      "z": 7,
      "name": "Deco_Bone_Full",
      "rotation": 1
    },
    {
      "x": -29,
      "y": 41,
      "z": 7,
      "name": "Deco_Bone_Full",
      "rotation": 1
    },
    {
      "x": -29,
      "y": 42,
      "z": 7,
      "name": "Deco_Bone_Full",
      "rotation": 1
    },
    {
      "x": -29,
      "y": 43,
      "z": 7,
      "name": "Deco_Bone_Full",
      "rotation": 1
    },
    {
      "x": -29,
      "y": 44,
      "z": 7,
      "name": "Deco_Bone_Full",
      "rotation": 1
    },
    {
      "x": -29,
      "y": 45,
      "z": 7,
      "name": "Deco_Bone_Full",
      "rotation": 1
    },
    {
      "x": -29,
      "y": 46,
      "z": 7,
      "name": "Soil_Hive_Corrupted",
      "rotation": 1
    },
    {
      "x": -29,
      "y": 47,
      "z": 7,
      "name": "Soil_Roots_Poisoned",
      "rotation": 1
    },
    {
      "x": -29,
      "y": 0,
      "z": 8,
      "name": "Soil_Grass"
    },
    {
      "x": -29,
      "y": 36,
      "z": 8,
      "name": "Deco_Bone_Full",
      "rotation": 1
    },
    {
      "x": -29,
      "y": 37,
      "z": 8,
      "name": "Deco_Bone_Full",
      "rotation": 1
    },
    {
      "x": -29,
      "y": 38,
      "z": 8,
      "name": "Deco_Bone_Full",
      "rotation": 1
    },
    {
      "x": -29,
      "y": 39,
      "z": 8,
      "name": "Deco_Bone_Full",
      "rotation": 1
    },
    {
      "x": -29,
      "y": 40,
      "z": 8,
      "name": "Deco_Bone_Full",
      "rotation": 1
    },
    {
      "x": -29,
      "y": 41,
      "z": 8,
      "name": "Deco_Bone_Full",
      "rotation": 1
    },
    {
      "x": -29,
      "y": 42,
      "z": 8,
      "name": "Deco_Bone_Full",
      "rotation": 1
    },
    {
      "x": -29,
      "y": 43,
      "z": 8,
      "name": "Deco_Bone_Full",
      "rotation": 1
    },
    {
      "x": -29,
      "y": 44,
      "z": 8,
      "name": "Deco_Bone_Full",
      "rotation": 1
    },
    {
      "x": -29,
      "y": 45,
      "z": 8,
      "name": "Deco_Bone_Full",
      "rotation": 1
    },
    {
      "x": -29,
      "y": 46,
      "z": 8,
      "name": "Deco_Bone_Full",
      "rotation": 1
    },
    {
      "x": -29,
      "y": 47,
      "z": 8,
      "name": "Deco_Bone_Full",
      "rotation": 1
    },
    {
      "x": -29,
      "y": 48,
      "z": 8,
      "name": "Deco_Bone_Full",
      "rotation": 1
    },
    {
      "x": -29,
      "y": 49,
      "z": 8,
      "name": "Soil_Roots_Poisoned",
      "rotation": 1
    },
    {
      "x": -29,
      "y": 50,
      "z": 8,
      "name": "Soil_Roots_Poisoned",
      "rotation": 1
    },
    {
      "x": -29,
      "y": 0,
      "z": 9,
      "name": "Soil_Grass"
    },
    {
      "x": -29,
      "y": 40,
      "z": 9,
      "name": "Deco_Bone_Full",
      "rotation": 1
    },
    {
      "x": -29,
      "y": 41,
      "z": 9,
      "name": "Deco_Bone_Full",
      "rotation": 1
    },
    {
      "x": -29,
      "y": 42,
      "z": 9,
      "name": "Deco_Bone_Full",
      "rotation": 1
    },
    {
      "x": -29,
      "y": 43,
      "z": 9,
      "name": "Deco_Bone_Full",
      "rotation": 1
    },
    {
      "x": -29,
      "y": 44,
      "z": 9,
      "name": "Deco_Bone_Full",
      "rotation": 1
    },
    {
      "x": -29,
      "y": 45,
      "z": 9,
      "name": "Deco_Bone_Full",
      "rotation": 1
    },
    {
      "x": -29,
      "y": 46,
      "z": 9,
      "name": "Deco_Bone_Full",
      "rotation": 1
    },
    {
      "x": -29,
      "y": 47,
      "z": 9,
      "name": "Deco_Bone_Full",
      "rotation": 1
    },
    {
      "x": -29,
      "y": 48,
      "z": 9,
      "name": "Deco_Bone_Full",
      "rotation": 1
    },
    {
      "x": -29,
      "y": 49,
      "z": 9,
      "name": "Deco_Bone_Full",
      "rotation": 1
    },
    {
      "x": -29,
      "y": 50,
      "z": 9,
      "name": "Deco_Bone_Full",
      "rotation": 1
    },
    {
      "x": -29,
      "y": 51,
      "z": 9,
      "name": "Soil_Hive_Corrupted",
      "rotation": 1
    },
    {
      "x": -29,
      "y": 52,
      "z": 9,
      "name": "Soil_Hive_Corrupted",
      "rotation": 1
    },
    {
      "x": -29,
      "y": 0,
      "z": 10,
      "name": "Soil_Grass"
    },
    {
      "x": -29,
      "y": 45,
      "z": 10,
      "name": "Deco_Bone_Full",
      "rotation": 1
    },
    {
      "x": -29,
      "y": 46,
      "z": 10,
      "name": "Deco_Bone_Full",
      "rotation": 1
    },
    {
      "x": -29,
      "y": 47,
      "z": 10,
      "name": "Deco_Bone_Full",
      "rotation": 1
    },
    {
      "x": -29,
      "y": 48,
      "z": 10,
      "name": "Deco_Bone_Full",
      "rotation": 1
    },
    {
      "x": -29,
      "y": 49,
      "z": 10,
      "name": "Deco_Bone_Full",
      "rotation": 1
    },
    {
      "x": -29,
      "y": 50,
      "z": 10,
      "name": "Deco_Bone_Full",
      "rotation": 1
    },
    {
      "x": -29,
      "y": 51,
      "z": 10,
      "name": "Soil_Hive_Corrupted",
      "rotation": 1
    },
    {
      "x": -29,
      "y": 52,
      "z": 10,
      "name": "Soil_Hive_Corrupted",
      "rotation": 1
    },
    {
      "x": -29,
      "y": 0,
      "z": 11,
      "name": "Soil_Grass"
    },
    {
      "x": -29,
      "y": 0,
      "z": 12,
      "name": "Soil_Grass"
    },
    {
      "x": -29,
      "y": 0,
      "z": 13,
      "name": "Soil_Grass"
    },
    {
      "x": -29,
      "y": 0,
      "z": 14,
      "name": "Soil_Grass"
    },
    {
      "x": -29,
      "y": 0,
      "z": 15,
      "name": "Soil_Grass"
    },
    {
      "x": -28,
      "y": 0,
      "z": -15,
      "name": "Soil_Grass"
    },
    {
      "x": -28,
      "y": 0,
      "z": -14,
      "name": "Soil_Grass"
    },
    {
      "x": -28,
      "y": 0,
      "z": -13,
      "name": "Soil_Grass"
    },
    {
      "x": -28,
      "y": 0,
      "z": -12,
      "name": "Soil_Grass"
    },
    {
      "x": -28,
      "y": 0,
      "z": -11,
      "name": "Soil_Grass"
    },
    {
      "x": -28,
      "y": 0,
      "z": -10,
      "name": "Soil_Grass"
    },
    {
      "x": -28,
      "y": 0,
      "z": -9,
      "name": "Soil_Grass"
    },
    {
      "x": -28,
      "y": 0,
      "z": -8,
      "name": "Soil_Grass"
    },
    {
      "x": -28,
      "y": 0,
      "z": -7,
      "name": "Soil_Grass"
    },
    {
      "x": -28,
      "y": 0,
      "z": -6,
      "name": "Soil_Grass"
    },
    {
      "x": -28,
      "y": 0,
      "z": -5,
      "name": "Soil_Grass"
    },
    {
      "x": -28,
      "y": 0,
      "z": -4,
      "name": "Soil_Grass"
    },
    {
      "x": -28,
      "y": 0,
      "z": -3,
      "name": "Soil_Grass"
    },
    {
      "x": -28,
      "y": 25,
      "z": -3,
      "name": "Deco_Bone_Full",
      "rotation": 1
    },
    {
      "x": -28,
      "y": 26,
      "z": -3,
      "name": "Deco_Bone_Full",
      "rotation": 1
    },
    {
      "x": -28,
      "y": 27,
      "z": -3,
      "name": "Deco_Bone_Full",
      "rotation": 1
    },
    {
      "x": -28,
      "y": 28,
      "z": -3,
      "name": "Deco_Bone_Full",
      "rotation": 1
    },
    {
      "x": -28,
      "y": 29,
      "z": -3,
      "name": "Soil_Hive_Corrupted",
      "rotation": 1
    },
    {
      "x": -28,
      "y": 30,
      "z": -3,
      "name": "Soil_Roots_Poisoned",
      "rotation": 1
    },
    {
      "x": -28,
      "y": 0,
      "z": -2,
      "name": "Soil_Grass"
    },
    {
      "x": -28,
      "y": 25,
      "z": -2,
      "name": "Deco_Bone_Full",
      "rotation": 1
    },
    {
      "x": -28,
      "y": 26,
      "z": -2,
      "name": "Deco_Bone_Full",
      "rotation": 1
    },
    {
      "x": -28,
      "y": 27,
      "z": -2,
      "name": "Deco_Bone_Full",
      "rotation": 1
    },
    {
      "x": -28,
      "y": 28,
      "z": -2,
      "name": "Deco_Bone_Full",
      "rotation": 1
    },
    {
      "x": -28,
      "y": 29,
      "z": -2,
      "name": "Deco_Bone_Full",
      "rotation": 1
    },
    {
      "x": -28,
      "y": 30,
      "z": -2,
      "name": "Deco_Bone_Full",
      "rotation": 1
    },
    {
      "x": -28,
      "y": 31,
      "z": -2,
      "name": "Deco_Bone_Full",
      "rotation": 1
    },
    {
      "x": -28,
      "y": 32,
      "z": -2,
      "name": "Soil_Roots_Poisoned",
      "rotation": 1
    },
    {
      "x": -28,
      "y": 33,
      "z": -2,
      "name": "Soil_Hive_Corrupted",
      "rotation": 1
    },
    {
      "x": -28,
      "y": 0,
      "z": -1,
      "name": "Soil_Grass"
    },
    {
      "x": -28,
      "y": 26,
      "z": -1,
      "name": "Deco_Bone_Full",
      "rotation": 1
    },
    {
      "x": -28,
      "y": 27,
      "z": -1,
      "name": "Deco_Bone_Full",
      "rotation": 1
    },
    {
      "x": -28,
      "y": 28,
      "z": -1,
      "name": "Deco_Bone_Full",
      "rotation": 1
    },
    {
      "x": -28,
      "y": 29,
      "z": -1,
      "name": "Deco_Bone_Full",
      "rotation": 1
    },
    {
      "x": -28,
      "y": 30,
      "z": -1,
      "name": "Deco_Bone_Full",
      "rotation": 1
    },
    {
      "x": -28,
      "y": 31,
      "z": -1,
      "name": "Deco_Bone_Full",
      "rotation": 1
    },
    {
      "x": -28,
      "y": 32,
      "z": -1,
      "name": "Deco_Bone_Full",
      "rotation": 1
    },
    {
      "x": -28,
      "y": 33,
      "z": -1,
      "name": "Deco_Bone_Full",
      "rotation": 1
    },
    {
      "x": -28,
      "y": 34,
      "z": -1,
      "name": "Deco_Bone_Full",
      "rotation": 1
    },
    {
      "x": -28,
      "y": 35,
      "z": -1,
      "name": "Deco_Bone_Full",
      "rotation": 1
    },
    {
      "x": -28,
      "y": 36,
      "z": -1,
      "name": "Deco_Bone_Full",
      "rotation": 1
    },
    {
      "x": -28,
      "y": 37,
      "z": -1,
      "name": "Soil_Hive_Corrupted",
      "rotation": 1
    },
    {
      "x": -28,
      "y": 38,
      "z": -1,
      "name": "Soil_Hive_Corrupted",
      "rotation": 1
    },
    {
      "x": -28,
      "y": 40,
      "z": -1,
      "name": "Soil_Hive_Corrupted",
      "rotation": 1
    },
    {
      "x": -28,
      "y": 41,
      "z": -1,
      "name": "Soil_Roots_Poisoned",
      "rotation": 1
    },
    {
      "x": -28,
      "y": 43,
      "z": -1,
      "name": "Soil_Hive_Corrupted",
      "rotation": 1
    },
    {
      "x": -28,
      "y": 44,
      "z": -1,
      "name": "Soil_Hive_Corrupted",
      "rotation": 1
    },
    {
      "x": -28,
      "y": 0,
      "z": 0,
      "name": "Soil_Grass"
    },
    {
      "x": -28,
      "y": 29,
      "z": 0,
      "name": "Deco_Bone_Full",
      "rotation": 1
    },
    {
      "x": -28,
      "y": 30,
      "z": 0,
      "name": "Deco_Bone_Full",
      "rotation": 1
    },
    {
      "x": -28,
      "y": 31,
      "z": 0,
      "name": "Deco_Bone_Full",
      "rotation": 1
    },
    {
      "x": -28,
      "y": 32,
      "z": 0,
      "name": "Deco_Bone_Full",
      "rotation": 1
    },
    {
      "x": -28,
      "y": 33,
      "z": 0,
      "name": "Deco_Bone_Full",
      "rotation": 1
    },
    {
      "x": -28,
      "y": 34,
      "z": 0,
      "name": "Deco_Bone_Full",
      "rotation": 1
    },
    {
      "x": -28,
      "y": 35,
      "z": 0,
      "name": "Deco_Bone_Full",
      "rotation": 1
    },
    {
      "x": -28,
      "y": 36,
      "z": 0,
      "name": "Deco_Bone_Full",
      "rotation": 1
    },
    {
      "x": -28,
      "y": 37,
      "z": 0,
      "name": "Deco_Bone_Full",
      "rotation": 1
    },
    {
      "x": -28,
      "y": 38,
      "z": 0,
      "name": "Deco_Bone_Full",
      "rotation": 1
    },
    {
      "x": -28,
      "y": 39,
      "z": 0,
      "name": "Deco_Bone_Full",
      "rotation": 1
    },
    {
      "x": -28,
      "y": 40,
      "z": 0,
      "name": "Deco_Bone_Full",
      "rotation": 1
    },
    {
      "x": -28,
      "y": 41,
      "z": 0,
      "name": "Deco_Bone_Full",
      "rotation": 1
    },
    {
      "x": -28,
      "y": 42,
      "z": 0,
      "name": "Deco_Bone_Full",
      "rotation": 1
    },
    {
      "x": -28,
      "y": 43,
      "z": 0,
      "name": "Deco_Bone_Full",
      "rotation": 1
    },
    {
      "x": -28,
      "y": 44,
      "z": 0,
      "name": "Deco_Bone_Full",
      "rotation": 1
    },
    {
      "x": -28,
      "y": 45,
      "z": 0,
      "name": "Deco_Bone_Full",
      "rotation": 1
    },
    {
      "x": -28,
      "y": 46,
      "z": 0,
      "name": "Soil_Roots_Poisoned",
      "rotation": 1
    },
    {
      "x": -28,
      "y": 47,
      "z": 0,
      "name": "Soil_Hive_Corrupted",
      "rotation": 1
    },
    {
      "x": -28,
      "y": 0,
      "z": 1,
      "name": "Soil_Grass"
    },
    {
      "x": -28,
      "y": 33,
      "z": 1,
      "name": "Deco_Bone_Full",
      "rotation": 1
    },
    {
      "x": -28,
      "y": 34,
      "z": 1,
      "name": "Deco_Bone_Full",
      "rotation": 1
    },
    {
      "x": -28,
      "y": 35,
      "z": 1,
      "name": "Deco_Bone_Full",
      "rotation": 1
    },
    {
      "x": -28,
      "y": 36,
      "z": 1,
      "name": "Deco_Bone_Full",
      "rotation": 1
    },
    {
      "x": -28,
      "y": 37,
      "z": 1,
      "name": "Deco_Bone_Full",
      "rotation": 1
    },
    {
      "x": -28,
      "y": 38,
      "z": 1,
      "name": "Deco_Bone_Full",
      "rotation": 1
    },
    {
      "x": -28,
      "y": 39,
      "z": 1,
      "name": "Deco_Bone_Full",
      "rotation": 1
    },
    {
      "x": -28,
      "y": 40,
      "z": 1,
      "name": "Deco_Bone_Full",
      "rotation": 1
    },
    {
      "x": -28,
      "y": 41,
      "z": 1,
      "name": "Deco_Bone_Full",
      "rotation": 1
    },
    {
      "x": -28,
      "y": 42,
      "z": 1,
      "name": "Deco_Bone_Full",
      "rotation": 1
    },
    {
      "x": -28,
      "y": 43,
      "z": 1,
      "name": "Deco_Bone_Full",
      "rotation": 1
    },
    {
      "x": -28,
      "y": 44,
      "z": 1,
      "name": "Deco_Bone_Full",
      "rotation": 1
    },
    {
      "x": -28,
      "y": 45,
      "z": 1,
      "name": "Deco_Bone_Full",
      "rotation": 1
    },
    {
      "x": -28,
      "y": 46,
      "z": 1,
      "name": "Soil_Roots_Poisoned",
      "rotation": 1
    },
    {
      "x": -28,
      "y": 47,
      "z": 1,
      "name": "Soil_Roots_Poisoned",
      "rotation": 1
    },
    {
      "x": -28,
      "y": 0,
      "z": 2,
      "name": "Soil_Grass"
    },
    {
      "x": -28,
      "y": 41,
      "z": 2,
      "name": "Soil_Hive_Corrupted",
      "rotation": 1
    },
    {
      "x": -28,
      "y": 43,
      "z": 2,
      "name": "Deco_Bone_Full",
      "rotation": 1
    },
    {
      "x": -28,
      "y": 44,
      "z": 2,
      "name": "Soil_Roots_Poisoned",
      "rotation": 1
    },
    {
      "x": -28,
      "y": 45,
      "z": 2,
      "name": "Soil_Roots_Poisoned",
      "rotation": 1
    },
    {
      "x": -28,
      "y": 0,
      "z": 3,
      "name": "Soil_Grass"
    },
    {
      "x": -28,
      "y": 28,
      "z": 3,
      "name": "Soil_Hive_Corrupted",
      "rotation": 1
    },
    {
      "x": -28,
      "y": 30,
      "z": 3,
      "name": "Soil_Roots_Poisoned",
      "rotation": 1
    },
    {
      "x": -28,
      "y": 0,
      "z": 4,
      "name": "Soil_Grass"
    },
    {
      "x": -28,
      "y": 28,
      "z": 4,
      "name": "Deco_Bone_Full",
      "rotation": 1
    },
    {
      "x": -28,
      "y": 29,
      "z": 4,
      "name": "Deco_Bone_Full",
      "rotation": 1
    },
    {
      "x": -28,
      "y": 30,
      "z": 4,
      "name": "Deco_Bone_Full",
      "rotation": 1
    },
    {
      "x": -28,
      "y": 31,
      "z": 4,
      "name": "Deco_Bone_Full",
      "rotation": 1
    },
    {
      "x": -28,
      "y": 32,
      "z": 4,
      "name": "Soil_Roots_Poisoned",
      "rotation": 1
    },
    {
      "x": -28,
      "y": 33,
      "z": 4,
      "name": "Soil_Hive_Corrupted",
      "rotation": 1
    },
    {
      "x": -28,
      "y": 0,
      "z": 5,
      "name": "Soil_Grass"
    },
    {
      "x": -28,
      "y": 27,
      "z": 5,
      "name": "Deco_Bone_Full",
      "rotation": 1
    },
    {
      "x": -28,
      "y": 28,
      "z": 5,
      "name": "Deco_Bone_Full",
      "rotation": 1
    },
    {
      "x": -28,
      "y": 29,
      "z": 5,
      "name": "Deco_Bone_Full",
      "rotation": 1
    },
    {
      "x": -28,
      "y": 30,
      "z": 5,
      "name": "Deco_Bone_Full",
      "rotation": 1
    },
    {
      "x": -28,
      "y": 31,
      "z": 5,
      "name": "Deco_Bone_Full",
      "rotation": 1
    },
    {
      "x": -28,
      "y": 32,
      "z": 5,
      "name": "Deco_Bone_Full",
      "rotation": 1
    },
    {
      "x": -28,
      "y": 33,
      "z": 5,
      "name": "Deco_Bone_Full",
      "rotation": 1
    },
    {
      "x": -28,
      "y": 34,
      "z": 5,
      "name": "Soil_Roots_Poisoned",
      "rotation": 1
    },
    {
      "x": -28,
      "y": 35,
      "z": 5,
      "name": "Soil_Roots_Poisoned",
      "rotation": 1
    },
    {
      "x": -28,
      "y": 0,
      "z": 6,
      "name": "Soil_Grass"
    },
    {
      "x": -28,
      "y": 29,
      "z": 6,
      "name": "Deco_Bone_Full",
      "rotation": 1
    },
    {
      "x": -28,
      "y": 30,
      "z": 6,
      "name": "Deco_Bone_Full",
      "rotation": 1
    },
    {
      "x": -28,
      "y": 31,
      "z": 6,
      "name": "Deco_Bone_Full",
      "rotation": 1
    },
    {
      "x": -28,
      "y": 32,
      "z": 6,
      "name": "Deco_Bone_Full",
      "rotation": 1
    },
    {
      "x": -28,
      "y": 33,
      "z": 6,
      "name": "Deco_Bone_Full",
      "rotation": 1
    },
    {
      "x": -28,
      "y": 34,
      "z": 6,
      "name": "Deco_Bone_Full",
      "rotation": 1
    },
    {
      "x": -28,
      "y": 35,
      "z": 6,
      "name": "Deco_Bone_Full",
      "rotation": 1
    },
    {
      "x": -28,
      "y": 36,
      "z": 6,
      "name": "Soil_Roots_Poisoned",
      "rotation": 1
    },
    {
      "x": -28,
      "y": 37,
      "z": 6,
      "name": "Soil_Hive_Corrupted",
      "rotation": 1
    },
    {
      "x": -28,
      "y": 0,
      "z": 7,
      "name": "Soil_Grass"
    },
    {
      "x": -28,
      "y": 31,
      "z": 7,
      "name": "Deco_Bone_Full",
      "rotation": 1
    },
    {
      "x": -28,
      "y": 32,
      "z": 7,
      "name": "Deco_Bone_Full",
      "rotation": 1
    },
    {
      "x": -28,
      "y": 33,
      "z": 7,
      "name": "Deco_Bone_Full",
      "rotation": 1
    },
    {
      "x": -28,
      "y": 34,
      "z": 7,
      "name": "Deco_Bone_Full",
      "rotation": 1
    },
    {
      "x": -28,
      "y": 35,
      "z": 7,
      "name": "Deco_Bone_Full",
      "rotation": 1
    },
    {
      "x": -28,
      "y": 36,
      "z": 7,
      "name": "Deco_Bone_Full",
      "rotation": 1
    },
    {
      "x": -28,
      "y": 37,
      "z": 7,
      "name": "Deco_Bone_Full",
      "rotation": 1
    },
    {
      "x": -28,
      "y": 38,
      "z": 7,
      "name": "Deco_Bone_Full",
      "rotation": 1
    },
    {
      "x": -28,
      "y": 39,
      "z": 7,
      "name": "Deco_Bone_Full",
      "rotation": 1
    },
    {
      "x": -28,
      "y": 40,
      "z": 7,
      "name": "Soil_Roots_Poisoned",
      "rotation": 1
    },
    {
      "x": -28,
      "y": 41,
      "z": 7,
      "name": "Soil_Roots_Poisoned",
      "rotation": 1
    },
    {
      "x": -28,
      "y": 0,
      "z": 8,
      "name": "Soil_Grass"
    },
    {
      "x": -28,
      "y": 34,
      "z": 8,
      "name": "Deco_Bone_Full",
      "rotation": 1
    },
    {
      "x": -28,
      "y": 35,
      "z": 8,
      "name": "Deco_Bone_Full",
      "rotation": 1
    },
    {
      "x": -28,
      "y": 36,
      "z": 8,
      "name": "Deco_Bone_Full",
      "rotation": 1
    },
    {
      "x": -28,
      "y": 37,
      "z": 8,
      "name": "Deco_Bone_Full",
      "rotation": 1
    },
    {
      "x": -28,
      "y": 38,
      "z": 8,
      "name": "Deco_Bone_Full",
      "rotation": 1
    },
    {
      "x": -28,
      "y": 39,
      "z": 8,
      "name": "Deco_Bone_Full",
      "rotation": 1
    },
    {
      "x": -28,
      "y": 40,
      "z": 8,
      "name": "Deco_Bone_Full",
      "rotation": 1
    },
    {
      "x": -28,
      "y": 41,
      "z": 8,
      "name": "Deco_Bone_Full",
      "rotation": 1
    },
    {
      "x": -28,
      "y": 42,
      "z": 8,
      "name": "Deco_Bone_Full",
      "rotation": 1
    },
    {
      "x": -28,
      "y": 43,
      "z": 8,
      "name": "Deco_Bone_Full",
      "rotation": 1
    },
    {
      "x": -28,
      "y": 44,
      "z": 8,
      "name": "Deco_Bone_Full",
      "rotation": 1
    },
    {
      "x": -28,
      "y": 45,
      "z": 8,
      "name": "Deco_Bone_Full",
      "rotation": 1
    },
    {
      "x": -28,
      "y": 46,
      "z": 8,
      "name": "Deco_Bone_Full",
      "rotation": 1
    },
    {
      "x": -28,
      "y": 47,
      "z": 8,
      "name": "Deco_Bone_Full",
      "rotation": 1
    },
    {
      "x": -28,
      "y": 48,
      "z": 8,
      "name": "Deco_Bone_Full",
      "rotation": 1
    },
    {
      "x": -28,
      "y": 49,
      "z": 8,
      "name": "Soil_Hive_Corrupted",
      "rotation": 1
    },
    {
      "x": -28,
      "y": 50,
      "z": 8,
      "name": "Soil_Hive_Corrupted",
      "rotation": 1
    },
    {
      "x": -28,
      "y": 0,
      "z": 9,
      "name": "Soil_Grass"
    },
    {
      "x": -28,
      "y": 39,
      "z": 9,
      "name": "Deco_Bone_Full",
      "rotation": 1
    },
    {
      "x": -28,
      "y": 40,
      "z": 9,
      "name": "Deco_Bone_Full",
      "rotation": 1
    },
    {
      "x": -28,
      "y": 41,
      "z": 9,
      "name": "Deco_Bone_Full",
      "rotation": 1
    },
    {
      "x": -28,
      "y": 42,
      "z": 9,
      "name": "Deco_Bone_Full",
      "rotation": 1
    },
    {
      "x": -28,
      "y": 43,
      "z": 9,
      "name": "Deco_Bone_Full",
      "rotation": 1
    },
    {
      "x": -28,
      "y": 44,
      "z": 9,
      "name": "Deco_Bone_Full",
      "rotation": 1
    },
    {
      "x": -28,
      "y": 45,
      "z": 9,
      "name": "Deco_Bone_Full",
      "rotation": 1
    },
    {
      "x": -28,
      "y": 46,
      "z": 9,
      "name": "Deco_Bone_Full",
      "rotation": 1
    },
    {
      "x": -28,
      "y": 47,
      "z": 9,
      "name": "Deco_Bone_Full",
      "rotation": 1
    },
    {
      "x": -28,
      "y": 48,
      "z": 9,
      "name": "Deco_Bone_Full",
      "rotation": 1
    },
    {
      "x": -28,
      "y": 49,
      "z": 9,
      "name": "Deco_Bone_Full",
      "rotation": 1
    },
    {
      "x": -28,
      "y": 50,
      "z": 9,
      "name": "Deco_Bone_Full",
      "rotation": 1
    },
    {
      "x": -28,
      "y": 51,
      "z": 9,
      "name": "Deco_Bone_Full",
      "rotation": 1
    },
    {
      "x": -28,
      "y": 52,
      "z": 9,
      "name": "Soil_Roots_Poisoned",
      "rotation": 1
    },
    {
      "x": -28,
      "y": 53,
      "z": 9,
      "name": "Soil_Hive_Corrupted",
      "rotation": 1
    },
    {
      "x": -28,
      "y": 0,
      "z": 10,
      "name": "Soil_Grass"
    },
    {
      "x": -28,
      "y": 45,
      "z": 10,
      "name": "Deco_Bone_Full",
      "rotation": 1
    },
    {
      "x": -28,
      "y": 46,
      "z": 10,
      "name": "Deco_Bone_Full",
      "rotation": 1
    },
    {
      "x": -28,
      "y": 47,
      "z": 10,
      "name": "Deco_Bone_Full",
      "rotation": 1
    },
    {
      "x": -28,
      "y": 48,
      "z": 10,
      "name": "Deco_Bone_Full",
      "rotation": 1
    },
    {
      "x": -28,
      "y": 49,
      "z": 10,
      "name": "Deco_Bone_Full",
      "rotation": 1
    },
    {
      "x": -28,
      "y": 50,
      "z": 10,
      "name": "Deco_Bone_Full",
      "rotation": 1
    },
    {
      "x": -28,
      "y": 51,
      "z": 10,
      "name": "Deco_Bone_Full",
      "rotation": 1
    },
    {
      "x": -28,
      "y": 52,
      "z": 10,
      "name": "Deco_Bone_Full",
      "rotation": 1
    },
    {
      "x": -28,
      "y": 53,
      "z": 10,
      "name": "Soil_Hive_Corrupted",
      "rotation": 1
    },
    {
      "x": -28,
      "y": 54,
      "z": 10,
      "name": "Soil_Hive_Corrupted",
      "rotation": 1
    },
    {
      "x": -28,
      "y": 0,
      "z": 11,
      "name": "Soil_Grass"
    },
    {
      "x": -28,
      "y": 51,
      "z": 11,
      "name": "Soil_Roots_Poisoned",
      "rotation": 1
    },
    {
      "x": -28,
      "y": 52,
      "z": 11,
      "name": "Soil_Roots_Poisoned",
      "rotation": 1
    },
    {
      "x": -28,
      "y": 0,
      "z": 12,
      "name": "Soil_Grass"
    },
    {
      "x": -28,
      "y": 0,
      "z": 13,
      "name": "Soil_Grass"
    },
    {
      "x": -28,
      "y": 0,
      "z": 14,
      "name": "Soil_Grass"
    },
    {
      "x": -28,
      "y": 0,
      "z": 15,
      "name": "Soil_Grass"
    },
    {
      "x": -27,
      "y": 0,
      "z": -15,
      "name": "Soil_Grass"
    },
    {
      "x": -27,
      "y": 0,
      "z": -14,
      "name": "Soil_Grass"
    },
    {
      "x": -27,
      "y": 0,
      "z": -13,
      "name": "Soil_Grass"
    },
    {
      "x": -27,
      "y": 0,
      "z": -12,
      "name": "Soil_Grass"
    },
    {
      "x": -27,
      "y": 0,
      "z": -11,
      "name": "Soil_Grass"
    },
    {
      "x": -27,
      "y": 0,
      "z": -10,
      "name": "Soil_Grass"
    },
    {
      "x": -27,
      "y": 0,
      "z": -9,
      "name": "Soil_Grass"
    },
    {
      "x": -27,
      "y": 0,
      "z": -8,
      "name": "Soil_Grass"
    },
    {
      "x": -27,
      "y": 0,
      "z": -7,
      "name": "Soil_Grass"
    },
    {
      "x": -27,
      "y": 0,
      "z": -6,
      "name": "Soil_Grass"
    },
    {
      "x": -27,
      "y": 0,
      "z": -5,
      "name": "Soil_Grass"
    },
    {
      "x": -27,
      "y": 0,
      "z": -4,
      "name": "Soil_Grass"
    },
    {
      "x": -27,
      "y": 25,
      "z": -4,
      "name": "Soil_Hive_Corrupted",
      "rotation": 1
    },
    {
      "x": -27,
      "y": 26,
      "z": -4,
      "name": "Soil_Roots_Poisoned",
      "rotation": 1
    },
    {
      "x": -27,
      "y": 0,
      "z": -3,
      "name": "Soil_Grass"
    },
    {
      "x": -27,
      "y": 23,
      "z": -3,
      "name": "Deco_Bone_Full",
      "rotation": 1
    },
    {
      "x": -27,
      "y": 24,
      "z": -3,
      "name": "Deco_Bone_Full",
      "rotation": 1
    },
    {
      "x": -27,
      "y": 25,
      "z": -3,
      "name": "Deco_Bone_Full",
      "rotation": 1
    },
    {
      "x": -27,
      "y": 26,
      "z": -3,
      "name": "Deco_Bone_Full",
      "rotation": 1
    },
    {
      "x": -27,
      "y": 27,
      "z": -3,
      "name": "Soil_Roots_Poisoned",
      "rotation": 1
    },
    {
      "x": -27,
      "y": 28,
      "z": -3,
      "name": "Soil_Hive_Corrupted",
      "rotation": 1
    },
    {
      "x": -27,
      "y": 0,
      "z": -2,
      "name": "Soil_Grass"
    },
    {
      "x": -27,
      "y": 23,
      "z": -2,
      "name": "Deco_Bone_Full",
      "rotation": 1
    },
    {
      "x": -27,
      "y": 24,
      "z": -2,
      "name": "Deco_Bone_Full",
      "rotation": 1
    },
    {
      "x": -27,
      "y": 25,
      "z": -2,
      "name": "Deco_Bone_Full",
      "rotation": 1
    },
    {
      "x": -27,
      "y": 26,
      "z": -2,
      "name": "Deco_Bone_Full",
      "rotation": 1
    },
    {
      "x": -27,
      "y": 27,
      "z": -2,
      "name": "Deco_Bone_Full",
      "rotation": 1
    },
    {
      "x": -27,
      "y": 28,
      "z": -2,
      "name": "Deco_Bone_Full",
      "rotation": 1
    },
    {
      "x": -27,
      "y": 29,
      "z": -2,
      "name": "Soil_Hive_Corrupted",
      "rotation": 1
    },
    {
      "x": -27,
      "y": 30,
      "z": -2,
      "name": "Soil_Roots_Poisoned",
      "rotation": 1
    },
    {
      "x": -27,
      "y": 0,
      "z": -1,
      "name": "Soil_Grass"
    },
    {
      "x": -27,
      "y": 24,
      "z": -1,
      "name": "Deco_Bone_Full",
      "rotation": 1
    },
    {
      "x": -27,
      "y": 25,
      "z": -1,
      "name": "Deco_Bone_Full",
      "rotation": 1
    },
    {
      "x": -27,
      "y": 26,
      "z": -1,
      "name": "Deco_Bone_Full",
      "rotation": 1
    },
    {
      "x": -27,
      "y": 27,
      "z": -1,
      "name": "Deco_Bone_Full",
      "rotation": 1
    },
    {
      "x": -27,
      "y": 28,
      "z": -1,
      "name": "Deco_Bone_Full",
      "rotation": 1
    },
    {
      "x": -27,
      "y": 29,
      "z": -1,
      "name": "Deco_Bone_Full",
      "rotation": 1
    },
    {
      "x": -27,
      "y": 30,
      "z": -1,
      "name": "Deco_Bone_Full",
      "rotation": 1
    },
    {
      "x": -27,
      "y": 31,
      "z": -1,
      "name": "Soil_Hive_Corrupted",
      "rotation": 1
    },
    {
      "x": -27,
      "y": 32,
      "z": -1,
      "name": "Soil_Roots_Poisoned",
      "rotation": 1
    },
    {
      "x": -27,
      "y": 0,
      "z": 0,
      "name": "Soil_Grass"
    },
    {
      "x": -27,
      "y": 27,
      "z": 0,
      "name": "Deco_Bone_Full",
      "rotation": 1
    },
    {
      "x": -27,
      "y": 28,
      "z": 0,
      "name": "Deco_Bone_Full",
      "rotation": 1
    },
    {
      "x": -27,
      "y": 29,
      "z": 0,
      "name": "Deco_Bone_Full",
      "rotation": 1
    },
    {
      "x": -27,
      "y": 30,
      "z": 0,
      "name": "Deco_Bone_Full",
      "rotation": 1
    },
    {
      "x": -27,
      "y": 31,
      "z": 0,
      "name": "Deco_Bone_Full",
      "rotation": 1
    },
    {
      "x": -27,
      "y": 32,
      "z": 0,
      "name": "Soil_Roots_Poisoned",
      "rotation": 1
    },
    {
      "x": -27,
      "y": 33,
      "z": 0,
      "name": "Soil_Hive_Corrupted",
      "rotation": 1
    },
    {
      "x": -27,
      "y": 35,
      "z": 0,
      "name": "Soil_Roots_Poisoned",
      "rotation": 1
    },
    {
      "x": -27,
      "y": 42,
      "z": 0,
      "name": "Deco_Bone_Full",
      "rotation": 1
    },
    {
      "x": -27,
      "y": 43,
      "z": 0,
      "name": "Deco_Bone_Full",
      "rotation": 1
    },
    {
      "x": -27,
      "y": 44,
      "z": 0,
      "name": "Deco_Bone_Full",
      "rotation": 1
    },
    {
      "x": -27,
      "y": 45,
      "z": 0,
      "name": "Deco_Bone_Full",
      "rotation": 1
    },
    {
      "x": -27,
      "y": 46,
      "z": 0,
      "name": "Soil_Hive_Corrupted",
      "rotation": 1
    },
    {
      "x": -27,
      "y": 47,
      "z": 0,
      "name": "Soil_Roots_Poisoned",
      "rotation": 1
    },
    {
      "x": -27,
      "y": 0,
      "z": 1,
      "name": "Soil_Grass"
    },
    {
      "x": -27,
      "y": 40,
      "z": 1,
      "name": "Deco_Bone_Full",
      "rotation": 1
    },
    {
      "x": -27,
      "y": 41,
      "z": 1,
      "name": "Deco_Bone_Full",
      "rotation": 1
    },
    {
      "x": -27,
      "y": 42,
      "z": 1,
      "name": "Deco_Bone_Full",
      "rotation": 1
    },
    {
      "x": -27,
      "y": 43,
      "z": 1,
      "name": "Deco_Bone_Full",
      "rotation": 1
    },
    {
      "x": -27,
      "y": 44,
      "z": 1,
      "name": "Deco_Bone_Full",
      "rotation": 1
    },
    {
      "x": -27,
      "y": 45,
      "z": 1,
      "name": "Deco_Bone_Full",
      "rotation": 1
    },
    {
      "x": -27,
      "y": 46,
      "z": 1,
      "name": "Deco_Bone_Full",
      "rotation": 1
    },
    {
      "x": -27,
      "y": 47,
      "z": 1,
      "name": "Deco_Bone_Full",
      "rotation": 1
    },
    {
      "x": -27,
      "y": 48,
      "z": 1,
      "name": "Soil_Hive_Corrupted",
      "rotation": 1
    },
    {
      "x": -27,
      "y": 49,
      "z": 1,
      "name": "Soil_Roots_Poisoned",
      "rotation": 1
    },
    {
      "x": -27,
      "y": 0,
      "z": 2,
      "name": "Soil_Grass"
    },
    {
      "x": -27,
      "y": 42,
      "z": 2,
      "name": "Deco_Bone_Full",
      "rotation": 1
    },
    {
      "x": -27,
      "y": 43,
      "z": 2,
      "name": "Deco_Bone_Full",
      "rotation": 1
    },
    {
      "x": -27,
      "y": 44,
      "z": 2,
      "name": "Deco_Bone_Full",
      "rotation": 1
    },
    {
      "x": -27,
      "y": 45,
      "z": 2,
      "name": "Deco_Bone_Full",
      "rotation": 1
    },
    {
      "x": -27,
      "y": 46,
      "z": 2,
      "name": "Deco_Bone_Full",
      "rotation": 1
    },
    {
      "x": -27,
      "y": 47,
      "z": 2,
      "name": "Deco_Bone_Full",
      "rotation": 1
    },
    {
      "x": -27,
      "y": 48,
      "z": 2,
      "name": "Soil_Hive_Corrupted",
      "rotation": 1
    },
    {
      "x": -27,
      "y": 49,
      "z": 2,
      "name": "Soil_Roots_Poisoned",
      "rotation": 1
    },
    {
      "x": -27,
      "y": 0,
      "z": 3,
      "name": "Soil_Grass"
    },
    {
      "x": -27,
      "y": 25,
      "z": 3,
      "name": "Deco_Bone_Full",
      "rotation": 1
    },
    {
      "x": -27,
      "y": 26,
      "z": 3,
      "name": "Deco_Bone_Full",
      "rotation": 1
    },
    {
      "x": -27,
      "y": 27,
      "z": 3,
      "name": "Soil_Roots_Poisoned",
      "rotation": 1
    },
    {
      "x": -27,
      "y": 28,
      "z": 3,
      "name": "Soil_Roots_Poisoned",
      "rotation": 1
    },
    {
      "x": -27,
      "y": 0,
      "z": 4,
      "name": "Soil_Grass"
    },
    {
      "x": -27,
      "y": 25,
      "z": 4,
      "name": "Deco_Bone_Full",
      "rotation": 1
    },
    {
      "x": -27,
      "y": 26,
      "z": 4,
      "name": "Deco_Bone_Full",
      "rotation": 1
    },
    {
      "x": -27,
      "y": 27,
      "z": 4,
      "name": "Deco_Bone_Full",
      "rotation": 1
    },
    {
      "x": -27,
      "y": 28,
      "z": 4,
      "name": "Deco_Bone_Full",
      "rotation": 1
    },
    {
      "x": -27,
      "y": 29,
      "z": 4,
      "name": "Deco_Bone_Full",
      "rotation": 1
    },
    {
      "x": -27,
      "y": 30,
      "z": 4,
      "name": "Soil_Hive_Corrupted",
      "rotation": 1
    },
    {
      "x": -27,
      "y": 31,
      "z": 4,
      "name": "Soil_Hive_Corrupted",
      "rotation": 1
    },
    {
      "x": -27,
      "y": 0,
      "z": 5,
      "name": "Soil_Grass"
    },
    {
      "x": -27,
      "y": 26,
      "z": 5,
      "name": "Deco_Bone_Full",
      "rotation": 1
    },
    {
      "x": -27,
      "y": 27,
      "z": 5,
      "name": "Deco_Bone_Full",
      "rotation": 1
    },
    {
      "x": -27,
      "y": 28,
      "z": 5,
      "name": "Deco_Bone_Full",
      "rotation": 1
    },
    {
      "x": -27,
      "y": 29,
      "z": 5,
      "name": "Deco_Bone_Full",
      "rotation": 1
    },
    {
      "x": -27,
      "y": 30,
      "z": 5,
      "name": "Deco_Bone_Full",
      "rotation": 1
    },
    {
      "x": -27,
      "y": 31,
      "z": 5,
      "name": "Soil_Roots_Poisoned",
      "rotation": 1
    },
    {
      "x": -27,
      "y": 32,
      "z": 5,
      "name": "Soil_Roots_Poisoned",
      "rotation": 1
    },
    {
      "x": -27,
      "y": 0,
      "z": 6,
      "name": "Soil_Grass"
    },
    {
      "x": -27,
      "y": 27,
      "z": 6,
      "name": "Deco_Bone_Full",
      "rotation": 1
    },
    {
      "x": -27,
      "y": 28,
      "z": 6,
      "name": "Deco_Bone_Full",
      "rotation": 1
    },
    {
      "x": -27,
      "y": 29,
      "z": 6,
      "name": "Deco_Bone_Full",
      "rotation": 1
    },
    {
      "x": -27,
      "y": 30,
      "z": 6,
      "name": "Deco_Bone_Full",
      "rotation": 1
    },
    {
      "x": -27,
      "y": 31,
      "z": 6,
      "name": "Deco_Bone_Full",
      "rotation": 1
    },
    {
      "x": -27,
      "y": 32,
      "z": 6,
      "name": "Soil_Hive_Corrupted",
      "rotation": 1
    },
    {
      "x": -27,
      "y": 33,
      "z": 6,
      "name": "Soil_Hive_Corrupted",
      "rotation": 1
    },
    {
      "x": -27,
      "y": 0,
      "z": 7,
      "name": "Soil_Grass"
    },
    {
      "x": -27,
      "y": 30,
      "z": 7,
      "name": "Deco_Bone_Full",
      "rotation": 1
    },
    {
      "x": -27,
      "y": 31,
      "z": 7,
      "name": "Deco_Bone_Full",
      "rotation": 1
    },
    {
      "x": -27,
      "y": 32,
      "z": 7,
      "name": "Deco_Bone_Full",
      "rotation": 1
    },
    {
      "x": -27,
      "y": 33,
      "z": 7,
      "name": "Deco_Bone_Full",
      "rotation": 1
    },
    {
      "x": -27,
      "y": 34,
      "z": 7,
      "name": "Soil_Hive_Corrupted",
      "rotation": 1
    },
    {
      "x": -27,
      "y": 35,
      "z": 7,
      "name": "Soil_Roots_Poisoned",
      "rotation": 1
    },
    {
      "x": -27,
      "y": 0,
      "z": 8,
      "name": "Soil_Grass"
    },
    {
      "x": -27,
      "y": 0,
      "z": 9,
      "name": "Soil_Grass"
    },
    {
      "x": -27,
      "y": 46,
      "z": 9,
      "name": "Deco_Bone_Full",
      "rotation": 1
    },
    {
      "x": -27,
      "y": 47,
      "z": 9,
      "name": "Deco_Bone_Full",
      "rotation": 1
    },
    {
      "x": -27,
      "y": 48,
      "z": 9,
      "name": "Deco_Bone_Full",
      "rotation": 1
    },
    {
      "x": -27,
      "y": 49,
      "z": 9,
      "name": "Deco_Bone_Full",
      "rotation": 1
    },
    {
      "x": -27,
      "y": 50,
      "z": 9,
      "name": "Deco_Bone_Full",
      "rotation": 1
    },
    {
      "x": -27,
      "y": 51,
      "z": 9,
      "name": "Deco_Bone_Full",
      "rotation": 1
    },
    {
      "x": -27,
      "y": 52,
      "z": 9,
      "name": "Soil_Roots_Poisoned",
      "rotation": 1
    },
    {
      "x": -27,
      "y": 53,
      "z": 9,
      "name": "Soil_Roots_Poisoned",
      "rotation": 1
    },
    {
      "x": -27,
      "y": 0,
      "z": 10,
      "name": "Soil_Grass"
    },
    {
      "x": -27,
      "y": 47,
      "z": 10,
      "name": "Deco_Bone_Full",
      "rotation": 1
    },
    {
      "x": -27,
      "y": 48,
      "z": 10,
      "name": "Deco_Bone_Full",
      "rotation": 1
    },
    {
      "x": -27,
      "y": 49,
      "z": 10,
      "name": "Deco_Bone_Full",
      "rotation": 1
    },
    {
      "x": -27,
      "y": 50,
      "z": 10,
      "name": "Deco_Bone_Full",
      "rotation": 1
    },
    {
      "x": -27,
      "y": 51,
      "z": 10,
      "name": "Deco_Bone_Full",
      "rotation": 1
    },
    {
      "x": -27,
      "y": 52,
      "z": 10,
      "name": "Deco_Bone_Full",
      "rotation": 1
    },
    {
      "x": -27,
      "y": 53,
      "z": 10,
      "name": "Deco_Bone_Full",
      "rotation": 1
    },
    {
      "x": -27,
      "y": 54,
      "z": 10,
      "name": "Soil_Hive_Corrupted",
      "rotation": 1
    },
    {
      "x": -27,
      "y": 55,
      "z": 10,
      "name": "Soil_Roots_Poisoned",
      "rotation": 1
    },
    {
      "x": -27,
      "y": 0,
      "z": 11,
      "name": "Soil_Grass"
    },
    {
      "x": -27,
      "y": 50,
      "z": 11,
      "name": "Deco_Bone_Full",
      "rotation": 1
    },
    {
      "x": -27,
      "y": 51,
      "z": 11,
      "name": "Deco_Bone_Full",
      "rotation": 1
    },
    {
      "x": -27,
      "y": 52,
      "z": 11,
      "name": "Deco_Bone_Full",
      "rotation": 1
    },
    {
      "x": -27,
      "y": 53,
      "z": 11,
      "name": "Deco_Bone_Full",
      "rotation": 1
    },
    {
      "x": -27,
      "y": 54,
      "z": 11,
      "name": "Soil_Roots_Poisoned",
      "rotation": 1
    },
    {
      "x": -27,
      "y": 55,
      "z": 11,
      "name": "Soil_Hive_Corrupted",
      "rotation": 1
    },
    {
      "x": -27,
      "y": 0,
      "z": 12,
      "name": "Soil_Grass"
    },
    {
      "x": -27,
      "y": 0,
      "z": 13,
      "name": "Soil_Grass"
    },
    {
      "x": -27,
      "y": 0,
      "z": 14,
      "name": "Soil_Grass"
    },
    {
      "x": -27,
      "y": 0,
      "z": 15,
      "name": "Soil_Grass"
    },
    {
      "x": -26,
      "y": 0,
      "z": -15,
      "name": "Soil_Grass"
    },
    {
      "x": -26,
      "y": 0,
      "z": -14,
      "name": "Soil_Grass"
    },
    {
      "x": -26,
      "y": 0,
      "z": -13,
      "name": "Soil_Grass"
    },
    {
      "x": -26,
      "y": 0,
      "z": -12,
      "name": "Soil_Grass"
    },
    {
      "x": -26,
      "y": 0,
      "z": -11,
      "name": "Soil_Grass"
    },
    {
      "x": -26,
      "y": 0,
      "z": -10,
      "name": "Soil_Grass"
    },
    {
      "x": -26,
      "y": 0,
      "z": -9,
      "name": "Soil_Grass"
    },
    {
      "x": -26,
      "y": 0,
      "z": -8,
      "name": "Soil_Grass"
    },
    {
      "x": -26,
      "y": 0,
      "z": -7,
      "name": "Soil_Grass"
    },
    {
      "x": -26,
      "y": 0,
      "z": -6,
      "name": "Soil_Grass"
    },
    {
      "x": -26,
      "y": 0,
      "z": -5,
      "name": "Soil_Grass"
    },
    {
      "x": -26,
      "y": 0,
      "z": -4,
      "name": "Soil_Grass"
    },
    {
      "x": -26,
      "y": 22,
      "z": -4,
      "name": "Deco_Bone_Full",
      "rotation": 1
    },
    {
      "x": -26,
      "y": 23,
      "z": -4,
      "name": "Soil_Roots_Poisoned",
      "rotation": 1
    },
    {
      "x": -26,
      "y": 24,
      "z": -4,
      "name": "Soil_Roots_Poisoned",
      "rotation": 1
    },
    {
      "x": -26,
      "y": 0,
      "z": -3,
      "name": "Soil_Grass"
    },
    {
      "x": -26,
      "y": 21,
      "z": -3,
      "name": "Deco_Bone_Full",
      "rotation": 1
    },
    {
      "x": -26,
      "y": 22,
      "z": -3,
      "name": "Deco_Bone_Full",
      "rotation": 1
    },
    {
      "x": -26,
      "y": 23,
      "z": -3,
      "name": "Deco_Bone_Full",
      "rotation": 1
    },
    {
      "x": -26,
      "y": 24,
      "z": -3,
      "name": "Deco_Bone_Full",
      "rotation": 1
    },
    {
      "x": -26,
      "y": 25,
      "z": -3,
      "name": "Deco_Bone_Full",
      "rotation": 1
    },
    {
      "x": -26,
      "y": 26,
      "z": -3,
      "name": "Soil_Roots_Poisoned",
      "rotation": 1
    },
    {
      "x": -26,
      "y": 27,
      "z": -3,
      "name": "Soil_Hive_Corrupted",
      "rotation": 1
    },
    {
      "x": -26,
      "y": 0,
      "z": -2,
      "name": "Soil_Grass"
    },
    {
      "x": -26,
      "y": 22,
      "z": -2,
      "name": "Deco_Bone_Full",
      "rotation": 1
    },
    {
      "x": -26,
      "y": 23,
      "z": -2,
      "name": "Deco_Bone_Full",
      "rotation": 1
    },
    {
      "x": -26,
      "y": 24,
      "z": -2,
      "name": "Deco_Bone_Full",
      "rotation": 1
    },
    {
      "x": -26,
      "y": 25,
      "z": -2,
      "name": "Deco_Bone_Full",
      "rotation": 1
    },
    {
      "x": -26,
      "y": 26,
      "z": -2,
      "name": "Deco_Bone_Full",
      "rotation": 1
    },
    {
      "x": -26,
      "y": 27,
      "z": -2,
      "name": "Soil_Roots_Poisoned",
      "rotation": 1
    },
    {
      "x": -26,
      "y": 28,
      "z": -2,
      "name": "Soil_Roots_Poisoned",
      "rotation": 1
    },
    {
      "x": -26,
      "y": 0,
      "z": -1,
      "name": "Soil_Grass"
    },
    {
      "x": -26,
      "y": 23,
      "z": -1,
      "name": "Deco_Bone_Full",
      "rotation": 1
    },
    {
      "x": -26,
      "y": 24,
      "z": -1,
      "name": "Deco_Bone_Full",
      "rotation": 1
    },
    {
      "x": -26,
      "y": 25,
      "z": -1,
      "name": "Deco_Bone_Full",
      "rotation": 1
    },
    {
      "x": -26,
      "y": 26,
      "z": -1,
      "name": "Deco_Bone_Full",
      "rotation": 1
    },
    {
      "x": -26,
      "y": 27,
      "z": -1,
      "name": "Deco_Bone_Full",
      "rotation": 1
    },
    {
      "x": -26,
      "y": 28,
      "z": -1,
      "name": "Soil_Roots_Poisoned",
      "rotation": 1
    },
    {
      "x": -26,
      "y": 29,
      "z": -1,
      "name": "Soil_Roots_Poisoned",
      "rotation": 1
    },
    {
      "x": -26,
      "y": 0,
      "z": 0,
      "name": "Soil_Grass"
    },
    {
      "x": -26,
      "y": 27,
      "z": 0,
      "name": "Soil_Roots_Poisoned",
      "rotation": 1
    },
    {
      "x": -26,
      "y": 28,
      "z": 0,
      "name": "Soil_Hive_Corrupted",
      "rotation": 1
    },
    {
      "x": -26,
      "y": 0,
      "z": 1,
      "name": "Soil_Grass"
    },
    {
      "x": -26,
      "y": 45,
      "z": 1,
      "name": "Deco_Bone_Full",
      "rotation": 1
    },
    {
      "x": -26,
      "y": 46,
      "z": 1,
      "name": "Deco_Bone_Full",
      "rotation": 1
    },
    {
      "x": -26,
      "y": 47,
      "z": 1,
      "name": "Deco_Bone_Full",
      "rotation": 1
    },
    {
      "x": -26,
      "y": 48,
      "z": 1,
      "name": "Deco_Bone_Full",
      "rotation": 1
    },
    {
      "x": -26,
      "y": 49,
      "z": 1,
      "name": "Soil_Roots_Poisoned",
      "rotation": 1
    },
    {
      "x": -26,
      "y": 50,
      "z": 1,
      "name": "Soil_Roots_Poisoned",
      "rotation": 1
    },
    {
      "x": -26,
      "y": 0,
      "z": 2,
      "name": "Soil_Grass"
    },
    {
      "x": -26,
      "y": 45,
      "z": 2,
      "name": "Deco_Bone_Full",
      "rotation": 1
    },
    {
      "x": -26,
      "y": 46,
      "z": 2,
      "name": "Deco_Bone_Full",
      "rotation": 1
    },
    {
      "x": -26,
      "y": 47,
      "z": 2,
      "name": "Deco_Bone_Full",
      "rotation": 1
    },
    {
      "x": -26,
      "y": 48,
      "z": 2,
      "name": "Deco_Bone_Full",
      "rotation": 1
    },
    {
      "x": -26,
      "y": 49,
      "z": 2,
      "name": "Deco_Bone_Full",
      "rotation": 1
    },
    {
      "x": -26,
      "y": 50,
      "z": 2,
      "name": "Soil_Roots_Poisoned",
      "rotation": 1
    },
    {
      "x": -26,
      "y": 51,
      "z": 2,
      "name": "Soil_Roots_Poisoned",
      "rotation": 1
    },
    {
      "x": -26,
      "y": 0,
      "z": 3,
      "name": "Soil_Grass"
    },
    {
      "x": -26,
      "y": 23,
      "z": 3,
      "name": "Deco_Bone_Full",
      "rotation": 1
    },
    {
      "x": -26,
      "y": 24,
      "z": 3,
      "name": "Deco_Bone_Full",
      "rotation": 1
    },
    {
      "x": -26,
      "y": 25,
      "z": 3,
      "name": "Deco_Bone_Full",
      "rotation": 1
    },
    {
      "x": -26,
      "y": 26,
      "z": 3,
      "name": "Deco_Bone_Full",
      "rotation": 1
    },
    {
      "x": -26,
      "y": 27,
      "z": 3,
      "name": "Soil_Roots_Poisoned",
      "rotation": 1
    },
    {
      "x": -26,
      "y": 28,
      "z": 3,
      "name": "Soil_Hive_Corrupted",
      "rotation": 1
    },
    {
      "x": -26,
      "y": 47,
      "z": 3,
      "name": "Soil_Roots_Poisoned",
      "rotation": 1
    },
    {
      "x": -26,
      "y": 48,
      "z": 3,
      "name": "Soil_Hive_Corrupted",
      "rotation": 1
    },
    {
      "x": -26,
      "y": 0,
      "z": 4,
      "name": "Soil_Grass"
    },
    {
      "x": -26,
      "y": 23,
      "z": 4,
      "name": "Deco_Bone_Full",
      "rotation": 1
    },
    {
      "x": -26,
      "y": 24,
      "z": 4,
      "name": "Deco_Bone_Full",
      "rotation": 1
    },
    {
      "x": -26,
      "y": 25,
      "z": 4,
      "name": "Deco_Bone_Full",
      "rotation": 1
    },
    {
      "x": -26,
      "y": 26,
      "z": 4,
      "name": "Deco_Bone_Full",
      "rotation": 1
    },
    {
      "x": -26,
      "y": 27,
      "z": 4,
      "name": "Deco_Bone_Full",
      "rotation": 1
    },
    {
      "x": -26,
      "y": 28,
      "z": 4,
      "name": "Soil_Hive_Corrupted",
      "rotation": 1
    },
    {
      "x": -26,
      "y": 29,
      "z": 4,
      "name": "Soil_Roots_Poisoned",
      "rotation": 1
    },
    {
      "x": -26,
      "y": 0,
      "z": 5,
      "name": "Soil_Grass"
    },
    {
      "x": -26,
      "y": 24,
      "z": 5,
      "name": "Deco_Bone_Full",
      "rotation": 1
    },
    {
      "x": -26,
      "y": 25,
      "z": 5,
      "name": "Deco_Bone_Full",
      "rotation": 1
    },
    {
      "x": -26,
      "y": 26,
      "z": 5,
      "name": "Deco_Bone_Full",
      "rotation": 1
    },
    {
      "x": -26,
      "y": 27,
      "z": 5,
      "name": "Deco_Bone_Full",
      "rotation": 1
    },
    {
      "x": -26,
      "y": 28,
      "z": 5,
      "name": "Deco_Bone_Full",
      "rotation": 1
    },
    {
      "x": -26,
      "y": 29,
      "z": 5,
      "name": "Soil_Hive_Corrupted",
      "rotation": 1
    },
    {
      "x": -26,
      "y": 30,
      "z": 5,
      "name": "Soil_Roots_Poisoned",
      "rotation": 1
    },
    {
      "x": -26,
      "y": 0,
      "z": 6,
      "name": "Soil_Grass"
    },
    {
      "x": -26,
      "y": 26,
      "z": 6,
      "name": "Deco_Bone_Full",
      "rotation": 1
    },
    {
      "x": -26,
      "y": 27,
      "z": 6,
      "name": "Deco_Bone_Full",
      "rotation": 1
    },
    {
      "x": -26,
      "y": 28,
      "z": 6,
      "name": "Deco_Bone_Full",
      "rotation": 1
    },
    {
      "x": -26,
      "y": 29,
      "z": 6,
      "name": "Deco_Bone_Full",
      "rotation": 1
    },
    {
      "x": -26,
      "y": 30,
      "z": 6,
      "name": "Soil_Hive_Corrupted",
      "rotation": 1
    },
    {
      "x": -26,
      "y": 31,
      "z": 6,
      "name": "Soil_Hive_Corrupted",
      "rotation": 1
    },
    {
      "x": -26,
      "y": 0,
      "z": 7,
      "name": "Soil_Grass"
    },
    {
      "x": -26,
      "y": 31,
      "z": 7,
      "name": "Soil_Roots_Poisoned",
      "rotation": 1
    },
    {
      "x": -26,
      "y": 0,
      "z": 8,
      "name": "Soil_Grass"
    },
    {
      "x": -26,
      "y": 0,
      "z": 9,
      "name": "Soil_Grass"
    },
    {
      "x": -26,
      "y": 0,
      "z": 10,
      "name": "Soil_Grass"
    },
    {
      "x": -26,
      "y": 52,
      "z": 10,
      "name": "Deco_Bone_Full",
      "rotation": 1
    },
    {
      "x": -26,
      "y": 53,
      "z": 10,
      "name": "Deco_Bone_Full",
      "rotation": 1
    },
    {
      "x": -26,
      "y": 54,
      "z": 10,
      "name": "Deco_Bone_Full",
      "rotation": 1
    },
    {
      "x": -26,
      "y": 55,
      "z": 10,
      "name": "Deco_Bone_Full",
      "rotation": 1
    },
    {
      "x": -26,
      "y": 56,
      "z": 10,
      "name": "Soil_Hive_Corrupted",
      "rotation": 1
    },
    {
      "x": -26,
      "y": 57,
      "z": 10,
      "name": "Soil_Roots_Poisoned",
      "rotation": 1
    },
    {
      "x": -26,
      "y": 0,
      "z": 11,
      "name": "Soil_Grass"
    },
    {
      "x": -26,
      "y": 51,
      "z": 11,
      "name": "Deco_Bone_Full",
      "rotation": 1
    },
    {
      "x": -26,
      "y": 52,
      "z": 11,
      "name": "Deco_Bone_Full",
      "rotation": 1
    },
    {
      "x": -26,
      "y": 53,
      "z": 11,
      "name": "Deco_Bone_Full",
      "rotation": 1
    },
    {
      "x": -26,
      "y": 54,
      "z": 11,
      "name": "Deco_Bone_Full",
      "rotation": 1
    },
    {
      "x": -26,
      "y": 55,
      "z": 11,
      "name": "Deco_Bone_Full",
      "rotation": 1
    },
    {
      "x": -26,
      "y": 56,
      "z": 11,
      "name": "Soil_Hive_Corrupted",
      "rotation": 1
    },
    {
      "x": -26,
      "y": 57,
      "z": 11,
      "name": "Soil_Hive_Corrupted",
      "rotation": 1
    },
    {
      "x": -26,
      "y": 0,
      "z": 12,
      "name": "Soil_Grass"
    },
    {
      "x": -26,
      "y": 54,
      "z": 12,
      "name": "Deco_Bone_Full",
      "rotation": 1
    },
    {
      "x": -26,
      "y": 55,
      "z": 12,
      "name": "Soil_Roots_Poisoned",
      "rotation": 1
    },
    {
      "x": -26,
      "y": 56,
      "z": 12,
      "name": "Soil_Roots_Poisoned",
      "rotation": 1
    },
    {
      "x": -26,
      "y": 0,
      "z": 13,
      "name": "Soil_Grass"
    },
    {
      "x": -26,
      "y": 0,
      "z": 14,
      "name": "Soil_Grass"
    },
    {
      "x": -26,
      "y": 0,
      "z": 15,
      "name": "Soil_Grass"
    },
    {
      "x": -25,
      "y": 0,
      "z": -15,
      "name": "Soil_Grass"
    },
    {
      "x": -25,
      "y": 0,
      "z": -14,
      "name": "Soil_Grass"
    },
    {
      "x": -25,
      "y": 0,
      "z": -13,
      "name": "Soil_Grass"
    },
    {
      "x": -25,
      "y": 0,
      "z": -12,
      "name": "Soil_Grass"
    },
    {
      "x": -25,
      "y": 0,
      "z": -11,
      "name": "Soil_Grass"
    },
    {
      "x": -25,
      "y": 0,
      "z": -10,
      "name": "Soil_Grass"
    },
    {
      "x": -25,
      "y": 0,
      "z": -9,
      "name": "Soil_Grass"
    },
    {
      "x": -25,
      "y": 0,
      "z": -8,
      "name": "Soil_Grass"
    },
    {
      "x": -25,
      "y": 0,
      "z": -7,
      "name": "Soil_Grass"
    },
    {
      "x": -25,
      "y": 0,
      "z": -6,
      "name": "Soil_Grass"
    },
    {
      "x": -25,
      "y": 0,
      "z": -5,
      "name": "Soil_Grass"
    },
    {
      "x": -25,
      "y": 0,
      "z": -4,
      "name": "Soil_Grass"
    },
    {
      "x": -25,
      "y": 20,
      "z": -4,
      "name": "Deco_Bone_Full",
      "rotation": 1
    },
    {
      "x": -25,
      "y": 21,
      "z": -4,
      "name": "Deco_Bone_Full",
      "rotation": 1
    },
    {
      "x": -25,
      "y": 22,
      "z": -4,
      "name": "Soil_Hive_Corrupted",
      "rotation": 1
    },
    {
      "x": -25,
      "y": 23,
      "z": -4,
      "name": "Soil_Roots_Poisoned",
      "rotation": 1
    },
    {
      "x": -25,
      "y": 0,
      "z": -3,
      "name": "Soil_Grass"
    },
    {
      "x": -25,
      "y": 20,
      "z": -3,
      "name": "Deco_Bone_Full",
      "rotation": 1
    },
    {
      "x": -25,
      "y": 21,
      "z": -3,
      "name": "Deco_Bone_Full",
      "rotation": 1
    },
    {
      "x": -25,
      "y": 22,
      "z": -3,
      "name": "Deco_Bone_Full",
      "rotation": 1
    },
    {
      "x": -25,
      "y": 23,
      "z": -3,
      "name": "Deco_Bone_Full",
      "rotation": 1
    },
    {
      "x": -25,
      "y": 24,
      "z": -3,
      "name": "Soil_Roots_Poisoned",
      "rotation": 1
    },
    {
      "x": -25,
      "y": 25,
      "z": -3,
      "name": "Soil_Hive_Corrupted",
      "rotation": 1
    },
    {
      "x": -25,
      "y": 0,
      "z": -2,
      "name": "Soil_Grass"
    },
    {
      "x": -25,
      "y": 20,
      "z": -2,
      "name": "Deco_Bone_Full",
      "rotation": 1
    },
    {
      "x": -25,
      "y": 21,
      "z": -2,
      "name": "Deco_Bone_Full",
      "rotation": 1
    },
    {
      "x": -25,
      "y": 22,
      "z": -2,
      "name": "Deco_Bone_Full",
      "rotation": 1
    },
    {
      "x": -25,
      "y": 23,
      "z": -2,
      "name": "Deco_Bone_Full",
      "rotation": 1
    },
    {
      "x": -25,
      "y": 24,
      "z": -2,
      "name": "Deco_Bone_Full",
      "rotation": 1
    },
    {
      "x": -25,
      "y": 25,
      "z": -2,
      "name": "Soil_Roots_Poisoned",
      "rotation": 1
    },
    {
      "x": -25,
      "y": 26,
      "z": -2,
      "name": "Soil_Roots_Poisoned",
      "rotation": 1
    },
    {
      "x": -25,
      "y": 0,
      "z": -1,
      "name": "Soil_Grass"
    },
    {
      "x": -25,
      "y": 22,
      "z": -1,
      "name": "Deco_Bone_Full",
      "rotation": 1
    },
    {
      "x": -25,
      "y": 23,
      "z": -1,
      "name": "Deco_Bone_Full",
      "rotation": 1
    },
    {
      "x": -25,
      "y": 24,
      "z": -1,
      "name": "Deco_Bone_Full",
      "rotation": 1
    },
    {
      "x": -25,
      "y": 25,
      "z": -1,
      "name": "Soil_Hive_Corrupted",
      "rotation": 1
    },
    {
      "x": -25,
      "y": 26,
      "z": -1,
      "name": "Soil_Hive_Corrupted",
      "rotation": 1
    },
    {
      "x": -25,
      "y": 0,
      "z": 0,
      "name": "Soil_Grass"
    },
    {
      "x": -25,
      "y": 0,
      "z": 1,
      "name": "Soil_Grass"
    },
    {
      "x": -25,
      "y": 48,
      "z": 1,
      "name": "Deco_Bone_Full",
      "rotation": 1
    },
    {
      "x": -25,
      "y": 49,
      "z": 1,
      "name": "Soil_Hive_Corrupted",
      "rotation": 1
    },
    {
      "x": -25,
      "y": 50,
      "z": 1,
      "name": "Soil_Hive_Corrupted",
      "rotation": 1
    },
    {
      "x": -25,
      "y": 0,
      "z": 2,
      "name": "Soil_Grass"
    },
    {
      "x": -25,
      "y": 24,
      "z": 2,
      "name": "Soil_Roots_Poisoned",
      "rotation": 1
    },
    {
      "x": -25,
      "y": 47,
      "z": 2,
      "name": "Deco_Bone_Full",
      "rotation": 1
    },
    {
      "x": -25,
      "y": 48,
      "z": 2,
      "name": "Deco_Bone_Full",
      "rotation": 1
    },
    {
      "x": -25,
      "y": 49,
      "z": 2,
      "name": "Deco_Bone_Full",
      "rotation": 1
    },
    {
      "x": -25,
      "y": 50,
      "z": 2,
      "name": "Deco_Bone_Full",
      "rotation": 1
    },
    {
      "x": -25,
      "y": 51,
      "z": 2,
      "name": "Soil_Roots_Poisoned",
      "rotation": 1
    },
    {
      "x": -25,
      "y": 52,
      "z": 2,
      "name": "Soil_Roots_Poisoned",
      "rotation": 1
    },
    {
      "x": -25,
      "y": 0,
      "z": 3,
      "name": "Soil_Grass"
    },
    {
      "x": -25,
      "y": 22,
      "z": 3,
      "name": "Deco_Bone_Full",
      "rotation": 1
    },
    {
      "x": -25,
      "y": 23,
      "z": 3,
      "name": "Deco_Bone_Full",
      "rotation": 1
    },
    {
      "x": -25,
      "y": 24,
      "z": 3,
      "name": "Deco_Bone_Full",
      "rotation": 1
    },
    {
      "x": -25,
      "y": 25,
      "z": 3,
      "name": "Soil_Hive_Corrupted",
      "rotation": 1
    },
    {
      "x": -25,
      "y": 26,
      "z": 3,
      "name": "Soil_Roots_Poisoned",
      "rotation": 1
    },
    {
      "x": -25,
      "y": 48,
      "z": 3,
      "name": "Deco_Bone_Full",
      "rotation": 1
    },
    {
      "x": -25,
      "y": 49,
      "z": 3,
      "name": "Deco_Bone_Full",
      "rotation": 1
    },
    {
      "x": -25,
      "y": 50,
      "z": 3,
      "name": "Soil_Hive_Corrupted",
      "rotation": 1
    },
    {
      "x": -25,
      "y": 51,
      "z": 3,
      "name": "Soil_Roots_Poisoned",
      "rotation": 1
    },
    {
      "x": -25,
      "y": 0,
      "z": 4,
      "name": "Soil_Grass"
    },
    {
      "x": -25,
      "y": 22,
      "z": 4,
      "name": "Deco_Bone_Full",
      "rotation": 1
    },
    {
      "x": -25,
      "y": 23,
      "z": 4,
      "name": "Deco_Bone_Full",
      "rotation": 1
    },
    {
      "x": -25,
      "y": 24,
      "z": 4,
      "name": "Deco_Bone_Full",
      "rotation": 1
    },
    {
      "x": -25,
      "y": 25,
      "z": 4,
      "name": "Deco_Bone_Full",
      "rotation": 1
    },
    {
      "x": -25,
      "y": 26,
      "z": 4,
      "name": "Soil_Roots_Poisoned",
      "rotation": 1
    },
    {
      "x": -25,
      "y": 27,
      "z": 4,
      "name": "Soil_Hive_Corrupted",
      "rotation": 1
    },
    {
      "x": -25,
      "y": 0,
      "z": 5,
      "name": "Soil_Grass"
    },
    {
      "x": -25,
      "y": 23,
      "z": 5,
      "name": "Deco_Bone_Full",
      "rotation": 1
    },
    {
      "x": -25,
      "y": 24,
      "z": 5,
      "name": "Deco_Bone_Full",
      "rotation": 1
    },
    {
      "x": -25,
      "y": 25,
      "z": 5,
      "name": "Deco_Bone_Full",
      "rotation": 1
    },
    {
      "x": -25,
      "y": 26,
      "z": 5,
      "name": "Deco_Bone_Full",
      "rotation": 1
    },
    {
      "x": -25,
      "y": 27,
      "z": 5,
      "name": "Soil_Hive_Corrupted",
      "rotation": 1
    },
    {
      "x": -25,
      "y": 28,
      "z": 5,
      "name": "Soil_Roots_Poisoned",
      "rotation": 1
    },
    {
      "x": -25,
      "y": 0,
      "z": 6,
      "name": "Soil_Grass"
    },
    {
      "x": -25,
      "y": 25,
      "z": 6,
      "name": "Deco_Bone_Full",
      "rotation": 1
    },
    {
      "x": -25,
      "y": 26,
      "z": 6,
      "name": "Deco_Bone_Full",
      "rotation": 1
    },
    {
      "x": -25,
      "y": 27,
      "z": 6,
      "name": "Deco_Bone_Full",
      "rotation": 1
    },
    {
      "x": -25,
      "y": 28,
      "z": 6,
      "name": "Soil_Roots_Poisoned",
      "rotation": 1
    },
    {
      "x": -25,
      "y": 29,
      "z": 6,
      "name": "Soil_Roots_Poisoned",
      "rotation": 1
    },
    {
      "x": -25,
      "y": 0,
      "z": 7,
      "name": "Soil_Grass"
    },
    {
      "x": -25,
      "y": 0,
      "z": 8,
      "name": "Soil_Grass"
    },
    {
      "x": -25,
      "y": 0,
      "z": 9,
      "name": "Soil_Grass"
    },
    {
      "x": -25,
      "y": 0,
      "z": 10,
      "name": "Soil_Grass"
    },
    {
      "x": -25,
      "y": 55,
      "z": 10,
      "name": "Deco_Bone_Full",
      "rotation": 1
    },
    {
      "x": -25,
      "y": 56,
      "z": 10,
      "name": "Soil_Hive_Corrupted",
      "rotation": 1
    },
    {
      "x": -25,
      "y": 57,
      "z": 10,
      "name": "Soil_Hive_Corrupted",
      "rotation": 1
    },
    {
      "x": -25,
      "y": 0,
      "z": 11,
      "name": "Soil_Grass"
    },
    {
      "x": -25,
      "y": 54,
      "z": 11,
      "name": "Deco_Bone_Full",
      "rotation": 1
    },
    {
      "x": -25,
      "y": 55,
      "z": 11,
      "name": "Deco_Bone_Full",
      "rotation": 1
    },
    {
      "x": -25,
      "y": 56,
      "z": 11,
      "name": "Deco_Bone_Full",
      "rotation": 1
    },
    {
      "x": -25,
      "y": 57,
      "z": 11,
      "name": "Deco_Bone_Full",
      "rotation": 1
    },
    {
      "x": -25,
      "y": 58,
      "z": 11,
      "name": "Soil_Roots_Poisoned",
      "rotation": 1
    },
    {
      "x": -25,
      "y": 59,
      "z": 11,
      "name": "Soil_Roots_Poisoned",
      "rotation": 1
    },
    {
      "x": -25,
      "y": 0,
      "z": 12,
      "name": "Soil_Grass"
    },
    {
      "x": -25,
      "y": 54,
      "z": 12,
      "name": "Deco_Bone_Full",
      "rotation": 1
    },
    {
      "x": -25,
      "y": 55,
      "z": 12,
      "name": "Deco_Bone_Full",
      "rotation": 1
    },
    {
      "x": -25,
      "y": 56,
      "z": 12,
      "name": "Deco_Bone_Full",
      "rotation": 1
    },
    {
      "x": -25,
      "y": 57,
      "z": 12,
      "name": "Soil_Roots_Poisoned",
      "rotation": 1
    },
    {
      "x": -25,
      "y": 58,
      "z": 12,
      "name": "Soil_Roots_Poisoned",
      "rotation": 1
    },
    {
      "x": -25,
      "y": 0,
      "z": 13,
      "name": "Soil_Grass"
    },
    {
      "x": -25,
      "y": 0,
      "z": 14,
      "name": "Soil_Grass"
    },
    {
      "x": -25,
      "y": 0,
      "z": 15,
      "name": "Soil_Grass"
    },
    {
      "x": -24,
      "y": 0,
      "z": -15,
      "name": "Soil_Grass"
    },
    {
      "x": -24,
      "y": 0,
      "z": -14,
      "name": "Soil_Grass"
    },
    {
      "x": -24,
      "y": 0,
      "z": -13,
      "name": "Soil_Grass"
    },
    {
      "x": -24,
      "y": 0,
      "z": -12,
      "name": "Soil_Grass"
    },
    {
      "x": -24,
      "y": 0,
      "z": -11,
      "name": "Soil_Grass"
    },
    {
      "x": -24,
      "y": 0,
      "z": -10,
      "name": "Soil_Grass"
    },
    {
      "x": -24,
      "y": 0,
      "z": -9,
      "name": "Soil_Grass"
    },
    {
      "x": -24,
      "y": 0,
      "z": -8,
      "name": "Soil_Grass"
    },
    {
      "x": -24,
      "y": 0,
      "z": -7,
      "name": "Soil_Grass"
    },
    {
      "x": -24,
      "y": 0,
      "z": -6,
      "name": "Soil_Grass"
    },
    {
      "x": -24,
      "y": 0,
      "z": -5,
      "name": "Soil_Grass"
    },
    {
      "x": -24,
      "y": 0,
      "z": -4,
      "name": "Soil_Grass"
    },
    {
      "x": -24,
      "y": 19,
      "z": -4,
      "name": "Deco_Bone_Full",
      "rotation": 1
    },
    {
      "x": -24,
      "y": 20,
      "z": -4,
      "name": "Deco_Bone_Full",
      "rotation": 1
    },
    {
      "x": -24,
      "y": 21,
      "z": -4,
      "name": "Soil_Hive_Corrupted",
      "rotation": 1
    },
    {
      "x": -24,
      "y": 22,
      "z": -4,
      "name": "Soil_Hive_Corrupted",
      "rotation": 1
    },
    {
      "x": -24,
      "y": 0,
      "z": -3,
      "name": "Soil_Grass"
    },
    {
      "x": -24,
      "y": 19,
      "z": -3,
      "name": "Deco_Bone_Full",
      "rotation": 1
    },
    {
      "x": -24,
      "y": 20,
      "z": -3,
      "name": "Deco_Bone_Full",
      "rotation": 1
    },
    {
      "x": -24,
      "y": 21,
      "z": -3,
      "name": "Deco_Bone_Full",
      "rotation": 1
    },
    {
      "x": -24,
      "y": 22,
      "z": -3,
      "name": "Soil_Roots_Poisoned",
      "rotation": 1
    },
    {
      "x": -24,
      "y": 23,
      "z": -3,
      "name": "Soil_Roots_Poisoned",
      "rotation": 1
    },
    {
      "x": -24,
      "y": 0,
      "z": -2,
      "name": "Soil_Grass"
    },
    {
      "x": -24,
      "y": 19,
      "z": -2,
      "name": "Deco_Bone_Full",
      "rotation": 1
    },
    {
      "x": -24,
      "y": 20,
      "z": -2,
      "name": "Deco_Bone_Full",
      "rotation": 1
    },
    {
      "x": -24,
      "y": 21,
      "z": -2,
      "name": "Deco_Bone_Full",
      "rotation": 1
    },
    {
      "x": -24,
      "y": 22,
      "z": -2,
      "name": "Deco_Bone_Full",
      "rotation": 1
    },
    {
      "x": -24,
      "y": 23,
      "z": -2,
      "name": "Soil_Roots_Poisoned",
      "rotation": 1
    },
    {
      "x": -24,
      "y": 24,
      "z": -2,
      "name": "Soil_Roots_Poisoned",
      "rotation": 1
    },
    {
      "x": -24,
      "y": 25,
      "z": -2,
      "name": "Plant_Bramble_Dead_Twisted"
    },
    {
      "x": -24,
      "y": 0,
      "z": -1,
      "name": "Soil_Grass"
    },
    {
      "x": -24,
      "y": 21,
      "z": -1,
      "name": "Deco_Bone_Full",
      "rotation": 1
    },
    {
      "x": -24,
      "y": 22,
      "z": -1,
      "name": "Deco_Bone_Full",
      "rotation": 1
    },
    {
      "x": -24,
      "y": 23,
      "z": -1,
      "name": "Soil_Roots_Poisoned",
      "rotation": 1
    },
    {
      "x": -24,
      "y": 24,
      "z": -1,
      "name": "Soil_Roots_Poisoned",
      "rotation": 1
    },
    {
      "x": -24,
      "y": 0,
      "z": 0,
      "name": "Soil_Grass"
    },
    {
      "x": -24,
      "y": 0,
      "z": 1,
      "name": "Soil_Grass"
    },
    {
      "x": -24,
      "y": 51,
      "z": 1,
      "name": "Soil_Roots_Poisoned",
      "rotation": 1
    },
    {
      "x": -24,
      "y": 52,
      "z": 1,
      "name": "Soil_Hive_Corrupted",
      "rotation": 1
    },
    {
      "x": -24,
      "y": 0,
      "z": 2,
      "name": "Soil_Grass"
    },
    {
      "x": -24,
      "y": 21,
      "z": 2,
      "name": "Deco_Bone_Full",
      "rotation": 1
    },
    {
      "x": -24,
      "y": 22,
      "z": 2,
      "name": "Soil_Roots_Poisoned",
      "rotation": 1
    },
    {
      "x": -24,
      "y": 23,
      "z": 2,
      "name": "Soil_Hive_Corrupted",
      "rotation": 1
    },
    {
      "x": -24,
      "y": 49,
      "z": 2,
      "name": "Deco_Bone_Full",
      "rotation": 1
    },
    {
      "x": -24,
      "y": 50,
      "z": 2,
      "name": "Deco_Bone_Full",
      "rotation": 1
    },
    {
      "x": -24,
      "y": 51,
      "z": 2,
      "name": "Deco_Bone_Full",
      "rotation": 1
    },
    {
      "x": -24,
      "y": 52,
      "z": 2,
      "name": "Soil_Roots_Poisoned",
      "rotation": 1
    },
    {
      "x": -24,
      "y": 53,
      "z": 2,
      "name": "Soil_Hive_Corrupted",
      "rotation": 1
    },
    {
      "x": -24,
      "y": 0,
      "z": 3,
      "name": "Soil_Grass"
    },
    {
      "x": -24,
      "y": 20,
      "z": 3,
      "name": "Deco_Bone_Full",
      "rotation": 1
    },
    {
      "x": -24,
      "y": 21,
      "z": 3,
      "name": "Deco_Bone_Full",
      "rotation": 1
    },
    {
      "x": -24,
      "y": 22,
      "z": 3,
      "name": "Deco_Bone_Full",
      "rotation": 1
    },
    {
      "x": -24,
      "y": 23,
      "z": 3,
      "name": "Deco_Bone_Full",
      "rotation": 1
    },
    {
      "x": -24,
      "y": 24,
      "z": 3,
      "name": "Soil_Hive_Corrupted",
      "rotation": 1
    },
    {
      "x": -24,
      "y": 25,
      "z": 3,
      "name": "Soil_Roots_Poisoned",
      "rotation": 1
    },
    {
      "x": -24,
      "y": 49,
      "z": 3,
      "name": "Deco_Bone_Full",
      "rotation": 1
    },
    {
      "x": -24,
      "y": 50,
      "z": 3,
      "name": "Deco_Bone_Full",
      "rotation": 1
    },
    {
      "x": -24,
      "y": 51,
      "z": 3,
      "name": "Deco_Bone_Full",
      "rotation": 1
    },
    {
      "x": -24,
      "y": 52,
      "z": 3,
      "name": "Soil_Hive_Corrupted",
      "rotation": 1
    },
    {
      "x": -24,
      "y": 53,
      "z": 3,
      "name": "Soil_Roots_Poisoned",
      "rotation": 1
    },
    {
      "x": -24,
      "y": 0,
      "z": 4,
      "name": "Soil_Grass"
    },
    {
      "x": -24,
      "y": 21,
      "z": 4,
      "name": "Deco_Bone_Full",
      "rotation": 1
    },
    {
      "x": -24,
      "y": 22,
      "z": 4,
      "name": "Deco_Bone_Full",
      "rotation": 1
    },
    {
      "x": -24,
      "y": 23,
      "z": 4,
      "name": "Deco_Bone_Full",
      "rotation": 1
    },
    {
      "x": -24,
      "y": 24,
      "z": 4,
      "name": "Soil_Hive_Corrupted",
      "rotation": 1
    },
    {
      "x": -24,
      "y": 25,
      "z": 4,
      "name": "Soil_Roots_Poisoned",
      "rotation": 1
    },
    {
      "x": -24,
      "y": 0,
      "z": 5,
      "name": "Soil_Grass"
    },
    {
      "x": -24,
      "y": 22,
      "z": 5,
      "name": "Deco_Bone_Full",
      "rotation": 1
    },
    {
      "x": -24,
      "y": 23,
      "z": 5,
      "name": "Deco_Bone_Full",
      "rotation": 1
    },
    {
      "x": -24,
      "y": 24,
      "z": 5,
      "name": "Deco_Bone_Full",
      "rotation": 1
    },
    {
      "x": -24,
      "y": 25,
      "z": 5,
      "name": "Soil_Hive_Corrupted",
      "rotation": 1
    },
    {
      "x": -24,
      "y": 26,
      "z": 5,
      "name": "Soil_Hive_Corrupted",
      "rotation": 1
    },
    {
      "x": -24,
      "y": 0,
      "z": 6,
      "name": "Soil_Grass"
    },
    {
      "x": -24,
      "y": 25,
      "z": 6,
      "name": "Soil_Hive_Corrupted",
      "rotation": 1
    },
    {
      "x": -24,
      "y": 26,
      "z": 6,
      "name": "Soil_Roots_Poisoned",
      "rotation": 1
    },
    {
      "x": -24,
      "y": 0,
      "z": 7,
      "name": "Soil_Grass"
    },
    {
      "x": -24,
      "y": 0,
      "z": 8,
      "name": "Soil_Grass"
    },
    {
      "x": -24,
      "y": 0,
      "z": 9,
      "name": "Soil_Grass"
    },
    {
      "x": -24,
      "y": 0,
      "z": 10,
      "name": "Soil_Grass"
    },
    {
      "x": -24,
      "y": 0,
      "z": 11,
      "name": "Soil_Grass"
    },
    {
      "x": -24,
      "y": 55,
      "z": 11,
      "name": "Deco_Bone_Full",
      "rotation": 1
    },
    {
      "x": -24,
      "y": 56,
      "z": 11,
      "name": "Deco_Bone_Full",
      "rotation": 1
    },
    {
      "x": -24,
      "y": 57,
      "z": 11,
      "name": "Deco_Bone_Full",
      "rotation": 1
    },
    {
      "x": -24,
      "y": 58,
      "z": 11,
      "name": "Deco_Bone_Full",
      "rotation": 1
    },
    {
      "x": -24,
      "y": 59,
      "z": 11,
      "name": "Soil_Roots_Poisoned",
      "rotation": 1
    },
    {
      "x": -24,
      "y": 60,
      "z": 11,
      "name": "Soil_Hive_Corrupted",
      "rotation": 1
    },
    {
      "x": -24,
      "y": 0,
      "z": 12,
      "name": "Soil_Grass"
    },
    {
      "x": -24,
      "y": 55,
      "z": 12,
      "name": "Deco_Bone_Full",
      "rotation": 1
    },
    {
      "x": -24,
      "y": 56,
      "z": 12,
      "name": "Deco_Bone_Full",
      "rotation": 1
    },
    {
      "x": -24,
      "y": 57,
      "z": 12,
      "name": "Deco_Bone_Full",
      "rotation": 1
    },
    {
      "x": -24,
      "y": 58,
      "z": 12,
      "name": "Deco_Bone_Full",
      "rotation": 1
    },
    {
      "x": -24,
      "y": 59,
      "z": 12,
      "name": "Soil_Hive_Corrupted",
      "rotation": 1
    },
    {
      "x": -24,
      "y": 60,
      "z": 12,
      "name": "Soil_Hive_Corrupted",
      "rotation": 1
    },
    {
      "x": -24,
      "y": 0,
      "z": 13,
      "name": "Soil_Grass"
    },
    {
      "x": -24,
      "y": 56,
      "z": 13,
      "name": "Deco_Bone_Full",
      "rotation": 1
