{
  "version": 8,
  "blockIdVersion": 11,
  "anchorX": 0,
  "anchorY": 6,
  "anchorZ": 0,
  "blocks": [
    {
      "x": -30,
      "y": 30,
      "z": 11,
      "name": "Soil_Hive_Corrupted",
      "rotation": 1
    },
    {
      "x": -30,
      "y": 32,
      "z": 11,
      "name": "Soil_Hive_Corrupted",
      "rotation": 1
    },
    {
      "x": -30,
      "y": 0,
      "z": 12,
      "name": "Soil_Grass"
    },
    {
      "x": -30,
      "y": 31,
      "z": 12,
      "name": "Soil_Hive_Corrupted",
      "rotation": 1
    },
    {
      "x": -30,
      "y": 0,
      "z": 13,
      "name": "Soil_Grass"
    },
    {
      "x": -30,
      "y": 0,
      "z": 14,
      "name": "Soil_Grass"
    },
    {
      "x": -29,
      "y": 0,
      "z": -13,
      "name": "Soil_Grass"
    },
    {
      "x": -29,
      "y": 0,
      "z": -12,
      "name": "Soil_Grass"
    },
    {
      "x": -29,
      "y": 0,
      "z": -11,
      "name": "Soil_Grass"
    },
    {
      "x": -29,
      "y": 0,
      "z": -10,
      "name": "Soil_Grass"
    },
    {
      "x": -29,
      "y": 0,
      "z": -9,
      "name": "Soil_Grass"
    },
    {
      "x": -29,
      "y": 0,
      "z": -8,
      "name": "Soil_Grass"
    },
    {
      "x": -29,
      "y": 0,
      "z": -7,
      "name": "Soil_Grass"
    },
    {
      "x": -29,
      "y": 0,
      "z": -6,
      "name": "Soil_Grass"
    },
    {
      "x": -29,
      "y": 0,
      "z": -5,
      "name": "Soil_Grass"
    },
    {
      "x": -29,
      "y": 0,
      "z": -4,
      "name": "Soil_Grass"
    },
    {
      "x": -29,
      "y": 0,
      "z": -3,
      "name": "Soil_Grass"
    },
    {
      "x": -29,
      "y": 0,
      "z": -2,
      "name": "Soil_Grass"
    },
    {
      "x": -29,
      "y": 0,
      "z": -1,
      "name": "Soil_Grass"
    },
    {
      "x": -29,
      "y": 0,
      "z": 0,
      "name": "Soil_Grass"
    },
    {
      "x": -29,
      "y": 0,
      "z": 1,
      "name": "Soil_Grass"
    },
    {
      "x": -29,
      "y": 0,
      "z": 2,
      "name": "Soil_Grass"
    },
    {
      "x": -29,
      "y": 0,
      "z": 3,
      "name": "Soil_Grass"
    },
    {
      "x": -29,
      "y": 0,
      "z": 4,
      "name": "Soil_Grass"
    },
    {
      "x": -29,
      "y": 0,
      "z": 5,
      "name": "Soil_Grass"
    },
    {
      "x": -29,
      "y": 0,
      "z": 6,
      "name": "Soil_Grass"
    },
    {
      "x": -29,
      "y": 0,
      "z": 7,
      "name": "Soil_Grass"
    },
    {
      "x": -29,
      "y": 0,
      "z": 8,
      "name": "Soil_Grass"
    },
    {
      "x": -29,
      "y": 0,
      "z": 9,
      "name": "Soil_Grass"
    },
    {
      "x": -29,
      "y": 0,
      "z": 10,
      "name": "Soil_Grass"
    },
    {
      "x": -29,
      "y": 26,
      "z": 10,
      "name": "Soil_Roots_Poisoned",
      "rotation": 1
    },
    {
      "x": -29,
      "y": 27,
      "z": 10,
      "name": "Soil_Hive_Corrupted",
      "rotation": 1
    },
    {
      "x": -29,
      "y": 0,
      "z": 11,
      "name": "Soil_Grass"
    },
    {
      "x": -29,
      "y": 26,
      "z": 11,
      "name": "Deco_Bone_Full",
      "rotation": 1
    },
    {
      "x": -29,
      "y": 27,
      "z": 11,
      "name": "Deco_Bone_Full",
      "rotation": 1
    },
    {
      "x": -29,
      "y": 28,
      "z": 11,
      "name": "Deco_Bone_Full",
      "rotation": 1
    },
    {
      "x": -29,
      "y": 29,
      "z": 11,
      "name": "Deco_Bone_Full",
      "rotation": 1
    },
    {
      "x": -29,
      "y": 30,
      "z": 11,
      "name": "Deco_Bone_Full",
      "rotation": 1
    },
    {
      "x": -29,
      "y": 31,
      "z": 11,
      "name": "Deco_Bone_Full",
      "rotation": 1
    },
    {
      "x": -29,
      "y": 32,
      "z": 11,
      "name": "Soil_Roots_Poisoned",
      "rotation": 1
    },
    {
      "x": -29,
      "y": 33,
      "z": 11,
      "name": "Soil_Roots_Poisoned",
      "rotation": 1
    },
    {
      "x": -29,
      "y": 0,
      "z": 12,
      "name": "Soil_Grass"
    },
    {
      "x": -29,
      "y": 29,
      "z": 12,
      "name": "Deco_Bone_Full",
      "rotation": 1
    },
    {
      "x": -29,
      "y": 30,
      "z": 12,
      "name": "Deco_Bone_Full",
      "rotation": 1
    },
    {
      "x": -29,
      "y": 31,
      "z": 12,
      "name": "Deco_Bone_Full",
      "rotation": 1
    },
    {
      "x": -29,
      "y": 32,
      "z": 12,
      "name": "Soil_Roots_Poisoned",
      "rotation": 1
    },
    {
      "x": -29,
      "y": 33,
      "z": 12,
      "name": "Soil_Roots_Poisoned",
      "rotation": 1
    },
    {
      "x": -29,
      "y": 0,
      "z": 13,
      "name": "Soil_Grass"
    },
    {
      "x": -29,
      "y": 31,
      "z": 13,
      "name": "Deco_Bone_Full",
      "rotation": 1
    },
    {
      "x": -29,
      "y": 32,
      "z": 13,
      "name": "Soil_Roots_Poisoned",
      "rotation": 1
    },
    {
      "x": -29,
      "y": 33,
      "z": 13,
      "name": "Soil_Roots_Poisoned",
      "rotation": 1
    },
    {
      "x": -29,
      "y": 0,
      "z": 14,
      "name": "Soil_Grass"
    },
    {
      "x": -28,
      "y": 0,
      "z": -13,
      "name": "Soil_Grass"
    },
    {
      "x": -28,
      "y": 0,
      "z": -12,
      "name": "Soil_Grass"
    },
    {
      "x": -28,
      "y": 0,
      "z": -11,
      "name": "Soil_Grass"
    },
    {
      "x": -28,
      "y": 0,
      "z": -10,
      "name": "Soil_Grass"
    },
    {
      "x": -28,
      "y": 0,
      "z": -9,
      "name": "Soil_Grass"
    },
    {
      "x": -28,
      "y": 0,
      "z": -8,
      "name": "Soil_Grass"
    },
    {
      "x": -28,
      "y": 0,
      "z": -7,
      "name": "Soil_Grass"
    },
    {
      "x": -28,
      "y": 0,
      "z": -6,
      "name": "Soil_Grass"
    },
    {
      "x": -28,
      "y": 0,
      "z": -5,
      "name": "Soil_Grass"
    },
    {
      "x": -28,
      "y": 0,
      "z": -4,
      "name": "Soil_Grass"
    },
    {
      "x": -28,
      "y": 0,
      "z": -3,
      "name": "Soil_Grass"
    },
    {
      "x": -28,
      "y": 0,
      "z": -2,
      "name": "Soil_Grass"
    },
    {
      "x": -28,
      "y": 0,
      "z": -1,
      "name": "Soil_Grass"
    },
    {
      "x": -28,
      "y": 0,
      "z": 0,
      "name": "Soil_Grass"
    },
    {
      "x": -28,
      "y": 0,
      "z": 1,
      "name": "Soil_Grass"
    },
    {
      "x": -28,
      "y": 0,
      "z": 2,
      "name": "Soil_Grass"
    },
    {
      "x": -28,
      "y": 0,
      "z": 3,
      "name": "Soil_Grass"
    },
    {
      "x": -28,
      "y": 0,
      "z": 4,
      "name": "Soil_Grass"
    },
    {
      "x": -28,
      "y": 0,
      "z": 5,
      "name": "Soil_Grass"
    },
    {
      "x": -28,
      "y": 0,
      "z": 6,
      "name": "Soil_Grass"
    },
    {
      "x": -28,
      "y": 0,
      "z": 7,
      "name": "Soil_Grass"
    },
    {
      "x": -28,
      "y": 0,
      "z": 8,
      "name": "Soil_Grass"
    },
    {
      "x": -28,
      "y": 0,
      "z": 9,
      "name": "Soil_Grass"
    },
    {
      "x": -28,
      "y": 22,
      "z": 9,
      "name": "Deco_Bone_Full",
      "rotation": 1
    },
    {
      "x": -28,
      "y": 23,
      "z": 9,
      "name": "Deco_Bone_Full",
      "rotation": 1
    },
    {
      "x": -28,
      "y": 24,
      "z": 9,
      "name": "Soil_Hive_Corrupted",
      "rotation": 1
    },
    {
      "x": -28,
      "y": 25,
      "z": 9,
      "name": "Soil_Roots_Poisoned",
      "rotation": 1
    },
    {
      "x": -28,
      "y": 0,
      "z": 10,
      "name": "Soil_Grass"
    },
    {
      "x": -28,
      "y": 23,
      "z": 10,
      "name": "Deco_Bone_Full",
      "rotation": 1
    },
    {
      "x": -28,
      "y": 24,
      "z": 10,
      "name": "Deco_Bone_Full",
      "rotation": 1
    },
    {
      "x": -28,
      "y": 25,
      "z": 10,
      "name": "Deco_Bone_Full",
      "rotation": 1
    },
    {
      "x": -28,
      "y": 26,
      "z": 10,
      "name": "Deco_Bone_Full",
      "rotation": 1
    },
    {
      "x": -28,
      "y": 27,
      "z": 10,
      "name": "Soil_Hive_Corrupted",
      "rotation": 1
    },
    {
      "x": -28,
      "y": 28,
      "z": 10,
      "name": "Soil_Roots_Poisoned",
      "rotation": 1
    },
    {
      "x": -28,
      "y": 0,
      "z": 11,
      "name": "Soil_Grass"
    },
    {
      "x": -28,
      "y": 25,
      "z": 11,
      "name": "Deco_Bone_Full",
      "rotation": 1
    },
    {
      "x": -28,
      "y": 26,
      "z": 11,
      "name": "Deco_Bone_Full",
      "rotation": 1
    },
    {
      "x": -28,
      "y": 27,
      "z": 11,
      "name": "Deco_Bone_Full",
      "rotation": 1
    },
    {
      "x": -28,
      "y": 28,
      "z": 11,
      "name": "Deco_Bone_Full",
      "rotation": 1
    },
    {
      "x": -28,
      "y": 29,
      "z": 11,
      "name": "Deco_Bone_Full",
      "rotation": 1
    },
    {
      "x": -28,
      "y": 30,
      "z": 11,
      "name": "Deco_Bone_Full",
      "rotation": 1
    },
    {
      "x": -28,
      "y": 31,
      "z": 11,
      "name": "Deco_Bone_Full",
      "rotation": 1
    },
    {
      "x": -28,
      "y": 32,
      "z": 11,
      "name": "Soil_Hive_Corrupted",
      "rotation": 1
    },
    {
      "x": -28,
      "y": 33,
      "z": 11,
      "name": "Soil_Roots_Poisoned",
      "rotation": 1
    },
    {
      "x": -28,
      "y": 0,
      "z": 12,
      "name": "Soil_Grass"
    },
    {
      "x": -28,
      "y": 27,
      "z": 12,
      "name": "Deco_Bone_Full",
      "rotation": 1
    },
    {
      "x": -28,
      "y": 28,
      "z": 12,
      "name": "Deco_Bone_Full",
      "rotation": 1
    },
    {
      "x": -28,
      "y": 29,
      "z": 12,
      "name": "Deco_Bone_Full",
      "rotation": 1
    },
    {
      "x": -28,
      "y": 30,
      "z": 12,
      "name": "Deco_Bone_Full",
      "rotation": 1
    },
    {
      "x": -28,
      "y": 31,
      "z": 12,
      "name": "Deco_Bone_Full",
      "rotation": 1
    },
    {
      "x": -28,
      "y": 32,
      "z": 12,
      "name": "Soil_Roots_Poisoned",
      "rotation": 1
    },
    {
      "x": -28,
      "y": 33,
      "z": 12,
      "name": "Soil_Hive_Corrupted",
      "rotation": 1
    },
    {
      "x": -28,
      "y": 0,
      "z": 13,
      "name": "Soil_Grass"
    },
    {
      "x": -28,
      "y": 30,
      "z": 13,
      "name": "Deco_Bone_Full",
      "rotation": 1
    },
    {
      "x": -28,
      "y": 31,
      "z": 13,
      "name": "Deco_Bone_Full",
      "rotation": 1
    },
    {
      "x": -28,
      "y": 32,
      "z": 13,
      "name": "Soil_Roots_Poisoned",
      "rotation": 1
    },
    {
      "x": -28,
      "y": 33,
      "z": 13,
      "name": "Soil_Roots_Poisoned",
      "rotation": 1
    },
    {
      "x": -28,
      "y": 0,
      "z": 14,
      "name": "Soil_Grass"
    },
    {
      "x": -27,
      "y": 0,
      "z": -13,
      "name": "Soil_Grass"
    },
    {
      "x": -27,
      "y": 0,
      "z": -12,
      "name": "Soil_Grass"
    },
    {
      "x": -27,
      "y": 0,
      "z": -11,
      "name": "Soil_Grass"
    },
    {
      "x": -27,
      "y": 0,
      "z": -10,
      "name": "Soil_Grass"
    },
    {
      "x": -27,
      "y": 0,
      "z": -9,
      "name": "Soil_Grass"
    },
    {
      "x": -27,
      "y": 0,
      "z": -8,
      "name": "Soil_Grass"
    },
    {
      "x": -27,
      "y": 0,
      "z": -7,
      "name": "Soil_Grass"
    },
    {
      "x": -27,
      "y": 0,
      "z": -6,
      "name": "Soil_Grass"
    },
    {
      "x": -27,
      "y": 0,
      "z": -5,
      "name": "Soil_Grass"
    },
    {
      "x": -27,
      "y": 0,
      "z": -4,
      "name": "Soil_Grass"
    },
    {
      "x": -27,
      "y": 0,
      "z": -3,
      "name": "Soil_Grass"
    },
    {
      "x": -27,
      "y": 0,
      "z": -2,
      "name": "Soil_Grass"
    },
    {
      "x": -27,
      "y": 0,
      "z": -1,
      "name": "Soil_Grass"
    },
    {
      "x": -27,
      "y": 0,
      "z": 0,
      "name": "Soil_Grass"
    },
    {
      "x": -27,
      "y": 0,
      "z": 1,
      "name": "Soil_Grass"
    },
    {
      "x": -27,
      "y": 0,
      "z": 2,
      "name": "Soil_Grass"
    },
    {
      "x": -27,
      "y": 0,
      "z": 3,
      "name": "Soil_Grass"
    },
    {
      "x": -27,
      "y": 0,
      "z": 4,
      "name": "Soil_Grass"
    },
    {
      "x": -27,
      "y": 0,
      "z": 5,
      "name": "Soil_Grass"
    },
    {
      "x": -27,
      "y": 0,
      "z": 6,
      "name": "Soil_Grass"
    },
    {
      "x": -27,
      "y": 0,
      "z": 7,
      "name": "Soil_Grass"
    },
    {
      "x": -27,
      "y": 0,
      "z": 8,
      "name": "Soil_Grass"
    },
    {
      "x": -27,
      "y": 20,
      "z": 8,
      "name": "Soil_Hive_Corrupted",
      "rotation": 1
    },
    {
      "x": -27,
      "y": 21,
      "z": 8,
      "name": "Soil_Hive_Corrupted",
      "rotation": 1
    },
    {
      "x": -27,
      "y": 0,
      "z": 9,
      "name": "Soil_Grass"
    },
    {
      "x": -27,
      "y": 20,
      "z": 9,
      "name": "Deco_Bone_Full",
      "rotation": 1
    },
    {
      "x": -27,
      "y": 21,
      "z": 9,
      "name": "Deco_Bone_Full",
      "rotation": 1
    },
    {
      "x": -27,
      "y": 22,
      "z": 9,
      "name": "Deco_Bone_Full",
      "rotation": 1
    },
    {
      "x": -27,
      "y": 23,
      "z": 9,
      "name": "Deco_Bone_Full",
      "rotation": 1
    },
    {
      "x": -27,
      "y": 24,
      "z": 9,
      "name": "Soil_Roots_Poisoned",
      "rotation": 1
    },
    {
      "x": -27,
      "y": 25,
      "z": 9,
      "name": "Soil_Roots_Poisoned",
      "rotation": 1
    },
    {
      "x": -27,
      "y": 0,
      "z": 10,
      "name": "Soil_Grass"
    },
    {
      "x": -27,
      "y": 21,
      "z": 10,
      "name": "Deco_Bone_Full",
      "rotation": 1
    },
    {
      "x": -27,
      "y": 22,
      "z": 10,
      "name": "Deco_Bone_Full",
      "rotation": 1
    },
    {
      "x": -27,
      "y": 23,
      "z": 10,
      "name": "Deco_Bone_Full",
      "rotation": 1
    },
    {
      "x": -27,
      "y": 24,
      "z": 10,
      "name": "Deco_Bone_Full",
      "rotation": 1
    },
    {
      "x": -27,
      "y": 25,
      "z": 10,
      "name": "Deco_Bone_Full",
      "rotation": 1
    },
    {
      "x": -27,
      "y": 26,
      "z": 10,
      "name": "Soil_Hive_Corrupted",
      "rotation": 1
    },
    {
      "x": -27,
      "y": 27,
      "z": 10,
      "name": "Soil_Hive_Corrupted",
      "rotation": 1
    },
    {
      "x": -27,
      "y": 0,
      "z": 11,
      "name": "Soil_Grass"
    },
    {
      "x": -27,
      "y": 23,
      "z": 11,
      "name": "Deco_Bone_Full",
      "rotation": 1
    },
    {
      "x": -27,
      "y": 24,
      "z": 11,
      "name": "Deco_Bone_Full",
      "rotation": 1
    },
    {
      "x": -27,
      "y": 25,
      "z": 11,
      "name": "Deco_Bone_Full",
      "rotation": 1
    },
    {
      "x": -27,
      "y": 26,
      "z": 11,
      "name": "Deco_Bone_Full",
      "rotation": 1
    },
    {
      "x": -27,
      "y": 27,
      "z": 11,
      "name": "Deco_Bone_Full",
      "rotation": 1
    },
    {
      "x": -27,
      "y": 28,
      "z": 11,
      "name": "Soil_Hive_Corrupted",
      "rotation": 1
    },
    {
      "x": -27,
      "y": 29,
      "z": 11,
      "name": "Soil_Roots_Poisoned",
      "rotation": 1
    },
    {
      "x": -27,
      "y": 31,
      "z": 11,
      "name": "Soil_Roots_Poisoned",
      "rotation": 1
    },
    {
      "x": -27,
      "y": 32,
      "z": 11,
      "name": "Soil_Roots_Poisoned",
      "rotation": 1
    },
    {
      "x": -27,
      "y": 0,
      "z": 12,
      "name": "Soil_Grass"
    },
    {
      "x": -27,
      "y": 26,
      "z": 12,
      "name": "Deco_Bone_Full",
      "rotation": 1
    },
    {
      "x": -27,
      "y": 27,
      "z": 12,
      "name": "Deco_Bone_Full",
      "rotation": 1
    },
    {
      "x": -27,
      "y": 28,
      "z": 12,
      "name": "Deco_Bone_Full",
      "rotation": 1
    },
    {
      "x": -27,
      "y": 29,
      "z": 12,
      "name": "Deco_Bone_Full",
      "rotation": 1
    },
    {
      "x": -27,
      "y": 30,
      "z": 12,
      "name": "Deco_Bone_Full",
      "rotation": 1
    },
    {
      "x": -27,
      "y": 31,
      "z": 12,
      "name": "Deco_Bone_Full",
      "rotation": 1
    },
    {
      "x": -27,
      "y": 32,
      "z": 12,
      "name": "Soil_Hive_Corrupted",
      "rotation": 1
    },
    {
      "x": -27,
      "y": 33,
      "z": 12,
      "name": "Soil_Hive_Corrupted",
      "rotation": 1
    },
    {
      "x": -27,
      "y": 0,
      "z": 13,
      "name": "Soil_Grass"
    },
    {
      "x": -27,
      "y": 31,
      "z": 13,
      "name": "Deco_Bone_Full",
      "rotation": 1
    },
    {
      "x": -27,
      "y": 32,
      "z": 13,
      "name": "Soil_Hive_Corrupted",
      "rotation": 1
    },
    {
      "x": -27,
      "y": 33,
      "z": 13,
      "name": "Soil_Roots_Poisoned",
      "rotation": 1
    },
    {
      "x": -27,
      "y": 0,
      "z": 14,
      "name": "Soil_Grass"
    },
    {
      "x": -26,
      "y": 0,
      "z": -13,
      "name": "Soil_Grass"
    },
    {
      "x": -26,
      "y": 0,
      "z": -12,
      "name": "Soil_Grass"
    },
    {
      "x": -26,
      "y": 0,
      "z": -11,
      "name": "Soil_Grass"
    },
    {
      "x": -26,
      "y": 0,
      "z": -10,
      "name": "Soil_Grass"
    },
    {
      "x": -26,
      "y": 0,
      "z": -9,
      "name": "Soil_Grass"
    },
    {
      "x": -26,
      "y": 0,
      "z": -8,
      "name": "Soil_Grass"
    },
    {
      "x": -26,
      "y": 0,
      "z": -7,
      "name": "Soil_Grass"
    },
    {
      "x": -26,
      "y": 0,
      "z": -6,
      "name": "Soil_Grass"
    },
    {
      "x": -26,
      "y": 0,
      "z": -5,
      "name": "Soil_Grass"
    },
    {
      "x": -26,
      "y": 0,
      "z": -4,
      "name": "Soil_Grass"
    },
    {
      "x": -26,
      "y": 0,
      "z": -3,
      "name": "Soil_Grass"
    },
    {
      "x": -26,
      "y": 0,
      "z": -2,
      "name": "Soil_Grass"
    },
    {
      "x": -26,
      "y": 0,
      "z": -1,
      "name": "Soil_Grass"
    },
    {
      "x": -26,
      "y": 0,
      "z": 0,
      "name": "Soil_Grass"
    },
    {
      "x": -26,
      "y": 0,
      "z": 1,
      "name": "Soil_Grass"
    },
    {
      "x": -26,
      "y": 0,
      "z": 2,
      "name": "Soil_Grass"
    },
    {
      "x": -26,
      "y": 0,
      "z": 3,
      "name": "Soil_Grass"
    },
    {
      "x": -26,
      "y": 27,
      "z": 3,
      "name": "Soil_Hive_Corrupted",
      "rotation": 1
    },
    {
      "x": -26,
      "y": 0,
      "z": 4,
      "name": "Soil_Grass"
    },
    {
      "x": -26,
      "y": 0,
      "z": 5,
      "name": "Soil_Grass"
    },
    {
      "x": -26,
      "y": 0,
      "z": 6,
      "name": "Soil_Grass"
    },
    {
      "x": -26,
      "y": 0,
      "z": 7,
      "name": "Soil_Grass"
    },
    {
      "x": -26,
      "y": 18,
      "z": 7,
      "name": "Soil_Hive_Corrupted",
      "rotation": 1
    },
    {
      "x": -26,
      "y": 19,
      "z": 7,
      "name": "Soil_Roots_Poisoned",
      "rotation": 1
    },
    {
      "x": -26,
      "y": 0,
      "z": 8,
      "name": "Soil_Grass"
    },
    {
      "x": -26,
      "y": 18,
      "z": 8,
      "name": "Deco_Bone_Full",
      "rotation": 1
    },
    {
      "x": -26,
      "y": 19,
      "z": 8,
      "name": "Deco_Bone_Full",
      "rotation": 1
    },
    {
      "x": -26,
      "y": 20,
      "z": 8,
      "name": "Deco_Bone_Full",
      "rotation": 1
    },
    {
      "x": -26,
      "y": 21,
      "z": 8,
      "name": "Soil_Roots_Poisoned",
      "rotation": 1
    },
    {
      "x": -26,
      "y": 22,
      "z": 8,
      "name": "Soil_Hive_Corrupted",
      "rotation": 1
    },
    {
      "x": -26,
      "y": 0,
      "z": 9,
      "name": "Soil_Grass"
    },
    {
      "x": -26,
      "y": 19,
      "z": 9,
      "name": "Deco_Bone_Full",
      "rotation": 1
    },
    {
      "x": -26,
      "y": 20,
      "z": 9,
      "name": "Deco_Bone_Full",
      "rotation": 1
    },
    {
      "x": -26,
      "y": 21,
      "z": 9,
      "name": "Deco_Bone_Full",
      "rotation": 1
    },
    {
      "x": -26,
      "y": 22,
      "z": 9,
      "name": "Soil_Roots_Poisoned",
      "rotation": 1
    },
    {
      "x": -26,
      "y": 23,
      "z": 9,
      "name": "Soil_Hive_Corrupted",
      "rotation": 1
    },
    {
      "x": -26,
      "y": 0,
      "z": 10,
      "name": "Soil_Grass"
    },
    {
      "x": -26,
      "y": 20,
      "z": 10,
      "name": "Deco_Bone_Full",
      "rotation": 1
    },
    {
      "x": -26,
      "y": 21,
      "z": 10,
      "name": "Deco_Bone_Full",
      "rotation": 1
    },
    {
      "x": -26,
      "y": 22,
      "z": 10,
      "name": "Deco_Bone_Full",
      "rotation": 1
    },
    {
      "x": -26,
      "y": 23,
      "z": 10,
      "name": "Deco_Bone_Full",
      "rotation": 1
    },
    {
      "x": -26,
      "y": 24,
      "z": 10,
      "name": "Soil_Hive_Corrupted",
      "rotation": 1
    },
    {
      "x": -26,
      "y": 25,
      "z": 10,
      "name": "Soil_Roots_Poisoned",
      "rotation": 1
    },
    {
      "x": -26,
      "y": 0,
      "z": 11,
      "name": "Soil_Grass"
    },
    {
      "x": -26,
      "y": 22,
      "z": 11,
      "name": "Deco_Bone_Full",
      "rotation": 1
    },
    {
      "x": -26,
      "y": 23,
      "z": 11,
      "name": "Deco_Bone_Full",
      "rotation": 1
    },
    {
      "x": -26,
      "y": 24,
      "z": 11,
      "name": "Deco_Bone_Full",
      "rotation": 1
    },
    {
      "x": -26,
      "y": 25,
      "z": 11,
      "name": "Soil_Hive_Corrupted",
      "rotation": 1
    },
    {
      "x": -26,
      "y": 26,
      "z": 11,
      "name": "Soil_Roots_Poisoned",
      "rotation": 1
    },
    {
      "x": -26,
      "y": 0,
      "z": 12,
      "name": "Soil_Grass"
    },
    {
      "x": -26,
      "y": 0,
      "z": 13,
      "name": "Soil_Grass"
    },
    {
      "x": -26,
      "y": 0,
      "z": 14,
      "name": "Soil_Grass"
    },
    {
      "x": -25,
      "y": 0,
      "z": -13,
      "name": "Soil_Grass"
    },
    {
      "x": -25,
      "y": 0,
      "z": -12,
      "name": "Soil_Grass"
    },
    {
      "x": -25,
      "y": 0,
      "z": -11,
      "name": "Soil_Grass"
    },
    {
      "x": -25,
      "y": 0,
      "z": -10,
      "name": "Soil_Grass"
    },
    {
      "x": -25,
      "y": 0,
      "z": -9,
      "name": "Soil_Grass"
    },
    {
      "x": -25,
      "y": 0,
      "z": -8,
      "name": "Soil_Grass"
    },
    {
      "x": -25,
      "y": 0,
      "z": -7,
      "name": "Soil_Grass"
    },
    {
      "x": -25,
      "y": 0,
      "z": -6,
      "name": "Soil_Grass"
    },
    {
      "x": -25,
      "y": 0,
      "z": -5,
      "name": "Soil_Grass"
    },
    {
      "x": -25,
      "y": 0,
      "z": -4,
      "name": "Soil_Grass"
    },
    {
      "x": -25,
      "y": 0,
      "z": -3,
      "name": "Soil_Grass"
    },
    {
      "x": -25,
      "y": 0,
      "z": -2,
      "name": "Soil_Grass"
    },
    {
      "x": -25,
      "y": 0,
      "z": -1,
      "name": "Soil_Grass"
    },
    {
      "x": -25,
      "y": 0,
      "z": 0,
      "name": "Soil_Grass"
    },
    {
      "x": -25,
      "y": 0,
      "z": 1,
      "name": "Soil_Grass"
    },
    {
      "x": -25,
      "y": 20,
      "z": 1,
      "name": "Deco_Bone_Full",
      "rotation": 1
    },
    {
      "x": -25,
      "y": 21,
      "z": 1,
      "name": "Soil_Roots_Poisoned",
      "rotation": 1
    },
    {
      "x": -25,
      "y": 22,
      "z": 1,
      "name": "Soil_Hive_Corrupted",
      "rotation": 1
    },
    {
      "x": -25,
      "y": 0,
      "z": 2,
      "name": "Soil_Grass"
    },
    {
      "x": -25,
      "y": 21,
      "z": 2,
      "name": "Deco_Bone_Full",
      "rotation": 1
    },
    {
      "x": -25,
      "y": 22,
      "z": 2,
      "name": "Deco_Bone_Full",
      "rotation": 1
    },
    {
      "x": -25,
      "y": 23,
      "z": 2,
      "name": "Deco_Bone_Full",
      "rotation": 1
    },
    {
      "x": -25,
      "y": 24,
      "z": 2,
      "name": "Deco_Bone_Full",
      "rotation": 1
    },
    {
      "x": -25,
      "y": 25,
      "z": 2,
      "name": "Deco_Bone_Full",
      "rotation": 1
    },
    {
      "x": -25,
      "y": 26,
      "z": 2,
      "name": "Deco_Bone_Full",
      "rotation": 1
    },
    {
      "x": -25,
      "y": 27,
      "z": 2,
      "name": "Deco_Bone_Full",
      "rotation": 1
    },
    {
      "x": -25,
      "y": 28,
      "z": 2,
      "name": "Soil_Hive_Corrupted",
      "rotation": 1
    },
    {
      "x": -25,
      "y": 29,
      "z": 2,
      "name": "Soil_Roots_Poisoned",
      "rotation": 1
    },
    {
      "x": -25,
      "y": 0,
      "z": 3,
      "name": "Soil_Grass"
    },
    {
      "x": -25,
      "y": 23,
      "z": 3,
      "name": "Deco_Bone_Full",
      "rotation": 1
    },
    {
      "x": -25,
      "y": 24,
      "z": 3,
      "name": "Deco_Bone_Full",
      "rotation": 1
    },
    {
      "x": -25,
      "y": 25,
      "z": 3,
      "name": "Deco_Bone_Full",
      "rotation": 1
    },
    {
      "x": -25,
      "y": 26,
      "z": 3,
      "name": "Deco_Bone_Full",
      "rotation": 1
    },
    {
      "x": -25,
      "y": 27,
      "z": 3,
      "name": "Deco_Bone_Full",
      "rotation": 1
    },
    {
      "x": -25,
      "y": 28,
      "z": 3,
      "name": "Soil_Hive_Corrupted",
      "rotation": 1
    },
    {
      "x": -25,
      "y": 29,
      "z": 3,
      "name": "Soil_Hive_Corrupted",
      "rotation": 1
    },
    {
      "x": -25,
      "y": 0,
      "z": 4,
      "name": "Soil_Grass"
    },
    {
      "x": -25,
      "y": 27,
      "z": 4,
      "name": "Deco_Bone_Full",
      "rotation": 1
    },
    {
      "x": -25,
      "y": 28,
      "z": 4,
      "name": "Soil_Hive_Corrupted",
      "rotation": 1
    },
    {
      "x": -25,
      "y": 29,
      "z": 4,
      "name": "Soil_Roots_Poisoned",
      "rotation": 1
    },
    {
      "x": -25,
      "y": 0,
      "z": 5,
      "name": "Soil_Grass"
    },
    {
      "x": -25,
      "y": 0,
      "z": 6,
      "name": "Soil_Grass"
    },
    {
      "x": -25,
      "y": 0,
      "z": 7,
      "name": "Soil_Grass"
    },
    {
      "x": -25,
      "y": 16,
      "z": 7,
      "name": "Deco_Bone_Full",
      "rotation": 1
    },
    {
      "x": -25,
      "y": 17,
      "z": 7,
      "name": "Deco_Bone_Full",
      "rotation": 1
    },
    {
      "x": -25,
      "y": 18,
      "z": 7,
      "name": "Soil_Hive_Corrupted",
      "rotation": 1
    },
    {
      "x": -25,
      "y": 19,
      "z": 7,
      "name": "Soil_Hive_Corrupted",
      "rotation": 1
    },
    {
      "x": -25,
      "y": 0,
      "z": 8,
      "name": "Soil_Grass"
    },
    {
      "x": -25,
      "y": 17,
      "z": 8,
      "name": "Deco_Bone_Full",
      "rotation": 1
    },
    {
      "x": -25,
      "y": 18,
      "z": 8,
      "name": "Deco_Bone_Full",
      "rotation": 1
    },
    {
      "x": -25,
      "y": 19,
      "z": 8,
      "name": "Soil_Hive_Corrupted",
      "rotation": 1
    },
    {
      "x": -25,
      "y": 20,
      "z": 8,
      "name": "Soil_Hive_Corrupted",
      "rotation": 1
    },
    {
      "x": -25,
      "y": 0,
      "z": 9,
      "name": "Soil_Grass"
    },
    {
      "x": -25,
      "y": 17,
      "z": 9,
      "name": "Deco_Bone_Full",
      "rotation": 1
    },
    {
      "x": -25,
      "y": 18,
      "z": 9,
      "name": "Deco_Bone_Full",
      "rotation": 1
    },
    {
      "x": -25,
      "y": 19,
      "z": 9,
      "name": "Deco_Bone_Full",
      "rotation": 1
    },
    {
      "x": -25,
      "y": 20,
      "z": 9,
      "name": "Deco_Bone_Full",
      "rotation": 1
    },
    {
      "x": -25,
      "y": 21,
      "z": 9,
      "name": "Soil_Hive_Corrupted",
      "rotation": 1
    },
    {
      "x": -25,
      "y": 22,
      "z": 9,
      "name": "Soil_Roots_Poisoned",
      "rotation": 1
    },
    {
      "x": -25,
      "y": 0,
      "z": 10,
      "name": "Soil_Grass"
    },
    {
      "x": -25,
      "y": 19,
      "z": 10,
      "name": "Deco_Bone_Full",
      "rotation": 1
    },
    {
      "x": -25,
      "y": 20,
      "z": 10,
      "name": "Deco_Bone_Full",
      "rotation": 1
    },
    {
      "x": -25,
      "y": 21,
      "z": 10,
      "name": "Deco_Bone_Full",
      "rotation": 1
    },
    {
      "x": -25,
      "y": 22,
      "z": 10,
      "name": "Soil_Roots_Poisoned",
      "rotation": 1
    },
    {
      "x": -25,
      "y": 23,
      "z": 10,
      "name": "Soil_Hive_Corrupted",
      "rotation": 1
    },
    {
      "x": -25,
      "y": 0,
      "z": 11,
      "name": "Soil_Grass"
    },
    {
      "x": -25,
      "y": 22,
      "z": 11,
      "name": "Soil_Hive_Corrupted",
      "rotation": 1
    },
    {
      "x": -25,
      "y": 23,
      "z": 11,
      "name": "Soil_Hive_Corrupted",
      "rotation": 1
    },
    {
      "x": -25,
      "y": 0,
      "z": 12,
      "name": "Soil_Grass"
    },
    {
      "x": -25,
      "y": 0,
      "z": 13,
      "name": "Soil_Grass"
    },
    {
      "x": -25,
      "y": 0,
      "z": 14,
      "name": "Soil_Grass"
    },
    {
      "x": -24,
      "y": 0,
      "z": -13,
      "name": "Soil_Grass"
    },
    {
      "x": -24,
      "y": 0,
      "z": -12,
      "name": "Soil_Grass"
    },
    {
      "x": -24,
      "y": 0,
      "z": -11,
      "name": "Soil_Grass"
    },
    {
      "x": -24,
      "y": 0,
      "z": -10,
      "name": "Soil_Grass"
    },
    {
      "x": -24,
      "y": 0,
      "z": -9,
      "name": "Soil_Grass"
    },
    {
      "x": -24,
      "y": 0,
      "z": -8,
      "name": "Soil_Grass"
    },
    {
      "x": -24,
      "y": 0,
      "z": -7,
      "name": "Soil_Grass"
    },
    {
      "x": -24,
      "y": 0,
      "z": -6,
      "name": "Soil_Grass"
    },
    {
      "x": -24,
      "y": 0,
      "z": -5,
      "name": "Soil_Grass"
    },
    {
      "x": -24,
      "y": 0,
      "z": -4,
      "name": "Soil_Grass"
    },
    {
      "x": -24,
      "y": 0,
      "z": -3,
      "name": "Soil_Grass"
    },
    {
      "x": -24,
      "y": 0,
      "z": -2,
      "name": "Soil_Grass"
    },
    {
      "x": -24,
      "y": 0,
      "z": -1,
      "name": "Soil_Grass"
    },
    {
      "x": -24,
      "y": 0,
      "z": 0,
      "name": "Soil_Grass"
    },
    {
      "x": -24,
      "y": 17,
      "z": 0,
      "name": "Soil_Hive_Corrupted",
      "rotation": 1
    },
    {
      "x": -24,
      "y": 18,
      "z": 0,
      "name": "Soil_Roots_Poisoned",
      "rotation": 1
    },
    {
      "x": -24,
      "y": 0,
      "z": 1,
      "name": "Soil_Grass"
    },
    {
      "x": -24,
      "y": 17,
      "z": 1,
      "name": "Deco_Bone_Full",
      "rotation": 1
    },
    {
      "x": -24,
      "y": 18,
      "z": 1,
      "name": "Deco_Bone_Full",
      "rotation": 1
    },
    {
      "x": -24,
      "y": 19,
      "z": 1,
      "name": "Deco_Bone_Full",
      "rotation": 1
    },
    {
      "x": -24,
      "y": 20,
      "z": 1,
      "name": "Deco_Bone_Full",
      "rotation": 1
    },
    {
      "x": -24,
      "y": 21,
      "z": 1,
      "name": "Soil_Roots_Poisoned",
      "rotation": 1
    },
    {
      "x": -24,
      "y": 22,
      "z": 1,
      "name": "Soil_Roots_Poisoned",
      "rotation": 1
    },
    {
      "x": -24,
      "y": 0,
      "z": 2,
      "name": "Soil_Grass"
    },
    {
      "x": -24,
      "y": 19,
      "z": 2,
      "name": "Deco_Bone_Full",
      "rotation": 1
    },
    {
      "x": -24,
      "y": 20,
      "z": 2,
      "name": "Deco_Bone_Full",
      "rotation": 1
    },
    {
      "x": -24,
      "y": 21,
      "z": 2,
      "name": "Deco_Bone_Full",
      "rotation": 1
    },
    {
      "x": -24,
      "y": 22,
      "z": 2,
      "name": "Deco_Bone_Full",
      "rotation": 1
    },
    {
      "x": -24,
      "y": 23,
      "z": 2,
      "name": "Deco_Bone_Full",
      "rotation": 1
    },
    {
      "x": -24,
      "y": 24,
      "z": 2,
      "name": "Deco_Bone_Full",
      "rotation": 1
    },
    {
      "x": -24,
      "y": 25,
      "z": 2,
      "name": "Deco_Bone_Full",
      "rotation": 1
    },
    {
      "x": -24,
      "y": 26,
      "z": 2,
      "name": "Deco_Bone_Full",
      "rotation": 1
    },
    {
      "x": -24,
      "y": 27,
      "z": 2,
      "name": "Deco_Bone_Full",
      "rotation": 1
    },
    {
      "x": -24,
      "y": 28,
      "z": 2,
      "name": "Soil_Roots_Poisoned",
      "rotation": 1
    },
    {
      "x": -24,
      "y": 29,
      "z": 2,
      "name": "Soil_Hive_Corrupted",
      "rotation": 1
    },
    {
      "x": -24,
      "y": 0,
      "z": 3,
      "name": "Soil_Grass"
    },
    {
      "x": -24,
      "y": 21,
      "z": 3,
      "name": "Deco_Bone_Full",
      "rotation": 1
    },
    {
      "x": -24,
      "y": 22,
      "z": 3,
      "name": "Deco_Bone_Full",
      "rotation": 1
    },
    {
      "x": -24,
      "y": 23,
      "z": 3,
      "name": "Deco_Bone_Full",
      "rotation": 1
    },
    {
      "x": -24,
      "y": 24,
      "z": 3,
      "name": "Deco_Bone_Full",
      "rotation": 1
    },
    {
      "x": -24,
      "y": 25,
      "z": 3,
      "name": "Deco_Bone_Full",
      "rotation": 1
    },
    {
      "x": -24,
      "y": 26,
      "z": 3,
      "name": "Deco_Bone_Full",
      "rotation": 1
    },
    {
      "x": -24,
      "y": 27,
      "z": 3,
      "name": "Deco_Bone_Full",
      "rotation": 1
    },
    {
      "x": -24,
      "y": 28,
      "z": 3,
      "name": "Soil_Hive_Corrupted",
      "rotation": 1
    },
    {
      "x": -24,
      "y": 29,
      "z": 3,
      "name": "Soil_Hive_Corrupted",
      "rotation": 1
    },
    {
      "x": -24,
      "y": 0,
      "z": 4,
      "name": "Soil_Grass"
    },
    {
      "x": -24,
      "y": 24,
      "z": 4,
      "name": "Deco_Bone_Full",
      "rotation": 1
    },
    {
      "x": -24,
      "y": 25,
      "z": 4,
      "name": "Deco_Bone_Full",
      "rotation": 1
    },
    {
      "x": -24,
      "y": 26,
      "z": 4,
      "name": "Deco_Bone_Full",
      "rotation": 1
    },
    {
      "x": -24,
      "y": 27,
      "z": 4,
      "name": "Deco_Bone_Full",
      "rotation": 1
    },
    {
      "x": -24,
      "y": 28,
      "z": 4,
      "name": "Soil_Hive_Corrupted",
      "rotation": 1
    },
    {
      "x": -24,
      "y": 29,
      "z": 4,
      "name": "Soil_Hive_Corrupted",
      "rotation": 1
    },
    {
      "x": -24,
      "y": 0,
      "z": 5,
      "name": "Soil_Grass"
    },
    {
      "x": -24,
      "y": 0,
      "z": 6,
      "name": "Soil_Grass"
    },
    {
      "x": -24,
      "y": 15,
      "z": 6,
      "name": "Soil_Hive_Corrupted",
      "rotation": 1
    },
    {
      "x": -24,
      "y": 0,
      "z": 7,
      "name": "Soil_Grass"
    },
    {
      "x": -24,
      "y": 15,
      "z": 7,
      "name": "Deco_Bone_Full",
      "rotation": 1
    },
    {
      "x": -24,
      "y": 16,
      "z": 7,
      "name": "Deco_Bone_Full",
      "rotation": 1
    },
    {
      "x": -24,
      "y": 17,
      "z": 7,
      "name": "Soil_Roots_Poisoned",
      "rotation": 1
    },
    {
      "x": -24,
      "y": 18,
      "z": 7,
      "name": "Soil_Hive_Corrupted",
      "rotation": 1
    },
    {
      "x": -24,
      "y": 0,
      "z": 8,
      "name": "Soil_Grass"
    },
    {
      "x": -24,
      "y": 15,
      "z": 8,
      "name": "Deco_Bone_Full",
      "rotation": 1
    },
    {
      "x": -24,
      "y": 16,
      "z": 8,
      "name": "Deco_Bone_Full",
      "rotation": 1
    },
    {
      "x": -24,
      "y": 17,
      "z": 8,
      "name": "Deco_Bone_Full",
      "rotation": 1
    },
    {
      "x": -24,
      "y": 18,
      "z": 8,
      "name": "Soil_Hive_Corrupted",
      "rotation": 1
    },
    {
      "x": -24,
      "y": 19,
      "z": 8,
      "name": "Soil_Hive_Corrupted",
      "rotation": 1
    },
    {
      "x": -24,
      "y": 0,
      "z": 9,
      "name": "Soil_Grass"
    },
    {
      "x": -24,
      "y": 16,
      "z": 9,
      "name": "Deco_Bone_Full",
      "rotation": 1
    },
    {
      "x": -24,
      "y": 17,
      "z": 9,
      "name": "Deco_Bone_Full",
      "rotation": 1
    },
    {
      "x": -24,
      "y": 18,
      "z": 9,
      "name": "Deco_Bone_Full",
      "rotation": 1
    },
    {
      "x": -24,
      "y": 19,
      "z": 9,
      "name": "Soil_Roots_Poisoned",
      "rotation": 1
    },
    {
      "x": -24,
      "y": 20,
      "z": 9,
      "name": "Soil_Hive_Corrupted",
      "rotation": 1
    },
    {
      "x": -24,
      "y": 0,
      "z": 10,
      "name": "Soil_Grass"
    },
    {
      "x": -24,
      "y": 18,
      "z": 10,
      "name": "Deco_Bone_Full",
      "rotation": 1
    },
    {
      "x": -24,
      "y": 19,
      "z": 10,
      "name": "Deco_Bone_Full",
      "rotation": 1
    },
    {
      "x": -24,
      "y": 20,
      "z": 10,
      "name": "Soil_Hive_Corrupted",
      "rotation": 1
    },
    {
      "x": -24,
      "y": 21,
      "z": 10,
      "name": "Soil_Hive_Corrupted",
      "rotation": 1
    },
    {
      "x": -24,
      "y": 0,
      "z": 11,
      "name": "Soil_Grass"
    },
    {
      "x": -24,
      "y": 0,
      "z": 12,
      "name": "Soil_Grass"
    },
    {
      "x": -24,
      "y": 0,
      "z": 13,
      "name": "Soil_Grass"
    },
    {
      "x": -24,
      "y": 0,
      "z": 14,
      "name": "Soil_Grass"
    },
    {
      "x": -23,
      "y": 0,
      "z": -13,
      "name": "Soil_Grass"
    },
    {
      "x": -23,
      "y": 0,
      "z": -12,
      "name": "Soil_Grass"
    },
    {
      "x": -23,
      "y": 0,
      "z": -11,
      "name": "Soil_Grass"
    },
    {
      "x": -23,
      "y": 0,
      "z": -10,
      "name": "Soil_Grass"
    },
    {
      "x": -23,
      "y": 0,
      "z": -9,
      "name": "Soil_Grass"
    },
    {
      "x": -23,
      "y": 0,
      "z": -8,
      "name": "Soil_Grass"
    },
    {
      "x": -23,
      "y": 0,
      "z": -7,
      "name": "Soil_Grass"
    },
    {
      "x": -23,
      "y": 0,
      "z": -6,
      "name": "Soil_Grass"
    },
    {
      "x": -23,
      "y": 0,
      "z": -5,
      "name": "Soil_Grass"
    },
    {
      "x": -23,
      "y": 0,
      "z": -4,
      "name": "Soil_Grass"
    },
    {
      "x": -23,
      "y": 0,
      "z": -3,
      "name": "Soil_Grass"
    },
    {
      "x": -23,
      "y": 0,
      "z": -2,
      "name": "Soil_Grass"
    },
    {
      "x": -23,
      "y": 0,
      "z": -1,
      "name": "Soil_Grass"
    },
    {
      "x": -23,
      "y": 15,
      "z": -1,
      "name": "Soil_Hive_Corrupted",
      "rotation": 1
    },
    {
      "x": -23,
      "y": 0,
      "z": 0,
      "name": "Soil_Grass"
    },
    {
      "x": -23,
      "y": 15,
      "z": 0,
      "name": "Deco_Bone_Full",
      "rotation": 1
    },
    {
      "x": -23,
      "y": 16,
      "z": 0,
      "name": "Deco_Bone_Full",
      "rotation": 1
    },
    {
      "x": -23,
      "y": 17,
      "z": 0,
      "name": "Deco_Bone_Full",
      "rotation": 1
    },
    {
      "x": -23,
      "y": 18,
      "z": 0,
      "name": "Soil_Roots_Poisoned",
      "rotation": 1
    },
    {
      "x": -23,
      "y": 19,
      "z": 0,
      "name": "Soil_Hive_Corrupted",
      "rotation": 1
    },
    {
      "x": -23,
      "y": 0,
      "z": 1,
      "name": "Soil_Grass"
    },
    {
      "x": -23,
      "y": 15,
      "z": 1,
      "name": "Deco_Bone_Full",
      "rotation": 1
    },
    {
      "x": -23,
      "y": 16,
      "z": 1,
      "name": "Deco_Bone_Full",
      "rotation": 1
    },
    {
      "x": -23,
      "y": 17,
      "z": 1,
      "name": "Deco_Bone_Full",
      "rotation": 1
    },
    {
      "x": -23,
      "y": 18,
      "z": 1,
      "name": "Deco_Bone_Full",
      "rotation": 1
    },
    {
      "x": -23,
      "y": 19,
      "z": 1,
      "name": "Deco_Bone_Full",
      "rotation": 1
    },
    {
      "x": -23,
      "y": 20,
      "z": 1,
      "name": "Soil_Roots_Poisoned",
      "rotation": 1
    },
    {
      "x": -23,
      "y": 21,
      "z": 1,
      "name": "Soil_Roots_Poisoned",
      "rotation": 1
    },
    {
      "x": -23,
      "y": 0,
      "z": 2,
      "name": "Soil_Grass"
    },
    {
      "x": -23,
      "y": 17,
      "z": 2,
      "name": "Deco_Bone_Full",
      "rotation": 1
    },
    {
      "x": -23,
      "y": 18,
      "z": 2,
      "name": "Deco_Bone_Full",
      "rotation": 1
    },
    {
      "x": -23,
      "y": 19,
      "z": 2,
      "name": "Deco_Bone_Full",
      "rotation": 1
    },
    {
      "x": -23,
      "y": 20,
      "z": 2,
      "name": "Deco_Bone_Full",
      "rotation": 1
    },
    {
      "x": -23,
      "y": 21,
      "z": 2,
      "name": "Deco_Bone_Full",
      "rotation": 1
    },
    {
      "x": -23,
      "y": 22,
      "z": 2,
      "name": "Deco_Bone_Full",
      "rotation": 1
    },
    {
      "x": -23,
      "y": 23,
      "z": 2,
      "name": "Soil_Roots_Poisoned",
      "rotation": 1
    },
    {
      "x": -23,
      "y": 24,
      "z": 2,
      "name": "Soil_Hive_Corrupted",
      "rotation": 1
    },
    {
      "x": -23,
      "y": 27,
      "z": 2,
      "name": "Soil_Hive_Corrupted",
      "rotation": 1
    },
    {
      "x": -23,
      "y": 28,
      "z": 2,
      "name": "Soil_Roots_Poisoned",
      "rotation": 1
    },
    {
      "x": -23,
      "y": 0,
      "z": 3,
      "name": "Soil_Grass"
    },
    {
      "x": -23,
      "y": 20,
      "z": 3,
      "name": "Deco_Bone_Full",
      "rotation": 1
    },
    {
      "x": -23,
      "y": 21,
      "z": 3,
      "name": "Deco_Bone_Full",
      "rotation": 1
    },
    {
      "x": -23,
      "y": 22,
      "z": 3,
      "name": "Deco_Bone_Full",
      "rotation": 1
    },
    {
      "x": -23,
      "y": 23,
      "z": 3,
      "name": "Deco_Bone_Full",
      "rotation": 1
    },
    {
      "x": -23,
      "y": 24,
      "z": 3,
      "name": "Deco_Bone_Full",
      "rotation": 1
    },
    {
      "x": -23,
      "y": 25,
      "z": 3,
      "name": "Deco_Bone_Full",
      "rotation": 1
    },
    {
      "x": -23,
      "y": 26,
      "z": 3,
      "name": "Deco_Bone_Full",
      "rotation": 1
    },
    {
      "x": -23,
      "y": 27,
      "z": 3,
      "name": "Deco_Bone_Full",
      "rotation": 1
    },
    {
      "x": -23,
      "y": 28,
      "z": 3,
      "name": "Soil_Roots_Poisoned",
      "rotation": 1
    },
    {
      "x": -23,
      "y": 29,
      "z": 3,
      "name": "Soil_Hive_Corrupted",
      "rotation": 1
    },
    {
      "x": -23,
      "y": 0,
      "z": 4,
      "name": "Soil_Grass"
    },
    {
      "x": -23,
      "y": 26,
      "z": 4,
      "name": "Deco_Bone_Full",
      "rotation": 1
    },
    {
      "x": -23,
      "y": 27,
      "z": 4,
      "name": "Deco_Bone_Full",
      "rotation": 1
    },
    {
      "x": -23,
      "y": 28,
      "z": 4,
      "name": "Soil_Roots_Poisoned",
      "rotation": 1
    },
    {
      "x": -23,
      "y": 29,
      "z": 4,
      "name": "Soil_Roots_Poisoned",
      "rotation": 1
    },
    {
      "x": -23,
      "y": 0,
      "z": 5,
      "name": "Soil_Grass"
    },
    {
      "x": -23,
      "y": 0,
      "z": 6,
      "name": "Soil_Grass"
    },
    {
      "x": -23,
      "y": 14,
      "z": 6,
      "name": "Deco_Bone_Full",
      "rotation": 1
    },
    {
      "x": -23,
      "y": 15,
      "z": 6,
      "name": "Soil_Roots_Poisoned",
      "rotation": 1
    },
    {
      "x": -23,
      "y": 16,
      "z": 6,
      "name": "Soil_Hive_Corrupted",
      "rotation": 1
    },
    {
      "x": -23,
      "y": 0,
      "z": 7,
      "name": "Soil_Grass"
    },
    {
      "x": -23,
      "y": 14,
      "z": 7,
      "name": "Deco_Bone_Full",
      "rotation": 1
    },
    {
      "x": -23,
      "y": 15,
      "z": 7,
      "name": "Deco_Bone_Full",
      "rotation": 1
    },
    {
      "x": -23,
      "y": 16,
      "z": 7,
      "name": "Soil_Roots_Poisoned",
      "rotation": 1
    },
    {
      "x": -23,
      "y": 17,
      "z": 7,
      "name": "Soil_Hive_Corrupted",
      "rotation": 1
    },
    {
      "x": -23,
      "y": 0,
      "z": 8,
      "name": "Soil_Grass"
    },
    {
      "x": -23,
      "y": 14,
      "z": 8,
      "name": "Deco_Bone_Full",
      "rotation": 1
    },
    {
      "x": -23,
      "y": 15,
      "z": 8,
      "name": "Deco_Bone_Full",
      "rotation": 1
    },
    {
      "x": -23,
      "y": 16,
      "z": 8,
      "name": "Deco_Bone_Full",
      "rotation": 1
    },
    {
      "x": -23,
      "y": 17,
      "z": 8,
      "name": "Soil_Hive_Corrupted",
      "rotation": 1
    },
    {
      "x": -23,
      "y": 18,
      "z": 8,
      "name": "Soil_Roots_Poisoned",
      "rotation": 1
    },
    {
      "x": -23,
      "y": 0,
      "z": 9,
      "name": "Soil_Grass"
    },
    {
      "x": -23,
      "y": 15,
      "z": 9,
      "name": "Deco_Bone_Full",
      "rotation": 1
    },
    {
      "x": -23,
      "y": 16,
      "z": 9,
      "name": "Deco_Bone_Full",
      "rotation": 1
    },
    {
      "x": -23,
      "y": 17,
      "z": 9,
      "name": "Deco_Bone_Full",
      "rotation": 1
    },
    {
      "x": -23,
      "y": 18,
      "z": 9,
      "name": "Soil_Hive_Corrupted",
      "rotation": 1
    },
    {
      "x": -23,
      "y": 19,
      "z": 9,
      "name": "Soil_Hive_Corrupted",
      "rotation": 1
    },
    {
      "x": -23,
      "y": 0,
      "z": 10,
      "name": "Soil_Grass"
    },
    {
      "x": -23,
      "y": 17,
      "z": 10,
      "name": "Deco_Bone_Full",
      "rotation": 1
    },
    {
      "x": -23,
      "y": 18,
      "z": 10,
      "name": "Soil_Hive_Corrupted",
      "rotation": 1
    },
    {
      "x": -23,
      "y": 19,
      "z": 10,
      "name": "Soil_Roots_Poisoned",
      "rotation": 1
    },
    {
      "x": -23,
      "y": 0,
      "z": 11,
      "name": "Soil_Grass"
    },
    {
      "x": -23,
      "y": 0,
      "z": 12,
      "name": "Soil_Grass"
    },
    {
      "x": -23,
      "y": 0,
      "z": 13,
      "name": "Soil_Grass"
    },
    {
      "x": -23,
      "y": 0,
      "z": 14,
      "name": "Soil_Grass"
    },
    {
      "x": -22,
      "y": 0,
      "z": -13,
      "name": "Soil_Grass"
    },
    {
      "x": -22,
      "y": 0,
      "z": -12,
      "name": "Soil_Grass"
    },
    {
      "x": -22,
      "y": 0,
      "z": -11,
      "name": "Soil_Grass"
    },
    {
      "x": -22,
      "y": 0,
      "z": -10,
      "name": "Soil_Grass"
    },
    {
      "x": -22,
      "y": 0,
      "z": -9,
      "name": "Soil_Grass"
    },
    {
      "x": -22,
      "y": 0,
      "z": -8,
      "name": "Soil_Grass"
    },
    {
      "x": -22,
      "y": 0,
      "z": -7,
      "name": "Soil_Grass"
    },
    {
      "x": -22,
      "y": 0,
      "z": -6,
      "name": "Soil_Grass"
    },
    {
      "x": -22,
      "y": 0,
      "z": -5,
      "name": "Soil_Grass"
    },
    {
      "x": -22,
      "y": 0,
      "z": -4,
      "name": "Soil_Grass"
    },
    {
      "x": -22,
      "y": 0,
      "z": -3,
      "name": "Soil_Grass"
    },
    {
      "x": -22,
      "y": 0,
      "z": -2,
      "name": "Soil_Grass"
    },
    {
      "x": -22,
      "y": 0,
      "z": -1,
      "name": "Soil_Grass"
    },
    {
      "x": -22,
      "y": 13,
      "z": -1,
      "name": "Deco_Bone_Full",
      "rotation": 1
    },
    {
      "x": -22,
      "y": 14,
      "z": -1,
      "name": "Soil_Roots_Poisoned",
      "rotation": 1
    },
    {
      "x": -22,
      "y": 15,
      "z": -1,
      "name": "Soil_Hive_Corrupted",
      "rotation": 1
    },
    {
      "x": -22,
      "y": 0,
      "z": 0,
      "name": "Soil_Grass"
    },
    {
      "x": -22,
      "y": 13,
      "z": 0,
      "name": "Deco_Bone_Full",
      "rotation": 1
    },
    {
      "x": -22,
      "y": 14,
      "z": 0,
      "name": "Deco_Bone_Full",
      "rotation": 1
    },
    {
      "x": -22,
      "y": 15,
      "z": 0,
      "name": "Deco_Bone_Full",
      "rotation": 1
    },
    {
      "x": -22,
      "y": 16,
      "z": 0,
      "name": "Soil_Roots_Poisoned",
      "rotation": 1
    },
    {
      "x": -22,
      "y": 17,
      "z": 0,
      "name": "Soil_Hive_Corrupted",
      "rotation": 1
    },
    {
      "x": -22,
      "y": 0,
      "z": 1,
      "name": "Soil_Grass"
    },
    {
      "x": -22,
      "y": 14,
      "z": 1,
      "name": "Deco_Bone_Full",
      "rotation": 1
    },
    {
      "x": -22,
      "y": 15,
      "z": 1,
      "name": "Deco_Bone_Full",
      "rotation": 1
    },
    {
      "x": -22,
      "y": 16,
      "z": 1,
      "name": "Deco_Bone_Full",
      "rotation": 1
    },
    {
      "x": -22,
      "y": 17,
      "z": 1,
      "name": "Deco_Bone_Full",
      "rotation": 1
    },
    {
      "x": -22,
      "y": 18,
      "z": 1,
      "name": "Soil_Roots_Poisoned",
      "rotation": 1
    },
    {
      "x": -22,
      "y": 19,
      "z": 1,
      "name": "Soil_Hive_Corrupted",
      "rotation": 1
    },
    {
      "x": -22,
      "y": 0,
      "z": 2,
      "name": "Soil_Grass"
    },
    {
      "x": -22,
      "y": 15,
      "z": 2,
      "name": "Deco_Bone_Full",
      "rotation": 1
    },
    {
      "x": -22,
      "y": 16,
      "z": 2,
      "name": "Deco_Bone_Full",
      "rotation": 1
    },
    {
      "x": -22,
      "y": 17,
      "z": 2,
      "name": "Deco_Bone_Full",
      "rotation": 1
    },
    {
      "x": -22,
      "y": 18,
      "z": 2,
      "name": "Deco_Bone_Full",
      "rotation": 1
    },
    {
      "x": -22,
      "y": 19,
      "z": 2,
      "name": "Soil_Roots_Poisoned",
      "rotation": 1
    },
    {
      "x": -22,
      "y": 20,
      "z": 2,
      "name": "Soil_Roots_Poisoned",
      "rotation": 1
    },
    {
      "x": -22,
      "y": 0,
      "z": 3,
      "name": "Soil_Grass"
    },
    {
      "x": -22,
      "y": 18,
      "z": 3,
      "name": "Soil_Hive_Corrupted",
      "rotation": 1
    },
    {
      "x": -22,
      "y": 20,
      "z": 3,
      "name": "Soil_Hive_Corrupted",
      "rotation": 1
    },
    {
      "x": -22,
      "y": 0,
      "z": 4,
      "name": "Soil_Grass"
    },
    {
      "x": -22,
      "y": 0,
      "z": 5,
      "name": "Soil_Grass"
    },
    {
      "x": -22,
      "y": 0,
      "z": 6,
      "name": "Soil_Grass"
    },
    {
      "x": -22,
      "y": 13,
      "z": 6,
      "name": "Deco_Bone_Full",
      "rotation": 1
    },
    {
      "x": -22,
      "y": 14,
      "z": 6,
      "name": "Soil_Hive_Corrupted",
      "rotation": 1
    },
    {
      "x": -22,
      "y": 15,
      "z": 6,
      "name": "Soil_Roots_Poisoned",
      "rotation": 1
    },
    {
      "x": -22,
      "y": 0,
      "z": 7,
      "name": "Soil_Grass"
    },
    {
      "x": -22,
      "y": 13,
      "z": 7,
      "name": "Deco_Bone_Full",
      "rotation": 1
    },
    {
      "x": -22,
      "y": 14,
      "z": 7,
      "name": "Deco_Bone_Full",
      "rotation": 1
    },
    {
      "x": -22,
      "y": 15,
      "z": 7,
      "name": "Soil_Roots_Poisoned",
      "rotation": 1
    },
    {
      "x": -22,
      "y": 16,
      "z": 7,
      "name": "Soil_Hive_Corrupted",
      "rotation": 1
    },
    {
      "x": -22,
      "y": 0,
      "z": 8,
      "name": "Soil_Grass"
    },
    {
      "x": -22,
      "y": 13,
      "z": 8,
      "name": "Deco_Bone_Full",
      "rotation": 1
    },
    {
      "x": -22,
      "y": 14,
      "z": 8,
      "name": "Deco_Bone_Full",
      "rotation": 1
    },
    {
      "x": -22,
      "y": 15,
      "z": 8,
      "name": "Deco_Bone_Full",
      "rotation": 1
    },
    {
      "x": -22,
      "y": 16,
      "z": 8,
      "name": "Soil_Roots_Poisoned",
      "rotation": 1
    },
    {
      "x": -22,
      "y": 17,
      "z": 8,
      "name": "Soil_Roots_Poisoned",
      "rotation": 1
    },
    {
      "x": -22,
      "y": 0,
      "z": 9,
      "name": "Soil_Grass"
    },
    {
      "x": -22,
      "y": 14,
      "z": 9,
      "name": "Deco_Bone_Full",
      "rotation": 1
    },
    {
      "x": -22,
      "y": 15,
      "z": 9,
      "name": "Deco_Bone_Full",
      "rotation": 1
    },
    {
      "x": -22,
      "y": 16,
      "z": 9,
      "name": "Deco_Bone_Full",
      "rotation": 1
    },
    {
      "x": -22,
      "y": 17,
      "z": 9,
      "name": "Soil_Roots_Poisoned",
      "rotation": 1
    },
    {
      "x": -22,
      "y": 18,
      "z": 9,
      "name": "Soil_Roots_Poisoned",
      "rotation": 1
    },
    {
      "x": -22,
      "y": 0,
      "z": 10,
      "name": "Soil_Grass"
    },
    {
      "x": -22,
      "y": 0,
      "z": 11,
      "name": "Soil_Grass"
    },
    {
      "x": -22,
      "y": 0,
      "z": 12,
      "name": "Soil_Grass"
    },
    {
      "x": -22,
      "y": 0,
      "z": 13,
      "name": "Soil_Grass"
    },
    {
      "x": -22,
      "y": 0,
      "z": 14,
      "name": "Soil_Grass"
    },
    {
      "x": -21,
      "y": 0,
      "z": -13,
      "name": "Soil_Grass"
    },
    {
      "x": -21,
      "y": 0,
      "z": -12,
      "name": "Soil_Grass"
    },
    {
      "x": -21,
      "y": 0,
      "z": -11,
      "name": "Soil_Grass"
    },
    {
      "x": -21,
      "y": 0,
      "z": -10,
      "name": "Soil_Grass"
    },
    {
      "x": -21,
      "y": 0,
      "z": -9,
      "name": "Soil_Grass"
    },
    {
      "x": -21,
      "y": 0,
      "z": -8,
      "name": "Soil_Grass"
    },
    {
      "x": -21,
      "y": 0,
      "z": -7,
      "name": "Soil_Grass"
    },
    {
      "x": -21,
      "y": 0,
      "z": -6,
      "name": "Soil_Grass"
    },
    {
      "x": -21,
      "y": 0,
      "z": -5,
      "name": "Soil_Grass"
    },
    {
      "x": -21,
      "y": 0,
      "z": -4,
      "name": "Soil_Grass"
    },
    {
      "x": -21,
      "y": 0,
      "z": -3,
      "name": "Soil_Grass"
    },
    {
      "x": -21,
      "y": 0,
      "z": -2,
      "name": "Soil_Grass"
    },
    {
      "x": -21,
      "y": 0,
      "z": -1,
      "name": "Soil_Grass"
    },
    {
      "x": -21,
      "y": 12,
      "z": -1,
      "name": "Deco_Bone_Full",
      "rotation": 1
    },
    {
      "x": -21,
      "y": 13,
      "z": -1,
      "name": "Soil_Roots_Poisoned",
      "rotation": 1
    },
    {
      "x": -21,
      "y": 14,
      "z": -1,
      "name": "Soil_Roots_Poisoned",
      "rotation": 1
    },
    {
      "x": -21,
      "y": 0,
      "z": 0,
      "name": "Soil_Grass"
    },
    {
      "x": -21,
      "y": 12,
      "z": 0,
      "name": "Deco_Bone_Full",
      "rotation": 1
    },
    {
      "x": -21,
      "y": 13,
      "z": 0,
      "name": "Deco_Bone_Full",
      "rotation": 1
    },
    {
      "x": -21,
      "y": 14,
      "z": 0,
      "name": "Deco_Bone_Full",
      "rotation": 1
    },
    {
      "x": -21,
      "y": 15,
      "z": 0,
      "name": "Soil_Roots_Poisoned",
      "rotation": 1
    },
    {
      "x": -21,
      "y": 16,
      "z": 0,
      "name": "Soil_Hive_Corrupted",
      "rotation": 1
    },
    {
      "x": -21,
      "y": 0,
      "z": 1,
      "name": "Soil_Grass"
    },
    {
      "x": -21,
      "y": 13,
      "z": 1,
      "name": "Deco_Bone_Full",
      "rotation": 1
    },
    {
      "x": -21,
      "y": 14,
      "z": 1,
      "name": "Deco_Bone_Full",
      "rotation": 1
    },
    {
      "x": -21,
      "y": 15,
      "z": 1,
      "name": "Deco_Bone_Full",
      "rotation": 1
    },
    {
      "x": -21,
      "y": 16,
      "z": 1,
      "name": "Soil_Roots_Poisoned",
      "rotation": 1
    },
    {
      "x": -21,
      "y": 17,
      "z": 1,
      "name": "Soil_Hive_Corrupted",
      "rotation": 1
    },
    {
      "x": -21,
      "y": 0,
      "z": 2,
      "name": "Soil_Grass"
    },
    {
      "x": -21,
      "y": 14,
      "z": 2,
      "name": "Deco_Bone_Full",
      "rotation": 1
    },
    {
      "x": -21,
      "y": 15,
      "z": 2,
      "name": "Deco_Bone_Full",
      "rotation": 1
    },
    {
      "x": -21,
      "y": 16,
      "z": 2,
      "name": "Deco_Bone_Full",
      "rotation": 1
    },
    {
      "x": -21,
      "y": 17,
      "z": 2,
      "name": "Soil_Hive_Corrupted",
      "rotation": 1
    },
    {
      "x": -21,
      "y": 18,
      "z": 2,
      "name": "Soil_Roots_Poisoned",
      "rotation": 1
    },
    {
      "x": -21,
      "y": 0,
      "z": 3,
      "name": "Soil_Grass"
    },
    {
      "x": -21,
      "y": 0,
      "z": 4,
      "name": "Soil_Grass"
    },
    {
      "x": -21,
      "y": 0,
      "z": 5,
      "name": "Soil_Grass"
    },
    {
      "x": -21,
      "y": 0,
      "z": 6,
      "name": "Soil_Grass"
    },
    {
      "x": -21,
      "y": 12,
      "z": 6,
      "name": "Deco_Bone_Full",
      "rotation": 1
    },
    {
      "x": -21,
      "y": 13,
      "z": 6,
      "name": "Soil_Hive_Corrupted",
      "rotation": 1
    },
    {
      "x": -21,
      "y": 14,
      "z": 6,
      "name": "Soil_Roots_Poisoned",
      "rotation": 1
    },
    {
      "x": -21,
      "y": 0,
      "z": 7,
      "name": "Soil_Grass"
    },
    {
      "x": -21,
      "y": 12,
      "z": 7,
      "name": "Deco_Bone_Full",
      "rotation": 1
    },
    {
      "x": -21,
      "y": 13,
      "z": 7,
      "name": "Deco_Bone_Full",
      "rotation": 1
    },
    {
      "x": -21,
      "y": 14,
      "z": 7,
      "name": "Soil_Roots_Poisoned",
      "rotation": 1
    },
    {
      "x": -21,
      "y": 15,
      "z": 7,
      "name": "Soil_Roots_Poisoned",
      "rotation": 1
    },
    {
      "x": -21,
      "y": 0,
      "z": 8,
      "name": "Soil_Grass"
    },
    {
      "x": -21,
      "y": 12,
      "z": 8,
      "name": "Deco_Bone_Full",
      "rotation": 1
    },
    {
      "x": -21,
      "y": 13,
      "z": 8,
      "name": "Deco_Bone_Full",
      "rotation": 1
    },
    {
      "x": -21,
      "y": 14,
      "z": 8,
      "name": "Deco_Bone_Full",
      "rotation": 1
    },
    {
      "x": -21,
      "y": 15,
      "z": 8,
      "name": "Soil_Hive_Corrupted",
      "rotation": 1
    },
    {
      "x": -21,
      "y": 16,
      "z": 8,
      "name": "Soil_Hive_Corrupted",
      "rotation": 1
    },
    {
      "x": -21,
      "y": 0,
      "z": 9,
      "name": "Soil_Grass"
    },
    {
      "x": -21,
      "y": 14,
      "z": 9,
      "name": "Deco_Bone_Full",
      "rotation": 1
    },
    {
      "x": -21,
      "y": 15,
      "z": 9,
      "name": "Deco_Bone_Full",
      "rotation": 1
    },
    {
      "x": -21,
      "y": 16,
      "z": 9,
      "name": "Soil_Roots_Poisoned",
      "rotation": 1
    },
    {
      "x": -21,
      "y": 17,
      "z": 9,
      "name": "Soil_Roots_Poisoned",
      "rotation": 1
    },
    {
      "x": -21,
      "y": 0,
      "z": 10,
      "name": "Soil_Grass"
    },
    {
      "x": -21,
      "y": 0,
      "z": 11,
      "name": "Soil_Grass"
    },
    {
      "x": -21,
      "y": 0,
      "z": 12,
      "name": "Soil_Grass"
    },
    {
      "x": -21,
      "y": 0,
      "z": 13,
      "name": "Soil_Grass"
    },
    {
      "x": -21,
      "y": 0,
      "z": 14,
      "name": "Soil_Grass"
    },
    {
      "x": -20,
      "y": 0,
      "z": -13,
      "name": "Soil_Grass"
    },
    {
      "x": -20,
      "y": 0,
      "z": -12,
      "name": "Soil_Grass"
    },
    {
      "x": -20,
      "y": 0,
      "z": -11,
      "name": "Soil_Grass"
    },
    {
      "x": -20,
      "y": 0,
      "z": -10,
      "name": "Soil_Grass"
    },
    {
      "x": -20,
      "y": 0,
      "z": -9,
      "name": "Soil_Grass"
    },
    {
      "x": -20,
      "y": 0,
      "z": -8,
      "name": "Soil_Grass"
    },
    {
      "x": -20,
      "y": 0,
      "z": -7,
      "name": "Soil_Grass"
    },
    {
      "x": -20,
      "y": 0,
      "z": -6,
      "name": "Soil_Grass"
    },
    {
      "x": -20,
      "y": 0,
      "z": -5,
      "name": "Soil_Grass"
    },
    {
      "x": -20,
      "y": 0,
      "z": -4,
      "name": "Soil_Grass"
    },
    {
      "x": -20,
      "y": 0,
      "z": -3,
      "name": "Soil_Grass"
    },
    {
      "x": -20,
      "y": 0,
      "z": -2,
      "name": "Soil_Grass"
    },
    {
      "x": -20,
      "y": 0,
      "z": -1,
      "name": "Soil_Grass"
    },
    {
      "x": -20,
      "y": 11,
      "z": -1,
      "name": "Deco_Bone_Full",
      "rotation": 1
    },
    {
      "x": -20,
      "y": 12,
      "z": -1,
      "name": "Soil_Roots_Poisoned",
      "rotation": 1
    },
    {
      "x": -20,
      "y": 13,
      "z": -1,
      "name": "Soil_Roots_Poisoned",
      "rotation": 1
    },
    {
      "x": -20,
      "y": 0,
      "z": 0,
      "name": "Soil_Grass"
    },
    {
      "x": -20,
      "y": 11,
      "z": 0,
      "name": "Deco_Bone_Full",
      "rotation": 1
    },
    {
      "x": -20,
      "y": 12,
      "z": 0,
      "name": "Deco_Bone_Full",
      "rotation": 1
    },
    {
      "x": -20,
      "y": 13,
      "z": 0,
      "name": "Deco_Bone_Full",
      "rotation": 1
    },
    {
      "x": -20,
      "y": 14,
      "z": 0,
      "name": "Soil_Roots_Poisoned",
      "rotation": 1
    },
    {
      "x": -20,
      "y": 15,
      "z": 0,
      "name": "Soil_Hive_Corrupted",
      "rotation": 1
    },
    {
      "x": -20,
      "y": 0,
      "z": 1,
      "name": "Soil_Grass"
    },
    {
      "x": -20,
      "y": 12,
      "z": 1,
      "name": "Deco_Bone_Full",
      "rotation": 1
    },
    {
      "x": -20,
      "y": 13,
      "z": 1,
      "name": "Deco_Bone_Full",
      "rotation": 1
    },
    {
      "x": -20,
      "y": 14,
      "z": 1,
      "name": "Deco_Bone_Full",
      "rotation": 1
    },
    {
      "x": -20,
      "y": 15,
      "z": 1,
      "name": "Soil_Roots_Poisoned",
      "rotation": 1
    },
    {
      "x": -20,
      "y": 16,
      "z": 1,
      "name": "Soil_Roots_Poisoned",
      "rotation": 1
    },
    {
      "x": -20,
      "y": 0,
      "z": 2,
      "name": "Soil_Grass"
    },
    {
      "x": -20,
      "y": 13,
      "z": 2,
      "name": "Deco_Bone_Full",
      "rotation": 1
    },
    {
      "x": -20,
      "y": 14,
      "z": 2,
      "name": "Deco_Bone_Full",
      "rotation": 1
    },
    {
      "x": -20,
      "y": 15,
      "z": 2,
      "name": "Soil_Roots_Poisoned",
      "rotation": 1
    },
    {
      "x": -20,
      "y": 16,
      "z": 2,
      "name": "Soil_Roots_Poisoned",
      "rotation": 1
    },
    {
      "x": -20,
      "y": 0,
      "z": 3,
      "name": "Soil_Grass"
    },
    {
      "x": -20,
      "y": 0,
      "z": 4,
      "name": "Soil_Grass"
    },
    {
      "x": -20,
      "y": 0,
      "z": 5,
      "name": "Soil_Grass"
    },
    {
      "x": -20,
      "y": 11,
      "z": 5,
      "name": "Soil_Hive_Corrupted",
      "rotation": 1
    },
    {
      "x": -20,
      "y": 12,
      "z": 5,
      "name": "Soil_Roots_Poisoned",
      "rotation": 1
    },
    {
      "x": -20,
      "y": 0,
      "z": 6,
      "name": "Soil_Grass"
    },
    {
      "x": -20,
      "y": 11,
      "z": 6,
      "name": "Deco_Bone_Full",
      "rotation": 1
    },
    {
      "x": -20,
      "y": 12,
      "z": 6,
      "name": "Soil_Roots_Poisoned",
      "rotation": 1
    },
    {
      "x": -20,
      "y": 13,
      "z": 6,
      "name": "Soil_Hive_Corrupted",
      "rotation": 1
    },
    {
      "x": -20,
      "y": 0,
      "z": 7,
      "name": "Soil_Grass"
    },
    {
      "x": -20,
      "y": 11,
      "z": 7,
      "name": "Deco_Bone_Full",
      "rotation": 1
    },
    {
      "x": -20,
      "y": 12,
      "z": 7,
      "name": "Deco_Bone_Full",
      "rotation": 1
    },
    {
      "x": -20,
      "y": 13,
      "z": 7,
      "name": "Soil_Roots_Poisoned",
      "rotation": 1
    },
    {
      "x": -20,
      "y": 14,
      "z": 7,
      "name": "Soil_Hive_Corrupted",
      "rotation": 1
    },
    {
      "x": -20,
      "y": 0,
      "z": 8,
      "name": "Soil_Grass"
    },
    {
      "x": -20,
      "y": 12,
      "z": 8,
      "name": "Deco_Bone_Full",
      "rotation": 1
    },
    {
      "x": -20,
      "y": 13,
      "z": 8,
      "name": "Deco_Bone_Full",
      "rotation": 1
    },
    {
      "x": -20,
      "y": 14,
      "z": 8,
      "name": "Soil_Roots_Poisoned",
      "rotation": 1
    },
    {
      "x": -20,
      "y": 15,
      "z": 8,
      "name": "Soil_Hive_Corrupted",
      "rotation": 1
    },
    {
      "x": -20,
      "y": 0,
      "z": 9,
      "name": "Soil_Grass"
    },
    {
      "x": -20,
      "y": 14,
      "z": 9,
      "name": "Soil_Hive_Corrupted",
      "rotation": 1
    },
    {
      "x": -20,
      "y": 15,
      "z": 9,
      "name": "Soil_Hive_Corrupted",
      "rotation": 1
    },
    {
      "x": -20,
      "y": 0,
      "z": 10,
      "name": "Soil_Grass"
    },
    {
      "x": -20,
      "y": 0,
      "z": 11,
      "name": "Soil_Grass"
    },
    {
      "x": -20,
      "y": 0,
      "z": 12,
      "name": "Soil_Grass"
    },
    {
      "x": -20,
      "y": 0,
      "z": 13,
      "name": "Soil_Grass"
    },
    {
      "x": -20,
      "y": 0,
      "z": 14,
      "name": "Soil_Grass"
    },
    {
      "x": -19,
      "y": 0,
      "z": -13,
      "name": "Soil_Grass"
    },
    {
      "x": -19,
      "y": 0,
      "z": -12,
      "name": "Soil_Grass"
    },
    {
      "x": -19,
      "y": 0,
      "z": -11,
      "name": "Soil_Grass"
    },
    {
      "x": -19,
      "y": 0,
      "z": -10,
      "name": "Soil_Grass"
    },
    {
      "x": -19,
      "y": 0,
      "z": -9,
      "name": "Soil_Grass"
    },
    {
      "x": -19,
      "y": 0,
      "z": -8,
      "name": "Soil_Grass"
    },
    {
      "x": -19,
      "y": 0,
      "z": -7,
      "name": "Soil_Grass"
    },
    {
      "x": -19,
      "y": 0,
      "z": -6,
      "name": "Soil_Grass"
    },
    {
      "x": -19,
      "y": 0,
      "z": -5,
      "name": "Soil_Grass"
    },
    {
      "x": -19,
      "y": 0,
      "z": -4,
      "name": "Soil_Roots_Poisoned"
    },
    {
      "x": -19,
      "y": 0,
      "z": -3,
      "name": "Soil_Roots_Poisoned"
    },
    {
      "x": -19,
      "y": 0,
      "z": -2,
      "name": "Soil_Roots_Poisoned"
    },
    {
      "x": -19,
      "y": 10,
      "z": -2,
      "name": "Soil_Roots_Poisoned",
      "rotation": 1
    },
    {
      "x": -19,
      "y": 11,
      "z": -2,
      "name": "Soil_Hive_Corrupted",
      "rotation": 1
    },
    {
      "x": -19,
      "y": 0,
      "z": -1,
      "name": "Soil_Roots_Poisoned"
    },
    {
      "x": -19,
      "y": 10,
      "z": -1,
      "name": "Deco_Bone_Full",
      "rotation": 1
    },
    {
      "x": -19,
      "y": 11,
      "z": -1,
      "name": "Soil_Hive_Corrupted",
      "rotation": 1
    },
    {
      "x": -19,
      "y": 12,
      "z": -1,
      "name": "Soil_Roots_Poisoned",
      "rotation": 1
    },
    {
      "x": -19,
      "y": 0,
      "z": 0,
      "name": "Soil_Roots_Poisoned"
    },
    {
      "x": -19,
      "y": 10,
      "z": 0,
      "name": "Deco_Bone_Full",
      "rotation": 1
    },
    {
      "x": -19,
      "y": 11,
      "z": 0,
      "name": "Deco_Bone_Full",
      "rotation": 1
    },
    {
      "x": -19,
      "y": 12,
      "z": 0,
      "name": "Deco_Bone_Full",
      "rotation": 1
    },
    {
      "x": -19,
      "y": 13,
      "z": 0,
      "name": "Soil_Roots_Poisoned",
      "rotation": 1
    },
    {
      "x": -19,
      "y": 14,
      "z": 0,
      "name": "Soil_Hive_Corrupted",
      "rotation": 1
    },
    {
      "x": -19,
      "y": 0,
      "z": 1,
      "name": "Soil_Roots_Poisoned"
    },
    {
      "x": -19,
      "y": 10,
      "z": 1,
      "name": "Deco_Bone_Full",
      "rotation": 1
    },
    {
      "x": -19,
      "y": 11,
      "z": 1,
      "name": "Deco_Bone_Full",
      "rotation": 1
    },
    {
      "x": -19,
      "y": 12,
      "z": 1,
      "name": "Deco_Bone_Full",
      "rotation": 1
    },
    {
      "x": -19,
      "y": 13,
      "z": 1,
      "name": "Soil_Roots_Poisoned",
      "rotation": 1
    },
    {
      "x": -19,
      "y": 14,
      "z": 1,
      "name": "Soil_Roots_Poisoned",
      "rotation": 1
    },
    {
      "x": -19,
      "y": 0,
      "z": 2,
      "name": "Soil_Grass"
    },
    {
      "x": -19,
      "y": 13,
      "z": 2,
      "name": "Deco_Bone_Full",
      "rotation": 1
    },
    {
      "x": -19,
      "y": 14,
      "z": 2,
      "name": "Soil_Hive_Corrupted",
      "rotation": 1
    },
    {
      "x": -19,
      "y": 15,
      "z": 2,
      "name": "Soil_Roots_Poisoned",
      "rotation": 1
    },
    {
      "x": -19,
      "y": 0,
      "z": 3,
      "name": "Soil_Grass"
    },
    {
      "x": -19,
      "y": 0,
      "z": 4,
      "name": "Soil_Grass"
    },
    {
      "x": -19,
      "y": 0,
      "z": 5,
      "name": "Soil_Grass"
    },
    {
      "x": -19,
      "y": 10,
      "z": 5,
      "name": "Deco_Bone_Full",
      "rotation": 1
    },
    {
      "x": -19,
      "y": 11,
      "z": 5,
      "name": "Soil_Roots_Poisoned",
      "rotation": 1
    },
    {
      "x": -19,
      "y": 12,
      "z": 5,
      "name": "Soil_Hive_Corrupted",
      "rotation": 1
    },
    {
      "x": -19,
      "y": 0,
      "z": 6,
      "name": "Soil_Grass"
    },
    {
      "x": -19,
      "y": 10,
      "z": 6,
      "name": "Deco_Bone_Full",
      "rotation": 1
    },
    {
      "x": -19,
      "y": 11,
      "z": 6,
      "name": "Deco_Bone_Full",
      "rotation": 1
    },
    {
      "x": -19,
      "y": 12,
      "z": 6,
      "name": "Soil_Hive_Corrupted",
      "rotation": 1
    },
    {
      "x": -19,
      "y": 13,
      "z": 6,
      "name": "Soil_Roots_Poisoned",
      "rotation": 1
    },
    {
      "x": -19,
      "y": 0,
      "z": 7,
      "name": "Soil_Grass"
    },
    {
      "x": -19,
      "y": 10,
      "z": 7,
      "name": "Deco_Bone_Full",
      "rotation": 1
    },
    {
      "x": -19,
      "y": 11,
      "z": 7,
      "name": "Deco_Bone_Full",
      "rotation": 1
    },
    {
      "x": -19,
      "y": 12,
      "z": 7,
      "name": "Soil_Hive_Corrupted",
      "rotation": 1
    },
    {
      "x": -19,
      "y": 13,
      "z": 7,
      "name": "Soil_Hive_Corrupted",
      "rotation": 1
    },
    {
      "x": -19,
      "y": 0,
      "z": 8,
      "name": "Soil_Grass"
    },
    {
      "x": -19,
      "y": 11,
      "z": 8,
      "name": "Deco_Bone_Full",
      "rotation": 1
    },
    {
      "x": -19,
      "y": 12,
      "z": 8,
      "name": "Deco_Bone_Full",
      "rotation": 1
    },
    {
      "x": -19,
      "y": 13,
      "z": 8,
      "name": "Soil_Hive_Corrupted",
      "rotation": 1
    },
    {
      "x": -19,
      "y": 14,
      "z": 8,
      "name": "Soil_Hive_Corrupted",
      "rotation": 1
    },
    {
      "x": -19,
      "y": 0,
      "z": 9,
      "name": "Soil_Grass"
    },
    {
      "x": -19,
      "y": 13,
      "z": 9,
      "name": "Soil_Roots_Poisoned",
      "rotation": 1
    },
    {
      "x": -19,
      "y": 0,
      "z": 10,
      "name": "Soil_Grass"
    },
    {
      "x": -19,
      "y": 0,
      "z": 11,
      "name": "Soil_Grass"
    },
    {
      "x": -19,
      "y": 0,
      "z": 12,
      "name": "Soil_Grass"
    },
    {
      "x": -19,
      "y": 0,
      "z": 13,
      "name": "Soil_Grass"
    },
    {
      "x": -19,
      "y": 0,
      "z": 14,
      "name": "Soil_Grass"
    },
    {
      "x": -18,
      "y": 0,
      "z": -13,
      "name": "Soil_Grass"
    },
    {
      "x": -18,
      "y": 0,
      "z": -12,
      "name": "Soil_Grass"
    },
    {
      "x": -18,
      "y": 0,
      "z": -11,
      "name": "Soil_Grass"
    },
    {
      "x": -18,
      "y": 0,
      "z": -10,
      "name": "Soil_Grass"
    },
    {
      "x": -18,
      "y": 0,
      "z": -9,
      "name": "Soil_Grass"
    },
    {
      "x": -18,
      "y": 0,
      "z": -8,
      "name": "Soil_Grass"
    },
    {
      "x": -18,
      "y": 0,
      "z": -7,
      "name": "Soil_Grass"
    },
    {
      "x": -18,
      "y": 0,
      "z": -6,
      "name": "Soil_Hive_Corrupted"
    },
    {
      "x": -18,
      "y": 0,
      "z": -5,
      "name": "Soil_Roots_Poisoned"
    },
    {
      "x": -18,
      "y": 0,
      "z": -4,
      "name": "Soil_Hive_Corrupted"
    },
    {
      "x": -18,
      "y": 0,
      "z": -3,
      "name": "Soil_Roots_Poisoned"
    },
    {
      "x": -18,
      "y": 0,
      "z": -2,
      "name": "Soil_Roots_Poisoned"
    },
    {
      "x": -18,
      "y": 9,
      "z": -2,
      "name": "Soil_Hive_Corrupted",
      "rotation": 1
    },
    {
      "x": -18,
      "y": 10,
      "z": -2,
      "name": "Soil_Hive_Corrupted",
      "rotation": 1
    },
    {
      "x": -18,
      "y": 0,
      "z": -1,
      "name": "Soil_Roots_Poisoned"
    },
    {
      "x": -18,
      "y": 9,
      "z": -1,
      "name": "Deco_Bone_Full",
      "rotation": 1
    },
    {
      "x": -18,
      "y": 10,
      "z": -1,
      "name": "Deco_Bone_Full",
      "rotation": 1
    },
    {
      "x": -18,
      "y": 11,
      "z": -1,
      "name": "Soil_Hive_Corrupted",
      "rotation": 1
    },
    {
      "x": -18,
      "y": 12,
      "z": -1,
      "name": "Soil_Hive_Corrupted",
      "rotation": 1
    },
    {
      "x": -18,
      "y": 0,
      "z": 0,
      "name": "Soil_Hive_Corrupted"
    },
    {
      "x": -18,
      "y": 9,
      "z": 0,
      "name": "Deco_Bone_Full",
      "rotation": 1
    },
    {
      "x": -18,
      "y": 10,
      "z": 0,
      "name": "Deco_Bone_Full",
      "rotation": 1
    },
    {
      "x": -18,
      "y": 11,
      "z": 0,
      "name": "Deco_Bone_Full",
      "rotation": 1
    },
    {
      "x": -18,
      "y": 12,
      "z": 0,
      "name": "Soil_Roots_Poisoned",
      "rotation": 1
    },
    {
      "x": -18,
      "y": 13,
      "z": 0,
      "name": "Soil_Roots_Poisoned",
      "rotation": 1
    },
    {
      "x": -18,
      "y": 0,
      "z": 1,
      "name": "Soil_Roots_Poisoned"
    },
    {
      "x": -18,
      "y": 10,
      "z": 1,
      "name": "Deco_Bone_Full",
      "rotation": 1
    },
    {
      "x": -18,
      "y": 11,
      "z": 1,
      "name": "Deco_Bone_Full",
      "rotation": 1
    },
    {
      "x": -18,
      "y": 12,
      "z": 1,
      "name": "Soil_Roots_Poisoned",
      "rotation": 1
    },
    {
      "x": -18,
      "y": 13,
      "z": 1,
      "name": "Soil_Hive_Corrupted",
      "rotation": 1
    },
    {
      "x": -18,
      "y": 0,
      "z": 2,
      "name": "Soil_Roots_Poisoned"
    },
    {
      "x": -18,
      "y": 13,
      "z": 2,
      "name": "Soil_Hive_Corrupted",
      "rotation": 1
    },
    {
      "x": -18,
      "y": 0,
      "z": 3,
      "name": "Soil_Hive_Corrupted"
    },
    {
      "x": -18,
      "y": 0,
      "z": 4,
      "name": "Soil_Grass"
    },
    {
      "x": -18,
      "y": 0,
      "z": 5,
      "name": "Soil_Grass"
    },
    {
      "x": -18,
      "y": 9,
      "z": 5,
      "name": "Deco_Bone_Full",
      "rotation": 1
    },
    {
      "x": -18,
      "y": 10,
      "z": 5,
      "name": "Soil_Hive_Corrupted",
      "rotation": 1
    },
    {
      "x": -18,
      "y": 11,
      "z": 5,
      "name": "Soil_Hive_Corrupted",
      "rotation": 1
    },
    {
      "x": -18,
      "y": 0,
      "z": 6,
      "name": "Soil_Grass"
    },
    {
      "x": -18,
      "y": 9,
      "z": 6,
      "name": "Deco_Bone_Full",
      "rotation": 1
    },
    {
      "x": -18,
      "y": 10,
      "z": 6,
      "name": "Deco_Bone_Full",
      "rotation": 1
    },
    {
      "x": -18,
      "y": 11,
      "z": 6,
      "name": "Soil_Roots_Poisoned",
      "rotation": 1
    },
    {
      "x": -18,
      "y": 12,
      "z": 6,
      "name": "Soil_Hive_Corrupted",
      "rotation": 1
    },
    {
      "x": -18,
      "y": 0,
      "z": 7,
      "name": "Soil_Grass"
    },
    {
      "x": -18,
      "y": 10,
      "z": 7,
      "name": "Deco_Bone_Full",
      "rotation": 1
    },
    {
      "x": -18,
      "y": 11,
      "z": 7,
      "name": "Deco_Bone_Full",
      "rotation": 1
    },
    {
      "x": -18,
      "y": 12,
      "z": 7,
      "name": "Soil_Hive_Corrupted",
      "rotation": 1
    },
    {
      "x": -18,
      "y": 13,
      "z": 7,
      "name": "Soil_Hive_Corrupted",
      "rotation": 1
    },
    {
      "x": -18,
      "y": 0,
      "z": 8,
      "name": "Soil_Grass"
    },
    {
      "x": -18,
      "y": 11,
      "z": 8,
      "name": "Deco_Bone_Full",
      "rotation": 1
    },
    {
      "x": -18,
      "y": 12,
      "z": 8,
      "name": "Soil_Hive_Corrupted",
      "rotation": 1
    },
    {
      "x": -18,
      "y": 13,
      "z": 8,
      "name": "Soil_Hive_Corrupted",
      "rotation": 1
    },
    {
      "x": -18,
      "y": 0,
      "z": 9,
      "name": "Soil_Grass"
    },
    {
      "x": -18,
      "y": 0,
      "z": 10,
      "name": "Soil_Grass"
    },
    {
      "x": -18,
      "y": 0,
      "z": 11,
      "name": "Soil_Grass"
    },
    {
      "x": -18,
      "y": 0,
      "z": 12,
      "name": "Soil_Grass"
    },
    {
      "x": -18,
      "y": 0,
      "z": 13,
      "name": "Soil_Grass"
    },
    {
      "x": -18,
      "y": 0,
      "z": 14,
      "name": "Soil_Grass"
    },
    {
      "x": -17,
      "y": 0,
      "z": -13,
      "name": "Soil_Grass"
    },
    {
      "x": -17,
      "y": 0,
      "z": -12,
      "name": "Soil_Grass"
    },
    {
      "x": -17,
      "y": 0,
      "z": -11,
      "name": "Soil_Grass"
    },
    {
      "x": -17,
      "y": 0,
      "z": -10,
      "name": "Soil_Grass"
    },
    {
      "x": -17,
      "y": 0,
      "z": -9,
      "name": "Soil_Grass"
    },
    {
      "x": -17,
      "y": 0,
      "z": -8,
      "name": "Soil_Hive_Corrupted"
    },
    {
      "x": -17,
      "y": 0,
      "z": -7,
      "name": "Soil_Hive_Corrupted"
    },
    {
      "x": -17,
      "y": 0,
      "z": -6,
      "name": "Soil_Roots_Poisoned"
    },
    {
      "x": -17,
      "y": 25,
      "z": -6,
      "name": "Soil_Hive_Corrupted",
      "rotation": 1
    },
    {
      "x": -17,
      "y": 26,
      "z": -6,
      "name": "Soil_Hive_Corrupted",
      "rotation": 1
    },
    {
      "x": -17,
      "y": 0,
      "z": -5,
      "name": "Soil_Roots_Poisoned"
    },
    {
      "x": -17,
      "y": 22,
      "z": -5,
      "name": "Deco_Bone_Full",
      "rotation": 1
    },
    {
      "x": -17,
      "y": 23,
      "z": -5,
      "name": "Deco_Bone_Full",
      "rotation": 1
    },
    {
      "x": -17,
      "y": 24,
      "z": -5,
      "name": "Deco_Bone_Full",
      "rotation": 1
    },
    {
      "x": -17,
      "y": 25,
      "z": -5,
      "name": "Soil_Roots_Poisoned",
      "rotation": 1
    },
    {
      "x": -17,
      "y": 26,
      "z": -5,
      "name": "Soil_Roots_Poisoned",
      "rotation": 1
    },
    {
      "x": -17,
      "y": 0,
      "z": -4,
      "name": "Soil_Hive_Corrupted"
    },
    {
      "x": -17,
      "y": 25,
      "z": -4,
      "name": "Soil_Roots_Poisoned",
      "rotation": 1
    },
    {
      "x": -17,
      "y": 26,
      "z": -4,
      "name": "Soil_Hive_Corrupted",
      "rotation": 1
    },
    {
      "x": -17,
      "y": 0,
      "z": -3,
      "name": "Soil_Roots_Poisoned"
    },
    {
      "x": -17,
      "y": 0,
      "z": -2,
      "name": "Soil_Roots_Poisoned"
    },
    {
      "x": -17,
      "y": 8,
      "z": -2,
      "name": "Deco_Bone_Full",
      "rotation": 1
    },
    {
      "x": -17,
      "y": 9,
      "z": -2,
      "name": "Soil_Hive_Corrupted",
      "rotation": 1
    },
    {
      "x": -17,
      "y": 10,
      "z": -2,
      "name": "Soil_Roots_Poisoned",
      "rotation": 1
    },
    {
      "x": -17,
      "y": 0,
      "z": -1,
      "name": "Soil_Hive_Corrupted"
    },
    {
      "x": -17,
      "y": 8,
      "z": -1,
      "name": "Deco_Bone_Full",
      "rotation": 1
    },
    {
      "x": -17,
      "y": 9,
      "z": -1,
      "name": "Deco_Bone_Full",
      "rotation": 1
    },
    {
      "x": -17,
      "y": 10,
      "z": -1,
      "name": "Soil_Roots_Poisoned",
      "rotation": 1
    },
    {
      "x": -17,
      "y": 11,
      "z": -1,
      "name": "Soil_Roots_Poisoned",
      "rotation": 1
    },
    {
      "x": -17,
      "y": 0,
      "z": 0,
      "name": "Soil_Roots_Poisoned"
    },
    {
      "x": -17,
      "y": 8,
      "z": 0,
      "name": "Deco_Bone_Full",
      "rotation": 1
    },
    {
      "x": -17,
      "y": 9,
      "z": 0,
      "name": "Deco_Bone_Full",
      "rotation": 1
    },
    {
      "x": -17,
      "y": 10,
      "z": 0,
      "name": "Deco_Bone_Full",
      "rotation": 1
    },
    {
      "x": -17,
      "y": 11,
      "z": 0,
      "name": "Soil_Roots_Poisoned",
      "rotation": 1
    },
    {
      "x": -17,
      "y": 12,
      "z": 0,
      "name": "Soil_Roots_Poisoned",
      "rotation": 1
    },
    {
      "x": -17,
      "y": 0,
      "z": 1,
      "name": "Soil_Roots_Poisoned"
    },
    {
      "x": -17,
      "y": 9,
      "z": 1,
      "name": "Deco_Bone_Full",
      "rotation": 1
    },
    {
      "x": -17,
      "y": 10,
      "z": 1,
      "name": "Deco_Bone_Full",
      "rotation": 1
    },
    {
      "x": -17,
      "y": 11,
      "z": 1,
      "name": "Soil_Roots_Poisoned",
      "rotation": 1
    },
    {
      "x": -17,
      "y": 12,
      "z": 1,
      "name": "Soil_Hive_Corrupted",
      "rotation": 1
    },
    {
      "x": -17,
      "y": 0,
      "z": 2,
      "name": "Soil_Hive_Corrupted"
    },
    {
      "x": -17,
      "y": 0,
      "z": 3,
      "name": "Soil_Hive_Corrupted"
    },
    {
      "x": -17,
      "y": 0,
      "z": 4,
      "name": "Soil_Roots_Poisoned"
    },
    {
      "x": -17,
      "y": 0,
      "z": 5,
      "name": "Soil_Grass"
    },
    {
      "x": -17,
      "y": 9,
      "z": 5,
      "name": "Deco_Bone_Full",
      "rotation": 1
    },
    {
      "x": -17,
      "y": 10,
      "z": 5,
      "name": "Soil_Hive_Corrupted",
      "rotation": 1
    },
    {
      "x": -17,
      "y": 11,
      "z": 5,
      "name": "Soil_Roots_Poisoned",
      "rotation": 1
    },
    {
      "x": -17,
      "y": 0,
      "z": 6,
      "name": "Soil_Grass"
    },
    {
      "x": -17,
      "y": 9,
      "z": 6,
      "name": "Deco_Bone_Full",
      "rotation": 1
    },
    {
      "x": -17,
      "y": 10,
      "z": 6,
      "name": "Soil_Hive_Corrupted",
      "rotation": 1
    },
    {
      "x": -17,
      "y": 11,
      "z": 6,
      "name": "Soil_Roots_Poisoned",
      "rotation": 1
    },
    {
      "x": -17,
      "y": 0,
      "z": 7,
      "name": "Soil_Grass"
    },
    {
      "x": -17,
      "y": 9,
      "z": 7,
      "name": "Deco_Bone_Full",
      "rotation": 1
    },
    {
      "x": -17,
      "y": 10,
      "z": 7,
      "name": "Deco_Bone_Full",
      "rotation": 1
    },
    {
      "x": -17,
      "y": 11,
      "z": 7,
      "name": "Soil_Hive_Corrupted",
      "rotation": 1
    },
    {
      "x": -17,
      "y": 12,
      "z": 7,
      "name": "Soil_Roots_Poisoned",
      "rotation": 1
    },
    {
      "x": -17,
      "y": 0,
      "z": 8,
      "name": "Soil_Grass"
    },
    {
      "x": -17,
      "y": 11,
      "z": 8,
      "name": "Soil_Hive_Corrupted",
      "rotation": 1
    },
    {
      "x": -17,
      "y": 12,
      "z": 8,
      "name": "Soil_Hive_Corrupted",
      "rotation": 1
    },
    {
      "x": -17,
      "y": 0,
      "z": 9,
      "name": "Soil_Grass"
    },
    {
      "x": -17,
      "y": 0,
      "z": 10,
      "name": "Soil_Grass"
    },
    {
      "x": -17,
      "y": 0,
      "z": 11,
      "name": "Soil_Grass"
    },
    {
      "x": -17,
      "y": 0,
      "z": 12,
      "name": "Soil_Grass"
    },
    {
      "x": -17,
      "y": 0,
      "z": 13,
      "name": "Soil_Grass"
    },
    {
      "x": -17,
      "y": 0,
      "z": 14,
      "name": "Soil_Grass"
    },
    {
      "x": -16,
      "y": 0,
      "z": -13,
      "name": "Soil_Grass"
    },
    {
      "x": -16,
      "y": 0,
      "z": -12,
      "name": "Soil_Grass"
    },
    {
      "x": -16,
      "y": 0,
      "z": -11,
      "name": "Soil_Grass"
    },
    {
      "x": -16,
      "y": 0,
      "z": -10,
      "name": "Soil_Grass"
    },
    {
      "x": -16,
      "y": 0,
      "z": -9,
      "name": "Soil_Grass"
    },
    {
      "x": -16,
      "y": 0,
      "z": -8,
      "name": "Soil_Roots_Poisoned"
    },
    {
      "x": -16,
      "y": 0,
      "z": -7,
      "name": "Soil_Roots_Poisoned"
    },
    {
      "x": -16,
      "y": 0,
      "z": -6,
      "name": "Soil_Roots_Poisoned"
    },
    {
      "x": -16,
      "y": 18,
      "z": -6,
      "name": "Deco_Bone_Full",
      "rotation": 1
    },
    {
      "x": -16,
      "y": 19,
      "z": -6,
      "name": "Deco_Bone_Full",
      "rotation": 1
    },
    {
      "x": -16,
      "y": 20,
      "z": -6,
      "name": "Deco_Bone_Full",
      "rotation": 1
    },
    {
      "x": -16,
      "y": 21,
      "z": -6,
      "name": "Deco_Bone_Full",
      "rotation": 1
    },
    {
      "x": -16,
      "y": 22,
      "z": -6,
      "name": "Deco_Bone_Full",
      "rotation": 1
    },
    {
      "x": -16,
      "y": 23,
      "z": -6,
      "name": "Deco_Bone_Full",
      "rotation": 1
    },
    {
      "x": -16,
      "y": 24,
      "z": -6,
      "name": "Deco_Bone_Full",
      "rotation": 1
    },
    {
      "x": -16,
      "y": 25,
      "z": -6,
      "name": "Soil_Roots_Poisoned",
      "rotation": 1
    },
    {
      "x": -16,
      "y": 26,
      "z": -6,
      "name": "Soil_Roots_Poisoned",
      "rotation": 1
    },
    {
      "x": -16,
      "y": 0,
      "z": -5,
      "name": "Soil_Hive_Corrupted"
    },
    {
      "x": -16,
      "y": 19,
      "z": -5,
      "name": "Deco_Bone_Full",
      "rotation": 1
    },
    {
      "x": -16,
      "y": 20,
      "z": -5,
      "name": "Deco_Bone_Full",
      "rotation": 1
    },
    {
      "x": -16,
      "y": 21,
      "z": -5,
      "name": "Deco_Bone_Full",
      "rotation": 1
    },
    {
      "x": -16,
      "y": 22,
      "z": -5,
      "name": "Deco_Bone_Full",
      "rotation": 1
    },
    {
      "x": -16,
      "y": 23,
      "z": -5,
      "name": "Deco_Bone_Full",
      "rotation": 1
    },
    {
      "x": -16,
      "y": 24,
      "z": -5,
      "name": "Deco_Bone_Full",
      "rotation": 1
    },
    {
      "x": -16,
      "y": 25,
      "z": -5,
      "name": "Soil_Roots_Poisoned",
      "rotation": 1
    },
    {
      "x": -16,
      "y": 26,
      "z": -5,
      "name": "Soil_Roots_Poisoned",
      "rotation": 1
    },
    {
      "x": -16,
      "y": 0,
      "z": -4,
      "name": "Soil_Roots_Poisoned"
    },
    {
      "x": -16,
      "y": 22,
      "z": -4,
      "name": "Deco_Bone_Full",
      "rotation": 1
    },
    {
      "x": -16,
      "y": 23,
      "z": -4,
      "name": "Deco_Bone_Full",
      "rotation": 1
    },
    {
      "x": -16,
      "y": 24,
      "z": -4,
      "name": "Deco_Bone_Full",
      "rotation": 1
    },
    {
      "x": -16,
      "y": 25,
      "z": -4,
      "name": "Soil_Hive_Corrupted",
      "rotation": 1
    },
    {
      "x": -16,
      "y": 26,
      "z": -4,
      "name": "Soil_Hive_Corrupted",
      "rotation": 1
    },
    {
      "x": -16,
      "y": 0,
      "z": -3,
      "name": "Soil_Roots_Poisoned"
    },
    {
      "x": -16,
      "y": 0,
      "z": -2,
      "name": "Soil_Roots_Poisoned"
    },
    {
      "x": -16,
      "y": 7,
      "z": -2,
      "name": "Deco_Bone_Full",
      "rotation": 1
    },
    {
      "x": -16,
      "y": 8,
      "z": -2,
      "name": "Soil_Hive_Corrupted",
      "rotation": 1
    },
    {
      "x": -16,
      "y": 9,
      "z": -2,
      "name": "Soil_Hive_Corrupted",
      "rotation": 1
    },
    {
      "x": -16,
      "y": 0,
      "z": -1,
      "name": "Soil_Roots_Poisoned"
    },
    {
      "x": -16,
      "y": 7,
      "z": -1,
      "name": "Deco_Bone_Full",
      "rotation": 1
    },
    {
      "x": -16,
      "y": 8,
      "z": -1,
      "name": "Deco_Bone_Full",
      "rotation": 1
    },
    {
      "x": -16,
      "y": 9,
      "z": -1,
      "name": "Soil_Hive_Corrupted",
      "rotation": 1
    },
    {
      "x": -16,
      "y": 10,
      "z": -1,
      "name": "Soil_Hive_Corrupted",
      "rotation": 1
    },
    {
      "x": -16,
      "y": 0,
      "z": 0,
      "name": "Soil_Roots_Poisoned"
    },
    {
      "x": -16,
      "y": 8,
      "z": 0,
      "name": "Deco_Bone_Full",
      "rotation": 1
    },
    {
      "x": -16,
      "y": 9,
      "z": 0,
      "name": "Deco_Bone_Full",
      "rotation": 1
    },
    {
      "x": -16,
      "y": 10,
      "z": 0,
      "name": "Soil_Roots_Poisoned",
      "rotation": 1
    },
    {
      "x": -16,
      "y": 11,
      "z": 0,
      "name": "Soil_Hive_Corrupted",
      "rotation": 1
    },
    {
      "x": -16,
      "y": 0,
      "z": 1,
      "name": "Soil_Hive_Corrupted"
    },
    {
      "x": -16,
      "y": 9,
      "z": 1,
      "name": "Deco_Bone_Full",
      "rotation": 1
    },
    {
      "x": -16,
      "y": 10,
      "z": 1,
      "name": "Soil_Roots_Poisoned",
      "rotation": 1
    },
    {
      "x": -16,
      "y": 11,
      "z": 1,
      "name": "Soil_Hive_Corrupted",
      "rotation": 1
    },
    {
      "x": -16,
      "y": 0,
      "z": 2,
      "name": "Soil_Hive_Corrupted"
    },
    {
      "x": -16,
      "y": 0,
      "z": 3,
      "name": "Soil_Hive_Corrupted"
    },
    {
      "x": -16,
      "y": 0,
      "z": 4,
      "name": "Soil_Hive_Corrupted"
    },
    {
      "x": -16,
      "y": 8,
      "z": 4,
      "name": "Soil_Hive_Corrupted",
      "rotation": 1
    },
    {
      "x": -16,
      "y": 9,
      "z": 4,
      "name": "Soil_Roots_Poisoned",
      "rotation": 1
    },
    {
      "x": -16,
      "y": 0,
      "z": 5,
      "name": "Soil_Grass"
    },
    {
      "x": -16,
      "y": 8,
      "z": 5,
      "name": "Deco_Bone_Full",
      "rotation": 1
    },
    {
      "x": -16,
      "y": 9,
      "z": 5,
      "name": "Soil_Roots_Poisoned",
      "rotation": 1
    },
    {
      "x": -16,
      "y": 10,
      "z": 5,
      "name": "Soil_Roots_Poisoned",
      "rotation": 1
    },
    {
      "x": -16,
      "y": 0,
      "z": 6,
      "name": "Soil_Grass"
    },
    {
      "x": -16,
      "y": 8,
      "z": 6,
      "name": "Deco_Bone_Full",
      "rotation": 1
    },
    {
      "x": -16,
      "y": 9,
      "z": 6,
      "name": "Deco_Bone_Full",
      "rotation": 1
    },
    {
      "x": -16,
      "y": 10,
      "z": 6,
      "name": "Soil_Roots_Poisoned",
      "rotation": 1
    },
    {
      "x": -16,
      "y": 11,
      "z": 6,
      "name": "Soil_Hive_Corrupted",
      "rotation": 1
    },
    {
      "x": -16,
      "y": 0,
      "z": 7,
      "name": "Soil_Grass"
    },
    {
      "x": -16,
      "y": 9,
      "z": 7,
      "name": "Deco_Bone_Full",
      "rotation": 1
    },
    {
      "x": -16,
      "y": 10,
      "z": 7,
      "name": "Soil_Roots_Poisoned",
      "rotation": 1
    },
    {
      "x": -16,
      "y": 11,
      "z": 7,
      "name": "Soil_Roots_Poisoned",
      "rotation": 1
    },
    {
      "x": -16,
      "y": 0,
      "z": 8,
      "name": "Soil_Grass"
    },
    {
      "x": -16,
      "y": 10,
      "z": 8,
      "name": "Soil_Hive_Corrupted",
      "rotation": 1
    },
    {
      "x": -16,
      "y": 11,
      "z": 8,
      "name": "Soil_Roots_Poisoned",
      "rotation": 1
    },
    {
      "x": -16,
      "y": 0,
      "z": 9,
      "name": "Soil_Grass"
    },
    {
      "x": -16,
      "y": 0,
      "z": 10,
      "name": "Soil_Grass"
    },
    {
      "x": -16,
      "y": 0,
      "z": 11,
      "name": "Soil_Grass"
    },
    {
      "x": -16,
      "y": 0,
      "z": 12,
      "name": "Soil_Grass"
    },
    {
      "x": -16,
      "y": 0,
      "z": 13,
      "name": "Soil_Grass"
    },
    {
      "x": -16,
      "y": 0,
      "z": 14,
      "name": "Soil_Grass"
    },
    {
      "x": -15,
      "y": 0,
      "z": -13,
      "name": "Soil_Grass"
    },
    {
      "x": -15,
      "y": 0,
      "z": -12,
      "name": "Soil_Grass"
    },
    {
      "x": -15,
      "y": 0,
      "z": -11,
      "name": "Soil_Grass"
    },
    {
      "x": -15,
      "y": 0,
      "z": -10,
      "name": "Soil_Grass"
    },
    {
      "x": -15,
      "y": 0,
      "z": -9,
      "name": "Soil_Roots_Poisoned"
    },
    {
      "x": -15,
      "y": 0,
      "z": -8,
      "name": "Soil_Roots_Poisoned"
    },
    {
      "x": -15,
      "y": 0,
      "z": -7,
      "name": "Soil_Roots_Poisoned"
    },
    {
      "x": -15,
      "y": 16,
      "z": -7,
      "name": "Soil_Hive_Corrupted",
      "rotation": 1
    },
    {
      "x": -15,
      "y": 17,
      "z": -7,
      "name": "Soil_Hive_Corrupted",
      "rotation": 1
    },
    {
      "x": -15,
      "y": 0,
      "z": -6,
      "name": "Soil_Hive_Corrupted"
    },
    {
      "x": -15,
      "y": 16,
      "z": -6,
      "name": "Deco_Bone_Full",
      "rotation": 1
    },
    {
      "x": -15,
      "y": 17,
      "z": -6,
      "name": "Deco_Bone_Full",
      "rotation": 1
    },
    {
      "x": -15,
      "y": 18,
      "z": -6,
      "name": "Deco_Bone_Full",
      "rotation": 1
    },
    {
      "x": -15,
      "y": 19,
      "z": -6,
      "name": "Deco_Bone_Full",
      "rotation": 1
    },
    {
      "x": -15,
      "y": 20,
      "z": -6,
      "name": "Soil_Roots_Poisoned",
      "rotation": 1
    },
    {
      "x": -15,
      "y": 21,
      "z": -6,
      "name": "Soil_Roots_Poisoned",
      "rotation": 1
    },
    {
      "x": -15,
      "y": 0,
      "z": -5,
      "name": "Soil_Hive_Corrupted"
    },
    {
      "x": -15,
      "y": 17,
      "z": -5,
      "name": "Deco_Bone_Full",
      "rotation": 1
    },
    {
      "x": -15,
      "y": 18,
      "z": -5,
      "name": "Deco_Bone_Full",
      "rotation": 1
    },
    {
      "x": -15,
      "y": 19,
      "z": -5,
      "name": "Deco_Bone_Full",
      "rotation": 1
    },
    {
      "x": -15,
      "y": 20,
      "z": -5,
      "name": "Deco_Bone_Full",
      "rotation": 1
    },
    {
      "x": -15,
      "y": 21,
      "z": -5,
      "name": "Deco_Bone_Full",
      "rotation": 1
    },
    {
      "x": -15,
      "y": 22,
      "z": -5,
      "name": "Deco_Bone_Full",
      "rotation": 1
    },
    {
      "x": -15,
      "y": 23,
      "z": -5,
      "name": "Deco_Bone_Full",
      "rotation": 1
    },
    {
      "x": -15,
      "y": 24,
      "z": -5,
      "name": "Deco_Bone_Full",
      "rotation": 1
    },
    {
      "x": -15,
      "y": 25,
      "z": -5,
      "name": "Deco_Bone_Full",
      "rotation": 1
    },
    {
      "x": -15,
      "y": 26,
      "z": -5,
      "name": "Soil_Roots_Poisoned",
      "rotation": 1
    },
    {
      "x": -15,
      "y": 27,
      "z": -5,
      "name": "Soil_Roots_Poisoned",
      "rotation": 1
    },
    {
      "x": -15,
      "y": 0,
      "z": -4,
      "name": "Soil_Roots_Poisoned"
    },
    {
      "x": -15,
      "y": 22,
      "z": -4,
      "name": "Deco_Bone_Full",
      "rotation": 1
    },
    {
      "x": -15,
      "y": 23,
      "z": -4,
      "name": "Deco_Bone_Full",
      "rotation": 1
    },
    {
      "x": -15,
      "y": 24,
      "z": -4,
      "name": "Deco_Bone_Full",
      "rotation": 1
    },
    {
      "x": -15,
      "y": 25,
      "z": -4,
      "name": "Soil_Hive_Corrupted",
      "rotation": 1
    },
    {
      "x": -15,
      "y": 26,
      "z": -4,
      "name": "Soil_Hive_Corrupted",
      "rotation": 1
    },
    {
      "x": -15,
      "y": 0,
      "z": -3,
      "name": "Soil_Hive_Corrupted"
    },
    {
      "x": -15,
      "y": 0,
      "z": -2,
      "name": "Soil_Hive_Corrupted"
    },
    {
      "x": -15,
      "y": 6,
      "z": -2,
      "name": "Deco_Bone_Full",
      "rotation": 1
    },
    {
      "x": -15,
      "y": 7,
      "z": -2,
      "name": "Soil_Hive_Corrupted",
      "rotation": 1
    },
    {
      "x": -15,
      "y": 8,
      "z": -2,
      "name": "Soil_Roots_Poisoned",
      "rotation": 1
    },
    {
      "x": -15,
      "y": 0,
      "z": -1,
      "name": "Soil_Roots_Poisoned"
    },
    {
      "x": -15,
      "y": 7,
      "z": -1,
      "name": "Deco_Bone_Full",
      "rotation": 1
    },
    {
      "x": -15,
      "y": 8,
      "z": -1,
      "name": "Soil_Roots_Poisoned",
      "rotation": 1
    },
    {
      "x": -15,
      "y": 9,
      "z": -1,
      "name": "Soil_Hive_Corrupted",
      "rotation": 1
    },
    {
      "x": -15,
      "y": 0,
      "z": 0,
      "name": "Soil_Hive_Corrupted"
    },
    {
      "x": -15,
      "y": 7,
      "z": 0,
      "name": "Deco_Bone_Full",
      "rotation": 1
    },
    {
      "x": -15,
      "y": 8,
      "z": 0,
      "name": "Deco_Bone_Full",
      "rotation": 1
    },
    {
      "x": -15,
      "y": 9,
      "z": 0,
      "name": "Soil_Hive_Corrupted",
      "rotation": 1
    },
    {
      "x": -15,
      "y": 10,
      "z": 0,
      "name": "Soil_Roots_Poisoned",
      "rotation": 1
    },
    {
      "x": -15,
      "y": 0,
      "z": 1,
      "name": "Soil_Roots_Poisoned"
    },
    {
      "x": -15,
      "y": 8,
      "z": 1,
      "name": "Deco_Bone_Full",
      "rotation": 1
    },
    {
      "x": -15,
      "y": 9,
      "z": 1,
      "name": "Soil_Roots_Poisoned",
      "rotation": 1
    },
    {
      "x": -15,
      "y": 10,
      "z": 1,
      "name": "Soil_Roots_Poisoned",
      "rotation": 1
    },
    {
      "x": -15,
      "y": 0,
      "z": 2,
      "name": "Soil_Roots_Poisoned"
    },
    {
      "x": -15,
      "y": 0,
      "z": 3,
      "name": "Soil_Roots_Poisoned"
    },
    {
      "x": -15,
      "y": 0,
      "z": 4,
      "name": "Soil_Roots_Poisoned"
    },
    {
      "x": -15,
      "y": 8,
      "z": 4,
      "name": "Soil_Roots_Poisoned",
      "rotation": 1
    },
    {
      "x": -15,
      "y": 9,
      "z": 4,
      "name": "Soil_Hive_Corrupted",
      "rotation": 1
    },
    {
      "x": -15,
      "y": 0,
      "z": 5,
      "name": "Soil_Roots_Poisoned"
    },
    {
      "x": -15,
      "y": 7,
      "z": 5,
      "name": "Deco_Bone_Full",
      "rotation": 1
    },
    {
      "x": -15,
      "y": 8,
      "z": 5,
      "name": "Deco_Bone_Full",
      "rotation": 1
    },
    {
      "x": -15,
      "y": 9,
      "z": 5,
      "name": "Soil_Hive_Corrupted",
      "rotation": 1
    },
    {
      "x": -15,
      "y": 10,
      "z": 5,
      "name": "Soil_Hive_Corrupted",
      "rotation": 1
    },
    {
      "x": -15,
      "y": 0,
      "z": 6,
      "name": "Soil_Grass"
    },
    {
      "x": -15,
      "y": 8,
      "z": 6,
      "name": "Deco_Bone_Full",
      "rotation": 1
    },
    {
      "x": -15,
      "y": 9,
      "z": 6,
      "name": "Soil_Hive_Corrupted",
      "rotation": 1
    },
    {
      "x": -15,
      "y": 10,
      "z": 6,
      "name": "Soil_Hive_Corrupted",
      "rotation": 1
    },
    {
      "x": -15,
      "y": 0,
      "z": 7,
      "name": "Soil_Grass"
    },
    {
      "x": -15,
      "y": 8,
      "z": 7,
      "name": "Deco_Bone_Full",
      "rotation": 1
    },
    {
      "x": -15,
      "y": 9,
      "z": 7,
      "name": "Deco_Bone_Full",
      "rotation": 1
    },
    {
      "x": -15,
      "y": 10,
      "z": 7,
      "name": "Soil_Roots_Poisoned",
      "rotation": 1
    },
    {
      "x": -15,
      "y": 11,
      "z": 7,
      "name": "Soil_Roots_Poisoned",
      "rotation": 1
    },
    {
      "x": -15,
      "y": 0,
      "z": 8,
