{
  "version": 8,
  "blockIdVersion": 11,
  "anchorX": 0,
  "anchorY": 6,
  "anchorZ": 0,
  "blocks": [
    {
      "x": -13,
      "y": 13,
      "z": -11,
      "name": "Rock_Volcanic_Brick_Stairs",
      "rotation": 9
    },
    {
      "x": -13,
      "y": 14,
      "z": -11,
      "name": "Rock_Volcanic_Brick_Roof_Steep",
      "rotation": 3
    },
    {
      "x": -13,
      "y": 15,
      "z": -11,
      "name": "Rock_Volcanic_Brick_Roof_Steep",
      "filler": 1024,
      "rotation": 3
    },
    {
      "x": -13,
      "y": 13,
      "z": -7,
      "name": "Rock_Volcanic_Brick_Stairs",
      "rotation": 9
    },
    {
      "x": -13,
      "y": 14,
      "z": -7,
      "name": "Rock_Volcanic_Brick_Roof_Steep",
      "rotation": 3
    },
    {
      "x": -13,
      "y": 15,
      "z": -7,
      "name": "Rock_Volcanic_Brick_Roof_Steep",
      "filler": 1024,
      "rotation": 3
    },
    {
      "x": -13,
      "y": 13,
      "z": -3,
      "name": "Rock_Volcanic_Brick_Stairs",
      "rotation": 9
    },
    {
      "x": -13,
      "y": 14,
      "z": -3,
      "name": "Rock_Volcanic_Brick_Roof_Steep",
      "rotation": 3
    },
    {
      "x": -13,
      "y": 15,
      "z": -3,
      "name": "Rock_Volcanic_Brick_Roof_Steep",
      "filler": 1024,
      "rotation": 3
    },
    {
      "x": -13,
      "y": 13,
      "z": 1,
      "name": "Rock_Volcanic_Brick_Stairs",
      "rotation": 9
    },
    {
      "x": -13,
      "y": 14,
      "z": 1,
      "name": "Rock_Volcanic_Brick_Roof_Steep",
      "rotation": 3
    },
    {
      "x": -13,
      "y": 15,
      "z": 1,
      "name": "Rock_Volcanic_Brick_Roof_Steep",
      "filler": 1024,
      "rotation": 3
    },
    {
      "x": -13,
      "y": 13,
      "z": 5,
      "name": "Rock_Volcanic_Brick_Stairs",
      "rotation": 9
    },
    {
      "x": -13,
      "y": 14,
      "z": 5,
      "name": "Rock_Volcanic_Brick_Roof_Steep",
      "rotation": 3
    },
    {
      "x": -13,
      "y": 15,
      "z": 5,
      "name": "Rock_Volcanic_Brick_Roof_Steep",
      "filler": 1024,
      "rotation": 3
    },
    {
      "x": -13,
      "y": 13,
      "z": 9,
      "name": "Rock_Volcanic_Brick_Stairs",
      "rotation": 9
    },
    {
      "x": -13,
      "y": 14,
      "z": 9,
      "name": "Rock_Volcanic_Brick_Roof_Steep",
      "rotation": 3
    },
    {
      "x": -13,
      "y": 15,
      "z": 9,
      "name": "Rock_Volcanic_Brick_Roof_Steep",
      "filler": 1024,
      "rotation": 3
    },
    {
      "x": -13,
      "y": 13,
      "z": 13,
      "name": "Rock_Volcanic_Brick_Stairs",
      "rotation": 9
    },
    {
      "x": -13,
      "y": 14,
      "z": 13,
      "name": "Rock_Volcanic_Brick_Roof_Steep",
      "rotation": 3
    },
    {
      "x": -13,
      "y": 15,
      "z": 13,
      "name": "Rock_Volcanic_Brick_Roof_Steep",
      "filler": 1024,
      "rotation": 3
    },
    {
      "x": -12,
      "y": 6,
      "z": -11,
      "name": "Rock_Volcanic_Brick_Stairs",
      "rotation": 9
    },
    {
      "x": -12,
      "y": 7,
      "z": -11,
      "name": "Rock_Volcanic_Brick_Pillar_Base"
    },
    {
      "x": -12,
      "y": 8,
      "z": -11,
      "name": "Rock_Volcanic_Brick_Pillar_Middle",
      "rotation": 8
    },
    {
      "x": -12,
      "y": 9,
      "z": -11,
      "name": "Rock_Volcanic_Brick_Pillar_Middle",
      "rotation": 8
    },
    {
      "x": -12,
      "y": 10,
      "z": -11,
      "name": "Rock_Volcanic_Brick_Pillar_Middle",
      "rotation": 8
    },
    {
      "x": -12,
      "y": 11,
      "z": -11,
      "name": "Rock_Volcanic_Brick_Pillar_Middle",
      "rotation": 8
    },
    {
      "x": -12,
      "y": 12,
      "z": -11,
      "name": "Rock_Volcanic_Brick_Pillar_Base",
      "rotation": 8
    },
    {
      "x": -12,
      "y": 13,
      "z": -11,
      "name": "Rock_Volcanic_Brick",
      "rotation": 2
    },
    {
      "x": -12,
      "y": 14,
      "z": -11,
      "name": "Rock_Volcanic_Brick",
      "rotation": 2
    },
    {
      "x": -12,
      "y": 15,
      "z": -11,
      "name": "Rock_Volcanic_Brick",
      "rotation": 2
    },
    {
      "x": -12,
      "y": 16,
      "z": -11,
      "name": "Rock_Volcanic_Brick_Roof_Steep",
      "rotation": 3
    },
    {
      "x": -12,
      "y": 17,
      "z": -11,
      "name": "Rock_Volcanic_Brick_Roof_Steep",
      "filler": 1024,
      "rotation": 3
    },
    {
      "x": -12,
      "y": 6,
      "z": -7,
      "name": "Rock_Volcanic_Brick_Stairs",
      "rotation": 9
    },
    {
      "x": -12,
      "y": 7,
      "z": -7,
      "name": "Rock_Volcanic_Brick_Pillar_Base"
    },
    {
      "x": -12,
      "y": 8,
      "z": -7,
      "name": "Rock_Volcanic_Brick_Pillar_Middle",
      "rotation": 8
    },
    {
      "x": -12,
      "y": 9,
      "z": -7,
      "name": "Rock_Volcanic_Brick_Pillar_Middle",
      "rotation": 8
    },
    {
      "x": -12,
      "y": 10,
      "z": -7,
      "name": "Rock_Volcanic_Brick_Pillar_Middle",
      "rotation": 8
    },
    {
      "x": -12,
      "y": 11,
      "z": -7,
      "name": "Rock_Volcanic_Brick_Pillar_Middle",
      "rotation": 8
    },
    {
      "x": -12,
      "y": 12,
      "z": -7,
      "name": "Rock_Volcanic_Brick_Pillar_Base",
      "rotation": 8
    },
    {
      "x": -12,
      "y": 13,
      "z": -7,
      "name": "Rock_Volcanic_Brick",
      "rotation": 2
    },
    {
      "x": -12,
      "y": 14,
      "z": -7,
      "name": "Rock_Volcanic_Brick",
      "rotation": 2
    },
    {
      "x": -12,
      "y": 15,
      "z": -7,
      "name": "Rock_Volcanic_Brick",
      "rotation": 2
    },
    {
      "x": -12,
      "y": 16,
      "z": -7,
      "name": "Rock_Volcanic_Brick_Roof_Steep",
      "rotation": 3
    },
    {
      "x": -12,
      "y": 17,
      "z": -7,
      "name": "Rock_Volcanic_Brick_Roof_Steep",
      "filler": 1024,
      "rotation": 3
    },
    {
      "x": -12,
      "y": 6,
      "z": -3,
      "name": "Rock_Volcanic_Brick_Stairs",
      "rotation": 9
    },
    {
      "x": -12,
      "y": 7,
      "z": -3,
      "name": "Rock_Volcanic_Brick_Pillar_Base"
    },
    {
      "x": -12,
      "y": 8,
      "z": -3,
      "name": "Rock_Volcanic_Brick_Pillar_Middle",
      "rotation": 8
    },
    {
      "x": -12,
      "y": 9,
      "z": -3,
      "name": "Rock_Volcanic_Brick_Pillar_Middle",
      "rotation": 8
    },
    {
      "x": -12,
      "y": 10,
      "z": -3,
      "name": "Rock_Volcanic_Brick_Pillar_Middle",
      "rotation": 8
    },
    {
      "x": -12,
      "y": 11,
      "z": -3,
      "name": "Rock_Volcanic_Brick_Pillar_Middle",
      "rotation": 8
    },
    {
      "x": -12,
      "y": 12,
      "z": -3,
      "name": "Rock_Volcanic_Brick_Pillar_Base",
      "rotation": 8
    },
    {
      "x": -12,
      "y": 13,
      "z": -3,
      "name": "Rock_Volcanic_Brick",
      "rotation": 2
    },
    {
      "x": -12,
      "y": 14,
      "z": -3,
      "name": "Rock_Volcanic_Brick",
      "rotation": 2
    },
    {
      "x": -12,
      "y": 15,
      "z": -3,
      "name": "Rock_Volcanic_Brick",
      "rotation": 2
    },
    {
      "x": -12,
      "y": 16,
      "z": -3,
      "name": "Rock_Volcanic_Brick_Roof_Steep",
      "rotation": 3
    },
    {
      "x": -12,
      "y": 17,
      "z": -3,
      "name": "Rock_Volcanic_Brick_Roof_Steep",
      "filler": 1024,
      "rotation": 3
    },
    {
      "x": -12,
      "y": 6,
      "z": 1,
      "name": "Rock_Volcanic_Brick_Stairs",
      "rotation": 9
    },
    {
      "x": -12,
      "y": 7,
      "z": 1,
      "name": "Rock_Volcanic_Brick_Pillar_Base"
    },
    {
      "x": -12,
      "y": 8,
      "z": 1,
      "name": "Rock_Volcanic_Brick_Pillar_Middle",
      "rotation": 8
    },
    {
      "x": -12,
      "y": 9,
      "z": 1,
      "name": "Rock_Volcanic_Brick_Pillar_Middle",
      "rotation": 8
    },
    {
      "x": -12,
      "y": 10,
      "z": 1,
      "name": "Rock_Volcanic_Brick_Pillar_Middle",
      "rotation": 8
    },
    {
      "x": -12,
      "y": 11,
      "z": 1,
      "name": "Rock_Volcanic_Brick_Pillar_Middle",
      "rotation": 8
    },
    {
      "x": -12,
      "y": 12,
      "z": 1,
      "name": "Rock_Volcanic_Brick_Pillar_Base",
      "rotation": 8
    },
    {
      "x": -12,
      "y": 13,
      "z": 1,
      "name": "Rock_Volcanic_Brick",
      "rotation": 2
    },
    {
      "x": -12,
      "y": 14,
      "z": 1,
      "name": "Rock_Volcanic_Brick",
      "rotation": 2
    },
    {
      "x": -12,
      "y": 15,
      "z": 1,
      "name": "Rock_Volcanic_Brick",
      "rotation": 2
    },
    {
      "x": -12,
      "y": 16,
      "z": 1,
      "name": "Rock_Volcanic_Brick_Roof_Steep",
      "rotation": 3
    },
    {
      "x": -12,
      "y": 17,
      "z": 1,
      "name": "Rock_Volcanic_Brick_Roof_Steep",
      "filler": 1024,
      "rotation": 3
    },
    {
      "x": -12,
      "y": 6,
      "z": 5,
      "name": "Rock_Volcanic_Brick_Stairs",
      "rotation": 9
    },
    {
      "x": -12,
      "y": 7,
      "z": 5,
      "name": "Rock_Volcanic_Brick_Pillar_Base"
    },
    {
      "x": -12,
      "y": 8,
      "z": 5,
      "name": "Rock_Volcanic_Brick_Pillar_Middle",
      "rotation": 8
    },
    {
      "x": -12,
      "y": 9,
      "z": 5,
      "name": "Rock_Volcanic_Brick_Pillar_Middle",
      "rotation": 8
    },
    {
      "x": -12,
      "y": 10,
      "z": 5,
      "name": "Rock_Volcanic_Brick_Pillar_Middle",
      "rotation": 8
    },
    {
      "x": -12,
      "y": 11,
      "z": 5,
      "name": "Rock_Volcanic_Brick_Pillar_Middle",
      "rotation": 8
    },
    {
      "x": -12,
      "y": 12,
      "z": 5,
      "name": "Rock_Volcanic_Brick_Pillar_Base",
      "rotation": 8
    },
    {
      "x": -12,
      "y": 13,
      "z": 5,
      "name": "Rock_Volcanic_Brick",
      "rotation": 2
    },
    {
      "x": -12,
      "y": 14,
      "z": 5,
      "name": "Rock_Volcanic_Brick",
      "rotation": 2
    },
    {
      "x": -12,
      "y": 15,
      "z": 5,
      "name": "Rock_Volcanic_Brick",
      "rotation": 2
    },
    {
      "x": -12,
      "y": 16,
      "z": 5,
      "name": "Rock_Volcanic_Brick_Roof_Steep",
      "rotation": 3
    },
    {
      "x": -12,
      "y": 17,
      "z": 5,
      "name": "Rock_Volcanic_Brick_Roof_Steep",
      "filler": 1024,
      "rotation": 3
    },
    {
      "x": -12,
      "y": 6,
      "z": 9,
      "name": "Rock_Volcanic_Brick_Stairs",
      "rotation": 9
    },
    {
      "x": -12,
      "y": 7,
      "z": 9,
      "name": "Rock_Volcanic_Brick_Pillar_Base"
    },
    {
      "x": -12,
      "y": 8,
      "z": 9,
      "name": "Rock_Volcanic_Brick_Pillar_Middle",
      "rotation": 8
    },
    {
      "x": -12,
      "y": 9,
      "z": 9,
      "name": "Rock_Volcanic_Brick_Pillar_Middle",
      "rotation": 8
    },
    {
      "x": -12,
      "y": 10,
      "z": 9,
      "name": "Rock_Volcanic_Brick_Pillar_Middle",
      "rotation": 8
    },
    {
      "x": -12,
      "y": 11,
      "z": 9,
      "name": "Rock_Volcanic_Brick_Pillar_Middle",
      "rotation": 8
    },
    {
      "x": -12,
      "y": 12,
      "z": 9,
      "name": "Rock_Volcanic_Brick_Pillar_Base",
      "rotation": 8
    },
    {
      "x": -12,
      "y": 13,
      "z": 9,
      "name": "Rock_Volcanic_Brick",
      "rotation": 2
    },
    {
      "x": -12,
      "y": 14,
      "z": 9,
      "name": "Rock_Volcanic_Brick",
      "rotation": 2
    },
    {
      "x": -12,
      "y": 15,
      "z": 9,
      "name": "Rock_Volcanic_Brick",
      "rotation": 2
    },
    {
      "x": -12,
      "y": 16,
      "z": 9,
      "name": "Rock_Volcanic_Brick_Roof_Steep",
      "rotation": 3
    },
    {
      "x": -12,
      "y": 17,
      "z": 9,
      "name": "Rock_Volcanic_Brick_Roof_Steep",
      "filler": 1024,
      "rotation": 3
    },
    {
      "x": -12,
      "y": 6,
      "z": 13,
      "name": "Rock_Volcanic_Brick_Stairs",
      "rotation": 9
    },
    {
      "x": -12,
      "y": 7,
      "z": 13,
      "name": "Rock_Volcanic_Brick_Pillar_Base"
    },
    {
      "x": -12,
      "y": 8,
      "z": 13,
      "name": "Rock_Volcanic_Brick_Pillar_Middle",
      "rotation": 8
    },
    {
      "x": -12,
      "y": 9,
      "z": 13,
      "name": "Rock_Volcanic_Brick_Pillar_Middle",
      "rotation": 8
    },
    {
      "x": -12,
      "y": 10,
      "z": 13,
      "name": "Rock_Volcanic_Brick_Pillar_Middle",
      "rotation": 8
    },
    {
      "x": -12,
      "y": 11,
      "z": 13,
      "name": "Rock_Volcanic_Brick_Pillar_Middle",
      "rotation": 8
    },
    {
      "x": -12,
      "y": 12,
      "z": 13,
      "name": "Rock_Volcanic_Brick_Pillar_Base",
      "rotation": 8
    },
    {
      "x": -12,
      "y": 13,
      "z": 13,
      "name": "Rock_Volcanic_Brick",
      "rotation": 2
    },
    {
      "x": -12,
      "y": 14,
      "z": 13,
      "name": "Rock_Volcanic_Brick",
      "rotation": 2
    },
    {
      "x": -12,
      "y": 15,
      "z": 13,
      "name": "Rock_Volcanic_Brick",
      "rotation": 2
    },
    {
      "x": -12,
      "y": 16,
      "z": 13,
      "name": "Rock_Volcanic_Brick_Roof_Steep",
      "rotation": 3
    },
    {
      "x": -12,
      "y": 17,
      "z": 13,
      "name": "Rock_Volcanic_Brick_Roof_Steep",
      "filler": 1024,
      "rotation": 3
    },
    {
      "x": -11,
      "y": 14,
      "z": -15,
      "name": "Rock_Volcanic_Cobble_Roof_Hollow",
      "rotation": 3
    },
    {
      "x": -11,
      "y": 13,
      "z": -14,
      "name": "Rock_Volcanic_Brick",
      "rotation": 2
    },
    {
      "x": -11,
      "y": 14,
      "z": -14,
      "name": "Rock_Volcanic_Cobble_Roof",
      "rotation": 3
    },
    {
      "x": -11,
      "y": 13,
      "z": -13,
      "name": "Rock_Volcanic_Brick",
      "rotation": 2
    },
    {
      "x": -11,
      "y": 14,
      "z": -13,
      "name": "Rock_Volcanic_Cobble_Roof",
      "rotation": 3
    },
    {
      "x": -11,
      "y": 13,
      "z": -12,
      "name": "Rock_Volcanic_Brick",
      "rotation": 2
    },
    {
      "x": -11,
      "y": 14,
      "z": -12,
      "name": "Rock_Volcanic_Cobble_Roof",
      "rotation": 3
    },
    {
      "x": -11,
      "y": 5,
      "z": -11,
      "name": "Rock_Volcanic_Brick_Stairs",
      "rotation": 9
    },
    {
      "x": -11,
      "y": 6,
      "z": -11,
      "name": "Rock_Volcanic_Brick_Stairs",
      "rotation": 1
    },
    {
      "x": -11,
      "y": 12,
      "z": -11,
      "name": "Rock_Volcanic_Brick_Stairs",
      "rotation": 9
    },
    {
      "x": -11,
      "y": 13,
      "z": -11,
      "name": "Rock_Volcanic_Brick",
      "rotation": 2
    },
    {
      "x": -11,
      "y": 14,
      "z": -11,
      "name": "Rock_Volcanic_Brick_Stairs",
      "rotation": 3
    },
    {
      "x": -11,
      "y": 16,
      "z": -11,
      "name": "Rock_Volcanic_Brick_Stairs",
      "rotation": 33
    },
    {
      "x": -11,
      "y": 17,
      "z": -11,
      "name": "Rock_Volcanic_Brick",
      "rotation": 2
    },
    {
      "x": -11,
      "y": 18,
      "z": -11,
      "name": "Rock_Volcanic_Brick_Roof_Steep",
      "rotation": 3
    },
    {
      "x": -11,
      "y": 19,
      "z": -11,
      "name": "Rock_Volcanic_Brick_Roof_Steep",
      "filler": 1024,
      "rotation": 3
    },
    {
      "x": -11,
      "y": 7,
      "z": -10,
      "name": "Rock_Volcanic_Brick_Stairs",
      "rotation": 35
    },
    {
      "x": -11,
      "y": 8,
      "z": -10,
      "name": "Rock_Volcanic_Brick_Wall",
      "rotation": 3
    },
    {
      "x": -11,
      "y": 13,
      "z": -10,
      "name": "Rock_Volcanic_Brick",
      "rotation": 2
    },
    {
      "x": -11,
      "y": 14,
      "z": -10,
      "name": "Rock_Volcanic_Cobble_Roof",
      "rotation": 3
    },
    {
      "x": -11,
      "y": 7,
      "z": -9,
      "name": "Rock_Volcanic_Brick_Stairs",
      "rotation": 35
    },
    {
      "x": -11,
      "y": 8,
      "z": -9,
      "name": "Rock_Volcanic_Brick_Wall",
      "rotation": 3
    },
    {
      "x": -11,
      "y": 13,
      "z": -9,
      "name": "Rock_Volcanic_Brick",
      "rotation": 2
    },
    {
      "x": -11,
      "y": 14,
      "z": -9,
      "name": "Rock_Volcanic_Cobble_Roof",
      "rotation": 3
    },
    {
      "x": -11,
      "y": 7,
      "z": -8,
      "name": "Rock_Volcanic_Brick_Stairs",
      "rotation": 35
    },
    {
      "x": -11,
      "y": 8,
      "z": -8,
      "name": "Rock_Volcanic_Brick_Wall",
      "rotation": 3
    },
    {
      "x": -11,
      "y": 13,
      "z": -8,
      "name": "Rock_Volcanic_Brick",
      "rotation": 2
    },
    {
      "x": -11,
      "y": 14,
      "z": -8,
      "name": "Rock_Volcanic_Cobble_Roof",
      "rotation": 3
    },
    {
      "x": -11,
      "y": 5,
      "z": -7,
      "name": "Rock_Volcanic_Brick_Stairs",
      "rotation": 9
    },
    {
      "x": -11,
      "y": 6,
      "z": -7,
      "name": "Rock_Volcanic_Brick_Stairs",
      "rotation": 1
    },
    {
      "x": -11,
      "y": 12,
      "z": -7,
      "name": "Rock_Volcanic_Brick_Stairs",
      "rotation": 9
    },
    {
      "x": -11,
      "y": 13,
      "z": -7,
      "name": "Rock_Volcanic_Brick",
      "rotation": 2
    },
    {
      "x": -11,
      "y": 14,
      "z": -7,
      "name": "Rock_Volcanic_Brick_Stairs",
      "rotation": 3
    },
    {
      "x": -11,
      "y": 16,
      "z": -7,
      "name": "Rock_Volcanic_Brick_Stairs",
      "rotation": 33
    },
    {
      "x": -11,
      "y": 17,
      "z": -7,
      "name": "Rock_Volcanic_Brick",
      "rotation": 2
    },
    {
      "x": -11,
      "y": 18,
      "z": -7,
      "name": "Rock_Volcanic_Brick_Roof_Steep",
      "rotation": 3
    },
    {
      "x": -11,
      "y": 19,
      "z": -7,
      "name": "Rock_Volcanic_Brick_Roof_Steep",
      "filler": 1024,
      "rotation": 3
    },
    {
      "x": -11,
      "y": 7,
      "z": -6,
      "name": "Rock_Volcanic_Brick_Stairs",
      "rotation": 35
    },
    {
      "x": -11,
      "y": 8,
      "z": -6,
      "name": "Rock_Volcanic_Brick_Wall",
      "rotation": 3
    },
    {
      "x": -11,
      "y": 13,
      "z": -6,
      "name": "Rock_Volcanic_Brick",
      "rotation": 2
    },
    {
      "x": -11,
      "y": 14,
      "z": -6,
      "name": "Rock_Volcanic_Cobble_Roof",
      "rotation": 3
    },
    {
      "x": -11,
      "y": 7,
      "z": -5,
      "name": "Rock_Volcanic_Brick_Stairs",
      "rotation": 35
    },
    {
      "x": -11,
      "y": 8,
      "z": -5,
      "name": "Rock_Volcanic_Brick_Wall",
      "rotation": 3
    },
    {
      "x": -11,
      "y": 13,
      "z": -5,
      "name": "Rock_Volcanic_Brick",
      "rotation": 2
    },
    {
      "x": -11,
      "y": 14,
      "z": -5,
      "name": "Rock_Volcanic_Cobble_Roof",
      "rotation": 3
    },
    {
      "x": -11,
      "y": 7,
      "z": -4,
      "name": "Rock_Volcanic_Brick_Stairs",
      "rotation": 35
    },
    {
      "x": -11,
      "y": 8,
      "z": -4,
      "name": "Rock_Volcanic_Brick_Wall",
      "rotation": 3
    },
    {
      "x": -11,
      "y": 13,
      "z": -4,
      "name": "Rock_Volcanic_Brick",
      "rotation": 2
    },
    {
      "x": -11,
      "y": 14,
      "z": -4,
      "name": "Rock_Volcanic_Cobble_Roof",
      "rotation": 3
    },
    {
      "x": -11,
      "y": 5,
      "z": -3,
      "name": "Rock_Volcanic_Brick_Stairs",
      "rotation": 9
    },
    {
      "x": -11,
      "y": 6,
      "z": -3,
      "name": "Rock_Volcanic_Brick_Stairs",
      "rotation": 1
    },
    {
      "x": -11,
      "y": 12,
      "z": -3,
      "name": "Rock_Volcanic_Brick_Stairs",
      "rotation": 9
    },
    {
      "x": -11,
      "y": 13,
      "z": -3,
      "name": "Rock_Volcanic_Brick",
      "rotation": 2
    },
    {
      "x": -11,
      "y": 14,
      "z": -3,
      "name": "Rock_Volcanic_Brick_Stairs",
      "rotation": 3
    },
    {
      "x": -11,
      "y": 16,
      "z": -3,
      "name": "Rock_Volcanic_Brick_Stairs",
      "rotation": 33
    },
    {
      "x": -11,
      "y": 17,
      "z": -3,
      "name": "Rock_Volcanic_Brick",
      "rotation": 2
    },
    {
      "x": -11,
      "y": 18,
      "z": -3,
      "name": "Rock_Volcanic_Brick_Roof_Steep",
      "rotation": 3
    },
    {
      "x": -11,
      "y": 19,
      "z": -3,
      "name": "Rock_Volcanic_Brick_Roof_Steep",
      "filler": 1024,
      "rotation": 3
    },
    {
      "x": -11,
      "y": 7,
      "z": -2,
      "name": "Rock_Volcanic_Brick_Stairs",
      "rotation": 35
    },
    {
      "x": -11,
      "y": 8,
      "z": -2,
      "name": "Rock_Volcanic_Brick_Wall",
      "rotation": 3
    },
    {
      "x": -11,
      "y": 13,
      "z": -2,
      "name": "Rock_Volcanic_Brick",
      "rotation": 2
    },
    {
      "x": -11,
      "y": 14,
      "z": -2,
      "name": "Rock_Volcanic_Cobble_Roof",
      "rotation": 3
    },
    {
      "x": -11,
      "y": 7,
      "z": -1,
      "name": "Rock_Volcanic_Brick_Stairs",
      "rotation": 35
    },
    {
      "x": -11,
      "y": 8,
      "z": -1,
      "name": "Rock_Volcanic_Brick_Wall",
      "rotation": 3
    },
    {
      "x": -11,
      "y": 13,
      "z": -1,
      "name": "Rock_Volcanic_Brick",
      "rotation": 2
    },
    {
      "x": -11,
      "y": 14,
      "z": -1,
      "name": "Rock_Volcanic_Cobble_Roof",
      "rotation": 3
    },
    {
      "x": -11,
      "y": 7,
      "z": 0,
      "name": "Rock_Volcanic_Brick_Stairs",
      "rotation": 35
    },
    {
      "x": -11,
      "y": 8,
      "z": 0,
      "name": "Rock_Volcanic_Brick_Wall",
      "rotation": 3
    },
    {
      "x": -11,
      "y": 13,
      "z": 0,
      "name": "Rock_Volcanic_Brick",
      "rotation": 2
    },
    {
      "x": -11,
      "y": 14,
      "z": 0,
      "name": "Rock_Volcanic_Cobble_Roof",
      "rotation": 3
    },
    {
      "x": -11,
      "y": 5,
      "z": 1,
      "name": "Rock_Volcanic_Brick_Stairs",
      "rotation": 9
    },
    {
      "x": -11,
      "y": 6,
      "z": 1,
      "name": "Rock_Volcanic_Brick_Stairs",
      "rotation": 1
    },
    {
      "x": -11,
      "y": 12,
      "z": 1,
      "name": "Rock_Volcanic_Brick_Stairs",
      "rotation": 9
    },
    {
      "x": -11,
      "y": 13,
      "z": 1,
      "name": "Rock_Volcanic_Brick",
      "rotation": 2
    },
    {
      "x": -11,
      "y": 14,
      "z": 1,
      "name": "Rock_Volcanic_Brick_Stairs",
      "rotation": 3
    },
    {
      "x": -11,
      "y": 16,
      "z": 1,
      "name": "Rock_Volcanic_Brick_Stairs",
      "rotation": 33
    },
    {
      "x": -11,
      "y": 17,
      "z": 1,
      "name": "Rock_Volcanic_Brick",
      "rotation": 2
    },
    {
      "x": -11,
      "y": 18,
      "z": 1,
      "name": "Rock_Volcanic_Brick_Roof_Steep",
      "rotation": 3
    },
    {
      "x": -11,
      "y": 19,
      "z": 1,
      "name": "Rock_Volcanic_Brick_Roof_Steep",
      "filler": 1024,
      "rotation": 3
    },
    {
      "x": -11,
      "y": 7,
      "z": 2,
      "name": "Rock_Volcanic_Brick_Stairs",
      "rotation": 35
    },
    {
      "x": -11,
      "y": 8,
      "z": 2,
      "name": "Rock_Volcanic_Brick_Wall",
      "rotation": 3
    },
    {
      "x": -11,
      "y": 13,
      "z": 2,
      "name": "Rock_Volcanic_Brick",
      "rotation": 2
    },
    {
      "x": -11,
      "y": 14,
      "z": 2,
      "name": "Rock_Volcanic_Cobble_Roof",
      "rotation": 3
    },
    {
      "x": -11,
      "y": 7,
      "z": 3,
      "name": "Rock_Volcanic_Brick_Stairs",
      "rotation": 35
    },
    {
      "x": -11,
      "y": 8,
      "z": 3,
      "name": "Rock_Volcanic_Brick_Wall",
      "rotation": 3
    },
    {
      "x": -11,
      "y": 13,
      "z": 3,
      "name": "Rock_Volcanic_Brick",
      "rotation": 2
    },
    {
      "x": -11,
      "y": 14,
      "z": 3,
      "name": "Rock_Volcanic_Cobble_Roof",
      "rotation": 3
    },
    {
      "x": -11,
      "y": 7,
      "z": 4,
      "name": "Rock_Volcanic_Brick_Stairs",
      "rotation": 35
    },
    {
      "x": -11,
      "y": 8,
      "z": 4,
      "name": "Rock_Volcanic_Brick_Wall",
      "rotation": 3
    },
    {
      "x": -11,
      "y": 13,
      "z": 4,
      "name": "Rock_Volcanic_Brick",
      "rotation": 2
    },
    {
      "x": -11,
      "y": 14,
      "z": 4,
      "name": "Rock_Volcanic_Cobble_Roof",
      "rotation": 3
    },
    {
      "x": -11,
      "y": 5,
      "z": 5,
      "name": "Rock_Volcanic_Brick_Stairs",
      "rotation": 9
    },
    {
      "x": -11,
      "y": 6,
      "z": 5,
      "name": "Rock_Volcanic_Brick_Stairs",
      "rotation": 1
    },
    {
      "x": -11,
      "y": 12,
      "z": 5,
      "name": "Rock_Volcanic_Brick_Stairs",
      "rotation": 9
    },
    {
      "x": -11,
      "y": 13,
      "z": 5,
      "name": "Rock_Volcanic_Brick",
      "rotation": 2
    },
    {
      "x": -11,
      "y": 14,
      "z": 5,
      "name": "Rock_Volcanic_Brick_Stairs",
      "rotation": 3
    },
    {
      "x": -11,
      "y": 16,
      "z": 5,
      "name": "Rock_Volcanic_Brick_Stairs",
      "rotation": 33
    },
    {
      "x": -11,
      "y": 17,
      "z": 5,
      "name": "Rock_Volcanic_Brick",
      "rotation": 2
    },
    {
      "x": -11,
      "y": 18,
      "z": 5,
      "name": "Rock_Volcanic_Brick_Roof_Steep",
      "rotation": 3
    },
    {
      "x": -11,
      "y": 19,
      "z": 5,
      "name": "Rock_Volcanic_Brick_Roof_Steep",
      "filler": 1024,
      "rotation": 3
    },
    {
      "x": -11,
      "y": 7,
      "z": 6,
      "name": "Rock_Volcanic_Brick_Stairs",
      "rotation": 35
    },
    {
      "x": -11,
      "y": 8,
      "z": 6,
      "name": "Rock_Volcanic_Brick_Wall",
      "rotation": 3
    },
    {
      "x": -11,
      "y": 13,
      "z": 6,
      "name": "Rock_Volcanic_Brick",
      "rotation": 2
    },
    {
      "x": -11,
      "y": 14,
      "z": 6,
      "name": "Rock_Volcanic_Cobble_Roof",
      "rotation": 3
    },
    {
      "x": -11,
      "y": 7,
      "z": 7,
      "name": "Rock_Volcanic_Brick_Stairs",
      "rotation": 35
    },
    {
      "x": -11,
      "y": 8,
      "z": 7,
      "name": "Rock_Volcanic_Brick_Wall",
      "rotation": 3
    },
    {
      "x": -11,
      "y": 13,
      "z": 7,
      "name": "Rock_Volcanic_Brick",
      "rotation": 2
    },
    {
      "x": -11,
      "y": 14,
      "z": 7,
      "name": "Rock_Volcanic_Cobble_Roof",
      "rotation": 3
    },
    {
      "x": -11,
      "y": 7,
      "z": 8,
      "name": "Rock_Volcanic_Brick_Stairs",
      "rotation": 35
    },
    {
      "x": -11,
      "y": 8,
      "z": 8,
      "name": "Rock_Volcanic_Brick_Wall",
      "rotation": 3
    },
    {
      "x": -11,
      "y": 13,
      "z": 8,
      "name": "Rock_Volcanic_Brick",
      "rotation": 2
    },
    {
      "x": -11,
      "y": 14,
      "z": 8,
      "name": "Rock_Volcanic_Cobble_Roof",
      "rotation": 3
    },
    {
      "x": -11,
      "y": 5,
      "z": 9,
      "name": "Rock_Volcanic_Brick_Stairs",
      "rotation": 9
    },
    {
      "x": -11,
      "y": 6,
      "z": 9,
      "name": "Rock_Volcanic_Brick_Stairs",
      "rotation": 1
    },
    {
      "x": -11,
      "y": 12,
      "z": 9,
      "name": "Rock_Volcanic_Brick_Stairs",
      "rotation": 9
    },
    {
      "x": -11,
      "y": 13,
      "z": 9,
      "name": "Rock_Volcanic_Brick",
      "rotation": 2
    },
    {
      "x": -11,
      "y": 14,
      "z": 9,
      "name": "Rock_Volcanic_Brick_Stairs",
      "rotation": 3
    },
    {
      "x": -11,
      "y": 16,
      "z": 9,
      "name": "Rock_Volcanic_Brick_Stairs",
      "rotation": 33
    },
    {
      "x": -11,
      "y": 17,
      "z": 9,
      "name": "Rock_Volcanic_Brick",
      "rotation": 2
    },
    {
      "x": -11,
      "y": 18,
      "z": 9,
      "name": "Rock_Volcanic_Brick_Roof_Steep",
      "rotation": 3
    },
    {
      "x": -11,
      "y": 19,
      "z": 9,
      "name": "Rock_Volcanic_Brick_Roof_Steep",
      "filler": 1024,
      "rotation": 3
    },
    {
      "x": -11,
      "y": 7,
      "z": 10,
      "name": "Rock_Volcanic_Brick_Stairs",
      "rotation": 35
    },
    {
      "x": -11,
      "y": 8,
      "z": 10,
      "name": "Rock_Volcanic_Brick_Wall",
      "rotation": 3
    },
    {
      "x": -11,
      "y": 13,
      "z": 10,
      "name": "Rock_Volcanic_Brick",
      "rotation": 2
    },
    {
      "x": -11,
      "y": 14,
      "z": 10,
      "name": "Rock_Volcanic_Cobble_Roof",
      "rotation": 3
    },
    {
      "x": -11,
      "y": 7,
      "z": 11,
      "name": "Rock_Volcanic_Brick_Stairs",
      "rotation": 35
    },
    {
      "x": -11,
      "y": 8,
      "z": 11,
      "name": "Rock_Volcanic_Brick_Wall",
      "rotation": 3
    },
    {
      "x": -11,
      "y": 13,
      "z": 11,
      "name": "Rock_Volcanic_Brick",
      "rotation": 2
    },
    {
      "x": -11,
      "y": 14,
      "z": 11,
      "name": "Rock_Volcanic_Cobble_Roof",
      "rotation": 3
    },
    {
      "x": -11,
      "y": 7,
      "z": 12,
      "name": "Rock_Volcanic_Brick_Stairs",
      "rotation": 35
    },
    {
      "x": -11,
      "y": 8,
      "z": 12,
      "name": "Rock_Volcanic_Brick_Wall",
      "rotation": 3
    },
    {
      "x": -11,
      "y": 13,
      "z": 12,
      "name": "Rock_Volcanic_Brick",
      "rotation": 2
    },
    {
      "x": -11,
      "y": 14,
      "z": 12,
      "name": "Rock_Volcanic_Cobble_Roof",
      "rotation": 3
    },
    {
      "x": -11,
      "y": 5,
      "z": 13,
      "name": "Rock_Volcanic_Brick_Stairs",
      "rotation": 9
    },
    {
      "x": -11,
      "y": 6,
      "z": 13,
      "name": "Rock_Volcanic_Brick_Stairs",
      "rotation": 1
    },
    {
      "x": -11,
      "y": 12,
      "z": 13,
      "name": "Rock_Volcanic_Brick_Stairs",
      "rotation": 9
    },
    {
      "x": -11,
      "y": 13,
      "z": 13,
      "name": "Rock_Volcanic_Brick",
      "rotation": 2
    },
    {
      "x": -11,
      "y": 14,
      "z": 13,
      "name": "Rock_Volcanic_Brick_Stairs",
      "rotation": 3
    },
    {
      "x": -11,
      "y": 16,
      "z": 13,
      "name": "Rock_Volcanic_Brick_Stairs",
      "rotation": 33
    },
    {
      "x": -11,
      "y": 17,
      "z": 13,
      "name": "Rock_Volcanic_Brick",
      "rotation": 2
    },
    {
      "x": -11,
      "y": 18,
      "z": 13,
      "name": "Rock_Volcanic_Brick_Roof_Steep",
      "rotation": 3
    },
    {
      "x": -11,
      "y": 19,
      "z": 13,
      "name": "Rock_Volcanic_Brick_Roof_Steep",
      "filler": 1024,
      "rotation": 3
    },
    {
      "x": -11,
      "y": 14,
      "z": 14,
      "name": "Rock_Volcanic_Cobble_Roof_Hollow",
      "rotation": 3
    },
    {
      "x": -11,
      "y": 14,
      "z": 15,
      "name": "Rock_Volcanic_Cobble_Roof_Hollow",
      "rotation": 3
    },
    {
      "x": -11,
      "y": 14,
      "z": 16,
      "name": "Rock_Volcanic_Cobble_Roof_Hollow",
      "rotation": 3
    },
    {
      "x": -10,
      "y": 14,
      "z": -15,
      "name": "Rock_Volcanic_Brick_Stairs",
      "rotation": 8
    },
    {
      "x": -10,
      "y": 15,
      "z": -15,
      "name": "Rock_Volcanic_Cobble_Roof",
      "rotation": 3
    },
    {
      "x": -10,
      "y": 0,
      "z": -14,
      "name": "UnbreakableWall"
    },
    {
      "x": -10,
      "y": 1,
      "z": -14,
      "name": "UnbreakableWall"
    },
    {
      "x": -10,
      "y": 2,
      "z": -14,
      "name": "UnbreakableWall"
    },
    {
      "x": -10,
      "y": 3,
      "z": -14,
      "name": "UnbreakableWall"
    },
    {
      "x": -10,
      "y": 4,
      "z": -14,
      "name": "UnbreakableWall"
    },
    {
      "x": -10,
      "y": 5,
      "z": -14,
      "name": "UnbreakableWall"
    },
    {
      "x": -10,
      "y": 6,
      "z": -14,
      "name": "UnbreakableWall"
    },
    {
      "x": -10,
      "y": 7,
      "z": -14,
      "name": "UnbreakableWall",
      "rotation": 2
    },
    {
      "x": -10,
      "y": 8,
      "z": -14,
      "name": "UnbreakableWall",
      "rotation": 2
    },
    {
      "x": -10,
      "y": 9,
      "z": -14,
      "name": "UnbreakableWall",
      "rotation": 2
    },
    {
      "x": -10,
      "y": 10,
      "z": -14,
      "name": "UnbreakableWall",
      "rotation": 2
    },
    {
      "x": -10,
      "y": 11,
      "z": -14,
      "name": "UnbreakableWall",
      "rotation": 2
    },
    {
      "x": -10,
      "y": 12,
      "z": -14,
      "name": "UnbreakableWall",
      "rotation": 2
    },
    {
      "x": -10,
      "y": 13,
      "z": -14,
      "name": "UnbreakableWall",
      "rotation": 2
    },
    {
      "x": -10,
      "y": 14,
      "z": -14,
      "name": "UnbreakableWall",
      "rotation": 2
    },
    {
      "x": -10,
      "y": 15,
      "z": -14,
      "name": "Rock_Volcanic_Cobble_Roof",
      "rotation": 3
    },
    {
      "x": -10,
      "y": 0,
      "z": -13,
      "name": "UnbreakableWall"
    },
    {
      "x": -10,
      "y": 1,
      "z": -13,
      "name": "UnbreakableWall"
    },
    {
      "x": -10,
      "y": 2,
      "z": -13,
      "name": "UnbreakableWall"
    },
    {
      "x": -10,
      "y": 3,
      "z": -13,
      "name": "UnbreakableWall"
    },
    {
      "x": -10,
      "y": 4,
      "z": -13,
      "name": "UnbreakableWall"
    },
    {
      "x": -10,
      "y": 5,
      "z": -13,
      "name": "UnbreakableWall"
    },
    {
      "x": -10,
      "y": 6,
      "z": -13,
      "name": "UnbreakableWall"
    },
    {
      "x": -10,
      "y": 7,
      "z": -13,
      "name": "UnbreakableWall",
      "rotation": 2
    },
    {
      "x": -10,
      "y": 8,
      "z": -13,
      "name": "UnbreakableWall",
      "rotation": 2
    },
    {
      "x": -10,
      "y": 9,
      "z": -13,
      "name": "UnbreakableWall",
      "rotation": 2
    },
    {
      "x": -10,
      "y": 10,
      "z": -13,
      "name": "UnbreakableWall",
      "rotation": 2
    },
    {
      "x": -10,
      "y": 11,
      "z": -13,
      "name": "UnbreakableWall",
      "rotation": 2
    },
    {
      "x": -10,
      "y": 12,
      "z": -13,
      "name": "UnbreakableWall",
      "rotation": 2
    },
    {
      "x": -10,
      "y": 13,
      "z": -13,
      "name": "UnbreakableWall",
      "rotation": 2
    },
    {
      "x": -10,
      "y": 14,
      "z": -13,
      "name": "UnbreakableWall",
      "rotation": 2
    },
    {
      "x": -10,
      "y": 15,
      "z": -13,
      "name": "Rock_Volcanic_Cobble_Roof",
      "rotation": 3
    },
    {
      "x": -10,
      "y": 0,
      "z": -12,
      "name": "UnbreakableWall"
    },
    {
      "x": -10,
      "y": 1,
      "z": -12,
      "name": "UnbreakableWall"
    },
    {
      "x": -10,
      "y": 2,
      "z": -12,
      "name": "UnbreakableWall"
    },
    {
      "x": -10,
      "y": 3,
      "z": -12,
      "name": "UnbreakableWall"
    },
    {
      "x": -10,
      "y": 4,
      "z": -12,
      "name": "UnbreakableWall"
    },
    {
      "x": -10,
      "y": 5,
      "z": -12,
      "name": "UnbreakableWall"
    },
    {
      "x": -10,
      "y": 6,
      "z": -12,
      "name": "UnbreakableWall"
    },
    {
      "x": -10,
      "y": 7,
      "z": -12,
      "name": "UnbreakableWall",
      "rotation": 2
    },
    {
      "x": -10,
      "y": 8,
      "z": -12,
      "name": "UnbreakableWall",
      "rotation": 2
    },
    {
      "x": -10,
      "y": 9,
      "z": -12,
      "name": "UnbreakableWall",
      "rotation": 2
    },
    {
      "x": -10,
      "y": 10,
      "z": -12,
      "name": "UnbreakableWall",
      "rotation": 2
    },
    {
      "x": -10,
      "y": 11,
      "z": -12,
      "name": "UnbreakableWall",
      "rotation": 2
    },
    {
      "x": -10,
      "y": 12,
      "z": -12,
      "name": "UnbreakableWall",
      "rotation": 2
    },
    {
      "x": -10,
      "y": 13,
      "z": -12,
      "name": "UnbreakableWall",
      "rotation": 2
    },
    {
      "x": -10,
      "y": 14,
      "z": -12,
      "name": "UnbreakableWall",
      "rotation": 2
    },
    {
      "x": -10,
      "y": 15,
      "z": -12,
      "name": "Rock_Volcanic_Cobble_Roof",
      "rotation": 3
    },
    {
      "x": -10,
      "y": 0,
      "z": -11,
      "name": "UnbreakableWall"
    },
    {
      "x": -10,
      "y": 1,
      "z": -11,
      "name": "UnbreakableWall"
    },
    {
      "x": -10,
      "y": 2,
      "z": -11,
      "name": "UnbreakableWall"
    },
    {
      "x": -10,
      "y": 3,
      "z": -11,
      "name": "UnbreakableWall"
    },
    {
      "x": -10,
      "y": 4,
      "z": -11,
      "name": "UnbreakableWall"
    },
    {
      "x": -10,
      "y": 5,
      "z": -11,
      "name": "UnbreakableWall"
    },
    {
      "x": -10,
      "y": 6,
      "z": -11,
      "name": "UnbreakableWall"
    },
    {
      "x": -10,
      "y": 7,
      "z": -11,
      "name": "UnbreakableWall",
      "rotation": 2
    },
    {
      "x": -10,
      "y": 8,
      "z": -11,
      "name": "UnbreakableWall",
      "rotation": 2
    },
    {
      "x": -10,
      "y": 9,
      "z": -11,
      "name": "UnbreakableWall",
      "rotation": 2
    },
    {
      "x": -10,
      "y": 10,
      "z": -11,
      "name": "UnbreakableWall",
      "rotation": 2
    },
    {
      "x": -10,
      "y": 11,
      "z": -11,
      "name": "UnbreakableWall",
      "rotation": 2
    },
    {
      "x": -10,
      "y": 12,
      "z": -11,
      "name": "UnbreakableWall",
      "rotation": 2
    },
    {
      "x": -10,
      "y": 13,
      "z": -11,
      "name": "UnbreakableWall",
      "rotation": 2
    },
    {
      "x": -10,
      "y": 14,
      "z": -11,
      "name": "UnbreakableWall",
      "rotation": 2
    },
    {
      "x": -10,
      "y": 15,
      "z": -11,
      "name": "Rock_Volcanic_Brick_Stairs",
      "rotation": 3
    },
    {
      "x": -10,
      "y": 18,
      "z": -11,
      "name": "Rock_Volcanic_Brick_Stairs",
      "rotation": 33
    },
    {
      "x": -10,
      "y": 19,
      "z": -11,
      "name": "Rock_Volcanic_Brick",
      "rotation": 2
    },
    {
      "x": -10,
      "y": 20,
      "z": -11,
      "name": "Rock_Volcanic_Stalactite_Large",
      "rotation": 2
    },
    {
      "x": -10,
      "y": 21,
      "z": -11,
      "name": "Rock_Volcanic_Stalactite_Large",
      "filler": 1024,
      "rotation": 2
    },
    {
      "x": -10,
      "y": 0,
      "z": -10,
      "name": "UnbreakableWall"
    },
    {
      "x": -10,
      "y": 1,
      "z": -10,
      "name": "UnbreakableWall"
    },
    {
      "x": -10,
      "y": 2,
      "z": -10,
      "name": "UnbreakableWall"
    },
    {
      "x": -10,
      "y": 3,
      "z": -10,
      "name": "UnbreakableWall"
    },
    {
      "x": -10,
      "y": 4,
      "z": -10,
      "name": "UnbreakableWall"
    },
    {
      "x": -10,
      "y": 5,
      "z": -10,
      "name": "UnbreakableWall"
    },
    {
      "x": -10,
      "y": 6,
      "z": -10,
      "name": "UnbreakableWall"
    },
    {
      "x": -10,
      "y": 7,
      "z": -10,
      "name": "UnbreakableWall",
      "rotation": 2
    },
    {
      "x": -10,
      "y": 8,
      "z": -10,
      "name": "Furniture_Temple_Wind_Window",
      "rotation": 3
    },
    {
      "x": -10,
      "y": 9,
      "z": -10,
      "name": "Furniture_Temple_Wind_Window",
      "rotation": 3
    },
    {
      "x": -10,
      "y": 10,
      "z": -10,
      "name": "Furniture_Temple_Wind_Window",
      "rotation": 3
    },
    {
      "x": -10,
      "y": 11,
      "z": -10,
      "name": "Furniture_Temple_Wind_Window",
      "rotation": 3
    },
    {
      "x": -10,
      "y": 12,
      "z": -10,
      "name": "UnbreakableWall",
      "rotation": 2
    },
    {
      "x": -10,
      "y": 13,
      "z": -10,
      "name": "UnbreakableWall",
      "rotation": 2
    },
    {
      "x": -10,
      "y": 14,
      "z": -10,
      "name": "UnbreakableWall",
      "rotation": 2
    },
    {
      "x": -10,
      "y": 15,
      "z": -10,
      "name": "Rock_Volcanic_Cobble_Roof",
      "rotation": 3
    },
    {
      "x": -10,
      "y": 0,
      "z": -9,
      "name": "UnbreakableWall"
    },
    {
      "x": -10,
      "y": 1,
      "z": -9,
      "name": "UnbreakableWall"
    },
    {
      "x": -10,
      "y": 2,
      "z": -9,
      "name": "UnbreakableWall"
    },
    {
      "x": -10,
      "y": 3,
      "z": -9,
      "name": "UnbreakableWall"
    },
    {
      "x": -10,
      "y": 4,
      "z": -9,
      "name": "UnbreakableWall"
    },
    {
      "x": -10,
      "y": 5,
      "z": -9,
      "name": "UnbreakableWall"
    },
    {
      "x": -10,
      "y": 6,
      "z": -9,
      "name": "UnbreakableWall"
    },
    {
      "x": -10,
      "y": 7,
      "z": -9,
      "name": "UnbreakableWall",
      "rotation": 2
    },
    {
      "x": -10,
      "y": 8,
      "z": -9,
      "name": "Furniture_Temple_Wind_Window",
      "rotation": 3
    },
    {
      "x": -10,
      "y": 9,
      "z": -9,
      "name": "Furniture_Temple_Wind_Window",
      "rotation": 3
    },
    {
      "x": -10,
      "y": 10,
      "z": -9,
      "name": "Furniture_Temple_Wind_Window",
      "rotation": 3
    },
    {
      "x": -10,
      "y": 11,
      "z": -9,
      "name": "Furniture_Temple_Wind_Window",
      "rotation": 3
    },
    {
      "x": -10,
      "y": 12,
      "z": -9,
      "name": "Furniture_Temple_Wind_Window",
      "rotation": 3
    },
    {
      "x": -10,
      "y": 13,
      "z": -9,
      "name": "UnbreakableWall",
      "rotation": 2
    },
    {
      "x": -10,
      "y": 14,
      "z": -9,
      "name": "UnbreakableWall",
      "rotation": 2
    },
    {
      "x": -10,
      "y": 15,
      "z": -9,
      "name": "Rock_Volcanic_Cobble_Roof",
      "rotation": 3
    },
    {
      "x": -10,
      "y": 0,
      "z": -8,
      "name": "UnbreakableWall"
    },
    {
      "x": -10,
      "y": 1,
      "z": -8,
      "name": "UnbreakableWall"
    },
    {
      "x": -10,
      "y": 2,
      "z": -8,
      "name": "UnbreakableWall"
    },
    {
      "x": -10,
      "y": 3,
      "z": -8,
      "name": "UnbreakableWall"
    },
    {
      "x": -10,
      "y": 4,
      "z": -8,
      "name": "UnbreakableWall"
    },
    {
      "x": -10,
      "y": 5,
      "z": -8,
      "name": "UnbreakableWall"
    },
    {
      "x": -10,
      "y": 6,
      "z": -8,
      "name": "UnbreakableWall"
    },
    {
      "x": -10,
      "y": 7,
      "z": -8,
      "name": "UnbreakableWall",
      "rotation": 2
    },
    {
      "x": -10,
      "y": 8,
      "z": -8,
      "name": "Furniture_Temple_Wind_Window",
      "rotation": 3
    },
    {
      "x": -10,
      "y": 9,
      "z": -8,
      "name": "Furniture_Temple_Wind_Window",
      "rotation": 3
    },
    {
      "x": -10,
      "y": 10,
      "z": -8,
      "name": "Furniture_Temple_Wind_Window",
      "rotation": 3
    },
    {
      "x": -10,
      "y": 11,
      "z": -8,
      "name": "Furniture_Temple_Wind_Window",
      "rotation": 3
    },
    {
      "x": -10,
      "y": 12,
      "z": -8,
      "name": "UnbreakableWall",
      "rotation": 2
    },
    {
      "x": -10,
      "y": 13,
      "z": -8,
      "name": "UnbreakableWall",
      "rotation": 2
    },
    {
      "x": -10,
      "y": 14,
      "z": -8,
      "name": "UnbreakableWall",
      "rotation": 2
    },
    {
      "x": -10,
      "y": 15,
      "z": -8,
      "name": "Rock_Volcanic_Cobble_Roof",
      "rotation": 3
    },
    {
      "x": -10,
      "y": 0,
      "z": -7,
      "name": "UnbreakableWall"
    },
    {
      "x": -10,
      "y": 1,
      "z": -7,
      "name": "UnbreakableWall"
    },
    {
      "x": -10,
      "y": 2,
      "z": -7,
      "name": "UnbreakableWall"
    },
    {
      "x": -10,
      "y": 3,
      "z": -7,
      "name": "UnbreakableWall"
    },
    {
      "x": -10,
      "y": 4,
      "z": -7,
      "name": "UnbreakableWall"
    },
    {
      "x": -10,
      "y": 5,
      "z": -7,
      "name": "UnbreakableWall"
    },
    {
      "x": -10,
      "y": 6,
      "z": -7,
      "name": "UnbreakableWall"
    },
    {
      "x": -10,
      "y": 7,
      "z": -7,
      "name": "UnbreakableWall",
      "rotation": 2
    },
    {
      "x": -10,
      "y": 8,
      "z": -7,
      "name": "UnbreakableWall",
      "rotation": 2
    },
    {
      "x": -10,
      "y": 9,
      "z": -7,
      "name": "UnbreakableWall",
      "rotation": 2
    },
    {
      "x": -10,
      "y": 10,
      "z": -7,
      "name": "UnbreakableWall",
      "rotation": 2
    },
    {
      "x": -10,
      "y": 11,
      "z": -7,
      "name": "UnbreakableWall",
      "rotation": 2
    },
    {
      "x": -10,
      "y": 12,
      "z": -7,
      "name": "UnbreakableWall",
      "rotation": 2
    },
    {
      "x": -10,
      "y": 13,
      "z": -7,
      "name": "UnbreakableWall",
      "rotation": 2
    },
    {
      "x": -10,
      "y": 14,
      "z": -7,
      "name": "UnbreakableWall",
      "rotation": 2
    },
    {
      "x": -10,
      "y": 15,
      "z": -7,
      "name": "Rock_Volcanic_Brick_Stairs",
      "rotation": 3
    },
    {
      "x": -10,
      "y": 18,
      "z": -7,
      "name": "Rock_Volcanic_Brick_Stairs",
      "rotation": 33
    },
    {
      "x": -10,
      "y": 19,
      "z": -7,
      "name": "Rock_Volcanic_Brick",
      "rotation": 2
    },
    {
      "x": -10,
      "y": 20,
      "z": -7,
      "name": "Rock_Volcanic_Stalactite_Large",
      "rotation": 2
    },
    {
      "x": -10,
      "y": 21,
      "z": -7,
      "name": "Rock_Volcanic_Stalactite_Large",
      "filler": 1024,
      "rotation": 2
    },
    {
      "x": -10,
      "y": 0,
      "z": -6,
      "name": "UnbreakableWall"
    },
    {
      "x": -10,
      "y": 1,
      "z": -6,
      "name": "UnbreakableWall"
    },
    {
      "x": -10,
      "y": 2,
      "z": -6,
      "name": "UnbreakableWall"
    },
    {
      "x": -10,
      "y": 3,
      "z": -6,
      "name": "UnbreakableWall"
    },
    {
      "x": -10,
      "y": 4,
      "z": -6,
      "name": "UnbreakableWall"
    },
    {
      "x": -10,
      "y": 5,
      "z": -6,
      "name": "UnbreakableWall"
    },
    {
      "x": -10,
      "y": 6,
      "z": -6,
      "name": "UnbreakableWall"
    },
    {
      "x": -10,
      "y": 7,
      "z": -6,
      "name": "UnbreakableWall",
      "rotation": 2
    },
    {
      "x": -10,
      "y": 8,
      "z": -6,
      "name": "Furniture_Temple_Wind_Window",
      "rotation": 3
    },
    {
      "x": -10,
      "y": 9,
      "z": -6,
      "name": "Furniture_Temple_Wind_Window",
      "rotation": 3
    },
    {
      "x": -10,
      "y": 10,
      "z": -6,
      "name": "Furniture_Temple_Wind_Window",
      "rotation": 3
    },
    {
      "x": -10,
      "y": 11,
      "z": -6,
      "name": "Furniture_Temple_Wind_Window",
      "rotation": 3
    },
    {
      "x": -10,
      "y": 12,
      "z": -6,
      "name": "UnbreakableWall",
      "rotation": 2
    },
    {
      "x": -10,
      "y": 13,
      "z": -6,
      "name": "UnbreakableWall",
      "rotation": 2
    },
    {
      "x": -10,
      "y": 14,
      "z": -6,
      "name": "UnbreakableWall",
      "rotation": 2
    },
    {
      "x": -10,
      "y": 15,
      "z": -6,
      "name": "Rock_Volcanic_Cobble_Roof",
      "rotation": 3
    },
    {
      "x": -10,
      "y": 0,
      "z": -5,
      "name": "UnbreakableWall"
    },
    {
      "x": -10,
      "y": 1,
      "z": -5,
      "name": "UnbreakableWall"
    },
    {
      "x": -10,
      "y": 2,
      "z": -5,
      "name": "UnbreakableWall"
    },
    {
      "x": -10,
      "y": 3,
      "z": -5,
      "name": "UnbreakableWall"
    },
    {
      "x": -10,
      "y": 4,
      "z": -5,
      "name": "UnbreakableWall"
    },
    {
      "x": -10,
      "y": 5,
      "z": -5,
      "name": "UnbreakableWall"
    },
    {
      "x": -10,
      "y": 6,
      "z": -5,
      "name": "UnbreakableWall"
    },
    {
      "x": -10,
      "y": 7,
      "z": -5,
      "name": "UnbreakableWall",
      "rotation": 2
    },
    {
      "x": -10,
      "y": 8,
      "z": -5,
      "name": "Furniture_Temple_Wind_Window",
      "rotation": 3
    },
    {
      "x": -10,
      "y": 9,
      "z": -5,
      "name": "Furniture_Temple_Wind_Window",
      "rotation": 3
    },
    {
      "x": -10,
      "y": 10,
      "z": -5,
      "name": "Furniture_Temple_Wind_Window",
      "rotation": 3
    },
    {
      "x": -10,
      "y": 11,
      "z": -5,
      "name": "Furniture_Temple_Wind_Window",
      "rotation": 3
    },
    {
      "x": -10,
      "y": 12,
      "z": -5,
      "name": "Furniture_Temple_Wind_Window",
      "rotation": 3
    },
    {
      "x": -10,
      "y": 13,
      "z": -5,
      "name": "UnbreakableWall",
      "rotation": 2
    },
    {
      "x": -10,
      "y": 14,
      "z": -5,
      "name": "UnbreakableWall",
      "rotation": 2
    },
    {
      "x": -10,
      "y": 15,
      "z": -5,
      "name": "Rock_Volcanic_Cobble_Roof",
      "rotation": 3
    },
    {
      "x": -10,
      "y": 0,
      "z": -4,
      "name": "UnbreakableWall"
    },
    {
      "x": -10,
      "y": 1,
      "z": -4,
      "name": "UnbreakableWall"
    },
    {
      "x": -10,
      "y": 2,
      "z": -4,
      "name": "UnbreakableWall"
    },
    {
      "x": -10,
      "y": 3,
      "z": -4,
      "name": "UnbreakableWall"
    },
    {
      "x": -10,
      "y": 4,
      "z": -4,
      "name": "UnbreakableWall"
    },
    {
      "x": -10,
      "y": 5,
      "z": -4,
      "name": "UnbreakableWall"
    },
    {
      "x": -10,
      "y": 6,
      "z": -4,
      "name": "UnbreakableWall"
    },
    {
      "x": -10,
      "y": 7,
      "z": -4,
      "name": "UnbreakableWall",
      "rotation": 2
    },
    {
      "x": -10,
      "y": 8,
      "z": -4,
      "name": "Furniture_Temple_Wind_Window",
      "rotation": 3
    },
    {
      "x": -10,
      "y": 9,
      "z": -4,
      "name": "Furniture_Temple_Wind_Window",
      "rotation": 3
    },
    {
      "x": -10,
      "y": 10,
      "z": -4,
      "name": "Furniture_Temple_Wind_Window",
      "rotation": 3
    },
    {
      "x": -10,
      "y": 11,
      "z": -4,
      "name": "Furniture_Temple_Wind_Window",
      "rotation": 3
    },
    {
      "x": -10,
      "y": 12,
      "z": -4,
      "name": "UnbreakableWall",
      "rotation": 2
    },
    {
      "x": -10,
      "y": 13,
      "z": -4,
      "name": "UnbreakableWall",
      "rotation": 2
    },
    {
      "x": -10,
      "y": 14,
      "z": -4,
      "name": "UnbreakableWall",
      "rotation": 2
    },
    {
      "x": -10,
      "y": 15,
      "z": -4,
      "name": "Rock_Volcanic_Cobble_Roof",
      "rotation": 3
    },
    {
      "x": -10,
      "y": 0,
      "z": -3,
      "name": "UnbreakableWall"
    },
    {
      "x": -10,
      "y": 1,
      "z": -3,
      "name": "UnbreakableWall"
    },
    {
      "x": -10,
      "y": 2,
      "z": -3,
      "name": "UnbreakableWall"
    },
    {
      "x": -10,
      "y": 3,
      "z": -3,
      "name": "UnbreakableWall"
    },
    {
      "x": -10,
      "y": 4,
      "z": -3,
      "name": "UnbreakableWall"
    },
    {
      "x": -10,
      "y": 5,
      "z": -3,
      "name": "UnbreakableWall"
    },
    {
      "x": -10,
      "y": 6,
      "z": -3,
      "name": "UnbreakableWall"
    },
    {
      "x": -10,
      "y": 7,
      "z": -3,
      "name": "UnbreakableWall",
      "rotation": 2
    },
    {
      "x": -10,
      "y": 8,
      "z": -3,
      "name": "UnbreakableWall",
      "rotation": 2
    },
    {
      "x": -10,
      "y": 9,
      "z": -3,
      "name": "UnbreakableWall",
      "rotation": 2
    },
    {
      "x": -10,
      "y": 10,
      "z": -3,
      "name": "UnbreakableWall",
      "rotation": 2
    },
    {
      "x": -10,
      "y": 11,
      "z": -3,
      "name": "UnbreakableWall",
      "rotation": 2
    },
    {
      "x": -10,
      "y": 12,
      "z": -3,
      "name": "UnbreakableWall",
      "rotation": 2
    },
    {
      "x": -10,
      "y": 13,
      "z": -3,
      "name": "UnbreakableWall",
      "rotation": 2
    },
    {
      "x": -10,
      "y": 14,
      "z": -3,
      "name": "UnbreakableWall",
      "rotation": 2
    },
    {
      "x": -10,
      "y": 15,
      "z": -3,
      "name": "Rock_Volcanic_Brick_Stairs",
      "rotation": 3
    },
    {
      "x": -10,
      "y": 18,
      "z": -3,
      "name": "Rock_Volcanic_Brick_Stairs",
      "rotation": 33
    },
    {
      "x": -10,
      "y": 19,
      "z": -3,
      "name": "Rock_Volcanic_Brick",
      "rotation": 2
    },
    {
      "x": -10,
      "y": 20,
      "z": -3,
      "name": "Rock_Volcanic_Stalactite_Large",
      "rotation": 2
    },
    {
      "x": -10,
      "y": 21,
      "z": -3,
      "name": "Rock_Volcanic_Stalactite_Large",
      "filler": 1024,
      "rotation": 2
    },
    {
      "x": -10,
      "y": 0,
      "z": -2,
      "name": "UnbreakableWall"
    },
    {
      "x": -10,
      "y": 1,
      "z": -2,
      "name": "UnbreakableWall"
    },
    {
      "x": -10,
      "y": 2,
      "z": -2,
      "name": "UnbreakableWall"
    },
    {
      "x": -10,
      "y": 3,
      "z": -2,
      "name": "UnbreakableWall"
    },
    {
      "x": -10,
      "y": 4,
      "z": -2,
      "name": "UnbreakableWall"
    },
    {
      "x": -10,
      "y": 5,
      "z": -2,
      "name": "UnbreakableWall"
    },
    {
      "x": -10,
      "y": 6,
      "z": -2,
      "name": "UnbreakableWall"
    },
    {
      "x": -10,
      "y": 7,
      "z": -2,
      "name": "UnbreakableWall",
      "rotation": 2
    },
    {
      "x": -10,
      "y": 8,
      "z": -2,
      "name": "Furniture_Temple_Wind_Window",
      "rotation": 3
    },
    {
      "x": -10,
      "y": 9,
      "z": -2,
      "name": "Furniture_Temple_Wind_Window",
      "rotation": 3
    },
    {
      "x": -10,
      "y": 10,
      "z": -2,
      "name": "Furniture_Temple_Wind_Window",
      "rotation": 3
    },
    {
      "x": -10,
      "y": 11,
      "z": -2,
      "name": "Furniture_Temple_Wind_Window",
      "rotation": 3
    },
    {
      "x": -10,
      "y": 12,
      "z": -2,
      "name": "UnbreakableWall",
      "rotation": 2
    },
    {
      "x": -10,
      "y": 13,
      "z": -2,
      "name": "UnbreakableWall",
      "rotation": 2
    },
    {
      "x": -10,
      "y": 14,
      "z": -2,
      "name": "UnbreakableWall",
      "rotation": 2
    },
    {
      "x": -10,
      "y": 15,
      "z": -2,
      "name": "Rock_Volcanic_Cobble_Roof",
      "rotation": 3
    },
    {
      "x": -10,
      "y": 0,
      "z": -1,
      "name": "UnbreakableWall"
    },
    {
      "x": -10,
      "y": 1,
      "z": -1,
      "name": "UnbreakableWall"
    },
    {
      "x": -10,
      "y": 2,
      "z": -1,
      "name": "UnbreakableWall"
    },
    {
      "x": -10,
      "y": 3,
      "z": -1,
      "name": "UnbreakableWall"
    },
    {
      "x": -10,
      "y": 4,
      "z": -1,
      "name": "UnbreakableWall"
    },
    {
      "x": -10,
      "y": 5,
      "z": -1,
      "name": "UnbreakableWall"
    },
    {
      "x": -10,
      "y": 6,
      "z": -1,
      "name": "UnbreakableWall"
    },
    {
      "x": -10,
      "y": 7,
      "z": -1,
      "name": "UnbreakableWall",
      "rotation": 2
    },
    {
      "x": -10,
      "y": 8,
      "z": -1,
      "name": "Furniture_Temple_Wind_Window",
      "rotation": 3
    },
    {
      "x": -10,
      "y": 9,
      "z": -1,
      "name": "Furniture_Temple_Wind_Window",
      "rotation": 3
    },
    {
      "x": -10,
      "y": 10,
      "z": -1,
      "name": "Furniture_Temple_Wind_Window",
      "rotation": 3
    },
    {
      "x": -10,
      "y": 11,
      "z": -1,
      "name": "Furniture_Temple_Wind_Window",
      "rotation": 3
    },
    {
      "x": -10,
      "y": 12,
      "z": -1,
      "name": "Furniture_Temple_Wind_Window",
      "rotation": 3
    },
    {
      "x": -10,
      "y": 13,
      "z": -1,
      "name": "UnbreakableWall",
      "rotation": 2
    },
    {
      "x": -10,
      "y": 14,
      "z": -1,
      "name": "UnbreakableWall",
      "rotation": 2
    },
    {
      "x": -10,
      "y": 15,
      "z": -1,
      "name": "Rock_Volcanic_Cobble_Roof",
      "rotation": 3
    },
    {
      "x": -10,
      "y": 0,
      "z": 0,
      "name": "UnbreakableWall"
    },
    {
      "x": -10,
      "y": 1,
      "z": 0,
      "name": "UnbreakableWall"
    },
    {
      "x": -10,
      "y": 2,
      "z": 0,
      "name": "UnbreakableWall"
    },
    {
      "x": -10,
      "y": 3,
      "z": 0,
      "name": "UnbreakableWall"
    },
    {
      "x": -10,
      "y": 4,
      "z": 0,
      "name": "UnbreakableWall"
    },
    {
      "x": -10,
      "y": 5,
      "z": 0,
      "name": "UnbreakableWall"
    },
    {
      "x": -10,
      "y": 6,
      "z": 0,
      "name": "UnbreakableWall"
    },
    {
      "x": -10,
      "y": 7,
      "z": 0,
      "name": "UnbreakableWall",
      "rotation": 2
    },
    {
      "x": -10,
      "y": 8,
      "z": 0,
      "name": "Furniture_Temple_Wind_Window",
      "rotation": 3
    },
    {
      "x": -10,
      "y": 9,
      "z": 0,
      "name": "Furniture_Temple_Wind_Window",
      "rotation": 3
    },
    {
      "x": -10,
      "y": 10,
      "z": 0,
      "name": "Furniture_Temple_Wind_Window",
      "rotation": 3
    },
    {
      "x": -10,
      "y": 11,
      "z": 0,
      "name": "Furniture_Temple_Wind_Window",
      "rotation": 3
    },
    {
      "x": -10,
      "y": 12,
      "z": 0,
      "name": "UnbreakableWall",
      "rotation": 2
    },
    {
      "x": -10,
      "y": 13,
      "z": 0,
      "name": "UnbreakableWall",
      "rotation": 2
    },
    {
      "x": -10,
      "y": 14,
      "z": 0,
      "name": "UnbreakableWall",
      "rotation": 2
    },
    {
      "x": -10,
      "y": 15,
      "z": 0,
      "name": "Rock_Volcanic_Cobble_Roof",
      "rotation": 3
    },
    {
      "x": -10,
      "y": 0,
      "z": 1,
      "name": "UnbreakableWall"
    },
    {
      "x": -10,
      "y": 1,
      "z": 1,
      "name": "UnbreakableWall"
    },
    {
      "x": -10,
      "y": 2,
      "z": 1,
      "name": "UnbreakableWall"
    },
    {
      "x": -10,
      "y": 3,
      "z": 1,
      "name": "UnbreakableWall"
    },
    {
      "x": -10,
      "y": 4,
      "z": 1,
      "name": "UnbreakableWall"
    },
    {
      "x": -10,
      "y": 5,
      "z": 1,
      "name": "UnbreakableWall"
    },
    {
      "x": -10,
      "y": 6,
      "z": 1,
      "name": "UnbreakableWall"
    },
    {
      "x": -10,
      "y": 7,
      "z": 1,
      "name": "UnbreakableWall",
      "rotation": 2
    },
    {
      "x": -10,
      "y": 8,
      "z": 1,
      "name": "UnbreakableWall",
      "rotation": 2
    },
    {
      "x": -10,
      "y": 9,
      "z": 1,
      "name": "UnbreakableWall",
      "rotation": 2
    },
    {
      "x": -10,
      "y": 10,
      "z": 1,
      "name": "UnbreakableWall",
      "rotation": 2
    },
    {
      "x": -10,
      "y": 11,
      "z": 1,
      "name": "UnbreakableWall",
      "rotation": 2
    },
    {
      "x": -10,
      "y": 12,
      "z": 1,
      "name": "UnbreakableWall",
      "rotation": 2
    },
    {
      "x": -10,
      "y": 13,
      "z": 1,
      "name": "UnbreakableWall",
      "rotation": 2
    },
    {
      "x": -10,
      "y": 14,
      "z": 1,
      "name": "UnbreakableWall",
      "rotation": 2
    },
    {
      "x": -10,
      "y": 15,
      "z": 1,
      "name": "Rock_Volcanic_Brick_Stairs",
      "rotation": 3
    },
    {
      "x": -10,
      "y": 18,
      "z": 1,
      "name": "Rock_Volcanic_Brick_Stairs",
      "rotation": 33
    },
    {
      "x": -10,
      "y": 19,
      "z": 1,
      "name": "Rock_Volcanic_Brick",
      "rotation": 2
    },
    {
      "x": -10,
      "y": 20,
      "z": 1,
      "name": "Rock_Volcanic_Stalactite_Large",
      "rotation": 2
    },
    {
      "x": -10,
      "y": 21,
      "z": 1,
      "name": "Rock_Volcanic_Stalactite_Large",
      "filler": 1024,
      "rotation": 2
    },
    {
      "x": -10,
      "y": 0,
      "z": 2,
      "name": "UnbreakableWall"
    },
    {
      "x": -10,
      "y": 1,
      "z": 2,
      "name": "UnbreakableWall"
    },
    {
      "x": -10,
      "y": 2,
      "z": 2,
      "name": "UnbreakableWall"
    },
    {
      "x": -10,
      "y": 3,
      "z": 2,
      "name": "UnbreakableWall"
    },
    {
      "x": -10,
      "y": 4,
      "z": 2,
      "name": "UnbreakableWall"
    },
    {
      "x": -10,
      "y": 5,
      "z": 2,
      "name": "UnbreakableWall"
    },
    {
      "x": -10,
      "y": 6,
      "z": 2,
      "name": "UnbreakableWall"
    },
    {
      "x": -10,
      "y": 7,
      "z": 2,
      "name": "UnbreakableWall",
      "rotation": 2
    },
    {
      "x": -10,
      "y": 8,
      "z": 2,
      "name": "Furniture_Temple_Wind_Window",
      "rotation": 3
    },
    {
      "x": -10,
      "y": 9,
      "z": 2,
      "name": "Furniture_Temple_Wind_Window",
      "rotation": 3
    },
    {
      "x": -10,
      "y": 10,
      "z": 2,
      "name": "Furniture_Temple_Wind_Window",
      "rotation": 3
    },
    {
      "x": -10,
      "y": 11,
      "z": 2,
      "name": "Furniture_Temple_Wind_Window",
      "rotation": 3
    },
    {
      "x": -10,
      "y": 12,
      "z": 2,
      "name": "UnbreakableWall",
      "rotation": 2
    },
    {
      "x": -10,
      "y": 13,
      "z": 2,
      "name": "UnbreakableWall",
      "rotation": 2
    },
    {
      "x": -10,
      "y": 14,
      "z": 2,
      "name": "UnbreakableWall",
      "rotation": 2
    },
    {
      "x": -10,
      "y": 15,
      "z": 2,
      "name": "Rock_Volcanic_Cobble_Roof",
      "rotation": 3
    },
    {
      "x": -10,
      "y": 0,
      "z": 3,
      "name": "UnbreakableWall"
    },
    {
      "x": -10,
      "y": 1,
      "z": 3,
      "name": "UnbreakableWall"
    },
    {
      "x": -10,
      "y": 2,
      "z": 3,
      "name": "UnbreakableWall"
    },
    {
      "x": -10,
      "y": 3,
      "z": 3,
      "name": "UnbreakableWall"
    },
    {
      "x": -10,
      "y": 4,
      "z": 3,
      "name": "UnbreakableWall"
    },
    {
      "x": -10,
      "y": 5,
      "z": 3,
      "name": "UnbreakableWall"
    },
    {
      "x": -10,
      "y": 6,
      "z": 3,
      "name": "UnbreakableWall"
    },
    {
      "x": -10,
      "y": 7,
      "z": 3,
      "name": "UnbreakableWall",
      "rotation": 2
    },
    {
      "x": -10,
      "y": 8,
      "z": 3,
      "name": "Furniture_Temple_Wind_Window",
      "rotation": 3
    },
    {
      "x": -10,
      "y": 9,
      "z": 3,
      "name": "Furniture_Temple_Wind_Window",
      "rotation": 3
    },
    {
      "x": -10,
      "y": 10,
      "z": 3,
      "name": "Furniture_Temple_Wind_Window",
      "rotation": 3
    },
    {
      "x": -10,
      "y": 11,
      "z": 3,
      "name": "Furniture_Temple_Wind_Window",
      "rotation": 3
    },
    {
      "x": -10,
      "y": 12,
      "z": 3,
      "name": "Furniture_Temple_Wind_Window",
      "rotation": 3
    },
    {
      "x": -10,
      "y": 13,
      "z": 3,
      "name": "UnbreakableWall",
      "rotation": 2
    },
    {
      "x": -10,
      "y": 14,
      "z": 3,
      "name": "UnbreakableWall",
      "rotation": 2
    },
    {
      "x": -10,
      "y": 15,
      "z": 3,
      "name": "Rock_Volcanic_Cobble_Roof",
      "rotation": 3
    },
    {
      "x": -10,
      "y": 0,
      "z": 4,
      "name": "UnbreakableWall"
    },
    {
      "x": -10,
      "y": 1,
      "z": 4,
      "name": "UnbreakableWall"
    },
    {
      "x": -10,
      "y": 2,
      "z": 4,
      "name": "UnbreakableWall"
    },
    {
      "x": -10,
      "y": 3,
      "z": 4,
      "name": "UnbreakableWall"
    },
    {
      "x": -10,
      "y": 4,
      "z": 4,
      "name": "UnbreakableWall"
    },
    {
      "x": -10,
      "y": 5,
      "z": 4,
      "name": "UnbreakableWall"
    },
    {
      "x": -10,
      "y": 6,
      "z": 4,
      "name": "UnbreakableWall"
    },
    {
      "x": -10,
      "y": 7,
      "z": 4,
      "name": "UnbreakableWall",
      "rotation": 2
    },
    {
      "x": -10,
      "y": 8,
      "z": 4,
      "name": "Furniture_Temple_Wind_Window",
      "rotation": 3
    },
    {
      "x": -10,
      "y": 9,
      "z": 4,
      "name": "Furniture_Temple_Wind_Window",
      "rotation": 3
    },
    {
      "x": -10,
      "y": 10,
      "z": 4,
      "name": "Furniture_Temple_Wind_Window",
      "rotation": 3
    },
    {
      "x": -10,
      "y": 11,
      "z": 4,
      "name": "Furniture_Temple_Wind_Window",
      "rotation": 3
    },
    {
      "x": -10,
      "y": 12,
      "z": 4,
      "name": "UnbreakableWall",
      "rotation": 2
    },
    {
      "x": -10,
      "y": 13,
      "z": 4,
      "name": "UnbreakableWall",
      "rotation": 2
    },
    {
      "x": -10,
      "y": 14,
      "z": 4,
      "name": "UnbreakableWall",
      "rotation": 2
    },
    {
      "x": -10,
      "y": 15,
      "z": 4,
      "name": "Rock_Volcanic_Cobble_Roof",
      "rotation": 3
    },
    {
      "x": -10,
      "y": 0,
      "z": 5,
      "name": "UnbreakableWall"
    },
    {
      "x": -10,
      "y": 1,
      "z": 5,
      "name": "UnbreakableWall"
    },
    {
      "x": -10,
      "y": 2,
      "z": 5,
      "name": "UnbreakableWall"
    },
    {
      "x": -10,
      "y": 3,
      "z": 5,
      "name": "UnbreakableWall"
    },
    {
      "x": -10,
      "y": 4,
      "z": 5,
      "name": "UnbreakableWall"
    },
    {
      "x": -10,
      "y": 5,
      "z": 5,
      "name": "UnbreakableWall"
    },
    {
      "x": -10,
      "y": 6,
      "z": 5,
      "name": "UnbreakableWall"
    },
    {
      "x": -10,
      "y": 7,
      "z": 5,
      "name": "UnbreakableWall",
      "rotation": 2
    },
    {
      "x": -10,
      "y": 8,
      "z": 5,
      "name": "UnbreakableWall",
      "rotation": 2
    },
    {
      "x": -10,
      "y": 9,
      "z": 5,
      "name": "UnbreakableWall",
      "rotation": 2
    },
    {
      "x": -10,
      "y": 10,
      "z": 5,
      "name": "UnbreakableWall",
      "rotation": 2
    },
    {
      "x": -10,
      "y": 11,
      "z": 5,
      "name": "UnbreakableWall",
      "rotation": 2
    },
    {
      "x": -10,
      "y": 12,
      "z": 5,
      "name": "UnbreakableWall",
      "rotation": 2
    },
    {
      "x": -10,
      "y": 13,
      "z": 5,
      "name": "UnbreakableWall",
      "rotation": 2
    },
    {
      "x": -10,
      "y": 14,
      "z": 5,
      "name": "UnbreakableWall",
      "rotation": 2
    },
    {
      "x": -10,
      "y": 15,
      "z": 5,
      "name": "Rock_Volcanic_Brick_Stairs",
      "rotation": 3
    },
    {
      "x": -10,
      "y": 18,
      "z": 5,
      "name": "Rock_Volcanic_Brick_Stairs",
      "rotation": 33
    },
    {
      "x": -10,
      "y": 19,
      "z": 5,
      "name": "Rock_Volcanic_Brick",
      "rotation": 2
    },
    {
      "x": -10,
      "y": 20,
      "z": 5,
      "name": "Rock_Volcanic_Stalactite_Large",
      "rotation": 2
    },
    {
      "x": -10,
      "y": 21,
      "z": 5,
      "name": "Rock_Volcanic_Stalactite_Large",
      "filler": 1024,
      "rotation": 2
    },
    {
      "x": -10,
      "y": 0,
      "z": 6,
      "name": "UnbreakableWall"
    },
    {
      "x": -10,
      "y": 1,
      "z": 6,
      "name": "UnbreakableWall"
    },
    {
      "x": -10,
      "y": 2,
      "z": 6,
      "name": "UnbreakableWall"
    },
    {
      "x": -10,
      "y": 3,
      "z": 6,
      "name": "UnbreakableWall"
    },
    {
      "x": -10,
      "y": 4,
      "z": 6,
      "name": "UnbreakableWall"
    },
    {
      "x": -10,
      "y": 5,
      "z": 6,
      "name": "UnbreakableWall"
    },
    {
      "x": -10,
      "y": 6,
      "z": 6,
      "name": "UnbreakableWall"
    },
    {
      "x": -10,
      "y": 7,
      "z": 6,
      "name": "UnbreakableWall",
      "rotation": 2
    },
    {
      "x": -10,
      "y": 8,
      "z": 6,
      "name": "Furniture_Temple_Wind_Window",
      "rotation": 3
    },
    {
      "x": -10,
      "y": 9,
      "z": 6,
      "name": "Furniture_Temple_Wind_Window",
      "rotation": 3
    },
    {
      "x": -10,
      "y": 10,
      "z": 6,
      "name": "Furniture_Temple_Wind_Window",
      "rotation": 3
    },
    {
      "x": -10,
      "y": 11,
      "z": 6,
      "name": "Furniture_Temple_Wind_Window",
      "rotation": 3
    },
    {
      "x": -10,
      "y": 12,
      "z": 6,
      "name": "UnbreakableWall",
      "rotation": 2
    },
    {
      "x": -10,
      "y": 13,
      "z": 6,
      "name": "UnbreakableWall",
      "rotation": 2
    },
    {
      "x": -10,
      "y": 14,
      "z": 6,
      "name": "UnbreakableWall",
      "rotation": 2
    },
    {
      "x": -10,
      "y": 15,
      "z": 6,
      "name": "Rock_Volcanic_Cobble_Roof",
      "rotation": 3
    },
    {
      "x": -10,
      "y": 0,
      "z": 7,
      "name": "UnbreakableWall"
    },
    {
      "x": -10,
      "y": 1,
      "z": 7,
      "name": "UnbreakableWall"
    },
    {
      "x": -10,
      "y": 2,
      "z": 7,
      "name": "UnbreakableWall"
    },
    {
      "x": -10,
      "y": 3,
      "z": 7,
      "name": "UnbreakableWall"
    },
    {
      "x": -10,
      "y": 4,
      "z": 7,
      "name": "UnbreakableWall"
    },
    {
      "x": -10,
      "y": 5,
      "z": 7,
      "name": "UnbreakableWall"
    },
    {
      "x": -10,
      "y": 6,
      "z": 7,
      "name": "UnbreakableWall"
    },
    {
      "x": -10,
      "y": 7,
      "z": 7,
      "name": "UnbreakableWall",
      "rotation": 2
    },
    {
      "x": -10,
      "y": 8,
      "z": 7,
      "name": "Furniture_Temple_Wind_Window",
      "rotation": 3
    },
    {
      "x": -10,
      "y": 9,
      "z": 7,
      "name": "Furniture_Temple_Wind_Window",
      "rotation": 3
    },
    {
      "x": -10,
      "y": 10,
      "z": 7,
      "name": "Furniture_Temple_Wind_Window",
      "rotation": 3
    },
    {
      "x": -10,
      "y": 11,
      "z": 7,
      "name": "Furniture_Temple_Wind_Window",
      "rotation": 3
    },
    {
      "x": -10,
      "y": 12,
      "z": 7,
      "name": "Furniture_Temple_Wind_Window",
      "rotation": 3
    },
    {
      "x": -10,
      "y": 13,
      "z": 7,
      "name": "UnbreakableWall",
      "rotation": 2
    },
    {
      "x": -10,
      "y": 14,
      "z": 7,
      "name": "UnbreakableWall"
    },
    {
      "x": -10,
      "y": 15,
      "z": 7,
      "name": "Rock_Volcanic_Cobble_Roof",
      "rotation": 3
    },
    {
      "x": -10,
      "y": 0,
      "z": 8,
      "name": "UnbreakableWall"
    },
    {
      "x": -10,
      "y": 1,
      "z": 8,
      "name": "UnbreakableWall"
    },
    {
      "x": -10,
      "y": 2,
      "z": 8,
      "name": "UnbreakableWall"
    },
    {
      "x": -10,
      "y": 3,
      "z": 8,
      "name": "UnbreakableWall"
    },
    {
      "x": -10,
      "y": 4,
      "z": 8,
      "name": "UnbreakableWall"
    },
    {
      "x": -10,
      "y": 5,
      "z": 8,
      "name": "UnbreakableWall"
    },
    {
      "x": -10,
      "y": 6,
      "z": 8,
      "name": "UnbreakableWall"
    },
    {
      "x": -10,
      "y": 7,
      "z": 8,
      "name": "UnbreakableWall",
      "rotation": 2
    },
    {
      "x": -10,
      "y": 8,
      "z": 8,
      "name": "Furniture_Temple_Wind_Window",
      "rotation": 3
    },
    {
      "x": -10,
      "y": 9,
      "z": 8,
      "name": "Furniture_Temple_Wind_Window",
      "rotation": 3
    },
    {
      "x": -10,
      "y": 10,
      "z": 8,
      "name": "Furniture_Temple_Wind_Window",
      "rotation": 3
    },
    {
      "x": -10,
      "y": 11,
      "z": 8,
      "name": "Furniture_Temple_Wind_Window",
      "rotation": 3
    },
    {
      "x": -10,
      "y": 12,
      "z": 8,
      "name": "UnbreakableWall",
      "rotation": 2
    },
    {
      "x": -10,
      "y": 13,
      "z": 8,
      "name": "UnbreakableWall",
      "rotation": 2
    },
    {
      "x": -10,
      "y": 14,
      "z": 8,
      "name": "UnbreakableWall",
      "rotation": 2
    },
    {
      "x": -10,
      "y": 15,
      "z": 8,
      "name": "Rock_Volcanic_Cobble_Roof",
      "rotation": 3
    },
    {
      "x": -10,
      "y": 0,
      "z": 9,
      "name": "UnbreakableWall"
    },
    {
      "x": -10,
      "y": 1,
      "z": 9,
      "name": "UnbreakableWall"
    },
    {
      "x": -10,
      "y": 2,
      "z": 9,
      "name": "UnbreakableWall"
    },
    {
      "x": -10,
      "y": 3,
      "z": 9,
      "name": "UnbreakableWall"
    },
    {
      "x": -10,
      "y": 4,
      "z": 9,
      "name": "UnbreakableWall"
    },
    {
      "x": -10,
      "y": 5,
      "z": 9,
      "name": "UnbreakableWall"
    },
    {
      "x": -10,
      "y": 6,
      "z": 9,
      "name": "UnbreakableWall"
    },
    {
      "x": -10,
      "y": 7,
      "z": 9,
      "name": "UnbreakableWall",
      "rotation": 2
    },
    {
      "x": -10,
      "y": 8,
      "z": 9,
      "name": "UnbreakableWall",
      "rotation": 2
    },
    {
      "x": -10,
      "y": 9,
      "z": 9,
      "name": "UnbreakableWall",
      "rotation": 2
    },
    {
      "x": -10,
      "y": 10,
      "z": 9,
      "name": "UnbreakableWall",
      "rotation": 2
    },
    {
      "x": -10,
      "y": 11,
      "z": 9,
      "name": "UnbreakableWall",
      "rotation": 2
    },
    {
      "x": -10,
      "y": 12,
      "z": 9,
      "name": "UnbreakableWall",
      "rotation": 2
    },
    {
      "x": -10,
      "y": 13,
      "z": 9,
      "name": "UnbreakableWall",
      "rotation": 2
    },
    {
      "x": -10,
      "y": 14,
      "z": 9,
      "name": "UnbreakableWall",
      "rotation": 2
    },
    {
      "x": -10,
      "y": 15,
      "z": 9,
      "name": "Rock_Volcanic_Brick_Stairs",
      "rotation": 3
    },
    {
      "x": -10,
      "y": 18,
      "z": 9,
      "name": "Rock_Volcanic_Brick_Stairs",
      "rotation": 33
    },
    {
      "x": -10,
      "y": 19,
      "z": 9,
      "name": "Rock_Volcanic_Brick",
      "rotation": 2
    },
    {
      "x": -10,
      "y": 20,
      "z": 9,
      "name": "Rock_Volcanic_Stalactite_Large",
      "rotation": 2
    },
    {
      "x": -10,
      "y": 21,
      "z": 9,
      "name": "Rock_Volcanic_Stalactite_Large",
      "filler": 1024,
      "rotation": 2
    },
    {
      "x": -10,
      "y": 0,
      "z": 10,
      "name": "UnbreakableWall"
    },
    {
      "x": -10,
      "y": 1,
      "z": 10,
      "name": "UnbreakableWall"
    },
    {
      "x": -10,
      "y": 2,
      "z": 10,
      "name": "UnbreakableWall"
    },
    {
      "x": -10,
      "y": 3,
      "z": 10,
      "name": "UnbreakableWall"
    },
    {
      "x": -10,
      "y": 4,
      "z": 10,
      "name": "UnbreakableWall"
    },
    {
      "x": -10,
      "y": 5,
      "z": 10,
      "name": "UnbreakableWall"
    },
    {
      "x": -10,
      "y": 6,
      "z": 10,
      "name": "UnbreakableWall"
    },
    {
      "x": -10,
      "y": 7,
      "z": 10,
      "name": "UnbreakableWall",
      "rotation": 2
    },
    {
      "x": -10,
      "y": 8,
      "z": 10,
      "name": "Furniture_Temple_Wind_Window",
      "rotation": 3
    },
    {
      "x": -10,
      "y": 9,
      "z": 10,
      "name": "Furniture_Temple_Wind_Window",
      "rotation": 3
    },
    {
      "x": -10,
      "y": 10,
      "z": 10,
      "name": "Furniture_Temple_Wind_Window",
      "rotation": 3
    },
    {
      "x": -10,
      "y": 11,
      "z": 10,
      "name": "Furniture_Temple_Wind_Window",
      "rotation": 3
    },
    {
      "x": -10,
      "y": 12,
      "z": 10,
      "name": "UnbreakableWall",
      "rotation": 2
    },
    {
      "x": -10,
      "y": 13,
      "z": 10,
      "name": "UnbreakableWall",
      "rotation": 2
    },
    {
      "x": -10,
      "y": 14,
      "z": 10,
      "name": "UnbreakableWall",
      "rotation": 2
    },
    {
      "x": -10,
      "y": 15,
      "z": 10,
      "name": "Rock_Volcanic_Cobble_Roof",
      "rotation": 3
    },
    {
      "x": -10,
      "y": 0,
      "z": 11,
      "name": "UnbreakableWall"
    },
    {
      "x": -10,
      "y": 1,
      "z": 11,
      "name": "UnbreakableWall"
    },
    {
      "x": -10,
      "y": 2,
      "z": 11,
      "name": "UnbreakableWall"
    },
    {
      "x": -10,
      "y": 3,
      "z": 11,
      "name": "UnbreakableWall"
    },
    {
      "x": -10,
      "y": 4,
      "z": 11,
      "name": "UnbreakableWall"
    },
    {
      "x": -10,
      "y": 5,
      "z": 11,
      "name": "UnbreakableWall"
    },
    {
      "x": -10,
      "y": 6,
      "z": 11,
      "name": "UnbreakableWall"
    },
    {
      "x": -10,
      "y": 7,
      "z": 11,
      "name": "UnbreakableWall",
      "rotation": 2
    },
    {
      "x": -10,
      "y": 8,
      "z": 11,
      "name": "Furniture_Temple_Wind_Window",
      "rotation": 3
    },
    {
      "x": -10,
      "y": 9,
      "z": 11,
      "name": "Furniture_Temple_Wind_Window",
      "rotation": 3
    },
    {
      "x": -10,
      "y": 10,
      "z": 11,
      "name": "Furniture_Temple_Wind_Window",
      "rotation": 3
    },
    {
      "x": -10,
      "y": 11,
      "z": 11,
      "name": "Furniture_Temple_Wind_Window",
      "rotation": 3
    },
    {
      "x": -10,
      "y": 12,
      "z": 11,
      "name": "Furniture_Temple_Wind_Window",
      "rotation": 3
    },
    {
      "x": -10,
      "y": 13,
      "z": 11,
      "name": "UnbreakableWall",
      "rotation": 2
    },
    {
      "x": -10,
      "y": 14,
      "z": 11,
      "name": "UnbreakableWall",
      "rotation": 2
    },
    {
      "x": -10,
      "y": 15,
      "z": 11,
      "name": "Rock_Volcanic_Cobble_Roof",
      "rotation": 3
    },
    {
      "x": -10,
      "y": 0,
      "z": 12,
      "name": "UnbreakableWall"
    },
    {
      "x": -10,
      "y": 1,
      "z": 12,
      "name": "UnbreakableWall"
    },
    {
      "x": -10,
      "y": 2,
      "z": 12,
      "name": "UnbreakableWall"
    },
    {
      "x": -10,
      "y": 3,
      "z": 12,
      "name": "UnbreakableWall"
    },
    {
      "x": -10,
      "y": 4,
      "z": 12,
      "name": "UnbreakableWall"
    },
    {
      "x": -10,
      "y": 5,
      "z": 12,
      "name": "UnbreakableWall"
    },
    {
      "x": -10,
      "y": 6,
      "z": 12,
      "name": "UnbreakableWall"
    },
    {
      "x": -10,
      "y": 7,
      "z": 12,
      "name": "UnbreakableWall",
      "rotation": 2
    },
    {
      "x": -10,
      "y": 8,
      "z": 12,
      "name": "Furniture_Temple_Wind_Window",
      "rotation": 3
    },
    {
      "x": -10,
      "y": 9,
      "z": 12,
      "name": "Furniture_Temple_Wind_Window",
      "rotation": 3
    },
    {
      "x": -10,
      "y": 10,
      "z": 12,
      "name": "Furniture_Temple_Wind_Window",
      "rotation": 3
    },
    {
      "x": -10,
      "y": 11,
      "z": 12,
      "name": "Furniture_Temple_Wind_Window",
      "rotation": 3
    },
    {
      "x": -10,
      "y": 12,
      "z": 12,
      "name": "UnbreakableWall",
      "rotation": 2
    },
    {
      "x": -10,
      "y": 13,
      "z": 12,
      "name": "UnbreakableWall",
      "rotation": 2
    },
    {
      "x": -10,
      "y": 14,
      "z": 12,
      "name": "UnbreakableWall",
      "rotation": 2
    },
    {
      "x": -10,
      "y": 15,
      "z": 12,
      "name": "Rock_Volcanic_Cobble_Roof",
      "rotation": 3
    },
    {
      "x": -10,
      "y": 0,
      "z": 13,
      "name": "UnbreakableWall"
    },
    {
      "x": -10,
      "y": 1,
      "z": 13,
      "name": "UnbreakableWall"
    },
    {
      "x": -10,
      "y": 2,
      "z": 13,
      "name": "UnbreakableWall"
    },
    {
      "x": -10,
      "y": 3,
      "z": 13,
      "name": "UnbreakableWall"
    },
    {
      "x": -10,
      "y": 4,
      "z": 13,
      "name": "UnbreakableWall"
    },
    {
      "x": -10,
      "y": 5,
      "z": 13,
      "name": "UnbreakableWall"
    },
    {
      "x": -10,
      "y": 6,
      "z": 13,
      "name": "UnbreakableWall"
    },
    {
      "x": -10,
      "y": 7,
      "z": 13,
      "name": "UnbreakableWall",
      "rotation": 2
    },
    {
      "x": -10,
      "y": 8,
      "z": 13,
      "name": "UnbreakableWall",
      "rotation": 2
    },
    {
      "x": -10,
      "y": 9,
      "z": 13,
      "name": "UnbreakableWall",
      "rotation": 2
    },
    {
      "x": -10,
      "y": 10,
      "z": 13,
      "name": "UnbreakableWall",
      "rotation": 2
    },
    {
      "x": -10,
      "y": 11,
      "z": 13,
      "name": "UnbreakableWall",
      "rotation": 2
    },
    {
      "x": -10,
      "y": 12,
      "z": 13,
      "name": "UnbreakableWall",
      "rotation": 2
    },
    {
      "x": -10,
      "y": 13,
      "z": 13,
      "name": "UnbreakableWall",
      "rotation": 2
    },
    {
      "x": -10,
      "y": 14,
      "z": 13,
      "name": "UnbreakableWall",
      "rotation": 2
    },
    {
      "x": -10,
      "y": 15,
      "z": 13,
      "name": "Rock_Volcanic_Brick_Stairs",
      "rotation": 3
    },
    {
      "x": -10,
      "y": 18,
      "z": 13,
      "name": "Rock_Volcanic_Brick_Stairs",
      "rotation": 33
    },
    {
      "x": -10,
      "y": 19,
      "z": 13,
      "name": "Rock_Volcanic_Brick",
      "rotation": 2
    },
    {
      "x": -10,
      "y": 20,
      "z": 13,
      "name": "Rock_Volcanic_Stalactite_Large",
      "rotation": 2
    },
    {
      "x": -10,
      "y": 21,
      "z": 13,
      "name": "Rock_Volcanic_Stalactite_Large",
      "filler": 1024,
      "rotation": 2
    },
    {
      "x": -10,
      "y": 0,
      "z": 14,
      "name": "Rock_Volcanic_Brick"
    },
    {
      "x": -10,
      "y": 1,
      "z": 14,
      "name": "Rock_Volcanic_Brick"
    },
    {
      "x": -10,
      "y": 2,
      "z": 14,
      "name": "Rock_Volcanic_Brick"
    },
    {
      "x": -10,
      "y": 3,
      "z": 14,
      "name": "Rock_Volcanic_Brick"
    },
    {
      "x": -10,
      "y": 4,
      "z": 14,
      "name": "Rock_Volcanic_Brick"
    },
    {
      "x": -10,
      "y": 5,
      "z": 14,
      "name": "Rock_Volcanic_Brick"
    },
    {
      "x": -10,
      "y": 6,
      "z": 14,
      "name": "Rock_Volcanic_Brick_Wall",
      "rotation": 3
    },
    {
      "x": -10,
      "y": 7,
      "z": 14,
      "name": "Rock_Volcanic_Brick"
    },
    {
      "x": -10,
      "y": 8,
      "z": 14,
      "name": "Rock_Volcanic_Brick_Wall",
      "rotation": 1
    },
    {
      "x": -10,
      "y": 15,
      "z": 14,
      "name": "Rock_Volcanic_Cobble_Roof_Hollow",
      "rotation": 3
    },
    {
      "x": -10,
      "y": 0,
      "z": 15,
      "name": "Rock_Volcanic_Brick"
    },
    {
      "x": -10,
      "y": 1,
      "z": 15,
      "name": "Rock_Volcanic_Brick"
    },
    {
      "x": -10,
      "y": 2,
      "z": 15,
      "name": "Rock_Volcanic_Brick"
    },
    {
      "x": -10,
      "y": 3,
      "z": 15,
      "name": "Rock_Volcanic_Brick"
    },
    {
      "x": -10,
      "y": 4,
      "z": 15,
      "name": "Rock_Volcanic_Brick"
    },
    {
      "x": -10,
      "y": 5,
      "z": 15,
      "name": "Rock_Volcanic_Brick"
    },
    {
      "x": -10,
      "y": 6,
      "z": 15,
      "name": "Rock_Volcanic_Brick_Wall",
      "rotation": 3
    },
    {
      "x": -10,
      "y": 7,
      "z": 15,
      "name": "Rock_Volcanic_Brick"
    },
    {
      "x": -10,
      "y": 8,
      "z": 15,
      "name": "Rock_Volcanic_Brick_Wall",
      "rotation": 1
    },
    {
      "x": -10,
      "y": 15,
      "z": 15,
      "name": "Rock_Volcanic_Cobble_Roof_Hollow",
      "rotation": 3
    },
    {
      "x": -10,
      "y": 0,
      "z": 16,
      "name": "Rock_Volcanic_Brick"
    },
    {
      "x": -10,
      "y": 1,
      "z": 16,
      "name": "Rock_Volcanic_Brick"
    },
    {
      "x": -10,
      "y": 2,
      "z": 16,
      "name": "Rock_Volcanic_Brick"
    },
    {
      "x": -10,
      "y": 3,
      "z": 16,
      "name": "Rock_Volcanic_Brick"
    },
    {
      "x": -10,
      "y": 4,
      "z": 16,
      "name": "Rock_Volcanic_Brick"
    },
    {
      "x": -10,
      "y": 5,
      "z": 16,
      "name": "Rock_Volcanic_Brick"
    },
    {
      "x": -10,
      "y": 6,
      "z": 16,
      "name": "Rock_Volcanic_Brick_Wall",
      "rotation": 3
    },
    {
      "x": -10,
      "y": 7,
      "z": 16,
      "name": "Rock_Volcanic_Brick"
    },
    {
      "x": -10,
      "y": 8,
      "z": 16,
      "name": "Rock_Volcanic_Brick_Wall",
      "rotation": 1
    },
    {
      "x": -10,
      "y": 15,
      "z": 16,
      "name": "Rock_Volcanic_Cobble_Roof_Hollow",
      "rotation": 3
    },
    {
      "x": -10,
      "y": 0,
      "z": 17,
      "name": "Rock_Volcanic_Brick"
    },
    {
      "x": -10,
      "y": 1,
      "z": 17,
      "name": "Rock_Volcanic_Brick"
    },
    {
      "x": -10,
      "y": 2,
      "z": 17,
      "name": "Rock_Volcanic_Brick"
    },
    {
      "x": -10,
      "y": 3,
      "z": 17,
      "name": "Rock_Volcanic_Brick"
    },
    {
      "x": -10,
      "y": 4,
      "z": 17,
      "name": "Rock_Volcanic_Brick"
    },
    {
      "x": -10,
      "y": 5,
      "z": 17,
      "name": "Rock_Volcanic_Brick"
    },
    {
      "x": -10,
      "y": 6,
      "z": 17,
      "name": "*Rock_Volcanic_Brick_Wall_State_Definitions_Corner",
      "rotation": 2
    },
    {
      "x": -10,
      "y": 7,
      "z": 17,
      "name": "Rock_Volcanic_Brick"
    },
    {
      "x": -10,
      "y": 8,
      "z": 17,
      "name": "*Rock_Volcanic_Brick_Wall_State_Definitions_Corner",
      "rotation": 2
    },
    {
      "x": -9,
      "y": 5,
      "z": -15,
      "name": "Rock_Volcanic_Brick_Stairs",
      "rotation": 8
    },
    {
      "x": -9,
      "y": 6,
      "z": -15,
      "name": "Rock_Volcanic_Brick_Pillar_Base"
    },
    {
      "x": -9,
      "y": 7,
      "z": -15,
      "name": "Rock_Volcanic_Brick_Pillar_Base",
      "rotation": 8
    },
    {
      "x": -9,
      "y": 8,
      "z": -15,
      "name": "Rock_Volcanic_Brick_Pillar_Middle",
      "rotation": 8
    },
    {
      "x": -9,
      "y": 9,
      "z": -15,
      "name": "Rock_Volcanic_Brick_Pillar_Middle",
      "rotation": 8
    },
    {
      "x": -9,
      "y": 10,
      "z": -15,
      "name": "Rock_Volcanic_Brick_Pillar_Middle",
      "rotation": 8
    },
    {
      "x": -9,
      "y": 11,
      "z": -15,
      "name": "Rock_Volcanic_Brick_Pillar_Middle",
      "rotation": 8
    },
    {
      "x": -9,
      "y": 12,
      "z": -15,
      "name": "Rock_Volcanic_Brick_Pillar_Middle",
      "rotation": 8
    },
    {
      "x": -9,
      "y": 13,
      "z": -15,
      "name": "Rock_Volcanic_Brick_Pillar_Middle",
      "rotation": 8
    },
    {
      "x": -9,
      "y": 14,
      "z": -15,
      "name": "Rock_Volcanic_Brick_Pillar_Middle",
      "rotation": 8
    },
    {
      "x": -9,
      "y": 15,
      "z": -15,
      "name": "Rock_Volcanic_Brick_Pillar_Base",
      "rotation": 8
    },
    {
      "x": -9,
      "y": 16,
      "z": -15,
      "name": "Rock_Volcanic_Cobble_Roof",
      "rotation": 3
    },
    {
      "x": -9,
      "y": 0,
      "z": -14,
      "name": "UnbreakableWall"
    },
    {
      "x": -9,
      "y": 1,
      "z": -14,
      "name": "UnbreakableWall"
    },
    {
      "x": -9,
      "y": 2,
      "z": -14,
      "name": "UnbreakableWall"
    },
    {
      "x": -9,
      "y": 3,
      "z": -14,
      "name": "UnbreakableWall"
    },
    {
      "x": -9,
      "y": 4,
      "z": -14,
      "name": "UnbreakableWall"
    },
    {
      "x": -9,
      "y": 5,
      "z": -14,
      "name": "UnbreakableWall"
    },
    {
      "x": -9,
      "y": 6,
      "z": -14,
      "name": "UnbreakableWall"
    },
    {
      "x": -9,
      "y": 7,
      "z": -14,
      "name": "UnbreakableWall",
      "rotation": 2
    },
    {
      "x": -9,
      "y": 8,
      "z": -14,
      "name": "UnbreakableWall",
      "rotation": 2
    },
    {
      "x": -9,
      "y": 9,
      "z": -14,
      "name": "UnbreakableWall",
      "rotation": 2
    },
    {
      "x": -9,
      "y": 10,
      "z": -14,
      "name": "UnbreakableWall",
      "rotation": 2
    },
    {
      "x": -9,
      "y": 11,
      "z": -14,
      "name": "UnbreakableWall",
      "rotation": 2
    },
    {
      "x": -9,
      "y": 12,
      "z": -14,
      "name": "UnbreakableWall",
      "rotation": 2
    },
    {
      "x": -9,
      "y": 13,
      "z": -14,
      "name": "UnbreakableWall",
      "rotation": 2
    },
    {
      "x": -9,
      "y": 14,
      "z": -14,
      "name": "UnbreakableWall",
      "rotation": 2
    },
    {
      "x": -9,
      "y": 15,
      "z": -14,
      "name": "UnbreakableWall",
      "rotation": 2
    },
    {
      "x": -9,
      "y": 16,
      "z": -14,
      "name": "Rock_Volcanic_Cobble_Roof",
      "rotation": 3
    },
    {
      "x": -9,
      "y": 0,
      "z": -13,
      "name": "UnbreakableWall"
    },
    {
      "x": -9,
      "y": 1,
      "z": -13,
      "name": "UnbreakableWall"
    },
    {
      "x": -9,
      "y": 2,
      "z": -13,
      "name": "UnbreakableWall"
    },
    {
      "x": -9,
      "y": 3,
      "z": -13,
      "name": "UnbreakableWall"
    },
    {
      "x": -9,
      "y": 4,
      "z": -13,
      "name": "UnbreakableWall"
    },
    {
      "x": -9,
      "y": 5,
      "z": -13,
      "name": "UnbreakableWall"
    },
    {
      "x": -9,
      "y": 6,
      "z": -13,
      "name": "UnbreakableWall"
    },
    {
      "x": -9,
      "y": 7,
      "z": -13,
      "name": "UnbreakableWall",
      "rotation": 2
    },
    {
      "x": -9,
      "y": 8,
      "z": -13,
      "name": "UnbreakableWall",
      "rotation": 2
    },
    {
      "x": -9,
      "y": 9,
      "z": -13,
      "name": "UnbreakableWall",
      "rotation": 2
    },
    {
      "x": -9,
      "y": 10,
      "z": -13,
      "name": "UnbreakableWall",
      "rotation": 2
    },
    {
      "x": -9,
      "y": 11,
      "z": -13,
      "name": "UnbreakableWall",
      "rotation": 2
    },
    {
      "x": -9,
      "y": 12,
      "z": -13,
      "name": "UnbreakableWall",
      "rotation": 2
    },
    {
      "x": -9,
      "y": 13,
      "z": -13,
      "name": "UnbreakableWall",
      "rotation": 2
    },
    {
      "x": -9,
      "y": 14,
      "z": -13,
      "name": "UnbreakableWall",
      "rotation": 2
    },
    {
      "x": -9,
      "y": 15,
      "z": -13,
      "name": "UnbreakableWall",
      "rotation": 2
    },
    {
      "x": -9,
      "y": 16,
      "z": -13,
      "name": "Rock_Volcanic_Cobble_Roof",
      "rotation": 3
    },
    {
      "x": -9,
      "y": 0,
      "z": -12,
      "name": "UnbreakableWall"
    },
    {
      "x": -9,
      "y": 1,
      "z": -12,
      "name": "UnbreakableWall"
    },
    {
      "x": -9,
      "y": 2,
      "z": -12,
      "name": "UnbreakableWall"
    },
    {
      "x": -9,
      "y": 3,
      "z": -12,
      "name": "UnbreakableWall"
    },
    {
      "x": -9,
      "y": 4,
      "z": -12,
      "name": "UnbreakableWall"
    },
    {
      "x": -9,
      "y": 5,
      "z": -12,
      "name": "UnbreakableWall"
    },
    {
      "x": -9,
      "y": 6,
      "z": -12,
      "name": "UnbreakableWall"
    },
    {
      "x": -9,
      "y": 7,
      "z": -12,
      "name": "UnbreakableWall",
      "rotation": 2
    },
    {
      "x": -9,
      "y": 8,
      "z": -12,
      "name": "UnbreakableWall",
      "rotation": 2
    },
    {
      "x": -9,
      "y": 9,
      "z": -12,
      "name": "UnbreakableWall",
      "rotation": 2
    },
    {
      "x": -9,
      "y": 10,
      "z": -12,
      "name": "UnbreakableWall",
      "rotation": 2
    },
    {
      "x": -9,
      "y": 11,
      "z": -12,
      "name": "UnbreakableWall",
      "rotation": 2
    },
    {
      "x": -9,
      "y": 12,
      "z": -12,
      "name": "UnbreakableWall",
      "rotation": 2
    },
    {
      "x": -9,
      "y": 13,
      "z": -12,
      "name": "UnbreakableWall",
      "rotation": 2
    },
    {
      "x": -9,
      "y": 14,
      "z": -12,
      "name": "UnbreakableWall",
      "rotation": 2
    },
    {
      "x": -9,
      "y": 15,
      "z": -12,
      "name": "UnbreakableWall",
      "rotation": 2
    },
    {
      "x": -9,
      "y": 16,
      "z": -12,
      "name": "Rock_Volcanic_Cobble_Roof",
      "rotation": 3
    },
    {
      "x": -9,
      "y": 0,
      "z": -11,
      "name": "UnbreakableWall"
    },
    {
      "x": -9,
      "y": 1,
      "z": -11,
      "name": "UnbreakableWall"
    },
    {
      "x": -9,
      "y": 2,
      "z": -11,
      "name": "UnbreakableWall"
    },
    {
      "x": -9,
      "y": 3,
      "z": -11,
      "name": "UnbreakableWall"
    },
    {
      "x": -9,
      "y": 4,
      "z": -11,
      "name": "UnbreakableWall"
    },
    {
      "x": -9,
      "y": 5,
      "z": -11,
      "name": "UnbreakableWall"
    },
    {
      "x": -9,
      "y": 6,
      "z": -11,
      "name": "UnbreakableWall"
    },
    {
      "x": -9,
      "y": 7,
      "z": -11,
      "name": "UnbreakableWall",
      "rotation": 2
    },
    {
      "x": -9,
      "y": 8,
      "z": -11,
      "name": "UnbreakableWall",
      "rotation": 2
    },
    {
      "x": -9,
      "y": 9,
      "z": -11,
      "name": "UnbreakableWall",
      "rotation": 2
    },
    {
      "x": -9,
      "y": 10,
      "z": -11,
      "name": "UnbreakableWall",
      "rotation": 2
    },
    {
      "x": -9,
      "y": 11,
      "z": -11,
      "name": "UnbreakableWall",
      "rotation": 2
    },
    {
      "x": -9,
      "y": 12,
      "z": -11,
      "name": "UnbreakableWall",
      "rotation": 2
    },
    {
      "x": -9,
      "y": 13,
      "z": -11,
      "name": "UnbreakableWall",
      "rotation": 2
    },
    {
      "x": -9,
      "y": 14,
      "z": -11,
      "name": "UnbreakableWall",
      "rotation": 2
    },
    {
      "x": -9,
      "y": 15,
      "z": -11,
      "name": "UnbreakableWall",
      "rotation": 2
    },
    {
      "x": -9,
      "y": 16,
      "z": -11,
      "name": "Rock_Volcanic_Brick_Stairs",
      "rotation": 3
    },
    {
      "x": -9,
      "y": 19,
      "z": -11,
      "name": "Rock_Volcanic_Brick_Stairs",
      "rotation": 33
    },
    {
      "x": -9,
      "y": 20,
      "z": -11,
      "name": "Rock_Volcanic_Brick",
      "rotation": 2
    },
    {
      "x": -9,
      "y": 21,
      "z": -11,
      "name": "Rock_Volcanic_Brick_Roof",
      "rotation": 3
    },
    {
      "x": -9,
      "y": 0,
      "z": -10,
      "name": "UnbreakableWall"
    },
    {
      "x": -9,
      "y": 1,
      "z": -10,
      "name": "UnbreakableWall"
    },
    {
      "x": -9,
      "y": 2,
      "z": -10,
      "name": "UnbreakableWall"
    },
    {
      "x": -9,
      "y": 3,
      "z": -10,
      "name": "UnbreakableWall"
    },
    {
      "x": -9,
      "y": 4,
      "z": -10,
      "name": "UnbreakableWall"
    },
    {
      "x": -9,
      "y": 5,
      "z": -10,
      "name": "UnbreakableWall"
    },
    {
      "x": -9,
      "y": 6,
      "z": -10,
      "name": "UnbreakableWall"
    },
    {
      "x": -9,
      "y": 7,
      "z": -10,
      "name": "UnbreakableWall",
      "rotation": 2
    },
    {
      "x": -9,
      "y": 8,
      "z": -10,
      "name": "Build_Lightsource_YellowLight",
      "rotation": 7
    },
    {
      "x": -9,
      "y": 9,
      "z": -10,
      "name": "Build_Lightsource_YellowLight",
      "rotation": 7
    },
    {
      "x": -9,
      "y": 10,
      "z": -10,
      "name": "Build_Lightsource_YellowLight",
      "rotation": 7
    },
    {
      "x": -9,
      "y": 11,
      "z": -10,
      "name": "Build_Lightsource_YellowLight",
      "rotation": 7
    },
    {
      "x": -9,
      "y": 12,
      "z": -10,
      "name": "UnbreakableWall",
      "rotation": 2
    },
    {
      "x": -9,
      "y": 13,
      "z": -10,
      "name": "UnbreakableWall",
      "rotation": 2
    },
    {
      "x": -9,
      "y": 14,
      "z": -10,
      "name": "UnbreakableWall",
      "rotation": 2
    },
    {
      "x": -9,
      "y": 15,
      "z": -10,
      "name": "UnbreakableWall",
      "rotation": 2
    },
    {
      "x": -9,
      "y": 16,
      "z": -10,
      "name": "Rock_Volcanic_Cobble_Roof",
      "rotation": 3
    },
    {
      "x": -9,
      "y": 0,
      "z": -9,
      "name": "UnbreakableWall"
    },
    {
      "x": -9,
      "y": 1,
      "z": -9,
      "name": "UnbreakableWall"
    },
    {
      "x": -9,
      "y": 2,
      "z": -9,
      "name": "Furniture_Ancient_Crate",
      "rotation": 1
    },
    {
      "x": -9,
      "y": 3,
      "z": -9,
      "name": "Furniture_Ancient_Crate",
      "rotation": 1
    },
    {
      "x": -9,
      "y": 4,
      "z": -9,
      "name": "Empty"
    },
    {
      "x": -9,
      "y": 5,
      "z": -9,
      "name": "Plant_Vine_Thick_Roots"
    },
    {
      "x": -9,
      "y": 6,
      "z": -9,
      "name": "UnbreakableWall"
    },
    {
      "x": -9,
      "y": 7,
      "z": -9,
      "name": "UnbreakableWall",
      "rotation": 2
    },
    {
      "x": -9,
      "y": 8,
      "z": -9,
      "name": "Build_Lightsource_YellowLight",
      "rotation": 7
    },
    {
      "x": -9,
      "y": 9,
      "z": -9,
      "name": "Build_Lightsource_YellowLight",
      "rotation": 7
    },
    {
      "x": -9,
      "y": 10,
      "z": -9,
      "name": "Build_Lightsource_YellowLight",
      "rotation": 7
    },
    {
      "x": -9,
      "y": 11,
      "z": -9,
      "name": "Build_Lightsource_YellowLight",
      "rotation": 7
    },
    {
      "x": -9,
      "y": 12,
      "z": -9,
      "name": "Build_Lightsource_YellowLight",
      "rotation": 2
    },
    {
      "x": -9,
      "y": 13,
      "z": -9,
      "name": "UnbreakableWall",
      "rotation": 2
    },
    {
      "x": -9,
      "y": 14,
      "z": -9,
      "name": "UnbreakableWall",
      "rotation": 2
    },
    {
      "x": -9,
      "y": 15,
      "z": -9,
      "name": "UnbreakableWall",
      "rotation": 2
    },
    {
      "x": -9,
      "y": 16,
      "z": -9,
      "name": "Rock_Volcanic_Cobble_Roof",
      "rotation": 3
    },
    {
      "x": -9,
      "y": 0,
      "z": -8,
      "name": "UnbreakableWall"
    },
    {
      "x": -9,
      "y": 1,
      "z": -8,
      "name": "Soil_Grass_Sunny_Full"
    },
    {
      "x": -9,
      "y": 2,
      "z": -8,
      "name": "Furniture_Ancient_Crate",
      "rotation": 1
    },
    {
      "x": -9,
      "y": 3,
      "z": -8,
      "name": "Empty"
    },
    {
      "x": -9,
      "y": 4,
      "z": -8,
      "name": "Empty"
    },
    {
      "x": -9,
      "y": 5,
      "z": -8,
      "name": "Empty"
    },
    {
      "x": -9,
      "y": 6,
      "z": -8,
      "name": "UnbreakableWall"
    },
    {
      "x": -9,
      "y": 7,
      "z": -8,
      "name": "UnbreakableWall",
      "rotation": 2
    },
    {
      "x": -9,
      "y": 8,
      "z": -8,
      "name": "Build_Lightsource_YellowLight",
      "rotation": 7
    },
    {
      "x": -9,
      "y": 9,
      "z": -8,
      "name": "Build_Lightsource_YellowLight",
      "rotation": 7
    },
    {
      "x": -9,
      "y": 10,
      "z": -8,
      "name": "Build_Lightsource_YellowLight",
      "rotation": 7
    },
    {
      "x": -9,
      "y": 11,
      "z": -8,
      "name": "Build_Lightsource_YellowLight",
      "rotation": 7
    },
    {
      "x": -9,
      "y": 12,
      "z": -8,
      "name": "UnbreakableWall",
      "rotation": 2
    },
    {
      "x": -9,
      "y": 13,
      "z": -8,
      "name": "UnbreakableWall",
      "rotation": 2
    },
    {
      "x": -9,
      "y": 14,
