{
  "version": 8,
  "blockIdVersion": 11,
  "anchorX": 0,
  "anchorY": 10,
  "anchorZ": 0,
  "blocks": [
    {
      "x": -59,
      "y": 33,
      "z": -4,
      "name": "*Rock_Volcanic_Brick_Stairs_State_Definitions_Corner_Right",
      "rotation": 8
    },
    {
      "x": -59,
      "y": 34,
      "z": -4,
      "name": "Rock_Volcanic_Brick_Half"
    },
    {
      "x": -59,
      "y": 33,
      "z": -3,
      "name": "*Rock_Volcanic_Brick_Stairs_State_Definitions_Inverted_Corner_Left",
      "rotation": 9
    },
    {
      "x": -59,
      "y": 0,
      "z": -2,
      "name": "Rock_Volcanic_Cobble"
    },
    {
      "x": -59,
      "y": 1,
      "z": -2,
      "name": "Rock_Volcanic_Brick"
    },
    {
      "x": -59,
      "y": 2,
      "z": -2,
      "name": "Rock_Volcanic_Cobble"
    },
    {
      "x": -59,
      "y": 3,
      "z": -2,
      "name": "Rock_Volcanic_Brick"
    },
    {
      "x": -59,
      "y": 4,
      "z": -2,
      "name": "Rock_Volcanic_Cobble"
    },
    {
      "x": -59,
      "y": 5,
      "z": -2,
      "name": "Rock_Volcanic_Brick"
    },
    {
      "x": -59,
      "y": 6,
      "z": -2,
      "name": "Rock_Volcanic_Cobble"
    },
    {
      "x": -59,
      "y": 7,
      "z": -2,
      "name": "Rock_Volcanic_Cobble"
    },
    {
      "x": -59,
      "y": 8,
      "z": -2,
      "name": "Rock_Volcanic_Cobble"
    },
    {
      "x": -59,
      "y": 9,
      "z": -2,
      "name": "Rock_Volcanic_Brick"
    },
    {
      "x": -59,
      "y": 10,
      "z": -2,
      "name": "Rock_Volcanic_Brick"
    },
    {
      "x": -59,
      "y": 11,
      "z": -2,
      "name": "Rock_Volcanic_Brick"
    },
    {
      "x": -59,
      "y": 12,
      "z": -2,
      "name": "Rock_Volcanic_Brick"
    },
    {
      "x": -59,
      "y": 13,
      "z": -2,
      "name": "Rock_Volcanic_Brick"
    },
    {
      "x": -59,
      "y": 14,
      "z": -2,
      "name": "Rock_Volcanic_Brick"
    },
    {
      "x": -59,
      "y": 15,
      "z": -2,
      "name": "Rock_Volcanic_Brick"
    },
    {
      "x": -59,
      "y": 16,
      "z": -2,
      "name": "Rock_Volcanic_Cobble"
    },
    {
      "x": -59,
      "y": 17,
      "z": -2,
      "name": "Rock_Volcanic_Brick"
    },
    {
      "x": -59,
      "y": 18,
      "z": -2,
      "name": "Rock_Volcanic_Cobble"
    },
    {
      "x": -59,
      "y": 19,
      "z": -2,
      "name": "Rock_Volcanic_Cobble"
    },
    {
      "x": -59,
      "y": 20,
      "z": -2,
      "name": "Rock_Volcanic_Cobble"
    },
    {
      "x": -59,
      "y": 21,
      "z": -2,
      "name": "Rock_Volcanic_Cobble"
    },
    {
      "x": -59,
      "y": 22,
      "z": -2,
      "name": "Rock_Volcanic_Cobble"
    },
    {
      "x": -59,
      "y": 23,
      "z": -2,
      "name": "Rock_Volcanic_Brick"
    },
    {
      "x": -59,
      "y": 24,
      "z": -2,
      "name": "Rock_Volcanic_Cobble"
    },
    {
      "x": -59,
      "y": 25,
      "z": -2,
      "name": "Rock_Volcanic_Cobble"
    },
    {
      "x": -59,
      "y": 26,
      "z": -2,
      "name": "Rock_Volcanic_Brick"
    },
    {
      "x": -59,
      "y": 27,
      "z": -2,
      "name": "Rock_Volcanic_Cobble"
    },
    {
      "x": -59,
      "y": 28,
      "z": -2,
      "name": "Rock_Volcanic_Cobble"
    },
    {
      "x": -59,
      "y": 29,
      "z": -2,
      "name": "Rock_Volcanic_Brick"
    },
    {
      "x": -59,
      "y": 30,
      "z": -2,
      "name": "Rock_Volcanic_Brick"
    },
    {
      "x": -59,
      "y": 31,
      "z": -2,
      "name": "Rock_Volcanic_Brick"
    },
    {
      "x": -59,
      "y": 32,
      "z": -2,
      "name": "Rock_Volcanic_Brick"
    },
    {
      "x": -59,
      "y": 33,
      "z": -2,
      "name": "Rock_Volcanic_Cobble"
    },
    {
      "x": -59,
      "y": 0,
      "z": -1,
      "name": "Rock_Volcanic_Cobble"
    },
    {
      "x": -59,
      "y": 1,
      "z": -1,
      "name": "Rock_Volcanic_Brick"
    },
    {
      "x": -59,
      "y": 2,
      "z": -1,
      "name": "Rock_Volcanic_Brick"
    },
    {
      "x": -59,
      "y": 3,
      "z": -1,
      "name": "Rock_Volcanic_Cobble"
    },
    {
      "x": -59,
      "y": 4,
      "z": -1,
      "name": "Rock_Volcanic_Cobble"
    },
    {
      "x": -59,
      "y": 5,
      "z": -1,
      "name": "Rock_Volcanic_Cobble"
    },
    {
      "x": -59,
      "y": 6,
      "z": -1,
      "name": "Rock_Volcanic_Cobble"
    },
    {
      "x": -59,
      "y": 7,
      "z": -1,
      "name": "Rock_Volcanic_Cobble"
    },
    {
      "x": -59,
      "y": 8,
      "z": -1,
      "name": "Rock_Volcanic_Brick"
    },
    {
      "x": -59,
      "y": 9,
      "z": -1,
      "name": "Rock_Volcanic_Brick"
    },
    {
      "x": -59,
      "y": 10,
      "z": -1,
      "name": "Rock_Volcanic_Cobble"
    },
    {
      "x": -59,
      "y": 11,
      "z": -1,
      "name": "Rock_Volcanic_Brick"
    },
    {
      "x": -59,
      "y": 12,
      "z": -1,
      "name": "Rock_Volcanic_Brick"
    },
    {
      "x": -59,
      "y": 13,
      "z": -1,
      "name": "Rock_Volcanic_Cobble"
    },
    {
      "x": -59,
      "y": 14,
      "z": -1,
      "name": "Rock_Volcanic_Brick"
    },
    {
      "x": -59,
      "y": 15,
      "z": -1,
      "name": "Rock_Volcanic_Brick"
    },
    {
      "x": -59,
      "y": 16,
      "z": -1,
      "name": "Rock_Volcanic_Brick"
    },
    {
      "x": -59,
      "y": 17,
      "z": -1,
      "name": "Rock_Volcanic_Cobble"
    },
    {
      "x": -59,
      "y": 18,
      "z": -1,
      "name": "Rock_Volcanic_Cobble"
    },
    {
      "x": -59,
      "y": 19,
      "z": -1,
      "name": "Rock_Volcanic_Brick"
    },
    {
      "x": -59,
      "y": 20,
      "z": -1,
      "name": "Rock_Volcanic_Cobble"
    },
    {
      "x": -59,
      "y": 21,
      "z": -1,
      "name": "Rock_Volcanic_Brick"
    },
    {
      "x": -59,
      "y": 22,
      "z": -1,
      "name": "Rock_Volcanic_Cobble"
    },
    {
      "x": -59,
      "y": 23,
      "z": -1,
      "name": "Rock_Volcanic_Cobble"
    },
    {
      "x": -59,
      "y": 24,
      "z": -1,
      "name": "Rock_Volcanic_Cobble"
    },
    {
      "x": -59,
      "y": 25,
      "z": -1,
      "name": "Rock_Volcanic_Brick"
    },
    {
      "x": -59,
      "y": 26,
      "z": -1,
      "name": "Rock_Volcanic_Brick"
    },
    {
      "x": -59,
      "y": 30,
      "z": -1,
      "name": "Rock_Volcanic_Brick_Stairs",
      "rotation": 10
    },
    {
      "x": -59,
      "y": 31,
      "z": -1,
      "name": "Rock_Volcanic_Cobble"
    },
    {
      "x": -59,
      "y": 32,
      "z": -1,
      "name": "Rock_Volcanic_Cobble"
    },
    {
      "x": -59,
      "y": 33,
      "z": -1,
      "name": "Rock_Volcanic_Cobble"
    },
    {
      "x": -59,
      "y": 0,
      "z": 0,
      "name": "Rock_Volcanic_Brick"
    },
    {
      "x": -59,
      "y": 1,
      "z": 0,
      "name": "Rock_Volcanic_Brick"
    },
    {
      "x": -59,
      "y": 2,
      "z": 0,
      "name": "Rock_Volcanic_Brick"
    },
    {
      "x": -59,
      "y": 3,
      "z": 0,
      "name": "Rock_Volcanic_Cobble"
    },
    {
      "x": -59,
      "y": 4,
      "z": 0,
      "name": "Rock_Volcanic_Cobble"
    },
    {
      "x": -59,
      "y": 5,
      "z": 0,
      "name": "Rock_Volcanic_Brick"
    },
    {
      "x": -59,
      "y": 6,
      "z": 0,
      "name": "Rock_Volcanic_Cobble"
    },
    {
      "x": -59,
      "y": 7,
      "z": 0,
      "name": "Rock_Volcanic_Brick"
    },
    {
      "x": -59,
      "y": 8,
      "z": 0,
      "name": "Rock_Volcanic_Cobble"
    },
    {
      "x": -59,
      "y": 9,
      "z": 0,
      "name": "Rock_Volcanic_Brick"
    },
    {
      "x": -59,
      "y": 10,
      "z": 0,
      "name": "Rock_Volcanic_Brick"
    },
    {
      "x": -59,
      "y": 11,
      "z": 0,
      "name": "Rock_Volcanic_Brick"
    },
    {
      "x": -59,
      "y": 12,
      "z": 0,
      "name": "Rock_Volcanic_Brick"
    },
    {
      "x": -59,
      "y": 13,
      "z": 0,
      "name": "Rock_Volcanic_Brick"
    },
    {
      "x": -59,
      "y": 14,
      "z": 0,
      "name": "Rock_Volcanic_Brick"
    },
    {
      "x": -59,
      "y": 17,
      "z": 0,
      "name": "Rock_Volcanic_Cobble"
    },
    {
      "x": -59,
      "y": 18,
      "z": 0,
      "name": "Rock_Volcanic_Cobble"
    },
    {
      "x": -59,
      "y": 19,
      "z": 0,
      "name": "Rock_Volcanic_Cobble"
    },
    {
      "x": -59,
      "y": 20,
      "z": 0,
      "name": "Rock_Volcanic_Brick"
    },
    {
      "x": -59,
      "y": 21,
      "z": 0,
      "name": "Rock_Volcanic_Brick"
    },
    {
      "x": -59,
      "y": 24,
      "z": 0,
      "name": "Rock_Volcanic_Brick"
    },
    {
      "x": -59,
      "y": 25,
      "z": 0,
      "name": "Rock_Volcanic_Brick"
    },
    {
      "x": -59,
      "y": 26,
      "z": 0,
      "name": "Rock_Volcanic_Cobble"
    },
    {
      "x": -59,
      "y": 31,
      "z": 0,
      "name": "Rock_Volcanic_Cobble"
    },
    {
      "x": -59,
      "y": 32,
      "z": 0,
      "name": "Rock_Volcanic_Brick"
    },
    {
      "x": -59,
      "y": 33,
      "z": 0,
      "name": "Rock_Volcanic_Brick"
    },
    {
      "x": -59,
      "y": 0,
      "z": 1,
      "name": "Rock_Volcanic_Cobble"
    },
    {
      "x": -59,
      "y": 1,
      "z": 1,
      "name": "Rock_Volcanic_Brick"
    },
    {
      "x": -59,
      "y": 2,
      "z": 1,
      "name": "Rock_Volcanic_Cobble"
    },
    {
      "x": -59,
      "y": 3,
      "z": 1,
      "name": "Rock_Volcanic_Brick"
    },
    {
      "x": -59,
      "y": 4,
      "z": 1,
      "name": "Rock_Volcanic_Brick"
    },
    {
      "x": -59,
      "y": 5,
      "z": 1,
      "name": "Rock_Volcanic_Cobble"
    },
    {
      "x": -59,
      "y": 6,
      "z": 1,
      "name": "Rock_Volcanic_Brick"
    },
    {
      "x": -59,
      "y": 7,
      "z": 1,
      "name": "Rock_Volcanic_Brick"
    },
    {
      "x": -59,
      "y": 8,
      "z": 1,
      "name": "Rock_Volcanic_Cobble"
    },
    {
      "x": -59,
      "y": 9,
      "z": 1,
      "name": "Rock_Volcanic_Brick"
    },
    {
      "x": -59,
      "y": 10,
      "z": 1,
      "name": "Rock_Volcanic_Brick"
    },
    {
      "x": -59,
      "y": 11,
      "z": 1,
      "name": "Rock_Volcanic_Brick"
    },
    {
      "x": -59,
      "y": 12,
      "z": 1,
      "name": "Rock_Volcanic_Brick"
    },
    {
      "x": -59,
      "y": 13,
      "z": 1,
      "name": "Rock_Volcanic_Brick"
    },
    {
      "x": -59,
      "y": 14,
      "z": 1,
      "name": "Rock_Volcanic_Brick"
    },
    {
      "x": -59,
      "y": 15,
      "z": 1,
      "name": "Rock_Volcanic_Brick"
    },
    {
      "x": -59,
      "y": 16,
      "z": 1,
      "name": "Rock_Volcanic_Cobble"
    },
    {
      "x": -59,
      "y": 17,
      "z": 1,
      "name": "Rock_Volcanic_Brick"
    },
    {
      "x": -59,
      "y": 18,
      "z": 1,
      "name": "Rock_Volcanic_Cobble"
    },
    {
      "x": -59,
      "y": 19,
      "z": 1,
      "name": "Rock_Volcanic_Brick"
    },
    {
      "x": -59,
      "y": 20,
      "z": 1,
      "name": "Rock_Volcanic_Brick"
    },
    {
      "x": -59,
      "y": 21,
      "z": 1,
      "name": "Rock_Volcanic_Cobble"
    },
    {
      "x": -59,
      "y": 22,
      "z": 1,
      "name": "Rock_Volcanic_Brick"
    },
    {
      "x": -59,
      "y": 23,
      "z": 1,
      "name": "Rock_Volcanic_Brick"
    },
    {
      "x": -59,
      "y": 24,
      "z": 1,
      "name": "Rock_Volcanic_Brick"
    },
    {
      "x": -59,
      "y": 25,
      "z": 1,
      "name": "Rock_Volcanic_Brick"
    },
    {
      "x": -59,
      "y": 26,
      "z": 1,
      "name": "Rock_Volcanic_Cobble"
    },
    {
      "x": -59,
      "y": 30,
      "z": 1,
      "name": "Rock_Volcanic_Brick_Stairs",
      "rotation": 8
    },
    {
      "x": -59,
      "y": 31,
      "z": 1,
      "name": "Rock_Volcanic_Brick"
    },
    {
      "x": -59,
      "y": 32,
      "z": 1,
      "name": "Rock_Volcanic_Cobble"
    },
    {
      "x": -59,
      "y": 33,
      "z": 1,
      "name": "Rock_Volcanic_Cobble"
    },
    {
      "x": -59,
      "y": 0,
      "z": 2,
      "name": "Rock_Volcanic_Cobble"
    },
    {
      "x": -59,
      "y": 1,
      "z": 2,
      "name": "Rock_Volcanic_Brick"
    },
    {
      "x": -59,
      "y": 2,
      "z": 2,
      "name": "Rock_Volcanic_Cobble"
    },
    {
      "x": -59,
      "y": 3,
      "z": 2,
      "name": "Rock_Volcanic_Brick"
    },
    {
      "x": -59,
      "y": 4,
      "z": 2,
      "name": "Rock_Volcanic_Cobble"
    },
    {
      "x": -59,
      "y": 5,
      "z": 2,
      "name": "Rock_Volcanic_Cobble"
    },
    {
      "x": -59,
      "y": 6,
      "z": 2,
      "name": "Rock_Volcanic_Cobble"
    },
    {
      "x": -59,
      "y": 7,
      "z": 2,
      "name": "Rock_Volcanic_Cobble"
    },
    {
      "x": -59,
      "y": 8,
      "z": 2,
      "name": "Rock_Volcanic_Cobble"
    },
    {
      "x": -59,
      "y": 9,
      "z": 2,
      "name": "Rock_Volcanic_Cobble"
    },
    {
      "x": -59,
      "y": 10,
      "z": 2,
      "name": "Rock_Volcanic_Cobble"
    },
    {
      "x": -59,
      "y": 11,
      "z": 2,
      "name": "Rock_Volcanic_Brick"
    },
    {
      "x": -59,
      "y": 12,
      "z": 2,
      "name": "Rock_Volcanic_Brick"
    },
    {
      "x": -59,
      "y": 13,
      "z": 2,
      "name": "Rock_Volcanic_Brick"
    },
    {
      "x": -59,
      "y": 14,
      "z": 2,
      "name": "Rock_Volcanic_Brick"
    },
    {
      "x": -59,
      "y": 15,
      "z": 2,
      "name": "Rock_Volcanic_Cobble"
    },
    {
      "x": -59,
      "y": 16,
      "z": 2,
      "name": "Rock_Volcanic_Brick"
    },
    {
      "x": -59,
      "y": 17,
      "z": 2,
      "name": "Rock_Volcanic_Brick"
    },
    {
      "x": -59,
      "y": 18,
      "z": 2,
      "name": "Rock_Volcanic_Brick"
    },
    {
      "x": -59,
      "y": 19,
      "z": 2,
      "name": "Rock_Volcanic_Brick"
    },
    {
      "x": -59,
      "y": 20,
      "z": 2,
      "name": "Rock_Volcanic_Brick"
    },
    {
      "x": -59,
      "y": 21,
      "z": 2,
      "name": "Rock_Volcanic_Cobble"
    },
    {
      "x": -59,
      "y": 22,
      "z": 2,
      "name": "Rock_Volcanic_Brick"
    },
    {
      "x": -59,
      "y": 23,
      "z": 2,
      "name": "Rock_Volcanic_Cobble"
    },
    {
      "x": -59,
      "y": 24,
      "z": 2,
      "name": "Rock_Volcanic_Brick"
    },
    {
      "x": -59,
      "y": 25,
      "z": 2,
      "name": "Rock_Volcanic_Brick"
    },
    {
      "x": -59,
      "y": 26,
      "z": 2,
      "name": "Rock_Volcanic_Brick"
    },
    {
      "x": -59,
      "y": 27,
      "z": 2,
      "name": "Rock_Volcanic_Brick"
    },
    {
      "x": -59,
      "y": 28,
      "z": 2,
      "name": "Rock_Volcanic_Brick"
    },
    {
      "x": -59,
      "y": 29,
      "z": 2,
      "name": "Rock_Volcanic_Cobble"
    },
    {
      "x": -59,
      "y": 30,
      "z": 2,
      "name": "Rock_Volcanic_Cobble"
    },
    {
      "x": -59,
      "y": 31,
      "z": 2,
      "name": "Rock_Volcanic_Brick"
    },
    {
      "x": -59,
      "y": 32,
      "z": 2,
      "name": "Rock_Volcanic_Cobble"
    },
    {
      "x": -59,
      "y": 33,
      "z": 2,
      "name": "Rock_Volcanic_Brick"
    },
    {
      "x": -59,
      "y": 33,
      "z": 3,
      "name": "*Rock_Volcanic_Brick_Stairs_State_Definitions_Inverted_Corner_Left",
      "rotation": 10
    },
    {
      "x": -59,
      "y": 33,
      "z": 4,
      "name": "*Rock_Volcanic_Brick_Stairs_State_Definitions_Corner_Right",
      "rotation": 9
    },
    {
      "x": -59,
      "y": 34,
      "z": 4,
      "name": "Rock_Volcanic_Brick_Half"
    },
    {
      "x": -58,
      "y": 33,
      "z": -5,
      "name": "*Rock_Volcanic_Brick_Stairs_State_Definitions_Corner_Right",
      "rotation": 8
    },
    {
      "x": -58,
      "y": 34,
      "z": -5,
      "name": "Rock_Volcanic_Brick_Half"
    },
    {
      "x": -58,
      "y": 33,
      "z": -4,
      "name": "*Rock_Volcanic_Brick_Stairs_State_Definitions_Inverted_Corner_Left",
      "rotation": 9
    },
    {
      "x": -58,
      "y": 0,
      "z": -3,
      "name": "Rock_Volcanic_Cobble"
    },
    {
      "x": -58,
      "y": 1,
      "z": -3,
      "name": "Rock_Volcanic_Brick"
    },
    {
      "x": -58,
      "y": 2,
      "z": -3,
      "name": "Rock_Volcanic_Cobble"
    },
    {
      "x": -58,
      "y": 3,
      "z": -3,
      "name": "Rock_Volcanic_Brick"
    },
    {
      "x": -58,
      "y": 4,
      "z": -3,
      "name": "Rock_Volcanic_Brick"
    },
    {
      "x": -58,
      "y": 5,
      "z": -3,
      "name": "Rock_Volcanic_Brick"
    },
    {
      "x": -58,
      "y": 6,
      "z": -3,
      "name": "Rock_Volcanic_Brick"
    },
    {
      "x": -58,
      "y": 7,
      "z": -3,
      "name": "Rock_Volcanic_Cobble"
    },
    {
      "x": -58,
      "y": 8,
      "z": -3,
      "name": "Rock_Volcanic_Brick"
    },
    {
      "x": -58,
      "y": 9,
      "z": -3,
      "name": "Rock_Volcanic_Brick"
    },
    {
      "x": -58,
      "y": 10,
      "z": -3,
      "name": "Rock_Volcanic_Brick"
    },
    {
      "x": -58,
      "y": 11,
      "z": -3,
      "name": "Rock_Volcanic_Cobble"
    },
    {
      "x": -58,
      "y": 12,
      "z": -3,
      "name": "Rock_Volcanic_Cobble"
    },
    {
      "x": -58,
      "y": 13,
      "z": -3,
      "name": "Rock_Volcanic_Brick"
    },
    {
      "x": -58,
      "y": 14,
      "z": -3,
      "name": "Rock_Volcanic_Cobble"
    },
    {
      "x": -58,
      "y": 15,
      "z": -3,
      "name": "Rock_Volcanic_Cobble"
    },
    {
      "x": -58,
      "y": 16,
      "z": -3,
      "name": "Rock_Volcanic_Cobble"
    },
    {
      "x": -58,
      "y": 17,
      "z": -3,
      "name": "Rock_Volcanic_Cobble"
    },
    {
      "x": -58,
      "y": 18,
      "z": -3,
      "name": "Rock_Volcanic_Brick"
    },
    {
      "x": -58,
      "y": 19,
      "z": -3,
      "name": "Rock_Volcanic_Brick"
    },
    {
      "x": -58,
      "y": 20,
      "z": -3,
      "name": "Rock_Volcanic_Cobble"
    },
    {
      "x": -58,
      "y": 21,
      "z": -3,
      "name": "Rock_Volcanic_Cobble"
    },
    {
      "x": -58,
      "y": 22,
      "z": -3,
      "name": "Rock_Volcanic_Cobble"
    },
    {
      "x": -58,
      "y": 23,
      "z": -3,
      "name": "Rock_Volcanic_Cobble"
    },
    {
      "x": -58,
      "y": 24,
      "z": -3,
      "name": "Rock_Volcanic_Brick"
    },
    {
      "x": -58,
      "y": 25,
      "z": -3,
      "name": "Rock_Volcanic_Brick"
    },
    {
      "x": -58,
      "y": 26,
      "z": -3,
      "name": "Rock_Volcanic_Cobble"
    },
    {
      "x": -58,
      "y": 27,
      "z": -3,
      "name": "Rock_Volcanic_Brick"
    },
    {
      "x": -58,
      "y": 28,
      "z": -3,
      "name": "Rock_Volcanic_Cobble"
    },
    {
      "x": -58,
      "y": 29,
      "z": -3,
      "name": "Rock_Volcanic_Brick"
    },
    {
      "x": -58,
      "y": 30,
      "z": -3,
      "name": "Rock_Volcanic_Cobble"
    },
    {
      "x": -58,
      "y": 31,
      "z": -3,
      "name": "Rock_Volcanic_Cobble"
    },
    {
      "x": -58,
      "y": 32,
      "z": -3,
      "name": "Rock_Volcanic_Brick"
    },
    {
      "x": -58,
      "y": 33,
      "z": -3,
      "name": "Rock_Volcanic_Brick"
    },
    {
      "x": -58,
      "y": 0,
      "z": -2,
      "name": "Rock_Volcanic_Brick"
    },
    {
      "x": -58,
      "y": 1,
      "z": -2,
      "name": "Rock_Volcanic_Cobble"
    },
    {
      "x": -58,
      "y": 2,
      "z": -2,
      "name": "Rock_Volcanic_Cobble"
    },
    {
      "x": -58,
      "y": 3,
      "z": -2,
      "name": "Rock_Volcanic_Cobble"
    },
    {
      "x": -58,
      "y": 4,
      "z": -2,
      "name": "Rock_Volcanic_Brick"
    },
    {
      "x": -58,
      "y": 5,
      "z": -2,
      "name": "Rock_Volcanic_Brick"
    },
    {
      "x": -58,
      "y": 6,
      "z": -2,
      "name": "Rock_Volcanic_Brick"
    },
    {
      "x": -58,
      "y": 7,
      "z": -2,
      "name": "Rock_Volcanic_Brick"
    },
    {
      "x": -58,
      "y": 8,
      "z": -2,
      "name": "Rock_Volcanic_Cobble"
    },
    {
      "x": -58,
      "y": 9,
      "z": -2,
      "name": "Rock_Volcanic_Cobble"
    },
    {
      "x": -58,
      "y": 10,
      "z": -2,
      "name": "Rock_Volcanic_Brick"
    },
    {
      "x": -58,
      "y": 11,
      "z": -2,
      "name": "Rock_Volcanic_Cobble"
    },
    {
      "x": -58,
      "y": 12,
      "z": -2,
      "name": "Rock_Volcanic_Brick"
    },
    {
      "x": -58,
      "y": 13,
      "z": -2,
      "name": "Rock_Volcanic_Brick"
    },
    {
      "x": -58,
      "y": 14,
      "z": -2,
      "name": "Rock_Volcanic_Brick"
    },
    {
      "x": -58,
      "y": 15,
      "z": -2,
      "name": "Rock_Volcanic_Cobble"
    },
    {
      "x": -58,
      "y": 16,
      "z": -2,
      "name": "Rock_Volcanic_Brick"
    },
    {
      "x": -58,
      "y": 17,
      "z": -2,
      "name": "Rock_Volcanic_Brick"
    },
    {
      "x": -58,
      "y": 18,
      "z": -2,
      "name": "Rock_Volcanic_Brick"
    },
    {
      "x": -58,
      "y": 19,
      "z": -2,
      "name": "Rock_Volcanic_Cobble"
    },
    {
      "x": -58,
      "y": 20,
      "z": -2,
      "name": "Rock_Volcanic_Brick"
    },
    {
      "x": -58,
      "y": 21,
      "z": -2,
      "name": "Rock_Volcanic_Cobble"
    },
    {
      "x": -58,
      "y": 22,
      "z": -2,
      "name": "Rock_Volcanic_Brick"
    },
    {
      "x": -58,
      "y": 23,
      "z": -2,
      "name": "Rock_Volcanic_Brick"
    },
    {
      "x": -58,
      "y": 24,
      "z": -2,
      "name": "Rock_Volcanic_Brick"
    },
    {
      "x": -58,
      "y": 25,
      "z": -2,
      "name": "Rock_Volcanic_Cobble"
    },
    {
      "x": -58,
      "y": 26,
      "z": -2,
      "name": "Rock_Volcanic_Brick"
    },
    {
      "x": -58,
      "y": 27,
      "z": -2,
      "name": "Rock_Volcanic_Cobble"
    },
    {
      "x": -58,
      "y": 28,
      "z": -2,
      "name": "Rock_Volcanic_Cobble"
    },
    {
      "x": -58,
      "y": 29,
      "z": -2,
      "name": "Rock_Volcanic_Brick"
    },
    {
      "x": -58,
      "y": 30,
      "z": -2,
      "name": "Rock_Volcanic_Cobble"
    },
    {
      "x": -58,
      "y": 31,
      "z": -2,
      "name": "Rock_Volcanic_Brick"
    },
    {
      "x": -58,
      "y": 32,
      "z": -2,
      "name": "Rock_Volcanic_Cobble"
    },
    {
      "x": -58,
      "y": 33,
      "z": -2,
      "name": "Rock_Volcanic_Brick"
    },
    {
      "x": -58,
      "y": 14,
      "z": -1,
      "name": "Rock_Volcanic_Brick"
    },
    {
      "x": -58,
      "y": 21,
      "z": -1,
      "name": "Rock_Volcanic_Brick"
    },
    {
      "x": -58,
      "y": 26,
      "z": -1,
      "name": "Rock_Volcanic_Brick"
    },
    {
      "x": -58,
      "y": 33,
      "z": -1,
      "name": "Rock_Volcanic_Brick"
    },
    {
      "x": -58,
      "y": 14,
      "z": 0,
      "name": "Rock_Volcanic_Brick"
    },
    {
      "x": -58,
      "y": 21,
      "z": 0,
      "name": "Rock_Volcanic_Brick"
    },
    {
      "x": -58,
      "y": 26,
      "z": 0,
      "name": "Rock_Volcanic_Brick"
    },
    {
      "x": -58,
      "y": 33,
      "z": 0,
      "name": "Rock_Volcanic_Brick"
    },
    {
      "x": -58,
      "y": 14,
      "z": 1,
      "name": "Rock_Volcanic_Brick"
    },
    {
      "x": -58,
      "y": 21,
      "z": 1,
      "name": "Rock_Volcanic_Brick"
    },
    {
      "x": -58,
      "y": 26,
      "z": 1,
      "name": "Rock_Volcanic_Brick"
    },
    {
      "x": -58,
      "y": 33,
      "z": 1,
      "name": "Rock_Volcanic_Brick"
    },
    {
      "x": -58,
      "y": 0,
      "z": 2,
      "name": "Rock_Volcanic_Cobble"
    },
    {
      "x": -58,
      "y": 1,
      "z": 2,
      "name": "Rock_Volcanic_Brick"
    },
    {
      "x": -58,
      "y": 2,
      "z": 2,
      "name": "Rock_Volcanic_Brick"
    },
    {
      "x": -58,
      "y": 3,
      "z": 2,
      "name": "Rock_Volcanic_Brick"
    },
    {
      "x": -58,
      "y": 4,
      "z": 2,
      "name": "Rock_Volcanic_Brick"
    },
    {
      "x": -58,
      "y": 5,
      "z": 2,
      "name": "Rock_Volcanic_Brick"
    },
    {
      "x": -58,
      "y": 6,
      "z": 2,
      "name": "Rock_Volcanic_Cobble"
    },
    {
      "x": -58,
      "y": 7,
      "z": 2,
      "name": "Rock_Volcanic_Brick"
    },
    {
      "x": -58,
      "y": 8,
      "z": 2,
      "name": "Rock_Volcanic_Brick"
    },
    {
      "x": -58,
      "y": 9,
      "z": 2,
      "name": "Rock_Volcanic_Brick"
    },
    {
      "x": -58,
      "y": 10,
      "z": 2,
      "name": "Rock_Volcanic_Brick"
    },
    {
      "x": -58,
      "y": 11,
      "z": 2,
      "name": "Rock_Volcanic_Cobble"
    },
    {
      "x": -58,
      "y": 12,
      "z": 2,
      "name": "Rock_Volcanic_Brick"
    },
    {
      "x": -58,
      "y": 13,
      "z": 2,
      "name": "Rock_Volcanic_Cobble"
    },
    {
      "x": -58,
      "y": 14,
      "z": 2,
      "name": "Rock_Volcanic_Brick"
    },
    {
      "x": -58,
      "y": 15,
      "z": 2,
      "name": "Rock_Volcanic_Brick"
    },
    {
      "x": -58,
      "y": 16,
      "z": 2,
      "name": "Rock_Volcanic_Brick"
    },
    {
      "x": -58,
      "y": 17,
      "z": 2,
      "name": "Rock_Volcanic_Cobble"
    },
    {
      "x": -58,
      "y": 18,
      "z": 2,
      "name": "Rock_Volcanic_Cobble"
    },
    {
      "x": -58,
      "y": 19,
      "z": 2,
      "name": "Rock_Volcanic_Brick"
    },
    {
      "x": -58,
      "y": 20,
      "z": 2,
      "name": "Rock_Volcanic_Brick"
    },
    {
      "x": -58,
      "y": 21,
      "z": 2,
      "name": "Rock_Volcanic_Cobble"
    },
    {
      "x": -58,
      "y": 22,
      "z": 2,
      "name": "Rock_Volcanic_Brick"
    },
    {
      "x": -58,
      "y": 23,
      "z": 2,
      "name": "Rock_Volcanic_Cobble"
    },
    {
      "x": -58,
      "y": 24,
      "z": 2,
      "name": "Rock_Volcanic_Brick"
    },
    {
      "x": -58,
      "y": 25,
      "z": 2,
      "name": "Rock_Volcanic_Brick"
    },
    {
      "x": -58,
      "y": 26,
      "z": 2,
      "name": "Rock_Volcanic_Cobble"
    },
    {
      "x": -58,
      "y": 27,
      "z": 2,
      "name": "Rock_Volcanic_Brick"
    },
    {
      "x": -58,
      "y": 28,
      "z": 2,
      "name": "Rock_Volcanic_Brick"
    },
    {
      "x": -58,
      "y": 29,
      "z": 2,
      "name": "Rock_Volcanic_Brick"
    },
    {
      "x": -58,
      "y": 30,
      "z": 2,
      "name": "Rock_Volcanic_Cobble"
    },
    {
      "x": -58,
      "y": 31,
      "z": 2,
      "name": "Rock_Volcanic_Cobble"
    },
    {
      "x": -58,
      "y": 32,
      "z": 2,
      "name": "Rock_Volcanic_Cobble"
    },
    {
      "x": -58,
      "y": 33,
      "z": 2,
      "name": "Rock_Volcanic_Brick"
    },
    {
      "x": -58,
      "y": 0,
      "z": 3,
      "name": "Rock_Volcanic_Brick"
    },
    {
      "x": -58,
      "y": 1,
      "z": 3,
      "name": "Rock_Volcanic_Brick"
    },
    {
      "x": -58,
      "y": 2,
      "z": 3,
      "name": "Rock_Volcanic_Cobble"
    },
    {
      "x": -58,
      "y": 3,
      "z": 3,
      "name": "Rock_Volcanic_Cobble"
    },
    {
      "x": -58,
      "y": 4,
      "z": 3,
      "name": "Rock_Volcanic_Cobble"
    },
    {
      "x": -58,
      "y": 5,
      "z": 3,
      "name": "Rock_Volcanic_Brick"
    },
    {
      "x": -58,
      "y": 6,
      "z": 3,
      "name": "Rock_Volcanic_Brick"
    },
    {
      "x": -58,
      "y": 7,
      "z": 3,
      "name": "Rock_Volcanic_Brick"
    },
    {
      "x": -58,
      "y": 8,
      "z": 3,
      "name": "Rock_Volcanic_Brick"
    },
    {
      "x": -58,
      "y": 9,
      "z": 3,
      "name": "Rock_Volcanic_Brick"
    },
    {
      "x": -58,
      "y": 10,
      "z": 3,
      "name": "Rock_Volcanic_Cobble"
    },
    {
      "x": -58,
      "y": 11,
      "z": 3,
      "name": "Rock_Volcanic_Brick"
    },
    {
      "x": -58,
      "y": 12,
      "z": 3,
      "name": "Rock_Volcanic_Cobble"
    },
    {
      "x": -58,
      "y": 13,
      "z": 3,
      "name": "Rock_Volcanic_Brick"
    },
    {
      "x": -58,
      "y": 14,
      "z": 3,
      "name": "Rock_Volcanic_Brick"
    },
    {
      "x": -58,
      "y": 15,
      "z": 3,
      "name": "Rock_Volcanic_Cobble"
    },
    {
      "x": -58,
      "y": 16,
      "z": 3,
      "name": "Rock_Volcanic_Brick"
    },
    {
      "x": -58,
      "y": 17,
      "z": 3,
      "name": "Rock_Volcanic_Brick"
    },
    {
      "x": -58,
      "y": 18,
      "z": 3,
      "name": "Rock_Volcanic_Brick"
    },
    {
      "x": -58,
      "y": 19,
      "z": 3,
      "name": "Rock_Volcanic_Cobble"
    },
    {
      "x": -58,
      "y": 20,
      "z": 3,
      "name": "Rock_Volcanic_Brick"
    },
    {
      "x": -58,
      "y": 21,
      "z": 3,
      "name": "Rock_Volcanic_Cobble"
    },
    {
      "x": -58,
      "y": 22,
      "z": 3,
      "name": "Rock_Volcanic_Cobble"
    },
    {
      "x": -58,
      "y": 23,
      "z": 3,
      "name": "Rock_Volcanic_Cobble"
    },
    {
      "x": -58,
      "y": 24,
      "z": 3,
      "name": "Rock_Volcanic_Cobble"
    },
    {
      "x": -58,
      "y": 25,
      "z": 3,
      "name": "Rock_Volcanic_Cobble"
    },
    {
      "x": -58,
      "y": 26,
      "z": 3,
      "name": "Rock_Volcanic_Brick"
    },
    {
      "x": -58,
      "y": 27,
      "z": 3,
      "name": "Rock_Volcanic_Cobble"
    },
    {
      "x": -58,
      "y": 28,
      "z": 3,
      "name": "Rock_Volcanic_Brick"
    },
    {
      "x": -58,
      "y": 29,
      "z": 3,
      "name": "Rock_Volcanic_Brick"
    },
    {
      "x": -58,
      "y": 30,
      "z": 3,
      "name": "Rock_Volcanic_Cobble"
    },
    {
      "x": -58,
      "y": 31,
      "z": 3,
      "name": "Rock_Volcanic_Brick"
    },
    {
      "x": -58,
      "y": 32,
      "z": 3,
      "name": "Rock_Volcanic_Brick"
    },
    {
      "x": -58,
      "y": 33,
      "z": 3,
      "name": "Rock_Volcanic_Cobble"
    },
    {
      "x": -58,
      "y": 33,
      "z": 4,
      "name": "*Rock_Volcanic_Brick_Stairs_State_Definitions_Inverted_Corner_Left",
      "rotation": 10
    },
    {
      "x": -58,
      "y": 33,
      "z": 5,
      "name": "*Rock_Volcanic_Brick_Stairs_State_Definitions_Corner_Right",
      "rotation": 9
    },
    {
      "x": -58,
      "y": 34,
      "z": 5,
      "name": "Rock_Volcanic_Brick_Half"
    },
    {
      "x": -57,
      "y": 33,
      "z": -6,
      "name": "*Rock_Volcanic_Brick_Stairs_State_Definitions_Corner_Right",
      "rotation": 8
    },
    {
      "x": -57,
      "y": 34,
      "z": -6,
      "name": "Rock_Volcanic_Brick_Half"
    },
    {
      "x": -57,
      "y": 33,
      "z": -5,
      "name": "*Rock_Volcanic_Brick_Stairs_State_Definitions_Inverted_Corner_Left",
      "rotation": 9
    },
    {
      "x": -57,
      "y": 0,
      "z": -4,
      "name": "Rock_Volcanic_Brick"
    },
    {
      "x": -57,
      "y": 1,
      "z": -4,
      "name": "Rock_Volcanic_Brick"
    },
    {
      "x": -57,
      "y": 2,
      "z": -4,
      "name": "Rock_Volcanic_Brick"
    },
    {
      "x": -57,
      "y": 3,
      "z": -4,
      "name": "Rock_Volcanic_Brick"
    },
    {
      "x": -57,
      "y": 4,
      "z": -4,
      "name": "Rock_Volcanic_Brick"
    },
    {
      "x": -57,
      "y": 5,
      "z": -4,
      "name": "Rock_Volcanic_Brick"
    },
    {
      "x": -57,
      "y": 6,
      "z": -4,
      "name": "Rock_Volcanic_Cobble"
    },
    {
      "x": -57,
      "y": 7,
      "z": -4,
      "name": "Rock_Volcanic_Cobble"
    },
    {
      "x": -57,
      "y": 8,
      "z": -4,
      "name": "Rock_Volcanic_Cobble"
    },
    {
      "x": -57,
      "y": 9,
      "z": -4,
      "name": "Rock_Volcanic_Brick"
    },
    {
      "x": -57,
      "y": 10,
      "z": -4,
      "name": "Rock_Volcanic_Cobble"
    },
    {
      "x": -57,
      "y": 11,
      "z": -4,
      "name": "Rock_Volcanic_Cobble"
    },
    {
      "x": -57,
      "y": 12,
      "z": -4,
      "name": "Rock_Volcanic_Brick"
    },
    {
      "x": -57,
      "y": 13,
      "z": -4,
      "name": "Rock_Volcanic_Brick"
    },
    {
      "x": -57,
      "y": 14,
      "z": -4,
      "name": "Rock_Volcanic_Brick"
    },
    {
      "x": -57,
      "y": 15,
      "z": -4,
      "name": "Rock_Volcanic_Cobble"
    },
    {
      "x": -57,
      "y": 16,
      "z": -4,
      "name": "Rock_Volcanic_Cobble"
    },
    {
      "x": -57,
      "y": 17,
      "z": -4,
      "name": "Rock_Volcanic_Cobble"
    },
    {
      "x": -57,
      "y": 18,
      "z": -4,
      "name": "Rock_Volcanic_Cobble"
    },
    {
      "x": -57,
      "y": 19,
      "z": -4,
      "name": "Rock_Volcanic_Cobble"
    },
    {
      "x": -57,
      "y": 20,
      "z": -4,
      "name": "Rock_Volcanic_Cobble"
    },
    {
      "x": -57,
      "y": 21,
      "z": -4,
      "name": "Rock_Volcanic_Cobble"
    },
    {
      "x": -57,
      "y": 22,
      "z": -4,
      "name": "Rock_Volcanic_Cobble"
    },
    {
      "x": -57,
      "y": 23,
      "z": -4,
      "name": "Rock_Volcanic_Cobble"
    },
    {
      "x": -57,
      "y": 24,
      "z": -4,
      "name": "Rock_Volcanic_Brick"
    },
    {
      "x": -57,
      "y": 25,
      "z": -4,
      "name": "Rock_Volcanic_Brick"
    },
    {
      "x": -57,
      "y": 26,
      "z": -4,
      "name": "Rock_Volcanic_Cobble"
    },
    {
      "x": -57,
      "y": 27,
      "z": -4,
      "name": "Rock_Volcanic_Brick"
    },
    {
      "x": -57,
      "y": 28,
      "z": -4,
      "name": "Rock_Volcanic_Brick"
    },
    {
      "x": -57,
      "y": 29,
      "z": -4,
      "name": "Rock_Volcanic_Brick"
    },
    {
      "x": -57,
      "y": 30,
      "z": -4,
      "name": "Rock_Volcanic_Brick"
    },
    {
      "x": -57,
      "y": 31,
      "z": -4,
      "name": "Rock_Volcanic_Cobble"
    },
    {
      "x": -57,
      "y": 32,
      "z": -4,
      "name": "Rock_Volcanic_Brick"
    },
    {
      "x": -57,
      "y": 33,
      "z": -4,
      "name": "Rock_Volcanic_Cobble"
    },
    {
      "x": -57,
      "y": 14,
      "z": -3,
      "name": "Rock_Volcanic_Brick"
    },
    {
      "x": -57,
      "y": 21,
      "z": -3,
      "name": "Rock_Volcanic_Brick"
    },
    {
      "x": -57,
      "y": 26,
      "z": -3,
      "name": "Rock_Volcanic_Brick"
    },
    {
      "x": -57,
      "y": 33,
      "z": -3,
      "name": "Rock_Volcanic_Brick"
    },
    {
      "x": -57,
      "y": 14,
      "z": -2,
      "name": "Rock_Volcanic_Brick"
    },
    {
      "x": -57,
      "y": 21,
      "z": -2,
      "name": "Rock_Volcanic_Brick"
    },
    {
      "x": -57,
      "y": 26,
      "z": -2,
      "name": "Rock_Volcanic_Brick"
    },
    {
      "x": -57,
      "y": 33,
      "z": -2,
      "name": "Rock_Volcanic_Brick"
    },
    {
      "x": -57,
      "y": 14,
      "z": -1,
      "name": "Rock_Volcanic_Brick"
    },
    {
      "x": -57,
      "y": 21,
      "z": -1,
      "name": "Rock_Volcanic_Brick"
    },
    {
      "x": -57,
      "y": 26,
      "z": -1,
      "name": "Rock_Volcanic_Brick"
    },
    {
      "x": -57,
      "y": 33,
      "z": -1,
      "name": "Rock_Volcanic_Brick"
    },
    {
      "x": -57,
      "y": 14,
      "z": 0,
      "name": "Rock_Volcanic_Brick"
    },
    {
      "x": -57,
      "y": 21,
      "z": 0,
      "name": "Rock_Volcanic_Brick"
    },
    {
      "x": -57,
      "y": 26,
      "z": 0,
      "name": "Rock_Volcanic_Brick"
    },
    {
      "x": -57,
      "y": 33,
      "z": 0,
      "name": "Rock_Volcanic_Brick"
    },
    {
      "x": -57,
      "y": 14,
      "z": 1,
      "name": "Rock_Volcanic_Brick"
    },
    {
      "x": -57,
      "y": 21,
      "z": 1,
      "name": "Rock_Volcanic_Brick"
    },
    {
      "x": -57,
      "y": 26,
      "z": 1,
      "name": "Rock_Volcanic_Brick"
    },
    {
      "x": -57,
      "y": 33,
      "z": 1,
      "name": "Rock_Volcanic_Brick"
    },
    {
      "x": -57,
      "y": 14,
      "z": 2,
      "name": "Rock_Volcanic_Brick"
    },
    {
      "x": -57,
      "y": 21,
      "z": 2,
      "name": "Rock_Volcanic_Brick"
    },
    {
      "x": -57,
      "y": 26,
      "z": 2,
      "name": "Rock_Volcanic_Brick"
    },
    {
      "x": -57,
      "y": 33,
      "z": 2,
      "name": "Rock_Volcanic_Brick"
    },
    {
      "x": -57,
      "y": 14,
      "z": 3,
      "name": "Rock_Volcanic_Brick"
    },
    {
      "x": -57,
      "y": 21,
      "z": 3,
      "name": "Rock_Volcanic_Brick"
    },
    {
      "x": -57,
      "y": 26,
      "z": 3,
      "name": "Rock_Volcanic_Brick"
    },
    {
      "x": -57,
      "y": 33,
      "z": 3,
      "name": "Rock_Volcanic_Brick"
    },
    {
      "x": -57,
      "y": 0,
      "z": 4,
      "name": "Rock_Volcanic_Brick"
    },
    {
      "x": -57,
      "y": 1,
      "z": 4,
      "name": "Rock_Volcanic_Brick"
    },
    {
      "x": -57,
      "y": 2,
      "z": 4,
      "name": "Rock_Volcanic_Cobble"
    },
    {
      "x": -57,
      "y": 3,
      "z": 4,
      "name": "Rock_Volcanic_Brick"
    },
    {
      "x": -57,
      "y": 4,
      "z": 4,
      "name": "Rock_Volcanic_Cobble"
    },
    {
      "x": -57,
      "y": 5,
      "z": 4,
      "name": "Rock_Volcanic_Cobble"
    },
    {
      "x": -57,
      "y": 6,
      "z": 4,
      "name": "Rock_Volcanic_Cobble"
    },
    {
      "x": -57,
      "y": 7,
      "z": 4,
      "name": "Rock_Volcanic_Cobble"
    },
    {
      "x": -57,
      "y": 8,
      "z": 4,
      "name": "Rock_Volcanic_Cobble"
    },
    {
      "x": -57,
      "y": 9,
      "z": 4,
      "name": "Rock_Volcanic_Brick"
    },
    {
      "x": -57,
      "y": 10,
      "z": 4,
      "name": "Rock_Volcanic_Cobble"
    },
    {
      "x": -57,
      "y": 11,
      "z": 4,
      "name": "Rock_Volcanic_Brick"
    },
    {
      "x": -57,
      "y": 12,
      "z": 4,
      "name": "Rock_Volcanic_Brick"
    },
    {
      "x": -57,
      "y": 13,
      "z": 4,
      "name": "Rock_Volcanic_Brick"
    },
    {
      "x": -57,
      "y": 14,
      "z": 4,
      "name": "Rock_Volcanic_Brick"
    },
    {
      "x": -57,
      "y": 15,
      "z": 4,
      "name": "Rock_Volcanic_Cobble"
    },
    {
      "x": -57,
      "y": 16,
      "z": 4,
      "name": "Rock_Volcanic_Cobble"
    },
    {
      "x": -57,
      "y": 17,
      "z": 4,
      "name": "Rock_Volcanic_Cobble"
    },
    {
      "x": -57,
      "y": 18,
      "z": 4,
      "name": "Rock_Volcanic_Brick"
    },
    {
      "x": -57,
      "y": 19,
      "z": 4,
      "name": "Rock_Volcanic_Brick"
    },
    {
      "x": -57,
      "y": 20,
      "z": 4,
      "name": "Rock_Volcanic_Brick"
    },
    {
      "x": -57,
      "y": 21,
      "z": 4,
      "name": "Rock_Volcanic_Cobble"
    },
    {
      "x": -57,
      "y": 22,
      "z": 4,
      "name": "Rock_Volcanic_Cobble"
    },
    {
      "x": -57,
      "y": 23,
      "z": 4,
      "name": "Rock_Volcanic_Cobble"
    },
    {
      "x": -57,
      "y": 24,
      "z": 4,
      "name": "Rock_Volcanic_Cobble"
    },
    {
      "x": -57,
      "y": 25,
      "z": 4,
      "name": "Rock_Volcanic_Brick"
    },
    {
      "x": -57,
      "y": 26,
      "z": 4,
      "name": "Rock_Volcanic_Brick"
    },
    {
      "x": -57,
      "y": 27,
      "z": 4,
      "name": "Rock_Volcanic_Brick"
    },
    {
      "x": -57,
      "y": 28,
      "z": 4,
      "name": "Rock_Volcanic_Brick"
    },
    {
      "x": -57,
      "y": 29,
      "z": 4,
      "name": "Rock_Volcanic_Brick"
    },
    {
      "x": -57,
      "y": 30,
      "z": 4,
      "name": "Rock_Volcanic_Brick"
    },
    {
      "x": -57,
      "y": 31,
      "z": 4,
      "name": "Rock_Volcanic_Brick"
    },
    {
      "x": -57,
      "y": 32,
      "z": 4,
      "name": "Rock_Volcanic_Brick"
    },
    {
      "x": -57,
      "y": 33,
      "z": 4,
      "name": "Rock_Volcanic_Brick"
    },
    {
      "x": -57,
      "y": 33,
      "z": 5,
      "name": "*Rock_Volcanic_Brick_Stairs_State_Definitions_Inverted_Corner_Left",
      "rotation": 10
    },
    {
      "x": -57,
      "y": 33,
      "z": 6,
      "name": "*Rock_Volcanic_Brick_Stairs_State_Definitions_Corner_Right",
      "rotation": 9
    },
    {
      "x": -57,
      "y": 34,
      "z": 6,
      "name": "Rock_Volcanic_Brick_Half"
    },
    {
      "x": -56,
      "y": 33,
      "z": -6,
      "name": "Rock_Volcanic_Brick_Stairs",
      "rotation": 8
    },
    {
      "x": -56,
      "y": 34,
      "z": -6,
      "name": "Rock_Volcanic_Brick_Pillar_Base"
    },
    {
      "x": -56,
      "y": 0,
      "z": -5,
      "name": "Rock_Volcanic_Brick"
    },
    {
      "x": -56,
      "y": 1,
      "z": -5,
      "name": "Rock_Volcanic_Brick"
    },
    {
      "x": -56,
      "y": 2,
      "z": -5,
      "name": "Rock_Volcanic_Cobble"
    },
    {
      "x": -56,
      "y": 3,
      "z": -5,
      "name": "Rock_Volcanic_Brick"
    },
    {
      "x": -56,
      "y": 4,
      "z": -5,
      "name": "Rock_Volcanic_Brick"
    },
    {
      "x": -56,
      "y": 5,
      "z": -5,
      "name": "Rock_Volcanic_Cobble"
    },
    {
      "x": -56,
      "y": 6,
      "z": -5,
      "name": "Rock_Volcanic_Brick"
    },
    {
      "x": -56,
      "y": 7,
      "z": -5,
      "name": "Rock_Volcanic_Brick"
    },
    {
      "x": -56,
      "y": 8,
      "z": -5,
      "name": "Rock_Volcanic_Brick"
    },
    {
      "x": -56,
      "y": 9,
      "z": -5,
      "name": "Rock_Volcanic_Cobble"
    },
    {
      "x": -56,
      "y": 10,
      "z": -5,
      "name": "Rock_Volcanic_Cobble"
    },
    {
      "x": -56,
      "y": 11,
      "z": -5,
      "name": "Rock_Volcanic_Brick"
    },
    {
      "x": -56,
      "y": 12,
      "z": -5,
      "name": "Rock_Volcanic_Cobble"
    },
    {
      "x": -56,
      "y": 13,
      "z": -5,
      "name": "Rock_Volcanic_Cobble"
    },
    {
      "x": -56,
      "y": 14,
      "z": -5,
      "name": "Rock_Volcanic_Cobble"
    },
    {
      "x": -56,
      "y": 15,
      "z": -5,
      "name": "Rock_Volcanic_Brick"
    },
    {
      "x": -56,
      "y": 16,
      "z": -5,
      "name": "Rock_Volcanic_Brick"
    },
    {
      "x": -56,
      "y": 17,
      "z": -5,
      "name": "Rock_Volcanic_Cobble"
    },
    {
      "x": -56,
      "y": 18,
      "z": -5,
      "name": "Rock_Volcanic_Brick"
    },
    {
      "x": -56,
      "y": 19,
      "z": -5,
      "name": "Rock_Volcanic_Brick"
    },
    {
      "x": -56,
      "y": 20,
      "z": -5,
      "name": "Rock_Volcanic_Brick"
    },
    {
      "x": -56,
      "y": 21,
      "z": -5,
      "name": "Rock_Volcanic_Brick"
    },
    {
      "x": -56,
      "y": 22,
      "z": -5,
      "name": "Rock_Volcanic_Brick"
    },
    {
      "x": -56,
      "y": 23,
      "z": -5,
      "name": "Rock_Volcanic_Cobble"
    },
    {
      "x": -56,
      "y": 24,
      "z": -5,
      "name": "Rock_Volcanic_Brick"
    },
    {
      "x": -56,
      "y": 25,
      "z": -5,
      "name": "Rock_Volcanic_Brick"
    },
    {
      "x": -56,
      "y": 26,
      "z": -5,
      "name": "Rock_Volcanic_Brick"
    },
    {
      "x": -56,
      "y": 27,
      "z": -5,
      "name": "Rock_Volcanic_Brick"
    },
    {
      "x": -56,
      "y": 28,
      "z": -5,
      "name": "Rock_Volcanic_Brick"
    },
    {
      "x": -56,
      "y": 29,
      "z": -5,
      "name": "Rock_Volcanic_Cobble"
    },
    {
      "x": -56,
      "y": 30,
      "z": -5,
      "name": "Rock_Volcanic_Brick"
    },
    {
      "x": -56,
      "y": 31,
      "z": -5,
      "name": "Rock_Volcanic_Brick"
    },
    {
      "x": -56,
      "y": 32,
      "z": -5,
      "name": "Rock_Volcanic_Cobble"
    },
    {
      "x": -56,
      "y": 33,
      "z": -5,
      "name": "Rock_Volcanic_Cobble"
    },
    {
      "x": -56,
      "y": 0,
      "z": -4,
      "name": "Rock_Volcanic_Brick"
    },
    {
      "x": -56,
      "y": 1,
      "z": -4,
      "name": "Rock_Volcanic_Cobble"
    },
    {
      "x": -56,
      "y": 2,
      "z": -4,
      "name": "Rock_Volcanic_Cobble"
    },
    {
      "x": -56,
      "y": 3,
      "z": -4,
      "name": "Rock_Volcanic_Brick"
    },
    {
      "x": -56,
      "y": 4,
      "z": -4,
      "name": "Rock_Volcanic_Cobble"
    },
    {
      "x": -56,
      "y": 5,
      "z": -4,
      "name": "Rock_Volcanic_Brick"
    },
    {
      "x": -56,
      "y": 6,
      "z": -4,
      "name": "Rock_Volcanic_Cobble"
    },
    {
      "x": -56,
      "y": 7,
      "z": -4,
      "name": "Rock_Volcanic_Cobble"
    },
    {
      "x": -56,
      "y": 8,
      "z": -4,
      "name": "Rock_Volcanic_Cobble"
    },
    {
      "x": -56,
      "y": 9,
      "z": -4,
      "name": "Rock_Volcanic_Cobble"
    },
    {
      "x": -56,
      "y": 10,
      "z": -4,
      "name": "Rock_Volcanic_Brick"
    },
    {
      "x": -56,
      "y": 11,
      "z": -4,
      "name": "Rock_Volcanic_Cobble"
    },
    {
      "x": -56,
      "y": 12,
      "z": -4,
      "name": "Rock_Volcanic_Brick"
    },
    {
      "x": -56,
      "y": 13,
      "z": -4,
      "name": "Rock_Volcanic_Cobble"
    },
    {
      "x": -56,
      "y": 14,
      "z": -4,
      "name": "Rock_Volcanic_Brick"
    },
    {
      "x": -56,
      "y": 15,
      "z": -4,
      "name": "Rock_Volcanic_Cobble"
    },
    {
      "x": -56,
      "y": 16,
      "z": -4,
      "name": "Rock_Volcanic_Cobble"
    },
    {
      "x": -56,
      "y": 17,
      "z": -4,
      "name": "Rock_Volcanic_Cobble"
    },
    {
      "x": -56,
      "y": 18,
      "z": -4,
      "name": "Rock_Volcanic_Cobble"
    },
    {
      "x": -56,
      "y": 19,
      "z": -4,
      "name": "Rock_Volcanic_Cobble"
    },
    {
      "x": -56,
      "y": 20,
      "z": -4,
      "name": "Rock_Volcanic_Cobble"
    },
    {
      "x": -56,
      "y": 21,
      "z": -4,
      "name": "Rock_Volcanic_Brick"
    },
    {
      "x": -56,
      "y": 22,
      "z": -4,
      "name": "Rock_Volcanic_Brick"
    },
    {
      "x": -56,
      "y": 23,
      "z": -4,
      "name": "Rock_Volcanic_Brick"
    },
    {
      "x": -56,
      "y": 24,
      "z": -4,
      "name": "Rock_Volcanic_Brick"
    },
    {
      "x": -56,
      "y": 25,
      "z": -4,
      "name": "Rock_Volcanic_Brick"
    },
    {
      "x": -56,
      "y": 26,
      "z": -4,
      "name": "Rock_Volcanic_Brick"
    },
    {
      "x": -56,
      "y": 27,
      "z": -4,
      "name": "Rock_Volcanic_Brick"
    },
    {
      "x": -56,
      "y": 28,
      "z": -4,
      "name": "Rock_Volcanic_Cobble"
    },
    {
      "x": -56,
      "y": 29,
      "z": -4,
      "name": "Rock_Volcanic_Cobble"
    },
    {
      "x": -56,
      "y": 30,
      "z": -4,
      "name": "Rock_Volcanic_Cobble"
    },
    {
      "x": -56,
      "y": 31,
      "z": -4,
      "name": "Rock_Volcanic_Brick"
    },
    {
      "x": -56,
      "y": 32,
      "z": -4,
      "name": "Rock_Volcanic_Brick"
    },
    {
      "x": -56,
      "y": 33,
      "z": -4,
      "name": "Rock_Volcanic_Brick"
    },
    {
      "x": -56,
      "y": 14,
      "z": -3,
      "name": "Rock_Volcanic_Brick"
    },
    {
      "x": -56,
      "y": 21,
      "z": -3,
      "name": "Rock_Volcanic_Brick"
    },
    {
      "x": -56,
      "y": 26,
      "z": -3,
      "name": "Rock_Volcanic_Brick"
    },
    {
      "x": -56,
      "y": 33,
      "z": -3,
      "name": "Rock_Volcanic_Brick"
    },
    {
      "x": -56,
      "y": 14,
      "z": -2,
      "name": "Rock_Volcanic_Brick"
    },
    {
      "x": -56,
      "y": 21,
      "z": -2,
      "name": "Rock_Volcanic_Brick"
    },
    {
      "x": -56,
      "y": 26,
      "z": -2,
      "name": "Rock_Volcanic_Brick"
    },
    {
      "x": -56,
      "y": 33,
      "z": -2,
      "name": "Rock_Volcanic_Brick"
    },
    {
      "x": -56,
      "y": 14,
      "z": -1,
      "name": "Rock_Volcanic_Brick"
    },
    {
      "x": -56,
      "y": 21,
      "z": -1,
      "name": "Rock_Volcanic_Brick"
    },
    {
      "x": -56,
      "y": 26,
      "z": -1,
      "name": "Rock_Volcanic_Brick"
    },
    {
      "x": -56,
      "y": 33,
      "z": -1,
      "name": "Deco_Iron_Bars_Platforms",
      "rotation": 1
    },
    {
      "x": -56,
      "y": 14,
      "z": 0,
      "name": "Rock_Volcanic_Brick"
    },
    {
      "x": -56,
      "y": 21,
      "z": 0,
      "name": "Rock_Volcanic_Brick"
    },
    {
      "x": -56,
      "y": 26,
      "z": 0,
      "name": "Rock_Volcanic_Brick"
    },
    {
      "x": -56,
      "y": 33,
      "z": 0,
      "name": "Deco_Iron_Bars_Platforms",
      "rotation": 1
    },
    {
      "x": -56,
      "y": 14,
      "z": 1,
      "name": "Rock_Volcanic_Brick"
    },
    {
      "x": -56,
      "y": 21,
      "z": 1,
      "name": "Rock_Volcanic_Brick"
    },
    {
      "x": -56,
      "y": 26,
      "z": 1,
      "name": "Rock_Volcanic_Brick"
    },
    {
      "x": -56,
      "y": 33,
      "z": 1,
      "name": "Deco_Iron_Bars_Platforms",
      "rotation": 1
    },
    {
      "x": -56,
      "y": 14,
      "z": 2,
      "name": "Rock_Volcanic_Brick"
    },
    {
      "x": -56,
      "y": 21,
      "z": 2,
      "name": "Rock_Volcanic_Brick"
    },
    {
      "x": -56,
      "y": 26,
      "z": 2,
      "name": "Rock_Volcanic_Brick"
    },
    {
      "x": -56,
      "y": 33,
      "z": 2,
      "name": "Rock_Volcanic_Brick"
    },
    {
      "x": -56,
      "y": 14,
      "z": 3,
      "name": "Rock_Volcanic_Brick"
    },
    {
      "x": -56,
      "y": 21,
      "z": 3,
      "name": "Rock_Volcanic_Brick"
    },
    {
      "x": -56,
      "y": 26,
      "z": 3,
      "name": "Rock_Volcanic_Brick"
    },
    {
      "x": -56,
      "y": 33,
      "z": 3,
      "name": "Rock_Volcanic_Brick"
    },
    {
      "x": -56,
      "y": 0,
      "z": 4,
      "name": "Rock_Volcanic_Brick"
    },
    {
      "x": -56,
      "y": 1,
      "z": 4,
      "name": "Rock_Volcanic_Cobble"
    },
    {
      "x": -56,
      "y": 2,
      "z": 4,
      "name": "Rock_Volcanic_Cobble"
    },
    {
      "x": -56,
      "y": 3,
      "z": 4,
      "name": "Rock_Volcanic_Cobble"
    },
    {
      "x": -56,
      "y": 4,
      "z": 4,
      "name": "Rock_Volcanic_Cobble"
    },
    {
      "x": -56,
      "y": 5,
      "z": 4,
      "name": "Rock_Volcanic_Brick"
    },
    {
      "x": -56,
      "y": 6,
      "z": 4,
      "name": "Rock_Volcanic_Cobble"
    },
    {
      "x": -56,
      "y": 7,
      "z": 4,
      "name": "Rock_Volcanic_Cobble"
    },
    {
      "x": -56,
      "y": 8,
      "z": 4,
      "name": "Rock_Volcanic_Brick"
    },
    {
      "x": -56,
      "y": 9,
      "z": 4,
      "name": "Rock_Volcanic_Brick"
    },
    {
      "x": -56,
      "y": 10,
      "z": 4,
      "name": "Rock_Volcanic_Brick"
    },
    {
      "x": -56,
      "y": 11,
      "z": 4,
      "name": "Rock_Volcanic_Brick"
    },
    {
      "x": -56,
      "y": 12,
      "z": 4,
      "name": "Rock_Volcanic_Cobble"
    },
    {
      "x": -56,
      "y": 13,
      "z": 4,
      "name": "Rock_Volcanic_Brick"
    },
    {
      "x": -56,
      "y": 14,
      "z": 4,
      "name": "Rock_Volcanic_Cobble"
    },
    {
      "x": -56,
      "y": 15,
      "z": 4,
      "name": "Rock_Volcanic_Cobble"
    },
    {
      "x": -56,
      "y": 16,
      "z": 4,
      "name": "Rock_Volcanic_Cobble"
    },
    {
      "x": -56,
      "y": 17,
      "z": 4,
      "name": "Rock_Volcanic_Brick"
    },
    {
      "x": -56,
      "y": 18,
      "z": 4,
      "name": "Rock_Volcanic_Brick"
    },
    {
      "x": -56,
      "y": 19,
      "z": 4,
      "name": "Rock_Volcanic_Cobble"
    },
    {
      "x": -56,
      "y": 20,
      "z": 4,
      "name": "Rock_Volcanic_Brick"
    },
    {
      "x": -56,
      "y": 21,
      "z": 4,
      "name": "Rock_Volcanic_Cobble"
    },
    {
      "x": -56,
      "y": 22,
      "z": 4,
      "name": "Rock_Volcanic_Cobble"
    },
    {
      "x": -56,
      "y": 23,
      "z": 4,
      "name": "Rock_Volcanic_Cobble"
    },
    {
      "x": -56,
      "y": 24,
      "z": 4,
      "name": "Rock_Volcanic_Brick"
    },
    {
      "x": -56,
      "y": 25,
      "z": 4,
      "name": "Rock_Volcanic_Brick"
    },
    {
      "x": -56,
      "y": 26,
      "z": 4,
      "name": "Rock_Volcanic_Brick"
    },
    {
      "x": -56,
      "y": 27,
      "z": 4,
      "name": "Rock_Volcanic_Brick"
    },
    {
      "x": -56,
      "y": 28,
      "z": 4,
      "name": "Rock_Volcanic_Cobble"
    },
    {
      "x": -56,
      "y": 29,
      "z": 4,
      "name": "Rock_Volcanic_Cobble"
    },
    {
      "x": -56,
      "y": 30,
      "z": 4,
      "name": "Rock_Volcanic_Cobble"
    },
    {
      "x": -56,
      "y": 31,
      "z": 4,
      "name": "Rock_Volcanic_Cobble"
    },
    {
      "x": -56,
      "y": 32,
      "z": 4,
      "name": "Rock_Volcanic_Brick"
    },
    {
      "x": -56,
      "y": 33,
      "z": 4,
      "name": "Rock_Volcanic_Cobble"
    },
    {
      "x": -56,
      "y": 0,
      "z": 5,
      "name": "Rock_Volcanic_Brick"
    },
    {
      "x": -56,
      "y": 1,
      "z": 5,
      "name": "Rock_Volcanic_Cobble"
    },
    {
      "x": -56,
      "y": 2,
      "z": 5,
      "name": "Rock_Volcanic_Cobble"
    },
    {
      "x": -56,
      "y": 3,
      "z": 5,
      "name": "Rock_Volcanic_Brick"
    },
    {
      "x": -56,
      "y": 4,
      "z": 5,
      "name": "Rock_Volcanic_Brick"
    },
    {
      "x": -56,
      "y": 5,
      "z": 5,
      "name": "Rock_Volcanic_Cobble"
    },
    {
      "x": -56,
      "y": 6,
      "z": 5,
      "name": "Rock_Volcanic_Cobble"
    },
    {
      "x": -56,
      "y": 7,
      "z": 5,
      "name": "Rock_Volcanic_Brick"
    },
    {
      "x": -56,
      "y": 8,
      "z": 5,
      "name": "Rock_Volcanic_Brick"
    },
    {
      "x": -56,
      "y": 9,
      "z": 5,
      "name": "Rock_Volcanic_Cobble"
    },
    {
      "x": -56,
      "y": 10,
      "z": 5,
      "name": "Rock_Volcanic_Cobble"
    },
    {
      "x": -56,
      "y": 11,
      "z": 5,
      "name": "Rock_Volcanic_Brick"
    },
    {
      "x": -56,
      "y": 12,
      "z": 5,
      "name": "Rock_Volcanic_Brick"
    },
    {
      "x": -56,
      "y": 13,
      "z": 5,
      "name": "Rock_Volcanic_Brick"
    },
    {
      "x": -56,
      "y": 14,
      "z": 5,
      "name": "Rock_Volcanic_Cobble"
    },
    {
      "x": -56,
      "y": 15,
      "z": 5,
      "name": "Rock_Volcanic_Cobble"
    },
    {
      "x": -56,
      "y": 16,
      "z": 5,
      "name": "Rock_Volcanic_Cobble"
    },
    {
      "x": -56,
      "y": 17,
      "z": 5,
      "name": "Rock_Volcanic_Brick"
    },
    {
      "x": -56,
      "y": 18,
      "z": 5,
      "name": "Rock_Volcanic_Cobble"
    },
    {
      "x": -56,
      "y": 19,
      "z": 5,
      "name": "Rock_Volcanic_Brick"
    },
    {
      "x": -56,
      "y": 20,
      "z": 5,
      "name": "Rock_Volcanic_Cobble"
    },
    {
      "x": -56,
      "y": 21,
      "z": 5,
      "name": "Rock_Volcanic_Brick"
    },
    {
      "x": -56,
      "y": 22,
      "z": 5,
      "name": "Rock_Volcanic_Cobble"
    },
    {
      "x": -56,
      "y": 23,
      "z": 5,
      "name": "Rock_Volcanic_Cobble"
    },
    {
      "x": -56,
      "y": 24,
      "z": 5,
      "name": "Rock_Volcanic_Cobble"
    },
    {
      "x": -56,
      "y": 25,
      "z": 5,
      "name": "Rock_Volcanic_Brick"
    },
    {
      "x": -56,
      "y": 26,
      "z": 5,
      "name": "Rock_Volcanic_Cobble"
    },
    {
      "x": -56,
      "y": 27,
      "z": 5,
      "name": "Rock_Volcanic_Cobble"
    },
    {
      "x": -56,
      "y": 28,
      "z": 5,
      "name": "Rock_Volcanic_Cobble"
    },
    {
      "x": -56,
      "y": 29,
      "z": 5,
      "name": "Rock_Volcanic_Cobble"
    },
    {
      "x": -56,
      "y": 30,
      "z": 5,
      "name": "Rock_Volcanic_Cobble"
    },
    {
      "x": -56,
      "y": 31,
      "z": 5,
      "name": "Rock_Volcanic_Brick"
    },
    {
      "x": -56,
      "y": 32,
      "z": 5,
      "name": "Rock_Volcanic_Cobble"
    },
    {
      "x": -56,
      "y": 33,
      "z": 5,
      "name": "Rock_Volcanic_Cobble"
    },
    {
      "x": -56,
      "y": 33,
      "z": 6,
      "name": "Rock_Volcanic_Brick_Stairs",
      "rotation": 10
    },
    {
      "x": -56,
      "y": 34,
      "z": 6,
      "name": "Rock_Volcanic_Brick_Pillar_Base"
    },
    {
      "x": -55,
      "y": 33,
      "z": -6,
      "name": "Rock_Volcanic_Brick_Stairs",
      "rotation": 8
    },
    {
      "x": -55,
      "y": 34,
      "z": -6,
      "name": "Rock_Volcanic_Brick_Half"
    },
    {
      "x": -55,
      "y": 0,
      "z": -5,
      "name": "Rock_Volcanic_Cobble"
    },
    {
      "x": -55,
      "y": 1,
      "z": -5,
      "name": "Rock_Volcanic_Cobble"
    },
    {
      "x": -55,
      "y": 2,
      "z": -5,
      "name": "Rock_Volcanic_Brick"
    },
    {
      "x": -55,
      "y": 3,
      "z": -5,
      "name": "Rock_Volcanic_Brick"
    },
    {
      "x": -55,
      "y": 4,
      "z": -5,
      "name": "Rock_Volcanic_Brick"
    },
    {
      "x": -55,
      "y": 5,
      "z": -5,
      "name": "Rock_Volcanic_Cobble"
    },
    {
      "x": -55,
      "y": 6,
      "z": -5,
      "name": "Rock_Volcanic_Cobble"
    },
    {
      "x": -55,
      "y": 7,
      "z": -5,
      "name": "Rock_Volcanic_Cobble"
    },
    {
      "x": -55,
      "y": 8,
      "z": -5,
      "name": "Rock_Volcanic_Brick"
    },
    {
      "x": -55,
      "y": 9,
      "z": -5,
      "name": "Rock_Volcanic_Brick"
    },
    {
      "x": -55,
      "y": 10,
      "z": -5,
      "name": "Rock_Volcanic_Cobble"
    },
    {
      "x": -55,
      "y": 11,
      "z": -5,
      "name": "Rock_Volcanic_Cobble"
    },
    {
      "x": -55,
      "y": 12,
      "z": -5,
      "name": "Rock_Volcanic_Brick"
    },
    {
      "x": -55,
      "y": 13,
      "z": -5,
      "name": "Rock_Volcanic_Cobble"
    },
    {
      "x": -55,
      "y": 14,
      "z": -5,
      "name": "Rock_Volcanic_Brick"
    },
    {
      "x": -55,
      "y": 15,
      "z": -5,
      "name": "Rock_Volcanic_Cobble"
    },
    {
      "x": -55,
      "y": 16,
      "z": -5,
      "name": "Rock_Volcanic_Cobble"
    },
    {
      "x": -55,
      "y": 17,
      "z": -5,
      "name": "Rock_Volcanic_Brick"
    },
    {
      "x": -55,
      "y": 18,
      "z": -5,
      "name": "Rock_Volcanic_Cobble"
    },
    {
      "x": -55,
      "y": 19,
      "z": -5,
      "name": "Rock_Volcanic_Brick"
    },
    {
      "x": -55,
      "y": 20,
      "z": -5,
      "name": "Rock_Volcanic_Cobble"
    },
    {
      "x": -55,
      "y": 21,
      "z": -5,
      "name": "Rock_Volcanic_Brick"
    },
    {
      "x": -55,
      "y": 22,
      "z": -5,
      "name": "Rock_Volcanic_Brick"
    },
    {
      "x": -55,
      "y": 23,
      "z": -5,
      "name": "Rock_Volcanic_Cobble"
    },
    {
      "x": -55,
      "y": 24,
      "z": -5,
      "name": "Rock_Volcanic_Brick"
    },
    {
      "x": -55,
      "y": 25,
      "z": -5,
      "name": "Rock_Volcanic_Cobble"
    },
    {
      "x": -55,
      "y": 26,
      "z": -5,
      "name": "Rock_Volcanic_Cobble"
    },
    {
      "x": -55,
      "y": 27,
      "z": -5,
      "name": "Rock_Volcanic_Cobble"
    },
    {
      "x": -55,
      "y": 28,
      "z": -5,
      "name": "Rock_Volcanic_Cobble"
    },
    {
      "x": -55,
      "y": 29,
      "z": -5,
      "name": "Rock_Volcanic_Brick"
    },
    {
      "x": -55,
      "y": 30,
      "z": -5,
      "name": "Rock_Volcanic_Cobble"
    },
    {
      "x": -55,
      "y": 31,
      "z": -5,
      "name": "Rock_Volcanic_Brick"
    },
    {
      "x": -55,
      "y": 32,
      "z": -5,
      "name": "Rock_Volcanic_Brick"
    },
    {
      "x": -55,
      "y": 33,
      "z": -5,
      "name": "Rock_Volcanic_Brick"
    },
    {
      "x": -55,
      "y": 14,
      "z": -4,
      "name": "Rock_Volcanic_Brick"
    },
    {
      "x": -55,
      "y": 21,
      "z": -4,
      "name": "Rock_Volcanic_Brick"
    },
    {
      "x": -55,
      "y": 26,
      "z": -4,
      "name": "Rock_Volcanic_Brick"
    },
    {
      "x": -55,
      "y": 33,
      "z": -4,
      "name": "Rock_Volcanic_Brick"
    },
    {
      "x": -55,
      "y": 14,
      "z": -3,
      "name": "Rock_Volcanic_Brick"
    },
    {
      "x": -55,
      "y": 21,
      "z": -3,
      "name": "Rock_Volcanic_Brick"
    },
    {
      "x": -55,
      "y": 26,
      "z": -3,
      "name": "Rock_Volcanic_Brick"
    },
    {
      "x": -55,
      "y": 33,
      "z": -3,
      "name": "Rock_Volcanic_Brick"
    },
    {
      "x": -55,
      "y": 14,
      "z": -2,
      "name": "Rock_Volcanic_Brick"
    },
    {
      "x": -55,
      "y": 21,
      "z": -2,
      "name": "Rock_Volcanic_Brick"
    },
    {
      "x": -55,
      "y": 26,
      "z": -2,
      "name": "Rock_Volcanic_Brick"
    },
    {
      "x": -55,
      "y": 33,
      "z": -2,
      "name": "Deco_Iron_Bars_Platforms",
      "rotation": 1
    },
    {
      "x": -55,
      "y": 14,
      "z": -1,
      "name": "Rock_Volcanic_Brick"
    },
    {
      "x": -55,
      "y": 21,
      "z": -1,
      "name": "Deco_Iron_Bars_Platforms",
      "rotation": 1
    },
    {
      "x": -55,
      "y": 26,
      "z": -1,
      "name": "Deco_Iron_Bars_Platforms",
      "rotation": 1
    },
    {
      "x": -55,
      "y": 33,
      "z": -1,
      "name": "Deco_Iron_Bars_Platforms",
      "rotation": 1
    },
    {
      "x": -55,
      "y": 14,
      "z": 0,
      "name": "Rock_Volcanic_Brick"
    },
    {
      "x": -55,
      "y": 21,
      "z": 0,
      "name": "Deco_Iron_Bars_Platforms",
      "rotation": 1
    },
    {
      "x": -55,
      "y": 26,
      "z": 0,
      "name": "Deco_Iron_Bars_Platforms",
      "rotation": 1
    },
    {
      "x": -55,
      "y": 33,
      "z": 0,
      "name": "Deco_Iron_Bars_Platforms",
      "rotation": 1
    },
    {
      "x": -55,
      "y": 14,
      "z": 1,
      "name": "Rock_Volcanic_Brick"
    },
    {
      "x": -55,
      "y": 21,
      "z": 1,
      "name": "Deco_Iron_Bars_Platforms",
      "rotation": 1
    },
    {
      "x": -55,
      "y": 26,
      "z": 1,
      "name": "Deco_Iron_Bars_Platforms",
      "rotation": 1
    },
    {
      "x": -55,
      "y": 33,
      "z": 1,
      "name": "Deco_Iron_Bars_Platforms",
      "rotation": 1
    },
    {
      "x": -55,
      "y": 14,
      "z": 2,
      "name": "Rock_Volcanic_Brick"
    },
    {
      "x": -55,
      "y": 21,
      "z": 2,
      "name": "Rock_Volcanic_Brick"
    },
    {
      "x": -55,
      "y": 26,
      "z": 2,
      "name": "Rock_Volcanic_Brick"
    },
    {
      "x": -55,
      "y": 33,
      "z": 2,
      "name": "Deco_Iron_Bars_Platforms",
      "rotation": 1
    },
    {
      "x": -55,
      "y": 14,
      "z": 3,
      "name": "Rock_Volcanic_Brick"
    },
    {
      "x": -55,
      "y": 21,
      "z": 3,
      "name": "Rock_Volcanic_Brick"
    },
    {
      "x": -55,
      "y": 26,
      "z": 3,
      "name": "Rock_Volcanic_Brick"
    },
    {
      "x": -55,
      "y": 33,
      "z": 3,
      "name": "Rock_Volcanic_Brick"
    },
    {
      "x": -55,
      "y": 14,
      "z": 4,
      "name": "Rock_Volcanic_Brick"
    },
    {
      "x": -55,
      "y": 21,
      "z": 4,
      "name": "Rock_Volcanic_Brick"
    },
    {
      "x": -55,
      "y": 26,
      "z": 4,
      "name": "Rock_Volcanic_Brick"
    },
    {
      "x": -55,
      "y": 33,
      "z": 4,
      "name": "Rock_Volcanic_Brick"
    },
    {
      "x": -55,
      "y": 0,
      "z": 5,
      "name": "Rock_Volcanic_Brick"
    },
    {
      "x": -55,
      "y": 1,
      "z": 5,
      "name": "Rock_Volcanic_Brick"
    },
    {
      "x": -55,
      "y": 2,
      "z": 5,
      "name": "Rock_Volcanic_Brick"
    },
    {
      "x": -55,
      "y": 3,
      "z": 5,
      "name": "Rock_Volcanic_Cobble"
    },
    {
      "x": -55,
      "y": 4,
      "z": 5,
      "name": "Rock_Volcanic_Cobble"
    },
    {
      "x": -55,
      "y": 5,
      "z": 5,
      "name": "Rock_Volcanic_Brick"
    },
    {
      "x": -55,
      "y": 6,
      "z": 5,
      "name": "Rock_Volcanic_Brick"
    },
    {
      "x": -55,
      "y": 7,
      "z": 5,
      "name": "Rock_Volcanic_Cobble"
    },
    {
      "x": -55,
      "y": 8,
      "z": 5,
      "name": "Rock_Volcanic_Brick"
    },
    {
      "x": -55,
      "y": 9,
      "z": 5,
      "name": "Rock_Volcanic_Cobble"
    },
    {
      "x": -55,
      "y": 10,
      "z": 5,
      "name": "Rock_Volcanic_Brick"
    },
    {
      "x": -55,
      "y": 11,
      "z": 5,
      "name": "Rock_Volcanic_Cobble"
    },
    {
      "x": -55,
      "y": 12,
      "z": 5,
      "name": "Rock_Volcanic_Cobble"
    },
    {
      "x": -55,
      "y": 13,
      "z": 5,
      "name": "Rock_Volcanic_Cobble"
    },
    {
      "x": -55,
      "y": 14,
      "z": 5,
      "name": "Rock_Volcanic_Cobble"
    },
    {
      "x": -55,
      "y": 15,
      "z": 5,
      "name": "Rock_Volcanic_Brick"
    },
    {
      "x": -55,
      "y": 16,
      "z": 5,
      "name": "Rock_Volcanic_Cobble"
    },
    {
      "x": -55,
      "y": 17,
      "z": 5,
      "name": "Rock_Volcanic_Brick"
    },
    {
      "x": -55,
      "y": 18,
      "z": 5,
      "name": "Rock_Volcanic_Cobble"
    },
    {
      "x": -55,
      "y": 19,
      "z": 5,
      "name": "Rock_Volcanic_Brick"
    },
    {
      "x": -55,
      "y": 20,
      "z": 5,
      "name": "Rock_Volcanic_Brick"
    },
    {
      "x": -55,
      "y": 21,
      "z": 5,
      "name": "Rock_Volcanic_Cobble"
    },
    {
      "x": -55,
      "y": 22,
      "z": 5,
      "name": "Rock_Volcanic_Cobble"
    },
    {
      "x": -55,
      "y": 23,
      "z": 5,
      "name": "Rock_Volcanic_Cobble"
    },
    {
      "x": -55,
      "y": 24,
      "z": 5,
      "name": "Rock_Volcanic_Cobble"
    },
    {
      "x": -55,
      "y": 25,
      "z": 5,
      "name": "Rock_Volcanic_Cobble"
    },
    {
      "x": -55,
      "y": 26,
      "z": 5,
      "name": "Rock_Volcanic_Brick"
    },
    {
      "x": -55,
      "y": 27,
      "z": 5,
      "name": "Rock_Volcanic_Cobble"
    },
    {
      "x": -55,
      "y": 28,
      "z": 5,
      "name": "Rock_Volcanic_Cobble"
    },
    {
      "x": -55,
      "y": 29,
      "z": 5,
      "name": "Rock_Volcanic_Brick"
    },
    {
      "x": -55,
      "y": 30,
      "z": 5,
      "name": "Rock_Volcanic_Cobble"
    },
    {
      "x": -55,
      "y": 31,
      "z": 5,
      "name": "Rock_Volcanic_Brick"
    },
    {
      "x": -55,
      "y": 32,
      "z": 5,
      "name": "Rock_Volcanic_Brick"
    },
    {
      "x": -55,
      "y": 33,
      "z": 5,
      "name": "Rock_Volcanic_Cobble"
    },
    {
      "x": -55,
      "y": 33,
      "z": 6,
      "name": "Rock_Volcanic_Brick_Stairs",
      "rotation": 10
    },
    {
      "x": -55,
      "y": 34,
      "z": 6,
      "name": "Rock_Volcanic_Brick_Half"
    },
    {
      "x": -54,
      "y": 31,
      "z": -6,
      "name": "Furniture_Human_Ruins_Banner",
      "rotation": 3
    },
    {
      "x": -54,
      "y": 33,
      "z": -6,
      "name": "Rock_Volcanic_Brick_Stairs",
      "rotation": 8
    },
    {
      "x": -54,
      "y": 34,
      "z": -6,
      "name": "Rock_Volcanic_Brick_Pillar_Base"
    },
    {
      "x": -54,
      "y": 0,
      "z": -5,
      "name": "Rock_Volcanic_Brick"
    },
    {
      "x": -54,
      "y": 1,
      "z": -5,
      "name": "Rock_Volcanic_Cobble"
    },
    {
      "x": -54,
      "y": 2,
      "z": -5,
      "name": "Rock_Volcanic_Brick"
    },
    {
      "x": -54,
      "y": 3,
      "z": -5,
      "name": "Rock_Volcanic_Brick"
    },
    {
      "x": -54,
      "y": 4,
      "z": -5,
      "name": "Rock_Volcanic_Brick"
    },
    {
      "x": -54,
      "y": 5,
      "z": -5,
      "name": "Rock_Volcanic_Brick"
    },
    {
      "x": -54,
      "y": 6,
      "z": -5,
      "name": "Rock_Volcanic_Cobble"
    },
    {
      "x": -54,
      "y": 7,
      "z": -5,
      "name": "Rock_Volcanic_Cobble"
    },
    {
      "x": -54,
      "y": 8,
      "z": -5,
      "name": "Rock_Volcanic_Brick"
    },
    {
      "x": -54,
      "y": 9,
      "z": -5,
      "name": "Rock_Volcanic_Brick"
    },
    {
      "x": -54,
      "y": 10,
      "z": -5,
      "name": "Rock_Volcanic_Brick"
    },
    {
      "x": -54,
      "y": 11,
      "z": -5,
      "name": "Rock_Volcanic_Brick"
    },
    {
      "x": -54,
      "y": 12,
      "z": -5,
      "name": "Rock_Volcanic_Brick"
    },
    {
      "x": -54,
      "y": 13,
      "z": -5,
      "name": "Rock_Volcanic_Brick"
    },
    {
      "x": -54,
      "y": 14,
      "z": -5,
      "name": "Rock_Volcanic_Brick"
    },
    {
      "x": -54,
      "y": 15,
      "z": -5,
      "name": "Rock_Volcanic_Cobble"
    },
    {
      "x": -54,
      "y": 16,
      "z": -5,
      "name": "Deco_Iron_Bars"
    },
    {
      "x": -54,
      "y": 17,
      "z": -5,
      "name": "Deco_Iron_Bars"
    },
    {
      "x": -54,
      "y": 18,
      "z": -5,
      "name": "Deco_Iron_Bars"
    },
    {
      "x": -54,
      "y": 19,
      "z": -5,
      "name": "Rock_Volcanic_Cobble"
    },
    {
      "x": -54,
      "y": 20,
      "z": -5,
      "name": "Rock_Volcanic_Cobble"
    },
    {
      "x": -54,
      "y": 21,
      "z": -5,
      "name": "Rock_Volcanic_Brick"
    },
    {
      "x": -54,
      "y": 22,
      "z": -5,
      "name": "Rock_Volcanic_Cobble"
    },
    {
      "x": -54,
      "y": 23,
      "z": -5,
      "name": "Deco_Iron_Bars"
    },
    {
      "x": -54,
      "y": 24,
      "z": -5,
      "name": "Deco_Iron_Bars"
    },
    {
      "x": -54,
      "y": 25,
      "z": -5,
      "name": "Deco_Iron_Bars"
    },
    {
      "x": -54,
      "y": 26,
      "z": -5,
      "name": "Rock_Volcanic_Brick"
    },
    {
      "x": -54,
      "y": 27,
      "z": -5,
      "name": "Rock_Volcanic_Brick"
    },
    {
      "x": -54,
      "y": 28,
      "z": -5,
      "name": "Deco_Iron_Bars"
    },
    {
      "x": -54,
      "y": 29,
      "z": -5,
      "name": "Deco_Iron_Bars"
    },
    {
      "x": -54,
      "y": 30,
      "z": -5,
      "name": "Deco_Iron_Bars"
    },
    {
      "x": -54,
      "y": 31,
      "z": -5,
      "name": "Rock_Volcanic_Cobble"
    },
    {
      "x": -54,
      "y": 32,
      "z": -5,
      "name": "Rock_Volcanic_Brick"
    },
    {
      "x": -54,
      "y": 33,
      "z": -5,
      "name": "Rock_Volcanic_Cobble"
    },
    {
      "x": -54,
      "y": 14,
      "z": -4,
      "name": "Rock_Volcanic_Brick"
    },
    {
      "x": -54,
      "y": 21,
      "z": -4,
      "name": "Rock_Volcanic_Brick"
    },
    {
      "x": -54,
      "y": 26,
      "z": -4,
      "name": "Rock_Volcanic_Brick"
    },
    {
      "x": -54,
      "y": 33,
      "z": -4,
      "name": "Rock_Volcanic_Brick"
    },
    {
      "x": -54,
      "y": 14,
      "z": -3,
      "name": "Rock_Volcanic_Brick"
    },
    {
      "x": -54,
      "y": 21,
      "z": -3,
      "name": "Rock_Volcanic_Brick"
    },
    {
      "x": -54,
      "y": 26,
      "z": -3,
      "name": "Rock_Volcanic_Brick"
    },
    {
      "x": -54,
      "y": 33,
      "z": -3,
      "name": "Rock_Volcanic_Brick"
    },
    {
      "x": -54,
      "y": 14,
      "z": -2,
      "name": "Rock_Volcanic_Brick"
    },
    {
      "x": -54,
      "y": 21,
      "z": -2,
      "name": "Rock_Volcanic_Brick"
    },
    {
      "x": -54,
      "y": 26,
      "z": -2,
      "name": "Rock_Volcanic_Brick"
    },
    {
      "x": -54,
      "y": 33,
      "z": -2,
      "name": "Deco_Iron_Bars_Platforms",
      "rotation": 1
    },
    {
      "x": -54,
      "y": 14,
      "z": -1,
      "name": "Rock_Volcanic_Brick"
    },
    {
      "x": -54,
      "y": 21,
      "z": -1,
      "name": "Deco_Iron_Bars_Platforms",
      "rotation": 1
    },
    {
      "x": -54,
      "y": 26,
      "z": -1,
      "name": "Deco_Iron_Bars_Platforms",
      "rotation": 1
    },
    {
      "x": -54,
      "y": 33,
      "z": -1,
      "name": "Deco_Iron_Bars_Platforms",
      "rotation": 1
    },
    {
      "x": -54,
      "y": 14,
      "z": 0,
      "name": "Rock_Volcanic_Brick"
    },
    {
      "x": -54,
      "y": 21,
      "z": 0,
      "name": "Deco_Iron_Bars_Platforms",
      "rotation": 1
    },
    {
      "x": -54,
      "y": 26,
      "z": 0,
      "name": "Deco_Iron_Bars_Platforms",
      "rotation": 1
    },
    {
      "x": -54,
      "y": 33,
      "z": 0,
      "name": "Deco_Iron_Bars_Platforms",
      "rotation": 1
    },
    {
      "x": -54,
      "y": 14,
      "z": 1,
      "name": "Rock_Volcanic_Brick"
    },
    {
      "x": -54,
      "y": 21,
      "z": 1,
      "name": "Deco_Iron_Bars_Platforms",
      "rotation": 1
    },
    {
      "x": -54,
      "y": 26,
      "z": 1,
      "name": "Deco_Iron_Bars_Platforms",
      "rotation": 1
    },
    {
      "x": -54,
      "y": 33,
      "z": 1,
      "name": "Deco_Iron_Bars_Platforms",
      "rotation": 1
    },
    {
      "x": -54,
      "y": 14,
      "z": 2,
      "name": "Rock_Volcanic_Brick"
    },
    {
      "x": -54,
      "y": 21,
      "z": 2,
      "name": "Rock_Volcanic_Brick"
    },
    {
      "x": -54,
      "y": 26,
      "z": 2,
      "name": "Rock_Volcanic_Brick"
    },
    {
      "x": -54,
      "y": 33,
      "z": 2,
      "name": "Deco_Iron_Bars_Platforms",
      "rotation": 1
    },
    {
      "x": -54,
      "y": 14,
      "z": 3,
      "name": "Rock_Volcanic_Brick"
    },
    {
      "x": -54,
      "y": 21,
      "z": 3,
      "name": "Rock_Volcanic_Brick"
    },
    {
      "x": -54,
      "y": 26,
      "z": 3,
      "name": "Rock_Volcanic_Brick"
    },
    {
      "x": -54,
      "y": 33,
      "z": 3,
      "name": "Rock_Volcanic_Brick"
    },
    {
      "x": -54,
      "y": 14,
      "z": 4,
      "name": "Rock_Volcanic_Brick"
    },
    {
      "x": -54,
      "y": 21,
      "z": 4,
      "name": "Rock_Volcanic_Brick"
    },
    {
      "x": -54,
      "y": 26,
      "z": 4,
      "name": "Rock_Volcanic_Brick"
    },
    {
      "x": -54,
      "y": 33,
      "z": 4,
      "name": "Rock_Volcanic_Brick"
    },
    {
      "x": -54,
      "y": 0,
      "z": 5,
      "name": "Rock_Volcanic_Brick"
    },
    {
      "x": -54,
      "y": 1,
      "z": 5,
      "name": "Rock_Volcanic_Brick"
    },
    {
      "x": -54,
      "y": 2,
      "z": 5,
      "name": "Rock_Volcanic_Brick"
    },
    {
      "x": -54,
      "y": 3,
      "z": 5,
      "name": "Rock_Volcanic_Brick"
    },
    {
      "x": -54,
      "y": 4,
      "z": 5,
      "name": "Rock_Volcanic_Cobble"
    },
    {
      "x": -54,
      "y": 5,
      "z": 5,
      "name": "Rock_Volcanic_Cobble"
    },
    {
      "x": -54,
      "y": 6,
      "z": 5,
      "name": "Rock_Volcanic_Brick"
    },
    {
      "x": -54,
      "y": 7,
      "z": 5,
      "name": "Rock_Volcanic_Brick"
    },
    {
      "x": -54,
      "y": 8,
      "z": 5,
      "name": "Rock_Volcanic_Brick"
    },
    {
      "x": -54,
      "y": 9,
      "z": 5,
      "name": "Rock_Volcanic_Cobble"
    },
    {
      "x": -54,
      "y": 10,
      "z": 5,
      "name": "Rock_Volcanic_Brick"
    },
    {
      "x": -54,
      "y": 11,
      "z": 5,
      "name": "Rock_Volcanic_Brick"
    },
    {
      "x": -54,
      "y": 12,
      "z": 5,
      "name": "Rock_Volcanic_Brick"
    },
    {
      "x": -54,
      "y": 13,
      "z": 5,
      "name": "Rock_Volcanic_Cobble"
    },
    {
      "x": -54,
      "y": 14,
      "z": 5,
      "name": "Rock_Volcanic_Cobble"
    },
    {
      "x": -54,
      "y": 15,
      "z": 5,
      "name": "Rock_Volcanic_Cobble"
    },
    {
      "x": -54,
      "y": 16,
      "z": 5,
      "name": "Deco_Iron_Bars"
    },
    {
      "x": -54,
      "y": 17,
      "z": 5,
      "name": "Deco_Iron_Bars"
    },
    {
      "x": -54,
      "y": 18,
      "z": 5,
      "name": "Deco_Iron_Bars"
    },
    {
      "x": -54,
      "y": 19,
      "z": 5,
      "name": "Rock_Volcanic_Brick"
    },
    {
      "x": -54,
      "y": 20,
      "z": 5,
      "name": "Rock_Volcanic_Cobble"
    },
    {
      "x": -54,
      "y": 21,
      "z": 5,
      "name": "Rock_Volcanic_Brick"
    },
    {
      "x": -54,
      "y": 22,
      "z": 5,
      "name": "Rock_Volcanic_Cobble"
    },
    {
      "x": -54,
      "y": 23,
      "z": 5,
      "name": "Deco_Iron_Bars"
    },
    {
      "x": -54,
      "y": 24,
      "z": 5,
      "name": "Deco_Iron_Bars"
    },
    {
      "x": -54,
      "y": 25,
      "z": 5,
      "name": "Deco_Iron_Bars"
    },
    {
      "x": -54,
      "y": 26,
      "z": 5,
      "name": "Rock_Volcanic_Brick"
    },
    {
      "x": -54,
      "y": 27,
      "z": 5,
      "name": "Rock_Volcanic_Cobble"
    },
    {
      "x": -54,
      "y": 28,
      "z": 5,
      "name": "Deco_Iron_Bars"
    },
    {
      "x": -54,
      "y": 29,
      "z": 5,
      "name": "Deco_Iron_Bars"
    },
    {
      "x": -54,
      "y": 30,
      "z": 5,
      "name": "Deco_Iron_Bars"
    },
    {
      "x": -54,
      "y": 31,
      "z": 5,
      "name": "Rock_Volcanic_Brick"
    },
    {
      "x": -54,
      "y": 32,
      "z": 5,
      "name": "Rock_Volcanic_Brick"
    },
    {
      "x": -54,
      "y": 33,
      "z": 5,
      "name": "Rock_Volcanic_Brick"
    },
    {
      "x": -54,
      "y": 31,
      "z": 6,
      "name": "Furniture_Human_Ruins_Banner",
      "rotation": 3
    },
    {
      "x": -54,
      "y": 33,
      "z": 6,
      "name": "Rock_Volcanic_Brick_Stairs",
      "rotation": 10
    },
    {
      "x": -54,
      "y": 34,
      "z": 6,
      "name": "Rock_Volcanic_Brick_Pillar_Base"
    },
    {
      "x": -53,
      "y": 33,
      "z": -6,
      "name": "Rock_Volcanic_Brick_Stairs",
      "rotation": 8
    },
    {
      "x": -53,
      "y": 34,
      "z": -6,
      "name": "Rock_Volcanic_Brick_Half"
    },
    {
      "x": -53,
      "y": 0,
      "z": -5,
      "name": "Rock_Volcanic_Cobble"
    },
    {
      "x": -53,
      "y": 1,
      "z": -5,
      "name": "Rock_Volcanic_Cobble"
    },
    {
      "x": -53,
      "y": 2,
      "z": -5,
      "name": "Rock_Volcanic_Cobble"
    },
    {
      "x": -53,
      "y": 3,
      "z": -5,
      "name": "Rock_Volcanic_Brick"
    },
    {
      "x": -53,
      "y": 4,
      "z": -5,
      "name": "Rock_Volcanic_Brick"
    },
    {
      "x": -53,
      "y": 5,
      "z": -5,
      "name": "Rock_Volcanic_Brick"
    },
    {
      "x": -53,
      "y": 6,
      "z": -5,
      "name": "Rock_Volcanic_Brick"
    },
    {
      "x": -53,
      "y": 7,
      "z": -5,
      "name": "Rock_Volcanic_Brick"
    },
    {
      "x": -53,
      "y": 8,
      "z": -5,
      "name": "Rock_Volcanic_Cobble"
    },
    {
      "x": -53,
      "y": 9,
      "z": -5,
      "name": "Rock_Volcanic_Cobble"
    },
    {
      "x": -53,
      "y": 10,
      "z": -5,
      "name": "Rock_Volcanic_Brick"
    },
    {
      "x": -53,
      "y": 11,
      "z": -5,
      "name": "Rock_Volcanic_Brick"
    },
    {
      "x": -53,
      "y": 12,
      "z": -5,
      "name": "Rock_Volcanic_Brick"
    },
    {
      "x": -53,
      "y": 13,
      "z": -5,
      "name": "Rock_Volcanic_Brick"
    },
    {
      "x": -53,
      "y": 14,
      "z": -5,
      "name": "Rock_Volcanic_Brick"
    },
    {
      "x": -53,
      "y": 15,
      "z": -5,
      "name": "Rock_Volcanic_Brick"
    },
    {
      "x": -53,
      "y": 16,
      "z": -5,
      "name": "Rock_Volcanic_Brick"
    },
    {
      "x": -53,
      "y": 17,
      "z": -5,
      "name": "Rock_Volcanic_Brick"
    },
    {
      "x": -53,
      "y": 18,
      "z": -5,
      "name": "Rock_Volcanic_Brick"
    },
    {
      "x": -53,
      "y": 19,
      "z": -5,
      "name": "Rock_Volcanic_Brick"
    },
    {
      "x": -53,
      "y": 20,
      "z": -5,
      "name": "Rock_Volcanic_Brick"
    },
    {
      "x": -53,
      "y": 21,
      "z": -5,
      "name": "Rock_Volcanic_Cobble"
    },
    {
      "x": -53,
      "y": 22,
      "z": -5,
      "name": "Rock_Volcanic_Cobble"
    },
    {
      "x": -53,
      "y": 23,
      "z": -5,
      "name": "Rock_Volcanic_Cobble"
    },
    {
      "x": -53,
      "y": 24,
      "z": -5,
      "name": "Rock_Volcanic_Cobble"
    },
    {
      "x": -53,
      "y": 25,
      "z": -5,
      "name": "Rock_Volcanic_Cobble"
    },
    {
      "x": -53,
      "y": 26,
      "z": -5,
      "name": "Rock_Volcanic_Brick"
    },
    {
      "x": -53,
      "y": 27,
      "z": -5,
      "name": "Rock_Volcanic_Cobble"
    },
    {
      "x": -53,
      "y": 28,
      "z": -5,
      "name": "Rock_Volcanic_Cobble"
    },
    {
      "x": -53,
      "y": 29,
      "z": -5,
      "name": "Rock_Volcanic_Brick"
    },
    {
      "x": -53,
      "y": 30,
      "z": -5,
      "name": "Rock_Volcanic_Cobble"
    },
    {
      "x": -53,
      "y": 31,
      "z": -5,
      "name": "Rock_Volcanic_Brick"
    },
    {
      "x": -53,
      "y": 32,
      "z": -5,
      "name": "Rock_Volcanic_Cobble"
    },
    {
      "x": -53,
      "y": 33,
      "z": -5,
      "name": "Rock_Volcanic_Cobble"
    },
    {
      "x": -53,
      "y": 14,
      "z": -4,
      "name": "Rock_Volcanic_Brick"
    },
    {
      "x": -53,
      "y": 21,
      "z": -4,
      "name": "Rock_Volcanic_Brick"
    },
    {
      "x": -53,
      "y": 26,
      "z": -4,
      "name": "Rock_Volcanic_Brick"
    },
    {
      "x": -53,
      "y": 33,
      "z": -4,
      "name": "Rock_Volcanic_Brick"
    },
    {
      "x": -53,
      "y": 14,
      "z": -3,
      "name": "Rock_Volcanic_Brick"
    },
    {
      "x": -53,
      "y": 21,
      "z": -3,
      "name": "Rock_Volcanic_Brick"
    },
    {
      "x": -53,
      "y": 26,
      "z": -3,
      "name": "Rock_Volcanic_Brick"
    },
    {
      "x": -53,
      "y": 33,
      "z": -3,
      "name": "Rock_Volcanic_Brick"
    },
    {
      "x": -53,
      "y": 14,
      "z": -2,
      "name": "Rock_Volcanic_Brick"
    },
    {
      "x": -53,
      "y": 21,
      "z": -2,
      "name": "Rock_Volcanic_Brick"
    },
    {
      "x": -53,
      "y": 26,
      "z": -2,
      "name": "Rock_Volcanic_Brick"
    },
    {
      "x": -53,
      "y": 33,
      "z": -2,
      "name": "Deco_Iron_Bars_Platforms",
      "rotation": 1
    },
    {
      "x": -53,
      "y": 14,
      "z": -1,
      "name": "Rock_Volcanic_Brick"
    },
    {
      "x": -53,
      "y": 21,
      "z": -1,
      "name": "Deco_Iron_Bars_Platforms",
      "rotation": 1
    },
    {
      "x": -53,
      "y": 26,
      "z": -1,
      "name": "Deco_Iron_Bars_Platforms",
      "rotation": 1
    },
    {
      "x": -53,
      "y": 33,
      "z": -1,
      "name": "Deco_Iron_Bars_Platforms",
      "rotation": 1
    },
    {
      "x": -53,
      "y": 14,
      "z": 0,
      "name": "Rock_Volcanic_Brick"
    },
    {
      "x": -53,
      "y": 21,
      "z": 0,
      "name": "Deco_Iron_Bars_Platforms",
      "rotation": 1
    },
    {
      "x": -53,
      "y": 26,
      "z": 0,
      "name": "Deco_Iron_Bars_Platforms",
      "rotation": 1
    },
    {
      "x": -53,
      "y": 33,
      "z": 0,
      "name": "Deco_Iron_Bars_Platforms",
      "rotation": 1
    },
    {
      "x": -53,
      "y": 14,
      "z": 1,
      "name": "Rock_Volcanic_Brick"
    },
    {
      "x": -53,
      "y": 21,
      "z": 1,
      "name": "Deco_Iron_Bars_Platforms",
      "rotation": 1
    },
    {
      "x": -53,
      "y": 26,
      "z": 1,
      "name": "Deco_Iron_Bars_Platforms",
      "rotation": 1
    },
    {
      "x": -53,
      "y": 33,
      "z": 1,
      "name": "Deco_Iron_Bars_Platforms",
      "rotation": 1
    },
    {
      "x": -53,
      "y": 14,
      "z": 2,
      "name": "Rock_Volcanic_Brick"
    },
    {
      "x": -53,
      "y": 21,
      "z": 2,
      "name": "Rock_Volcanic_Brick"
    },
    {
      "x": -53,
      "y": 26,
      "z": 2,
      "name": "Rock_Volcanic_Brick"
    },
    {
      "x": -53,
      "y": 33,
      "z": 2,
      "name": "Deco_Iron_Bars_Platforms",
      "rotation": 1
    },
    {
      "x": -53,
      "y": 14,
      "z": 3,
      "name": "Rock_Volcanic_Brick"
    },
    {
      "x": -53,
      "y": 21,
      "z": 3,
      "name": "Rock_Volcanic_Brick"
    },
    {
      "x": -53,
      "y": 26,
      "z": 3,
      "name": "Rock_Volcanic_Brick"
    },
    {
      "x": -53,
      "y": 33,
      "z": 3,
      "name": "Rock_Volcanic_Brick"
    },
    {
      "x": -53,
      "y": 14,
      "z": 4,
      "name": "Rock_Volcanic_Brick"
    },
    {
      "x": -53,
      "y": 21,
      "z": 4,
      "name": "Rock_Volcanic_Brick"
    },
    {
      "x": -53,
      "y": 26,
      "z": 4,
      "name": "Rock_Volcanic_Brick"
    },
    {
      "x": -53,
      "y": 33,
      "z": 4,
      "name": "Rock_Volcanic_Brick"
    },
    {
      "x": -53,
      "y": 0,
      "z": 5,
      "name": "Rock_Volcanic_Cobble"
    },
    {
      "x": -53,
      "y": 1,
      "z": 5,
      "name": "Rock_Volcanic_Brick"
    },
    {
      "x": -53,
      "y": 2,
      "z": 5,
      "name": "Rock_Volcanic_Cobble"
    },
    {
      "x": -53,
      "y": 3,
      "z": 5,
      "name": "Rock_Volcanic_Cobble"
    },
    {
      "x": -53,
      "y": 4,
      "z": 5,
      "name": "Rock_Volcanic_Cobble"
    },
    {
      "x": -53,
      "y": 5,
      "z": 5,
      "name": "Rock_Volcanic_Cobble"
    },
    {
      "x": -53,
      "y": 6,
      "z": 5,
      "name": "Rock_Volcanic_Cobble"
    },
    {
      "x": -53,
      "y": 7,
      "z": 5,
      "name": "Rock_Volcanic_Brick"
    },
    {
      "x": -53,
      "y": 8,
      "z": 5,
      "name": "Rock_Volcanic_Brick"
    },
    {
      "x": -53,
      "y": 9,
      "z": 5,
      "name": "Rock_Volcanic_Brick"
    },
    {
      "x": -53,
      "y": 10,
      "z": 5,
      "name": "Rock_Volcanic_Cobble"
    },
    {
      "x": -53,
      "y": 11,
      "z": 5,
      "name": "Rock_Volcanic_Cobble"
    },
    {
      "x": -53,
      "y": 12,
      "z": 5,
      "name": "Rock_Volcanic_Cobble"
    },
    {
      "x": -53,
      "y": 13,
      "z": 5,
      "name": "Rock_Volcanic_Brick"
    },
    {
      "x": -53,
      "y": 14,
      "z": 5,
      "name": "Rock_Volcanic_Cobble"
    },
    {
      "x": -53,
      "y": 15,
      "z": 5,
      "name": "Rock_Volcanic_Brick"
    },
    {
      "x": -53,
      "y": 16,
      "z": 5,
      "name": "Rock_Volcanic_Cobble"
    },
    {
      "x": -53,
      "y": 17,
      "z": 5,
      "name": "Rock_Volcanic_Cobble"
    },
    {
      "x": -53,
      "y": 18,
      "z": 5,
      "name": "Rock_Volcanic_Brick"
    },
    {
      "x": -53,
      "y": 19,
      "z": 5,
      "name": "Rock_Volcanic_Cobble"
    },
    {
      "x": -53,
      "y": 20,
      "z": 5,
      "name": "Rock_Volcanic_Cobble"
    },
    {
      "x": -53,
      "y": 21,
      "z": 5,
      "name": "Rock_Volcanic_Cobble"
    },
    {
      "x": -53,
      "y": 22,
      "z": 5,
      "name": "Rock_Volcanic_Cobble"
    },
    {
      "x": -53,
      "y": 23,
      "z": 5,
      "name": "Rock_Volcanic_Brick"
    },
    {
      "x": -53,
      "y": 24,
      "z": 5,
      "name": "Rock_Volcanic_Brick"
    },
    {
      "x": -53,
      "y": 25,
      "z": 5,
      "name": "Rock_Volcanic_Cobble"
    },
    {
      "x": -53,
      "y": 26,
      "z": 5,
      "name": "Rock_Volcanic_Cobble"
    },
    {
      "x": -53,
      "y": 27,
      "z": 5,
      "name": "Rock_Volcanic_Brick"
    },
    {
      "x": -53,
      "y": 28,
      "z": 5,
      "name": "Rock_Volcanic_Brick"
    },
    {
      "x": -53,
      "y": 29,
      "z": 5,
      "name": "Rock_Volcanic_Cobble"
    },
    {
      "x": -53,
      "y": 30,
      "z": 5,
      "name": "Rock_Volcanic_Cobble"
    },
    {
      "x": -53,
      "y": 31,
      "z": 5,
      "name": "Rock_Volcanic_Cobble"
    },
    {
      "x": -53,
      "y": 32,
      "z": 5,
      "name": "Rock_Volcanic_Cobble"
    },
    {
      "x": -53,
      "y": 33,
      "z": 5,
      "name": "Rock_Volcanic_Cobble"
    },
    {
      "x": -53,
      "y": 33,
      "z": 6,
      "name": "Rock_Volcanic_Brick_Stairs",
      "rotation": 10
    },
    {
      "x": -53,
      "y": 34,
      "z": 6,
      "name": "Rock_Volcanic_Brick_Half"
    },
    {
      "x": -52,
      "y": 33,
      "z": -6,
      "name": "Rock_Volcanic_Brick_Stairs",
      "rotation": 8
    },
    {
      "x": -52,
      "y": 34,
      "z": -6,
      "name": "Rock_Volcanic_Brick_Pillar_Base"
    },
    {
      "x": -52,
      "y": 0,
      "z": -5,
      "name": "Rock_Volcanic_Cobble"
    },
    {
      "x": -52,
      "y": 1,
      "z": -5,
      "name": "Rock_Volcanic_Cobble"
    },
    {
      "x": -52,
      "y": 2,
      "z": -5,
      "name": "Rock_Volcanic_Cobble"
    },
    {
      "x": -52,
      "y": 3,
      "z": -5,
      "name": "Rock_Volcanic_Brick"
    },
    {
      "x": -52,
      "y": 4,
      "z": -5,
      "name": "Rock_Volcanic_Brick"
    },
    {
      "x": -52,
      "y": 5,
      "z": -5,
      "name": "Rock_Volcanic_Cobble"
    },
    {
      "x": -52,
      "y": 6,
      "z": -5,
      "name": "Rock_Volcanic_Cobble"
    },
    {
      "x": -52,
      "y": 7,
      "z": -5,
      "name": "Rock_Volcanic_Cobble"
    },
    {
      "x": -52,
      "y": 8,
      "z": -5,
      "name": "Rock_Volcanic_Cobble"
    },
    {
      "x": -52,
      "y": 9,
      "z": -5,
      "name": "Rock_Volcanic_Cobble"
    },
    {
      "x": -52,
      "y": 10,
      "z": -5,
      "name": "Rock_Volcanic_Cobble"
    },
    {
      "x": -52,
      "y": 11,
      "z": -5,
      "name": "Rock_Volcanic_Cobble"
    },
    {
      "x": -52,
      "y": 12,
      "z": -5,
      "name": "Rock_Volcanic_Cobble"
    },
    {
      "x": -52,
      "y": 13,
      "z": -5,
      "name": "Rock_Volcanic_Brick"
    },
    {
      "x": -52,
      "y": 14,
      "z": -5,
      "name": "Rock_Volcanic_Brick"
    },
    {
      "x": -52,
      "y": 15,
      "z": -5,
      "name": "Rock_Volcanic_Cobble"
    },
    {
      "x": -52,
      "y": 16,
      "z": -5,
      "name": "Rock_Volcanic_Cobble"
    },
    {
      "x": -52,
      "y": 17,
      "z": -5,
      "name": "Rock_Volcanic_Cobble"
    },
    {
      "x": -52,
      "y": 18,
      "z": -5,
      "name": "Rock_Volcanic_Cobble"
    },
    {
      "x": -52,
      "y": 19,
      "z": -5,
      "name": "Rock_Volcanic_Cobble"
    },
    {
      "x": -52,
      "y": 20,
      "z": -5,
      "name": "Rock_Volcanic_Cobble"
    },
    {
      "x": -52,
      "y": 21,
      "z": -5,
      "name": "Rock_Volcanic_Cobble"
    },
    {
      "x": -52,
      "y": 22,
      "z": -5,
      "name": "Rock_Volcanic_Brick"
    },
    {
      "x": -52,
      "y": 23,
      "z": -5,
      "name": "Rock_Volcanic_Cobble"
    },
    {
      "x": -52,
      "y": 24,
      "z": -5,
      "name": "Rock_Volcanic_Brick"
    },
    {
      "x": -52,
      "y": 25,
      "z": -5,
      "name": "Rock_Volcanic_Brick"
    },
    {
      "x": -52,
      "y": 26,
      "z": -5,
      "name": "Rock_Volcanic_Cobble"
    },
    {
      "x": -52,
      "y": 27,
      "z": -5,
      "name": "Rock_Volcanic_Cobble"
    },
    {
      "x": -52,
      "y": 28,
      "z": -5,
      "name": "Rock_Volcanic_Brick"
    },
    {
      "x": -52,
      "y": 29,
      "z": -5,
      "name": "Rock_Volcanic_Cobble"
    },
    {
      "x": -52,
      "y": 30,
      "z": -5,
      "name": "Rock_Volcanic_Brick"
    },
    {
      "x": -52,
      "y": 31,
      "z": -5,
      "name": "Rock_Volcanic_Brick"
    },
    {
      "x": -52,
      "y": 32,
      "z": -5,
      "name": "Rock_Volcanic_Brick"
    },
    {
      "x": -52,
      "y": 33,
      "z": -5,
      "name": "Rock_Volcanic_Brick"
    },
    {
      "x": -52,
      "y": 0,
      "z": -4,
      "name": "Rock_Volcanic_Cobble"
    },
    {
      "x": -52,
      "y": 1,
      "z": -4,
      "name": "Rock_Volcanic_Brick"
    },
    {
      "x": -52,
      "y": 2,
      "z": -4,
      "name": "Rock_Volcanic_Cobble"
    },
    {
      "x": -52,
      "y": 3,
      "z": -4,
      "name": "Rock_Volcanic_Cobble"
    },
    {
      "x": -52,
      "y": 4,
      "z": -4,
      "name": "Rock_Volcanic_Cobble"
    },
    {
      "x": -52,
      "y": 5,
      "z": -4,
      "name": "Rock_Volcanic_Brick"
    },
    {
      "x": -52,
      "y": 6,
      "z": -4,
      "name": "Rock_Volcanic_Cobble"
    },
    {
      "x": -52,
      "y": 7,
      "z": -4,
      "name": "Rock_Volcanic_Brick"
    },
    {
      "x": -52,
      "y": 8,
      "z": -4,
      "name": "Rock_Volcanic_Brick"
    },
    {
      "x": -52,
      "y": 9,
      "z": -4,
      "name": "Rock_Volcanic_Cobble"
    },
    {
      "x": -52,
      "y": 10,
      "z": -4,
      "name": "Rock_Volcanic_Cobble"
    },
    {
      "x": -52,
      "y": 11,
      "z": -4,
      "name": "Rock_Volcanic_Brick"
    },
    {
      "x": -52,
      "y": 12,
      "z": -4,
      "name": "Rock_Volcanic_Cobble"
    },
    {
      "x": -52,
      "y": 13,
      "z": -4,
      "name": "Rock_Volcanic_Cobble"
    },
    {
      "x": -52,
      "y": 14,
      "z": -4,
      "name": "Rock_Volcanic_Cobble"
    },
    {
      "x": -52,
      "y": 15,
      "z": -4,
      "name": "Rock_Volcanic_Cobble"
    },
    {
      "x": -52,
      "y": 16,
      "z": -4,
      "name": "Rock_Volcanic_Cobble"
    },
    {
      "x": -52,
      "y": 17,
      "z": -4,
      "name": "Rock_Volcanic_Brick"
    },
    {
      "x": -52,
      "y": 18,
      "z": -4,
      "name": "Rock_Volcanic_Brick"
    },
    {
      "x": -52,
      "y": 19,
      "z": -4,
      "name": "Rock_Volcanic_Cobble"
    },
    {
      "x": -52,
      "y": 20,
      "z": -4,
      "name": "Rock_Volcanic_Brick"
    },
    {
      "x": -52,
      "y": 21,
      "z": -4,
      "name": "Rock_Volcanic_Cobble"
    },
    {
      "x": -52,
      "y": 22,
      "z": -4,
      "name": "Rock_Volcanic_Brick"
    },
    {
      "x": -52,
      "y": 23,
      "z": -4,
      "name": "Rock_Volcanic_Cobble"
    },
    {
      "x": -52,
      "y": 24,
      "z": -4,
      "name": "Rock_Volcanic_Brick"
    },
    {
      "x": -52,
      "y": 25,
      "z": -4,
      "name": "Rock_Volcanic_Cobble"
    },
    {
      "x": -52,
      "y": 26,
      "z": -4,
      "name": "Rock_Volcanic_Brick"
    },
    {
      "x": -52,
      "y": 27,
      "z": -4,
      "name": "Rock_Volcanic_Brick"
    },
    {
      "x": -52,
      "y": 28,
      "z": -4,
      "name": "Rock_Volcanic_Brick"
    },
    {
      "x": -52,
      "y": 29,
      "z": -4,
      "name": "Rock_Volcanic_Brick"
    },
    {
      "x": -52,
      "y": 30,
      "z": -4,
      "name": "Rock_Volcanic_Brick"
    },
    {
      "x": -52,
      "y": 31,
      "z": -4,
      "name": "Rock_Volcanic_Brick"
    },
    {
      "x": -52,
      "y": 32,
      "z": -4,
      "name": "Rock_Volcanic_Cobble"
    },
    {
      "x": -52,
      "y": 33,
      "z": -4,
      "name": "Rock_Volcanic_Brick"
    },
    {
      "x": -52,
      "y": 14,
      "z": -3,
      "name": "Rock_Volcanic_Brick"
    },
    {
      "x": -52,
      "y": 21,
      "z": -3,
      "name": "Rock_Volcanic_Brick"
    },
    {
      "x": -52,
      "y": 26,
      "z": -3,
      "name": "Rock_Volcanic_Brick"
    },
    {
      "x": -52,
      "y": 33,
      "z": -3,
      "name": "Rock_Volcanic_Brick"
    },
    {
      "x": -52,
      "y": 14,
      "z": -2,
      "name": "Rock_Volcanic_Brick"
    },
    {
      "x": -52,
      "y": 21,
      "z": -2,
      "name": "Rock_Volcanic_Brick"
    },
    {
      "x": -52,
      "y": 26,
      "z": -2,
      "name": "Rock_Volcanic_Brick"
    },
    {
      "x": -52,
      "y": 33,
      "z": -2,
      "name": "Rock_Volcanic_Brick"
    },
    {
      "x": -52,
      "y": 14,
      "z": -1,
      "name": "Rock_Volcanic_Brick"
    },
    {
      "x": -52,
      "y": 21,
      "z": -1,
      "name": "Rock_Volcanic_Brick"
    },
    {
      "x": -52,
      "y": 26,
      "z": -1,
      "name": "Rock_Volcanic_Brick"
    },
    {
      "x": -52,
      "y": 33,
      "z": -1,
      "name": "Deco_Iron_Bars_Platforms",
      "rotation": 1
    },
    {
      "x": -52,
      "y": 14,
      "z": 0,
      "name": "Rock_Volcanic_Brick"
    },
    {
      "x": -52,
      "y": 21,
      "z": 0,
      "name": "Rock_Volcanic_Brick"
    },
    {
      "x": -52,
      "y": 26,
      "z": 0,
      "name": "Rock_Volcanic_Brick"
    },
    {
      "x": -52,
      "y": 33,
      "z": 0,
      "name": "Deco_Iron_Bars_Platforms",
      "rotation": 1
    },
    {
      "x": -52,
      "y": 14,
      "z": 1,
      "name": "Rock_Volcanic_Brick"
    },
    {
      "x": -52,
      "y": 21,
      "z": 1,
      "name": "Rock_Volcanic_Brick"
    },
    {
      "x": -52,
      "y": 26,
      "z": 1,
      "name": "Rock_Volcanic_Brick"
    },
    {
      "x": -52,
      "y": 33,
      "z": 1,
      "name": "Deco_Iron_Bars_Platforms",
      "rotation": 1
    },
    {
      "x": -52,
      "y": 14,
      "z": 2,
      "name": "Rock_Volcanic_Brick"
    },
    {
      "x": -52,
      "y": 21,
      "z": 2,
      "name": "Rock_Volcanic_Brick"
    },
    {
      "x": -52,
      "y": 26,
      "z": 2,
      "name": "Rock_Volcanic_Brick"
    },
    {
      "x": -52,
      "y": 33,
      "z": 2,
      "name": "Rock_Volcanic_Brick"
    },
    {
      "x": -52,
      "y": 14,
      "z": 3,
      "name": "Rock_Volcanic_Brick"
    },
    {
      "x": -52,
      "y": 15,
      "z": 3,
      "name": "Furniture_Human_Ruins_Ladder",
      "rotation": 2
    },
    {
      "x": -52,
      "y": 16,
      "z": 3,
      "name": "Furniture_Human_Ruins_Ladder",
      "rotation": 2
    },
    {
      "x": -52,
      "y": 17,
      "z": 3,
      "name": "Furniture_Human_Ruins_Ladder",
      "rotation": 2
    },
    {
      "x": -52,
      "y": 18,
      "z": 3,
      "name": "Furniture_Human_Ruins_Ladder",
      "rotation": 2
    },
    {
      "x": -52,
      "y": 19,
      "z": 3,
      "name": "Furniture_Human_Ruins_Ladder",
      "rotation": 2
    },
    {
      "x": -52,
      "y": 20,
      "z": 3,
      "name": "Furniture_Human_Ruins_Ladder",
      "rotation": 2
    },
    {
      "x": -52,
      "y": 21,
      "z": 3,
      "name": "Furniture_Human_Ruins_Ladder",
      "rotation": 2
    },
    {
      "x": -52,
      "y": 22,
      "z": 3,
      "name": "Furniture_Human_Ruins_Ladder",
      "rotation": 2
    },
    {
      "x": -52,
      "y": 23,
      "z": 3,
      "name": "Furniture_Human_Ruins_Ladder",
      "rotation": 2
    },
    {
      "x": -52,
      "y": 24,
      "z": 3,
      "name": "Furniture_Human_Ruins_Ladder",
      "rotation": 2
    },
    {
      "x": -52,
      "y": 25,
      "z": 3,
      "name": "Furniture_Human_Ruins_Ladder",
      "rotation": 2
    },
    {
      "x": -52,
      "y": 26,
      "z": 3,
      "name": "Furniture_Human_Ruins_Ladder",
      "rotation": 2
    },
    {
      "x": -52,
      "y": 27,
      "z": 3,
      "name": "Furniture_Human_Ruins_Ladder",
      "rotation": 2
    },
    {
      "x": -52,
      "y": 28,
      "z": 3,
      "name": "Furniture_Human_Ruins_Ladder",
      "rotation": 2
    },
    {
      "x": -52,
      "y": 29,
      "z": 3,
      "name": "Furniture_Human_Ruins_Ladder",
      "rotation": 2
    },
    {
      "x": -52,
      "y": 30,
      "z": 3,
      "name": "Furniture_Human_Ruins_Ladder",
      "rotation": 2
    },
    {
      "x": -52,
      "y": 31,
      "z": 3,
      "name": "Furniture_Human_Ruins_Ladder",
      "rotation": 2
    },
    {
      "x": -52,
      "y": 32,
      "z": 3,
      "name": "Furniture_Human_Ruins_Ladder",
      "rotation": 2
    },
    {
      "x": -52,
      "y": 33,
      "z": 3,
      "name": "Furniture_Human_Ruins_Ladder",
      "rotation": 2
    },
    {
      "x": -52,
      "y": 0,
      "z": 4,
