{
  "version": 8,
  "blockIdVersion": 11,
  "anchorX": 0,
  "anchorY": 1,
  "anchorZ": 0,
  "blocks": [
    {
      "x": -5,
      "y": -4,
      "z": -4,
      "name": "Rock_Volcanic_Cobble"
    },
    {
      "x": -5,
      "y": -3,
      "z": -4,
      "name": "Rock_Volcanic_Cobble"
    },
    {
      "x": -5,
      "y": -2,
      "z": -4,
      "name": "Rock_Volcanic_Cobble"
    },
    {
      "x": -5,
      "y": -1,
      "z": -4,
      "name": "Rock_Volcanic_Cobble"
    },
    {
      "x": -5,
      "y": 0,
      "z": -4,
      "name": "Rock_Volcanic_Cobble"
    },
    {
      "x": -5,
      "y": 1,
      "z": -4,
      "name": "Rock_Volcanic_Cobble"
    },
    {
      "x": -5,
      "y": 2,
      "z": -4,
      "name": "Rock_Volcanic_Cobble_Half"
    },
    {
      "x": -5,
      "y": -4,
      "z": -3,
      "name": "Rock_Volcanic_Cobble"
    },
    {
      "x": -5,
      "y": -3,
      "z": -3,
      "name": "Rock_Volcanic_Cobble"
    },
    {
      "x": -5,
      "y": -2,
      "z": -3,
      "name": "Rock_Volcanic_Cobble"
    },
    {
      "x": -5,
      "y": -1,
      "z": -3,
      "name": "Rock_Volcanic_Cobble"
    },
    {
      "x": -5,
      "y": 0,
      "z": -3,
      "name": "Rock_Volcanic_Cobble"
    },
    {
      "x": -5,
      "y": 1,
      "z": -3,
      "name": "Rock_Volcanic_Cobble"
    },
    {
      "x": -5,
      "y": -4,
      "z": -2,
      "name": "Rock_Volcanic_Cobble"
    },
    {
      "x": -5,
      "y": -3,
      "z": -2,
      "name": "Rock_Volcanic_Cobble"
    },
    {
      "x": -5,
      "y": -2,
      "z": -2,
      "name": "Rock_Volcanic_Cobble"
    },
    {
      "x": -5,
      "y": -1,
      "z": -2,
      "name": "Rock_Volcanic_Cobble"
    },
    {
      "x": -5,
      "y": 0,
      "z": -2,
      "name": "Rock_Volcanic_Cobble"
    },
    {
      "x": -5,
      "y": 1,
      "z": -2,
      "name": "Rock_Volcanic_Cobble_Half"
    },
    {
      "x": -5,
      "y": -4,
      "z": -1,
      "name": "Rock_Volcanic_Cobble"
    },
    {
      "x": -5,
      "y": -3,
      "z": -1,
      "name": "Rock_Volcanic_Cobble"
    },
    {
      "x": -5,
      "y": -2,
      "z": -1,
      "name": "Rock_Volcanic_Cobble"
    },
    {
      "x": -5,
      "y": -1,
      "z": -1,
      "name": "Rock_Volcanic_Cobble"
    },
    {
      "x": -5,
      "y": 0,
      "z": -1,
      "name": "Rock_Volcanic_Cobble"
    },
    {
      "x": -5,
      "y": -4,
      "z": 0,
      "name": "Rock_Volcanic_Cobble"
    },
    {
      "x": -5,
      "y": -3,
      "z": 0,
      "name": "Rock_Volcanic_Cobble"
    },
    {
      "x": -5,
      "y": -2,
      "z": 0,
      "name": "Rock_Volcanic_Cobble"
    },
    {
      "x": -5,
      "y": -1,
      "z": 0,
      "name": "Rock_Volcanic_Cobble"
    },
    {
      "x": -5,
      "y": 0,
      "z": 0,
      "name": "Rock_Volcanic_Cobble"
    },
    {
      "x": -5,
      "y": -4,
      "z": 1,
      "name": "Rock_Volcanic_Cobble"
    },
    {
      "x": -5,
      "y": -3,
      "z": 1,
      "name": "Rock_Volcanic_Cobble"
    },
    {
      "x": -5,
      "y": -2,
      "z": 1,
      "name": "Rock_Volcanic_Cobble"
    },
    {
      "x": -5,
      "y": -1,
      "z": 1,
      "name": "Rock_Volcanic_Cobble"
    },
    {
      "x": -5,
      "y": 0,
      "z": 1,
      "name": "Rock_Volcanic_Cobble"
    },
    {
      "x": -5,
      "y": 1,
      "z": 1,
      "name": "Rock_Volcanic_Cobble_Half"
    },
    {
      "x": -5,
      "y": -4,
      "z": 2,
      "name": "Rock_Volcanic_Cobble"
    },
    {
      "x": -5,
      "y": -3,
      "z": 2,
      "name": "Rock_Volcanic_Cobble"
    },
    {
      "x": -5,
      "y": -2,
      "z": 2,
      "name": "Rock_Volcanic_Cobble"
    },
    {
      "x": -5,
      "y": -1,
      "z": 2,
      "name": "Rock_Volcanic_Cobble"
    },
    {
      "x": -5,
      "y": 0,
      "z": 2,
      "name": "Rock_Volcanic_Cobble"
    },
    {
      "x": -5,
      "y": 1,
      "z": 2,
      "name": "Rock_Volcanic_Cobble"
    },
    {
      "x": -5,
      "y": 2,
      "z": 2,
      "name": "Wood_Deadwood_Beam"
    },
    {
      "x": -5,
      "y": 3,
      "z": 2,
      "name": "Wood_Deadwood_Beam"
    },
    {
      "x": -5,
      "y": -4,
      "z": 3,
      "name": "Rock_Volcanic_Cobble"
    },
    {
      "x": -5,
      "y": -3,
      "z": 3,
      "name": "Rock_Volcanic_Cobble"
    },
    {
      "x": -5,
      "y": -2,
      "z": 3,
      "name": "Rock_Volcanic_Cobble"
    },
    {
      "x": -5,
      "y": -1,
      "z": 3,
      "name": "Rock_Volcanic_Cobble"
    },
    {
      "x": -5,
      "y": 0,
      "z": 3,
      "name": "Rock_Volcanic_Cobble"
    },
    {
      "x": -5,
      "y": 1,
      "z": 3,
      "name": "Rock_Volcanic_Cobble"
    },
    {
      "x": -5,
      "y": -4,
      "z": 4,
      "name": "Rock_Volcanic_Cobble"
    },
    {
      "x": -5,
      "y": -3,
      "z": 4,
      "name": "Rock_Volcanic_Cobble"
    },
    {
      "x": -5,
      "y": -2,
      "z": 4,
      "name": "Rock_Volcanic_Cobble"
    },
    {
      "x": -5,
      "y": -1,
      "z": 4,
      "name": "Rock_Volcanic_Cobble"
    },
    {
      "x": -5,
      "y": 0,
      "z": 4,
      "name": "Rock_Volcanic_Cobble"
    },
    {
      "x": -5,
      "y": 1,
      "z": 4,
      "name": "Rock_Volcanic_Cobble"
    },
    {
      "x": -4,
      "y": -4,
      "z": -4,
      "name": "Rock_Volcanic_Cobble"
    },
    {
      "x": -4,
      "y": -3,
      "z": -4,
      "name": "Rock_Volcanic_Cobble"
    },
    {
      "x": -4,
      "y": -2,
      "z": -4,
      "name": "Rock_Volcanic_Cobble"
    },
    {
      "x": -4,
      "y": -1,
      "z": -4,
      "name": "Rock_Volcanic_Cobble"
    },
    {
      "x": -4,
      "y": 0,
      "z": -4,
      "name": "Rock_Volcanic_Cobble"
    },
    {
      "x": -4,
      "y": 1,
      "z": -4,
      "name": "Rock_Volcanic_Cobble"
    },
    {
      "x": -4,
      "y": 2,
      "z": -4,
      "name": "Wood_Deadwood_Beam"
    },
    {
      "x": -4,
      "y": 1,
      "z": -3,
      "name": "Rock_Volcanic_Cobble_Half"
    },
    {
      "x": -4,
      "y": 1,
      "z": 2,
      "name": "Rock_Volcanic_Cobble_Half"
    },
    {
      "x": -4,
      "y": 1,
      "z": 3,
      "name": "*Rock_Volcanic_Cobble_Half_State_Definitions_Block"
    },
    {
      "x": -4,
      "y": -4,
      "z": 4,
      "name": "Rock_Volcanic_Cobble"
    },
    {
      "x": -4,
      "y": -3,
      "z": 4,
      "name": "Rock_Volcanic_Cobble"
    },
    {
      "x": -4,
      "y": -2,
      "z": 4,
      "name": "Rock_Volcanic_Cobble"
    },
    {
      "x": -4,
      "y": -1,
      "z": 4,
      "name": "Rock_Volcanic_Cobble"
    },
    {
      "x": -4,
      "y": 0,
      "z": 4,
      "name": "Rock_Volcanic_Cobble"
    },
    {
      "x": -4,
      "y": 1,
      "z": 4,
      "name": "Rock_Volcanic_Cobble"
    },
    {
      "x": -4,
      "y": 2,
      "z": 4,
      "name": "Rock_Volcanic_Brick"
    },
    {
      "x": -4,
      "y": 3,
      "z": 4,
      "name": "Wood_Deadwood_Beam"
    },
    {
      "x": -3,
      "y": -4,
      "z": -4,
      "name": "Rock_Volcanic_Cobble"
    },
    {
      "x": -3,
      "y": -3,
      "z": -4,
      "name": "Rock_Volcanic_Cobble"
    },
    {
      "x": -3,
      "y": -2,
      "z": -4,
      "name": "Rock_Volcanic_Cobble"
    },
    {
      "x": -3,
      "y": -1,
      "z": -4,
      "name": "Rock_Volcanic_Cobble"
    },
    {
      "x": -3,
      "y": 0,
      "z": -4,
      "name": "Rock_Volcanic_Cobble"
    },
    {
      "x": -3,
      "y": 1,
      "z": -4,
      "name": "Rock_Volcanic_Cobble"
    },
    {
      "x": -3,
      "y": 2,
      "z": -4,
      "name": "Rock_Volcanic_Cobble_Half"
    },
    {
      "x": -3,
      "y": -4,
      "z": 4,
      "name": "Rock_Volcanic_Cobble"
    },
    {
      "x": -3,
      "y": -3,
      "z": 4,
      "name": "Rock_Volcanic_Cobble"
    },
    {
      "x": -3,
      "y": -2,
      "z": 4,
      "name": "Rock_Volcanic_Cobble"
    },
    {
      "x": -3,
      "y": -1,
      "z": 4,
      "name": "Rock_Volcanic_Cobble"
    },
    {
      "x": -3,
      "y": 0,
      "z": 4,
      "name": "Rock_Volcanic_Cobble"
    },
    {
      "x": -3,
      "y": 1,
      "z": 4,
      "name": "Rock_Volcanic_Brick"
    },
    {
      "x": -3,
      "y": 2,
      "z": 4,
      "name": "Rock_Volcanic_Cobble_Half"
    },
    {
      "x": -2,
      "y": -4,
      "z": -4,
      "name": "Rock_Volcanic_Cobble"
    },
    {
      "x": -2,
      "y": -3,
      "z": -4,
      "name": "Rock_Volcanic_Cobble"
    },
    {
      "x": -2,
      "y": -2,
      "z": -4,
      "name": "Rock_Volcanic_Cobble"
    },
    {
      "x": -2,
      "y": -1,
      "z": -4,
      "name": "Rock_Volcanic_Cobble"
    },
    {
      "x": -2,
      "y": 0,
      "z": -4,
      "name": "Rock_Volcanic_Cobble"
    },
    {
      "x": -2,
      "y": 1,
      "z": -4,
      "name": "Rock_Volcanic_Cobble"
    },
    {
      "x": -2,
      "y": 2,
      "z": -4,
      "name": "*Rock_Volcanic_Cobble_Half_State_Definitions_Block"
    },
    {
      "x": -2,
      "y": 3,
      "z": -4,
      "name": "Wood_Deadwood_Beam"
    },
    {
      "x": -2,
      "y": 4,
      "z": -4,
      "name": "Wood_Deadwood_Beam"
    },
    {
      "x": -2,
      "y": 1,
      "z": -3,
      "name": "Rock_Volcanic_Cobble_Half",
      "rotation": 4
    },
    {
      "x": -2,
      "y": 1,
      "z": -2,
      "name": "Rock_Volcanic_Cobble_Half"
    },
    {
      "x": -2,
      "y": -4,
      "z": 4,
      "name": "Rock_Volcanic_Cobble"
    },
    {
      "x": -2,
      "y": -3,
      "z": 4,
      "name": "Rock_Volcanic_Cobble"
    },
    {
      "x": -2,
      "y": -2,
      "z": 4,
      "name": "Rock_Volcanic_Cobble"
    },
    {
      "x": -2,
      "y": -1,
      "z": 4,
      "name": "Rock_Volcanic_Cobble"
    },
    {
      "x": -2,
      "y": 0,
      "z": 4,
      "name": "Rock_Volcanic_Cobble"
    },
    {
      "x": -2,
      "y": 1,
      "z": 4,
      "name": "Rock_Volcanic_Cobble_Half"
    },
    {
      "x": -1,
      "y": -4,
      "z": -4,
      "name": "Rock_Volcanic_Cobble"
    },
    {
      "x": -1,
      "y": -3,
      "z": -4,
      "name": "Rock_Volcanic_Cobble"
    },
    {
      "x": -1,
      "y": -2,
      "z": -4,
      "name": "Rock_Volcanic_Cobble"
    },
    {
      "x": -1,
      "y": -1,
      "z": -4,
      "name": "Rock_Volcanic_Cobble"
    },
    {
      "x": -1,
      "y": 0,
      "z": -4,
      "name": "Rock_Volcanic_Cobble"
    },
    {
      "x": -1,
      "y": 1,
      "z": -4,
      "name": "Rock_Volcanic_Brick"
    },
    {
      "x": -1,
      "y": 2,
      "z": -4,
      "name": "Rock_Volcanic_Cobble"
    },
    {
      "x": -1,
      "y": 3,
      "z": -4,
      "name": "Wood_Deadwood_Beam"
    },
    {
      "x": -1,
      "y": 1,
      "z": -3,
      "name": "Rock_Volcanic_Cobble_Half"
    },
    {
      "x": -1,
      "y": -4,
      "z": 4,
      "name": "Rock_Volcanic_Cobble"
    },
    {
      "x": -1,
      "y": -3,
      "z": 4,
      "name": "Rock_Volcanic_Cobble"
    },
    {
      "x": -1,
      "y": -2,
      "z": 4,
      "name": "Rock_Volcanic_Cobble"
    },
    {
      "x": -1,
      "y": -1,
      "z": 4,
      "name": "Rock_Volcanic_Cobble"
    },
    {
      "x": -1,
      "y": 0,
      "z": 4,
      "name": "Rock_Volcanic_Cobble"
    },
    {
      "x": 0,
      "y": -4,
      "z": -4,
      "name": "Rock_Volcanic_Cobble"
    },
    {
      "x": 0,
      "y": -3,
      "z": -4,
      "name": "Rock_Volcanic_Cobble"
    },
    {
      "x": 0,
      "y": -2,
      "z": -4,
      "name": "Rock_Volcanic_Cobble"
    },
    {
      "x": 0,
      "y": -1,
      "z": -4,
      "name": "Rock_Volcanic_Cobble"
    },
    {
      "x": 0,
      "y": 0,
      "z": -4,
      "name": "Rock_Volcanic_Cobble"
    },
    {
      "x": 0,
      "y": 1,
      "z": -4,
      "name": "Rock_Volcanic_Brick"
    },
    {
      "x": 0,
      "y": 2,
      "z": -4,
      "name": "Rock_Volcanic_Cobble"
    },
    {
      "x": 0,
      "y": 3,
      "z": -4,
      "name": "Rock_Volcanic_Cobble_Half"
    },
    {
      "x": 0,
      "y": -4,
      "z": 4,
      "name": "Rock_Volcanic_Cobble"
    },
    {
      "x": 0,
      "y": -3,
      "z": 4,
      "name": "Rock_Volcanic_Cobble"
    },
    {
      "x": 0,
      "y": -2,
      "z": 4,
      "name": "Rock_Volcanic_Cobble"
    },
    {
      "x": 0,
      "y": -1,
      "z": 4,
      "name": "Rock_Volcanic_Cobble"
    },
    {
      "x": 0,
      "y": 0,
      "z": 4,
      "name": "Rock_Volcanic_Cobble"
    },
    {
      "x": 1,
      "y": -4,
      "z": -4,
      "name": "Rock_Volcanic_Cobble"
    },
    {
      "x": 1,
      "y": -3,
      "z": -4,
      "name": "Rock_Volcanic_Cobble"
    },
    {
      "x": 1,
      "y": -2,
      "z": -4,
      "name": "Rock_Volcanic_Cobble"
    },
    {
      "x": 1,
      "y": -1,
      "z": -4,
      "name": "Rock_Volcanic_Cobble"
    },
    {
      "x": 1,
      "y": 0,
      "z": -4,
      "name": "Rock_Volcanic_Cobble"
    },
    {
      "x": 1,
      "y": 1,
      "z": -4,
      "name": "Rock_Volcanic_Cobble"
    },
    {
      "x": 1,
      "y": 2,
      "z": -4,
      "name": "Rock_Volcanic_Brick"
    },
    {
      "x": 1,
      "y": -4,
      "z": 4,
      "name": "Rock_Volcanic_Cobble"
    },
    {
      "x": 1,
      "y": -3,
      "z": 4,
      "name": "Rock_Volcanic_Cobble"
    },
    {
      "x": 1,
      "y": -2,
      "z": 4,
      "name": "Rock_Volcanic_Cobble"
    },
    {
      "x": 1,
      "y": -1,
      "z": 4,
      "name": "Rock_Volcanic_Cobble"
    },
    {
      "x": 1,
      "y": 0,
      "z": 4,
      "name": "Rock_Volcanic_Cobble"
    },
    {
      "x": 2,
      "y": -4,
      "z": -4,
      "name": "Rock_Volcanic_Cobble"
    },
    {
      "x": 2,
      "y": -3,
      "z": -4,
      "name": "Rock_Volcanic_Cobble"
    },
    {
      "x": 2,
      "y": -2,
      "z": -4,
      "name": "Rock_Volcanic_Cobble"
    },
    {
      "x": 2,
      "y": -1,
      "z": -4,
      "name": "Rock_Volcanic_Cobble"
    },
    {
      "x": 2,
      "y": 0,
      "z": -4,
      "name": "Rock_Volcanic_Cobble"
    },
    {
      "x": 2,
      "y": 1,
      "z": -4,
      "name": "Rock_Volcanic_Brick"
    },
    {
      "x": 2,
      "y": 2,
      "z": -4,
      "name": "Rock_Volcanic_Cobble"
    },
    {
      "x": 2,
      "y": 3,
      "z": -4,
      "name": "Rock_Volcanic_Brick"
    },
    {
      "x": 2,
      "y": 1,
      "z": -3,
      "name": "Rock_Volcanic_Cobble_Half"
    },
    {
      "x": 2,
      "y": 1,
      "z": -1,
      "name": "Rock_Volcanic_Cobble_Half"
    },
    {
      "x": 2,
      "y": -4,
      "z": 4,
      "name": "Rock_Volcanic_Cobble"
    },
    {
      "x": 2,
      "y": -3,
      "z": 4,
      "name": "Rock_Volcanic_Cobble"
    },
    {
      "x": 2,
      "y": -2,
      "z": 4,
      "name": "Rock_Volcanic_Cobble"
    },
    {
      "x": 2,
      "y": -1,
      "z": 4,
      "name": "Rock_Volcanic_Cobble"
    },
    {
      "x": 2,
      "y": 0,
      "z": 4,
      "name": "Rock_Volcanic_Cobble"
    },
    {
      "x": 3,
      "y": -4,
      "z": -4,
      "name": "Rock_Volcanic_Cobble"
    },
    {
      "x": 3,
      "y": -3,
      "z": -4,
      "name": "Rock_Volcanic_Cobble"
    },
    {
      "x": 3,
      "y": -2,
      "z": -4,
      "name": "Rock_Volcanic_Cobble"
    },
    {
      "x": 3,
      "y": -1,
      "z": -4,
      "name": "Rock_Volcanic_Cobble"
    },
    {
      "x": 3,
      "y": 0,
      "z": -4,
      "name": "Rock_Volcanic_Cobble"
    },
    {
      "x": 3,
      "y": 1,
      "z": -4,
      "name": "Rock_Volcanic_Cobble"
    },
    {
      "x": 3,
      "y": 2,
      "z": -4,
      "name": "Rock_Volcanic_Brick"
    },
    {
      "x": 3,
      "y": 3,
      "z": -4,
      "name": "Rock_Volcanic_Cobble"
    },
    {
      "x": 3,
      "y": 4,
      "z": -4,
      "name": "Rock_Volcanic_Cobble_Half"
    },
    {
      "x": 3,
      "y": 1,
      "z": -3,
      "name": "*Rock_Volcanic_Cobble_Half_State_Definitions_Block"
    },
    {
      "x": 3,
      "y": 1,
      "z": -2,
      "name": "Rock_Volcanic_Cobble_Half"
    },
    {
      "x": 3,
      "y": 1,
      "z": 1,
      "name": "Rock_Volcanic_Cobble_Half"
    },
    {
      "x": 3,
      "y": -4,
      "z": 4,
      "name": "Rock_Volcanic_Cobble"
    },
    {
      "x": 3,
      "y": -3,
      "z": 4,
      "name": "Rock_Volcanic_Cobble"
    },
    {
      "x": 3,
      "y": -2,
      "z": 4,
      "name": "Rock_Volcanic_Cobble"
    },
    {
      "x": 3,
      "y": -1,
      "z": 4,
      "name": "Rock_Volcanic_Cobble"
    },
    {
      "x": 3,
      "y": 0,
      "z": 4,
      "name": "Rock_Volcanic_Cobble"
    },
    {
      "x": 4,
      "y": -4,
      "z": -4,
      "name": "Rock_Volcanic_Cobble"
    },
    {
      "x": 4,
      "y": -3,
      "z": -4,
      "name": "Rock_Volcanic_Cobble"
    },
    {
      "x": 4,
      "y": -2,
      "z": -4,
      "name": "Rock_Volcanic_Cobble"
    },
    {
      "x": 4,
      "y": -1,
      "z": -4,
      "name": "Rock_Volcanic_Cobble"
    },
    {
      "x": 4,
      "y": 0,
      "z": -4,
      "name": "Rock_Volcanic_Cobble"
    },
    {
      "x": 4,
      "y": 1,
      "z": -4,
      "name": "Rock_Volcanic_Cobble"
    },
    {
      "x": 4,
      "y": 2,
      "z": -4,
      "name": "Rock_Volcanic_Cobble"
    },
    {
      "x": 4,
      "y": -4,
      "z": -3,
      "name": "Rock_Volcanic_Cobble"
    },
    {
      "x": 4,
      "y": -3,
      "z": -3,
      "name": "Rock_Volcanic_Cobble"
    },
    {
      "x": 4,
      "y": -2,
      "z": -3,
      "name": "Rock_Volcanic_Cobble"
    },
    {
      "x": 4,
      "y": -1,
      "z": -3,
      "name": "Rock_Volcanic_Cobble"
    },
    {
      "x": 4,
      "y": 0,
      "z": -3,
      "name": "Rock_Volcanic_Cobble"
    },
    {
      "x": 4,
      "y": 1,
      "z": -3,
      "name": "Rock_Volcanic_Brick"
    },
    {
      "x": 4,
      "y": 2,
      "z": -3,
      "name": "Rock_Volcanic_Cobble"
    },
    {
      "x": 4,
      "y": 3,
      "z": -3,
      "name": "Rock_Volcanic_Cobble_Half"
    },
    {
      "x": 4,
      "y": -4,
      "z": -2,
      "name": "Rock_Volcanic_Cobble"
    },
    {
      "x": 4,
      "y": -3,
      "z": -2,
      "name": "Rock_Volcanic_Cobble"
    },
    {
      "x": 4,
      "y": -2,
      "z": -2,
      "name": "Rock_Volcanic_Cobble"
    },
    {
      "x": 4,
      "y": -1,
      "z": -2,
      "name": "Rock_Volcanic_Cobble"
    },
    {
      "x": 4,
      "y": 0,
      "z": -2,
      "name": "Rock_Volcanic_Cobble"
    },
    {
      "x": 4,
      "y": 1,
      "z": -2,
      "name": "Rock_Volcanic_Brick"
    },
    {
      "x": 4,
      "y": 2,
      "z": -2,
      "name": "Rock_Volcanic_Brick"
    },
    {
      "x": 4,
      "y": 3,
      "z": -2,
      "name": "Rock_Volcanic_Brick"
    },
    {
      "x": 4,
      "y": 4,
      "z": -2,
      "name": "Wood_Deadwood_Beam"
    },
    {
      "x": 4,
      "y": -4,
      "z": -1,
      "name": "Rock_Volcanic_Cobble"
    },
    {
      "x": 4,
      "y": -3,
      "z": -1,
      "name": "Rock_Volcanic_Cobble"
    },
    {
      "x": 4,
      "y": -2,
      "z": -1,
      "name": "Rock_Volcanic_Cobble"
    },
    {
      "x": 4,
      "y": -1,
      "z": -1,
      "name": "Rock_Volcanic_Cobble"
    },
    {
      "x": 4,
      "y": 0,
      "z": -1,
      "name": "Rock_Volcanic_Cobble"
    },
    {
      "x": 4,
      "y": 1,
      "z": -1,
      "name": "Rock_Volcanic_Cobble"
    },
    {
      "x": 4,
      "y": 2,
      "z": -1,
      "name": "Rock_Volcanic_Brick"
    },
    {
      "x": 4,
      "y": 3,
      "z": -1,
      "name": "Rock_Volcanic_Cobble"
    },
    {
      "x": 4,
      "y": 4,
      "z": -1,
      "name": "Rock_Volcanic_Cobble_Half"
    },
    {
      "x": 4,
      "y": -4,
      "z": 0,
      "name": "Rock_Volcanic_Cobble"
    },
    {
      "x": 4,
      "y": -3,
      "z": 0,
      "name": "Rock_Volcanic_Cobble"
    },
    {
      "x": 4,
      "y": -2,
      "z": 0,
      "name": "Rock_Volcanic_Cobble"
    },
    {
      "x": 4,
      "y": -1,
      "z": 0,
      "name": "Rock_Volcanic_Cobble"
    },
    {
      "x": 4,
      "y": 0,
      "z": 0,
      "name": "Rock_Volcanic_Cobble"
    },
    {
      "x": 4,
      "y": 1,
      "z": 0,
      "name": "Rock_Volcanic_Brick"
    },
    {
      "x": 4,
      "y": 2,
      "z": 0,
      "name": "Rock_Volcanic_Brick"
    },
    {
      "x": 4,
      "y": 3,
      "z": 0,
      "name": "Rock_Volcanic_Cobble"
    },
    {
      "x": 4,
      "y": 4,
      "z": 0,
      "name": "Rock_Volcanic_Brick"
    },
    {
      "x": 4,
      "y": 5,
      "z": 0,
      "name": "Rock_Volcanic_Cobble_Half"
    },
    {
      "x": 4,
      "y": -4,
      "z": 1,
      "name": "Rock_Volcanic_Cobble"
    },
    {
      "x": 4,
      "y": -3,
      "z": 1,
      "name": "Rock_Volcanic_Cobble"
    },
    {
      "x": 4,
      "y": -2,
      "z": 1,
      "name": "Rock_Volcanic_Cobble"
    },
    {
      "x": 4,
      "y": -1,
      "z": 1,
      "name": "Rock_Volcanic_Cobble"
    },
    {
      "x": 4,
      "y": 0,
      "z": 1,
      "name": "Rock_Volcanic_Cobble"
    },
    {
      "x": 4,
      "y": 1,
      "z": 1,
      "name": "Rock_Volcanic_Cobble"
    },
    {
      "x": 4,
      "y": 2,
      "z": 1,
      "name": "Rock_Volcanic_Cobble"
    },
    {
      "x": 4,
      "y": 3,
      "z": 1,
      "name": "Rock_Volcanic_Brick"
    },
    {
      "x": 4,
      "y": 4,
      "z": 1,
      "name": "Rock_Volcanic_Cobble"
    },
    {
      "x": 4,
      "y": 5,
      "z": 1,
      "name": "Rock_Volcanic_Cobble"
    },
    {
      "x": 4,
      "y": 6,
      "z": 1,
      "name": "Wood_Deadwood_Beam"
    },
    {
      "x": 4,
      "y": -4,
      "z": 2,
      "name": "Rock_Volcanic_Cobble"
    },
    {
      "x": 4,
      "y": -3,
      "z": 2,
      "name": "Rock_Volcanic_Cobble"
    },
    {
      "x": 4,
      "y": -2,
      "z": 2,
      "name": "Rock_Volcanic_Cobble"
    },
    {
      "x": 4,
      "y": -1,
      "z": 2,
      "name": "Rock_Volcanic_Cobble"
    },
    {
      "x": 4,
      "y": 0,
      "z": 2,
      "name": "Rock_Volcanic_Cobble"
    },
    {
      "x": 4,
      "y": 1,
      "z": 2,
      "name": "Rock_Volcanic_Cobble"
    },
    {
      "x": 4,
      "y": 2,
      "z": 2,
      "name": "Rock_Volcanic_Cobble"
    },
    {
      "x": 4,
      "y": 3,
      "z": 2,
      "name": "Rock_Volcanic_Cobble_Half"
    },
    {
      "x": 4,
      "y": -4,
      "z": 3,
      "name": "Rock_Volcanic_Cobble"
    },
    {
      "x": 4,
      "y": -3,
      "z": 3,
      "name": "Rock_Volcanic_Cobble"
    },
    {
      "x": 4,
      "y": -2,
      "z": 3,
      "name": "Rock_Volcanic_Cobble"
    },
    {
      "x": 4,
      "y": -1,
      "z": 3,
      "name": "Rock_Volcanic_Cobble"
    },
    {
      "x": 4,
      "y": 0,
      "z": 3,
      "name": "Rock_Volcanic_Cobble"
    },
    {
      "x": 4,
      "y": 1,
      "z": 3,
      "name": "Rock_Volcanic_Cobble"
    },
    {
      "x": 4,
      "y": 2,
      "z": 3,
      "name": "Rock_Volcanic_Cobble_Half"
    },
    {
      "x": 4,
      "y": -4,
      "z": 4,
      "name": "Rock_Volcanic_Cobble"
    },
    {
      "x": 4,
      "y": -3,
      "z": 4,
      "name": "Rock_Volcanic_Cobble"
    },
    {
      "x": 4,
      "y": -2,
      "z": 4,
      "name": "Rock_Volcanic_Cobble"
    },
    {
      "x": 4,
      "y": -1,
      "z": 4,
      "name": "Rock_Volcanic_Cobble"
    },
    {
      "x": 4,
      "y": 0,
      "z": 4,
      "name": "Rock_Volcanic_Cobble"
    },
    {
      "x": 4,
      "y": 1,
      "z": 4,
      "name": "Rock_Volcanic_Cobble"
    },
    {
      "x": 4,
      "y": 2,
      "z": 4,
      "name": "Wood_Deadwood_Beam"
    },
    {
      "x": 4,
      "y": 3,
      "z": 4,
      "name": "Wood_Deadwood_Beam"
    }
  ]
}