{
  "version": 8,
  "blockIdVersion": 11,
  "anchorX": 0,
  "anchorY": 0,
  "anchorZ": 0,
  "blocks": [
    {
      "x": -4,
      "y": 25,
      "z": -3,
      "name": "Rock_Volcanic_Brick_Stairs",
      "rotation": 34
    },
    {
      "x": -4,
      "y": 26,
      "z": -3,
      "name": "Rock_Volcanic_Brick_Wall",
      "rotation": 2
    },
    {
      "x": -4,
      "y": 0,
      "z": -2,
      "name": "Rock_Volcanic_Brick"
    },
    {
      "x": -4,
      "y": 1,
      "z": -2,
      "name": "Rock_Volcanic_Brick"
    },
    {
      "x": -4,
      "y": 2,
      "z": -2,
      "name": "Rock_Volcanic_Brick_Stairs",
      "rotation": 3
    },
    {
      "x": -4,
      "y": 25,
      "z": -2,
      "name": "Rock_Volcanic_Brick"
    },
    {
      "x": -4,
      "y": 24,
      "z": -1,
      "name": "Rock_Volcanic_Brick_Wall"
    },
    {
      "x": -4,
      "y": 25,
      "z": -1,
      "name": "Rock_Volcanic_Brick_Pillar_Base",
      "rotation": 5
    },
    {
      "x": -4,
      "y": 24,
      "z": 0,
      "name": "Rock_Volcanic_Brick_Pillar_Base",
      "rotation": 5
    },
    {
      "x": -4,
      "y": 25,
      "z": 0,
      "name": "Rock_Volcanic_Brick"
    },
    {
      "x": -4,
      "y": 24,
      "z": 1,
      "name": "Rock_Volcanic_Brick_Pillar_Base",
      "rotation": 5
    },
    {
      "x": -4,
      "y": 25,
      "z": 1,
      "name": "Rock_Volcanic_Brick"
    },
    {
      "x": -4,
      "y": 24,
      "z": 2,
      "name": "Rock_Volcanic_Brick_Wall",
      "rotation": 2
    },
    {
      "x": -4,
      "y": 25,
      "z": 2,
      "name": "Rock_Volcanic_Brick_Pillar_Base",
      "rotation": 5
    },
    {
      "x": -4,
      "y": 0,
      "z": 3,
      "name": "Rock_Volcanic_Brick"
    },
    {
      "x": -4,
      "y": 1,
      "z": 3,
      "name": "Rock_Volcanic_Brick"
    },
    {
      "x": -4,
      "y": 2,
      "z": 3,
      "name": "Rock_Volcanic_Brick_Stairs",
      "rotation": 3
    },
    {
      "x": -4,
      "y": 25,
      "z": 3,
      "name": "Rock_Volcanic_Brick"
    },
    {
      "x": -4,
      "y": 25,
      "z": 4,
      "name": "Rock_Volcanic_Brick_Stairs",
      "rotation": 10
    },
    {
      "x": -4,
      "y": 26,
      "z": 4,
      "name": "Rock_Volcanic_Brick_Wall"
    },
    {
      "x": -3,
      "y": 25,
      "z": -3,
      "name": "Rock_Volcanic_Brick_Stairs",
      "rotation": 34
    },
    {
      "x": -3,
      "y": 26,
      "z": -3,
      "name": "Rock_Volcanic_Brick_Wall",
      "rotation": 2
    },
    {
      "x": -3,
      "y": 0,
      "z": -2,
      "name": "Rock_Volcanic_Brick"
    },
    {
      "x": -3,
      "y": 1,
      "z": -2,
      "name": "Rock_Volcanic_Brick"
    },
    {
      "x": -3,
      "y": 2,
      "z": -2,
      "name": "Rock_Volcanic_Brick"
    },
    {
      "x": -3,
      "y": 3,
      "z": -2,
      "name": "Rock_Volcanic_Brick"
    },
    {
      "x": -3,
      "y": 4,
      "z": -2,
      "name": "Rock_Volcanic_Brick_Stairs",
      "rotation": 3
    },
    {
      "x": -3,
      "y": 24,
      "z": -2,
      "name": "Rock_Volcanic_Brick_Stairs",
      "rotation": 35
    },
    {
      "x": -3,
      "y": 25,
      "z": -2,
      "name": "Rock_Volcanic_Brick",
      "rotation": 2
    },
    {
      "x": -3,
      "y": 24,
      "z": -1,
      "name": "Rock_Volcanic_Brick_Wall"
    },
    {
      "x": -3,
      "y": 25,
      "z": -1,
      "name": "Rock_Volcanic_Brick_Pillar_Middle",
      "rotation": 7
    },
    {
      "x": -3,
      "y": 24,
      "z": 0,
      "name": "Rock_Volcanic_Brick_Pillar_Middle",
      "rotation": 7
    },
    {
      "x": -3,
      "y": 25,
      "z": 0,
      "name": "Rock_Volcanic_Brick"
    },
    {
      "x": -3,
      "y": 24,
      "z": 1,
      "name": "Rock_Volcanic_Brick_Pillar_Middle",
      "rotation": 7
    },
    {
      "x": -3,
      "y": 25,
      "z": 1,
      "name": "Rock_Volcanic_Brick"
    },
    {
      "x": -3,
      "y": 24,
      "z": 2,
      "name": "Rock_Volcanic_Brick_Wall",
      "rotation": 2
    },
    {
      "x": -3,
      "y": 25,
      "z": 2,
      "name": "Rock_Volcanic_Brick_Pillar_Middle",
      "rotation": 7
    },
    {
      "x": -3,
      "y": 0,
      "z": 3,
      "name": "Rock_Volcanic_Brick"
    },
    {
      "x": -3,
      "y": 1,
      "z": 3,
      "name": "Rock_Volcanic_Brick"
    },
    {
      "x": -3,
      "y": 2,
      "z": 3,
      "name": "Rock_Volcanic_Brick"
    },
    {
      "x": -3,
      "y": 3,
      "z": 3,
      "name": "Rock_Volcanic_Brick"
    },
    {
      "x": -3,
      "y": 4,
      "z": 3,
      "name": "Rock_Volcanic_Brick_Stairs",
      "rotation": 3
    },
    {
      "x": -3,
      "y": 24,
      "z": 3,
      "name": "Rock_Volcanic_Brick_Stairs",
      "rotation": 9
    },
    {
      "x": -3,
      "y": 25,
      "z": 3,
      "name": "Rock_Volcanic_Brick"
    },
    {
      "x": -3,
      "y": 25,
      "z": 4,
      "name": "Rock_Volcanic_Brick_Stairs",
      "rotation": 10
    },
    {
      "x": -3,
      "y": 26,
      "z": 4,
      "name": "Rock_Volcanic_Brick_Wall"
    },
    {
      "x": -2,
      "y": 0,
      "z": -4,
      "name": "Rock_Volcanic_Cobble"
    },
    {
      "x": -2,
      "y": 1,
      "z": -4,
      "name": "Rock_Volcanic_Cobble"
    },
    {
      "x": -2,
      "y": 2,
      "z": -4,
      "name": "Rock_Volcanic_Brick"
    },
    {
      "x": -2,
      "y": 3,
      "z": -4,
      "name": "Rock_Volcanic_Brick"
    },
    {
      "x": -2,
      "y": 4,
      "z": -4,
      "name": "Rock_Volcanic_Brick_Half"
    },
    {
      "x": -2,
      "y": 0,
      "z": -3,
      "name": "Rock_Volcanic_Brick"
    },
    {
      "x": -2,
      "y": 1,
      "z": -3,
      "name": "Rock_Volcanic_Brick"
    },
    {
      "x": -2,
      "y": 2,
      "z": -3,
      "name": "Soil_Volcanic_Gravel"
    },
    {
      "x": -2,
      "y": 3,
      "z": -3,
      "name": "Rock_Volcanic_Cobble"
    },
    {
      "x": -2,
      "y": 4,
      "z": -3,
      "name": "Rock_Volcanic_Cobble"
    },
    {
      "x": -2,
      "y": 5,
      "z": -3,
      "name": "Rock_Volcanic_Brick_Half",
      "rotation": 7
    },
    {
      "x": -2,
      "y": 11,
      "z": -3,
      "name": "Rock_Volcanic_Brick_Half",
      "rotation": 7
    },
    {
      "x": -2,
      "y": 25,
      "z": -3,
      "name": "Rock_Volcanic_Brick_Stairs",
      "rotation": 34
    },
    {
      "x": -2,
      "y": 26,
      "z": -3,
      "name": "Rock_Volcanic_Brick"
    },
    {
      "x": -2,
      "y": 27,
      "z": -3,
      "name": "Rock_Volcanic_Brick_Stairs",
      "rotation": 2
    },
    {
      "x": -2,
      "y": 0,
      "z": -2,
      "name": "Rock_Volcanic_Brick"
    },
    {
      "x": -2,
      "y": 1,
      "z": -2,
      "name": "Rock_Volcanic_Brick"
    },
    {
      "x": -2,
      "y": 2,
      "z": -2,
      "name": "Rock_Volcanic_Cobble"
    },
    {
      "x": -2,
      "y": 3,
      "z": -2,
      "name": "Soil_Volcanic_Gravel"
    },
    {
      "x": -2,
      "y": 4,
      "z": -2,
      "name": "Rock_Volcanic_Brick"
    },
    {
      "x": -2,
      "y": 5,
      "z": -2,
      "name": "Rock_Volcanic_Brick_Half",
      "rotation": 7
    },
    {
      "x": -2,
      "y": 11,
      "z": -2,
      "name": "Rock_Volcanic_Brick_Half",
      "rotation": 7
    },
    {
      "x": -2,
      "y": 24,
      "z": -2,
      "name": "Rock_Volcanic_Brick",
      "rotation": 2
    },
    {
      "x": -2,
      "y": 25,
      "z": -2,
      "name": "Rock_Volcanic_Brick",
      "rotation": 2
    },
    {
      "x": -2,
      "y": 0,
      "z": -1,
      "name": "Rock_Volcanic_Cobble"
    },
    {
      "x": -2,
      "y": 1,
      "z": -1,
      "name": "Rock_Volcanic_Brick"
    },
    {
      "x": -2,
      "y": 2,
      "z": -1,
      "name": "Rock_Volcanic_Brick"
    },
    {
      "x": -2,
      "y": 3,
      "z": -1,
      "name": "Rock_Volcanic_Brick"
    },
    {
      "x": -2,
      "y": 4,
      "z": -1,
      "name": "Rock_Volcanic_Cobble"
    },
    {
      "x": -2,
      "y": 5,
      "z": -1,
      "name": "Rock_Volcanic_Brick_Half",
      "rotation": 7
    },
    {
      "x": -2,
      "y": 11,
      "z": -1,
      "name": "Rock_Volcanic_Brick_Half",
      "rotation": 7
    },
    {
      "x": -2,
      "y": 24,
      "z": -1,
      "name": "Rock_Volcanic_Brick_Wall"
    },
    {
      "x": -2,
      "y": 25,
      "z": -1,
      "name": "Rock_Volcanic_Brick_Pillar_Middle",
      "rotation": 7
    },
    {
      "x": -2,
      "y": 0,
      "z": 0,
      "name": "Rock_Volcanic_Cobble"
    },
    {
      "x": -2,
      "y": 1,
      "z": 0,
      "name": "Rock_Volcanic_Brick"
    },
    {
      "x": -2,
      "y": 2,
      "z": 0,
      "name": "Rock_Volcanic_Brick"
    },
    {
      "x": -2,
      "y": 3,
      "z": 0,
      "name": "Rock_Volcanic_Brick"
    },
    {
      "x": -2,
      "y": 4,
      "z": 0,
      "name": "Rock_Volcanic_Brick_Half"
    },
    {
      "x": -2,
      "y": 24,
      "z": 0,
      "name": "Rock_Volcanic_Brick_Pillar_Middle",
      "rotation": 7
    },
    {
      "x": -2,
      "y": 25,
      "z": 0,
      "name": "Rock_Volcanic_Brick"
    },
    {
      "x": -2,
      "y": 0,
      "z": 1,
      "name": "Rock_Volcanic_Brick"
    },
    {
      "x": -2,
      "y": 1,
      "z": 1,
      "name": "Rock_Volcanic_Brick"
    },
    {
      "x": -2,
      "y": 2,
      "z": 1,
      "name": "Soil_Volcanic_Gravel"
    },
    {
      "x": -2,
      "y": 3,
      "z": 1,
      "name": "Rock_Volcanic_Cobble"
    },
    {
      "x": -2,
      "y": 4,
      "z": 1,
      "name": "Rock_Volcanic_Brick_Half"
    },
    {
      "x": -2,
      "y": 24,
      "z": 1,
      "name": "Rock_Volcanic_Brick_Pillar_Middle",
      "rotation": 7
    },
    {
      "x": -2,
      "y": 25,
      "z": 1,
      "name": "Rock_Volcanic_Brick"
    },
    {
      "x": -2,
      "y": 0,
      "z": 2,
      "name": "Rock_Volcanic_Brick"
    },
    {
      "x": -2,
      "y": 1,
      "z": 2,
      "name": "Rock_Volcanic_Cobble"
    },
    {
      "x": -2,
      "y": 2,
      "z": 2,
      "name": "Rock_Volcanic_Cobble"
    },
    {
      "x": -2,
      "y": 3,
      "z": 2,
      "name": "Rock_Volcanic_Cobble"
    },
    {
      "x": -2,
      "y": 4,
      "z": 2,
      "name": "Rock_Volcanic_Brick"
    },
    {
      "x": -2,
      "y": 5,
      "z": 2,
      "name": "Rock_Volcanic_Brick_Half",
      "rotation": 7
    },
    {
      "x": -2,
      "y": 11,
      "z": 2,
      "name": "Rock_Volcanic_Brick_Half",
      "rotation": 7
    },
    {
      "x": -2,
      "y": 24,
      "z": 2,
      "name": "Rock_Volcanic_Brick_Wall",
      "rotation": 2
    },
    {
      "x": -2,
      "y": 25,
      "z": 2,
      "name": "Rock_Volcanic_Brick_Pillar_Middle",
      "rotation": 7
    },
    {
      "x": -2,
      "y": 0,
      "z": 3,
      "name": "Rock_Volcanic_Cobble"
    },
    {
      "x": -2,
      "y": 1,
      "z": 3,
      "name": "Rock_Volcanic_Cobble"
    },
    {
      "x": -2,
      "y": 2,
      "z": 3,
      "name": "Rock_Volcanic_Brick"
    },
    {
      "x": -2,
      "y": 3,
      "z": 3,
      "name": "Soil_Volcanic_Gravel"
    },
    {
      "x": -2,
      "y": 4,
      "z": 3,
      "name": "Soil_Volcanic_Gravel"
    },
    {
      "x": -2,
      "y": 5,
      "z": 3,
      "name": "Rock_Volcanic_Brick_Half",
      "rotation": 7
    },
    {
      "x": -2,
      "y": 11,
      "z": 3,
      "name": "Rock_Volcanic_Brick_Half",
      "rotation": 7
    },
    {
      "x": -2,
      "y": 21,
      "z": 3,
      "name": "Rock_Volcanic_Brick_Half",
      "rotation": 7
    },
    {
      "x": -2,
      "y": 22,
      "z": 3,
      "name": "Rock_Volcanic_Brick_Half",
      "rotation": 7
    },
    {
      "x": -2,
      "y": 23,
      "z": 3,
      "name": "Rock_Volcanic_Brick_Stairs",
      "rotation": 9
    },
    {
      "x": -2,
      "y": 24,
      "z": 3,
      "name": "Rock_Volcanic_Brick"
    },
    {
      "x": -2,
      "y": 25,
      "z": 3,
      "name": "Rock_Volcanic_Brick"
    },
    {
      "x": -2,
      "y": 0,
      "z": 4,
      "name": "Rock_Volcanic_Brick"
    },
    {
      "x": -2,
      "y": 1,
      "z": 4,
      "name": "Rock_Volcanic_Brick"
    },
    {
      "x": -2,
      "y": 2,
      "z": 4,
      "name": "Soil_Volcanic_Gravel"
    },
    {
      "x": -2,
      "y": 3,
      "z": 4,
      "name": "Rock_Volcanic_Brick"
    },
    {
      "x": -2,
      "y": 4,
      "z": 4,
      "name": "Rock_Volcanic_Cobble"
    },
    {
      "x": -2,
      "y": 5,
      "z": 4,
      "name": "Rock_Volcanic_Brick_Half",
      "rotation": 7
    },
    {
      "x": -2,
      "y": 11,
      "z": 4,
      "name": "Rock_Volcanic_Brick_Half",
      "rotation": 7
    },
    {
      "x": -2,
      "y": 25,
      "z": 4,
      "name": "Rock_Volcanic_Brick_Stairs",
      "rotation": 10
    },
    {
      "x": -2,
      "y": 26,
      "z": 4,
      "name": "Rock_Volcanic_Brick"
    },
    {
      "x": -2,
      "y": 27,
      "z": 4,
      "name": "Rock_Volcanic_Brick_Stairs"
    },
    {
      "x": -2,
      "y": 0,
      "z": 5,
      "name": "Soil_Volcanic_Gravel"
    },
    {
      "x": -2,
      "y": 1,
      "z": 5,
      "name": "Rock_Volcanic_Brick"
    },
    {
      "x": -2,
      "y": 2,
      "z": 5,
      "name": "Rock_Volcanic_Cobble"
    },
    {
      "x": -2,
      "y": 3,
      "z": 5,
      "name": "Soil_Volcanic_Gravel"
    },
    {
      "x": -2,
      "y": 4,
      "z": 5,
      "name": "Rock_Volcanic_Brick_Half"
    },
    {
      "x": -1,
      "y": 0,
      "z": -4,
      "name": "Rock_Volcanic_Brick"
    },
    {
      "x": -1,
      "y": 1,
      "z": -4,
      "name": "Soil_Volcanic_Gravel"
    },
    {
      "x": -1,
      "y": 2,
      "z": -4,
      "name": "Rock_Volcanic_Cobble"
    },
    {
      "x": -1,
      "y": 3,
      "z": -4,
      "name": "Rock_Volcanic_Brick"
    },
    {
      "x": -1,
      "y": 4,
      "z": -4,
      "name": "Rock_Volcanic_Brick"
    },
    {
      "x": -1,
      "y": 5,
      "z": -4,
      "name": "Rock_Volcanic_Brick_Half",
      "rotation": 6
    },
    {
      "x": -1,
      "y": 11,
      "z": -4,
      "name": "Rock_Volcanic_Brick_Half",
      "rotation": 6
    },
    {
      "x": -1,
      "y": 0,
      "z": -3,
      "name": "Rock_Volcanic_Brick"
    },
    {
      "x": -1,
      "y": 1,
      "z": -3,
      "name": "Rock_Volcanic_Cobble"
    },
    {
      "x": -1,
      "y": 2,
      "z": -3,
      "name": "Rock_Volcanic_Cobble"
    },
    {
      "x": -1,
      "y": 3,
      "z": -3,
      "name": "Rock_Volcanic_Cobble"
    },
    {
      "x": -1,
      "y": 4,
      "z": -3,
      "name": "Rock_Volcanic_Cobble"
    },
    {
      "x": -1,
      "y": 5,
      "z": -3,
      "name": "Rock_Volcanic_Brick_Pillar_Middle"
    },
    {
      "x": -1,
      "y": 6,
      "z": -3,
      "name": "Rock_Volcanic_Brick_Ornate"
    },
    {
      "x": -1,
      "y": 7,
      "z": -3,
      "name": "Rock_Volcanic_Brick_Pillar_Middle",
      "rotation": 8
    },
    {
      "x": -1,
      "y": 8,
      "z": -3,
      "name": "Rock_Volcanic_Brick_Pillar_Middle",
      "rotation": 8
    },
    {
      "x": -1,
      "y": 9,
      "z": -3,
      "name": "Rock_Volcanic_Brick_Pillar_Middle",
      "rotation": 8
    },
    {
      "x": -1,
      "y": 10,
      "z": -3,
      "name": "Rock_Volcanic_Brick_Pillar_Middle",
      "rotation": 8
    },
    {
      "x": -1,
      "y": 11,
      "z": -3,
      "name": "Rock_Volcanic_Brick_Pillar_Middle",
      "rotation": 8
    },
    {
      "x": -1,
      "y": 12,
      "z": -3,
      "name": "Rock_Volcanic_Brick_Ornate"
    },
    {
      "x": -1,
      "y": 13,
      "z": -3,
      "name": "Rock_Volcanic_Brick_Pillar_Base"
    },
    {
      "x": -1,
      "y": 24,
      "z": -3,
      "name": "Rock_Volcanic_Brick_Pillar_Base",
      "rotation": 7
    },
    {
      "x": -1,
      "y": 25,
      "z": -3,
      "name": "Rock_Volcanic_Brick_Stairs",
      "rotation": 34
    },
    {
      "x": -1,
      "y": 26,
      "z": -3,
      "name": "Rock_Volcanic_Brick_Wall",
      "rotation": 2
    },
    {
      "x": -1,
      "y": 0,
      "z": -2,
      "name": "Soil_Volcanic_Gravel"
    },
    {
      "x": -1,
      "y": 1,
      "z": -2,
      "name": "Soil_Volcanic_Gravel"
    },
    {
      "x": -1,
      "y": 2,
      "z": -2,
      "name": "Rock_Volcanic_Brick"
    },
    {
      "x": -1,
      "y": 3,
      "z": -2,
      "name": "Soil_Volcanic_Gravel"
    },
    {
      "x": -1,
      "y": 4,
      "z": -2,
      "name": "Rock_Volcanic_Brick"
    },
    {
      "x": -1,
      "y": 5,
      "z": -2,
      "name": "Rock_Volcanic_Brick_Pillar_Base",
      "rotation": 8
    },
    {
      "x": -1,
      "y": 6,
      "z": -2,
      "name": "Rock_Volcanic_Brick_Pillar_Base"
    },
    {
      "x": -1,
      "y": 7,
      "z": -2,
      "name": "Rock_Volcanic_Brick_Pillar_Middle"
    },
    {
      "x": -1,
      "y": 8,
      "z": -2,
      "name": "Rock_Volcanic_Brick_Pillar_Base",
      "rotation": 8
    },
    {
      "x": -1,
      "y": 9,
      "z": -2,
      "name": "Rock_Volcanic_Brick_Pillar_Base"
    },
    {
      "x": -1,
      "y": 10,
      "z": -2,
      "name": "Rock_Volcanic_Brick_Pillar_Middle"
    },
    {
      "x": -1,
      "y": 11,
      "z": -2,
      "name": "Rock_Volcanic_Brick_Pillar_Base",
      "rotation": 8
    },
    {
      "x": -1,
      "y": 12,
      "z": -2,
      "name": "Rock_Volcanic_Brick_Pillar_Base"
    },
    {
      "x": -1,
      "y": 13,
      "z": -2,
      "name": "Rock_Volcanic_Brick_Pillar_Middle"
    },
    {
      "x": -1,
      "y": 14,
      "z": -2,
      "name": "Rock_Volcanic_Brick_Pillar_Base",
      "rotation": 8
    },
    {
      "x": -1,
      "y": 15,
      "z": -2,
      "name": "Rock_Volcanic_Brick_Pillar_Base"
    },
    {
      "x": -1,
      "y": 16,
      "z": -2,
      "name": "Rock_Volcanic_Brick_Pillar_Middle"
    },
    {
      "x": -1,
      "y": 17,
      "z": -2,
      "name": "Rock_Volcanic_Brick_Pillar_Base",
      "rotation": 8
    },
    {
      "x": -1,
      "y": 18,
      "z": -2,
      "name": "Rock_Volcanic_Brick_Pillar_Base"
    },
    {
      "x": -1,
      "y": 19,
      "z": -2,
      "name": "Rock_Volcanic_Brick_Pillar_Middle"
    },
    {
      "x": -1,
      "y": 20,
      "z": -2,
      "name": "Rock_Volcanic_Brick_Pillar_Base",
      "rotation": 8
    },
    {
      "x": -1,
      "y": 21,
      "z": -2,
      "name": "Rock_Volcanic_Brick_Pillar_Base"
    },
    {
      "x": -1,
      "y": 22,
      "z": -2,
      "name": "Rock_Volcanic_Brick_Pillar_Middle"
    },
    {
      "x": -1,
      "y": 23,
      "z": -2,
      "name": "Rock_Volcanic_Brick_Pillar_Base",
      "rotation": 8
    },
    {
      "x": -1,
      "y": 24,
      "z": -2,
      "name": "Rock_Volcanic_Brick_Pillar_Base",
      "rotation": 2
    },
    {
      "x": -1,
      "y": 25,
      "z": -2,
      "name": "Rock_Volcanic_Brick_Pillar_Base",
      "rotation": 32
    },
    {
      "x": -1,
      "y": 0,
      "z": -1,
      "name": "Rock_Volcanic_Cobble"
    },
    {
      "x": -1,
      "y": 1,
      "z": -1,
      "name": "Rock_Volcanic_Brick"
    },
    {
      "x": -1,
      "y": 2,
      "z": -1,
      "name": "Soil_Volcanic_Gravel"
    },
    {
      "x": -1,
      "y": 3,
      "z": -1,
      "name": "Rock_Volcanic_Cobble"
    },
    {
      "x": -1,
      "y": 4,
      "z": -1,
      "name": "Rock_Volcanic_Brick"
    },
    {
      "x": -1,
      "y": 5,
      "z": -1,
      "name": "Rock_Volcanic_Brick_Pillar_Middle"
    },
    {
      "x": -1,
      "y": 6,
      "z": -1,
      "name": "Rock_Volcanic_Brick_Ornate"
    },
    {
      "x": -1,
      "y": 7,
      "z": -1,
      "name": "Rock_Volcanic_Brick_Pillar_Middle",
      "rotation": 8
    },
    {
      "x": -1,
      "y": 8,
      "z": -1,
      "name": "Rock_Volcanic_Brick_Pillar_Middle",
      "rotation": 8
    },
    {
      "x": -1,
      "y": 9,
      "z": -1,
      "name": "Rock_Volcanic_Brick_Pillar_Middle",
      "rotation": 8
    },
    {
      "x": -1,
      "y": 10,
      "z": -1,
      "name": "Rock_Volcanic_Brick_Pillar_Middle",
      "rotation": 8
    },
    {
      "x": -1,
      "y": 11,
      "z": -1,
      "name": "Rock_Volcanic_Brick_Pillar_Middle",
      "rotation": 8
    },
    {
      "x": -1,
      "y": 12,
      "z": -1,
      "name": "Rock_Volcanic_Brick_Ornate"
    },
    {
      "x": -1,
      "y": 13,
      "z": -1,
      "name": "Rock_Volcanic_Brick_Pillar_Base"
    },
    {
      "x": -1,
      "y": 24,
      "z": -1,
      "name": "Rock_Volcanic_Brick_Wall"
    },
    {
      "x": -1,
      "y": 25,
      "z": -1,
      "name": "Rock_Volcanic_Brick_Pillar_Middle",
      "rotation": 7
    },
    {
      "x": -1,
      "y": 0,
      "z": 0,
      "name": "Rock_Volcanic_Brick"
    },
    {
      "x": -1,
      "y": 1,
      "z": 0,
      "name": "Soil_Volcanic_Gravel"
    },
    {
      "x": -1,
      "y": 2,
      "z": 0,
      "name": "Rock_Volcanic_Brick"
    },
    {
      "x": -1,
      "y": 3,
      "z": 0,
      "name": "Rock_Volcanic_Brick"
    },
    {
      "x": -1,
      "y": 4,
      "z": 0,
      "name": "Rock_Volcanic_Cobble"
    },
    {
      "x": -1,
      "y": 5,
      "z": 0,
      "name": "Rock_Volcanic_Brick_Half",
      "rotation": 4
    },
    {
      "x": -1,
      "y": 11,
      "z": 0,
      "name": "Rock_Volcanic_Brick_Half",
      "rotation": 4
    },
    {
      "x": -1,
      "y": 24,
      "z": 0,
      "name": "Rock_Volcanic_Brick_Pillar_Base",
      "rotation": 7
    },
    {
      "x": -1,
      "y": 25,
      "z": 0,
      "name": "Rock_Volcanic_Brick"
    },
    {
      "x": -1,
      "y": 0,
      "z": 1,
      "name": "Rock_Volcanic_Cobble"
    },
    {
      "x": -1,
      "y": 1,
      "z": 1,
      "name": "Rock_Volcanic_Cobble"
    },
    {
      "x": -1,
      "y": 2,
      "z": 1,
      "name": "Soil_Volcanic_Gravel"
    },
    {
      "x": -1,
      "y": 3,
      "z": 1,
      "name": "Rock_Volcanic_Brick"
    },
    {
      "x": -1,
      "y": 4,
      "z": 1,
      "name": "Rock_Volcanic_Cobble"
    },
    {
      "x": -1,
      "y": 5,
      "z": 1,
      "name": "Rock_Volcanic_Brick_Half",
      "rotation": 6
    },
    {
      "x": -1,
      "y": 11,
      "z": 1,
      "name": "Rock_Volcanic_Brick_Half",
      "rotation": 6
    },
    {
      "x": -1,
      "y": 24,
      "z": 1,
      "name": "Rock_Volcanic_Brick_Pillar_Base",
      "rotation": 7
    },
    {
      "x": -1,
      "y": 25,
      "z": 1,
      "name": "Rock_Volcanic_Brick"
    },
    {
      "x": -1,
      "y": 0,
      "z": 2,
      "name": "Soil_Volcanic_Gravel"
    },
    {
      "x": -1,
      "y": 1,
      "z": 2,
      "name": "Rock_Volcanic_Cobble"
    },
    {
      "x": -1,
      "y": 2,
      "z": 2,
      "name": "Rock_Volcanic_Brick"
    },
    {
      "x": -1,
      "y": 3,
      "z": 2,
      "name": "Rock_Volcanic_Cobble"
    },
    {
      "x": -1,
      "y": 4,
      "z": 2,
      "name": "Rock_Volcanic_Brick"
    },
    {
      "x": -1,
      "y": 5,
      "z": 2,
      "name": "Rock_Volcanic_Brick_Pillar_Middle"
    },
    {
      "x": -1,
      "y": 6,
      "z": 2,
      "name": "Rock_Volcanic_Brick_Ornate"
    },
    {
      "x": -1,
      "y": 7,
      "z": 2,
      "name": "Rock_Volcanic_Brick_Pillar_Middle",
      "rotation": 8
    },
    {
      "x": -1,
      "y": 8,
      "z": 2,
      "name": "Rock_Volcanic_Brick_Pillar_Middle",
      "rotation": 8
    },
    {
      "x": -1,
      "y": 9,
      "z": 2,
      "name": "Rock_Volcanic_Brick_Pillar_Middle",
      "rotation": 8
    },
    {
      "x": -1,
      "y": 10,
      "z": 2,
      "name": "Rock_Volcanic_Brick_Pillar_Middle",
      "rotation": 8
    },
    {
      "x": -1,
      "y": 11,
      "z": 2,
      "name": "Rock_Volcanic_Brick_Pillar_Middle",
      "rotation": 8
    },
    {
      "x": -1,
      "y": 12,
      "z": 2,
      "name": "Rock_Volcanic_Brick_Ornate"
    },
    {
      "x": -1,
      "y": 13,
      "z": 2,
      "name": "Rock_Volcanic_Brick_Pillar_Base"
    },
    {
      "x": -1,
      "y": 24,
      "z": 2,
      "name": "Rock_Volcanic_Brick_Wall",
      "rotation": 2
    },
    {
      "x": -1,
      "y": 25,
      "z": 2,
      "name": "Rock_Volcanic_Brick_Pillar_Middle",
      "rotation": 7
    },
    {
      "x": -1,
      "y": 0,
      "z": 3,
      "name": "Rock_Volcanic_Brick"
    },
    {
      "x": -1,
      "y": 1,
      "z": 3,
      "name": "Soil_Volcanic_Gravel"
    },
    {
      "x": -1,
      "y": 2,
      "z": 3,
      "name": "Rock_Volcanic_Brick"
    },
    {
      "x": -1,
      "y": 3,
      "z": 3,
      "name": "Soil_Volcanic_Gravel"
    },
    {
      "x": -1,
      "y": 4,
      "z": 3,
      "name": "Soil_Volcanic_Gravel"
    },
    {
      "x": -1,
      "y": 5,
      "z": 3,
      "name": "Rock_Volcanic_Brick_Pillar_Base",
      "rotation": 8
    },
    {
      "x": -1,
      "y": 6,
      "z": 3,
      "name": "Rock_Volcanic_Brick_Pillar_Base"
    },
    {
      "x": -1,
      "y": 7,
      "z": 3,
      "name": "Rock_Volcanic_Brick_Pillar_Middle"
    },
    {
      "x": -1,
      "y": 8,
      "z": 3,
      "name": "Rock_Volcanic_Brick_Pillar_Base",
      "rotation": 8
    },
    {
      "x": -1,
      "y": 9,
      "z": 3,
      "name": "Rock_Volcanic_Brick_Pillar_Base"
    },
    {
      "x": -1,
      "y": 10,
      "z": 3,
      "name": "Rock_Volcanic_Brick_Pillar_Middle"
    },
    {
      "x": -1,
      "y": 11,
      "z": 3,
      "name": "Rock_Volcanic_Brick_Pillar_Base",
      "rotation": 8
    },
    {
      "x": -1,
      "y": 12,
      "z": 3,
      "name": "Rock_Volcanic_Brick_Pillar_Base"
    },
    {
      "x": -1,
      "y": 13,
      "z": 3,
      "name": "Rock_Volcanic_Brick_Pillar_Middle"
    },
    {
      "x": -1,
      "y": 14,
      "z": 3,
      "name": "Rock_Volcanic_Brick_Pillar_Base",
      "rotation": 8
    },
    {
      "x": -1,
      "y": 15,
      "z": 3,
      "name": "Rock_Volcanic_Brick_Pillar_Base"
    },
    {
      "x": -1,
      "y": 16,
      "z": 3,
      "name": "Rock_Volcanic_Brick_Pillar_Middle"
    },
    {
      "x": -1,
      "y": 17,
      "z": 3,
      "name": "Rock_Volcanic_Brick_Pillar_Base",
      "rotation": 8
    },
    {
      "x": -1,
      "y": 18,
      "z": 3,
      "name": "Rock_Volcanic_Brick_Pillar_Base"
    },
    {
      "x": -1,
      "y": 19,
      "z": 3,
      "name": "Rock_Volcanic_Brick_Pillar_Middle"
    },
    {
      "x": -1,
      "y": 20,
      "z": 3,
      "name": "Rock_Volcanic_Brick_Pillar_Base",
      "rotation": 8
    },
    {
      "x": -1,
      "y": 21,
      "z": 3,
      "name": "Rock_Volcanic_Brick_Pillar_Base"
    },
    {
      "x": -1,
      "y": 22,
      "z": 3,
      "name": "Rock_Volcanic_Brick_Pillar_Middle"
    },
    {
      "x": -1,
      "y": 23,
      "z": 3,
      "name": "Rock_Volcanic_Brick_Pillar_Base",
      "rotation": 8
    },
    {
      "x": -1,
      "y": 24,
      "z": 3,
      "name": "Rock_Volcanic_Brick_Pillar_Base"
    },
    {
      "x": -1,
      "y": 25,
      "z": 3,
      "name": "Rock_Volcanic_Brick_Pillar_Base",
      "rotation": 8
    },
    {
      "x": -1,
      "y": 0,
      "z": 4,
      "name": "Rock_Volcanic_Brick"
    },
    {
      "x": -1,
      "y": 1,
      "z": 4,
      "name": "Rock_Volcanic_Cobble"
    },
    {
      "x": -1,
      "y": 2,
      "z": 4,
      "name": "Soil_Volcanic_Gravel"
    },
    {
      "x": -1,
      "y": 3,
      "z": 4,
      "name": "Rock_Volcanic_Cobble"
    },
    {
      "x": -1,
      "y": 4,
      "z": 4,
      "name": "Soil_Volcanic_Gravel"
    },
    {
      "x": -1,
      "y": 5,
      "z": 4,
      "name": "Rock_Volcanic_Brick_Pillar_Middle"
    },
    {
      "x": -1,
      "y": 6,
      "z": 4,
      "name": "Rock_Volcanic_Brick_Ornate"
    },
    {
      "x": -1,
      "y": 7,
      "z": 4,
      "name": "Rock_Volcanic_Brick_Pillar_Middle",
      "rotation": 8
    },
    {
      "x": -1,
      "y": 8,
      "z": 4,
      "name": "Rock_Volcanic_Brick_Pillar_Middle",
      "rotation": 8
    },
    {
      "x": -1,
      "y": 9,
      "z": 4,
      "name": "Rock_Volcanic_Brick_Pillar_Middle",
      "rotation": 8
    },
    {
      "x": -1,
      "y": 10,
      "z": 4,
      "name": "Rock_Volcanic_Brick_Pillar_Middle",
      "rotation": 8
    },
    {
      "x": -1,
      "y": 11,
      "z": 4,
      "name": "Rock_Volcanic_Brick_Pillar_Middle",
      "rotation": 8
    },
    {
      "x": -1,
      "y": 12,
      "z": 4,
      "name": "Rock_Volcanic_Brick_Ornate"
    },
    {
      "x": -1,
      "y": 13,
      "z": 4,
      "name": "Rock_Volcanic_Brick_Pillar_Base"
    },
    {
      "x": -1,
      "y": 24,
      "z": 4,
      "name": "Rock_Volcanic_Brick_Pillar_Base",
      "rotation": 7
    },
    {
      "x": -1,
      "y": 25,
      "z": 4,
      "name": "Rock_Volcanic_Brick_Stairs",
      "rotation": 10
    },
    {
      "x": -1,
      "y": 26,
      "z": 4,
      "name": "Rock_Volcanic_Brick_Wall"
    },
    {
      "x": -1,
      "y": 0,
      "z": 5,
      "name": "Soil_Volcanic_Gravel"
    },
    {
      "x": -1,
      "y": 1,
      "z": 5,
      "name": "Soil_Volcanic_Gravel"
    },
    {
      "x": -1,
      "y": 2,
      "z": 5,
      "name": "Rock_Volcanic_Brick"
    },
    {
      "x": -1,
      "y": 3,
      "z": 5,
      "name": "Rock_Volcanic_Brick"
    },
    {
      "x": -1,
      "y": 4,
      "z": 5,
      "name": "Rock_Volcanic_Cobble"
    },
    {
      "x": -1,
      "y": 5,
      "z": 5,
      "name": "Rock_Volcanic_Brick_Half",
      "rotation": 4
    },
    {
      "x": -1,
      "y": 11,
      "z": 5,
      "name": "Rock_Volcanic_Brick_Half",
      "rotation": 4
    },
    {
      "x": 0,
      "y": 0,
      "z": -4,
      "name": "Rock_Volcanic_Brick"
    },
    {
      "x": 0,
      "y": 1,
      "z": -4,
      "name": "Soil_Volcanic_Gravel"
    },
    {
      "x": 0,
      "y": 2,
      "z": -4,
      "name": "Rock_Volcanic_Cobble"
    },
    {
      "x": 0,
      "y": 3,
      "z": -4,
      "name": "Rock_Volcanic_Brick"
    },
    {
      "x": 0,
      "y": 4,
      "z": -4,
      "name": "Rock_Volcanic_Brick"
    },
    {
      "x": 0,
      "y": 5,
      "z": -4,
      "name": "Rock_Volcanic_Brick_Half",
      "rotation": 6
    },
    {
      "x": 0,
      "y": 11,
      "z": -4,
      "name": "Rock_Volcanic_Brick_Half",
      "rotation": 6
    },
    {
      "x": 0,
      "y": 0,
      "z": -3,
      "name": "Rock_Volcanic_Brick"
    },
    {
      "x": 0,
      "y": 1,
      "z": -3,
      "name": "Soil_Volcanic_Gravel"
    },
    {
      "x": 0,
      "y": 2,
      "z": -3,
      "name": "Rock_Volcanic_Brick"
    },
    {
      "x": 0,
      "y": 3,
      "z": -3,
      "name": "Rock_Volcanic_Cobble"
    },
    {
      "x": 0,
      "y": 4,
      "z": -3,
      "name": "Rock_Volcanic_Cobble"
    },
    {
      "x": 0,
      "y": 5,
      "z": -3,
      "name": "Rock_Volcanic_Brick_Pillar_Base",
      "rotation": 8
    },
    {
      "x": 0,
      "y": 6,
      "z": -3,
      "name": "Rock_Volcanic_Brick_Pillar_Base"
    },
    {
      "x": 0,
      "y": 7,
      "z": -3,
      "name": "Rock_Volcanic_Brick_Pillar_Middle"
    },
    {
      "x": 0,
      "y": 8,
      "z": -3,
      "name": "Rock_Volcanic_Brick_Pillar_Base",
      "rotation": 8
    },
    {
      "x": 0,
      "y": 9,
      "z": -3,
      "name": "Rock_Volcanic_Brick_Pillar_Base"
    },
    {
      "x": 0,
      "y": 10,
      "z": -3,
      "name": "Rock_Volcanic_Brick_Pillar_Middle"
    },
    {
      "x": 0,
      "y": 11,
      "z": -3,
      "name": "Rock_Volcanic_Brick_Pillar_Base",
      "rotation": 8
    },
    {
      "x": 0,
      "y": 12,
      "z": -3,
      "name": "Rock_Volcanic_Brick_Pillar_Base"
    },
    {
      "x": 0,
      "y": 13,
      "z": -3,
      "name": "Rock_Volcanic_Brick_Pillar_Middle"
    },
    {
      "x": 0,
      "y": 14,
      "z": -3,
      "name": "Rock_Volcanic_Brick_Pillar_Base",
      "rotation": 8
    },
    {
      "x": 0,
      "y": 15,
      "z": -3,
      "name": "Rock_Volcanic_Brick_Pillar_Base"
    },
    {
      "x": 0,
      "y": 16,
      "z": -3,
      "name": "Rock_Volcanic_Brick_Pillar_Middle"
    },
    {
      "x": 0,
      "y": 17,
      "z": -3,
      "name": "Rock_Volcanic_Brick_Pillar_Base",
      "rotation": 8
    },
    {
      "x": 0,
      "y": 18,
      "z": -3,
      "name": "Rock_Volcanic_Brick_Pillar_Base"
    },
    {
      "x": 0,
      "y": 19,
      "z": -3,
      "name": "Rock_Volcanic_Brick_Pillar_Middle"
    },
    {
      "x": 0,
      "y": 20,
      "z": -3,
      "name": "Rock_Volcanic_Brick_Pillar_Base",
      "rotation": 8
    },
    {
      "x": 0,
      "y": 21,
      "z": -3,
      "name": "Rock_Volcanic_Brick_Pillar_Base"
    },
    {
      "x": 0,
      "y": 22,
      "z": -3,
      "name": "Rock_Volcanic_Brick_Pillar_Middle"
    },
    {
      "x": 0,
      "y": 23,
      "z": -3,
      "name": "Rock_Volcanic_Brick_Pillar_Base",
      "rotation": 8
    },
    {
      "x": 0,
      "y": 24,
      "z": -3,
      "name": "Rock_Volcanic_Brick_Ornate",
      "rotation": 2
    },
    {
      "x": 0,
      "y": 25,
      "z": -3,
      "name": "Rock_Volcanic_Brick_Pillar_Base",
      "rotation": 32
    },
    {
      "x": 0,
      "y": 26,
      "z": -3,
      "name": "Rock_Volcanic_Brick_Wall",
      "rotation": 2
    },
    {
      "x": 0,
      "y": 0,
      "z": -2,
      "name": "Rock_Volcanic_Brick"
    },
    {
      "x": 0,
      "y": 1,
      "z": -2,
      "name": "Rock_Volcanic_Brick"
    },
    {
      "x": 0,
      "y": 2,
      "z": -2,
      "name": "Soil_Volcanic_Gravel"
    },
    {
      "x": 0,
      "y": 3,
      "z": -2,
      "name": "Soil_Volcanic_Gravel"
    },
    {
      "x": 0,
      "y": 4,
      "z": -2,
      "name": "Rock_Volcanic_Brick"
    },
    {
      "x": 0,
      "y": 5,
      "z": -2,
      "name": "Rock_Volcanic_Brick"
    },
    {
      "x": 0,
      "y": 6,
      "z": -2,
      "name": "Rock_Volcanic_Brick"
    },
    {
      "x": 0,
      "y": 7,
      "z": -2,
      "name": "Rock_Volcanic_Brick"
    },
    {
      "x": 0,
      "y": 8,
      "z": -2,
      "name": "Rock_Volcanic_Brick"
    },
    {
      "x": 0,
      "y": 9,
      "z": -2,
      "name": "Rock_Volcanic_Brick"
    },
    {
      "x": 0,
      "y": 10,
      "z": -2,
      "name": "Rock_Volcanic_Brick"
    },
    {
      "x": 0,
      "y": 11,
      "z": -2,
      "name": "Rock_Volcanic_Brick"
    },
    {
      "x": 0,
      "y": 12,
      "z": -2,
      "name": "Rock_Volcanic_Brick"
    },
    {
      "x": 0,
      "y": 13,
      "z": -2,
      "name": "Rock_Volcanic_Brick"
    },
    {
      "x": 0,
      "y": 14,
      "z": -2,
      "name": "Rock_Volcanic_Brick"
    },
    {
      "x": 0,
      "y": 15,
      "z": -2,
      "name": "Rock_Volcanic_Brick"
    },
    {
      "x": 0,
      "y": 16,
      "z": -2,
      "name": "Rock_Volcanic_Brick"
    },
    {
      "x": 0,
      "y": 17,
      "z": -2,
      "name": "Rock_Volcanic_Brick"
    },
    {
      "x": 0,
      "y": 18,
      "z": -2,
      "name": "Rock_Volcanic_Brick"
    },
    {
      "x": 0,
      "y": 19,
      "z": -2,
      "name": "Rock_Volcanic_Brick"
    },
    {
      "x": 0,
      "y": 20,
      "z": -2,
      "name": "Rock_Volcanic_Brick"
    },
    {
      "x": 0,
      "y": 21,
      "z": -2,
      "name": "Rock_Volcanic_Brick"
    },
    {
      "x": 0,
      "y": 22,
      "z": -2,
      "name": "Rock_Volcanic_Brick"
    },
    {
      "x": 0,
      "y": 23,
      "z": -2,
      "name": "Rock_Volcanic_Brick"
    },
    {
      "x": 0,
      "y": 24,
      "z": -2,
      "name": "Rock_Volcanic_Brick",
      "rotation": 2
    },
    {
      "x": 0,
      "y": 25,
      "z": -2,
      "name": "Rock_Volcanic_Brick",
      "rotation": 2
    },
    {
      "x": 0,
      "y": 0,
      "z": -1,
      "name": "Rock_Volcanic_Cobble"
    },
    {
      "x": 0,
      "y": 1,
      "z": -1,
      "name": "Soil_Volcanic_Gravel"
    },
    {
      "x": 0,
      "y": 2,
      "z": -1,
      "name": "Rock_Volcanic_Brick"
    },
    {
      "x": 0,
      "y": 3,
      "z": -1,
      "name": "Soil_Volcanic_Gravel"
    },
    {
      "x": 0,
      "y": 4,
      "z": -1,
      "name": "Rock_Volcanic_Cobble"
    },
    {
      "x": 0,
      "y": 5,
      "z": -1,
      "name": "Rock_Volcanic_Brick_Pillar_Base",
      "rotation": 8
    },
    {
      "x": 0,
      "y": 6,
      "z": -1,
      "name": "Rock_Volcanic_Brick_Pillar_Base"
    },
    {
      "x": 0,
      "y": 7,
      "z": -1,
      "name": "Rock_Volcanic_Brick_Pillar_Middle"
    },
    {
      "x": 0,
      "y": 8,
      "z": -1,
      "name": "Rock_Volcanic_Brick_Pillar_Base",
      "rotation": 8
    },
    {
      "x": 0,
      "y": 9,
      "z": -1,
      "name": "Rock_Volcanic_Brick_Pillar_Base"
    },
    {
      "x": 0,
      "y": 10,
      "z": -1,
      "name": "Rock_Volcanic_Brick_Pillar_Middle"
    },
    {
      "x": 0,
      "y": 11,
      "z": -1,
      "name": "Rock_Volcanic_Brick_Pillar_Base",
      "rotation": 8
    },
    {
      "x": 0,
      "y": 12,
      "z": -1,
      "name": "Rock_Volcanic_Brick_Pillar_Base"
    },
    {
      "x": 0,
      "y": 13,
      "z": -1,
      "name": "Rock_Volcanic_Brick_Pillar_Middle"
    },
    {
      "x": 0,
      "y": 14,
      "z": -1,
      "name": "Rock_Volcanic_Brick_Pillar_Base",
      "rotation": 8
    },
    {
      "x": 0,
      "y": 15,
      "z": -1,
      "name": "Rock_Volcanic_Brick_Pillar_Base"
    },
    {
      "x": 0,
      "y": 16,
      "z": -1,
      "name": "Rock_Volcanic_Brick_Pillar_Middle"
    },
    {
      "x": 0,
      "y": 17,
      "z": -1,
      "name": "Rock_Volcanic_Brick_Pillar_Base",
      "rotation": 8
    },
    {
      "x": 0,
      "y": 18,
      "z": -1,
      "name": "Rock_Volcanic_Brick_Pillar_Base"
    },
    {
      "x": 0,
      "y": 19,
      "z": -1,
      "name": "Rock_Volcanic_Brick_Pillar_Middle"
    },
    {
      "x": 0,
      "y": 20,
      "z": -1,
      "name": "Rock_Volcanic_Brick_Ornate"
    },
    {
      "x": 0,
      "y": 21,
      "z": -1,
      "name": "Rock_Volcanic_Brick_Pillar_Base"
    },
    {
      "x": 0,
      "y": 22,
      "z": -1,
      "name": "Rock_Volcanic_Brick_Pillar_Middle"
    },
    {
      "x": 0,
      "y": 23,
      "z": -1,
      "name": "Rock_Volcanic_Brick_Ornate"
    },
    {
      "x": 0,
      "y": 24,
      "z": -1,
      "name": "Rock_Volcanic_Brick_Pillar_Base"
    },
    {
      "x": 0,
      "y": 25,
      "z": -1,
      "name": "Rock_Volcanic_Brick_Pillar_Middle",
      "rotation": 7
    },
    {
      "x": 0,
      "y": 0,
      "z": 0,
      "name": "Rock_Volcanic_Brick"
    },
    {
      "x": 0,
      "y": 1,
      "z": 0,
      "name": "Rock_Volcanic_Cobble"
    },
    {
      "x": 0,
      "y": 2,
      "z": 0,
      "name": "Rock_Volcanic_Cobble"
    },
    {
      "x": 0,
      "y": 3,
      "z": 0,
      "name": "Rock_Volcanic_Brick"
    },
    {
      "x": 0,
      "y": 4,
      "z": 0,
      "name": "Soil_Volcanic_Gravel"
    },
    {
      "x": 0,
      "y": 5,
      "z": 0,
      "name": "Rock_Volcanic_Brick_Half",
      "rotation": 4
    },
    {
      "x": 0,
      "y": 11,
      "z": 0,
      "name": "Rock_Volcanic_Brick_Half",
      "rotation": 4
    },
    {
      "x": 0,
      "y": 20,
      "z": 0,
      "name": "Rock_Volcanic_Brick_Pillar_Base",
      "rotation": 4
    },
    {
      "x": 0,
      "y": 23,
      "z": 0,
      "name": "Rock_Volcanic_Brick_Pillar_Base",
      "rotation": 4
    },
    {
      "x": 0,
      "y": 24,
      "z": 0,
      "name": "Rock_Volcanic_Brick_Ornate"
    },
    {
      "x": 0,
      "y": 25,
      "z": 0,
      "name": "Rock_Volcanic_Brick"
    },
    {
      "x": 0,
      "y": 0,
      "z": 1,
      "name": "Rock_Volcanic_Cobble"
    },
    {
      "x": 0,
      "y": 1,
      "z": 1,
      "name": "Rock_Volcanic_Cobble"
    },
    {
      "x": 0,
      "y": 2,
      "z": 1,
      "name": "Rock_Volcanic_Brick"
    },
    {
      "x": 0,
      "y": 3,
      "z": 1,
      "name": "Rock_Volcanic_Cobble"
    },
    {
      "x": 0,
      "y": 4,
      "z": 1,
      "name": "Rock_Volcanic_Cobble"
    },
    {
      "x": 0,
      "y": 5,
      "z": 1,
      "name": "Rock_Volcanic_Brick_Half",
      "rotation": 6
    },
    {
      "x": 0,
      "y": 11,
      "z": 1,
      "name": "Rock_Volcanic_Brick_Half",
      "rotation": 6
    },
    {
      "x": 0,
      "y": 20,
      "z": 1,
      "name": "Rock_Volcanic_Brick_Pillar_Base",
      "rotation": 6
    },
    {
      "x": 0,
      "y": 23,
      "z": 1,
      "name": "Rock_Volcanic_Brick_Pillar_Base",
      "rotation": 6
    },
    {
      "x": 0,
      "y": 24,
      "z": 1,
      "name": "Rock_Volcanic_Brick_Ornate"
    },
    {
      "x": 0,
      "y": 25,
      "z": 1,
      "name": "Rock_Volcanic_Brick"
    },
    {
      "x": 0,
      "y": 0,
      "z": 2,
      "name": "Rock_Volcanic_Cobble"
    },
    {
      "x": 0,
      "y": 1,
      "z": 2,
      "name": "Rock_Volcanic_Brick"
    },
    {
      "x": 0,
      "y": 2,
      "z": 2,
      "name": "Rock_Volcanic_Brick"
    },
    {
      "x": 0,
      "y": 3,
      "z": 2,
      "name": "Rock_Volcanic_Cobble"
    },
    {
      "x": 0,
      "y": 4,
      "z": 2,
      "name": "Rock_Volcanic_Brick"
    },
    {
      "x": 0,
      "y": 5,
      "z": 2,
      "name": "Rock_Volcanic_Brick_Pillar_Base",
      "rotation": 8
    },
    {
      "x": 0,
      "y": 6,
      "z": 2,
      "name": "Rock_Volcanic_Brick_Pillar_Base"
    },
    {
      "x": 0,
      "y": 7,
      "z": 2,
      "name": "Rock_Volcanic_Brick_Pillar_Middle"
    },
    {
      "x": 0,
      "y": 8,
      "z": 2,
      "name": "Rock_Volcanic_Brick_Pillar_Base",
      "rotation": 8
    },
    {
      "x": 0,
      "y": 9,
      "z": 2,
      "name": "Rock_Volcanic_Brick_Pillar_Base"
    },
    {
      "x": 0,
      "y": 10,
      "z": 2,
      "name": "Rock_Volcanic_Brick_Pillar_Middle"
    },
    {
      "x": 0,
      "y": 11,
      "z": 2,
      "name": "Rock_Volcanic_Brick_Pillar_Base",
      "rotation": 8
    },
    {
      "x": 0,
      "y": 12,
      "z": 2,
      "name": "Rock_Volcanic_Brick_Pillar_Base"
    },
    {
      "x": 0,
      "y": 13,
      "z": 2,
      "name": "Rock_Volcanic_Brick_Pillar_Middle"
    },
    {
      "x": 0,
      "y": 14,
      "z": 2,
      "name": "Rock_Volcanic_Brick_Pillar_Base",
      "rotation": 8
    },
    {
      "x": 0,
      "y": 15,
      "z": 2,
      "name": "Rock_Volcanic_Brick_Pillar_Base"
    },
    {
      "x": 0,
      "y": 16,
      "z": 2,
      "name": "Rock_Volcanic_Brick_Pillar_Middle"
    },
    {
      "x": 0,
      "y": 17,
      "z": 2,
      "name": "Rock_Volcanic_Brick_Pillar_Base",
      "rotation": 8
    },
    {
      "x": 0,
      "y": 18,
      "z": 2,
      "name": "Rock_Volcanic_Brick_Pillar_Base"
    },
    {
      "x": 0,
      "y": 19,
      "z": 2,
      "name": "Rock_Volcanic_Brick_Pillar_Middle"
    },
    {
      "x": 0,
      "y": 20,
      "z": 2,
      "name": "Rock_Volcanic_Brick_Ornate"
    },
    {
      "x": 0,
      "y": 21,
      "z": 2,
      "name": "Rock_Volcanic_Brick_Pillar_Base"
    },
    {
      "x": 0,
      "y": 22,
      "z": 2,
      "name": "Rock_Volcanic_Brick_Pillar_Middle"
    },
    {
      "x": 0,
      "y": 23,
      "z": 2,
      "name": "Rock_Volcanic_Brick_Ornate"
    },
    {
      "x": 0,
      "y": 24,
      "z": 2,
      "name": "Rock_Volcanic_Brick_Pillar_Base"
    },
    {
      "x": 0,
      "y": 25,
      "z": 2,
      "name": "Rock_Volcanic_Brick_Pillar_Middle",
      "rotation": 7
    },
    {
      "x": 0,
      "y": 0,
      "z": 3,
      "name": "Rock_Volcanic_Brick"
    },
    {
      "x": 0,
      "y": 1,
      "z": 3,
      "name": "Rock_Volcanic_Brick"
    },
    {
      "x": 0,
      "y": 2,
      "z": 3,
      "name": "Rock_Volcanic_Cobble"
    },
    {
      "x": 0,
      "y": 3,
      "z": 3,
      "name": "Rock_Volcanic_Cobble"
    },
    {
      "x": 0,
      "y": 4,
      "z": 3,
      "name": "Rock_Volcanic_Brick"
    },
    {
      "x": 0,
      "y": 5,
      "z": 3,
      "name": "Rock_Volcanic_Brick"
    },
    {
      "x": 0,
      "y": 6,
      "z": 3,
      "name": "Rock_Volcanic_Brick"
    },
    {
      "x": 0,
      "y": 7,
      "z": 3,
      "name": "Rock_Volcanic_Brick"
    },
    {
      "x": 0,
      "y": 8,
      "z": 3,
      "name": "Rock_Volcanic_Brick"
    },
    {
      "x": 0,
      "y": 9,
      "z": 3,
      "name": "Rock_Volcanic_Brick"
    },
    {
      "x": 0,
      "y": 10,
      "z": 3,
      "name": "Rock_Volcanic_Brick"
    },
    {
      "x": 0,
      "y": 11,
      "z": 3,
      "name": "Rock_Volcanic_Brick"
    },
    {
      "x": 0,
      "y": 12,
      "z": 3,
      "name": "Rock_Volcanic_Brick"
    },
    {
      "x": 0,
      "y": 13,
      "z": 3,
      "name": "Rock_Volcanic_Brick"
    },
    {
      "x": 0,
      "y": 14,
      "z": 3,
      "name": "Rock_Volcanic_Brick"
    },
    {
      "x": 0,
      "y": 15,
      "z": 3,
      "name": "Rock_Volcanic_Brick"
    },
    {
      "x": 0,
      "y": 16,
      "z": 3,
      "name": "Rock_Volcanic_Brick"
    },
    {
      "x": 0,
      "y": 17,
      "z": 3,
      "name": "Rock_Volcanic_Brick"
    },
    {
      "x": 0,
      "y": 18,
      "z": 3,
      "name": "Rock_Volcanic_Brick"
    },
    {
      "x": 0,
      "y": 19,
      "z": 3,
      "name": "Rock_Volcanic_Brick"
    },
    {
      "x": 0,
      "y": 20,
      "z": 3,
      "name": "Rock_Volcanic_Brick"
    },
    {
      "x": 0,
      "y": 21,
      "z": 3,
      "name": "Rock_Volcanic_Brick"
    },
    {
      "x": 0,
      "y": 22,
      "z": 3,
      "name": "Rock_Volcanic_Brick"
    },
    {
      "x": 0,
      "y": 23,
      "z": 3,
      "name": "Rock_Volcanic_Brick"
    },
    {
      "x": 0,
      "y": 24,
      "z": 3,
      "name": "Rock_Volcanic_Brick"
    },
    {
      "x": 0,
      "y": 25,
      "z": 3,
      "name": "Rock_Volcanic_Brick"
    },
    {
      "x": 0,
      "y": 0,
      "z": 4,
      "name": "Rock_Volcanic_Brick"
    },
    {
      "x": 0,
      "y": 1,
      "z": 4,
      "name": "Rock_Volcanic_Cobble"
    },
    {
      "x": 0,
      "y": 2,
      "z": 4,
      "name": "Rock_Volcanic_Brick"
    },
    {
      "x": 0,
      "y": 3,
      "z": 4,
      "name": "Rock_Volcanic_Cobble"
    },
    {
      "x": 0,
      "y": 4,
      "z": 4,
      "name": "Rock_Volcanic_Brick"
    },
    {
      "x": 0,
      "y": 5,
      "z": 4,
      "name": "Rock_Volcanic_Brick_Pillar_Base",
      "rotation": 8
    },
    {
      "x": 0,
      "y": 6,
      "z": 4,
      "name": "Rock_Volcanic_Brick_Pillar_Base"
    },
    {
      "x": 0,
      "y": 7,
      "z": 4,
      "name": "Rock_Volcanic_Brick_Pillar_Middle"
    },
    {
      "x": 0,
      "y": 8,
      "z": 4,
      "name": "Rock_Volcanic_Brick_Pillar_Base",
      "rotation": 8
    },
    {
      "x": 0,
      "y": 9,
      "z": 4,
      "name": "Rock_Volcanic_Brick_Pillar_Base"
    },
    {
      "x": 0,
      "y": 10,
      "z": 4,
      "name": "Rock_Volcanic_Brick_Pillar_Middle"
    },
    {
      "x": 0,
      "y": 11,
      "z": 4,
      "name": "Rock_Volcanic_Brick_Pillar_Base",
      "rotation": 8
    },
    {
      "x": 0,
      "y": 12,
      "z": 4,
      "name": "Rock_Volcanic_Brick_Pillar_Base"
    },
    {
      "x": 0,
      "y": 13,
      "z": 4,
      "name": "Rock_Volcanic_Brick_Pillar_Middle"
    },
    {
      "x": 0,
      "y": 14,
      "z": 4,
      "name": "Rock_Volcanic_Brick_Pillar_Base",
      "rotation": 8
    },
    {
      "x": 0,
      "y": 15,
      "z": 4,
      "name": "Rock_Volcanic_Brick_Pillar_Base"
    },
    {
      "x": 0,
      "y": 16,
      "z": 4,
      "name": "Rock_Volcanic_Brick_Pillar_Middle"
    },
    {
      "x": 0,
      "y": 17,
      "z": 4,
      "name": "Rock_Volcanic_Brick_Pillar_Base",
      "rotation": 8
    },
    {
      "x": 0,
      "y": 18,
      "z": 4,
      "name": "Rock_Volcanic_Brick_Pillar_Base"
    },
    {
      "x": 0,
      "y": 19,
      "z": 4,
      "name": "Rock_Volcanic_Brick_Pillar_Middle"
    },
    {
      "x": 0,
      "y": 20,
      "z": 4,
      "name": "Rock_Volcanic_Brick_Pillar_Base",
      "rotation": 8
    },
    {
      "x": 0,
      "y": 21,
      "z": 4,
      "name": "Rock_Volcanic_Brick_Pillar_Base"
    },
    {
      "x": 0,
      "y": 22,
      "z": 4,
      "name": "Rock_Volcanic_Brick_Pillar_Middle"
    },
    {
      "x": 0,
      "y": 23,
      "z": 4,
      "name": "Rock_Volcanic_Brick_Pillar_Base",
      "rotation": 8
    },
    {
      "x": 0,
      "y": 24,
      "z": 4,
      "name": "Rock_Volcanic_Brick_Ornate"
    },
    {
      "x": 0,
      "y": 25,
      "z": 4,
      "name": "Rock_Volcanic_Brick_Pillar_Base",
      "rotation": 8
    },
    {
      "x": 0,
      "y": 26,
      "z": 4,
      "name": "Rock_Volcanic_Brick_Wall"
    },
    {
      "x": 0,
      "y": 0,
      "z": 5,
      "name": "Soil_Volcanic_Gravel"
    },
    {
      "x": 0,
      "y": 1,
      "z": 5,
      "name": "Soil_Volcanic_Gravel"
    },
    {
      "x": 0,
      "y": 2,
      "z": 5,
      "name": "Rock_Volcanic_Brick"
    },
    {
      "x": 0,
      "y": 3,
      "z": 5,
      "name": "Rock_Volcanic_Cobble"
    },
    {
      "x": 0,
      "y": 4,
      "z": 5,
      "name": "Rock_Volcanic_Cobble"
    },
    {
      "x": 0,
      "y": 5,
      "z": 5,
      "name": "Rock_Volcanic_Brick_Half",
      "rotation": 4
    },
    {
      "x": 0,
      "y": 11,
      "z": 5,
      "name": "Rock_Volcanic_Brick_Half",
      "rotation": 4
    },
    {
      "x": 1,
      "y": 0,
      "z": -4,
      "name": "Rock_Volcanic_Brick"
    },
    {
      "x": 1,
      "y": 1,
      "z": -4,
      "name": "Rock_Volcanic_Brick"
    },
    {
      "x": 1,
      "y": 2,
      "z": -4,
      "name": "Soil_Volcanic_Gravel"
    },
    {
      "x": 1,
      "y": 3,
      "z": -4,
      "name": "Soil_Volcanic_Gravel"
    },
    {
      "x": 1,
      "y": 4,
      "z": -4,
      "name": "Rock_Volcanic_Brick"
    },
    {
      "x": 1,
      "y": 5,
      "z": -4,
      "name": "Rock_Volcanic_Brick_Half",
      "rotation": 6
    },
    {
      "x": 1,
      "y": 11,
      "z": -4,
      "name": "Rock_Volcanic_Brick_Half",
      "rotation": 6
    },
    {
      "x": 1,
      "y": 0,
      "z": -3,
      "name": "Rock_Volcanic_Brick"
    },
    {
      "x": 1,
      "y": 1,
      "z": -3,
      "name": "Rock_Volcanic_Cobble"
    },
    {
      "x": 1,
      "y": 2,
      "z": -3,
      "name": "Rock_Volcanic_Cobble"
    },
    {
      "x": 1,
      "y": 3,
      "z": -3,
      "name": "Rock_Volcanic_Brick"
    },
    {
      "x": 1,
      "y": 4,
      "z": -3,
      "name": "Rock_Volcanic_Cobble"
    },
    {
      "x": 1,
      "y": 5,
      "z": -3,
      "name": "Rock_Volcanic_Brick_Pillar_Middle"
    },
    {
      "x": 1,
      "y": 6,
      "z": -3,
      "name": "Rock_Volcanic_Brick_Ornate"
    },
    {
      "x": 1,
      "y": 7,
      "z": -3,
      "name": "Rock_Volcanic_Brick_Pillar_Middle",
      "rotation": 8
    },
    {
      "x": 1,
      "y": 8,
      "z": -3,
      "name": "Rock_Volcanic_Brick_Pillar_Middle",
      "rotation": 8
    },
    {
      "x": 1,
      "y": 9,
      "z": -3,
      "name": "Rock_Volcanic_Brick_Pillar_Middle",
      "rotation": 8
    },
    {
      "x": 1,
      "y": 10,
      "z": -3,
      "name": "Rock_Volcanic_Brick_Pillar_Middle",
      "rotation": 8
    },
    {
      "x": 1,
      "y": 11,
      "z": -3,
      "name": "Rock_Volcanic_Brick_Pillar_Middle",
      "rotation": 8
    },
    {
      "x": 1,
      "y": 12,
      "z": -3,
      "name": "Rock_Volcanic_Brick_Ornate"
    },
    {
      "x": 1,
      "y": 13,
      "z": -3,
      "name": "Rock_Volcanic_Brick_Pillar_Base"
    },
    {
      "x": 1,
      "y": 24,
      "z": -3,
      "name": "Rock_Volcanic_Brick_Pillar_Base",
      "rotation": 5
    },
    {
      "x": 1,
      "y": 25,
      "z": -3,
      "name": "Rock_Volcanic_Brick_Stairs",
      "rotation": 34
    },
    {
      "x": 1,
      "y": 26,
      "z": -3,
      "name": "Rock_Volcanic_Brick_Wall",
      "rotation": 2
    },
    {
      "x": 1,
      "y": 0,
      "z": -2,
      "name": "Rock_Volcanic_Cobble"
    },
    {
      "x": 1,
      "y": 1,
      "z": -2,
      "name": "Rock_Volcanic_Brick"
    },
    {
      "x": 1,
      "y": 2,
      "z": -2,
      "name": "Rock_Volcanic_Brick"
    },
    {
      "x": 1,
      "y": 3,
      "z": -2,
      "name": "Soil_Volcanic_Gravel"
    },
    {
      "x": 1,
      "y": 4,
      "z": -2,
      "name": "Rock_Volcanic_Brick"
    },
    {
      "x": 1,
      "y": 5,
      "z": -2,
      "name": "Rock_Volcanic_Brick_Pillar_Base",
      "rotation": 8
    },
    {
      "x": 1,
      "y": 6,
      "z": -2,
      "name": "Rock_Volcanic_Brick_Pillar_Base"
    },
    {
      "x": 1,
      "y": 7,
      "z": -2,
      "name": "Rock_Volcanic_Brick_Pillar_Middle"
    },
    {
      "x": 1,
      "y": 8,
      "z": -2,
      "name": "Rock_Volcanic_Brick_Pillar_Base",
      "rotation": 8
    },
    {
      "x": 1,
      "y": 9,
      "z": -2,
      "name": "Rock_Volcanic_Brick_Pillar_Base"
    },
    {
      "x": 1,
      "y": 10,
      "z": -2,
      "name": "Rock_Volcanic_Brick_Pillar_Middle"
    },
    {
      "x": 1,
      "y": 11,
      "z": -2,
      "name": "Rock_Volcanic_Brick_Pillar_Base",
      "rotation": 8
    },
    {
      "x": 1,
      "y": 12,
      "z": -2,
      "name": "Rock_Volcanic_Brick_Pillar_Base"
    },
    {
      "x": 1,
      "y": 13,
      "z": -2,
      "name": "Rock_Volcanic_Brick_Pillar_Middle"
    },
    {
      "x": 1,
      "y": 14,
      "z": -2,
      "name": "Rock_Volcanic_Brick_Pillar_Base",
      "rotation": 8
    },
    {
      "x": 1,
      "y": 15,
      "z": -2,
      "name": "Rock_Volcanic_Brick_Pillar_Base"
    },
    {
      "x": 1,
      "y": 16,
      "z": -2,
      "name": "Rock_Volcanic_Brick_Pillar_Middle"
    },
    {
      "x": 1,
      "y": 17,
      "z": -2,
      "name": "Rock_Volcanic_Brick_Pillar_Base",
      "rotation": 8
    },
    {
      "x": 1,
      "y": 18,
      "z": -2,
      "name": "Rock_Volcanic_Brick_Pillar_Base"
    },
    {
      "x": 1,
      "y": 19,
      "z": -2,
      "name": "Rock_Volcanic_Brick_Pillar_Middle"
    },
    {
      "x": 1,
      "y": 20,
      "z": -2,
      "name": "Rock_Volcanic_Brick_Pillar_Base",
      "rotation": 8
    },
    {
      "x": 1,
      "y": 21,
      "z": -2,
      "name": "Rock_Volcanic_Brick_Pillar_Base"
    },
    {
      "x": 1,
      "y": 22,
      "z": -2,
      "name": "Rock_Volcanic_Brick_Pillar_Middle"
    },
    {
      "x": 1,
      "y": 23,
      "z": -2,
      "name": "Rock_Volcanic_Brick_Pillar_Base",
      "rotation": 8
    },
    {
      "x": 1,
      "y": 24,
      "z": -2,
      "name": "Rock_Volcanic_Brick_Pillar_Base",
      "rotation": 2
    },
    {
      "x": 1,
      "y": 25,
      "z": -2,
      "name": "Rock_Volcanic_Brick_Pillar_Base",
      "rotation": 32
    },
    {
      "x": 1,
      "y": 0,
      "z": -1,
      "name": "Rock_Volcanic_Cobble"
    },
    {
      "x": 1,
      "y": 1,
      "z": -1,
      "name": "Soil_Volcanic_Gravel"
    },
    {
      "x": 1,
      "y": 2,
      "z": -1,
      "name": "Soil_Volcanic_Gravel"
    },
    {
      "x": 1,
      "y": 3,
      "z": -1,
      "name": "Soil_Volcanic_Gravel"
    },
    {
      "x": 1,
      "y": 4,
      "z": -1,
      "name": "Rock_Volcanic_Brick"
    },
    {
      "x": 1,
      "y": 5,
      "z": -1,
      "name": "Rock_Volcanic_Brick_Pillar_Middle"
    },
    {
      "x": 1,
      "y": 6,
      "z": -1,
      "name": "Rock_Volcanic_Brick_Ornate"
    },
    {
      "x": 1,
      "y": 7,
      "z": -1,
      "name": "Rock_Volcanic_Brick_Pillar_Middle",
      "rotation": 8
    },
    {
      "x": 1,
      "y": 8,
      "z": -1,
      "name": "Rock_Volcanic_Brick_Pillar_Middle",
      "rotation": 8
    },
    {
      "x": 1,
      "y": 9,
      "z": -1,
      "name": "Rock_Volcanic_Brick_Pillar_Middle",
      "rotation": 8
    },
    {
      "x": 1,
      "y": 10,
      "z": -1,
      "name": "Rock_Volcanic_Brick_Pillar_Middle",
      "rotation": 8
    },
    {
      "x": 1,
      "y": 11,
      "z": -1,
      "name": "Rock_Volcanic_Brick_Pillar_Middle",
      "rotation": 8
    },
    {
      "x": 1,
      "y": 12,
      "z": -1,
      "name": "Rock_Volcanic_Brick_Ornate"
    },
    {
      "x": 1,
      "y": 13,
      "z": -1,
      "name": "Rock_Volcanic_Brick_Pillar_Base"
    },
    {
      "x": 1,
      "y": 24,
      "z": -1,
      "name": "Rock_Volcanic_Brick_Wall"
    },
    {
      "x": 1,
      "y": 25,
      "z": -1,
      "name": "Rock_Volcanic_Brick_Pillar_Middle",
      "rotation": 7
    },
    {
      "x": 1,
      "y": 0,
      "z": 0,
      "name": "Rock_Volcanic_Brick"
    },
    {
      "x": 1,
      "y": 1,
      "z": 0,
      "name": "Rock_Volcanic_Brick"
    },
    {
      "x": 1,
      "y": 2,
      "z": 0,
      "name": "Rock_Volcanic_Brick"
    },
    {
      "x": 1,
      "y": 3,
      "z": 0,
      "name": "Rock_Volcanic_Brick"
    },
    {
      "x": 1,
      "y": 4,
      "z": 0,
      "name": "Rock_Volcanic_Brick"
    },
    {
      "x": 1,
      "y": 5,
      "z": 0,
      "name": "Rock_Volcanic_Brick_Half",
      "rotation": 4
    },
    {
      "x": 1,
      "y": 11,
      "z": 0,
      "name": "Rock_Volcanic_Brick_Half",
      "rotation": 4
    },
    {
      "x": 1,
      "y": 24,
      "z": 0,
      "name": "Rock_Volcanic_Brick_Pillar_Base",
      "rotation": 5
    },
    {
      "x": 1,
      "y": 25,
      "z": 0,
      "name": "Rock_Volcanic_Brick"
    },
    {
      "x": 1,
      "y": 0,
      "z": 1,
      "name": "Soil_Volcanic_Gravel"
    },
    {
      "x": 1,
      "y": 1,
      "z": 1,
      "name": "Rock_Volcanic_Brick"
    },
    {
      "x": 1,
      "y": 2,
      "z": 1,
      "name": "Rock_Volcanic_Brick"
    },
    {
      "x": 1,
      "y": 3,
      "z": 1,
      "name": "Rock_Volcanic_Cobble"
    },
    {
      "x": 1,
      "y": 4,
      "z": 1,
      "name": "Soil_Volcanic_Gravel"
    },
    {
      "x": 1,
      "y": 5,
      "z": 1,
      "name": "Rock_Volcanic_Brick_Half",
      "rotation": 6
    },
    {
      "x": 1,
      "y": 11,
      "z": 1,
      "name": "Rock_Volcanic_Brick_Half",
      "rotation": 6
    },
    {
      "x": 1,
      "y": 24,
      "z": 1,
      "name": "Rock_Volcanic_Brick_Pillar_Base",
      "rotation": 5
    },
    {
      "x": 1,
      "y": 25,
      "z": 1,
      "name": "Rock_Volcanic_Brick"
    },
    {
      "x": 1,
      "y": 0,
      "z": 2,
      "name": "Rock_Volcanic_Brick"
    },
    {
      "x": 1,
      "y": 1,
      "z": 2,
      "name": "Rock_Volcanic_Brick"
    },
    {
      "x": 1,
      "y": 2,
      "z": 2,
      "name": "Rock_Volcanic_Cobble"
    },
    {
      "x": 1,
      "y": 3,
      "z": 2,
      "name": "Rock_Volcanic_Cobble"
    },
    {
      "x": 1,
      "y": 4,
      "z": 2,
      "name": "Rock_Volcanic_Cobble"
    },
    {
      "x": 1,
      "y": 5,
      "z": 2,
      "name": "Rock_Volcanic_Brick_Pillar_Middle"
    },
    {
      "x": 1,
      "y": 6,
      "z": 2,
      "name": "Rock_Volcanic_Brick_Ornate"
    },
    {
      "x": 1,
      "y": 7,
      "z": 2,
      "name": "Rock_Volcanic_Brick_Pillar_Middle",
      "rotation": 8
    },
    {
      "x": 1,
      "y": 8,
      "z": 2,
      "name": "Rock_Volcanic_Brick_Pillar_Middle",
      "rotation": 8
    },
    {
      "x": 1,
      "y": 9,
      "z": 2,
      "name": "Rock_Volcanic_Brick_Pillar_Middle",
      "rotation": 8
    },
    {
      "x": 1,
      "y": 10,
      "z": 2,
      "name": "Rock_Volcanic_Brick_Pillar_Middle",
      "rotation": 8
    },
    {
      "x": 1,
      "y": 11,
      "z": 2,
      "name": "Rock_Volcanic_Brick_Pillar_Middle",
      "rotation": 8
    },
    {
      "x": 1,
      "y": 12,
      "z": 2,
      "name": "Rock_Volcanic_Brick_Ornate"
    },
    {
      "x": 1,
      "y": 13,
      "z": 2,
      "name": "Rock_Volcanic_Brick_Pillar_Base"
    },
    {
      "x": 1,
      "y": 24,
      "z": 2,
      "name": "Rock_Volcanic_Brick_Wall",
      "rotation": 2
    },
    {
      "x": 1,
      "y": 25,
      "z": 2,
      "name": "Rock_Volcanic_Brick_Pillar_Middle",
      "rotation": 7
    },
    {
      "x": 1,
      "y": 0,
      "z": 3,
      "name": "Rock_Volcanic_Cobble"
    },
    {
      "x": 1,
      "y": 1,
      "z": 3,
      "name": "Rock_Volcanic_Brick"
    },
    {
      "x": 1,
      "y": 2,
      "z": 3,
      "name": "Rock_Volcanic_Cobble"
    },
    {
      "x": 1,
      "y": 3,
      "z": 3,
      "name": "Rock_Volcanic_Brick"
    },
    {
      "x": 1,
      "y": 4,
      "z": 3,
      "name": "Soil_Volcanic_Gravel"
    },
    {
      "x": 1,
      "y": 5,
      "z": 3,
      "name": "Rock_Volcanic_Brick_Pillar_Base",
      "rotation": 8
    },
    {
      "x": 1,
      "y": 6,
      "z": 3,
      "name": "Rock_Volcanic_Brick_Pillar_Base"
    },
    {
      "x": 1,
      "y": 7,
      "z": 3,
      "name": "Rock_Volcanic_Brick_Pillar_Middle"
    },
    {
      "x": 1,
      "y": 8,
      "z": 3,
      "name": "Rock_Volcanic_Brick_Pillar_Base",
      "rotation": 8
    },
    {
      "x": 1,
      "y": 9,
      "z": 3,
      "name": "Rock_Volcanic_Brick_Pillar_Base"
    },
    {
      "x": 1,
      "y": 10,
      "z": 3,
      "name": "Rock_Volcanic_Brick_Pillar_Middle"
    },
    {
      "x": 1,
      "y": 11,
      "z": 3,
      "name": "Rock_Volcanic_Brick_Pillar_Base",
      "rotation": 8
    },
    {
      "x": 1,
      "y": 12,
      "z": 3,
      "name": "Rock_Volcanic_Brick_Pillar_Base"
    },
    {
      "x": 1,
      "y": 13,
      "z": 3,
      "name": "Rock_Volcanic_Brick_Pillar_Middle"
    },
    {
      "x": 1,
      "y": 14,
      "z": 3,
      "name": "Rock_Volcanic_Brick_Pillar_Base",
      "rotation": 8
    },
    {
      "x": 1,
      "y": 15,
      "z": 3,
      "name": "Rock_Volcanic_Brick_Pillar_Base"
    },
    {
      "x": 1,
      "y": 16,
      "z": 3,
      "name": "Rock_Volcanic_Brick_Pillar_Middle"
    },
    {
      "x": 1,
      "y": 17,
      "z": 3,
      "name": "Rock_Volcanic_Brick_Pillar_Base",
      "rotation": 8
    },
    {
      "x": 1,
      "y": 18,
      "z": 3,
      "name": "Rock_Volcanic_Brick_Pillar_Base"
    },
    {
      "x": 1,
      "y": 19,
      "z": 3,
      "name": "Rock_Volcanic_Brick_Pillar_Middle"
    },
    {
      "x": 1,
      "y": 20,
      "z": 3,
      "name": "Rock_Volcanic_Brick_Pillar_Base",
      "rotation": 8
    },
    {
      "x": 1,
      "y": 21,
      "z": 3,
      "name": "Rock_Volcanic_Brick_Pillar_Base"
    },
    {
      "x": 1,
      "y": 22,
      "z": 3,
      "name": "Rock_Volcanic_Brick_Pillar_Middle"
    },
    {
      "x": 1,
      "y": 23,
      "z": 3,
      "name": "Rock_Volcanic_Brick_Pillar_Base",
      "rotation": 8
    },
    {
      "x": 1,
      "y": 24,
      "z": 3,
      "name": "Rock_Volcanic_Brick_Pillar_Base"
    },
    {
      "x": 1,
      "y": 25,
      "z": 3,
      "name": "Rock_Volcanic_Brick_Pillar_Base",
      "rotation": 8
    },
    {
      "x": 1,
      "y": 0,
      "z": 4,
      "name": "Rock_Volcanic_Cobble"
    },
    {
      "x": 1,
      "y": 1,
      "z": 4,
      "name": "Rock_Volcanic_Brick"
    },
    {
      "x": 1,
      "y": 2,
      "z": 4,
      "name": "Soil_Volcanic_Gravel"
    },
    {
      "x": 1,
      "y": 3,
      "z": 4,
      "name": "Rock_Volcanic_Brick"
    },
    {
      "x": 1,
      "y": 4,
      "z": 4,
      "name": "Rock_Volcanic_Brick"
    },
    {
      "x": 1,
      "y": 5,
      "z": 4,
      "name": "Rock_Volcanic_Brick_Pillar_Middle"
    },
    {
      "x": 1,
      "y": 6,
      "z": 4,
      "name": "Rock_Volcanic_Brick_Ornate"
    },
    {
      "x": 1,
      "y": 7,
      "z": 4,
      "name": "Rock_Volcanic_Brick_Pillar_Middle",
      "rotation": 8
    },
    {
      "x": 1,
      "y": 8,
      "z": 4,
      "name": "Rock_Volcanic_Brick_Pillar_Middle",
      "rotation": 8
    },
    {
      "x": 1,
      "y": 9,
      "z": 4,
      "name": "Rock_Volcanic_Brick_Pillar_Middle",
      "rotation": 8
    },
    {
      "x": 1,
      "y": 10,
      "z": 4,
      "name": "Rock_Volcanic_Brick_Pillar_Middle",
      "rotation": 8
    },
    {
      "x": 1,
      "y": 11,
      "z": 4,
      "name": "Rock_Volcanic_Brick_Pillar_Middle",
      "rotation": 8
    },
    {
      "x": 1,
      "y": 12,
      "z": 4,
      "name": "Rock_Volcanic_Brick_Ornate"
    },
    {
      "x": 1,
      "y": 13,
      "z": 4,
      "name": "Rock_Volcanic_Brick_Pillar_Base"
    },
    {
      "x": 1,
      "y": 24,
      "z": 4,
      "name": "Rock_Volcanic_Brick_Pillar_Base",
      "rotation": 5
    },
    {
      "x": 1,
      "y": 25,
      "z": 4,
      "name": "Rock_Volcanic_Brick_Stairs",
      "rotation": 10
    },
    {
      "x": 1,
      "y": 26,
      "z": 4,
      "name": "Rock_Volcanic_Brick_Wall"
    },
    {
      "x": 1,
      "y": 0,
      "z": 5,
      "name": "Rock_Volcanic_Cobble"
    },
    {
      "x": 1,
      "y": 1,
      "z": 5,
      "name": "Rock_Volcanic_Cobble"
    },
    {
      "x": 1,
      "y": 2,
      "z": 5,
      "name": "Rock_Volcanic_Cobble"
    },
    {
      "x": 1,
      "y": 3,
      "z": 5,
      "name": "Rock_Volcanic_Cobble"
    },
    {
      "x": 1,
      "y": 4,
      "z": 5,
      "name": "Soil_Volcanic_Gravel"
    },
    {
      "x": 1,
      "y": 5,
      "z": 5,
      "name": "Rock_Volcanic_Brick_Half",
      "rotation": 4
    },
    {
      "x": 1,
      "y": 11,
      "z": 5,
      "name": "Rock_Volcanic_Brick_Half",
      "rotation": 4
    },
    {
      "x": 2,
      "y": 0,
      "z": -4,
      "name": "Rock_Volcanic_Cobble"
    },
    {
      "x": 2,
      "y": 1,
      "z": -4,
      "name": "Rock_Volcanic_Brick"
    },
    {
      "x": 2,
      "y": 2,
      "z": -4,
      "name": "Rock_Volcanic_Cobble"
    },
    {
      "x": 2,
      "y": 3,
      "z": -4,
      "name": "Rock_Volcanic_Brick"
    },
    {
      "x": 2,
      "y": 4,
      "z": -4,
      "name": "Rock_Volcanic_Brick_Half"
    },
    {
      "x": 2,
      "y": 0,
      "z": -3,
      "name": "Rock_Volcanic_Cobble"
    },
    {
      "x": 2,
      "y": 1,
      "z": -3,
      "name": "Soil_Volcanic_Gravel"
    },
    {
      "x": 2,
      "y": 2,
      "z": -3,
      "name": "Rock_Volcanic_Cobble"
    },
    {
      "x": 2,
      "y": 3,
      "z": -3,
      "name": "Soil_Volcanic_Gravel"
    },
    {
      "x": 2,
      "y": 4,
      "z": -3,
      "name": "Rock_Volcanic_Cobble"
    },
    {
      "x": 2,
      "y": 5,
      "z": -3,
      "name": "Rock_Volcanic_Brick_Half",
      "rotation": 5
    },
    {
      "x": 2,
      "y": 11,
      "z": -3,
      "name": "Rock_Volcanic_Brick_Half",
      "rotation": 5
    },
    {
      "x": 2,
      "y": 25,
      "z": -3,
      "name": "Rock_Volcanic_Brick_Stairs",
      "rotation": 34
    },
    {
      "x": 2,
      "y": 26,
      "z": -3,
      "name": "Rock_Volcanic_Brick"
    },
    {
      "x": 2,
      "y": 27,
      "z": -3,
      "name": "Rock_Volcanic_Brick_Stairs",
      "rotation": 2
    },
    {
      "x": 2,
      "y": 0,
      "z": -2,
      "name": "Rock_Volcanic_Cobble"
    },
    {
      "x": 2,
      "y": 1,
      "z": -2,
      "name": "Rock_Volcanic_Brick"
    },
    {
      "x": 2,
      "y": 2,
      "z": -2,
      "name": "Rock_Volcanic_Cobble"
    },
    {
      "x": 2,
      "y": 3,
      "z": -2,
      "name": "Soil_Volcanic_Gravel"
    },
    {
      "x": 2,
      "y": 4,
      "z": -2,
      "name": "Rock_Volcanic_Brick"
    },
    {
      "x": 2,
      "y": 5,
      "z": -2,
      "name": "Rock_Volcanic_Brick_Half",
      "rotation": 5
    },
    {
      "x": 2,
      "y": 11,
      "z": -2,
      "name": "Rock_Volcanic_Brick_Half",
      "rotation": 5
    },
    {
      "x": 2,
      "y": 24,
      "z": -2,
      "name": "Rock_Volcanic_Brick",
      "rotation": 2
    },
    {
      "x": 2,
      "y": 25,
      "z": -2,
      "name": "Rock_Volcanic_Brick",
      "rotation": 2
    },
    {
      "x": 2,
      "y": 0,
      "z": -1,
      "name": "Rock_Volcanic_Cobble"
    },
    {
      "x": 2,
      "y": 1,
      "z": -1,
      "name": "Soil_Volcanic_Gravel"
    },
    {
      "x": 2,
      "y": 2,
      "z": -1,
      "name": "Rock_Volcanic_Brick"
    },
    {
      "x": 2,
      "y": 3,
      "z": -1,
      "name": "Rock_Volcanic_Brick"
    },
    {
      "x": 2,
      "y": 4,
      "z": -1,
      "name": "Rock_Volcanic_Brick"
    },
    {
      "x": 2,
      "y": 5,
      "z": -1,
      "name": "Rock_Volcanic_Brick_Half",
      "rotation": 5
    },
    {
      "x": 2,
      "y": 11,
      "z": -1,
      "name": "Rock_Volcanic_Brick_Half",
      "rotation": 5
    },
    {
      "x": 2,
      "y": 24,
      "z": -1,
      "name": "Rock_Volcanic_Brick_Wall"
    },
    {
      "x": 2,
      "y": 25,
      "z": -1,
      "name": "Rock_Volcanic_Brick_Pillar_Middle",
      "rotation": 7
    },
    {
      "x": 2,
      "y": 0,
      "z": 0,
      "name": "Rock_Volcanic_Brick"
    },
    {
      "x": 2,
      "y": 1,
      "z": 0,
      "name": "Rock_Volcanic_Cobble"
    },
    {
      "x": 2,
      "y": 2,
      "z": 0,
      "name": "Rock_Volcanic_Cobble"
    },
    {
      "x": 2,
      "y": 3,
      "z": 0,
      "name": "Rock_Volcanic_Brick"
    },
    {
      "x": 2,
      "y": 4,
      "z": 0,
      "name": "Rock_Volcanic_Brick_Half"
    },
    {
      "x": 2,
      "y": 24,
      "z": 0,
      "name": "Rock_Volcanic_Brick_Pillar_Middle",
      "rotation": 5
    },
    {
      "x": 2,
      "y": 25,
      "z": 0,
      "name": "Rock_Volcanic_Brick"
    },
    {
      "x": 2,
      "y": 0,
      "z": 1,
      "name": "Soil_Volcanic_Gravel"
    },
    {
      "x": 2,
      "y": 1,
      "z": 1,
      "name": "Rock_Volcanic_Brick"
    },
    {
      "x": 2,
      "y": 2,
      "z": 1,
      "name": "Rock_Volcanic_Cobble"
    },
    {
      "x": 2,
      "y": 3,
      "z": 1,
      "name": "Rock_Volcanic_Cobble"
    },
    {
      "x": 2,
      "y": 4,
      "z": 1,
      "name": "Rock_Volcanic_Brick_Half"
    },
    {
      "x": 2,
      "y": 24,
      "z": 1,
      "name": "Rock_Volcanic_Brick_Pillar_Middle",
      "rotation": 5
    },
    {
      "x": 2,
      "y": 25,
      "z": 1,
      "name": "Rock_Volcanic_Brick"
    },
    {
      "x": 2,
      "y": 0,
      "z": 2,
      "name": "Soil_Volcanic_Gravel"
    },
    {
      "x": 2,
      "y": 1,
      "z": 2,
      "name": "Rock_Volcanic_Brick"
    },
    {
      "x": 2,
      "y": 2,
      "z": 2,
      "name": "Rock_Volcanic_Cobble"
    },
    {
      "x": 2,
      "y": 3,
      "z": 2,
      "name": "Rock_Volcanic_Brick"
    },
    {
      "x": 2,
      "y": 4,
      "z": 2,
      "name": "Soil_Volcanic_Gravel"
    },
    {
      "x": 2,
      "y": 5,
      "z": 2,
      "name": "Rock_Volcanic_Brick_Half",
      "rotation": 5
    },
    {
      "x": 2,
      "y": 11,
      "z": 2,
      "name": "Rock_Volcanic_Brick_Half",
      "rotation": 5
    },
    {
      "x": 2,
      "y": 24,
      "z": 2,
      "name": "Rock_Volcanic_Brick_Wall",
      "rotation": 2
    },
    {
      "x": 2,
      "y": 25,
      "z": 2,
      "name": "Rock_Volcanic_Brick_Pillar_Middle",
      "rotation": 7
    },
    {
      "x": 2,
      "y": 0,
      "z": 3,
      "name": "Rock_Volcanic_Brick"
    },
    {
      "x": 2,
      "y": 1,
      "z": 3,
      "name": "Rock_Volcanic_Brick"
    },
    {
      "x": 2,
      "y": 2,
      "z": 3,
      "name": "Rock_Volcanic_Brick"
    },
    {
      "x": 2,
      "y": 3,
      "z": 3,
      "name": "Soil_Volcanic_Gravel"
    },
    {
      "x": 2,
      "y": 4,
      "z": 3,
      "name": "Rock_Volcanic_Cobble"
    },
    {
      "x": 2,
      "y": 5,
      "z": 3,
      "name": "Rock_Volcanic_Brick_Half",
      "rotation": 5
    },
    {
      "x": 2,
      "y": 11,
      "z": 3,
      "name": "Rock_Volcanic_Brick_Half",
      "rotation": 5
    },
    {
      "x": 2,
      "y": 21,
      "z": 3,
      "name": "Rock_Volcanic_Brick_Half",
      "rotation": 5
    },
    {
      "x": 2,
      "y": 22,
      "z": 3,
      "name": "Rock_Volcanic_Brick_Half",
      "rotation": 5
    },
    {
      "x": 2,
      "y": 23,
      "z": 3,
      "name": "Rock_Volcanic_Brick_Stairs",
      "rotation": 11
    },
    {
      "x": 2,
      "y": 24,
      "z": 3,
      "name": "Rock_Volcanic_Brick"
    },
    {
      "x": 2,
      "y": 25,
      "z": 3,
      "name": "Rock_Volcanic_Brick"
    },
    {
      "x": 2,
      "y": 0,
      "z": 4,
      "name": "Rock_Volcanic_Brick"
    },
    {
      "x": 2,
      "y": 1,
      "z": 4,
      "name": "Soil_Volcanic_Gravel"
    },
    {
      "x": 2,
      "y": 2,
      "z": 4,
      "name": "Rock_Volcanic_Cobble"
    },
    {
      "x": 2,
      "y": 3,
      "z": 4,
      "name": "Rock_Volcanic_Brick"
    },
    {
      "x": 2,
      "y": 4,
      "z": 4,
      "name": "Rock_Volcanic_Brick"
    },
    {
      "x": 2,
      "y": 5,
      "z": 4,
      "name": "Rock_Volcanic_Brick_Half",
      "rotation": 5
    },
    {
      "x": 2,
      "y": 11,
      "z": 4,
      "name": "Rock_Volcanic_Brick_Half",
      "rotation": 5
    },
    {
      "x": 2,
      "y": 25,
      "z": 4,
      "name": "Rock_Volcanic_Brick_Stairs",
      "rotation": 10
    },
    {
      "x": 2,
      "y": 26,
      "z": 4,
      "name": "Rock_Volcanic_Brick"
    },
    {
      "x": 2,
      "y": 27,
      "z": 4,
      "name": "Rock_Volcanic_Brick_Stairs"
    },
    {
      "x": 2,
      "y": 0,
      "z": 5,
      "name": "Rock_Volcanic_Cobble"
    },
    {
      "x": 2,
      "y": 1,
      "z": 5,
      "name": "Rock_Volcanic_Brick"
    },
    {
      "x": 2,
      "y": 2,
      "z": 5,
      "name": "Rock_Volcanic_Brick"
    },
    {
      "x": 2,
      "y": 3,
      "z": 5,
      "name": "Soil_Volcanic_Gravel"
    },
    {
      "x": 2,
      "y": 4,
      "z": 5,
      "name": "Rock_Volcanic_Brick_Half"
    },
    {
      "x": 3,
      "y": 25,
      "z": -3,
      "name": "Rock_Volcanic_Brick_Stairs",
      "rotation": 34
    },
    {
      "x": 3,
      "y": 26,
      "z": -3,
      "name": "Rock_Volcanic_Brick_Wall",
      "rotation": 2
    },
    {
      "x": 3,
      "y": 0,
      "z": -2,
      "name": "Rock_Volcanic_Brick"
    },
    {
      "x": 3,
      "y": 1,
      "z": -2,
      "name": "Rock_Volcanic_Brick"
    },
    {
      "x": 3,
      "y": 2,
      "z": -2,
      "name": "Rock_Volcanic_Brick"
    },
    {
      "x": 3,
      "y": 3,
      "z": -2,
      "name": "Rock_Volcanic_Brick"
    },
    {
      "x": 3,
      "y": 4,
      "z": -2,
      "name": "Rock_Volcanic_Brick_Stairs",
      "rotation": 1
    },
    {
      "x": 3,
      "y": 24,
      "z": -2,
      "name": "Rock_Volcanic_Brick_Stairs",
      "rotation": 33
    },
    {
      "x": 3,
      "y": 25,
      "z": -2,
      "name": "Rock_Volcanic_Brick",
      "rotation": 2
    },
    {
      "x": 3,
      "y": 24,
      "z": -1,
      "name": "Rock_Volcanic_Brick_Wall"
    },
    {
      "x": 3,
      "y": 25,
      "z": -1,
      "name": "Rock_Volcanic_Brick_Pillar_Middle",
      "rotation": 7
    },
    {
      "x": 3,
      "y": 24,
      "z": 0,
      "name": "Rock_Volcanic_Brick_Pillar_Middle",
      "rotation": 5
    },
    {
      "x": 3,
      "y": 25,
      "z": 0,
      "name": "Rock_Volcanic_Brick"
    },
    {
      "x": 3,
      "y": 24,
      "z": 1,
      "name": "Rock_Volcanic_Brick_Pillar_Middle",
      "rotation": 5
    },
    {
      "x": 3,
      "y": 25,
      "z": 1,
      "name": "Rock_Volcanic_Brick"
    },
    {
      "x": 3,
      "y": 24,
      "z": 2,
      "name": "Rock_Volcanic_Brick_Wall",
      "rotation": 2
    },
    {
      "x": 3,
      "y": 25,
      "z": 2,
      "name": "Rock_Volcanic_Brick_Pillar_Middle",
      "rotation": 7
    },
    {
      "x": 3,
      "y": 0,
      "z": 3,
      "name": "Rock_Volcanic_Brick"
    },
    {
      "x": 3,
      "y": 1,
      "z": 3,
      "name": "Rock_Volcanic_Brick"
    },
    {
      "x": 3,
      "y": 2,
      "z": 3,
      "name": "Rock_Volcanic_Brick"
    },
    {
      "x": 3,
      "y": 3,
      "z": 3,
      "name": "Rock_Volcanic_Brick"
    },
    {
      "x": 3,
      "y": 4,
      "z": 3,
      "name": "Rock_Volcanic_Brick_Stairs",
      "rotation": 1
    },
    {
      "x": 3,
      "y": 24,
      "z": 3,
      "name": "Rock_Volcanic_Brick_Stairs",
      "rotation": 11
    },
    {
      "x": 3,
      "y": 25,
      "z": 3,
      "name": "Rock_Volcanic_Brick"
    },
    {
      "x": 3,
      "y": 25,
      "z": 4,
      "name": "Rock_Volcanic_Brick_Stairs",
      "rotation": 10
    },
    {
      "x": 3,
      "y": 26,
      "z": 4,
      "name": "Rock_Volcanic_Brick_Wall"
    },
    {
      "x": 4,
      "y": 25,
      "z": -3,
      "name": "Rock_Volcanic_Brick_Stairs",
      "rotation": 34
    },
    {
      "x": 4,
      "y": 26,
      "z": -3,
      "name": "Rock_Volcanic_Brick_Wall",
      "rotation": 2
    },
    {
      "x": 4,
      "y": 0,
      "z": -2,
      "name": "Rock_Volcanic_Brick"
    },
    {
      "x": 4,
      "y": 1,
      "z": -2,
      "name": "Rock_Volcanic_Brick"
    },
    {
      "x": 4,
      "y": 2,
      "z": -2,
      "name": "Rock_Volcanic_Brick_Stairs",
      "rotation": 1
    },
    {
      "x": 4,
      "y": 25,
      "z": -2,
      "name": "Rock_Volcanic_Brick",
      "rotation": 2
    },
    {
      "x": 4,
      "y": 24,
      "z": -1,
      "name": "Rock_Volcanic_Brick_Wall"
    },
    {
      "x": 4,
      "y": 25,
      "z": -1,
      "name": "Rock_Volcanic_Brick_Pillar_Base",
      "rotation": 7
    },
    {
      "x": 4,
      "y": 24,
      "z": 0,
      "name": "Rock_Volcanic_Brick_Pillar_Base",
      "rotation": 7
    },
    {
      "x": 4,
      "y": 25,
      "z": 0,
      "name": "Rock_Volcanic_Brick"
    },
    {
      "x": 4,
      "y": 24,
      "z": 1,
      "name": "Rock_Volcanic_Brick_Pillar_Base",
      "rotation": 7
    },
    {
      "x": 4,
      "y": 25,
      "z": 1,
      "name": "Rock_Volcanic_Brick"
    },
    {
      "x": 4,
      "y": 24,
      "z": 2,
      "name": "Rock_Volcanic_Brick_Wall",
      "rotation": 2
    },
    {
      "x": 4,
      "y": 25,
      "z": 2,
      "name": "Rock_Volcanic_Brick_Pillar_Base",
      "rotation": 7
    },
    {
      "x": 4,
      "y": 0,
      "z": 3,
      "name": "Rock_Volcanic_Brick"
    },
    {
      "x": 4,
      "y": 1,
      "z": 3,
      "name": "Rock_Volcanic_Brick"
    },
    {
      "x": 4,
      "y": 2,
      "z": 3,
      "name": "Rock_Volcanic_Brick_Stairs",
      "rotation": 1
    },
    {
      "x": 4,
      "y": 25,
      "z": 3,
      "name": "Rock_Volcanic_Brick"
    },
    {
      "x": 4,
      "y": 25,
      "z": 4,
      "name": "Rock_Volcanic_Brick_Stairs",
      "rotation": 10
    },
    {
      "x": 4,
      "y": 26,
      "z": 4,
      "name": "Rock_Volcanic_Brick_Wall"
    }
  ],
  "fluids": [
    {
      "x": -4,
      "y": 25,
      "z": -3,
      "name": "Empty",
      "level": 0
    },
    {
      "x": -4,
      "y": 26,
      "z": -3,
      "name": "Empty",
      "level": 0
    },
    {
      "x": -4,
      "y": 0,
      "z": -2,
      "name": "Empty",
      "level": 0
    },
    {
      "x": -4,
      "y": 1,
      "z": -2,
      "name": "Empty",
      "level": 0
    },
    {
      "x": -4,
      "y": 2,
      "z": -2,
      "name": "Empty",
      "level": 0
    },
    {
      "x": -4,
      "y": 25,
      "z": -2,
      "name": "Empty",
      "level": 0
    },
    {
      "x": -4,
      "y": 24,
      "z": -1,
      "name": "Empty",
      "level": 0
    },
    {
      "x": -4,
      "y": 25,
      "z": -1,
      "name": "Empty",
      "level": 0
    },
    {
      "x": -4,
      "y": 24,
      "z": 0,
      "name": "Empty",
      "level": 0
    },
    {
      "x": -4,
      "y": 25,
      "z": 0,
      "name": "Empty",
      "level": 0
    },
    {
      "x": -4,
      "y": 24,
      "z": 1,
      "name": "Empty",
      "level": 0
    },
    {
      "x": -4,
      "y": 25,
      "z": 1,
      "name": "Empty",
      "level": 0
    },
    {
      "x": -4,
      "y": 24,
      "z": 2,
      "name": "Empty",
      "level": 0
    },
    {
      "x": -4,
      "y": 25,
      "z": 2,
      "name": "Empty",
      "level": 0
    },
    {
      "x": -4,
      "y": 0,
      "z": 3,
      "name": "Empty",
      "level": 0
    },
    {
      "x": -4,
      "y": 1,
      "z": 3,
      "name": "Empty",
      "level": 0
    },
    {
      "x": -4,
      "y": 2,
      "z": 3,
      "name": "Empty",
      "level": 0
    },
    {
      "x": -4,
      "y": 25,
      "z": 3,
      "name": "Empty",
      "level": 0
    },
    {
      "x": -4,
      "y": 25,
      "z": 4,
      "name": "Empty",
      "level": 0
    },
    {
      "x": -4,
      "y": 26,
      "z": 4,
      "name": "Empty",
      "level": 0
    },
    {
      "x": -3,
      "y": 25,
      "z": -3,
      "name": "Empty",
      "level": 0
    },
    {
      "x": -3,
      "y": 26,
      "z": -3,
      "name": "Empty",
      "level": 0
    },
    {
      "x": -3,
      "y": 0,
      "z": -2,
      "name": "Empty",
      "level": 0
    },
    {
      "x": -3,
      "y": 1,
      "z": -2,
      "name": "Empty",
      "level": 0
    },
    {
      "x": -3,
      "y": 2,
      "z": -2,
      "name": "Empty",
      "level": 0
    },
    {
      "x": -3,
      "y": 3,
      "z": -2,
      "name": "Empty",
      "level": 0
    },
    {
      "x": -3,
      "y": 4,
      "z": -2,
      "name": "Empty",
      "level": 0
    },
    {
      "x": -3,
      "y": 24,
      "z": -2,
      "name": "Empty",
      "level": 0
    },
    {
      "x": -3,
      "y": 25,
      "z": -2,
      "name": "Empty",
      "level": 0
    },
    {
      "x": -3,
      "y": 24,
      "z": -1,
      "name": "Empty",
      "level": 0
    },
    {
      "x": -3,
      "y": 25,
      "z": -1,
      "name": "Empty",
      "level": 0
    },
    {
      "x": -3,
      "y": 24,
      "z": 0,
      "name": "Empty",
      "level": 0
    },
    {
      "x": -3,
      "y": 25,
      "z": 0,
      "name": "Empty",
      "level": 0
    },
    {
      "x": -3,
      "y": 24,
      "z": 1,
      "name": "Empty",
      "level": 0
    },
    {
      "x": -3,
      "y": 25,
      "z": 1,
      "name": "Empty",
      "level": 0
    },
    {
      "x": -3,
      "y": 24,
      "z": 2,
      "name": "Empty",
      "level": 0
    },
    {
      "x": -3,
      "y": 25,
      "z": 2,
      "name": "Empty",
      "level": 0
    },
    {
      "x": -3,
      "y": 0,
      "z": 3,
      "name": "Empty",
      "level": 0
    },
    {
      "x": -3,
      "y": 1,
      "z": 3,
      "name": "Empty",
      "level": 0
    },
    {
      "x": -3,
      "y": 2,
      "z": 3,
      "name": "Empty",
      "level": 0
    },
    {
      "x": -3,
      "y": 3,
      "z": 3,
      "name": "Empty",
      "level": 0
    },
    {
      "x": -3,
      "y": 4,
      "z": 3,
      "name": "Empty",
      "level": 0
    },
    {
      "x": -3,
      "y": 24,
      "z": 3,
      "name": "Empty",
      "level": 0
    },
    {
      "x": -3,
      "y": 25,
      "z": 3,
      "name": "Empty",
      "level": 0
    },
    {
      "x": -3,
      "y": 25,
      "z": 4,
      "name": "Empty",
      "level": 0
    },
    {
      "x": -3,
      "y": 26,
      "z": 4,
      "name": "Empty",
      "level": 0
    },
    {
      "x": -2,
      "y": 0,
      "z": -4,
      "name": "Empty",
      "level": 0
    },
    {
      "x": -2,
      "y": 1,
      "z": -4,
      "name": "Empty",
      "level": 0
    },
    {
      "x": -2,
      "y": 2,
      "z": -4,
      "name": "Empty",
      "level": 0
    },
    {
      "x": -2,
      "y": 3,
      "z": -4,
      "name": "Empty",
      "level": 0
    },
    {
      "x": -2,
      "y": 4,
      "z": -4,
      "name": "Empty",
      "level": 0
    },
    {
      "x": -2,
      "y": 0,
      "z": -3,
      "name": "Empty",
      "level": 0
    },
    {
      "x": -2,
      "y": 1,
      "z": -3,
      "name": "Empty",
      "level": 0
    },
    {
      "x": -2,
      "y": 2,
      "z": -3,
      "name": "Empty",
      "level": 0
    },
    {
      "x": -2,
      "y": 3,
      "z": -3,
      "name": "Empty",
      "level": 0
    },
    {
      "x": -2,
      "y": 4,
      "z": -3,
      "name": "Empty",
      "level": 0
    },
    {
      "x": -2,
      "y": 5,
      "z": -3,
      "name": "Empty",
      "level": 0
    },
    {
      "x": -2,
      "y": 11,
      "z": -3,
      "name": "Empty",
      "level": 0
    },
    {
      "x": -2,
      "y": 25,
      "z": -3,
      "name": "Empty",
      "level": 0
    },
    {
      "x": -2,
      "y": 26,
      "z": -3,
      "name": "Empty",
      "level": 0
    },
    {
      "x": -2,
      "y": 27,
      "z": -3,
      "name": "Empty",
      "level": 0
    },
    {
      "x": -2,
      "y": 0,
      "z": -2,
      "name": "Empty",
      "level": 0
    },
    {
      "x": -2,
      "y": 1,
      "z": -2,
      "name": "Empty",
      "level": 0
    },
    {
      "x": -2,
      "y": 2,
      "z": -2,
      "name": "Empty",
      "level": 0
    },
    {
      "x": -2,
      "y": 3,
      "z": -2,
      "name": "Empty",
      "level": 0
    },
    {
      "x": -2,
      "y": 4,
      "z": -2,
      "name": "Empty",
      "level": 0
    },
    {
      "x": -2,
      "y": 5,
      "z": -2,
      "name": "Empty",
      "level": 0
    },
    {
      "x": -2,
      "y": 11,
      "z": -2,
      "name": "Empty",
      "level": 0
    },
    {
      "x": -2,
      "y": 24,
      "z": -2,
      "name": "Empty",
      "level": 0
    },
    {
      "x": -2,
      "y": 25,
      "z": -2,
      "name": "Empty",
      "level": 0
    },
    {
      "x": -2,
      "y": 0,
      "z": -1,
      "name": "Empty",
      "level": 0
    },
    {
      "x": -2,
      "y": 1,
      "z": -1,
      "name": "Empty",
      "level": 0
    },
    {
      "x": -2,
      "y": 2,
      "z": -1,
      "name": "Empty",
      "level": 0
    },
    {
      "x": -2,
      "y": 3,
      "z": -1,
      "name": "Empty",
      "level": 0
    },
    {
      "x": -2,
      "y": 4,
      "z": -1,
      "name": "Empty",
      "level": 0
    },
    {
      "x": -2,
      "y": 5,
      "z": -1,
      "name": "Empty",
      "level": 0
    },
    {
      "x": -2,
      "y": 11,
      "z": -1,
      "name": "Empty",
      "level": 0
    },
    {
      "x": -2,
      "y": 24,
      "z": -1,
      "name": "Empty",
      "level": 0
    },
    {
      "x": -2,
      "y": 25,
      "z": -1,
      "name": "Empty",
      "level": 0
    },
    {
      "x": -2,
      "y": 0,
      "z": 0,
      "name": "Empty",
      "level": 0
    },
    {
      "x": -2,
      "y": 1,
      "z": 0,
      "name": "Empty",
      "level": 0
    },
    {
      "x": -2,
      "y": 2,
      "z": 0,
      "name": "Empty",
      "level": 0
    },
    {
      "x": -2,
      "y": 3,
      "z": 0,
      "name": "Empty",
      "level": 0
    },
    {
      "x": -2,
      "y": 4,
      "z": 0,
      "name": "Empty",
      "level": 0
    },
    {
      "x": -2,
      "y": 24,
      "z": 0,
      "name": "Empty",
      "level": 0
    },
    {
      "x": -2,
      "y": 25,
      "z": 0,
      "name": "Empty",
      "level": 0
    },
    {
      "x": -2,
      "y": 0,
      "z": 1,
      "name": "Empty",
      "level": 0
    },
    {
      "x": -2,
      "y": 1,
      "z": 1,
      "name": "Empty",
      "level": 0
    },
    {
      "x": -2,
      "y": 2,
      "z": 1,
      "name": "Empty",
      "level": 0
    },
    {
      "x": -2,
      "y": 3,
      "z": 1,
      "name": "Empty",
      "level": 0
    },
    {
      "x": -2,
      "y": 4,
      "z": 1,
      "name": "Empty",
      "level": 0
    },
    {
      "x": -2,
      "y": 24,
      "z": 1,
      "name": "Empty",
      "level": 0
    },
    {
      "x": -2,
      "y": 25,
      "z": 1,
      "name": "Empty",
      "level": 0
    },
    {
      "x": -2,
      "y": 0,
      "z": 2,
      "name": "Empty",
      "level": 0
    },
    {
      "x": -2,
      "y": 1,
      "z": 2,
      "name": "Empty",
      "level": 0
    },
    {
      "x": -2,
      "y": 2,
      "z": 2,
      "name": "Empty",
      "level": 0
    },
    {
      "x": -2,
      "y": 3,
      "z": 2,
      "name": "Empty",
      "level": 0
    },
    {
      "x": -2,
      "y": 4,
      "z": 2,
      "name": "Empty",
      "level": 0
    },
    {
      "x": -2,
      "y": 5,
      "z": 2,
      "name": "Empty",
      "level": 0
    },
    {
      "x": -2,
      "y": 11,
      "z": 2,
      "name": "Empty",
      "level": 0
    },
    {
      "x": -2,
      "y": 24,
      "z": 2,
      "name": "Empty",
      "level": 0
    },
    {
      "x": -2,
      "y": 25,
      "z": 2,
      "name": "Empty",
      "level": 0
    },
    {
      "x": -2,
      "y": 0,
      "z": 3,
      "name": "Empty",
      "level": 0
    },
    {
      "x": -2,
      "y": 1,
      "z": 3,
      "name": "Empty",
      "level": 0
    },
    {
      "x": -2,
      "y": 2,
      "z": 3,
      "name": "Empty",
      "level": 0
    },
    {
      "x": -2,
      "y": 3,
      "z": 3,
      "name": "Empty",
      "level": 0
    },
    {
      "x": -2,
      "y": 4,
      "z": 3,
      "name": "Empty",
      "level": 0
    },
    {
      "x": -2,
      "y": 5,
      "z": 3,
      "name": "Empty",
      "level": 0
    },
    {
      "x": -2,
      "y": 11,
      "z": 3,
      "name": "Empty",
      "level": 0
    },
    {
      "x": -2,
      "y": 21,
      "z": 3,
      "name": "Empty",
      "level": 0
    },
    {
      "x": -2,
      "y": 22,
      "z": 3,
      "name": "Empty",
      "level": 0
    },
    {
      "x": -2,
      "y": 23,
      "z": 3,
      "name": "Empty",
      "level": 0
    },
    {
      "x": -2,
      "y": 24,
      "z": 3,
      "name": "Empty",
      "level": 0
    },
    {
      "x": -2,
      "y": 25,
      "z": 3,
      "name": "Empty",
      "level": 0
    },
    {
      "x": -2,
      "y": 0,
      "z": 4,
      "name": "Empty",
      "level": 0
    },
    {
      "x": -2,
      "y": 1,
      "z": 4,
      "name": "Empty",
      "level": 0
    },
    {
      "x": -2,
      "y": 2,
      "z": 4,
      "name": "Empty",
      "level": 0
    },
    {
      "x": -2,
      "y": 3,
      "z": 4,
      "name": "Empty",
      "level": 0
    },
    {
      "x": -2,
      "y": 4,
      "z": 4,
      "name": "Empty",
      "level": 0
    },
    {
      "x": -2,
      "y": 5,
      "z": 4,
      "name": "Empty",
      "level": 0
    },
    {
      "x": -2,
      "y": 11,
      "z": 4,
      "name": "Empty",
      "level": 0
    },
    {
      "x": -2,
      "y": 25,
      "z": 4,
      "name": "Empty",
      "level": 0
    },
    {
      "x": -2,
      "y": 26,
      "z": 4,
      "name": "Empty",
      "level": 0
    },
    {
      "x": -2,
      "y": 27,
      "z": 4,
      "name": "Empty",
      "level": 0
    },
    {
      "x": -2,
      "y": 0,
      "z": 5,
      "name": "Empty",
      "level": 0
    },
    {
      "x": -2,
      "y": 1,
      "z": 5,
      "name": "Empty",
      "level": 0
    },
    {
      "x": -2,
      "y": 2,
      "z": 5,
      "name": "Empty",
      "level": 0
    },
    {
      "x": -2,
      "y": 3,
      "z": 5,
      "name": "Empty",
      "level": 0
    },
    {
      "x": -2,
      "y": 4,
      "z": 5,
      "name": "Empty",
      "level": 0
    },
    {
      "x": -1,
      "y": 0,
      "z": -4,
      "name": "Empty",
      "level": 0
    },
    {
      "x": -1,
      "y": 1,
      "z": -4,
      "name": "Empty",
      "level": 0
    },
    {
      "x": -1,
      "y": 2,
      "z": -4,
      "name": "Empty",
      "level": 0
    },
    {
      "x": -1,
      "y": 3,
      "z": -4,
      "name": "Empty",
      "level": 0
    },
    {
      "x": -1,
      "y": 4,
      "z": -4,
      "name": "Empty",
      "level": 0
    },
    {
      "x": -1,
      "y": 5,
      "z": -4,
      "name": "Empty",
      "level": 0
    },
    {
      "x": -1,
      "y": 11,
      "z": -4,
      "name": "Empty",
      "level": 0
    },
    {
      "x": -1,
      "y": 0,
      "z": -3,
      "name": "Empty",
      "level": 0
    },
    {
      "x": -1,
      "y": 1,
      "z": -3,
      "name": "Empty",
      "level": 0
    },
    {
      "x": -1,
      "y": 2,
      "z": -3,
      "name": "Empty",
      "level": 0
    },
    {
      "x": -1,
      "y": 3,
      "z": -3,
      "name": "Empty",
      "level": 0
    },
    {
      "x": -1,
      "y": 4,
      "z": -3,
      "name": "Empty",
      "level": 0
    },
    {
      "x": -1,
      "y": 5,
      "z": -3,
      "name": "Empty",
      "level": 0
    },
    {
      "x": -1,
      "y": 6,
      "z": -3,
      "name": "Empty",
      "level": 0
    },
    {
      "x": -1,
      "y": 7,
      "z": -3,
      "name": "Empty",
      "level": 0
    },
    {
      "x": -1,
      "y": 8,
      "z": -3,
      "name": "Empty",
      "level": 0
    },
    {
      "x": -1,
      "y": 9,
      "z": -3,
      "name": "Empty",
      "level": 0
    },
    {
      "x": -1,
      "y": 10,
      "z": -3,
      "name": "Empty",
      "level": 0
    },
    {
      "x": -1,
      "y": 11,
      "z": -3,
      "name": "Empty",
      "level": 0
    },
    {
      "x": -1,
      "y": 12,
      "z": -3,
      "name": "Empty",
      "level": 0
    },
    {
      "x": -1,
      "y": 13,
      "z": -3,
      "name": "Empty",
      "level": 0
    },
    {
      "x": -1,
      "y": 24,
      "z": -3,
      "name": "Empty",
      "level": 0
    },
    {
      "x": -1,
      "y": 25,
      "z": -3,
      "name": "Empty",
      "level": 0
    },
    {
      "x": -1,
      "y": 26,
      "z": -3,
      "name": "Empty",
      "level": 0
    },
    {
      "x": -1,
      "y": 0,
      "z": -2,
      "name": "Empty",
      "level": 0
    },
    {
      "x": -1,
      "y": 1,
      "z": -2,
      "name": "Empty",
      "level": 0
    },
    {
      "x": -1,
      "y": 2,
      "z": -2,
      "name": "Empty",
      "level": 0
    },
    {
      "x": -1,
      "y": 3,
      "z": -2,
      "name": "Empty",
      "level": 0
    },
    {
      "x": -1,
      "y": 4,
      "z": -2,
      "name": "Empty",
      "level": 0
    },
    {
      "x": -1,
      "y": 5,
      "z": -2,
      "name": "Empty",
      "level": 0
    },
    {
      "x": -1,
      "y": 6,
      "z": -2,
      "name": "Empty",
      "level": 0
    },
    {
      "x": -1,
      "y": 7,
      "z": -2,
      "name": "Empty",
      "level": 0
    },
    {
      "x": -1,
      "y": 8,
      "z": -2,
      "name": "Empty",
      "level": 0
    },
    {
      "x": -1,
      "y": 9,
      "z": -2,
      "name": "Empty",
      "level": 0
    },
    {
      "x": -1,
      "y": 10,
      "z": -2,
      "name": "Empty",
      "level": 0
    },
    {
      "x": -1,
      "y": 11,
      "z": -2,
      "name": "Empty",
      "level": 0
    },
    {
      "x": -1,
      "y": 12,
      "z": -2,
      "name": "Empty",
      "level": 0
    },
    {
      "x": -1,
      "y": 13,
      "z": -2,
      "name": "Empty",
      "level": 0
    },
    {
      "x": -1,
      "y": 14,
      "z": -2,
      "name": "Empty",
      "level": 0
    },
    {
      "x": -1,
      "y": 15,
      "z": -2,
      "name": "Empty",
      "level": 0
    },
    {
      "x": -1,
      "y": 16,
      "z": -2,
      "name": "Empty",
      "level": 0
    },
    {
      "x": -1,
      "y": 17,
      "z": -2,
      "name": "Empty",
      "level": 0
    },
    {
      "x": -1,
      "y": 18,
      "z": -2,
      "name": "Empty",
      "level": 0
    },
    {
      "x": -1,
      "y": 19,
      "z": -2,
      "name": "Empty",
      "level": 0
    },
    {
      "x": -1,
      "y": 20,
      "z": -2,
      "name": "Empty",
      "level": 0
    },
    {
      "x": -1,
      "y": 21,
      "z": -2,
      "name": "Empty",
      "level": 0
    },
    {
      "x": -1,
      "y": 22,
      "z": -2,
      "name": "Empty",
      "level": 0
    },
    {
      "x": -1,
      "y": 23,
      "z": -2,
      "name": "Empty",
      "level": 0
    },
    {
      "x": -1,
      "y": 24,
      "z": -2,
      "name": "Empty",
      "level": 0
    },
    {
      "x": -1,
      "y": 25,
      "z": -2,
      "name": "Empty",
      "level": 0
    },
    {
      "x": -1,
      "y": 0,
      "z": -1,
      "name": "Empty",
      "level": 0
    },
    {
      "x": -1,
      "y": 1,
      "z": -1,
      "name": "Empty",
      "level": 0
    },
    {
      "x": -1,
      "y": 2,
      "z": -1,
      "name": "Empty",
      "level": 0
    },
    {
      "x": -1,
      "y": 3,
      "z": -1,
      "name": "Empty",
      "level": 0
    },
    {
      "x": -1,
      "y": 4,
      "z": -1,
      "name": "Empty",
      "level": 0
    },
    {
      "x": -1,
      "y": 5,
      "z": -1,
      "name": "Empty",
      "level": 0
    },
    {
      "x": -1,
      "y": 6,
      "z": -1,
      "name": "Empty",
      "level": 0
    },
    {
      "x": -1,
      "y": 7,
      "z": -1,
      "name": "Empty",
      "level": 0
    },
    {
      "x": -1,
      "y": 8,
      "z": -1,
      "name": "Empty",
      "level": 0
    },
    {
      "x": -1,
      "y": 9,
      "z": -1,
      "name": "Empty",
      "level": 0
    },
    {
      "x": -1,
      "y": 10,
      "z": -1,
      "name": "Empty",
      "level": 0
    },
    {
      "x": -1,
      "y": 11,
      "z": -1,
      "name": "Empty",
      "level": 0
    },
    {
      "x": -1,
      "y": 12,
      "z": -1,
      "name": "Empty",
      "level": 0
    },
    {
      "x": -1,
      "y": 13,
      "z": -1,
      "name": "Empty",
      "level": 0
    },
    {
      "x": -1,
      "y": 24,
      "z": -1,
      "name": "Empty",
      "level": 0
    },
    {
      "x": -1,
      "y": 25,
      "z": -1,
      "name": "Empty",
      "level": 0
    },
    {
      "x": -1,
      "y": 0,
      "z": 0,
      "name": "Empty",
      "level": 0
    },
    {
      "x": -1,
      "y": 1,
      "z": 0,
      "name": "Empty",
      "level": 0
    },
    {
      "x": -1,
      "y": 2,
      "z": 0,
      "name": "Empty",
      "level": 0
    },
    {
      "x": -1,
      "y": 3,
      "z": 0,
      "name": "Empty",
      "level": 0
    },
    {
      "x": -1,
      "y": 4,
      "z": 0,
      "name": "Empty",
      "level": 0
    },
    {
      "x": -1,
      "y": 5,
      "z": 0,
      "name": "Empty",
      "level": 0
    },
    {
      "x": -1,
      "y": 11,
      "z": 0,
      "name": "Empty",
      "level": 0
    },
    {
      "x": -1,
      "y": 24,
      "z": 0,
      "name": "Empty",
      "level": 0
    },
    {
      "x": -1,
      "y": 25,
      "z": 0,
      "name": "Empty",
      "level": 0
    },
    {
      "x": -1,
      "y": 0,
      "z": 1,
      "name": "Empty",
      "level": 0
    },
    {
      "x": -1,
      "y": 1,
      "z": 1,
      "name": "Empty",
      "level": 0
    },
    {
      "x": -1,
      "y": 2,
      "z": 1,
      "name": "Empty",
      "level": 0
    },
    {
      "x": -1,
      "y": 3,
      "z": 1,
      "name": "Empty",
      "level": 0
    },
    {
      "x": -1,
      "y": 4,
      "z": 1,
      "name": "Empty",
      "level": 0
    },
    {
      "x": -1,
      "y": 5,
      "z": 1,
      "name": "Empty",
      "level": 0
    },
    {
      "x": -1,
      "y": 11,
      "z": 1,
      "name": "Empty",
      "level": 0
    },
    {
      "x": -1,
      "y": 24,
      "z": 1,
      "name": "Empty",
      "level": 0
    },
    {
      "x": -1,
      "y": 25,
      "z": 1,
      "name": "Empty",
      "level": 0
    },
    {
      "x": -1,
      "y": 0,
      "z": 2,
      "name": "Empty",
      "level": 0
    },
    {
      "x": -1,
      "y": 1,
      "z": 2,
      "name": "Empty",
      "level": 0
    },
    {
