{
  "version": 8,
  "blockIdVersion": 11,
  "anchorX": 0,
  "anchorY": 5,
  "anchorZ": 0,
  "blocks": [
    {
      "x": -23,
      "y": -14,
      "z": -18,
      "name": "Rock_Volcanic_Cobble"
    },
    {
      "x": -23,
      "y": -13,
      "z": -18,
      "name": "Rock_Volcanic_Brick"
    },
    {
      "x": -23,
      "y": -12,
      "z": -18,
      "name": "Rock_Volcanic_Cobble"
    },
    {
      "x": -23,
      "y": -11,
      "z": -18,
      "name": "Rock_Volcanic_Brick"
    },
    {
      "x": -23,
      "y": -10,
      "z": -18,
      "name": "Rock_Volcanic_Cobble"
    },
    {
      "x": -23,
      "y": -9,
      "z": -18,
      "name": "Rock_Volcanic_Brick"
    },
    {
      "x": -23,
      "y": -8,
      "z": -18,
      "name": "Rock_Volcanic_Brick"
    },
    {
      "x": -23,
      "y": -7,
      "z": -18,
      "name": "Rock_Volcanic_Brick"
    },
    {
      "x": -23,
      "y": -6,
      "z": -18,
      "name": "Rock_Volcanic_Brick"
    },
    {
      "x": -23,
      "y": -5,
      "z": -18,
      "name": "Rock_Volcanic_Brick"
    },
    {
      "x": -23,
      "y": -4,
      "z": -18,
      "name": "Rock_Volcanic_Cobble"
    },
    {
      "x": -23,
      "y": -3,
      "z": -18,
      "name": "Rock_Volcanic_Brick"
    },
    {
      "x": -23,
      "y": -2,
      "z": -18,
      "name": "Rock_Volcanic_Brick"
    },
    {
      "x": -23,
      "y": -1,
      "z": -18,
      "name": "Rock_Volcanic_Brick"
    },
    {
      "x": -23,
      "y": 0,
      "z": -18,
      "name": "Rock_Volcanic_Brick"
    },
    {
      "x": -23,
      "y": 1,
      "z": -18,
      "name": "Rock_Volcanic_Cobble"
    },
    {
      "x": -23,
      "y": 2,
      "z": -18,
      "name": "Rock_Volcanic_Brick"
    },
    {
      "x": -23,
      "y": 3,
      "z": -18,
      "name": "Rock_Volcanic_Cobble"
    },
    {
      "x": -23,
      "y": -14,
      "z": -17,
      "name": "Rock_Volcanic_Cobble"
    },
    {
      "x": -23,
      "y": -13,
      "z": -17,
      "name": "Rock_Volcanic_Cobble"
    },
    {
      "x": -23,
      "y": -12,
      "z": -17,
      "name": "Rock_Volcanic_Brick"
    },
    {
      "x": -23,
      "y": -11,
      "z": -17,
      "name": "Rock_Volcanic_Brick"
    },
    {
      "x": -23,
      "y": -10,
      "z": -17,
      "name": "Rock_Volcanic_Brick"
    },
    {
      "x": -23,
      "y": -9,
      "z": -17,
      "name": "Rock_Volcanic_Brick"
    },
    {
      "x": -23,
      "y": -8,
      "z": -17,
      "name": "Rock_Volcanic_Brick"
    },
    {
      "x": -23,
      "y": -7,
      "z": -17,
      "name": "Rock_Volcanic_Brick"
    },
    {
      "x": -23,
      "y": -6,
      "z": -17,
      "name": "Rock_Volcanic_Cobble"
    },
    {
      "x": -23,
      "y": -5,
      "z": -17,
      "name": "Rock_Volcanic_Brick"
    },
    {
      "x": -23,
      "y": -4,
      "z": -17,
      "name": "Rock_Volcanic_Cobble"
    },
    {
      "x": -23,
      "y": -3,
      "z": -17,
      "name": "Rock_Volcanic_Cobble"
    },
    {
      "x": -23,
      "y": -2,
      "z": -17,
      "name": "Rock_Volcanic_Cobble"
    },
    {
      "x": -23,
      "y": -1,
      "z": -17,
      "name": "Rock_Volcanic_Cobble"
    },
    {
      "x": -23,
      "y": 0,
      "z": -17,
      "name": "Rock_Volcanic_Brick"
    },
    {
      "x": -23,
      "y": 1,
      "z": -17,
      "name": "Rock_Volcanic_Brick"
    },
    {
      "x": -23,
      "y": 2,
      "z": -17,
      "name": "Rock_Volcanic_Cobble"
    },
    {
      "x": -23,
      "y": 3,
      "z": -17,
      "name": "Rock_Volcanic_Cobble"
    },
    {
      "x": -23,
      "y": 4,
      "z": -17,
      "name": "Rock_Volcanic_Brick_Stairs",
      "rotation": 3
    },
    {
      "x": -23,
      "y": -14,
      "z": -16,
      "name": "Rock_Volcanic_Cobble"
    },
    {
      "x": -23,
      "y": -13,
      "z": -16,
      "name": "Rock_Volcanic_Brick"
    },
    {
      "x": -23,
      "y": -12,
      "z": -16,
      "name": "Rock_Volcanic_Cobble"
    },
    {
      "x": -23,
      "y": -11,
      "z": -16,
      "name": "Rock_Volcanic_Brick"
    },
    {
      "x": -23,
      "y": -10,
      "z": -16,
      "name": "Rock_Volcanic_Brick"
    },
    {
      "x": -23,
      "y": -9,
      "z": -16,
      "name": "Rock_Volcanic_Cobble"
    },
    {
      "x": -23,
      "y": -8,
      "z": -16,
      "name": "Rock_Volcanic_Cobble"
    },
    {
      "x": -23,
      "y": -7,
      "z": -16,
      "name": "Rock_Volcanic_Brick"
    },
    {
      "x": -23,
      "y": -6,
      "z": -16,
      "name": "Rock_Volcanic_Cobble"
    },
    {
      "x": -23,
      "y": -5,
      "z": -16,
      "name": "Rock_Volcanic_Brick"
    },
    {
      "x": -23,
      "y": -4,
      "z": -16,
      "name": "Rock_Volcanic_Cobble"
    },
    {
      "x": -23,
      "y": -3,
      "z": -16,
      "name": "Rock_Volcanic_Cobble"
    },
    {
      "x": -23,
      "y": -2,
      "z": -16,
      "name": "Rock_Volcanic_Cobble"
    },
    {
      "x": -23,
      "y": -1,
      "z": -16,
      "name": "Rock_Volcanic_Brick"
    },
    {
      "x": -23,
      "y": 0,
      "z": -16,
      "name": "Rock_Volcanic_Cobble"
    },
    {
      "x": -23,
      "y": 1,
      "z": -16,
      "name": "Rock_Volcanic_Cobble"
    },
    {
      "x": -23,
      "y": 2,
      "z": -16,
      "name": "Rock_Volcanic_Cobble"
    },
    {
      "x": -23,
      "y": 3,
      "z": -16,
      "name": "Rock_Volcanic_Brick"
    },
    {
      "x": -23,
      "y": 4,
      "z": -16,
      "name": "Rock_Volcanic_Brick",
      "rotation": 2
    },
    {
      "x": -23,
      "y": 5,
      "z": -16,
      "name": "Rock_Volcanic_Brick",
      "rotation": 2
    },
    {
      "x": -23,
      "y": 6,
      "z": -16,
      "name": "Rock_Volcanic_Brick",
      "rotation": 2
    },
    {
      "x": -23,
      "y": 7,
      "z": -16,
      "name": "Rock_Volcanic_Brick_Stairs",
      "rotation": 3
    },
    {
      "x": -23,
      "y": -14,
      "z": -15,
      "name": "Rock_Volcanic_Brick"
    },
    {
      "x": -23,
      "y": -13,
      "z": -15,
      "name": "Rock_Volcanic_Cobble"
    },
    {
      "x": -23,
      "y": -12,
      "z": -15,
      "name": "Rock_Volcanic_Cobble"
    },
    {
      "x": -23,
      "y": -11,
      "z": -15,
      "name": "Rock_Volcanic_Cobble"
    },
    {
      "x": -23,
      "y": -10,
      "z": -15,
      "name": "Rock_Volcanic_Brick"
    },
    {
      "x": -23,
      "y": -9,
      "z": -15,
      "name": "Rock_Volcanic_Brick"
    },
    {
      "x": -23,
      "y": -8,
      "z": -15,
      "name": "Rock_Volcanic_Brick"
    },
    {
      "x": -23,
      "y": -7,
      "z": -15,
      "name": "Rock_Volcanic_Brick"
    },
    {
      "x": -23,
      "y": -6,
      "z": -15,
      "name": "Rock_Volcanic_Brick"
    },
    {
      "x": -23,
      "y": -5,
      "z": -15,
      "name": "Rock_Volcanic_Brick"
    },
    {
      "x": -23,
      "y": -4,
      "z": -15,
      "name": "Rock_Volcanic_Cobble"
    },
    {
      "x": -23,
      "y": -3,
      "z": -15,
      "name": "Rock_Volcanic_Cobble"
    },
    {
      "x": -23,
      "y": -2,
      "z": -15,
      "name": "Rock_Volcanic_Brick"
    },
    {
      "x": -23,
      "y": -1,
      "z": -15,
      "name": "Rock_Volcanic_Cobble"
    },
    {
      "x": -23,
      "y": 0,
      "z": -15,
      "name": "Rock_Volcanic_Cobble"
    },
    {
      "x": -23,
      "y": 1,
      "z": -15,
      "name": "Rock_Volcanic_Brick"
    },
    {
      "x": -23,
      "y": 2,
      "z": -15,
      "name": "Rock_Volcanic_Cobble"
    },
    {
      "x": -23,
      "y": 3,
      "z": -15,
      "name": "Rock_Volcanic_Brick"
    },
    {
      "x": -23,
      "y": 4,
      "z": -15,
      "name": "Rock_Volcanic_Brick_Stairs",
      "rotation": 3
    },
    {
      "x": -23,
      "y": -14,
      "z": -14,
      "name": "Rock_Volcanic_Brick"
    },
    {
      "x": -23,
      "y": -13,
      "z": -14,
      "name": "Rock_Volcanic_Brick"
    },
    {
      "x": -23,
      "y": -12,
      "z": -14,
      "name": "Rock_Volcanic_Brick"
    },
    {
      "x": -23,
      "y": -11,
      "z": -14,
      "name": "Rock_Volcanic_Brick"
    },
    {
      "x": -23,
      "y": -10,
      "z": -14,
      "name": "Rock_Volcanic_Cobble"
    },
    {
      "x": -23,
      "y": -9,
      "z": -14,
      "name": "Rock_Volcanic_Brick"
    },
    {
      "x": -23,
      "y": -8,
      "z": -14,
      "name": "Rock_Volcanic_Cobble"
    },
    {
      "x": -23,
      "y": -7,
      "z": -14,
      "name": "Rock_Volcanic_Cobble"
    },
    {
      "x": -23,
      "y": -6,
      "z": -14,
      "name": "Rock_Volcanic_Brick"
    },
    {
      "x": -23,
      "y": -5,
      "z": -14,
      "name": "Rock_Volcanic_Cobble"
    },
    {
      "x": -23,
      "y": -4,
      "z": -14,
      "name": "Rock_Volcanic_Brick"
    },
    {
      "x": -23,
      "y": -3,
      "z": -14,
      "name": "Rock_Volcanic_Brick"
    },
    {
      "x": -23,
      "y": -2,
      "z": -14,
      "name": "Rock_Volcanic_Cobble"
    },
    {
      "x": -23,
      "y": -1,
      "z": -14,
      "name": "Rock_Volcanic_Brick"
    },
    {
      "x": -23,
      "y": 0,
      "z": -14,
      "name": "Rock_Volcanic_Brick"
    },
    {
      "x": -23,
      "y": 1,
      "z": -14,
      "name": "Rock_Volcanic_Cobble"
    },
    {
      "x": -23,
      "y": 2,
      "z": -14,
      "name": "Rock_Volcanic_Cobble"
    },
    {
      "x": -23,
      "y": 3,
      "z": -14,
      "name": "Rock_Volcanic_Cobble"
    },
    {
      "x": -23,
      "y": -14,
      "z": 15,
      "name": "Rock_Volcanic_Cobble"
    },
    {
      "x": -23,
      "y": -13,
      "z": 15,
      "name": "Rock_Volcanic_Brick"
    },
    {
      "x": -23,
      "y": -12,
      "z": 15,
      "name": "Rock_Volcanic_Cobble"
    },
    {
      "x": -23,
      "y": -11,
      "z": 15,
      "name": "Rock_Volcanic_Cobble"
    },
    {
      "x": -23,
      "y": -10,
      "z": 15,
      "name": "Rock_Volcanic_Brick"
    },
    {
      "x": -23,
      "y": -9,
      "z": 15,
      "name": "Rock_Volcanic_Brick"
    },
    {
      "x": -23,
      "y": -8,
      "z": 15,
      "name": "Rock_Volcanic_Cobble"
    },
    {
      "x": -23,
      "y": -7,
      "z": 15,
      "name": "Rock_Volcanic_Brick"
    },
    {
      "x": -23,
      "y": -6,
      "z": 15,
      "name": "Rock_Volcanic_Brick"
    },
    {
      "x": -23,
      "y": -5,
      "z": 15,
      "name": "Rock_Volcanic_Brick"
    },
    {
      "x": -23,
      "y": -4,
      "z": 15,
      "name": "Rock_Volcanic_Cobble"
    },
    {
      "x": -23,
      "y": -3,
      "z": 15,
      "name": "Rock_Volcanic_Cobble"
    },
    {
      "x": -23,
      "y": -2,
      "z": 15,
      "name": "Rock_Volcanic_Brick"
    },
    {
      "x": -23,
      "y": -1,
      "z": 15,
      "name": "Rock_Volcanic_Brick"
    },
    {
      "x": -23,
      "y": 0,
      "z": 15,
      "name": "Rock_Volcanic_Cobble"
    },
    {
      "x": -23,
      "y": 1,
      "z": 15,
      "name": "Rock_Volcanic_Cobble"
    },
    {
      "x": -23,
      "y": 2,
      "z": 15,
      "name": "Rock_Volcanic_Cobble"
    },
    {
      "x": -23,
      "y": -14,
      "z": 16,
      "name": "Rock_Volcanic_Brick"
    },
    {
      "x": -23,
      "y": -13,
      "z": 16,
      "name": "Rock_Volcanic_Brick"
    },
    {
      "x": -23,
      "y": -12,
      "z": 16,
      "name": "Rock_Volcanic_Cobble"
    },
    {
      "x": -23,
      "y": -11,
      "z": 16,
      "name": "Rock_Volcanic_Cobble"
    },
    {
      "x": -23,
      "y": -10,
      "z": 16,
      "name": "Rock_Volcanic_Brick"
    },
    {
      "x": -23,
      "y": -9,
      "z": 16,
      "name": "Rock_Volcanic_Cobble"
    },
    {
      "x": -23,
      "y": -8,
      "z": 16,
      "name": "Rock_Volcanic_Brick"
    },
    {
      "x": -23,
      "y": -7,
      "z": 16,
      "name": "Rock_Volcanic_Brick"
    },
    {
      "x": -23,
      "y": -6,
      "z": 16,
      "name": "Rock_Volcanic_Cobble"
    },
    {
      "x": -23,
      "y": -5,
      "z": 16,
      "name": "Rock_Volcanic_Cobble"
    },
    {
      "x": -23,
      "y": -4,
      "z": 16,
      "name": "Rock_Volcanic_Cobble"
    },
    {
      "x": -23,
      "y": -3,
      "z": 16,
      "name": "Rock_Volcanic_Cobble"
    },
    {
      "x": -23,
      "y": -2,
      "z": 16,
      "name": "Rock_Volcanic_Brick"
    },
    {
      "x": -23,
      "y": -1,
      "z": 16,
      "name": "Rock_Volcanic_Cobble"
    },
    {
      "x": -23,
      "y": 0,
      "z": 16,
      "name": "Rock_Volcanic_Cobble"
    },
    {
      "x": -23,
      "y": 1,
      "z": 16,
      "name": "Rock_Volcanic_Brick"
    },
    {
      "x": -23,
      "y": 2,
      "z": 16,
      "name": "Rock_Volcanic_Brick"
    },
    {
      "x": -23,
      "y": 3,
      "z": 16,
      "name": "Rock_Volcanic_Cobble"
    },
    {
      "x": -23,
      "y": 4,
      "z": 16,
      "name": "Rock_Volcanic_Brick_Stairs",
      "rotation": 3
    },
    {
      "x": -23,
      "y": -14,
      "z": 17,
      "name": "Rock_Volcanic_Brick"
    },
    {
      "x": -23,
      "y": -13,
      "z": 17,
      "name": "Rock_Volcanic_Brick"
    },
    {
      "x": -23,
      "y": -12,
      "z": 17,
      "name": "Rock_Volcanic_Brick"
    },
    {
      "x": -23,
      "y": -11,
      "z": 17,
      "name": "Rock_Volcanic_Cobble"
    },
    {
      "x": -23,
      "y": -10,
      "z": 17,
      "name": "Rock_Volcanic_Brick"
    },
    {
      "x": -23,
      "y": -9,
      "z": 17,
      "name": "Rock_Volcanic_Brick"
    },
    {
      "x": -23,
      "y": -8,
      "z": 17,
      "name": "Rock_Volcanic_Cobble"
    },
    {
      "x": -23,
      "y": -7,
      "z": 17,
      "name": "Rock_Volcanic_Cobble"
    },
    {
      "x": -23,
      "y": -6,
      "z": 17,
      "name": "Rock_Volcanic_Cobble"
    },
    {
      "x": -23,
      "y": -5,
      "z": 17,
      "name": "Rock_Volcanic_Cobble"
    },
    {
      "x": -23,
      "y": -4,
      "z": 17,
      "name": "Rock_Volcanic_Brick"
    },
    {
      "x": -23,
      "y": -3,
      "z": 17,
      "name": "Rock_Volcanic_Brick"
    },
    {
      "x": -23,
      "y": -2,
      "z": 17,
      "name": "Rock_Volcanic_Brick"
    },
    {
      "x": -23,
      "y": -1,
      "z": 17,
      "name": "Rock_Volcanic_Cobble"
    },
    {
      "x": -23,
      "y": 0,
      "z": 17,
      "name": "Rock_Volcanic_Brick"
    },
    {
      "x": -23,
      "y": 1,
      "z": 17,
      "name": "Rock_Volcanic_Brick"
    },
    {
      "x": -23,
      "y": 2,
      "z": 17,
      "name": "Rock_Volcanic_Brick"
    },
    {
      "x": -23,
      "y": 3,
      "z": 17,
      "name": "Rock_Volcanic_Cobble"
    },
    {
      "x": -23,
      "y": 4,
      "z": 17,
      "name": "Rock_Volcanic_Brick",
      "rotation": 3
    },
    {
      "x": -23,
      "y": 5,
      "z": 17,
      "name": "Rock_Volcanic_Brick",
      "rotation": 3
    },
    {
      "x": -23,
      "y": 6,
      "z": 17,
      "name": "Rock_Volcanic_Brick",
      "rotation": 3
    },
    {
      "x": -23,
      "y": 7,
      "z": 17,
      "name": "Rock_Volcanic_Brick_Stairs",
      "rotation": 3
    },
    {
      "x": -23,
      "y": -14,
      "z": 18,
      "name": "Rock_Volcanic_Brick"
    },
    {
      "x": -23,
      "y": -13,
      "z": 18,
      "name": "Rock_Volcanic_Brick"
    },
    {
      "x": -23,
      "y": -12,
      "z": 18,
      "name": "Rock_Volcanic_Cobble"
    },
    {
      "x": -23,
      "y": -11,
      "z": 18,
      "name": "Rock_Volcanic_Cobble"
    },
    {
      "x": -23,
      "y": -10,
      "z": 18,
      "name": "Rock_Volcanic_Cobble"
    },
    {
      "x": -23,
      "y": -9,
      "z": 18,
      "name": "Rock_Volcanic_Brick"
    },
    {
      "x": -23,
      "y": -8,
      "z": 18,
      "name": "Rock_Volcanic_Cobble"
    },
    {
      "x": -23,
      "y": -7,
      "z": 18,
      "name": "Rock_Volcanic_Brick"
    },
    {
      "x": -23,
      "y": -6,
      "z": 18,
      "name": "Rock_Volcanic_Brick"
    },
    {
      "x": -23,
      "y": -5,
      "z": 18,
      "name": "Rock_Volcanic_Cobble"
    },
    {
      "x": -23,
      "y": -4,
      "z": 18,
      "name": "Rock_Volcanic_Cobble"
    },
    {
      "x": -23,
      "y": -3,
      "z": 18,
      "name": "Rock_Volcanic_Brick"
    },
    {
      "x": -23,
      "y": -2,
      "z": 18,
      "name": "Rock_Volcanic_Cobble"
    },
    {
      "x": -23,
      "y": -1,
      "z": 18,
      "name": "Rock_Volcanic_Brick"
    },
    {
      "x": -23,
      "y": 0,
      "z": 18,
      "name": "Rock_Volcanic_Brick"
    },
    {
      "x": -23,
      "y": 1,
      "z": 18,
      "name": "Rock_Volcanic_Brick"
    },
    {
      "x": -23,
      "y": 2,
      "z": 18,
      "name": "Rock_Volcanic_Cobble"
    },
    {
      "x": -23,
      "y": 3,
      "z": 18,
      "name": "Rock_Volcanic_Cobble"
    },
    {
      "x": -23,
      "y": 4,
      "z": 18,
      "name": "Rock_Volcanic_Brick_Stairs",
      "rotation": 3
    },
    {
      "x": -23,
      "y": -14,
      "z": 19,
      "name": "Rock_Volcanic_Brick"
    },
    {
      "x": -23,
      "y": -13,
      "z": 19,
      "name": "Rock_Volcanic_Cobble"
    },
    {
      "x": -23,
      "y": -12,
      "z": 19,
      "name": "Rock_Volcanic_Brick"
    },
    {
      "x": -23,
      "y": -11,
      "z": 19,
      "name": "Rock_Volcanic_Brick"
    },
    {
      "x": -23,
      "y": -10,
      "z": 19,
      "name": "Rock_Volcanic_Cobble"
    },
    {
      "x": -23,
      "y": -9,
      "z": 19,
      "name": "Rock_Volcanic_Cobble"
    },
    {
      "x": -23,
      "y": -8,
      "z": 19,
      "name": "Rock_Volcanic_Cobble"
    },
    {
      "x": -23,
      "y": -7,
      "z": 19,
      "name": "Rock_Volcanic_Brick"
    },
    {
      "x": -23,
      "y": -6,
      "z": 19,
      "name": "Rock_Volcanic_Brick"
    },
    {
      "x": -23,
      "y": -5,
      "z": 19,
      "name": "Rock_Volcanic_Brick"
    },
    {
      "x": -23,
      "y": -4,
      "z": 19,
      "name": "Rock_Volcanic_Brick"
    },
    {
      "x": -23,
      "y": -3,
      "z": 19,
      "name": "Rock_Volcanic_Cobble"
    },
    {
      "x": -23,
      "y": -2,
      "z": 19,
      "name": "Rock_Volcanic_Cobble"
    },
    {
      "x": -23,
      "y": -1,
      "z": 19,
      "name": "Rock_Volcanic_Brick"
    },
    {
      "x": -23,
      "y": 0,
      "z": 19,
      "name": "Rock_Volcanic_Brick"
    },
    {
      "x": -23,
      "y": 1,
      "z": 19,
      "name": "Rock_Volcanic_Brick"
    },
    {
      "x": -23,
      "y": 2,
      "z": 19,
      "name": "Rock_Volcanic_Brick"
    },
    {
      "x": -22,
      "y": -14,
      "z": -20,
      "name": "Rock_Volcanic_Cobble"
    },
    {
      "x": -22,
      "y": -13,
      "z": -20,
      "name": "Rock_Volcanic_Brick"
    },
    {
      "x": -22,
      "y": -12,
      "z": -20,
      "name": "Rock_Volcanic_Brick"
    },
    {
      "x": -22,
      "y": -11,
      "z": -20,
      "name": "Rock_Volcanic_Cobble"
    },
    {
      "x": -22,
      "y": -10,
      "z": -20,
      "name": "Rock_Volcanic_Brick"
    },
    {
      "x": -22,
      "y": -9,
      "z": -20,
      "name": "Rock_Volcanic_Brick"
    },
    {
      "x": -22,
      "y": -8,
      "z": -20,
      "name": "Rock_Volcanic_Cobble"
    },
    {
      "x": -22,
      "y": -7,
      "z": -20,
      "name": "Rock_Volcanic_Cobble"
    },
    {
      "x": -22,
      "y": -6,
      "z": -20,
      "name": "Rock_Volcanic_Brick"
    },
    {
      "x": -22,
      "y": -5,
      "z": -20,
      "name": "Rock_Volcanic_Brick"
    },
    {
      "x": -22,
      "y": -4,
      "z": -20,
      "name": "Rock_Volcanic_Cobble"
    },
    {
      "x": -22,
      "y": -3,
      "z": -20,
      "name": "Rock_Volcanic_Brick"
    },
    {
      "x": -22,
      "y": -2,
      "z": -20,
      "name": "Rock_Volcanic_Brick"
    },
    {
      "x": -22,
      "y": -1,
      "z": -20,
      "name": "Rock_Volcanic_Cobble"
    },
    {
      "x": -22,
      "y": 0,
      "z": -20,
      "name": "Rock_Volcanic_Brick"
    },
    {
      "x": -22,
      "y": 1,
      "z": -20,
      "name": "Rock_Volcanic_Brick"
    },
    {
      "x": -22,
      "y": 2,
      "z": -20,
      "name": "Rock_Volcanic_Brick"
    },
    {
      "x": -22,
      "y": 3,
      "z": -20,
      "name": "Rock_Volcanic_Brick"
    },
    {
      "x": -22,
      "y": -14,
      "z": -19,
      "name": "Rock_Volcanic_Cobble"
    },
    {
      "x": -22,
      "y": -13,
      "z": -19,
      "name": "Rock_Volcanic_Cobble"
    },
    {
      "x": -22,
      "y": -12,
      "z": -19,
      "name": "Rock_Volcanic_Cobble"
    },
    {
      "x": -22,
      "y": -11,
      "z": -19,
      "name": "Rock_Volcanic_Cobble"
    },
    {
      "x": -22,
      "y": -10,
      "z": -19,
      "name": "Rock_Volcanic_Brick"
    },
    {
      "x": -22,
      "y": -9,
      "z": -19,
      "name": "Rock_Volcanic_Cobble"
    },
    {
      "x": -22,
      "y": -8,
      "z": -19,
      "name": "Rock_Volcanic_Brick"
    },
    {
      "x": -22,
      "y": -7,
      "z": -19,
      "name": "Rock_Volcanic_Cobble"
    },
    {
      "x": -22,
      "y": -6,
      "z": -19,
      "name": "Rock_Volcanic_Cobble"
    },
    {
      "x": -22,
      "y": -5,
      "z": -19,
      "name": "Rock_Volcanic_Cobble"
    },
    {
      "x": -22,
      "y": -4,
      "z": -19,
      "name": "Rock_Volcanic_Brick"
    },
    {
      "x": -22,
      "y": -3,
      "z": -19,
      "name": "Rock_Volcanic_Cobble"
    },
    {
      "x": -22,
      "y": -2,
      "z": -19,
      "name": "Rock_Volcanic_Brick"
    },
    {
      "x": -22,
      "y": -1,
      "z": -19,
      "name": "Rock_Volcanic_Cobble"
    },
    {
      "x": -22,
      "y": 0,
      "z": -19,
      "name": "Rock_Volcanic_Cobble"
    },
    {
      "x": -22,
      "y": 1,
      "z": -19,
      "name": "Rock_Volcanic_Cobble"
    },
    {
      "x": -22,
      "y": 2,
      "z": -19,
      "name": "Rock_Volcanic_Brick"
    },
    {
      "x": -22,
      "y": 3,
      "z": -19,
      "name": "Rock_Volcanic_Brick"
    },
    {
      "x": -22,
      "y": -14,
      "z": -18,
      "name": "Rock_Volcanic_Brick"
    },
    {
      "x": -22,
      "y": -13,
      "z": -18,
      "name": "Rock_Volcanic_Cobble"
    },
    {
      "x": -22,
      "y": -12,
      "z": -18,
      "name": "Rock_Volcanic_Cobble"
    },
    {
      "x": -22,
      "y": -11,
      "z": -18,
      "name": "Rock_Volcanic_Cobble"
    },
    {
      "x": -22,
      "y": -10,
      "z": -18,
      "name": "Rock_Volcanic_Brick"
    },
    {
      "x": -22,
      "y": -9,
      "z": -18,
      "name": "Rock_Volcanic_Cobble"
    },
    {
      "x": -22,
      "y": -8,
      "z": -18,
      "name": "Rock_Volcanic_Cobble"
    },
    {
      "x": -22,
      "y": -7,
      "z": -18,
      "name": "Rock_Volcanic_Cobble"
    },
    {
      "x": -22,
      "y": -6,
      "z": -18,
      "name": "Rock_Volcanic_Brick"
    },
    {
      "x": -22,
      "y": -5,
      "z": -18,
      "name": "Rock_Volcanic_Cobble"
    },
    {
      "x": -22,
      "y": -4,
      "z": -18,
      "name": "Rock_Volcanic_Cobble"
    },
    {
      "x": -22,
      "y": -3,
      "z": -18,
      "name": "Rock_Volcanic_Cobble"
    },
    {
      "x": -22,
      "y": -2,
      "z": -18,
      "name": "Rock_Volcanic_Cobble"
    },
    {
      "x": -22,
      "y": -1,
      "z": -18,
      "name": "Rock_Volcanic_Cobble"
    },
    {
      "x": -22,
      "y": 0,
      "z": -18,
      "name": "Rock_Volcanic_Cobble"
    },
    {
      "x": -22,
      "y": 1,
      "z": -18,
      "name": "Rock_Volcanic_Brick"
    },
    {
      "x": -22,
      "y": 2,
      "z": -18,
      "name": "Rock_Volcanic_Brick"
    },
    {
      "x": -22,
      "y": 3,
      "z": -18,
      "name": "Rock_Volcanic_Brick"
    },
    {
      "x": -22,
      "y": -14,
      "z": -17,
      "name": "Rock_Volcanic_Cobble"
    },
    {
      "x": -22,
      "y": -13,
      "z": -17,
      "name": "Rock_Volcanic_Brick"
    },
    {
      "x": -22,
      "y": -12,
      "z": -17,
      "name": "Rock_Volcanic_Cobble"
    },
    {
      "x": -22,
      "y": -11,
      "z": -17,
      "name": "Rock_Volcanic_Brick"
    },
    {
      "x": -22,
      "y": -10,
      "z": -17,
      "name": "Rock_Volcanic_Cobble"
    },
    {
      "x": -22,
      "y": -9,
      "z": -17,
      "name": "Rock_Volcanic_Cobble"
    },
    {
      "x": -22,
      "y": -8,
      "z": -17,
      "name": "Rock_Volcanic_Cobble"
    },
    {
      "x": -22,
      "y": -7,
      "z": -17,
      "name": "Rock_Volcanic_Brick"
    },
    {
      "x": -22,
      "y": -6,
      "z": -17,
      "name": "Rock_Volcanic_Brick"
    },
    {
      "x": -22,
      "y": -5,
      "z": -17,
      "name": "Rock_Volcanic_Brick"
    },
    {
      "x": -22,
      "y": -4,
      "z": -17,
      "name": "Rock_Volcanic_Brick"
    },
    {
      "x": -22,
      "y": -3,
      "z": -17,
      "name": "Rock_Volcanic_Brick"
    },
    {
      "x": -22,
      "y": -2,
      "z": -17,
      "name": "Rock_Volcanic_Brick"
    },
    {
      "x": -22,
      "y": -1,
      "z": -17,
      "name": "Rock_Volcanic_Brick"
    },
    {
      "x": -22,
      "y": 0,
      "z": -17,
      "name": "Rock_Volcanic_Cobble"
    },
    {
      "x": -22,
      "y": 1,
      "z": -17,
      "name": "Rock_Volcanic_Cobble"
    },
    {
      "x": -22,
      "y": 2,
      "z": -17,
      "name": "Rock_Volcanic_Brick"
    },
    {
      "x": -22,
      "y": 3,
      "z": -17,
      "name": "Rock_Volcanic_Brick"
    },
    {
      "x": -22,
      "y": 4,
      "z": -17,
      "name": "Rock_Volcanic_Brick",
      "rotation": 2
    },
    {
      "x": -22,
      "y": 5,
      "z": -17,
      "name": "Rock_Volcanic_Brick",
      "rotation": 2
    },
    {
      "x": -22,
      "y": 6,
      "z": -17,
      "name": "Rock_Volcanic_Brick",
      "rotation": 2
    },
    {
      "x": -22,
      "y": 7,
      "z": -17,
      "name": "Rock_Volcanic_Brick",
      "rotation": 2
    },
    {
      "x": -22,
      "y": 8,
      "z": -17,
      "name": "Rock_Volcanic_Brick",
      "rotation": 2
    },
    {
      "x": -22,
      "y": 9,
      "z": -17,
      "name": "Rock_Volcanic_Brick_Stairs",
      "rotation": 3
    },
    {
      "x": -22,
      "y": -14,
      "z": -16,
      "name": "Rock_Volcanic_Brick"
    },
    {
      "x": -22,
      "y": -13,
      "z": -16,
      "name": "Rock_Volcanic_Brick"
    },
    {
      "x": -22,
      "y": -12,
      "z": -16,
      "name": "Rock_Volcanic_Brick"
    },
    {
      "x": -22,
      "y": -11,
      "z": -16,
      "name": "Rock_Volcanic_Cobble"
    },
    {
      "x": -22,
      "y": -10,
      "z": -16,
      "name": "Rock_Volcanic_Cobble"
    },
    {
      "x": -22,
      "y": -9,
      "z": -16,
      "name": "Rock_Volcanic_Brick"
    },
    {
      "x": -22,
      "y": -8,
      "z": -16,
      "name": "Rock_Volcanic_Cobble"
    },
    {
      "x": -22,
      "y": -7,
      "z": -16,
      "name": "Rock_Volcanic_Cobble"
    },
    {
      "x": -22,
      "y": -6,
      "z": -16,
      "name": "Rock_Volcanic_Brick"
    },
    {
      "x": -22,
      "y": -5,
      "z": -16,
      "name": "Rock_Volcanic_Cobble"
    },
    {
      "x": -22,
      "y": -4,
      "z": -16,
      "name": "Rock_Volcanic_Cobble"
    },
    {
      "x": -22,
      "y": -3,
      "z": -16,
      "name": "Rock_Volcanic_Cobble"
    },
    {
      "x": -22,
      "y": -2,
      "z": -16,
      "name": "Rock_Volcanic_Brick"
    },
    {
      "x": -22,
      "y": -1,
      "z": -16,
      "name": "Rock_Volcanic_Brick"
    },
    {
      "x": -22,
      "y": 0,
      "z": -16,
      "name": "Rock_Volcanic_Cobble"
    },
    {
      "x": -22,
      "y": 1,
      "z": -16,
      "name": "Rock_Volcanic_Brick"
    },
    {
      "x": -22,
      "y": 2,
      "z": -16,
      "name": "Rock_Volcanic_Brick"
    },
    {
      "x": -22,
      "y": 3,
      "z": -16,
      "name": "Rock_Volcanic_Cobble"
    },
    {
      "x": -22,
      "y": 4,
      "z": -16,
      "name": "Rock_Volcanic_Brick",
      "rotation": 2
    },
    {
      "x": -22,
      "y": 5,
      "z": -16,
      "name": "Rock_Volcanic_Brick",
      "rotation": 2
    },
    {
      "x": -22,
      "y": 6,
      "z": -16,
      "name": "Rock_Volcanic_Brick",
      "rotation": 2
    },
    {
      "x": -22,
      "y": 7,
      "z": -16,
      "name": "Rock_Volcanic_Brick",
      "rotation": 2
    },
    {
      "x": -22,
      "y": 8,
      "z": -16,
      "name": "Rock_Volcanic_Brick",
      "rotation": 2
    },
    {
      "x": -22,
      "y": 9,
      "z": -16,
      "name": "Rock_Volcanic_Brick",
      "rotation": 2
    },
    {
      "x": -22,
      "y": 10,
      "z": -16,
      "name": "Rock_Volcanic_Brick",
      "rotation": 2
    },
    {
      "x": -22,
      "y": 11,
      "z": -16,
      "name": "Rock_Volcanic_Brick",
      "rotation": 2
    },
    {
      "x": -22,
      "y": 12,
      "z": -16,
      "name": "Rock_Volcanic_Brick_Stairs",
      "rotation": 3
    },
    {
      "x": -22,
      "y": -14,
      "z": -15,
      "name": "Rock_Volcanic_Brick"
    },
    {
      "x": -22,
      "y": -13,
      "z": -15,
      "name": "Rock_Volcanic_Cobble"
    },
    {
      "x": -22,
      "y": -12,
      "z": -15,
      "name": "Rock_Volcanic_Cobble"
    },
    {
      "x": -22,
      "y": -11,
      "z": -15,
      "name": "Rock_Volcanic_Brick"
    },
    {
      "x": -22,
      "y": -10,
      "z": -15,
      "name": "Rock_Volcanic_Brick"
    },
    {
      "x": -22,
      "y": -9,
      "z": -15,
      "name": "Rock_Volcanic_Brick"
    },
    {
      "x": -22,
      "y": -8,
      "z": -15,
      "name": "Rock_Volcanic_Cobble"
    },
    {
      "x": -22,
      "y": -7,
      "z": -15,
      "name": "Rock_Volcanic_Cobble"
    },
    {
      "x": -22,
      "y": -6,
      "z": -15,
      "name": "Rock_Volcanic_Brick"
    },
    {
      "x": -22,
      "y": -5,
      "z": -15,
      "name": "Rock_Volcanic_Brick"
    },
    {
      "x": -22,
      "y": -4,
      "z": -15,
      "name": "Rock_Volcanic_Cobble"
    },
    {
      "x": -22,
      "y": -3,
      "z": -15,
      "name": "Rock_Volcanic_Brick"
    },
    {
      "x": -22,
      "y": -2,
      "z": -15,
      "name": "Rock_Volcanic_Brick"
    },
    {
      "x": -22,
      "y": -1,
      "z": -15,
      "name": "Rock_Volcanic_Cobble"
    },
    {
      "x": -22,
      "y": 0,
      "z": -15,
      "name": "Rock_Volcanic_Brick"
    },
    {
      "x": -22,
      "y": 1,
      "z": -15,
      "name": "Rock_Volcanic_Brick"
    },
    {
      "x": -22,
      "y": 2,
      "z": -15,
      "name": "Rock_Volcanic_Cobble"
    },
    {
      "x": -22,
      "y": 3,
      "z": -15,
      "name": "Rock_Volcanic_Cobble"
    },
    {
      "x": -22,
      "y": 4,
      "z": -15,
      "name": "Rock_Volcanic_Brick",
      "rotation": 2
    },
    {
      "x": -22,
      "y": 5,
      "z": -15,
      "name": "Rock_Volcanic_Brick",
      "rotation": 2
    },
    {
      "x": -22,
      "y": 6,
      "z": -15,
      "name": "Rock_Volcanic_Brick",
      "rotation": 2
    },
    {
      "x": -22,
      "y": 7,
      "z": -15,
      "name": "Wood_Burnt_Trunk"
    },
    {
      "x": -22,
      "y": 8,
      "z": -15,
      "name": "Rock_Volcanic_Brick",
      "rotation": 2
    },
    {
      "x": -22,
      "y": 9,
      "z": -15,
      "name": "Rock_Volcanic_Brick_Stairs",
      "rotation": 3
    },
    {
      "x": -22,
      "y": 12,
      "z": -15,
      "name": "Wood_Burnt_Trunk"
    },
    {
      "x": -22,
      "y": 18,
      "z": -15,
      "name": "Wood_Burnt_Trunk"
    },
    {
      "x": -22,
      "y": 19,
      "z": -15,
      "name": "Wood_Burnt_Trunk"
    },
    {
      "x": -22,
      "y": -14,
      "z": -14,
      "name": "Rock_Volcanic_Brick"
    },
    {
      "x": -22,
      "y": -13,
      "z": -14,
      "name": "Rock_Volcanic_Brick"
    },
    {
      "x": -22,
      "y": -12,
      "z": -14,
      "name": "Rock_Volcanic_Cobble"
    },
    {
      "x": -22,
      "y": -11,
      "z": -14,
      "name": "Rock_Volcanic_Cobble"
    },
    {
      "x": -22,
      "y": -10,
      "z": -14,
      "name": "Rock_Volcanic_Cobble"
    },
    {
      "x": -22,
      "y": -9,
      "z": -14,
      "name": "Rock_Volcanic_Cobble"
    },
    {
      "x": -22,
      "y": -8,
      "z": -14,
      "name": "Rock_Volcanic_Brick"
    },
    {
      "x": -22,
      "y": -7,
      "z": -14,
      "name": "Rock_Volcanic_Brick"
    },
    {
      "x": -22,
      "y": -6,
      "z": -14,
      "name": "Rock_Volcanic_Brick"
    },
    {
      "x": -22,
      "y": -5,
      "z": -14,
      "name": "Rock_Volcanic_Brick"
    },
    {
      "x": -22,
      "y": -4,
      "z": -14,
      "name": "Rock_Volcanic_Cobble"
    },
    {
      "x": -22,
      "y": -3,
      "z": -14,
      "name": "Rock_Volcanic_Brick"
    },
    {
      "x": -22,
      "y": -2,
      "z": -14,
      "name": "Rock_Volcanic_Cobble"
    },
    {
      "x": -22,
      "y": -1,
      "z": -14,
      "name": "Rock_Volcanic_Cobble"
    },
    {
      "x": -22,
      "y": 0,
      "z": -14,
      "name": "Rock_Volcanic_Brick"
    },
    {
      "x": -22,
      "y": 1,
      "z": -14,
      "name": "Rock_Volcanic_Cobble"
    },
    {
      "x": -22,
      "y": 2,
      "z": -14,
      "name": "Rock_Volcanic_Brick"
    },
    {
      "x": -22,
      "y": 3,
      "z": -14,
      "name": "Rock_Volcanic_Brick"
    },
    {
      "x": -22,
      "y": 7,
      "z": -14,
      "name": "Wood_Burnt_Trunk"
    },
    {
      "x": -22,
      "y": 8,
      "z": -14,
      "name": "Wood_Burnt_Trunk"
    },
    {
      "x": -22,
      "y": 12,
      "z": -14,
      "name": "Wood_Burnt_Trunk"
    },
    {
      "x": -22,
      "y": -14,
      "z": -13,
      "name": "Rock_Volcanic_Brick"
    },
    {
      "x": -22,
      "y": -13,
      "z": -13,
      "name": "Rock_Volcanic_Brick"
    },
    {
      "x": -22,
      "y": -12,
      "z": -13,
      "name": "Rock_Volcanic_Brick"
    },
    {
      "x": -22,
      "y": -11,
      "z": -13,
      "name": "Rock_Volcanic_Cobble"
    },
    {
      "x": -22,
      "y": -10,
      "z": -13,
      "name": "Rock_Volcanic_Cobble"
    },
    {
      "x": -22,
      "y": -9,
      "z": -13,
      "name": "Rock_Volcanic_Brick"
    },
    {
      "x": -22,
      "y": -8,
      "z": -13,
      "name": "Rock_Volcanic_Cobble"
    },
    {
      "x": -22,
      "y": -7,
      "z": -13,
      "name": "Rock_Volcanic_Cobble"
    },
    {
      "x": -22,
      "y": -6,
      "z": -13,
      "name": "Rock_Volcanic_Brick"
    },
    {
      "x": -22,
      "y": -5,
      "z": -13,
      "name": "Rock_Volcanic_Cobble"
    },
    {
      "x": -22,
      "y": -4,
      "z": -13,
      "name": "Rock_Volcanic_Cobble"
    },
    {
      "x": -22,
      "y": -3,
      "z": -13,
      "name": "Rock_Volcanic_Cobble"
    },
    {
      "x": -22,
      "y": -2,
      "z": -13,
      "name": "Rock_Volcanic_Brick"
    },
    {
      "x": -22,
      "y": -1,
      "z": -13,
      "name": "Rock_Volcanic_Cobble"
    },
    {
      "x": -22,
      "y": 0,
      "z": -13,
      "name": "Rock_Volcanic_Cobble"
    },
    {
      "x": -22,
      "y": 1,
      "z": -13,
      "name": "Rock_Volcanic_Cobble"
    },
    {
      "x": -22,
      "y": 2,
      "z": -13,
      "name": "Rock_Volcanic_Cobble"
    },
    {
      "x": -22,
      "y": 3,
      "z": -13,
      "name": "Rock_Volcanic_Brick"
    },
    {
      "x": -22,
      "y": 7,
      "z": -13,
      "name": "Wood_Burnt_Trunk"
    },
    {
      "x": -22,
      "y": 12,
      "z": -13,
      "name": "Wood_Burnt_Trunk"
    },
    {
      "x": -22,
      "y": -14,
      "z": -12,
      "name": "Rock_Volcanic_Cobble"
    },
    {
      "x": -22,
      "y": -13,
      "z": -12,
      "name": "Rock_Volcanic_Cobble"
    },
    {
      "x": -22,
      "y": -12,
      "z": -12,
      "name": "Rock_Volcanic_Brick"
    },
    {
      "x": -22,
      "y": -11,
      "z": -12,
      "name": "Rock_Volcanic_Cobble"
    },
    {
      "x": -22,
      "y": -10,
      "z": -12,
      "name": "Rock_Volcanic_Cobble"
    },
    {
      "x": -22,
      "y": -9,
      "z": -12,
      "name": "Rock_Volcanic_Brick"
    },
    {
      "x": -22,
      "y": -8,
      "z": -12,
      "name": "Rock_Volcanic_Brick"
    },
    {
      "x": -22,
      "y": -7,
      "z": -12,
      "name": "Rock_Volcanic_Cobble"
    },
    {
      "x": -22,
      "y": -6,
      "z": -12,
      "name": "Rock_Volcanic_Cobble"
    },
    {
      "x": -22,
      "y": -5,
      "z": -12,
      "name": "Rock_Volcanic_Brick"
    },
    {
      "x": -22,
      "y": -4,
      "z": -12,
      "name": "Rock_Volcanic_Brick"
    },
    {
      "x": -22,
      "y": -3,
      "z": -12,
      "name": "Rock_Volcanic_Cobble"
    },
    {
      "x": -22,
      "y": -2,
      "z": -12,
      "name": "Rock_Volcanic_Cobble"
    },
    {
      "x": -22,
      "y": -1,
      "z": -12,
      "name": "Rock_Volcanic_Brick"
    },
    {
      "x": -22,
      "y": 0,
      "z": -12,
      "name": "Rock_Volcanic_Cobble"
    },
    {
      "x": -22,
      "y": 1,
      "z": -12,
      "name": "Rock_Volcanic_Brick"
    },
    {
      "x": -22,
      "y": 2,
      "z": -12,
      "name": "Rock_Volcanic_Cobble"
    },
    {
      "x": -22,
      "y": 3,
      "z": -12,
      "name": "Rock_Volcanic_Brick"
    },
    {
      "x": -22,
      "y": -14,
      "z": 13,
      "name": "Rock_Volcanic_Brick"
    },
    {
      "x": -22,
      "y": -13,
      "z": 13,
      "name": "Rock_Volcanic_Cobble"
    },
    {
      "x": -22,
      "y": -12,
      "z": 13,
      "name": "Rock_Volcanic_Brick"
    },
    {
      "x": -22,
      "y": -11,
      "z": 13,
      "name": "Rock_Volcanic_Brick"
    },
    {
      "x": -22,
      "y": -10,
      "z": 13,
      "name": "Rock_Volcanic_Brick"
    },
    {
      "x": -22,
      "y": -9,
      "z": 13,
      "name": "Rock_Volcanic_Cobble"
    },
    {
      "x": -22,
      "y": -8,
      "z": 13,
      "name": "Rock_Volcanic_Brick"
    },
    {
      "x": -22,
      "y": -7,
      "z": 13,
      "name": "Rock_Volcanic_Brick"
    },
    {
      "x": -22,
      "y": -6,
      "z": 13,
      "name": "Rock_Volcanic_Brick"
    },
    {
      "x": -22,
      "y": -5,
      "z": 13,
      "name": "Rock_Volcanic_Brick"
    },
    {
      "x": -22,
      "y": -4,
      "z": 13,
      "name": "Rock_Volcanic_Brick"
    },
    {
      "x": -22,
      "y": -3,
      "z": 13,
      "name": "Rock_Volcanic_Cobble"
    },
    {
      "x": -22,
      "y": -2,
      "z": 13,
      "name": "Rock_Volcanic_Brick"
    },
    {
      "x": -22,
      "y": -1,
      "z": 13,
      "name": "Rock_Volcanic_Cobble"
    },
    {
      "x": -22,
      "y": 0,
      "z": 13,
      "name": "Rock_Volcanic_Cobble"
    },
    {
      "x": -22,
      "y": 1,
      "z": 13,
      "name": "Rock_Volcanic_Cobble"
    },
    {
      "x": -22,
      "y": 2,
      "z": 13,
      "name": "Rock_Volcanic_Cobble"
    },
    {
      "x": -22,
      "y": -14,
      "z": 14,
      "name": "Rock_Volcanic_Brick"
    },
    {
      "x": -22,
      "y": -13,
      "z": 14,
      "name": "Rock_Volcanic_Brick"
    },
    {
      "x": -22,
      "y": -12,
      "z": 14,
      "name": "Rock_Volcanic_Brick"
    },
    {
      "x": -22,
      "y": -11,
      "z": 14,
      "name": "Rock_Volcanic_Cobble"
    },
    {
      "x": -22,
      "y": -10,
      "z": 14,
      "name": "Rock_Volcanic_Cobble"
    },
    {
      "x": -22,
      "y": -9,
      "z": 14,
      "name": "Rock_Volcanic_Brick"
    },
    {
      "x": -22,
      "y": -8,
      "z": 14,
      "name": "Rock_Volcanic_Brick"
    },
    {
      "x": -22,
      "y": -7,
      "z": 14,
      "name": "Rock_Volcanic_Cobble"
    },
    {
      "x": -22,
      "y": -6,
      "z": 14,
      "name": "Rock_Volcanic_Brick"
    },
    {
      "x": -22,
      "y": -5,
      "z": 14,
      "name": "Rock_Volcanic_Brick"
    },
    {
      "x": -22,
      "y": -4,
      "z": 14,
      "name": "Rock_Volcanic_Cobble"
    },
    {
      "x": -22,
      "y": -3,
      "z": 14,
      "name": "Rock_Volcanic_Brick"
    },
    {
      "x": -22,
      "y": -2,
      "z": 14,
      "name": "Rock_Volcanic_Brick"
    },
    {
      "x": -22,
      "y": -1,
      "z": 14,
      "name": "Rock_Volcanic_Cobble"
    },
    {
      "x": -22,
      "y": 0,
      "z": 14,
      "name": "Rock_Volcanic_Brick"
    },
    {
      "x": -22,
      "y": 1,
      "z": 14,
      "name": "Rock_Volcanic_Brick"
    },
    {
      "x": -22,
      "y": 2,
      "z": 14,
      "name": "Rock_Volcanic_Brick"
    },
    {
      "x": -22,
      "y": -14,
      "z": 15,
      "name": "Rock_Volcanic_Cobble"
    },
    {
      "x": -22,
      "y": -13,
      "z": 15,
      "name": "Rock_Volcanic_Brick"
    },
    {
      "x": -22,
      "y": -12,
      "z": 15,
      "name": "Rock_Volcanic_Cobble"
    },
    {
      "x": -22,
      "y": -11,
      "z": 15,
      "name": "Rock_Volcanic_Cobble"
    },
    {
      "x": -22,
      "y": -10,
      "z": 15,
      "name": "Rock_Volcanic_Brick"
    },
    {
      "x": -22,
      "y": -9,
      "z": 15,
      "name": "Rock_Volcanic_Brick"
    },
    {
      "x": -22,
      "y": -8,
      "z": 15,
      "name": "Rock_Volcanic_Cobble"
    },
    {
      "x": -22,
      "y": -7,
      "z": 15,
      "name": "Rock_Volcanic_Cobble"
    },
    {
      "x": -22,
      "y": -6,
      "z": 15,
      "name": "Rock_Volcanic_Brick"
    },
    {
      "x": -22,
      "y": -5,
      "z": 15,
      "name": "Rock_Volcanic_Brick"
    },
    {
      "x": -22,
      "y": -4,
      "z": 15,
      "name": "Rock_Volcanic_Brick"
    },
    {
      "x": -22,
      "y": -3,
      "z": 15,
      "name": "Rock_Volcanic_Brick"
    },
    {
      "x": -22,
      "y": -2,
      "z": 15,
      "name": "Rock_Volcanic_Brick"
    },
    {
      "x": -22,
      "y": -1,
      "z": 15,
      "name": "Rock_Volcanic_Cobble"
    },
    {
      "x": -22,
      "y": 0,
      "z": 15,
      "name": "Rock_Volcanic_Brick"
    },
    {
      "x": -22,
      "y": 1,
      "z": 15,
      "name": "Rock_Volcanic_Brick"
    },
    {
      "x": -22,
      "y": 2,
      "z": 15,
      "name": "Rock_Volcanic_Cobble"
    },
    {
      "x": -22,
      "y": -14,
      "z": 16,
      "name": "Rock_Volcanic_Brick"
    },
    {
      "x": -22,
      "y": -13,
      "z": 16,
      "name": "Rock_Volcanic_Cobble"
    },
    {
      "x": -22,
      "y": -12,
      "z": 16,
      "name": "Rock_Volcanic_Cobble"
    },
    {
      "x": -22,
      "y": -11,
      "z": 16,
      "name": "Rock_Volcanic_Cobble"
    },
    {
      "x": -22,
      "y": -10,
      "z": 16,
      "name": "Rock_Volcanic_Cobble"
    },
    {
      "x": -22,
      "y": -9,
      "z": 16,
      "name": "Rock_Volcanic_Brick"
    },
    {
      "x": -22,
      "y": -8,
      "z": 16,
      "name": "Rock_Volcanic_Cobble"
    },
    {
      "x": -22,
      "y": -7,
      "z": 16,
      "name": "Rock_Volcanic_Cobble"
    },
    {
      "x": -22,
      "y": -6,
      "z": 16,
      "name": "Rock_Volcanic_Brick"
    },
    {
      "x": -22,
      "y": -5,
      "z": 16,
      "name": "Rock_Volcanic_Cobble"
    },
    {
      "x": -22,
      "y": -4,
      "z": 16,
      "name": "Rock_Volcanic_Brick"
    },
    {
      "x": -22,
      "y": -3,
      "z": 16,
      "name": "Rock_Volcanic_Cobble"
    },
    {
      "x": -22,
      "y": -2,
      "z": 16,
      "name": "Rock_Volcanic_Cobble"
    },
    {
      "x": -22,
      "y": -1,
      "z": 16,
      "name": "Rock_Volcanic_Brick"
    },
    {
      "x": -22,
      "y": 0,
      "z": 16,
      "name": "Rock_Volcanic_Cobble"
    },
    {
      "x": -22,
      "y": 1,
      "z": 16,
      "name": "Rock_Volcanic_Cobble"
    },
    {
      "x": -22,
      "y": 2,
      "z": 16,
      "name": "Rock_Volcanic_Cobble"
    },
    {
      "x": -22,
      "y": 3,
      "z": 16,
      "name": "Rock_Volcanic_Cobble"
    },
    {
      "x": -22,
      "y": 4,
      "z": 16,
      "name": "Rock_Volcanic_Brick",
      "rotation": 3
    },
    {
      "x": -22,
      "y": 5,
      "z": 16,
      "name": "Rock_Volcanic_Brick",
      "rotation": 3
    },
    {
      "x": -22,
      "y": 6,
      "z": 16,
      "name": "Rock_Volcanic_Brick",
      "rotation": 3
    },
    {
      "x": -22,
      "y": 7,
      "z": 16,
      "name": "Rock_Volcanic_Brick",
      "rotation": 3
    },
    {
      "x": -22,
      "y": 8,
      "z": 16,
      "name": "Rock_Volcanic_Brick",
      "rotation": 3
    },
    {
      "x": -22,
      "y": -14,
      "z": 17,
      "name": "Rock_Volcanic_Cobble"
    },
    {
      "x": -22,
      "y": -13,
      "z": 17,
      "name": "Rock_Volcanic_Brick"
    },
    {
      "x": -22,
      "y": -12,
      "z": 17,
      "name": "Rock_Volcanic_Cobble"
    },
    {
      "x": -22,
      "y": -11,
      "z": 17,
      "name": "Rock_Volcanic_Brick"
    },
    {
      "x": -22,
      "y": -10,
      "z": 17,
      "name": "Rock_Volcanic_Cobble"
    },
    {
      "x": -22,
      "y": -9,
      "z": 17,
      "name": "Rock_Volcanic_Cobble"
    },
    {
      "x": -22,
      "y": -8,
      "z": 17,
      "name": "Rock_Volcanic_Brick"
    },
    {
      "x": -22,
      "y": -7,
      "z": 17,
      "name": "Rock_Volcanic_Brick"
    },
    {
      "x": -22,
      "y": -6,
      "z": 17,
      "name": "Rock_Volcanic_Brick"
    },
    {
      "x": -22,
      "y": -5,
      "z": 17,
      "name": "Rock_Volcanic_Brick"
    },
    {
      "x": -22,
      "y": -4,
      "z": 17,
      "name": "Rock_Volcanic_Brick"
    },
    {
      "x": -22,
      "y": -3,
      "z": 17,
      "name": "Rock_Volcanic_Cobble"
    },
    {
      "x": -22,
      "y": -2,
      "z": 17,
      "name": "Rock_Volcanic_Cobble"
    },
    {
      "x": -22,
      "y": -1,
      "z": 17,
      "name": "Rock_Volcanic_Cobble"
    },
    {
      "x": -22,
      "y": 0,
      "z": 17,
      "name": "Rock_Volcanic_Cobble"
    },
    {
      "x": -22,
      "y": 1,
      "z": 17,
      "name": "Rock_Volcanic_Brick"
    },
    {
      "x": -22,
      "y": 2,
      "z": 17,
      "name": "Rock_Volcanic_Cobble"
    },
    {
      "x": -22,
      "y": 3,
      "z": 17,
      "name": "Rock_Volcanic_Cobble"
    },
    {
      "x": -22,
      "y": 4,
      "z": 17,
      "name": "Rock_Volcanic_Brick",
      "rotation": 3
    },
    {
      "x": -22,
      "y": 5,
      "z": 17,
      "name": "Rock_Volcanic_Brick",
      "rotation": 3
    },
    {
      "x": -22,
      "y": 6,
      "z": 17,
      "name": "Rock_Volcanic_Brick",
      "rotation": 3
    },
    {
      "x": -22,
      "y": 7,
      "z": 17,
      "name": "Rock_Volcanic_Brick",
      "rotation": 3
    },
    {
      "x": -22,
      "y": 8,
      "z": 17,
      "name": "Rock_Volcanic_Brick",
      "rotation": 3
    },
    {
      "x": -22,
      "y": 9,
      "z": 17,
      "name": "Rock_Volcanic_Brick",
      "rotation": 3
    },
    {
      "x": -22,
      "y": 10,
      "z": 17,
      "name": "Rock_Volcanic_Cobble_Half"
    },
    {
      "x": -22,
      "y": -14,
      "z": 18,
      "name": "Rock_Volcanic_Cobble"
    },
    {
      "x": -22,
      "y": -13,
      "z": 18,
      "name": "Rock_Volcanic_Brick"
    },
    {
      "x": -22,
      "y": -12,
      "z": 18,
      "name": "Rock_Volcanic_Brick"
    },
    {
      "x": -22,
      "y": -11,
      "z": 18,
      "name": "Rock_Volcanic_Brick"
    },
    {
      "x": -22,
      "y": -10,
      "z": 18,
      "name": "Rock_Volcanic_Cobble"
    },
    {
      "x": -22,
      "y": -9,
      "z": 18,
      "name": "Rock_Volcanic_Brick"
    },
    {
      "x": -22,
      "y": -8,
      "z": 18,
      "name": "Rock_Volcanic_Cobble"
    },
    {
      "x": -22,
      "y": -7,
      "z": 18,
      "name": "Rock_Volcanic_Brick"
    },
    {
      "x": -22,
      "y": -6,
      "z": 18,
      "name": "Rock_Volcanic_Cobble"
    },
    {
      "x": -22,
      "y": -5,
      "z": 18,
      "name": "Rock_Volcanic_Brick"
    },
    {
      "x": -22,
      "y": -4,
      "z": 18,
      "name": "Rock_Volcanic_Brick"
    },
    {
      "x": -22,
      "y": -3,
      "z": 18,
      "name": "Rock_Volcanic_Brick"
    },
    {
      "x": -22,
      "y": -2,
      "z": 18,
      "name": "Rock_Volcanic_Brick"
    },
    {
      "x": -22,
      "y": -1,
      "z": 18,
      "name": "Rock_Volcanic_Cobble"
    },
    {
      "x": -22,
      "y": 0,
      "z": 18,
      "name": "Rock_Volcanic_Brick"
    },
    {
      "x": -22,
      "y": 1,
      "z": 18,
      "name": "Rock_Volcanic_Brick"
    },
    {
      "x": -22,
      "y": 2,
      "z": 18,
      "name": "Rock_Volcanic_Cobble"
    },
    {
      "x": -22,
      "y": 3,
      "z": 18,
      "name": "Rock_Volcanic_Cobble"
    },
    {
      "x": -22,
      "y": 4,
      "z": 18,
      "name": "Rock_Volcanic_Brick",
      "rotation": 3
    },
    {
      "x": -22,
      "y": 5,
      "z": 18,
      "name": "Rock_Volcanic_Brick",
      "rotation": 3
    },
    {
      "x": -22,
      "y": 6,
      "z": 18,
      "name": "Rock_Volcanic_Brick",
      "rotation": 3
    },
    {
      "x": -22,
      "y": 7,
      "z": 18,
      "name": "Rock_Volcanic_Brick",
      "rotation": 3
    },
    {
      "x": -22,
      "y": 8,
      "z": 18,
      "name": "Rock_Volcanic_Brick",
      "rotation": 3
    },
    {
      "x": -22,
      "y": 9,
      "z": 18,
      "name": "Rock_Volcanic_Brick_Stairs",
      "rotation": 3
    },
    {
      "x": -22,
      "y": -14,
      "z": 19,
      "name": "Rock_Volcanic_Brick"
    },
    {
      "x": -22,
      "y": -13,
      "z": 19,
      "name": "Rock_Volcanic_Cobble"
    },
    {
      "x": -22,
      "y": -12,
      "z": 19,
      "name": "Rock_Volcanic_Brick"
    },
    {
      "x": -22,
      "y": -11,
      "z": 19,
      "name": "Rock_Volcanic_Cobble"
    },
    {
      "x": -22,
      "y": -10,
      "z": 19,
      "name": "Rock_Volcanic_Brick"
    },
    {
      "x": -22,
      "y": -9,
      "z": 19,
      "name": "Rock_Volcanic_Cobble"
    },
    {
      "x": -22,
      "y": -8,
      "z": 19,
      "name": "Rock_Volcanic_Brick"
    },
    {
      "x": -22,
      "y": -7,
      "z": 19,
      "name": "Rock_Volcanic_Brick"
    },
    {
      "x": -22,
      "y": -6,
      "z": 19,
      "name": "Rock_Volcanic_Brick"
    },
    {
      "x": -22,
      "y": -5,
      "z": 19,
      "name": "Rock_Volcanic_Cobble"
    },
    {
      "x": -22,
      "y": -4,
      "z": 19,
      "name": "Rock_Volcanic_Brick"
    },
    {
      "x": -22,
      "y": -3,
      "z": 19,
      "name": "Rock_Volcanic_Brick"
    },
    {
      "x": -22,
      "y": -2,
      "z": 19,
      "name": "Rock_Volcanic_Brick"
    },
    {
      "x": -22,
      "y": -1,
      "z": 19,
      "name": "Rock_Volcanic_Brick"
    },
    {
      "x": -22,
      "y": 0,
      "z": 19,
      "name": "Rock_Volcanic_Cobble"
    },
    {
      "x": -22,
      "y": 1,
      "z": 19,
      "name": "Rock_Volcanic_Cobble"
    },
    {
      "x": -22,
      "y": 2,
      "z": 19,
      "name": "Rock_Volcanic_Cobble"
    },
    {
      "x": -22,
      "y": -14,
      "z": 20,
      "name": "Rock_Volcanic_Cobble"
    },
    {
      "x": -22,
      "y": -13,
      "z": 20,
      "name": "Rock_Volcanic_Brick"
    },
    {
      "x": -22,
      "y": -12,
      "z": 20,
      "name": "Rock_Volcanic_Brick"
    },
    {
      "x": -22,
      "y": -11,
      "z": 20,
      "name": "Rock_Volcanic_Cobble"
    },
    {
      "x": -22,
      "y": -10,
      "z": 20,
      "name": "Rock_Volcanic_Cobble"
    },
    {
      "x": -22,
      "y": -9,
      "z": 20,
      "name": "Rock_Volcanic_Cobble"
    },
    {
      "x": -22,
      "y": -8,
      "z": 20,
      "name": "Rock_Volcanic_Cobble"
    },
    {
      "x": -22,
      "y": -7,
      "z": 20,
      "name": "Rock_Volcanic_Cobble"
    },
    {
      "x": -22,
      "y": -6,
      "z": 20,
      "name": "Rock_Volcanic_Brick"
    },
    {
      "x": -22,
      "y": -5,
      "z": 20,
      "name": "Rock_Volcanic_Cobble"
    },
    {
      "x": -22,
      "y": -4,
      "z": 20,
      "name": "Rock_Volcanic_Brick"
    },
    {
      "x": -22,
      "y": -3,
      "z": 20,
      "name": "Rock_Volcanic_Brick"
    },
    {
      "x": -22,
      "y": -2,
      "z": 20,
      "name": "Rock_Volcanic_Brick"
    },
    {
      "x": -22,
      "y": -1,
      "z": 20,
      "name": "Rock_Volcanic_Brick"
    },
    {
      "x": -22,
      "y": 0,
      "z": 20,
      "name": "Rock_Volcanic_Cobble"
    },
    {
      "x": -22,
      "y": 1,
      "z": 20,
      "name": "Rock_Volcanic_Cobble"
    },
    {
      "x": -22,
      "y": 2,
      "z": 20,
      "name": "Rock_Volcanic_Cobble"
    },
    {
      "x": -22,
      "y": -14,
      "z": 21,
      "name": "Rock_Volcanic_Brick"
    },
    {
      "x": -22,
      "y": -13,
      "z": 21,
      "name": "Rock_Volcanic_Cobble"
    },
    {
      "x": -22,
      "y": -12,
      "z": 21,
      "name": "Rock_Volcanic_Cobble"
    },
    {
      "x": -22,
      "y": -11,
      "z": 21,
      "name": "Rock_Volcanic_Cobble"
    },
    {
      "x": -22,
      "y": -10,
      "z": 21,
      "name": "Rock_Volcanic_Cobble"
    },
    {
      "x": -22,
      "y": -9,
      "z": 21,
      "name": "Rock_Volcanic_Cobble"
    },
    {
      "x": -22,
      "y": -8,
      "z": 21,
      "name": "Rock_Volcanic_Brick"
    },
    {
      "x": -22,
      "y": -7,
      "z": 21,
      "name": "Rock_Volcanic_Cobble"
    },
    {
      "x": -22,
      "y": -6,
      "z": 21,
      "name": "Rock_Volcanic_Brick"
    },
    {
      "x": -22,
      "y": -5,
      "z": 21,
      "name": "Rock_Volcanic_Cobble"
    },
    {
      "x": -22,
      "y": -4,
      "z": 21,
      "name": "Rock_Volcanic_Brick"
    },
    {
      "x": -22,
      "y": -3,
      "z": 21,
      "name": "Rock_Volcanic_Brick"
    },
    {
      "x": -22,
      "y": -2,
      "z": 21,
      "name": "Rock_Volcanic_Brick"
    },
    {
      "x": -22,
      "y": -1,
      "z": 21,
      "name": "Rock_Volcanic_Cobble"
    },
    {
      "x": -22,
      "y": 0,
      "z": 21,
      "name": "Rock_Volcanic_Brick"
    },
    {
      "x": -22,
      "y": 1,
      "z": 21,
      "name": "Rock_Volcanic_Brick"
    },
    {
      "x": -22,
      "y": 2,
      "z": 21,
      "name": "Rock_Volcanic_Brick"
    },
    {
      "x": -21,
      "y": -14,
      "z": -21,
      "name": "Rock_Volcanic_Brick"
    },
    {
      "x": -21,
      "y": -13,
      "z": -21,
      "name": "Rock_Volcanic_Brick"
    },
    {
      "x": -21,
      "y": -12,
      "z": -21,
      "name": "Rock_Volcanic_Brick"
    },
    {
      "x": -21,
      "y": -11,
      "z": -21,
      "name": "Rock_Volcanic_Cobble"
    },
    {
      "x": -21,
      "y": -10,
      "z": -21,
      "name": "Rock_Volcanic_Brick"
    },
    {
      "x": -21,
      "y": -9,
      "z": -21,
      "name": "Rock_Volcanic_Brick"
    },
    {
      "x": -21,
      "y": -8,
      "z": -21,
      "name": "Rock_Volcanic_Cobble"
    },
    {
      "x": -21,
      "y": -7,
      "z": -21,
      "name": "Rock_Volcanic_Brick"
    },
    {
      "x": -21,
      "y": -6,
      "z": -21,
      "name": "Rock_Volcanic_Cobble"
    },
    {
      "x": -21,
      "y": -5,
      "z": -21,
      "name": "Rock_Volcanic_Cobble"
    },
    {
      "x": -21,
      "y": -4,
      "z": -21,
      "name": "Rock_Volcanic_Brick"
    },
    {
      "x": -21,
      "y": -3,
      "z": -21,
      "name": "Rock_Volcanic_Brick"
    },
    {
      "x": -21,
      "y": -2,
      "z": -21,
      "name": "Rock_Volcanic_Cobble"
    },
    {
      "x": -21,
      "y": -1,
      "z": -21,
      "name": "Rock_Volcanic_Cobble"
    },
    {
      "x": -21,
      "y": 0,
      "z": -21,
      "name": "Rock_Volcanic_Cobble"
    },
    {
      "x": -21,
      "y": 1,
      "z": -21,
      "name": "Rock_Volcanic_Brick"
    },
    {
      "x": -21,
      "y": 2,
      "z": -21,
      "name": "Rock_Volcanic_Brick"
    },
    {
      "x": -21,
      "y": 3,
      "z": -21,
      "name": "Rock_Volcanic_Brick"
    },
    {
      "x": -21,
      "y": -14,
      "z": -20,
      "name": "Rock_Volcanic_Cobble"
    },
    {
      "x": -21,
      "y": -13,
      "z": -20,
      "name": "Rock_Volcanic_Brick"
    },
    {
      "x": -21,
      "y": -12,
      "z": -20,
      "name": "Rock_Volcanic_Brick"
    },
    {
      "x": -21,
      "y": -11,
      "z": -20,
      "name": "Rock_Volcanic_Brick"
    },
    {
      "x": -21,
      "y": -10,
      "z": -20,
      "name": "Rock_Volcanic_Brick"
    },
    {
      "x": -21,
      "y": -9,
      "z": -20,
      "name": "Rock_Volcanic_Brick"
    },
    {
      "x": -21,
      "y": -8,
      "z": -20,
      "name": "Rock_Volcanic_Brick"
    },
    {
      "x": -21,
      "y": -7,
      "z": -20,
      "name": "Rock_Volcanic_Cobble"
    },
    {
      "x": -21,
      "y": -6,
      "z": -20,
      "name": "Rock_Volcanic_Cobble"
    },
    {
      "x": -21,
      "y": -5,
      "z": -20,
      "name": "Rock_Volcanic_Brick"
    },
    {
      "x": -21,
      "y": -4,
      "z": -20,
      "name": "Rock_Volcanic_Cobble"
    },
    {
      "x": -21,
      "y": -3,
      "z": -20,
      "name": "Rock_Volcanic_Brick"
    },
    {
      "x": -21,
      "y": -2,
      "z": -20,
      "name": "Rock_Volcanic_Cobble"
    },
    {
      "x": -21,
      "y": -1,
      "z": -20,
      "name": "Rock_Volcanic_Cobble"
    },
    {
      "x": -21,
      "y": 0,
      "z": -20,
      "name": "Rock_Volcanic_Cobble"
    },
    {
      "x": -21,
      "y": 1,
      "z": -20,
      "name": "Rock_Volcanic_Cobble"
    },
    {
      "x": -21,
      "y": 2,
      "z": -20,
      "name": "Rock_Volcanic_Brick"
    },
    {
      "x": -21,
      "y": 3,
      "z": -20,
      "name": "Rock_Volcanic_Brick"
    },
    {
      "x": -21,
      "y": -14,
      "z": -19,
      "name": "Rock_Volcanic_Cobble"
    },
    {
      "x": -21,
      "y": -13,
      "z": -19,
      "name": "Rock_Volcanic_Cobble"
    },
    {
      "x": -21,
      "y": -12,
      "z": -19,
      "name": "Rock_Volcanic_Cobble"
    },
    {
      "x": -21,
      "y": -11,
      "z": -19,
      "name": "Rock_Volcanic_Brick"
    },
    {
      "x": -21,
      "y": -10,
      "z": -19,
      "name": "Rock_Volcanic_Brick"
    },
    {
      "x": -21,
      "y": -9,
      "z": -19,
      "name": "Rock_Volcanic_Brick"
    },
    {
      "x": -21,
      "y": -8,
      "z": -19,
      "name": "Rock_Volcanic_Brick"
    },
    {
      "x": -21,
      "y": -7,
      "z": -19,
      "name": "Rock_Volcanic_Cobble"
    },
    {
      "x": -21,
      "y": -6,
      "z": -19,
      "name": "Rock_Volcanic_Cobble"
    },
    {
      "x": -21,
      "y": -5,
      "z": -19,
      "name": "Rock_Volcanic_Cobble"
    },
    {
      "x": -21,
      "y": -4,
      "z": -19,
      "name": "Rock_Volcanic_Brick"
    },
    {
      "x": -21,
      "y": -3,
      "z": -19,
      "name": "Rock_Volcanic_Cobble"
    },
    {
      "x": -21,
      "y": -2,
      "z": -19,
      "name": "Rock_Volcanic_Brick"
    },
    {
      "x": -21,
      "y": -1,
      "z": -19,
      "name": "Rock_Volcanic_Cobble"
    },
    {
      "x": -21,
      "y": 0,
      "z": -19,
      "name": "Rock_Volcanic_Brick"
    },
    {
      "x": -21,
      "y": 1,
      "z": -19,
      "name": "Rock_Volcanic_Brick"
    },
    {
      "x": -21,
      "y": 2,
      "z": -19,
      "name": "Rock_Volcanic_Cobble"
    },
    {
      "x": -21,
      "y": 3,
      "z": -19,
      "name": "Rock_Volcanic_Cobble"
    },
    {
      "x": -21,
      "y": -14,
      "z": -18,
      "name": "Rock_Volcanic_Brick"
    },
    {
      "x": -21,
      "y": -13,
      "z": -18,
      "name": "Rock_Volcanic_Cobble"
    },
    {
      "x": -21,
      "y": -12,
      "z": -18,
      "name": "Rock_Volcanic_Brick"
    },
    {
      "x": -21,
      "y": -11,
      "z": -18,
      "name": "Rock_Volcanic_Brick"
    },
    {
      "x": -21,
      "y": -10,
      "z": -18,
      "name": "Rock_Volcanic_Brick"
    },
    {
      "x": -21,
      "y": -9,
      "z": -18,
      "name": "Rock_Volcanic_Brick"
    },
    {
      "x": -21,
      "y": -8,
      "z": -18,
      "name": "Rock_Volcanic_Brick"
    },
    {
      "x": -21,
      "y": -7,
      "z": -18,
      "name": "Rock_Volcanic_Brick"
    },
    {
      "x": -21,
      "y": -6,
      "z": -18,
      "name": "Rock_Volcanic_Cobble"
    },
    {
      "x": -21,
      "y": -5,
      "z": -18,
      "name": "Rock_Volcanic_Brick"
    },
    {
      "x": -21,
      "y": -4,
      "z": -18,
      "name": "Rock_Volcanic_Brick"
    },
    {
      "x": -21,
      "y": -3,
      "z": -18,
      "name": "Rock_Volcanic_Cobble"
    },
    {
      "x": -21,
      "y": -2,
      "z": -18,
      "name": "Rock_Volcanic_Cobble"
    },
    {
      "x": -21,
      "y": -1,
      "z": -18,
      "name": "Rock_Volcanic_Brick"
    },
    {
      "x": -21,
      "y": 0,
      "z": -18,
      "name": "Rock_Volcanic_Brick"
    },
    {
      "x": -21,
      "y": 1,
      "z": -18,
      "name": "Rock_Volcanic_Cobble"
    },
    {
      "x": -21,
      "y": 2,
      "z": -18,
      "name": "Rock_Volcanic_Cobble"
    },
    {
      "x": -21,
      "y": 3,
      "z": -18,
      "name": "Rock_Volcanic_Brick"
    },
    {
      "x": -21,
      "y": 4,
      "z": -18,
      "name": "Rock_Volcanic_Cobble",
      "rotation": 2
    },
    {
      "x": -21,
      "y": 5,
      "z": -18,
      "name": "Rock_Volcanic_Brick",
      "rotation": 2
    },
    {
      "x": -21,
      "y": 6,
      "z": -18,
      "name": "Rock_Volcanic_Cobble",
      "rotation": 2
    },
    {
      "x": -21,
      "y": 7,
      "z": -18,
      "name": "Rock_Volcanic_Cobble",
      "rotation": 2
    },
    {
      "x": -21,
      "y": 8,
      "z": -18,
      "name": "Rock_Volcanic_Cobble",
      "rotation": 2
    },
    {
      "x": -21,
      "y": 9,
      "z": -18,
      "name": "Wood_Burnt_Trunk"
    },
    {
      "x": -21,
      "y": 10,
      "z": -18,
      "name": "Wood_Burnt_Trunk"
    },
    {
      "x": -21,
      "y": 11,
      "z": -18,
      "name": "Wood_Burnt_Trunk"
    },
    {
      "x": -21,
      "y": 12,
      "z": -18,
      "name": "Rock_Volcanic_Brick",
      "rotation": 2
    },
    {
      "x": -21,
      "y": 13,
      "z": -18,
      "name": "Rock_Volcanic_Cobble",
      "rotation": 2
    },
    {
      "x": -21,
      "y": 14,
      "z": -18,
      "name": "Rock_Volcanic_Brick",
      "rotation": 2
    },
    {
      "x": -21,
      "y": -14,
      "z": -17,
      "name": "Rock_Volcanic_Cobble"
    },
    {
      "x": -21,
      "y": -13,
      "z": -17,
      "name": "Rock_Volcanic_Cobble"
    },
    {
      "x": -21,
      "y": -12,
      "z": -17,
      "name": "Rock_Volcanic_Cobble"
    },
    {
      "x": -21,
      "y": -11,
      "z": -17,
      "name": "Rock_Volcanic_Brick"
    },
    {
      "x": -21,
      "y": -10,
      "z": -17,
      "name": "Rock_Volcanic_Brick"
    },
    {
      "x": -21,
      "y": -9,
      "z": -17,
      "name": "Rock_Volcanic_Cobble"
    },
    {
      "x": -21,
      "y": -8,
      "z": -17,
      "name": "Rock_Volcanic_Brick"
    },
    {
      "x": -21,
      "y": -7,
      "z": -17,
      "name": "Rock_Volcanic_Cobble"
    },
    {
      "x": -21,
      "y": -6,
      "z": -17,
      "name": "Rock_Volcanic_Brick"
    },
    {
      "x": -21,
      "y": -5,
      "z": -17,
      "name": "Rock_Volcanic_Brick"
    },
    {
      "x": -21,
      "y": -4,
      "z": -17,
      "name": "Rock_Volcanic_Cobble"
    },
    {
      "x": -21,
      "y": -3,
      "z": -17,
      "name": "Rock_Volcanic_Cobble"
    },
    {
      "x": -21,
      "y": -2,
      "z": -17,
      "name": "Rock_Volcanic_Brick"
    },
    {
      "x": -21,
      "y": -1,
      "z": -17,
      "name": "Rock_Volcanic_Brick"
    },
    {
      "x": -21,
      "y": 0,
      "z": -17,
      "name": "Rock_Volcanic_Cobble"
    },
    {
      "x": -21,
      "y": 1,
      "z": -17,
      "name": "Rock_Volcanic_Brick"
    },
    {
      "x": -21,
      "y": 2,
      "z": -17,
      "name": "Rock_Volcanic_Brick"
    },
    {
      "x": -21,
      "y": 3,
      "z": -17,
      "name": "Rock_Volcanic_Brick"
    },
    {
      "x": -21,
      "y": 4,
      "z": -17,
      "name": "Rock_Volcanic_Brick",
      "rotation": 2
    },
    {
      "x": -21,
      "y": 5,
      "z": -17,
      "name": "Rock_Volcanic_Brick",
      "rotation": 2
    },
    {
      "x": -21,
      "y": 6,
      "z": -17,
      "name": "Rock_Volcanic_Cobble",
      "rotation": 2
    },
    {
      "x": -21,
      "y": 7,
      "z": -17,
      "name": "Rock_Volcanic_Cobble",
      "rotation": 2
    },
    {
      "x": -21,
      "y": 8,
      "z": -17,
      "name": "Rock_Volcanic_Brick",
      "rotation": 2
    },
    {
      "x": -21,
      "y": 9,
      "z": -17,
      "name": "Wood_Burnt_Trunk"
    },
    {
      "x": -21,
      "y": 10,
      "z": -17,
      "name": "Wood_Burnt_Trunk"
    },
    {
      "x": -21,
      "y": 11,
      "z": -17,
      "name": "Wood_Burnt_Trunk"
    },
    {
      "x": -21,
      "y": 12,
      "z": -17,
      "name": "Wood_Burnt_Trunk"
    },
    {
      "x": -21,
      "y": 13,
      "z": -17,
      "name": "Rock_Volcanic_Brick",
      "rotation": 2
    },
    {
      "x": -21,
      "y": 23,
      "z": -17,
      "name": "Wood_Burnt_Trunk"
    },
    {
      "x": -21,
      "y": -14,
      "z": -16,
      "name": "Rock_Volcanic_Brick"
    },
    {
      "x": -21,
      "y": -13,
      "z": -16,
      "name": "Rock_Volcanic_Cobble"
    },
    {
      "x": -21,
      "y": -12,
      "z": -16,
      "name": "Rock_Volcanic_Cobble"
    },
    {
      "x": -21,
      "y": -11,
      "z": -16,
      "name": "Rock_Volcanic_Brick"
    },
    {
      "x": -21,
      "y": -10,
      "z": -16,
      "name": "Rock_Volcanic_Brick"
    },
    {
      "x": -21,
      "y": -9,
      "z": -16,
      "name": "Rock_Volcanic_Brick"
    },
    {
      "x": -21,
      "y": -8,
      "z": -16,
      "name": "Rock_Volcanic_Brick"
    },
    {
      "x": -21,
      "y": -7,
      "z": -16,
      "name": "Rock_Volcanic_Brick"
    },
    {
      "x": -21,
      "y": -6,
      "z": -16,
      "name": "Rock_Volcanic_Brick"
    },
    {
      "x": -21,
      "y": -5,
      "z": -16,
      "name": "Rock_Volcanic_Cobble"
    },
    {
      "x": -21,
      "y": -4,
      "z": -16,
      "name": "Rock_Volcanic_Brick"
    },
    {
      "x": -21,
      "y": -3,
      "z": -16,
      "name": "Rock_Volcanic_Cobble"
    },
    {
      "x": -21,
      "y": -2,
      "z": -16,
      "name": "Rock_Volcanic_Brick"
    },
    {
      "x": -21,
      "y": -1,
      "z": -16,
      "name": "Rock_Volcanic_Cobble"
    },
    {
      "x": -21,
      "y": 0,
      "z": -16,
      "name": "Rock_Volcanic_Brick"
    },
    {
      "x": -21,
      "y": 1,
      "z": -16,
      "name": "Rock_Volcanic_Brick"
    },
    {
      "x": -21,
      "y": 2,
      "z": -16,
      "name": "Rock_Volcanic_Cobble"
    },
    {
      "x": -21,
      "y": 3,
      "z": -16,
      "name": "Rock_Volcanic_Brick"
    },
    {
      "x": -21,
      "y": 4,
      "z": -16,
      "name": "Rock_Volcanic_Cobble",
      "rotation": 2
    },
    {
      "x": -21,
      "y": 5,
      "z": -16,
      "name": "Rock_Volcanic_Brick",
      "rotation": 2
    },
    {
      "x": -21,
      "y": 6,
      "z": -16,
      "name": "Rock_Volcanic_Cobble",
      "rotation": 2
    },
    {
      "x": -21,
      "y": 7,
      "z": -16,
      "name": "Wood_Burnt_Trunk"
    },
    {
      "x": -21,
      "y": 8,
      "z": -16,
      "name": "Wood_Burnt_Trunk"
    },
    {
      "x": -21,
      "y": 9,
      "z": -16,
      "name": "Wood_Burnt_Trunk"
    },
    {
      "x": -21,
      "y": 10,
      "z": -16,
      "name": "Wood_Burnt_Trunk"
    },
    {
      "x": -21,
      "y": 11,
      "z": -16,
      "name": "Wood_Burnt_Trunk"
    },
    {
      "x": -21,
      "y": 12,
      "z": -16,
      "name": "Wood_Burnt_Trunk"
    },
    {
      "x": -21,
      "y": 13,
      "z": -16,
      "name": "Rock_Volcanic_Cobble",
      "rotation": 2
    },
    {
      "x": -21,
      "y": 17,
      "z": -16,
      "name": "Wood_Burnt_Trunk"
    },
    {
      "x": -21,
      "y": 18,
      "z": -16,
      "name": "Wood_Burnt_Trunk"
    },
    {
      "x": -21,
      "y": 19,
      "z": -16,
      "name": "Wood_Burnt_Trunk"
    },
    {
      "x": -21,
      "y": 20,
      "z": -16,
      "name": "Wood_Burnt_Trunk"
    },
    {
      "x": -21,
      "y": 21,
      "z": -16,
      "name": "Wood_Burnt_Trunk"
    },
    {
      "x": -21,
      "y": 22,
      "z": -16,
      "name": "Wood_Burnt_Trunk"
    },
    {
      "x": -21,
      "y": 23,
      "z": -16,
      "name": "Wood_Burnt_Trunk"
    },
    {
      "x": -21,
      "y": 24,
      "z": -16,
      "name": "Wood_Burnt_Trunk"
    },
    {
      "x": -21,
      "y": -14,
      "z": -15,
      "name": "Rock_Volcanic_Cobble"
    },
    {
      "x": -21,
      "y": -13,
      "z": -15,
      "name": "Rock_Volcanic_Brick"
    },
    {
      "x": -21,
      "y": -12,
      "z": -15,
      "name": "Rock_Volcanic_Brick"
    },
    {
      "x": -21,
      "y": -11,
      "z": -15,
      "name": "Rock_Volcanic_Cobble"
    },
    {
      "x": -21,
      "y": -10,
      "z": -15,
      "name": "Rock_Volcanic_Brick"
    },
    {
      "x": -21,
      "y": -9,
      "z": -15,
      "name": "Rock_Volcanic_Cobble"
    },
    {
      "x": -21,
      "y": -8,
      "z": -15,
      "name": "Rock_Volcanic_Brick"
    },
    {
      "x": -21,
      "y": -7,
      "z": -15,
      "name": "Rock_Volcanic_Brick"
    },
    {
      "x": -21,
      "y": -6,
      "z": -15,
      "name": "Rock_Volcanic_Brick"
    },
    {
      "x": -21,
      "y": -5,
      "z": -15,
      "name": "Rock_Volcanic_Cobble"
    },
    {
      "x": -21,
      "y": -4,
      "z": -15,
      "name": "Rock_Volcanic_Brick"
    },
    {
      "x": -21,
      "y": -3,
      "z": -15,
      "name": "Rock_Volcanic_Brick"
    },
    {
      "x": -21,
      "y": -2,
      "z": -15,
      "name": "Rock_Volcanic_Brick"
    },
    {
      "x": -21,
      "y": -1,
      "z": -15,
      "name": "Rock_Volcanic_Brick"
    },
    {
      "x": -21,
      "y": 0,
      "z": -15,
      "name": "Rock_Volcanic_Cobble"
    },
    {
      "x": -21,
      "y": 1,
      "z": -15,
      "name": "Rock_Volcanic_Brick"
    },
    {
      "x": -21,
      "y": 2,
      "z": -15,
      "name": "Rock_Volcanic_Brick"
    },
    {
      "x": -21,
      "y": 3,
      "z": -15,
      "name": "Rock_Volcanic_Brick"
    },
    {
      "x": -21,
      "y": 4,
      "z": -15,
      "name": "Rock_Volcanic_Cobble",
      "rotation": 2
    },
    {
      "x": -21,
      "y": 5,
      "z": -15,
      "name": "Rock_Volcanic_Brick",
      "rotation": 2
    },
    {
      "x": -21,
      "y": 6,
      "z": -15,
      "name": "Wood_Burnt_Trunk"
    },
    {
      "x": -21,
      "y": 7,
      "z": -15,
      "name": "Wood_Burnt_Trunk"
    },
    {
      "x": -21,
      "y": 8,
      "z": -15,
      "name": "Wood_Burnt_Trunk"
    },
    {
      "x": -21,
      "y": 9,
      "z": -15,
      "name": "Wood_Burnt_Trunk"
    },
    {
      "x": -21,
      "y": 10,
      "z": -15,
      "name": "Wood_Burnt_Trunk"
    },
    {
      "x": -21,
      "y": 11,
      "z": -15,
      "name": "Wood_Burnt_Trunk"
    },
    {
      "x": -21,
      "y": 12,
      "z": -15,
      "name": "Wood_Burnt_Trunk"
    },
    {
      "x": -21,
      "y": 13,
      "z": -15,
      "name": "Wood_Burnt_Trunk"
    },
    {
      "x": -21,
      "y": 17,
      "z": -15,
      "name": "Wood_Burnt_Trunk"
    },
    {
      "x": -21,
      "y": 18,
      "z": -15,
      "name": "Wood_Burnt_Trunk"
    },
    {
      "x": -21,
      "y": 19,
      "z": -15,
      "name": "Wood_Burnt_Trunk"
    },
    {
      "x": -21,
      "y": 20,
      "z": -15,
      "name": "Wood_Burnt_Trunk"
    },
    {
      "x": -21,
      "y": 21,
      "z": -15,
      "name": "Wood_Burnt_Trunk"
    },
    {
      "x": -21,
      "y": 22,
      "z": -15,
      "name": "Wood_Burnt_Trunk"
    },
    {
      "x": -21,
      "y": 23,
      "z": -15,
      "name": "Wood_Burnt_Trunk"
    },
    {
      "x": -21,
      "y": -14,
      "z": -14,
      "name": "Rock_Volcanic_Cobble"
    },
    {
      "x": -21,
      "y": -13,
      "z": -14,
      "name": "Rock_Volcanic_Cobble"
    },
    {
      "x": -21,
      "y": -12,
      "z": -14,
      "name": "Rock_Volcanic_Cobble"
    },
    {
      "x": -21,
      "y": -11,
      "z": -14,
      "name": "Rock_Volcanic_Brick"
    },
    {
      "x": -21,
      "y": -10,
      "z": -14,
      "name": "Rock_Volcanic_Cobble"
    },
    {
      "x": -21,
      "y": -9,
      "z": -14,
      "name": "Rock_Volcanic_Brick"
    },
    {
      "x": -21,
      "y": -8,
      "z": -14,
      "name": "Rock_Volcanic_Cobble"
    },
    {
      "x": -21,
      "y": -7,
      "z": -14,
      "name": "Rock_Volcanic_Brick"
    },
    {
      "x": -21,
      "y": -6,
      "z": -14,
      "name": "Rock_Volcanic_Cobble"
    },
    {
      "x": -21,
      "y": -5,
      "z": -14,
      "name": "Rock_Volcanic_Cobble"
    },
    {
      "x": -21,
      "y": -4,
      "z": -14,
      "name": "Rock_Volcanic_Brick"
    },
    {
      "x": -21,
      "y": -3,
      "z": -14,
      "name": "Rock_Volcanic_Brick"
    },
    {
      "x": -21,
      "y": -2,
      "z": -14,
      "name": "Rock_Volcanic_Brick"
    },
    {
      "x": -21,
      "y": -1,
      "z": -14,
      "name": "Rock_Volcanic_Brick"
    },
    {
      "x": -21,
      "y": 0,
      "z": -14,
      "name": "Rock_Volcanic_Brick"
    },
    {
      "x": -21,
      "y": 1,
      "z": -14,
      "name": "Rock_Volcanic_Brick"
    },
    {
      "x": -21,
      "y": 2,
      "z": -14,
      "name": "Rock_Volcanic_Cobble"
    },
    {
      "x": -21,
      "y": 3,
      "z": -14,
      "name": "Rock_Volcanic_Cobble"
    },
    {
      "x": -21,
      "y": 4,
      "z": -14,
      "name": "Rock_Volcanic_Cobble",
      "rotation": 2
    },
    {
      "x": -21,
      "y": 5,
      "z": -14,
      "name": "Wood_Burnt_Trunk"
    },
    {
      "x": -21,
      "y": 6,
      "z": -14,
      "name": "Wood_Burnt_Trunk"
    },
    {
      "x": -21,
      "y": 7,
      "z": -14,
      "name": "Wood_Burnt_Trunk"
    },
    {
      "x": -21,
      "y": 8,
      "z": -14,
      "name": "Wood_Burnt_Trunk"
    },
    {
      "x": -21,
      "y": 9,
      "z": -14,
      "name": "Wood_Burnt_Trunk"
    },
    {
      "x": -21,
      "y": 10,
      "z": -14,
      "name": "Rock_Volcanic_Cobble",
      "rotation": 2
    },
    {
      "x": -21,
      "y": 11,
      "z": -14,
      "name": "Wood_Burnt_Trunk"
    },
    {
      "x": -21,
      "y": 12,
      "z": -14,
      "name": "Wood_Burnt_Trunk"
    },
    {
      "x": -21,
      "y": 13,
      "z": -14,
      "name": "Wood_Burnt_Trunk"
    },
    {
      "x": -21,
      "y": 14,
      "z": -14,
      "name": "Wood_Burnt_Trunk"
    },
    {
      "x": -21,
      "y": 15,
      "z": -14,
      "name": "Wood_Burnt_Trunk"
    },
    {
      "x": -21,
      "y": 18,
      "z": -14,
      "name": "Wood_Burnt_Trunk"
    },
    {
      "x": -21,
      "y": 19,
      "z": -14,
      "name": "Wood_Burnt_Trunk"
    },
    {
      "x": -21,
      "y": -14,
      "z": -13,
      "name": "Rock_Volcanic_Brick"
    },
    {
      "x": -21,
      "y": -13,
      "z": -13,
      "name": "Rock_Volcanic_Cobble"
    },
    {
      "x": -21,
      "y": -12,
      "z": -13,
      "name": "Rock_Volcanic_Cobble"
    },
    {
      "x": -21,
      "y": -11,
      "z": -13,
      "name": "Rock_Volcanic_Brick"
    },
    {
      "x": -21,
      "y": -10,
      "z": -13,
      "name": "Rock_Volcanic_Brick"
    },
    {
      "x": -21,
      "y": -9,
      "z": -13,
      "name": "Rock_Volcanic_Brick"
    },
    {
      "x": -21,
      "y": -8,
      "z": -13,
      "name": "Rock_Volcanic_Cobble"
    },
    {
      "x": -21,
      "y": -7,
      "z": -13,
      "name": "Rock_Volcanic_Brick"
    },
    {
      "x": -21,
      "y": -6,
      "z": -13,
      "name": "Rock_Volcanic_Cobble"
    },
    {
      "x": -21,
      "y": -5,
      "z": -13,
      "name": "Rock_Volcanic_Brick"
    },
    {
      "x": -21,
      "y": -4,
      "z": -13,
      "name": "Rock_Volcanic_Brick"
    },
    {
      "x": -21,
      "y": -3,
      "z": -13,
      "name": "Rock_Volcanic_Brick"
    },
    {
      "x": -21,
      "y": -2,
      "z": -13,
      "name": "Rock_Volcanic_Brick"
    },
    {
      "x": -21,
      "y": -1,
      "z": -13,
      "name": "Rock_Volcanic_Cobble"
    },
    {
      "x": -21,
      "y": 0,
      "z": -13,
      "name": "Rock_Volcanic_Brick"
    },
    {
      "x": -21,
      "y": 1,
      "z": -13,
      "name": "Rock_Volcanic_Brick"
    },
    {
      "x": -21,
      "y": 2,
      "z": -13,
      "name": "Rock_Volcanic_Brick"
    },
    {
      "x": -21,
      "y": 3,
      "z": -13,
      "name": "Rock_Volcanic_Cobble"
    },
    {
      "x": -21,
      "y": 4,
      "z": -13,
      "name": "Wood_Burnt_Trunk"
    },
    {
      "x": -21,
      "y": 5,
      "z": -13,
      "name": "Wood_Burnt_Trunk"
    },
    {
      "x": -21,
      "y": 6,
      "z": -13,
      "name": "Wood_Burnt_Trunk"
    },
    {
      "x": -21,
      "y": 7,
      "z": -13,
      "name": "Wood_Burnt_Trunk"
    },
    {
      "x": -21,
      "y": 8,
      "z": -13,
      "name": "Wood_Burnt_Trunk"
    },
    {
      "x": -21,
      "y": 9,
      "z": -13,
      "name": "Wood_Burnt_Trunk"
    },
    {
      "x": -21,
      "y": 10,
      "z": -13,
      "name": "Wood_Burnt_Trunk"
    },
    {
      "x": -21,
      "y": 11,
      "z": -13,
      "name": "Wood_Burnt_Trunk"
    },
    {
      "x": -21,
      "y": 12,
      "z": -13,
      "name": "Wood_Burnt_Trunk"
    },
    {
      "x": -21,
      "y": 13,
      "z": -13,
      "name": "Wood_Burnt_Trunk"
    },
    {
      "x": -21,
      "y": -14,
      "z": -12,
      "name": "Rock_Volcanic_Brick"
    },
    {
      "x": -21,
      "y": -13,
      "z": -12,
      "name": "Rock_Volcanic_Cobble"
    },
    {
      "x": -21,
      "y": -12,
      "z": -12,
      "name": "Rock_Volcanic_Cobble"
    },
    {
      "x": -21,
      "y": -11,
      "z": -12,
      "name": "Rock_Volcanic_Brick"
    },
    {
      "x": -21,
      "y": -10,
      "z": -12,
      "name": "Rock_Volcanic_Cobble"
    },
    {
      "x": -21,
      "y": -9,
      "z": -12,
      "name": "Rock_Volcanic_Cobble"
    },
    {
      "x": -21,
      "y": -8,
      "z": -12,
      "name": "Rock_Volcanic_Brick"
    },
    {
      "x": -21,
      "y": -7,
      "z": -12,
      "name": "Rock_Volcanic_Cobble"
    },
    {
      "x": -21,
      "y": -6,
      "z": -12,
      "name": "Rock_Volcanic_Cobble"
    },
    {
      "x": -21,
      "y": -5,
      "z": -12,
      "name": "Rock_Volcanic_Cobble"
    },
    {
      "x": -21,
      "y": -4,
      "z": -12,
      "name": "Rock_Volcanic_Cobble"
    },
    {
      "x": -21,
      "y": -3,
      "z": -12,
      "name": "Rock_Volcanic_Brick"
    },
    {
      "x": -21,
      "y": -2,
      "z": -12,
      "name": "Rock_Volcanic_Cobble"
    },
    {
      "x": -21,
      "y": -1,
      "z": -12,
      "name": "Rock_Volcanic_Brick"
    },
    {
      "x": -21,
      "y": 0,
      "z": -12,
      "name": "Rock_Volcanic_Cobble"
    },
    {
      "x": -21,
      "y": 1,
      "z": -12,
      "name": "Rock_Volcanic_Cobble"
    },
    {
      "x": -21,
      "y": 2,
      "z": -12,
      "name": "Rock_Volcanic_Cobble"
    },
    {
      "x": -21,
      "y": 3,
      "z": -12,
      "name": "Rock_Volcanic_Cobble"
    },
    {
      "x": -21,
      "y": 7,
      "z": -12,
      "name": "Wood_Burnt_Trunk"
    },
    {
      "x": -21,
      "y": 12,
      "z": -12,
      "name": "Wood_Burnt_Trunk"
    },
    {
      "x": -21,
      "y": -14,
      "z": -11,
      "name": "Rock_Volcanic_Brick"
    },
    {
      "x": -21,
      "y": -13,
      "z": -11,
      "name": "Rock_Volcanic_Brick"
    },
    {
      "x": -21,
      "y": -12,
      "z": -11,
      "name": "Rock_Volcanic_Brick"
    },
    {
      "x": -21,
      "y": -11,
      "z": -11,
      "name": "Rock_Volcanic_Brick"
    },
    {
      "x": -21,
      "y": -10,
      "z": -11,
      "name": "Rock_Volcanic_Brick"
    },
    {
      "x": -21,
      "y": -9,
      "z": -11,
      "name": "Rock_Volcanic_Brick"
    },
    {
      "x": -21,
      "y": -8,
      "z": -11,
      "name": "Rock_Volcanic_Cobble"
    },
    {
      "x": -21,
      "y": -7,
      "z": -11,
      "name": "Rock_Volcanic_Brick"
    },
    {
      "x": -21,
      "y": -6,
      "z": -11,
      "name": "Rock_Volcanic_Brick"
    },
    {
      "x": -21,
      "y": -5,
      "z": -11,
      "name": "Rock_Volcanic_Brick"
    },
    {
      "x": -21,
      "y": -4,
      "z": -11,
      "name": "Rock_Volcanic_Cobble"
    },
    {
      "x": -21,
      "y": -3,
      "z": -11,
      "name": "Rock_Volcanic_Cobble"
    },
    {
      "x": -21,
      "y": -2,
      "z": -11,
      "name": "Rock_Volcanic_Cobble"
    },
    {
      "x": -21,
      "y": -1,
      "z": -11,
      "name": "Rock_Volcanic_Cobble"
    },
    {
      "x": -21,
      "y": 0,
      "z": -11,
      "name": "Rock_Volcanic_Brick"
    },
    {
      "x": -21,
      "y": 1,
      "z": -11,
      "name": "Rock_Volcanic_Cobble"
    },
    {
      "x": -21,
      "y": 2,
      "z": -11,
      "name": "Rock_Volcanic_Brick"
    },
    {
      "x": -21,
      "y": 3,
      "z": -11,
      "name": "Rock_Volcanic_Cobble"
    },
    {
      "x": -21,
      "y": -14,
      "z": 12,
      "name": "Rock_Volcanic_Cobble"
    },
    {
      "x": -21,
      "y": -13,
      "z": 12,
      "name": "Rock_Volcanic_Cobble"
    },
    {
      "x": -21,
      "y": -12,
      "z": 12,
      "name": "Rock_Volcanic_Brick"
    },
    {
      "x": -21,
      "y": -11,
      "z": 12,
      "name": "Rock_Volcanic_Brick"
    },
    {
      "x": -21,
      "y": -10,
      "z": 12,
      "name": "Rock_Volcanic_Brick"
    },
    {
      "x": -21,
      "y": -9,
      "z": 12,
      "name": "Rock_Volcanic_Cobble"
    },
    {
      "x": -21,
      "y": -8,
      "z": 12,
      "name": "Rock_Volcanic_Cobble"
    },
    {
      "x": -21,
      "y": -7,
      "z": 12,
      "name": "Rock_Volcanic_Cobble"
    },
    {
      "x": -21,
      "y": -6,
      "z": 12,
      "name": "Rock_Volcanic_Cobble"
    },
    {
      "x": -21,
      "y": -5,
      "z": 12,
      "name": "Rock_Volcanic_Cobble"
    },
    {
      "x": -21,
      "y": -4,
      "z": 12,
      "name": "Rock_Volcanic_Brick"
    },
    {
      "x": -21,
      "y": -3,
      "z": 12,
      "name": "Rock_Volcanic_Cobble"
    },
    {
      "x": -21,
      "y": -2,
      "z": 12,
      "name": "Rock_Volcanic_Brick"
    },
    {
      "x": -21,
      "y": -1,
      "z": 12,
      "name": "Rock_Volcanic_Brick"
    },
    {
      "x": -21,
      "y": 0,
      "z": 12,
      "name": "Rock_Volcanic_Brick"
    },
    {
      "x": -21,
      "y": 1,
      "z": 12,
      "name": "Rock_Volcanic_Brick"
    },
    {
      "x": -21,
      "y": 2,
      "z": 12,
      "name": "Rock_Volcanic_Brick"
    },
    {
      "x": -21,
      "y": -14,
      "z": 13,
      "name": "Rock_Volcanic_Cobble"
    },
    {
      "x": -21,
      "y": -13,
      "z": 13,
      "name": "Rock_Volcanic_Brick"
    },
    {
      "x": -21,
      "y": -12,
      "z": 13,
      "name": "Rock_Volcanic_Cobble"
    },
    {
      "x": -21,
      "y": -11,
      "z": 13,
      "name": "Rock_Volcanic_Cobble"
    },
    {
      "x": -21,
      "y": -10,
      "z": 13,
      "name": "Rock_Volcanic_Brick"
    },
    {
      "x": -21,
      "y": -9,
      "z": 13,
      "name": "Rock_Volcanic_Cobble"
    },
    {
      "x": -21,
      "y": -8,
      "z": 13,
      "name": "Rock_Volcanic_Brick"
    },
    {
      "x": -21,
      "y": -7,
      "z": 13,
      "name": "Rock_Volcanic_Brick"
    },
    {
      "x": -21,
      "y": -6,
      "z": 13,
      "name": "Rock_Volcanic_Cobble"
    },
    {
      "x": -21,
      "y": -5,
      "z": 13,
      "name": "Rock_Volcanic_Cobble"
    },
    {
      "x": -21,
      "y": -4,
      "z": 13,
      "name": "Rock_Volcanic_Brick"
    },
    {
      "x": -21,
      "y": -3,
      "z": 13,
      "name": "Rock_Volcanic_Brick"
    },
    {
      "x": -21,
      "y": -2,
      "z": 13,
      "name": "Rock_Volcanic_Cobble"
    },
    {
      "x": -21,
      "y": -1,
      "z": 13,
      "name": "Rock_Volcanic_Cobble"
    },
    {
      "x": -21,
      "y": 0,
      "z": 13,
      "name": "Rock_Volcanic_Cobble"
    },
    {
      "x": -21,
      "y": 1,
      "z": 13,
      "name": "Rock_Volcanic_Brick"
    },
    {
      "x": -21,
      "y": 2,
      "z": 13,
      "name": "Rock_Volcanic_Cobble"
    },
    {
      "x": -21,
      "y": -14,
      "z": 14,
      "name": "Rock_Volcanic_Brick"
    },
    {
      "x": -21,
      "y": -13,
      "z": 14,
      "name": "Rock_Volcanic_Brick"
    },
    {
      "x": -21,
      "y": -12,
      "z": 14,
      "name": "Rock_Volcanic_Cobble"
    },
    {
      "x": -21,
      "y": -11,
      "z": 14,
      "name": "Rock_Volcanic_Cobble"
    },
    {
      "x": -21,
      "y": -10,
      "z": 14,
      "name": "Rock_Volcanic_Brick"
    },
    {
      "x": -21,
      "y": -9,
      "z": 14,
      "name": "Rock_Volcanic_Brick"
    },
    {
      "x": -21,
      "y": -8,
      "z": 14,
      "name": "Rock_Volcanic_Brick"
    },
    {
      "x": -21,
      "y": -7,
      "z": 14,
      "name": "Rock_Volcanic_Brick"
    },
    {
      "x": -21,
      "y": -6,
      "z": 14,
      "name": "Rock_Volcanic_Cobble"
    },
    {
      "x": -21,
      "y": -5,
      "z": 14,
      "name": "Rock_Volcanic_Cobble"
    },
    {
      "x": -21,
      "y": -4,
      "z": 14,
      "name": "Rock_Volcanic_Cobble"
    },
    {
      "x": -21,
      "y": -3,
      "z": 14,
      "name": "Rock_Volcanic_Cobble"
    },
    {
      "x": -21,
      "y": -2,
      "z": 14,
      "name": "Rock_Volcanic_Brick"
    },
    {
      "x": -21,
      "y": -1,
      "z": 14,
      "name": "Rock_Volcanic_Brick"
    },
    {
      "x": -21,
      "y": 0,
      "z": 14,
      "name": "Rock_Volcanic_Brick"
    },
    {
      "x": -21,
      "y": 1,
      "z": 14,
      "name": "Rock_Volcanic_Brick"
    },
    {
      "x": -21,
      "y": 2,
      "z": 14,
      "name": "Rock_Volcanic_Cobble"
    },
    {
      "x": -21,
      "y": -14,
      "z": 15,
      "name": "Rock_Volcanic_Brick"
    },
    {
      "x": -21,
      "y": -13,
      "z": 15,
      "name": "Rock_Volcanic_Cobble"
    },
    {
      "x": -21,
      "y": -12,
      "z": 15,
      "name": "Rock_Volcanic_Brick"
    },
    {
      "x": -21,
      "y": -11,
      "z": 15,
      "name": "Rock_Volcanic_Cobble"
    },
    {
      "x": -21,
      "y": -10,
      "z": 15,
      "name": "Rock_Volcanic_Cobble"
    },
    {
      "x": -21,
      "y": -9,
      "z": 15,
      "name": "Rock_Volcanic_Cobble"
    },
    {
      "x": -21,
      "y": -8,
      "z": 15,
      "name": "Rock_Volcanic_Brick"
    },
    {
      "x": -21,
      "y": -7,
      "z": 15,
      "name": "Rock_Volcanic_Cobble"
    },
    {
      "x": -21,
      "y": -6,
      "z": 15,
      "name": "Rock_Volcanic_Cobble"
    },
    {
      "x": -21,
      "y": -5,
      "z": 15,
      "name": "Rock_Volcanic_Cobble"
    },
    {
      "x": -21,
      "y": -4,
      "z": 15,
      "name": "Rock_Volcanic_Brick"
    },
    {
      "x": -21,
      "y": -3,
      "z": 15,
      "name": "Rock_Volcanic_Brick"
    },
    {
      "x": -21,
      "y": -2,
      "z": 15,
      "name": "Rock_Volcanic_Cobble"
    },
    {
      "x": -21,
      "y": -1,
      "z": 15,
      "name": "Rock_Volcanic_Brick"
    },
    {
      "x": -21,
      "y": 0,
      "z": 15,
      "name": "Rock_Volcanic_Brick"
    },
    {
      "x": -21,
      "y": 1,
      "z": 15,
      "name": "Rock_Volcanic_Cobble"
    },
    {
      "x": -21,
      "y": 2,
      "z": 15,
      "name": "Rock_Volcanic_Brick"
    },
    {
      "x": -21,
      "y": 3,
      "z": 15,
      "name": "Rock_Volcanic_Cobble"
    },
    {
      "x": -21,
      "y": 4,
      "z": 15,
      "name": "Rock_Volcanic_Cobble",
      "rotation": 3
    },
    {
      "x": -21,
      "y": 5,
      "z": 15,
      "name": "Rock_Volcanic_Cobble",
      "rotation": 3
    },
    {
      "x": -21,
      "y": 6,
      "z": 15,
      "name": "Rock_Volcanic_Cobble",
      "rotation": 3
    },
    {
      "x": -21,
      "y": 7,
      "z": 15,
      "name": "Rock_Volcanic_Cobble",
      "rotation": 3
    },
    {
      "x": -21,
      "y": -14,
      "z": 16,
      "name": "Rock_Volcanic_Cobble"
    },
    {
      "x": -21,
      "y": -13,
      "z": 16,
      "name": "Rock_Volcanic_Cobble"
    },
    {
      "x": -21,
      "y": -12,
      "z": 16,
      "name": "Rock_Volcanic_Brick"
    },
    {
      "x": -21,
      "y": -11,
      "z": 16,
      "name": "Rock_Volcanic_Cobble"
    },
    {
      "x": -21,
      "y": -10,
      "z": 16,
      "name": "Rock_Volcanic_Cobble"
    },
    {
      "x": -21,
      "y": -9,
      "z": 16,
      "name": "Rock_Volcanic_Brick"
    },
    {
      "x": -21,
      "y": -8,
      "z": 16,
      "name": "Rock_Volcanic_Brick"
    },
    {
      "x": -21,
      "y": -7,
      "z": 16,
      "name": "Rock_Volcanic_Brick"
    },
    {
      "x": -21,
      "y": -6,
      "z": 16,
      "name": "Rock_Volcanic_Brick"
    },
    {
      "x": -21,
      "y": -5,
      "z": 16,
      "name": "Rock_Volcanic_Brick"
    },
    {
      "x": -21,
      "y": -4,
      "z": 16,
      "name": "Rock_Volcanic_Brick"
    },
    {
      "x": -21,
      "y": -3,
      "z": 16,
      "name": "Rock_Volcanic_Cobble"
    },
    {
      "x": -21,
      "y": -2,
      "z": 16,
      "name": "Rock_Volcanic_Brick"
    },
    {
      "x": -21,
      "y": -1,
      "z": 16,
      "name": "Rock_Volcanic_Brick"
    },
    {
      "x": -21,
      "y": 0,
      "z": 16,
      "name": "Rock_Volcanic_Brick"
    },
    {
      "x": -21,
      "y": 1,
      "z": 16,
      "name": "Rock_Volcanic_Cobble"
    },
    {
      "x": -21,
      "y": 2,
      "z": 16,
      "name": "Rock_Volcanic_Cobble"
    },
    {
      "x": -21,
      "y": 3,
      "z": 16,
      "name": "Rock_Volcanic_Cobble"
    },
    {
      "x": -21,
      "y": 4,
      "z": 16,
      "name": "Rock_Volcanic_Cobble",
      "rotation": 3
    },
    {
      "x": -21,
      "y": 5,
      "z": 16,
      "name": "Rock_Volcanic_Brick",
      "rotation": 3
    },
    {
      "x": -21,
      "y": 6,
      "z": 16,
      "name": "Rock_Volcanic_Brick",
      "rotation": 3
    },
    {
      "x": -21,
      "y": 7,
      "z": 16,
      "name": "Rock_Volcanic_Brick",
      "rotation": 3
    },
    {
      "x": -21,
      "y": 8,
      "z": 16,
      "name": "Rock_Volcanic_Brick",
      "rotation": 3
    },
    {
      "x": -21,
      "y": -14,
      "z": 17,
      "name": "Rock_Volcanic_Cobble"
    },
    {
      "x": -21,
      "y": -13,
      "z": 17,
      "name": "Rock_Volcanic_Cobble"
    },
    {
      "x": -21,
      "y": -12,
      "z": 17,
      "name": "Rock_Volcanic_Cobble"
    },
    {
      "x": -21,
      "y": -11,
      "z": 17,
      "name": "Rock_Volcanic_Brick"
    },
    {
      "x": -21,
      "y": -10,
      "z": 17,
      "name": "Rock_Volcanic_Brick"
    },
    {
      "x": -21,
      "y": -9,
      "z": 17,
      "name": "Rock_Volcanic_Brick"
    },
    {
      "x": -21,
      "y": -8,
      "z": 17,
      "name": "Rock_Volcanic_Cobble"
    },
    {
      "x": -21,
      "y": -7,
      "z": 17,
      "name": "Rock_Volcanic_Brick"
    },
    {
      "x": -21,
      "y": -6,
      "z": 17,
      "name": "Rock_Volcanic_Cobble"
    },
    {
      "x": -21,
      "y": -5,
      "z": 17,
      "name": "Rock_Volcanic_Brick"
    },
    {
      "x": -21,
      "y": -4,
      "z": 17,
      "name": "Rock_Volcanic_Brick"
    },
    {
      "x": -21,
      "y": -3,
      "z": 17,
      "name": "Rock_Volcanic_Brick"
    },
    {
      "x": -21,
      "y": -2,
      "z": 17,
      "name": "Rock_Volcanic_Cobble"
    },
    {
      "x": -21,
      "y": -1,
      "z": 17,
      "name": "Rock_Volcanic_Cobble"
    },
    {
      "x": -21,
      "y": 0,
      "z": 17,
      "name": "Rock_Volcanic_Brick"
    },
    {
      "x": -21,
      "y": 1,
      "z": 17,
      "name": "Rock_Volcanic_Brick"
    },
    {
      "x": -21,
      "y": 2,
      "z": 17,
      "name": "Rock_Volcanic_Cobble"
    },
    {
      "x": -21,
      "y": 3,
      "z": 17,
      "name": "Rock_Volcanic_Cobble"
    },
    {
      "x": -21,
      "y": 4,
      "z": 17,
      "name": "Rock_Volcanic_Cobble",
      "rotation": 3
    },
    {
      "x": -21,
      "y": 5,
      "z": 17,
      "name": "Rock_Volcanic_Cobble",
      "rotation": 3
    },
    {
      "x": -21,
      "y": 6,
      "z": 17,
      "name": "Rock_Volcanic_Cobble",
      "rotation": 3
    },
    {
      "x": -21,
      "y": 7,
      "z": 17,
      "name": "Rock_Volcanic_Brick",
      "rotation": 3
    },
    {
      "x": -21,
      "y": 8,
      "z": 17,
      "name": "Rock_Volcanic_Brick",
      "rotation": 3
    },
    {
      "x": -21,
      "y": 9,
      "z": 17,
      "name": "Rock_Volcanic_Cobble_Half"
    },
    {
      "x": -21,
      "y": -14,
      "z": 18,
      "name": "Rock_Volcanic_Cobble"
    },
    {
      "x": -21,
      "y": -13,
      "z": 18,
      "name": "Rock_Volcanic_Brick"
    },
    {
      "x": -21,
      "y": -12,
      "z": 18,
      "name": "Rock_Volcanic_Cobble"
    },
    {
      "x": -21,
      "y": -11,
      "z": 18,
      "name": "Rock_Volcanic_Cobble"
    },
    {
      "x": -21,
      "y": -10,
      "z": 18,
      "name": "Rock_Volcanic_Brick"
    },
    {
      "x": -21,
      "y": -9,
      "z": 18,
      "name": "Rock_Volcanic_Cobble"
    },
    {
      "x": -21,
      "y": -8,
      "z": 18,
      "name": "Rock_Volcanic_Cobble"
    },
    {
      "x": -21,
      "y": -7,
      "z": 18,
      "name": "Rock_Volcanic_Brick"
    },
    {
      "x": -21,
      "y": -6,
      "z": 18,
      "name": "Rock_Volcanic_Cobble"
    },
    {
      "x": -21,
      "y": -5,
      "z": 18,
      "name": "Rock_Volcanic_Brick"
    },
    {
      "x": -21,
      "y": -4,
      "z": 18,
      "name": "Rock_Volcanic_Brick"
    },
    {
      "x": -21,
      "y": -3,
      "z": 18,
      "name": "Rock_Volcanic_Brick"
    },
    {
      "x": -21,
      "y": -2,
      "z": 18,
      "name": "Rock_Volcanic_Brick"
    },
    {
      "x": -21,
      "y": -1,
      "z": 18,
      "name": "Rock_Volcanic_Brick"
    },
    {
      "x": -21,
      "y": 0,
      "z": 18,
      "name": "Rock_Volcanic_Cobble"
    },
    {
      "x": -21,
      "y": 1,
      "z": 18,
      "name": "Rock_Volcanic_Brick"
    },
    {
      "x": -21,
      "y": 2,
      "z": 18,
      "name": "Rock_Volcanic_Cobble"
    },
    {
      "x": -21,
      "y": 3,
      "z": 18,
      "name": "Rock_Volcanic_Cobble"
    },
    {
      "x": -21,
      "y": 4,
      "z": 18,
      "name": "Rock_Volcanic_Brick",
      "rotation": 3
    },
    {
      "x": -21,
      "y": 5,
      "z": 18,
      "name": "Rock_Volcanic_Brick",
      "rotation": 3
    },
    {
      "x": -21,
      "y": 6,
      "z": 18,
      "name": "Rock_Volcanic_Cobble",
      "rotation": 3
    },
    {
      "x": -21,
      "y": 7,
      "z": 18,
      "name": "Rock_Volcanic_Cobble",
      "rotation": 3
    },
    {
      "x": -21,
      "y": -14,
      "z": 19,
      "name": "Rock_Volcanic_Brick"
    },
    {
      "x": -21,
      "y": -13,
      "z": 19,
      "name": "Rock_Volcanic_Brick"
    },
    {
      "x": -21,
      "y": -12,
      "z": 19,
      "name": "Rock_Volcanic_Brick"
    },
    {
      "x": -21,
      "y": -11,
      "z": 19,
      "name": "Rock_Volcanic_Brick"
    },
    {
      "x": -21,
      "y": -10,
      "z": 19,
      "name": "Rock_Volcanic_Brick"
    },
    {
      "x": -21,
      "y": -9,
      "z": 19,
      "name": "Rock_Volcanic_Brick"
    },
    {
      "x": -21,
      "y": -8,
      "z": 19,
      "name": "Rock_Volcanic_Cobble"
    },
    {
      "x": -21,
      "y": -7,
      "z": 19,
      "name": "Rock_Volcanic_Cobble"
    },
    {
      "x": -21,
      "y": -6,
      "z": 19,
      "name": "Rock_Volcanic_Brick"
    },
    {
      "x": -21,
      "y": -5,
      "z": 19,
      "name": "Rock_Volcanic_Cobble"
    },
    {
      "x": -21,
      "y": -4,
      "z": 19,
      "name": "Rock_Volcanic_Cobble"
    },
    {
      "x": -21,
      "y": -3,
      "z": 19,
      "name": "Rock_Volcanic_Cobble"
    },
    {
      "x": -21,
      "y": -2,
      "z": 19,
      "name": "Rock_Volcanic_Cobble"
    },
    {
      "x": -21,
      "y": -1,
      "z": 19,
      "name": "Rock_Volcanic_Cobble"
    },
    {
      "x": -21,
      "y": 0,
      "z": 19,
      "name": "Rock_Volcanic_Brick"
    },
    {
      "x": -21,
      "y": 1,
      "z": 19,
      "name": "Rock_Volcanic_Brick"
    },
    {
      "x": -21,
      "y": 2,
      "z": 19,
      "name": "Rock_Volcanic_Brick"
    },
    {
      "x": -21,
      "y": 3,
      "z": 19,
      "name": "Rock_Volcanic_Cobble"
    },
    {
      "x": -21,
      "y": 4,
      "z": 19,
      "name": "Rock_Volcanic_Cobble",
      "rotation": 3
    },
    {
      "x": -21,
      "y": 5,
      "z": 19,
      "name": "Rock_Volcanic_Cobble",
      "rotation": 3
    },
    {
      "x": -21,
      "y": 6,
      "z": 19,
      "name": "Rock_Volcanic_Brick",
      "rotation": 3
    },
    {
      "x": -21,
      "y": 7,
      "z": 19,
      "name": "Rock_Volcanic_Cobble_Half"
    },
    {
      "x": -21,
      "y": -14,
      "z": 20,
      "name": "Rock_Volcanic_Cobble"
    },
    {
      "x": -21,
      "y": -13,
      "z": 20,
      "name": "Rock_Volcanic_Brick"
    },
    {
      "x": -21,
      "y": -12,
      "z": 20,
      "name": "Rock_Volcanic_Brick"
    },
    {
      "x": -21,
      "y": -11,
      "z": 20,
      "name": "Rock_Volcanic_Cobble"
    },
    {
      "x": -21,
      "y": -10,
      "z": 20,
      "name": "Rock_Volcanic_Cobble"
    },
    {
      "x": -21,
      "y": -9,
      "z": 20,
      "name": "Rock_Volcanic_Cobble"
    },
    {
      "x": -21,
      "y": -8,
      "z": 20,
      "name": "Rock_Volcanic_Cobble"
    },
    {
      "x": -21,
      "y": -7,
      "z": 20,
      "name": "Rock_Volcanic_Brick"
    },
    {
      "x": -21,
      "y": -6,
      "z": 20,
      "name": "Rock_Volcanic_Brick"
    },
    {
      "x": -21,
      "y": -5,
      "z": 20,
      "name": "Rock_Volcanic_Cobble"
    },
    {
      "x": -21,
      "y": -4,
      "z": 20,
      "name": "Rock_Volcanic_Cobble"
    },
    {
      "x": -21,
      "y": -3,
      "z": 20,
      "name": "Rock_Volcanic_Brick"
    },
    {
      "x": -21,
      "y": -2,
      "z": 20,
      "name": "Rock_Volcanic_Cobble"
    },
    {
      "x": -21,
      "y": -1,
      "z": 20,
      "name": "Rock_Volcanic_Brick"
    },
    {
      "x": -21,
      "y": 0,
      "z": 20,
      "name": "Rock_Volcanic_Cobble"
    },
    {
      "x": -21,
      "y": 1,
      "z": 20,
      "name": "Rock_Volcanic_Brick"
    },
    {
      "x": -21,
      "y": 2,
      "z": 20,
      "name": "Rock_Volcanic_Cobble"
    },
    {
      "x": -21,
      "y": -14,
      "z": 21,
      "name": "Rock_Volcanic_Cobble"
    },
    {
      "x": -21,
      "y": -13,
      "z": 21,
      "name": "Rock_Volcanic_Brick"
    },
    {
      "x": -21,
      "y": -12,
      "z": 21,
      "name": "Rock_Volcanic_Brick"
    },
    {
      "x": -21,
      "y": -11,
      "z": 21,
      "name": "Rock_Volcanic_Cobble"
    },
    {
      "x": -21,
      "y": -10,
      "z": 21,
      "name": "Rock_Volcanic_Brick"
    },
    {
      "x": -21,
      "y": -9,
