{
  "version": 8,
  "blockIdVersion": 11,
  "anchorX": 0,
  "anchorY": 0,
  "anchorZ": 0,
  "blocks": [
    {
      "x": -22,
      "y": 0,
      "z": -17,
      "name": "Rock_Volcanic_Brick_Stairs",
      "rotation": 3
    },
    {
      "x": -22,
      "y": 0,
      "z": -16,
      "name": "Rock_Volcanic_Brick",
      "rotation": 2
    },
    {
      "x": -22,
      "y": 1,
      "z": -16,
      "name": "Rock_Volcanic_Brick",
      "rotation": 2
    },
    {
      "x": -22,
      "y": 2,
      "z": -16,
      "name": "Rock_Volcanic_Brick",
      "rotation": 2
    },
    {
      "x": -22,
      "y": 3,
      "z": -16,
      "name": "Rock_Volcanic_Brick_Stairs",
      "rotation": 3
    },
    {
      "x": -22,
      "y": 24,
      "z": -16,
      "name": "Furniture_Human_Ruins_Banner"
    },
    {
      "x": -22,
      "y": 0,
      "z": -15,
      "name": "Rock_Volcanic_Brick_Stairs",
      "rotation": 3
    },
    {
      "x": -22,
      "y": 0,
      "z": 16,
      "name": "Rock_Volcanic_Brick_Stairs",
      "rotation": 3
    },
    {
      "x": -22,
      "y": 0,
      "z": 17,
      "name": "Rock_Volcanic_Brick",
      "rotation": 3
    },
    {
      "x": -22,
      "y": 1,
      "z": 17,
      "name": "Rock_Volcanic_Brick",
      "rotation": 3
    },
    {
      "x": -22,
      "y": 2,
      "z": 17,
      "name": "Rock_Volcanic_Brick",
      "rotation": 3
    },
    {
      "x": -22,
      "y": 3,
      "z": 17,
      "name": "Rock_Volcanic_Brick_Stairs",
      "rotation": 3
    },
    {
      "x": -22,
      "y": 24,
      "z": 17,
      "name": "Furniture_Human_Ruins_Banner"
    },
    {
      "x": -22,
      "y": 0,
      "z": 18,
      "name": "Rock_Volcanic_Brick_Stairs",
      "rotation": 3
    },
    {
      "x": -21,
      "y": 24,
      "z": -19,
      "name": "Rock_Volcanic_Brick_Stairs",
      "rotation": 8
    },
    {
      "x": -21,
      "y": 19,
      "z": -18,
      "name": "Rock_Volcanic_Brick_Smooth_Half",
      "rotation": 7
    },
    {
      "x": -21,
      "y": 23,
      "z": -18,
      "name": "Rock_Volcanic_Brick_Stairs",
      "rotation": 9
    },
    {
      "x": -21,
      "y": 24,
      "z": -18,
      "name": "Rock_Volcanic_Brick",
      "rotation": 2
    },
    {
      "x": -21,
      "y": 25,
      "z": -18,
      "name": "Rock_Volcanic_Brick",
      "rotation": 2
    },
    {
      "x": -21,
      "y": 26,
      "z": -18,
      "name": "Rock_Volcanic_Brick_Stairs",
      "rotation": 3
    },
    {
      "x": -21,
      "y": 0,
      "z": -17,
      "name": "Rock_Volcanic_Brick",
      "rotation": 2
    },
    {
      "x": -21,
      "y": 1,
      "z": -17,
      "name": "Rock_Volcanic_Brick",
      "rotation": 2
    },
    {
      "x": -21,
      "y": 2,
      "z": -17,
      "name": "Rock_Volcanic_Brick",
      "rotation": 2
    },
    {
      "x": -21,
      "y": 3,
      "z": -17,
      "name": "Rock_Volcanic_Brick",
      "rotation": 2
    },
    {
      "x": -21,
      "y": 4,
      "z": -17,
      "name": "Rock_Volcanic_Brick",
      "rotation": 2
    },
    {
      "x": -21,
      "y": 5,
      "z": -17,
      "name": "Rock_Volcanic_Brick_Stairs",
      "rotation": 3
    },
    {
      "x": -21,
      "y": 19,
      "z": -17,
      "name": "Rock_Volcanic_Brick_Smooth_Half",
      "rotation": 7
    },
    {
      "x": -21,
      "y": 24,
      "z": -17,
      "name": "Rock_Volcanic_Brick_Stairs",
      "rotation": 9
    },
    {
      "x": -21,
      "y": 25,
      "z": -17,
      "name": "Rock_Volcanic_Brick_Wall",
      "rotation": 1
    },
    {
      "x": -21,
      "y": 0,
      "z": -16,
      "name": "Rock_Volcanic_Brick",
      "rotation": 2
    },
    {
      "x": -21,
      "y": 1,
      "z": -16,
      "name": "Rock_Volcanic_Brick",
      "rotation": 2
    },
    {
      "x": -21,
      "y": 2,
      "z": -16,
      "name": "Rock_Volcanic_Brick",
      "rotation": 2
    },
    {
      "x": -21,
      "y": 3,
      "z": -16,
      "name": "Rock_Volcanic_Brick",
      "rotation": 2
    },
    {
      "x": -21,
      "y": 4,
      "z": -16,
      "name": "Rock_Volcanic_Brick",
      "rotation": 2
    },
    {
      "x": -21,
      "y": 5,
      "z": -16,
      "name": "Rock_Volcanic_Brick",
      "rotation": 2
    },
    {
      "x": -21,
      "y": 6,
      "z": -16,
      "name": "Rock_Volcanic_Brick",
      "rotation": 2
    },
    {
      "x": -21,
      "y": 7,
      "z": -16,
      "name": "Rock_Volcanic_Brick",
      "rotation": 2
    },
    {
      "x": -21,
      "y": 8,
      "z": -16,
      "name": "Rock_Volcanic_Brick_Stairs",
      "rotation": 3
    },
    {
      "x": -21,
      "y": 19,
      "z": -16,
      "name": "Rock_Volcanic_Brick_Smooth_Half",
      "rotation": 7
    },
    {
      "x": -21,
      "y": 22,
      "z": -16,
      "name": "Rock_Volcanic_Brick_Stairs",
      "rotation": 9
    },
    {
      "x": -21,
      "y": 23,
      "z": -16,
      "name": "Rock_Volcanic_Brick",
      "rotation": 2
    },
    {
      "x": -21,
      "y": 24,
      "z": -16,
      "name": "Rock_Volcanic_Brick",
      "rotation": 2
    },
    {
      "x": -21,
      "y": 25,
      "z": -16,
      "name": "Rock_Volcanic_Brick",
      "rotation": 2
    },
    {
      "x": -21,
      "y": 26,
      "z": -16,
      "name": "Rock_Volcanic_Brick_Stairs",
      "rotation": 3
    },
    {
      "x": -21,
      "y": 0,
      "z": -15,
      "name": "Rock_Volcanic_Brick",
      "rotation": 2
    },
    {
      "x": -21,
      "y": 1,
      "z": -15,
      "name": "Rock_Volcanic_Brick",
      "rotation": 2
    },
    {
      "x": -21,
      "y": 2,
      "z": -15,
      "name": "Rock_Volcanic_Brick",
      "rotation": 2
    },
    {
      "x": -21,
      "y": 3,
      "z": -15,
      "name": "Rock_Volcanic_Brick",
      "rotation": 2
    },
    {
      "x": -21,
      "y": 4,
      "z": -15,
      "name": "Rock_Volcanic_Brick",
      "rotation": 2
    },
    {
      "x": -21,
      "y": 5,
      "z": -15,
      "name": "Rock_Volcanic_Brick_Stairs",
      "rotation": 3
    },
    {
      "x": -21,
      "y": 19,
      "z": -15,
      "name": "Rock_Volcanic_Brick_Smooth_Half",
      "rotation": 7
    },
    {
      "x": -21,
      "y": 24,
      "z": -15,
      "name": "Rock_Volcanic_Brick_Stairs",
      "rotation": 9
    },
    {
      "x": -21,
      "y": 25,
      "z": -15,
      "name": "Rock_Volcanic_Brick_Wall",
      "rotation": 1
    },
    {
      "x": -21,
      "y": 19,
      "z": -14,
      "name": "Rock_Volcanic_Brick_Smooth_Half",
      "rotation": 7
    },
    {
      "x": -21,
      "y": 23,
      "z": -14,
      "name": "Rock_Volcanic_Brick_Stairs",
      "rotation": 9
    },
    {
      "x": -21,
      "y": 24,
      "z": -14,
      "name": "Rock_Volcanic_Brick",
      "rotation": 2
    },
    {
      "x": -21,
      "y": 25,
      "z": -14,
      "name": "Rock_Volcanic_Brick",
      "rotation": 2
    },
    {
      "x": -21,
      "y": 26,
      "z": -14,
      "name": "Rock_Volcanic_Brick_Stairs",
      "rotation": 3
    },
    {
      "x": -21,
      "y": 24,
      "z": -13,
      "name": "*Rock_Volcanic_Brick_Stairs_State_Definitions_Corner_Right",
      "rotation": 9
    },
    {
      "x": -21,
      "y": 24,
      "z": 14,
      "name": "Rock_Volcanic_Brick_Stairs",
      "rotation": 8
    },
    {
      "x": -21,
      "y": 19,
      "z": 15,
      "name": "Rock_Volcanic_Brick_Smooth_Half",
      "rotation": 7
    },
    {
      "x": -21,
      "y": 23,
      "z": 15,
      "name": "Rock_Volcanic_Brick_Stairs",
      "rotation": 9
    },
    {
      "x": -21,
      "y": 24,
      "z": 15,
      "name": "Rock_Volcanic_Brick",
      "rotation": 3
    },
    {
      "x": -21,
      "y": 25,
      "z": 15,
      "name": "Rock_Volcanic_Brick",
      "rotation": 3
    },
    {
      "x": -21,
      "y": 26,
      "z": 15,
      "name": "Rock_Volcanic_Brick_Stairs",
      "rotation": 3
    },
    {
      "x": -21,
      "y": 0,
      "z": 16,
      "name": "Rock_Volcanic_Brick",
      "rotation": 3
    },
    {
      "x": -21,
      "y": 1,
      "z": 16,
      "name": "Rock_Volcanic_Brick",
      "rotation": 3
    },
    {
      "x": -21,
      "y": 2,
      "z": 16,
      "name": "Rock_Volcanic_Brick",
      "rotation": 3
    },
    {
      "x": -21,
      "y": 3,
      "z": 16,
      "name": "Rock_Volcanic_Brick",
      "rotation": 3
    },
    {
      "x": -21,
      "y": 4,
      "z": 16,
      "name": "Rock_Volcanic_Brick",
      "rotation": 3
    },
    {
      "x": -21,
      "y": 5,
      "z": 16,
      "name": "Rock_Volcanic_Brick_Stairs",
      "rotation": 3
    },
    {
      "x": -21,
      "y": 19,
      "z": 16,
      "name": "Rock_Volcanic_Brick_Smooth_Half",
      "rotation": 7
    },
    {
      "x": -21,
      "y": 24,
      "z": 16,
      "name": "Rock_Volcanic_Brick_Stairs",
      "rotation": 9
    },
    {
      "x": -21,
      "y": 25,
      "z": 16,
      "name": "Rock_Volcanic_Brick_Wall",
      "rotation": 1
    },
    {
      "x": -21,
      "y": 0,
      "z": 17,
      "name": "Rock_Volcanic_Brick",
      "rotation": 3
    },
    {
      "x": -21,
      "y": 1,
      "z": 17,
      "name": "Rock_Volcanic_Brick",
      "rotation": 3
    },
    {
      "x": -21,
      "y": 2,
      "z": 17,
      "name": "Rock_Volcanic_Brick",
      "rotation": 3
    },
    {
      "x": -21,
      "y": 3,
      "z": 17,
      "name": "Rock_Volcanic_Brick",
      "rotation": 3
    },
    {
      "x": -21,
      "y": 4,
      "z": 17,
      "name": "Rock_Volcanic_Brick",
      "rotation": 3
    },
    {
      "x": -21,
      "y": 5,
      "z": 17,
      "name": "Rock_Volcanic_Brick",
      "rotation": 3
    },
    {
      "x": -21,
      "y": 6,
      "z": 17,
      "name": "Rock_Volcanic_Brick",
      "rotation": 3
    },
    {
      "x": -21,
      "y": 7,
      "z": 17,
      "name": "Rock_Volcanic_Brick",
      "rotation": 3
    },
    {
      "x": -21,
      "y": 8,
      "z": 17,
      "name": "Rock_Volcanic_Brick_Stairs",
      "rotation": 3
    },
    {
      "x": -21,
      "y": 19,
      "z": 17,
      "name": "Rock_Volcanic_Brick_Smooth_Half",
      "rotation": 7
    },
    {
      "x": -21,
      "y": 22,
      "z": 17,
      "name": "Rock_Volcanic_Brick_Stairs",
      "rotation": 9
    },
    {
      "x": -21,
      "y": 23,
      "z": 17,
      "name": "Rock_Volcanic_Brick",
      "rotation": 3
    },
    {
      "x": -21,
      "y": 24,
      "z": 17,
      "name": "Rock_Volcanic_Brick",
      "rotation": 3
    },
    {
      "x": -21,
      "y": 25,
      "z": 17,
      "name": "Rock_Volcanic_Brick",
      "rotation": 3
    },
    {
      "x": -21,
      "y": 26,
      "z": 17,
      "name": "Rock_Volcanic_Brick_Stairs",
      "rotation": 3
    },
    {
      "x": -21,
      "y": 0,
      "z": 18,
      "name": "Rock_Volcanic_Brick",
      "rotation": 3
    },
    {
      "x": -21,
      "y": 1,
      "z": 18,
      "name": "Rock_Volcanic_Brick",
      "rotation": 3
    },
    {
      "x": -21,
      "y": 2,
      "z": 18,
      "name": "Rock_Volcanic_Brick",
      "rotation": 3
    },
    {
      "x": -21,
      "y": 3,
      "z": 18,
      "name": "Rock_Volcanic_Brick",
      "rotation": 3
    },
    {
      "x": -21,
      "y": 4,
      "z": 18,
      "name": "Rock_Volcanic_Brick",
      "rotation": 3
    },
    {
      "x": -21,
      "y": 5,
      "z": 18,
      "name": "Rock_Volcanic_Brick_Stairs",
      "rotation": 3
    },
    {
      "x": -21,
      "y": 19,
      "z": 18,
      "name": "Rock_Volcanic_Brick_Smooth_Half",
      "rotation": 7
    },
    {
      "x": -21,
      "y": 24,
      "z": 18,
      "name": "Rock_Volcanic_Brick_Stairs",
      "rotation": 9
    },
    {
      "x": -21,
      "y": 25,
      "z": 18,
      "name": "Rock_Volcanic_Brick_Wall",
      "rotation": 1
    },
    {
      "x": -21,
      "y": 19,
      "z": 19,
      "name": "Rock_Volcanic_Brick_Smooth_Half",
      "rotation": 7
    },
    {
      "x": -21,
      "y": 23,
      "z": 19,
      "name": "Rock_Volcanic_Brick_Stairs",
      "rotation": 9
    },
    {
      "x": -21,
      "y": 24,
      "z": 19,
      "name": "Rock_Volcanic_Brick",
      "rotation": 3
    },
    {
      "x": -21,
      "y": 25,
      "z": 19,
      "name": "Rock_Volcanic_Brick",
      "rotation": 3
    },
    {
      "x": -21,
      "y": 26,
      "z": 19,
      "name": "Rock_Volcanic_Brick_Stairs",
      "rotation": 3
    },
    {
      "x": -21,
      "y": 24,
      "z": 20,
      "name": "*Rock_Volcanic_Brick_Stairs_State_Definitions_Corner_Right",
      "rotation": 9
    },
    {
      "x": -20,
      "y": 24,
      "z": -20,
      "name": "*Rock_Volcanic_Brick_Stairs_State_Definitions_Corner_Right",
      "rotation": 8
    },
    {
      "x": -20,
      "y": 25,
      "z": -20,
      "name": "Rock_Volcanic_Brick",
      "rotation": 2
    },
    {
      "x": -20,
      "y": 26,
      "z": -20,
      "name": "Rock_Volcanic_Brick_Stairs",
      "rotation": 3
    },
    {
      "x": -20,
      "y": 19,
      "z": -19,
      "name": "Rock_Volcanic_Brick",
      "rotation": 2
    },
    {
      "x": -20,
      "y": 24,
      "z": -19,
      "name": "*Rock_Volcanic_Brick_Stairs_State_Definitions_Inverted_Corner_Left",
      "rotation": 9
    },
    {
      "x": -20,
      "y": 25,
      "z": -19,
      "name": "Rock_Volcanic_Brick_Wall",
      "rotation": 1
    },
    {
      "x": -20,
      "y": 0,
      "z": -18,
      "name": "Rock_Volcanic_Cobble",
      "rotation": 2
    },
    {
      "x": -20,
      "y": 1,
      "z": -18,
      "name": "Rock_Volcanic_Brick",
      "rotation": 2
    },
    {
      "x": -20,
      "y": 2,
      "z": -18,
      "name": "Rock_Volcanic_Cobble",
      "rotation": 2
    },
    {
      "x": -20,
      "y": 3,
      "z": -18,
      "name": "Rock_Volcanic_Cobble",
      "rotation": 2
    },
    {
      "x": -20,
      "y": 4,
      "z": -18,
      "name": "Rock_Volcanic_Cobble",
      "rotation": 2
    },
    {
      "x": -20,
      "y": 5,
      "z": -18,
      "name": "Rock_Volcanic_Cobble",
      "rotation": 2
    },
    {
      "x": -20,
      "y": 6,
      "z": -18,
      "name": "Rock_Volcanic_Cobble",
      "rotation": 2
    },
    {
      "x": -20,
      "y": 7,
      "z": -18,
      "name": "Rock_Volcanic_Cobble",
      "rotation": 2
    },
    {
      "x": -20,
      "y": 8,
      "z": -18,
      "name": "Rock_Volcanic_Brick",
      "rotation": 2
    },
    {
      "x": -20,
      "y": 9,
      "z": -18,
      "name": "Rock_Volcanic_Cobble",
      "rotation": 2
    },
    {
      "x": -20,
      "y": 10,
      "z": -18,
      "name": "Rock_Volcanic_Brick",
      "rotation": 2
    },
    {
      "x": -20,
      "y": 11,
      "z": -18,
      "name": "Rock_Volcanic_Brick",
      "rotation": 2
    },
    {
      "x": -20,
      "y": 12,
      "z": -18,
      "name": "Rock_Volcanic_Brick",
      "rotation": 2
    },
    {
      "x": -20,
      "y": 13,
      "z": -18,
      "name": "Rock_Volcanic_Cobble",
      "rotation": 2
    },
    {
      "x": -20,
      "y": 14,
      "z": -18,
      "name": "Rock_Volcanic_Cobble",
      "rotation": 2
    },
    {
      "x": -20,
      "y": 15,
      "z": -18,
      "name": "Rock_Volcanic_Brick",
      "rotation": 2
    },
    {
      "x": -20,
      "y": 16,
      "z": -18,
      "name": "Rock_Volcanic_Brick",
      "rotation": 2
    },
    {
      "x": -20,
      "y": 17,
      "z": -18,
      "name": "Rock_Volcanic_Cobble",
      "rotation": 2
    },
    {
      "x": -20,
      "y": 18,
      "z": -18,
      "name": "Rock_Volcanic_Cobble",
      "rotation": 2
    },
    {
      "x": -20,
      "y": 19,
      "z": -18,
      "name": "Rock_Volcanic_Cobble",
      "rotation": 2
    },
    {
      "x": -20,
      "y": 20,
      "z": -18,
      "name": "Rock_Volcanic_Brick",
      "rotation": 2
    },
    {
      "x": -20,
      "y": 21,
      "z": -18,
      "name": "Rock_Volcanic_Cobble",
      "rotation": 2
    },
    {
      "x": -20,
      "y": 22,
      "z": -18,
      "name": "Rock_Volcanic_Brick",
      "rotation": 2
    },
    {
      "x": -20,
      "y": 23,
      "z": -18,
      "name": "Rock_Volcanic_Brick",
      "rotation": 2
    },
    {
      "x": -20,
      "y": 24,
      "z": -18,
      "name": "Rock_Volcanic_Brick",
      "rotation": 2
    },
    {
      "x": -20,
      "y": 25,
      "z": -18,
      "name": "Rock_Volcanic_Brick_Stairs",
      "rotation": 1
    },
    {
      "x": -20,
      "y": 0,
      "z": -17,
      "name": "Rock_Volcanic_Brick",
      "rotation": 2
    },
    {
      "x": -20,
      "y": 1,
      "z": -17,
      "name": "Rock_Volcanic_Brick",
      "rotation": 2
    },
    {
      "x": -20,
      "y": 2,
      "z": -17,
      "name": "Rock_Volcanic_Cobble",
      "rotation": 2
    },
    {
      "x": -20,
      "y": 3,
      "z": -17,
      "name": "Rock_Volcanic_Cobble",
      "rotation": 2
    },
    {
      "x": -20,
      "y": 4,
      "z": -17,
      "name": "Rock_Volcanic_Brick",
      "rotation": 2
    },
    {
      "x": -20,
      "y": 5,
      "z": -17,
      "name": "Rock_Volcanic_Brick",
      "rotation": 2
    },
    {
      "x": -20,
      "y": 6,
      "z": -17,
      "name": "Rock_Volcanic_Brick",
      "rotation": 2
    },
    {
      "x": -20,
      "y": 7,
      "z": -17,
      "name": "Rock_Volcanic_Brick",
      "rotation": 2
    },
    {
      "x": -20,
      "y": 8,
      "z": -17,
      "name": "Rock_Volcanic_Brick",
      "rotation": 2
    },
    {
      "x": -20,
      "y": 9,
      "z": -17,
      "name": "Rock_Volcanic_Brick",
      "rotation": 2
    },
    {
      "x": -20,
      "y": 10,
      "z": -17,
      "name": "Rock_Volcanic_Brick",
      "rotation": 2
    },
    {
      "x": -20,
      "y": 11,
      "z": -17,
      "name": "Rock_Volcanic_Brick",
      "rotation": 2
    },
    {
      "x": -20,
      "y": 12,
      "z": -17,
      "name": "Rock_Volcanic_Brick",
      "rotation": 2
    },
    {
      "x": -20,
      "y": 13,
      "z": -17,
      "name": "Rock_Volcanic_Brick",
      "rotation": 2
    },
    {
      "x": -20,
      "y": 14,
      "z": -17,
      "name": "Rock_Volcanic_Cobble",
      "rotation": 2
    },
    {
      "x": -20,
      "y": 15,
      "z": -17,
      "name": "Rock_Volcanic_Cobble",
      "rotation": 2
    },
    {
      "x": -20,
      "y": 16,
      "z": -17,
      "name": "Rock_Volcanic_Brick",
      "rotation": 2
    },
    {
      "x": -20,
      "y": 17,
      "z": -17,
      "name": "Rock_Volcanic_Brick",
      "rotation": 2
    },
    {
      "x": -20,
      "y": 18,
      "z": -17,
      "name": "Rock_Volcanic_Brick",
      "rotation": 2
    },
    {
      "x": -20,
      "y": 19,
      "z": -17,
      "name": "Rock_Volcanic_Brick",
      "rotation": 2
    },
    {
      "x": -20,
      "y": 20,
      "z": -17,
      "name": "Rock_Volcanic_Brick",
      "rotation": 2
    },
    {
      "x": -20,
      "y": 21,
      "z": -17,
      "name": "Rock_Volcanic_Cobble",
      "rotation": 2
    },
    {
      "x": -20,
      "y": 22,
      "z": -17,
      "name": "Deco_Iron_Bars",
      "rotation": 3
    },
    {
      "x": -20,
      "y": 23,
      "z": -17,
      "name": "Deco_Iron_Bars",
      "rotation": 3
    },
    {
      "x": -20,
      "y": 24,
      "z": -17,
      "name": "Rock_Volcanic_Brick",
      "rotation": 2
    },
    {
      "x": -20,
      "y": 0,
      "z": -16,
      "name": "Rock_Volcanic_Cobble",
      "rotation": 2
    },
    {
      "x": -20,
      "y": 1,
      "z": -16,
      "name": "Rock_Volcanic_Brick",
      "rotation": 2
    },
    {
      "x": -20,
      "y": 2,
      "z": -16,
      "name": "Rock_Volcanic_Cobble",
      "rotation": 2
    },
    {
      "x": -20,
      "y": 3,
      "z": -16,
      "name": "Rock_Volcanic_Cobble",
      "rotation": 2
    },
    {
      "x": -20,
      "y": 4,
      "z": -16,
      "name": "Rock_Volcanic_Brick",
      "rotation": 2
    },
    {
      "x": -20,
      "y": 5,
      "z": -16,
      "name": "Rock_Volcanic_Brick",
      "rotation": 2
    },
    {
      "x": -20,
      "y": 6,
      "z": -16,
      "name": "Rock_Volcanic_Brick",
      "rotation": 2
    },
    {
      "x": -20,
      "y": 7,
      "z": -16,
      "name": "Rock_Volcanic_Cobble",
      "rotation": 2
    },
    {
      "x": -20,
      "y": 8,
      "z": -16,
      "name": "Rock_Volcanic_Brick",
      "rotation": 2
    },
    {
      "x": -20,
      "y": 9,
      "z": -16,
      "name": "Rock_Volcanic_Cobble",
      "rotation": 2
    },
    {
      "x": -20,
      "y": 10,
      "z": -16,
      "name": "Rock_Volcanic_Cobble",
      "rotation": 2
    },
    {
      "x": -20,
      "y": 11,
      "z": -16,
      "name": "Rock_Volcanic_Cobble",
      "rotation": 2
    },
    {
      "x": -20,
      "y": 12,
      "z": -16,
      "name": "Rock_Volcanic_Brick",
      "rotation": 2
    },
    {
      "x": -20,
      "y": 13,
      "z": -16,
      "name": "Rock_Volcanic_Brick",
      "rotation": 2
    },
    {
      "x": -20,
      "y": 14,
      "z": -16,
      "name": "Rock_Volcanic_Brick",
      "rotation": 2
    },
    {
      "x": -20,
      "y": 15,
      "z": -16,
      "name": "Rock_Volcanic_Cobble",
      "rotation": 2
    },
    {
      "x": -20,
      "y": 16,
      "z": -16,
      "name": "Rock_Volcanic_Cobble",
      "rotation": 2
    },
    {
      "x": -20,
      "y": 17,
      "z": -16,
      "name": "Rock_Volcanic_Cobble",
      "rotation": 2
    },
    {
      "x": -20,
      "y": 18,
      "z": -16,
      "name": "Rock_Volcanic_Brick",
      "rotation": 2
    },
    {
      "x": -20,
      "y": 19,
      "z": -16,
      "name": "Rock_Volcanic_Cobble",
      "rotation": 2
    },
    {
      "x": -20,
      "y": 20,
      "z": -16,
      "name": "Rock_Volcanic_Brick",
      "rotation": 2
    },
    {
      "x": -20,
      "y": 21,
      "z": -16,
      "name": "Rock_Volcanic_Cobble",
      "rotation": 2
    },
    {
      "x": -20,
      "y": 22,
      "z": -16,
      "name": "Rock_Volcanic_Cobble",
      "rotation": 2
    },
    {
      "x": -20,
      "y": 23,
      "z": -16,
      "name": "Rock_Volcanic_Cobble",
      "rotation": 2
    },
    {
      "x": -20,
      "y": 24,
      "z": -16,
      "name": "Rock_Volcanic_Brick",
      "rotation": 2
    },
    {
      "x": -20,
      "y": 25,
      "z": -16,
      "name": "Rock_Volcanic_Brick_Stairs",
      "rotation": 1
    },
    {
      "x": -20,
      "y": 0,
      "z": -15,
      "name": "Rock_Volcanic_Cobble",
      "rotation": 2
    },
    {
      "x": -20,
      "y": 1,
      "z": -15,
      "name": "Rock_Volcanic_Brick",
      "rotation": 2
    },
    {
      "x": -20,
      "y": 2,
      "z": -15,
      "name": "Rock_Volcanic_Cobble",
      "rotation": 2
    },
    {
      "x": -20,
      "y": 3,
      "z": -15,
      "name": "Rock_Volcanic_Brick",
      "rotation": 2
    },
    {
      "x": -20,
      "y": 4,
      "z": -15,
      "name": "Rock_Volcanic_Brick",
      "rotation": 2
    },
    {
      "x": -20,
      "y": 5,
      "z": -15,
      "name": "Rock_Volcanic_Cobble",
      "rotation": 2
    },
    {
      "x": -20,
      "y": 6,
      "z": -15,
      "name": "Rock_Volcanic_Brick",
      "rotation": 2
    },
    {
      "x": -20,
      "y": 7,
      "z": -15,
      "name": "Rock_Volcanic_Cobble",
      "rotation": 2
    },
    {
      "x": -20,
      "y": 8,
      "z": -15,
      "name": "Rock_Volcanic_Cobble",
      "rotation": 2
    },
    {
      "x": -20,
      "y": 9,
      "z": -15,
      "name": "Rock_Volcanic_Brick",
      "rotation": 2
    },
    {
      "x": -20,
      "y": 10,
      "z": -15,
      "name": "Rock_Volcanic_Brick",
      "rotation": 2
    },
    {
      "x": -20,
      "y": 11,
      "z": -15,
      "name": "Rock_Volcanic_Cobble",
      "rotation": 2
    },
    {
      "x": -20,
      "y": 12,
      "z": -15,
      "name": "Rock_Volcanic_Cobble",
      "rotation": 2
    },
    {
      "x": -20,
      "y": 13,
      "z": -15,
      "name": "Rock_Volcanic_Brick",
      "rotation": 2
    },
    {
      "x": -20,
      "y": 14,
      "z": -15,
      "name": "Rock_Volcanic_Brick",
      "rotation": 2
    },
    {
      "x": -20,
      "y": 15,
      "z": -15,
      "name": "Rock_Volcanic_Cobble",
      "rotation": 2
    },
    {
      "x": -20,
      "y": 16,
      "z": -15,
      "name": "Rock_Volcanic_Cobble",
      "rotation": 2
    },
    {
      "x": -20,
      "y": 17,
      "z": -15,
      "name": "Rock_Volcanic_Cobble",
      "rotation": 2
    },
    {
      "x": -20,
      "y": 18,
      "z": -15,
      "name": "Rock_Volcanic_Cobble",
      "rotation": 2
    },
    {
      "x": -20,
      "y": 19,
      "z": -15,
      "name": "Rock_Volcanic_Brick",
      "rotation": 2
    },
    {
      "x": -20,
      "y": 20,
      "z": -15,
      "name": "Rock_Volcanic_Cobble",
      "rotation": 2
    },
    {
      "x": -20,
      "y": 21,
      "z": -15,
      "name": "Rock_Volcanic_Brick",
      "rotation": 2
    },
    {
      "x": -20,
      "y": 22,
      "z": -15,
      "name": "Deco_Iron_Bars",
      "rotation": 3
    },
    {
      "x": -20,
      "y": 23,
      "z": -15,
      "name": "Deco_Iron_Bars",
      "rotation": 3
    },
    {
      "x": -20,
      "y": 24,
      "z": -15,
      "name": "Rock_Volcanic_Brick",
      "rotation": 2
    },
    {
      "x": -20,
      "y": 0,
      "z": -14,
      "name": "Rock_Volcanic_Cobble",
      "rotation": 2
    },
    {
      "x": -20,
      "y": 1,
      "z": -14,
      "name": "Rock_Volcanic_Cobble",
      "rotation": 2
    },
    {
      "x": -20,
      "y": 2,
      "z": -14,
      "name": "Rock_Volcanic_Cobble",
      "rotation": 2
    },
    {
      "x": -20,
      "y": 3,
      "z": -14,
      "name": "Rock_Volcanic_Brick",
      "rotation": 2
    },
    {
      "x": -20,
      "y": 4,
      "z": -14,
      "name": "Rock_Volcanic_Brick",
      "rotation": 2
    },
    {
      "x": -20,
      "y": 5,
      "z": -14,
      "name": "Rock_Volcanic_Cobble",
      "rotation": 2
    },
    {
      "x": -20,
      "y": 6,
      "z": -14,
      "name": "Rock_Volcanic_Cobble",
      "rotation": 2
    },
    {
      "x": -20,
      "y": 7,
      "z": -14,
      "name": "Rock_Volcanic_Brick",
      "rotation": 2
    },
    {
      "x": -20,
      "y": 8,
      "z": -14,
      "name": "Rock_Volcanic_Cobble",
      "rotation": 2
    },
    {
      "x": -20,
      "y": 9,
      "z": -14,
      "name": "Rock_Volcanic_Cobble",
      "rotation": 2
    },
    {
      "x": -20,
      "y": 10,
      "z": -14,
      "name": "Rock_Volcanic_Cobble",
      "rotation": 2
    },
    {
      "x": -20,
      "y": 11,
      "z": -14,
      "name": "Rock_Volcanic_Cobble",
      "rotation": 2
    },
    {
      "x": -20,
      "y": 12,
      "z": -14,
      "name": "Rock_Volcanic_Brick",
      "rotation": 2
    },
    {
      "x": -20,
      "y": 13,
      "z": -14,
      "name": "Rock_Volcanic_Cobble",
      "rotation": 2
    },
    {
      "x": -20,
      "y": 14,
      "z": -14,
      "name": "Rock_Volcanic_Brick",
      "rotation": 2
    },
    {
      "x": -20,
      "y": 15,
      "z": -14,
      "name": "Rock_Volcanic_Cobble",
      "rotation": 2
    },
    {
      "x": -20,
      "y": 16,
      "z": -14,
      "name": "Rock_Volcanic_Brick",
      "rotation": 2
    },
    {
      "x": -20,
      "y": 17,
      "z": -14,
      "name": "Rock_Volcanic_Brick",
      "rotation": 2
    },
    {
      "x": -20,
      "y": 18,
      "z": -14,
      "name": "Rock_Volcanic_Cobble",
      "rotation": 2
    },
    {
      "x": -20,
      "y": 19,
      "z": -14,
      "name": "Rock_Volcanic_Brick",
      "rotation": 2
    },
    {
      "x": -20,
      "y": 20,
      "z": -14,
      "name": "Rock_Volcanic_Brick",
      "rotation": 2
    },
    {
      "x": -20,
      "y": 21,
      "z": -14,
      "name": "Rock_Volcanic_Brick",
      "rotation": 2
    },
    {
      "x": -20,
      "y": 22,
      "z": -14,
      "name": "Rock_Volcanic_Brick",
      "rotation": 2
    },
    {
      "x": -20,
      "y": 23,
      "z": -14,
      "name": "Rock_Volcanic_Brick",
      "rotation": 2
    },
    {
      "x": -20,
      "y": 24,
      "z": -14,
      "name": "Rock_Volcanic_Brick",
      "rotation": 2
    },
    {
      "x": -20,
      "y": 25,
      "z": -14,
      "name": "Rock_Volcanic_Brick_Stairs",
      "rotation": 1
    },
    {
      "x": -20,
      "y": 19,
      "z": -13,
      "name": "Rock_Volcanic_Brick",
      "rotation": 2
    },
    {
      "x": -20,
      "y": 24,
      "z": -13,
      "name": "*Rock_Volcanic_Brick_Stairs_State_Definitions_Inverted_Corner_Left",
      "rotation": 10
    },
    {
      "x": -20,
      "y": 25,
      "z": -13,
      "name": "Rock_Volcanic_Brick_Wall",
      "rotation": 1
    },
    {
      "x": -20,
      "y": 24,
      "z": -12,
      "name": "*Rock_Volcanic_Brick_Stairs_State_Definitions_Corner_Right",
      "rotation": 9
    },
    {
      "x": -20,
      "y": 25,
      "z": -12,
      "name": "Rock_Volcanic_Brick",
      "rotation": 2
    },
    {
      "x": -20,
      "y": 26,
      "z": -12,
      "name": "Rock_Volcanic_Brick_Stairs",
      "rotation": 3
    },
    {
      "x": -20,
      "y": 24,
      "z": 13,
      "name": "*Rock_Volcanic_Brick_Stairs_State_Definitions_Corner_Right",
      "rotation": 8
    },
    {
      "x": -20,
      "y": 25,
      "z": 13,
      "name": "Rock_Volcanic_Brick",
      "rotation": 3
    },
    {
      "x": -20,
      "y": 26,
      "z": 13,
      "name": "Rock_Volcanic_Brick_Stairs",
      "rotation": 3
    },
    {
      "x": -20,
      "y": 19,
      "z": 14,
      "name": "Rock_Volcanic_Brick",
      "rotation": 3
    },
    {
      "x": -20,
      "y": 24,
      "z": 14,
      "name": "*Rock_Volcanic_Brick_Stairs_State_Definitions_Inverted_Corner_Left",
      "rotation": 9
    },
    {
      "x": -20,
      "y": 25,
      "z": 14,
      "name": "Rock_Volcanic_Brick_Wall",
      "rotation": 1
    },
    {
      "x": -20,
      "y": 0,
      "z": 15,
      "name": "Rock_Volcanic_Cobble",
      "rotation": 3
    },
    {
      "x": -20,
      "y": 1,
      "z": 15,
      "name": "Rock_Volcanic_Cobble",
      "rotation": 3
    },
    {
      "x": -20,
      "y": 2,
      "z": 15,
      "name": "Rock_Volcanic_Cobble",
      "rotation": 3
    },
    {
      "x": -20,
      "y": 3,
      "z": 15,
      "name": "Rock_Volcanic_Cobble",
      "rotation": 3
    },
    {
      "x": -20,
      "y": 4,
      "z": 15,
      "name": "Rock_Volcanic_Cobble",
      "rotation": 3
    },
    {
      "x": -20,
      "y": 5,
      "z": 15,
      "name": "Rock_Volcanic_Cobble",
      "rotation": 3
    },
    {
      "x": -20,
      "y": 6,
      "z": 15,
      "name": "Rock_Volcanic_Brick",
      "rotation": 3
    },
    {
      "x": -20,
      "y": 7,
      "z": 15,
      "name": "Rock_Volcanic_Brick",
      "rotation": 3
    },
    {
      "x": -20,
      "y": 8,
      "z": 15,
      "name": "Rock_Volcanic_Brick",
      "rotation": 3
    },
    {
      "x": -20,
      "y": 9,
      "z": 15,
      "name": "Rock_Volcanic_Brick",
      "rotation": 3
    },
    {
      "x": -20,
      "y": 10,
      "z": 15,
      "name": "Rock_Volcanic_Brick",
      "rotation": 3
    },
    {
      "x": -20,
      "y": 11,
      "z": 15,
      "name": "Rock_Volcanic_Cobble",
      "rotation": 3
    },
    {
      "x": -20,
      "y": 12,
      "z": 15,
      "name": "Rock_Volcanic_Cobble",
      "rotation": 3
    },
    {
      "x": -20,
      "y": 13,
      "z": 15,
      "name": "Rock_Volcanic_Cobble",
      "rotation": 3
    },
    {
      "x": -20,
      "y": 14,
      "z": 15,
      "name": "Rock_Volcanic_Brick",
      "rotation": 3
    },
    {
      "x": -20,
      "y": 15,
      "z": 15,
      "name": "Rock_Volcanic_Cobble",
      "rotation": 3
    },
    {
      "x": -20,
      "y": 16,
      "z": 15,
      "name": "Rock_Volcanic_Brick",
      "rotation": 3
    },
    {
      "x": -20,
      "y": 17,
      "z": 15,
      "name": "Rock_Volcanic_Cobble",
      "rotation": 3
    },
    {
      "x": -20,
      "y": 18,
      "z": 15,
      "name": "Rock_Volcanic_Brick",
      "rotation": 3
    },
    {
      "x": -20,
      "y": 19,
      "z": 15,
      "name": "Rock_Volcanic_Brick",
      "rotation": 3
    },
    {
      "x": -20,
      "y": 20,
      "z": 15,
      "name": "Rock_Volcanic_Cobble",
      "rotation": 3
    },
    {
      "x": -20,
      "y": 21,
      "z": 15,
      "name": "Rock_Volcanic_Cobble",
      "rotation": 3
    },
    {
      "x": -20,
      "y": 22,
      "z": 15,
      "name": "Rock_Volcanic_Cobble",
      "rotation": 3
    },
    {
      "x": -20,
      "y": 23,
      "z": 15,
      "name": "Rock_Volcanic_Brick",
      "rotation": 3
    },
    {
      "x": -20,
      "y": 24,
      "z": 15,
      "name": "Rock_Volcanic_Brick",
      "rotation": 3
    },
    {
      "x": -20,
      "y": 25,
      "z": 15,
      "name": "Rock_Volcanic_Brick_Stairs",
      "rotation": 1
    },
    {
      "x": -20,
      "y": 0,
      "z": 16,
      "name": "Rock_Volcanic_Cobble",
      "rotation": 3
    },
    {
      "x": -20,
      "y": 1,
      "z": 16,
      "name": "Rock_Volcanic_Brick",
      "rotation": 3
    },
    {
      "x": -20,
      "y": 2,
      "z": 16,
      "name": "Rock_Volcanic_Brick",
      "rotation": 3
    },
    {
      "x": -20,
      "y": 3,
      "z": 16,
      "name": "Rock_Volcanic_Brick",
      "rotation": 3
    },
    {
      "x": -20,
      "y": 4,
      "z": 16,
      "name": "Rock_Volcanic_Brick",
      "rotation": 3
    },
    {
      "x": -20,
      "y": 5,
      "z": 16,
      "name": "Rock_Volcanic_Cobble",
      "rotation": 3
    },
    {
      "x": -20,
      "y": 6,
      "z": 16,
      "name": "Rock_Volcanic_Cobble",
      "rotation": 3
    },
    {
      "x": -20,
      "y": 7,
      "z": 16,
      "name": "Rock_Volcanic_Cobble",
      "rotation": 3
    },
    {
      "x": -20,
      "y": 8,
      "z": 16,
      "name": "Rock_Volcanic_Cobble",
      "rotation": 3
    },
    {
      "x": -20,
      "y": 9,
      "z": 16,
      "name": "Rock_Volcanic_Cobble",
      "rotation": 3
    },
    {
      "x": -20,
      "y": 10,
      "z": 16,
      "name": "Rock_Volcanic_Brick",
      "rotation": 3
    },
    {
      "x": -20,
      "y": 11,
      "z": 16,
      "name": "Rock_Volcanic_Brick",
      "rotation": 3
    },
    {
      "x": -20,
      "y": 12,
      "z": 16,
      "name": "Rock_Volcanic_Cobble",
      "rotation": 3
    },
    {
      "x": -20,
      "y": 13,
      "z": 16,
      "name": "Rock_Volcanic_Brick",
      "rotation": 3
    },
    {
      "x": -20,
      "y": 14,
      "z": 16,
      "name": "Rock_Volcanic_Cobble",
      "rotation": 3
    },
    {
      "x": -20,
      "y": 15,
      "z": 16,
      "name": "Rock_Volcanic_Brick",
      "rotation": 3
    },
    {
      "x": -20,
      "y": 16,
      "z": 16,
      "name": "Rock_Volcanic_Cobble",
      "rotation": 3
    },
    {
      "x": -20,
      "y": 17,
      "z": 16,
      "name": "Rock_Volcanic_Brick",
      "rotation": 3
    },
    {
      "x": -20,
      "y": 18,
      "z": 16,
      "name": "Rock_Volcanic_Brick",
      "rotation": 3
    },
    {
      "x": -20,
      "y": 19,
      "z": 16,
      "name": "Rock_Volcanic_Brick",
      "rotation": 3
    },
    {
      "x": -20,
      "y": 20,
      "z": 16,
      "name": "Rock_Volcanic_Cobble",
      "rotation": 3
    },
    {
      "x": -20,
      "y": 21,
      "z": 16,
      "name": "Rock_Volcanic_Brick",
      "rotation": 3
    },
    {
      "x": -20,
      "y": 22,
      "z": 16,
      "name": "Deco_Iron_Bars",
      "rotation": 3
    },
    {
      "x": -20,
      "y": 23,
      "z": 16,
      "name": "Deco_Iron_Bars",
      "rotation": 3
    },
    {
      "x": -20,
      "y": 24,
      "z": 16,
      "name": "Rock_Volcanic_Brick",
      "rotation": 3
    },
    {
      "x": -20,
      "y": 0,
      "z": 17,
      "name": "Rock_Volcanic_Cobble",
      "rotation": 3
    },
    {
      "x": -20,
      "y": 1,
      "z": 17,
      "name": "Rock_Volcanic_Cobble",
      "rotation": 3
    },
    {
      "x": -20,
      "y": 2,
      "z": 17,
      "name": "Rock_Volcanic_Cobble",
      "rotation": 3
    },
    {
      "x": -20,
      "y": 3,
      "z": 17,
      "name": "Rock_Volcanic_Brick",
      "rotation": 3
    },
    {
      "x": -20,
      "y": 4,
      "z": 17,
      "name": "Rock_Volcanic_Brick",
      "rotation": 3
    },
    {
      "x": -20,
      "y": 5,
      "z": 17,
      "name": "Rock_Volcanic_Cobble",
      "rotation": 3
    },
    {
      "x": -20,
      "y": 6,
      "z": 17,
      "name": "Rock_Volcanic_Cobble",
      "rotation": 3
    },
    {
      "x": -20,
      "y": 7,
      "z": 17,
      "name": "Rock_Volcanic_Cobble",
      "rotation": 3
    },
    {
      "x": -20,
      "y": 8,
      "z": 17,
      "name": "Rock_Volcanic_Brick",
      "rotation": 3
    },
    {
      "x": -20,
      "y": 9,
      "z": 17,
      "name": "Rock_Volcanic_Cobble",
      "rotation": 3
    },
    {
      "x": -20,
      "y": 10,
      "z": 17,
      "name": "Rock_Volcanic_Brick",
      "rotation": 3
    },
    {
      "x": -20,
      "y": 11,
      "z": 17,
      "name": "Rock_Volcanic_Cobble",
      "rotation": 3
    },
    {
      "x": -20,
      "y": 12,
      "z": 17,
      "name": "Rock_Volcanic_Brick",
      "rotation": 3
    },
    {
      "x": -20,
      "y": 13,
      "z": 17,
      "name": "Rock_Volcanic_Cobble",
      "rotation": 3
    },
    {
      "x": -20,
      "y": 14,
      "z": 17,
      "name": "Rock_Volcanic_Brick",
      "rotation": 3
    },
    {
      "x": -20,
      "y": 15,
      "z": 17,
      "name": "Rock_Volcanic_Brick",
      "rotation": 3
    },
    {
      "x": -20,
      "y": 16,
      "z": 17,
      "name": "Rock_Volcanic_Cobble",
      "rotation": 3
    },
    {
      "x": -20,
      "y": 17,
      "z": 17,
      "name": "Rock_Volcanic_Cobble",
      "rotation": 3
    },
    {
      "x": -20,
      "y": 18,
      "z": 17,
      "name": "Rock_Volcanic_Brick",
      "rotation": 3
    },
    {
      "x": -20,
      "y": 19,
      "z": 17,
      "name": "Rock_Volcanic_Brick",
      "rotation": 3
    },
    {
      "x": -20,
      "y": 20,
      "z": 17,
      "name": "Rock_Volcanic_Brick",
      "rotation": 3
    },
    {
      "x": -20,
      "y": 21,
      "z": 17,
      "name": "Rock_Volcanic_Cobble",
      "rotation": 3
    },
    {
      "x": -20,
      "y": 22,
      "z": 17,
      "name": "Rock_Volcanic_Cobble",
      "rotation": 3
    },
    {
      "x": -20,
      "y": 23,
      "z": 17,
      "name": "Rock_Volcanic_Brick",
      "rotation": 3
    },
    {
      "x": -20,
      "y": 24,
      "z": 17,
      "name": "Rock_Volcanic_Brick",
      "rotation": 3
    },
    {
      "x": -20,
      "y": 25,
      "z": 17,
      "name": "Rock_Volcanic_Brick_Stairs",
      "rotation": 1
    },
    {
      "x": -20,
      "y": 0,
      "z": 18,
      "name": "Rock_Volcanic_Brick",
      "rotation": 3
    },
    {
      "x": -20,
      "y": 1,
      "z": 18,
      "name": "Rock_Volcanic_Brick",
      "rotation": 3
    },
    {
      "x": -20,
      "y": 2,
      "z": 18,
      "name": "Rock_Volcanic_Cobble",
      "rotation": 3
    },
    {
      "x": -20,
      "y": 3,
      "z": 18,
      "name": "Rock_Volcanic_Cobble",
      "rotation": 3
    },
    {
      "x": -20,
      "y": 4,
      "z": 18,
      "name": "Rock_Volcanic_Brick",
      "rotation": 3
    },
    {
      "x": -20,
      "y": 5,
      "z": 18,
      "name": "Rock_Volcanic_Cobble",
      "rotation": 3
    },
    {
      "x": -20,
      "y": 6,
      "z": 18,
      "name": "Rock_Volcanic_Cobble",
      "rotation": 3
    },
    {
      "x": -20,
      "y": 7,
      "z": 18,
      "name": "Rock_Volcanic_Brick",
      "rotation": 3
    },
    {
      "x": -20,
      "y": 8,
      "z": 18,
      "name": "Rock_Volcanic_Cobble",
      "rotation": 3
    },
    {
      "x": -20,
      "y": 9,
      "z": 18,
      "name": "Rock_Volcanic_Cobble",
      "rotation": 3
    },
    {
      "x": -20,
      "y": 10,
      "z": 18,
      "name": "Rock_Volcanic_Cobble",
      "rotation": 3
    },
    {
      "x": -20,
      "y": 11,
      "z": 18,
      "name": "Rock_Volcanic_Cobble",
      "rotation": 3
    },
    {
      "x": -20,
      "y": 12,
      "z": 18,
      "name": "Rock_Volcanic_Brick",
      "rotation": 3
    },
    {
      "x": -20,
      "y": 13,
      "z": 18,
      "name": "Rock_Volcanic_Cobble",
      "rotation": 3
    },
    {
      "x": -20,
      "y": 14,
      "z": 18,
      "name": "Rock_Volcanic_Cobble",
      "rotation": 3
    },
    {
      "x": -20,
      "y": 15,
      "z": 18,
      "name": "Rock_Volcanic_Cobble",
      "rotation": 3
    },
    {
      "x": -20,
      "y": 16,
      "z": 18,
      "name": "Rock_Volcanic_Brick",
      "rotation": 3
    },
    {
      "x": -20,
      "y": 17,
      "z": 18,
      "name": "Rock_Volcanic_Cobble",
      "rotation": 3
    },
    {
      "x": -20,
      "y": 18,
      "z": 18,
      "name": "Rock_Volcanic_Cobble",
      "rotation": 3
    },
    {
      "x": -20,
      "y": 19,
      "z": 18,
      "name": "Rock_Volcanic_Brick",
      "rotation": 3
    },
    {
      "x": -20,
      "y": 20,
      "z": 18,
      "name": "Rock_Volcanic_Cobble",
      "rotation": 3
    },
    {
      "x": -20,
      "y": 21,
      "z": 18,
      "name": "Rock_Volcanic_Cobble",
      "rotation": 3
    },
    {
      "x": -20,
      "y": 22,
      "z": 18,
      "name": "Deco_Iron_Bars",
      "rotation": 3
    },
    {
      "x": -20,
      "y": 23,
      "z": 18,
      "name": "Deco_Iron_Bars",
      "rotation": 3
    },
    {
      "x": -20,
      "y": 24,
      "z": 18,
      "name": "Rock_Volcanic_Brick",
      "rotation": 3
    },
    {
      "x": -20,
      "y": 0,
      "z": 19,
      "name": "Rock_Volcanic_Cobble",
      "rotation": 3
    },
    {
      "x": -20,
      "y": 1,
      "z": 19,
      "name": "Rock_Volcanic_Cobble",
      "rotation": 3
    },
    {
      "x": -20,
      "y": 2,
      "z": 19,
      "name": "Rock_Volcanic_Brick",
      "rotation": 3
    },
    {
      "x": -20,
      "y": 3,
      "z": 19,
      "name": "Rock_Volcanic_Cobble",
      "rotation": 3
    },
    {
      "x": -20,
      "y": 4,
      "z": 19,
      "name": "Rock_Volcanic_Cobble",
      "rotation": 3
    },
    {
      "x": -20,
      "y": 5,
      "z": 19,
      "name": "Rock_Volcanic_Brick",
      "rotation": 3
    },
    {
      "x": -20,
      "y": 6,
      "z": 19,
      "name": "Rock_Volcanic_Cobble",
      "rotation": 3
    },
    {
      "x": -20,
      "y": 7,
      "z": 19,
      "name": "Rock_Volcanic_Cobble",
      "rotation": 3
    },
    {
      "x": -20,
      "y": 8,
      "z": 19,
      "name": "Rock_Volcanic_Brick",
      "rotation": 3
    },
    {
      "x": -20,
      "y": 9,
      "z": 19,
      "name": "Rock_Volcanic_Cobble",
      "rotation": 3
    },
    {
      "x": -20,
      "y": 10,
      "z": 19,
      "name": "Rock_Volcanic_Brick",
      "rotation": 3
    },
    {
      "x": -20,
      "y": 11,
      "z": 19,
      "name": "Rock_Volcanic_Brick",
      "rotation": 3
    },
    {
      "x": -20,
      "y": 12,
      "z": 19,
      "name": "Rock_Volcanic_Brick",
      "rotation": 3
    },
    {
      "x": -20,
      "y": 13,
      "z": 19,
      "name": "Rock_Volcanic_Brick",
      "rotation": 3
    },
    {
      "x": -20,
      "y": 14,
      "z": 19,
      "name": "Rock_Volcanic_Brick",
      "rotation": 3
    },
    {
      "x": -20,
      "y": 15,
      "z": 19,
      "name": "Rock_Volcanic_Brick",
      "rotation": 3
    },
    {
      "x": -20,
      "y": 16,
      "z": 19,
      "name": "Rock_Volcanic_Brick",
      "rotation": 3
    },
    {
      "x": -20,
      "y": 17,
      "z": 19,
      "name": "Rock_Volcanic_Brick",
      "rotation": 3
    },
    {
      "x": -20,
      "y": 18,
      "z": 19,
      "name": "Rock_Volcanic_Cobble",
      "rotation": 3
    },
    {
      "x": -20,
      "y": 19,
      "z": 19,
      "name": "Rock_Volcanic_Cobble",
      "rotation": 3
    },
    {
      "x": -20,
      "y": 20,
      "z": 19,
      "name": "Rock_Volcanic_Brick",
      "rotation": 3
    },
    {
      "x": -20,
      "y": 21,
      "z": 19,
      "name": "Rock_Volcanic_Cobble",
      "rotation": 3
    },
    {
      "x": -20,
      "y": 22,
      "z": 19,
      "name": "Rock_Volcanic_Cobble",
      "rotation": 3
    },
    {
      "x": -20,
      "y": 23,
      "z": 19,
      "name": "Rock_Volcanic_Brick",
      "rotation": 3
    },
    {
      "x": -20,
      "y": 24,
      "z": 19,
      "name": "Rock_Volcanic_Brick",
      "rotation": 3
    },
    {
      "x": -20,
      "y": 25,
      "z": 19,
      "name": "Rock_Volcanic_Brick_Stairs",
      "rotation": 1
    },
    {
      "x": -20,
      "y": 19,
      "z": 20,
      "name": "Rock_Volcanic_Brick",
      "rotation": 3
    },
    {
      "x": -20,
      "y": 24,
      "z": 20,
      "name": "*Rock_Volcanic_Brick_Stairs_State_Definitions_Inverted_Corner_Left",
      "rotation": 10
    },
    {
      "x": -20,
      "y": 25,
      "z": 20,
      "name": "Rock_Volcanic_Brick_Wall",
      "rotation": 1
    },
    {
      "x": -20,
      "y": 24,
      "z": 21,
      "name": "*Rock_Volcanic_Brick_Stairs_State_Definitions_Corner_Right",
      "rotation": 9
    },
    {
      "x": -20,
      "y": 25,
      "z": 21,
      "name": "Rock_Volcanic_Brick",
      "rotation": 3
    },
    {
      "x": -20,
      "y": 26,
      "z": 21,
      "name": "Rock_Volcanic_Brick_Stairs",
      "rotation": 3
    },
    {
      "x": -19,
      "y": 24,
      "z": -21,
      "name": "*Rock_Volcanic_Brick_Stairs_State_Definitions_Corner_Right",
      "rotation": 8
    },
    {
      "x": -19,
      "y": 25,
      "z": -21,
      "name": "Rock_Volcanic_Brick",
      "rotation": 2
    },
    {
      "x": -19,
      "y": 26,
      "z": -21,
      "name": "Rock_Volcanic_Brick_Stairs",
      "rotation": 2
    },
    {
      "x": -19,
      "y": 19,
      "z": -20,
      "name": "Rock_Volcanic_Brick",
      "rotation": 2
    },
    {
      "x": -19,
      "y": 24,
      "z": -20,
      "name": "*Rock_Volcanic_Brick_Stairs_State_Definitions_Inverted_Corner_Left",
      "rotation": 9
    },
    {
      "x": -19,
      "y": 0,
      "z": -19,
      "name": "Rock_Volcanic_Cobble",
      "rotation": 2
    },
    {
      "x": -19,
      "y": 1,
      "z": -19,
      "name": "Rock_Volcanic_Cobble",
      "rotation": 2
    },
    {
      "x": -19,
      "y": 2,
      "z": -19,
      "name": "Rock_Volcanic_Brick",
      "rotation": 2
    },
    {
      "x": -19,
      "y": 3,
      "z": -19,
      "name": "Rock_Volcanic_Cobble",
      "rotation": 2
    },
    {
      "x": -19,
      "y": 4,
      "z": -19,
      "name": "Rock_Volcanic_Brick",
      "rotation": 2
    },
    {
      "x": -19,
      "y": 5,
      "z": -19,
      "name": "Rock_Volcanic_Brick",
      "rotation": 2
    },
    {
      "x": -19,
      "y": 6,
      "z": -19,
      "name": "Rock_Volcanic_Brick",
      "rotation": 2
    },
    {
      "x": -19,
      "y": 7,
      "z": -19,
      "name": "Rock_Volcanic_Brick",
      "rotation": 2
    },
    {
      "x": -19,
      "y": 8,
      "z": -19,
      "name": "Rock_Volcanic_Brick",
      "rotation": 2
    },
    {
      "x": -19,
      "y": 9,
      "z": -19,
      "name": "Rock_Volcanic_Brick",
      "rotation": 2
    },
    {
      "x": -19,
      "y": 10,
      "z": -19,
      "name": "Rock_Volcanic_Cobble",
      "rotation": 2
    },
    {
      "x": -19,
      "y": 11,
      "z": -19,
      "name": "Rock_Volcanic_Cobble",
      "rotation": 2
    },
    {
      "x": -19,
      "y": 12,
      "z": -19,
      "name": "Rock_Volcanic_Brick",
      "rotation": 2
    },
    {
      "x": -19,
      "y": 13,
      "z": -19,
      "name": "Rock_Volcanic_Cobble",
      "rotation": 2
    },
    {
      "x": -19,
      "y": 14,
      "z": -19,
      "name": "Rock_Volcanic_Cobble",
      "rotation": 2
    },
    {
      "x": -19,
      "y": 15,
      "z": -19,
      "name": "Rock_Volcanic_Cobble",
      "rotation": 2
    },
    {
      "x": -19,
      "y": 16,
      "z": -19,
      "name": "Rock_Volcanic_Brick",
      "rotation": 2
    },
    {
      "x": -19,
      "y": 17,
      "z": -19,
      "name": "Rock_Volcanic_Cobble",
      "rotation": 2
    },
    {
      "x": -19,
      "y": 18,
      "z": -19,
      "name": "Rock_Volcanic_Brick",
      "rotation": 2
    },
    {
      "x": -19,
      "y": 19,
      "z": -19,
      "name": "Rock_Volcanic_Brick",
      "rotation": 2
    },
    {
      "x": -19,
      "y": 20,
      "z": -19,
      "name": "Rock_Volcanic_Brick",
      "rotation": 2
    },
    {
      "x": -19,
      "y": 21,
      "z": -19,
      "name": "Rock_Volcanic_Cobble",
      "rotation": 2
    },
    {
      "x": -19,
      "y": 22,
      "z": -19,
      "name": "Rock_Volcanic_Brick",
      "rotation": 2
    },
    {
      "x": -19,
      "y": 23,
      "z": -19,
      "name": "Rock_Volcanic_Brick",
      "rotation": 2
    },
    {
      "x": -19,
      "y": 24,
      "z": -19,
      "name": "Rock_Volcanic_Brick",
      "rotation": 2
    },
    {
      "x": -19,
      "y": 0,
      "z": -18,
      "name": "Rock_Volcanic_Brick",
      "rotation": 2
    },
    {
      "x": -19,
      "y": 1,
      "z": -18,
      "name": "Rock_Volcanic_Brick",
      "rotation": 2
    },
    {
      "x": -19,
      "y": 2,
      "z": -18,
      "name": "Rock_Volcanic_Cobble",
      "rotation": 2
    },
    {
      "x": -19,
      "y": 3,
      "z": -18,
      "name": "Rock_Volcanic_Brick",
      "rotation": 2
    },
    {
      "x": -19,
      "y": 4,
      "z": -18,
      "name": "Rock_Volcanic_Cobble",
      "rotation": 2
    },
    {
      "x": -19,
      "y": 5,
      "z": -18,
      "name": "Rock_Volcanic_Brick",
      "rotation": 2
    },
    {
      "x": -19,
      "y": 6,
      "z": -18,
      "name": "Rock_Volcanic_Brick",
      "rotation": 2
    },
    {
      "x": -19,
      "y": 7,
      "z": -18,
      "name": "Rock_Volcanic_Cobble",
      "rotation": 2
    },
    {
      "x": -19,
      "y": 8,
      "z": -18,
      "name": "Rock_Volcanic_Brick",
      "rotation": 2
    },
    {
      "x": -19,
      "y": 9,
      "z": -18,
      "name": "Rock_Volcanic_Brick",
      "rotation": 2
    },
    {
      "x": -19,
      "y": 10,
      "z": -18,
      "name": "Rock_Volcanic_Cobble",
      "rotation": 2
    },
    {
      "x": -19,
      "y": 11,
      "z": -18,
      "name": "Rock_Volcanic_Cobble",
      "rotation": 2
    },
    {
      "x": -19,
      "y": 12,
      "z": -18,
      "name": "Rock_Volcanic_Brick",
      "rotation": 2
    },
    {
      "x": -19,
      "y": 13,
      "z": -18,
      "name": "Rock_Volcanic_Brick",
      "rotation": 2
    },
    {
      "x": -19,
      "y": 14,
      "z": -18,
      "name": "Rock_Volcanic_Cobble",
      "rotation": 2
    },
    {
      "x": -19,
      "y": 15,
      "z": -18,
      "name": "Rock_Volcanic_Cobble",
      "rotation": 2
    },
    {
      "x": -19,
      "y": 16,
      "z": -18,
      "name": "Rock_Volcanic_Cobble",
      "rotation": 2
    },
    {
      "x": -19,
      "y": 17,
      "z": -18,
      "name": "Rock_Volcanic_Brick",
      "rotation": 2
    },
    {
      "x": -19,
      "y": 18,
      "z": -18,
      "name": "Rock_Volcanic_Cobble",
      "rotation": 2
    },
    {
      "x": -19,
      "y": 19,
      "z": -18,
      "name": "Rock_Volcanic_Brick",
      "rotation": 2
    },
    {
      "x": -19,
      "y": 20,
      "z": -18,
      "name": "Rock_Volcanic_Brick",
      "rotation": 2
    },
    {
      "x": -19,
      "y": 21,
      "z": -18,
      "name": "Rock_Volcanic_Brick",
      "rotation": 2
    },
    {
      "x": -19,
      "y": 22,
      "z": -18,
      "name": "Rock_Volcanic_Brick",
      "rotation": 2
    },
    {
      "x": -19,
      "y": 23,
      "z": -18,
      "name": "Rock_Volcanic_Brick",
      "rotation": 2
    },
    {
      "x": -19,
      "y": 24,
      "z": -18,
      "name": "Rock_Volcanic_Brick",
      "rotation": 2
    },
    {
      "x": -19,
      "y": 20,
      "z": -17,
      "name": "Rock_Volcanic_Cobble",
      "rotation": 2
    },
    {
      "x": -19,
      "y": 24,
      "z": -17,
      "name": "Rock_Volcanic_Cobble",
      "rotation": 2
    },
    {
      "x": -19,
      "y": 20,
      "z": -16,
      "name": "Rock_Volcanic_Cobble",
      "rotation": 2
    },
    {
      "x": -19,
      "y": 24,
      "z": -16,
      "name": "Rock_Volcanic_Cobble",
      "rotation": 2
    },
    {
      "x": -19,
      "y": 20,
      "z": -15,
      "name": "Rock_Volcanic_Cobble",
      "rotation": 2
    },
    {
      "x": -19,
      "y": 24,
      "z": -15,
      "name": "Rock_Volcanic_Cobble",
      "rotation": 2
    },
    {
      "x": -19,
      "y": 0,
      "z": -14,
      "name": "Rock_Volcanic_Cobble",
      "rotation": 2
    },
    {
      "x": -19,
      "y": 1,
      "z": -14,
      "name": "Rock_Volcanic_Brick",
      "rotation": 2
    },
    {
      "x": -19,
      "y": 2,
      "z": -14,
      "name": "Rock_Volcanic_Cobble",
      "rotation": 2
    },
    {
      "x": -19,
      "y": 3,
      "z": -14,
      "name": "Rock_Volcanic_Brick",
      "rotation": 2
    },
    {
      "x": -19,
      "y": 4,
      "z": -14,
      "name": "Rock_Volcanic_Brick",
      "rotation": 2
    },
    {
      "x": -19,
      "y": 5,
      "z": -14,
      "name": "Rock_Volcanic_Brick",
      "rotation": 2
    },
    {
      "x": -19,
      "y": 6,
      "z": -14,
      "name": "Rock_Volcanic_Cobble",
      "rotation": 2
    },
    {
      "x": -19,
      "y": 7,
      "z": -14,
      "name": "Rock_Volcanic_Brick",
      "rotation": 2
    },
    {
      "x": -19,
      "y": 8,
      "z": -14,
      "name": "Rock_Volcanic_Cobble",
      "rotation": 2
    },
    {
      "x": -19,
      "y": 9,
      "z": -14,
      "name": "Rock_Volcanic_Brick",
      "rotation": 2
    },
    {
      "x": -19,
      "y": 10,
      "z": -14,
      "name": "Rock_Volcanic_Cobble",
      "rotation": 2
    },
    {
      "x": -19,
      "y": 11,
      "z": -14,
      "name": "Rock_Volcanic_Cobble",
      "rotation": 2
    },
    {
      "x": -19,
      "y": 12,
      "z": -14,
      "name": "Rock_Volcanic_Cobble",
      "rotation": 2
    },
    {
      "x": -19,
      "y": 13,
      "z": -14,
      "name": "Rock_Volcanic_Brick",
      "rotation": 2
    },
    {
      "x": -19,
      "y": 14,
      "z": -14,
      "name": "Rock_Volcanic_Cobble",
      "rotation": 2
    },
    {
      "x": -19,
      "y": 15,
      "z": -14,
      "name": "Rock_Volcanic_Brick",
      "rotation": 2
    },
    {
      "x": -19,
      "y": 16,
      "z": -14,
      "name": "Rock_Volcanic_Brick",
      "rotation": 2
    },
    {
      "x": -19,
      "y": 17,
      "z": -14,
      "name": "Rock_Volcanic_Cobble",
      "rotation": 2
    },
    {
      "x": -19,
      "y": 18,
      "z": -14,
      "name": "Rock_Volcanic_Brick",
      "rotation": 2
    },
    {
      "x": -19,
      "y": 19,
      "z": -14,
      "name": "Rock_Volcanic_Cobble",
      "rotation": 2
    },
    {
      "x": -19,
      "y": 20,
      "z": -14,
      "name": "Rock_Volcanic_Brick",
      "rotation": 2
    },
    {
      "x": -19,
      "y": 21,
      "z": -14,
      "name": "Rock_Volcanic_Brick",
      "rotation": 2
    },
    {
      "x": -19,
      "y": 22,
      "z": -14,
      "name": "Rock_Volcanic_Cobble",
      "rotation": 2
    },
    {
      "x": -19,
      "y": 23,
      "z": -14,
      "name": "Rock_Volcanic_Brick",
      "rotation": 2
    },
    {
      "x": -19,
      "y": 24,
      "z": -14,
      "name": "Rock_Volcanic_Brick",
      "rotation": 2
    },
    {
      "x": -19,
      "y": 0,
      "z": -13,
      "name": "Rock_Volcanic_Brick",
      "rotation": 2
    },
    {
      "x": -19,
      "y": 1,
      "z": -13,
      "name": "Rock_Volcanic_Brick",
      "rotation": 2
    },
    {
      "x": -19,
      "y": 2,
      "z": -13,
      "name": "Rock_Volcanic_Brick",
      "rotation": 2
    },
    {
      "x": -19,
      "y": 3,
      "z": -13,
      "name": "Rock_Volcanic_Cobble",
      "rotation": 2
    },
    {
      "x": -19,
      "y": 4,
      "z": -13,
      "name": "Rock_Volcanic_Cobble",
      "rotation": 2
    },
    {
      "x": -19,
      "y": 5,
      "z": -13,
      "name": "Rock_Volcanic_Brick",
      "rotation": 2
    },
    {
      "x": -19,
      "y": 6,
      "z": -13,
      "name": "Rock_Volcanic_Cobble",
      "rotation": 2
    },
    {
      "x": -19,
      "y": 7,
      "z": -13,
      "name": "Rock_Volcanic_Brick",
      "rotation": 2
    },
    {
      "x": -19,
      "y": 8,
      "z": -13,
      "name": "Rock_Volcanic_Brick",
      "rotation": 2
    },
    {
      "x": -19,
      "y": 9,
      "z": -13,
      "name": "Rock_Volcanic_Brick",
      "rotation": 2
    },
    {
      "x": -19,
      "y": 10,
      "z": -13,
      "name": "Rock_Volcanic_Cobble",
      "rotation": 2
    },
    {
      "x": -19,
      "y": 11,
      "z": -13,
      "name": "Rock_Volcanic_Brick",
      "rotation": 2
    },
    {
      "x": -19,
      "y": 12,
      "z": -13,
      "name": "Rock_Volcanic_Brick",
      "rotation": 2
    },
    {
      "x": -19,
      "y": 13,
      "z": -13,
      "name": "Rock_Volcanic_Cobble",
      "rotation": 2
    },
    {
      "x": -19,
      "y": 14,
      "z": -13,
      "name": "Rock_Volcanic_Brick",
      "rotation": 2
    },
    {
      "x": -19,
      "y": 15,
      "z": -13,
      "name": "Rock_Volcanic_Cobble",
      "rotation": 2
    },
    {
      "x": -19,
      "y": 16,
      "z": -13,
      "name": "Rock_Volcanic_Brick",
      "rotation": 2
    },
    {
      "x": -19,
      "y": 17,
      "z": -13,
      "name": "Rock_Volcanic_Cobble",
      "rotation": 2
    },
    {
      "x": -19,
      "y": 18,
      "z": -13,
      "name": "Rock_Volcanic_Brick",
      "rotation": 2
    },
    {
      "x": -19,
      "y": 19,
      "z": -13,
      "name": "Rock_Volcanic_Cobble",
      "rotation": 2
    },
    {
      "x": -19,
      "y": 20,
      "z": -13,
      "name": "Rock_Volcanic_Cobble",
      "rotation": 2
    },
    {
      "x": -19,
      "y": 21,
      "z": -13,
      "name": "Rock_Volcanic_Brick",
      "rotation": 2
    },
    {
      "x": -19,
      "y": 22,
      "z": -13,
      "name": "Rock_Volcanic_Cobble",
      "rotation": 2
    },
    {
      "x": -19,
      "y": 23,
      "z": -13,
      "name": "Rock_Volcanic_Brick",
      "rotation": 2
    },
    {
      "x": -19,
      "y": 24,
      "z": -13,
      "name": "Rock_Volcanic_Brick",
      "rotation": 2
    },
    {
      "x": -19,
      "y": 19,
      "z": -12,
      "name": "Rock_Volcanic_Brick",
      "rotation": 2
    },
    {
      "x": -19,
      "y": 24,
      "z": -12,
      "name": "*Rock_Volcanic_Brick_Stairs_State_Definitions_Inverted_Corner_Left",
      "rotation": 10
    },
    {
      "x": -19,
      "y": 24,
      "z": -11,
      "name": "*Rock_Volcanic_Brick_Stairs_State_Definitions_Corner_Right",
      "rotation": 9
    },
    {
      "x": -19,
      "y": 25,
      "z": -11,
      "name": "Rock_Volcanic_Brick",
      "rotation": 2
    },
    {
      "x": -19,
      "y": 26,
      "z": -11,
      "name": "Rock_Volcanic_Brick_Stairs"
    },
    {
      "x": -19,
      "y": 24,
      "z": 12,
      "name": "*Rock_Volcanic_Brick_Stairs_State_Definitions_Corner_Right",
      "rotation": 8
    },
    {
      "x": -19,
      "y": 25,
      "z": 12,
      "name": "Rock_Volcanic_Brick",
      "rotation": 3
    },
    {
      "x": -19,
      "y": 26,
      "z": 12,
      "name": "Rock_Volcanic_Brick_Stairs",
      "rotation": 2
    },
    {
      "x": -19,
      "y": 19,
      "z": 13,
      "name": "Rock_Volcanic_Brick",
      "rotation": 3
    },
    {
      "x": -19,
      "y": 24,
      "z": 13,
      "name": "*Rock_Volcanic_Brick_Stairs_State_Definitions_Inverted_Corner_Left",
      "rotation": 9
    },
    {
      "x": -19,
      "y": 0,
      "z": 14,
      "name": "Rock_Volcanic_Cobble",
      "rotation": 3
    },
    {
      "x": -19,
      "y": 1,
      "z": 14,
      "name": "Rock_Volcanic_Brick",
      "rotation": 3
    },
    {
      "x": -19,
      "y": 2,
      "z": 14,
      "name": "Rock_Volcanic_Cobble",
      "rotation": 3
    },
    {
      "x": -19,
      "y": 3,
      "z": 14,
      "name": "Rock_Volcanic_Cobble",
      "rotation": 3
    },
    {
      "x": -19,
      "y": 4,
      "z": 14,
      "name": "Rock_Volcanic_Cobble",
      "rotation": 3
    },
    {
      "x": -19,
      "y": 5,
      "z": 14,
      "name": "Rock_Volcanic_Brick",
      "rotation": 3
    },
    {
      "x": -19,
      "y": 6,
      "z": 14,
      "name": "Rock_Volcanic_Brick",
      "rotation": 3
    },
    {
      "x": -19,
      "y": 7,
      "z": 14,
      "name": "Rock_Volcanic_Brick",
      "rotation": 3
    },
    {
      "x": -19,
      "y": 8,
      "z": 14,
      "name": "Rock_Volcanic_Brick",
      "rotation": 3
    },
    {
      "x": -19,
      "y": 9,
      "z": 14,
      "name": "Rock_Volcanic_Cobble",
      "rotation": 3
    },
    {
      "x": -19,
      "y": 10,
      "z": 14,
      "name": "Rock_Volcanic_Cobble",
      "rotation": 3
    },
    {
      "x": -19,
      "y": 11,
      "z": 14,
      "name": "Rock_Volcanic_Brick",
      "rotation": 3
    },
    {
      "x": -19,
      "y": 12,
      "z": 14,
      "name": "Rock_Volcanic_Cobble",
      "rotation": 3
    },
    {
      "x": -19,
      "y": 13,
      "z": 14,
      "name": "Rock_Volcanic_Brick",
      "rotation": 3
    },
    {
      "x": -19,
      "y": 14,
      "z": 14,
      "name": "Rock_Volcanic_Cobble",
      "rotation": 3
    },
    {
      "x": -19,
      "y": 15,
      "z": 14,
      "name": "Rock_Volcanic_Cobble",
      "rotation": 3
    },
    {
      "x": -19,
      "y": 16,
      "z": 14,
      "name": "Rock_Volcanic_Cobble",
      "rotation": 3
    },
    {
      "x": -19,
      "y": 17,
      "z": 14,
      "name": "Rock_Volcanic_Brick",
      "rotation": 3
    },
    {
      "x": -19,
      "y": 18,
      "z": 14,
      "name": "Rock_Volcanic_Cobble",
      "rotation": 3
    },
    {
      "x": -19,
      "y": 19,
      "z": 14,
      "name": "Rock_Volcanic_Brick",
      "rotation": 3
    },
    {
      "x": -19,
      "y": 20,
      "z": 14,
      "name": "Rock_Volcanic_Brick",
      "rotation": 3
    },
    {
      "x": -19,
      "y": 21,
      "z": 14,
      "name": "Rock_Volcanic_Cobble",
      "rotation": 3
    },
    {
      "x": -19,
      "y": 22,
      "z": 14,
      "name": "Rock_Volcanic_Brick",
      "rotation": 3
    },
    {
      "x": -19,
      "y": 23,
      "z": 14,
      "name": "Rock_Volcanic_Cobble",
      "rotation": 3
    },
    {
      "x": -19,
      "y": 24,
      "z": 14,
      "name": "Rock_Volcanic_Brick",
      "rotation": 3
    },
    {
      "x": -19,
      "y": 0,
      "z": 15,
      "name": "Rock_Volcanic_Brick",
      "rotation": 3
    },
    {
      "x": -19,
      "y": 1,
      "z": 15,
      "name": "Rock_Volcanic_Brick",
      "rotation": 3
    },
    {
      "x": -19,
      "y": 2,
      "z": 15,
      "name": "Rock_Volcanic_Cobble",
      "rotation": 3
    },
    {
      "x": -19,
      "y": 3,
      "z": 15,
      "name": "Rock_Volcanic_Brick",
      "rotation": 3
    },
    {
      "x": -19,
      "y": 4,
      "z": 15,
      "name": "Rock_Volcanic_Cobble",
      "rotation": 3
    },
    {
      "x": -19,
      "y": 5,
      "z": 15,
      "name": "Rock_Volcanic_Brick",
      "rotation": 3
    },
    {
      "x": -19,
      "y": 6,
      "z": 15,
      "name": "Rock_Volcanic_Brick",
      "rotation": 3
    },
    {
      "x": -19,
      "y": 7,
      "z": 15,
      "name": "Rock_Volcanic_Cobble",
      "rotation": 3
    },
    {
      "x": -19,
      "y": 8,
      "z": 15,
      "name": "Rock_Volcanic_Brick",
      "rotation": 3
    },
    {
      "x": -19,
      "y": 9,
      "z": 15,
      "name": "Rock_Volcanic_Cobble",
      "rotation": 3
    },
    {
      "x": -19,
      "y": 10,
      "z": 15,
      "name": "Rock_Volcanic_Brick",
      "rotation": 3
    },
    {
      "x": -19,
      "y": 11,
      "z": 15,
      "name": "Rock_Volcanic_Brick",
      "rotation": 3
    },
    {
      "x": -19,
      "y": 12,
      "z": 15,
      "name": "Rock_Volcanic_Cobble",
      "rotation": 3
    },
    {
      "x": -19,
      "y": 13,
      "z": 15,
      "name": "Rock_Volcanic_Brick",
      "rotation": 3
    },
    {
      "x": -19,
      "y": 14,
      "z": 15,
      "name": "Rock_Volcanic_Brick",
      "rotation": 3
    },
    {
      "x": -19,
      "y": 15,
      "z": 15,
      "name": "Rock_Volcanic_Brick",
      "rotation": 3
    },
    {
      "x": -19,
      "y": 16,
      "z": 15,
      "name": "Rock_Volcanic_Cobble",
      "rotation": 3
    },
    {
      "x": -19,
      "y": 17,
      "z": 15,
      "name": "Rock_Volcanic_Brick",
      "rotation": 3
    },
    {
      "x": -19,
      "y": 18,
      "z": 15,
      "name": "Rock_Volcanic_Brick",
      "rotation": 3
    },
    {
      "x": -19,
      "y": 19,
      "z": 15,
      "name": "Rock_Volcanic_Brick",
      "rotation": 3
    },
    {
      "x": -19,
      "y": 20,
      "z": 15,
      "name": "Rock_Volcanic_Cobble",
      "rotation": 3
    },
    {
      "x": -19,
      "y": 21,
      "z": 15,
      "name": "Rock_Volcanic_Brick",
      "rotation": 3
    },
    {
      "x": -19,
      "y": 22,
      "z": 15,
      "name": "Rock_Volcanic_Cobble",
      "rotation": 3
    },
    {
      "x": -19,
      "y": 23,
      "z": 15,
      "name": "Rock_Volcanic_Cobble",
      "rotation": 3
    },
    {
      "x": -19,
      "y": 24,
      "z": 15,
      "name": "Rock_Volcanic_Brick",
      "rotation": 3
    },
    {
      "x": -19,
      "y": 20,
      "z": 16,
      "name": "Rock_Volcanic_Cobble",
      "rotation": 3
    },
    {
      "x": -19,
      "y": 24,
      "z": 16,
      "name": "Rock_Volcanic_Cobble",
      "rotation": 3
    },
    {
      "x": -19,
      "y": 20,
      "z": 17,
      "name": "Rock_Volcanic_Cobble",
      "rotation": 3
    },
    {
      "x": -19,
      "y": 24,
      "z": 17,
      "name": "Rock_Volcanic_Cobble",
      "rotation": 3
    },
    {
      "x": -19,
      "y": 20,
      "z": 18,
      "name": "Rock_Volcanic_Cobble",
      "rotation": 3
    },
    {
      "x": -19,
      "y": 24,
      "z": 18,
      "name": "Rock_Volcanic_Cobble",
      "rotation": 3
    },
    {
      "x": -19,
      "y": 0,
      "z": 19,
      "name": "Rock_Volcanic_Cobble",
      "rotation": 3
    },
    {
      "x": -19,
      "y": 1,
      "z": 19,
      "name": "Rock_Volcanic_Cobble",
      "rotation": 3
    },
    {
      "x": -19,
      "y": 2,
      "z": 19,
      "name": "Rock_Volcanic_Brick",
      "rotation": 3
    },
    {
      "x": -19,
      "y": 3,
      "z": 19,
      "name": "Rock_Volcanic_Cobble",
      "rotation": 3
    },
    {
      "x": -19,
      "y": 4,
      "z": 19,
      "name": "Rock_Volcanic_Brick",
      "rotation": 3
    },
    {
      "x": -19,
      "y": 5,
      "z": 19,
      "name": "Rock_Volcanic_Cobble",
      "rotation": 3
    },
    {
      "x": -19,
      "y": 6,
      "z": 19,
      "name": "Rock_Volcanic_Cobble",
      "rotation": 3
    },
    {
      "x": -19,
      "y": 7,
      "z": 19,
      "name": "Rock_Volcanic_Cobble",
      "rotation": 3
    },
    {
      "x": -19,
      "y": 8,
      "z": 19,
      "name": "Rock_Volcanic_Cobble",
      "rotation": 3
    },
    {
      "x": -19,
      "y": 9,
      "z": 19,
      "name": "Rock_Volcanic_Brick",
      "rotation": 3
    },
    {
      "x": -19,
      "y": 10,
      "z": 19,
      "name": "Rock_Volcanic_Cobble",
      "rotation": 3
    },
    {
      "x": -19,
      "y": 11,
      "z": 19,
      "name": "Rock_Volcanic_Cobble",
      "rotation": 3
    },
    {
      "x": -19,
      "y": 12,
      "z": 19,
      "name": "Rock_Volcanic_Cobble",
      "rotation": 3
    },
    {
      "x": -19,
      "y": 13,
      "z": 19,
      "name": "Rock_Volcanic_Brick",
      "rotation": 3
    },
    {
      "x": -19,
      "y": 14,
      "z": 19,
      "name": "Rock_Volcanic_Brick",
      "rotation": 3
    },
    {
      "x": -19,
      "y": 15,
      "z": 19,
      "name": "Rock_Volcanic_Brick",
      "rotation": 3
    },
    {
      "x": -19,
      "y": 16,
      "z": 19,
      "name": "Rock_Volcanic_Cobble",
      "rotation": 3
    },
    {
      "x": -19,
      "y": 17,
      "z": 19,
      "name": "Rock_Volcanic_Cobble",
      "rotation": 3
    },
    {
      "x": -19,
      "y": 18,
      "z": 19,
      "name": "Rock_Volcanic_Brick",
      "rotation": 3
    },
    {
      "x": -19,
      "y": 19,
      "z": 19,
      "name": "Rock_Volcanic_Cobble",
      "rotation": 3
    },
    {
      "x": -19,
      "y": 20,
      "z": 19,
      "name": "Rock_Volcanic_Brick",
      "rotation": 3
    },
    {
      "x": -19,
      "y": 21,
      "z": 19,
      "name": "Rock_Volcanic_Brick",
      "rotation": 3
    },
    {
      "x": -19,
      "y": 22,
      "z": 19,
      "name": "Rock_Volcanic_Brick",
      "rotation": 3
    },
    {
      "x": -19,
      "y": 23,
      "z": 19,
      "name": "Rock_Volcanic_Cobble",
      "rotation": 3
    },
    {
      "x": -19,
      "y": 24,
      "z": 19,
      "name": "Rock_Volcanic_Brick",
      "rotation": 3
    },
    {
      "x": -19,
      "y": 0,
      "z": 20,
      "name": "Rock_Volcanic_Brick",
      "rotation": 3
    },
    {
      "x": -19,
      "y": 1,
      "z": 20,
      "name": "Rock_Volcanic_Brick",
      "rotation": 3
    },
    {
      "x": -19,
      "y": 2,
      "z": 20,
      "name": "Rock_Volcanic_Brick",
      "rotation": 3
    },
    {
      "x": -19,
      "y": 3,
      "z": 20,
      "name": "Rock_Volcanic_Brick",
      "rotation": 3
    },
    {
      "x": -19,
      "y": 4,
      "z": 20,
      "name": "Rock_Volcanic_Cobble",
      "rotation": 3
    },
    {
      "x": -19,
      "y": 5,
      "z": 20,
      "name": "Rock_Volcanic_Cobble",
      "rotation": 3
    },
    {
      "x": -19,
      "y": 6,
      "z": 20,
      "name": "Rock_Volcanic_Brick",
      "rotation": 3
    },
    {
      "x": -19,
      "y": 7,
      "z": 20,
      "name": "Rock_Volcanic_Brick",
      "rotation": 3
    },
    {
      "x": -19,
      "y": 8,
      "z": 20,
      "name": "Rock_Volcanic_Brick",
      "rotation": 3
    },
    {
      "x": -19,
      "y": 9,
      "z": 20,
      "name": "Rock_Volcanic_Brick",
      "rotation": 3
    },
    {
      "x": -19,
      "y": 10,
      "z": 20,
      "name": "Rock_Volcanic_Brick",
      "rotation": 3
    },
    {
      "x": -19,
      "y": 11,
      "z": 20,
      "name": "Rock_Volcanic_Brick",
      "rotation": 3
    },
    {
      "x": -19,
      "y": 12,
      "z": 20,
      "name": "Rock_Volcanic_Cobble",
      "rotation": 3
    },
    {
      "x": -19,
      "y": 13,
      "z": 20,
      "name": "Rock_Volcanic_Cobble",
      "rotation": 3
    },
    {
      "x": -19,
      "y": 14,
      "z": 20,
      "name": "Rock_Volcanic_Cobble",
      "rotation": 3
    },
    {
      "x": -19,
      "y": 15,
      "z": 20,
      "name": "Rock_Volcanic_Cobble",
      "rotation": 3
    },
    {
      "x": -19,
      "y": 16,
      "z": 20,
      "name": "Rock_Volcanic_Brick",
      "rotation": 3
    },
    {
      "x": -19,
      "y": 17,
      "z": 20,
      "name": "Rock_Volcanic_Cobble",
      "rotation": 3
    },
    {
      "x": -19,
      "y": 18,
      "z": 20,
      "name": "Rock_Volcanic_Brick",
      "rotation": 3
    },
    {
      "x": -19,
      "y": 19,
      "z": 20,
      "name": "Rock_Volcanic_Cobble",
      "rotation": 3
    },
    {
      "x": -19,
      "y": 20,
      "z": 20,
      "name": "Rock_Volcanic_Brick",
      "rotation": 3
    },
    {
      "x": -19,
      "y": 21,
      "z": 20,
      "name": "Rock_Volcanic_Cobble",
      "rotation": 3
    },
    {
      "x": -19,
      "y": 22,
      "z": 20,
      "name": "Rock_Volcanic_Cobble",
      "rotation": 3
    },
    {
      "x": -19,
      "y": 23,
      "z": 20,
      "name": "Rock_Volcanic_Cobble",
      "rotation": 3
    },
    {
      "x": -19,
      "y": 24,
      "z": 20,
      "name": "Rock_Volcanic_Brick",
      "rotation": 3
    },
    {
      "x": -19,
      "y": 19,
      "z": 21,
      "name": "Rock_Volcanic_Brick",
      "rotation": 3
    },
    {
      "x": -19,
      "y": 24,
      "z": 21,
      "name": "*Rock_Volcanic_Brick_Stairs_State_Definitions_Inverted_Corner_Left",
      "rotation": 10
    },
    {
      "x": -19,
      "y": 24,
      "z": 22,
      "name": "*Rock_Volcanic_Brick_Stairs_State_Definitions_Corner_Right",
      "rotation": 9
    },
    {
      "x": -19,
      "y": 25,
      "z": 22,
      "name": "Rock_Volcanic_Brick",
      "rotation": 3
    },
    {
      "x": -19,
      "y": 26,
      "z": 22,
      "name": "Rock_Volcanic_Brick_Stairs"
    },
    {
      "x": -18,
      "y": 24,
      "z": -22,
      "name": "*Rock_Volcanic_Brick_Stairs_State_Definitions_Corner_Right",
      "rotation": 8
    },
    {
      "x": -18,
      "y": 19,
      "z": -21,
      "name": "Rock_Volcanic_Brick",
      "rotation": 2
    },
    {
      "x": -18,
      "y": 24,
      "z": -21,
      "name": "*Rock_Volcanic_Brick_Stairs_State_Definitions_Inverted_Corner_Left",
      "rotation": 9
    },
    {
      "x": -18,
      "y": 25,
      "z": -21,
      "name": "Rock_Volcanic_Brick_Wall"
    },
    {
      "x": -18,
      "y": 0,
      "z": -20,
      "name": "Rock_Volcanic_Brick",
      "rotation": 2
    },
    {
      "x": -18,
      "y": 1,
      "z": -20,
      "name": "Rock_Volcanic_Brick",
      "rotation": 2
    },
    {
      "x": -18,
      "y": 2,
      "z": -20,
      "name": "Rock_Volcanic_Brick",
      "rotation": 2
    },
    {
      "x": -18,
      "y": 3,
      "z": -20,
      "name": "Rock_Volcanic_Brick",
      "rotation": 2
    },
    {
      "x": -18,
      "y": 4,
      "z": -20,
      "name": "Rock_Volcanic_Cobble",
      "rotation": 2
    },
    {
      "x": -18,
      "y": 5,
      "z": -20,
      "name": "Rock_Volcanic_Cobble",
      "rotation": 2
    },
    {
      "x": -18,
      "y": 6,
      "z": -20,
      "name": "Rock_Volcanic_Brick",
      "rotation": 2
    },
    {
      "x": -18,
      "y": 7,
      "z": -20,
      "name": "Rock_Volcanic_Brick",
      "rotation": 2
    },
    {
      "x": -18,
      "y": 8,
      "z": -20,
      "name": "Rock_Volcanic_Brick",
      "rotation": 2
    },
    {
      "x": -18,
      "y": 9,
      "z": -20,
      "name": "Rock_Volcanic_Brick",
      "rotation": 2
    },
    {
      "x": -18,
      "y": 10,
      "z": -20,
      "name": "Rock_Volcanic_Brick",
      "rotation": 2
    },
    {
      "x": -18,
      "y": 11,
      "z": -20,
      "name": "Rock_Volcanic_Brick",
      "rotation": 2
    },
    {
      "x": -18,
      "y": 12,
      "z": -20,
      "name": "Rock_Volcanic_Cobble",
      "rotation": 2
    },
    {
      "x": -18,
      "y": 13,
      "z": -20,
      "name": "Rock_Volcanic_Cobble",
      "rotation": 2
    },
    {
      "x": -18,
      "y": 14,
      "z": -20,
      "name": "Rock_Volcanic_Cobble",
      "rotation": 2
    },
    {
      "x": -18,
      "y": 15,
      "z": -20,
      "name": "Rock_Volcanic_Cobble",
      "rotation": 2
    },
    {
      "x": -18,
      "y": 16,
      "z": -20,
      "name": "Rock_Volcanic_Brick",
      "rotation": 2
    },
    {
      "x": -18,
      "y": 17,
      "z": -20,
      "name": "Rock_Volcanic_Cobble",
      "rotation": 2
    },
    {
      "x": -18,
      "y": 18,
      "z": -20,
      "name": "Rock_Volcanic_Brick",
      "rotation": 2
    },
    {
      "x": -18,
      "y": 19,
      "z": -20,
      "name": "Rock_Volcanic_Cobble",
      "rotation": 2
    },
    {
      "x": -18,
      "y": 20,
      "z": -20,
      "name": "Rock_Volcanic_Brick",
      "rotation": 2
    },
    {
      "x": -18,
      "y": 21,
      "z": -20,
      "name": "Rock_Volcanic_Cobble",
      "rotation": 2
    },
    {
      "x": -18,
      "y": 22,
      "z": -20,
      "name": "Rock_Volcanic_Cobble",
      "rotation": 2
    },
    {
      "x": -18,
      "y": 23,
      "z": -20,
      "name": "Rock_Volcanic_Cobble",
      "rotation": 2
    },
    {
      "x": -18,
      "y": 24,
      "z": -20,
      "name": "Rock_Volcanic_Brick",
      "rotation": 2
    },
    {
      "x": -18,
      "y": 20,
      "z": -19,
      "name": "Rock_Volcanic_Cobble",
      "rotation": 2
    },
    {
      "x": -18,
      "y": 24,
      "z": -19,
      "name": "Rock_Volcanic_Cobble",
      "rotation": 2
    },
    {
      "x": -18,
      "y": 20,
      "z": -18,
      "name": "Rock_Volcanic_Cobble",
      "rotation": 2
    },
    {
      "x": -18,
      "y": 24,
      "z": -18,
      "name": "Rock_Volcanic_Cobble",
      "rotation": 2
    },
    {
      "x": -18,
      "y": 20,
      "z": -17,
      "name": "Rock_Volcanic_Cobble",
      "rotation": 2
    },
    {
      "x": -18,
      "y": 24,
      "z": -17,
      "name": "Rock_Volcanic_Cobble",
      "rotation": 2
    },
    {
      "x": -18,
      "y": 20,
      "z": -16,
      "name": "Rock_Volcanic_Cobble",
      "rotation": 2
    },
    {
      "x": -18,
      "y": 24,
      "z": -16,
      "name": "Rock_Volcanic_Cobble",
      "rotation": 2
    },
    {
      "x": -18,
      "y": 20,
      "z": -15,
      "name": "Rock_Volcanic_Cobble",
      "rotation": 2
    },
    {
      "x": -18,
      "y": 24,
      "z": -15,
      "name": "Rock_Volcanic_Cobble",
      "rotation": 2
    },
    {
      "x": -18,
      "y": 20,
      "z": -14,
      "name": "Rock_Volcanic_Cobble",
      "rotation": 2
    },
    {
      "x": -18,
      "y": 24,
      "z": -14,
      "name": "Rock_Volcanic_Cobble",
      "rotation": 2
    },
    {
      "x": -18,
      "y": 20,
      "z": -13,
      "name": "Rock_Volcanic_Cobble",
      "rotation": 2
    },
    {
      "x": -18,
      "y": 24,
      "z": -13,
      "name": "Rock_Volcanic_Cobble",
      "rotation": 2
    },
    {
      "x": -18,
      "y": 0,
      "z": -12,
      "name": "Rock_Volcanic_Brick",
      "rotation": 2
    },
    {
      "x": -18,
      "y": 1,
      "z": -12,
      "name": "Rock_Volcanic_Brick",
      "rotation": 2
    },
    {
      "x": -18,
      "y": 2,
      "z": -12,
      "name": "Rock_Volcanic_Cobble",
      "rotation": 2
    },
    {
      "x": -18,
      "y": 3,
      "z": -12,
      "name": "Rock_Volcanic_Brick",
      "rotation": 2
    },
    {
      "x": -18,
      "y": 4,
      "z": -12,
      "name": "Rock_Volcanic_Brick",
      "rotation": 2
    },
    {
      "x": -18,
      "y": 5,
      "z": -12,
      "name": "Rock_Volcanic_Brick",
      "rotation": 2
    },
    {
      "x": -18,
      "y": 6,
      "z": -12,
      "name": "Rock_Volcanic_Cobble",
      "rotation": 2
    },
    {
      "x": -18,
      "y": 7,
      "z": -12,
      "name": "Rock_Volcanic_Cobble",
      "rotation": 2
    },
    {
      "x": -18,
      "y": 8,
      "z": -12,
      "name": "Rock_Volcanic_Cobble",
      "rotation": 2
    },
    {
      "x": -18,
      "y": 9,
      "z": -12,
      "name": "Rock_Volcanic_Brick",
      "rotation": 2
    },
    {
      "x": -18,
      "y": 10,
      "z": -12,
      "name": "Rock_Volcanic_Brick",
      "rotation": 2
    },
    {
      "x": -18,
      "y": 11,
      "z": -12,
      "name": "Rock_Volcanic_Cobble",
      "rotation": 2
    },
    {
      "x": -18,
      "y": 12,
      "z": -12,
      "name": "Rock_Volcanic_Brick",
      "rotation": 2
    },
    {
      "x": -18,
      "y": 13,
      "z": -12,
      "name": "Rock_Volcanic_Cobble",
      "rotation": 2
    },
    {
      "x": -18,
      "y": 14,
      "z": -12,
      "name": "Rock_Volcanic_Brick",
      "rotation": 2
    },
    {
      "x": -18,
      "y": 15,
      "z": -12,
      "name": "Rock_Volcanic_Cobble",
      "rotation": 2
    },
    {
      "x": -18,
      "y": 16,
      "z": -12,
      "name": "Rock_Volcanic_Brick",
      "rotation": 2
    },
    {
      "x": -18,
      "y": 17,
      "z": -12,
      "name": "Rock_Volcanic_Cobble",
      "rotation": 2
    },
    {
      "x": -18,
      "y": 18,
      "z": -12,
      "name": "Rock_Volcanic_Cobble",
      "rotation": 2
    },
    {
      "x": -18,
      "y": 19,
      "z": -12,
      "name": "Rock_Volcanic_Brick",
      "rotation": 2
    },
    {
      "x": -18,
      "y": 20,
      "z": -12,
      "name": "Rock_Volcanic_Brick",
      "rotation": 2
    },
    {
      "x": -18,
      "y": 21,
      "z": -12,
      "name": "Rock_Volcanic_Cobble",
      "rotation": 2
    },
    {
      "x": -18,
      "y": 22,
      "z": -12,
      "name": "Rock_Volcanic_Cobble",
      "rotation": 2
    },
    {
      "x": -18,
      "y": 23,
      "z": -12,
      "name": "Rock_Volcanic_Cobble",
      "rotation": 2
    },
    {
      "x": -18,
      "y": 24,
      "z": -12,
      "name": "Rock_Volcanic_Brick",
      "rotation": 2
    },
    {
      "x": -18,
      "y": 19,
      "z": -11,
      "name": "Rock_Volcanic_Brick",
      "rotation": 2
    },
    {
      "x": -18,
      "y": 24,
      "z": -11,
      "name": "Rock_Volcanic_Brick_Stairs",
      "rotation": 10
    },
    {
      "x": -18,
      "y": 25,
      "z": -11,
      "name": "Rock_Volcanic_Brick_Wall",
      "rotation": 2
    },
    {
      "x": -18,
      "y": 24,
      "z": -10,
      "name": "Rock_Volcanic_Brick_Stairs",
      "rotation": 10
    },
    {
      "x": -18,
      "y": 24,
      "z": 11,
      "name": "Rock_Volcanic_Brick_Stairs",
      "rotation": 9
    },
    {
      "x": -18,
      "y": 19,
      "z": 12,
      "name": "Rock_Volcanic_Brick",
      "rotation": 3
    },
    {
      "x": -18,
      "y": 24,
      "z": 12,
      "name": "*Rock_Volcanic_Brick_Stairs_State_Definitions_Inverted_Corner_Left",
      "rotation": 9
    },
    {
      "x": -18,
      "y": 25,
      "z": 12,
      "name": "Rock_Volcanic_Brick_Wall"
    },
    {
      "x": -18,
      "y": 0,
      "z": 13,
      "name": "Rock_Volcanic_Brick",
      "rotation": 3
    },
    {
      "x": -18,
      "y": 1,
      "z": 13,
      "name": "Rock_Volcanic_Cobble",
      "rotation": 3
    },
    {
      "x": -18,
      "y": 2,
      "z": 13,
      "name": "Rock_Volcanic_Cobble",
      "rotation": 3
    },
    {
      "x": -18,
      "y": 3,
      "z": 13,
      "name": "Rock_Volcanic_Cobble",
      "rotation": 3
    },
    {
      "x": -18,
      "y": 4,
      "z": 13,
      "name": "Rock_Volcanic_Brick",
      "rotation": 3
    },
    {
      "x": -18,
      "y": 5,
      "z": 13,
      "name": "Rock_Volcanic_Brick",
      "rotation": 3
    },
    {
      "x": -18,
      "y": 6,
      "z": 13,
      "name": "Rock_Volcanic_Brick",
      "rotation": 3
    },
    {
      "x": -18,
      "y": 7,
      "z": 13,
      "name": "Rock_Volcanic_Brick",
      "rotation": 3
    },
    {
      "x": -18,
      "y": 8,
      "z": 13,
      "name": "Rock_Volcanic_Brick",
      "rotation": 3
    },
    {
      "x": -18,
      "y": 9,
      "z": 13,
      "name": "Rock_Volcanic_Cobble",
      "rotation": 3
    },
    {
      "x": -18,
      "y": 10,
      "z": 13,
      "name": "Rock_Volcanic_Cobble",
      "rotation": 3
    },
    {
      "x": -18,
      "y": 11,
      "z": 13,
      "name": "Rock_Volcanic_Cobble",
      "rotation": 3
    },
    {
      "x": -18,
      "y": 12,
      "z": 13,
      "name": "Rock_Volcanic_Cobble",
      "rotation": 3
    },
    {
      "x": -18,
      "y": 13,
      "z": 13,
      "name": "Rock_Volcanic_Cobble",
      "rotation": 3
    },
    {
      "x": -18,
      "y": 14,
      "z": 13,
      "name": "Rock_Volcanic_Brick",
      "rotation": 3
    },
    {
      "x": -18,
      "y": 15,
      "z": 13,
      "name": "Rock_Volcanic_Brick",
      "rotation": 3
    },
    {
      "x": -18,
      "y": 16,
      "z": 13,
      "name": "Rock_Volcanic_Cobble",
      "rotation": 3
    },
    {
      "x": -18,
      "y": 17,
      "z": 13,
      "name": "Rock_Volcanic_Cobble",
      "rotation": 3
    },
    {
      "x": -18,
      "y": 18,
      "z": 13,
      "name": "Rock_Volcanic_Brick",
      "rotation": 3
    },
    {
      "x": -18,
      "y": 19,
      "z": 13,
      "name": "Rock_Volcanic_Brick",
      "rotation": 3
    },
    {
      "x": -18,
      "y": 20,
      "z": 13,
      "name": "Rock_Volcanic_Brick",
      "rotation": 3
    },
    {
      "x": -18,
      "y": 21,
      "z": 13,
      "name": "Rock_Volcanic_Cobble",
      "rotation": 3
    },
    {
      "x": -18,
      "y": 22,
      "z": 13,
      "name": "Rock_Volcanic_Brick",
      "rotation": 3
    },
    {
      "x": -18,
      "y": 23,
      "z": 13,
      "name": "Rock_Volcanic_Cobble",
      "rotation": 3
    },
    {
      "x": -18,
      "y": 24,
      "z": 13,
      "name": "Rock_Volcanic_Brick",
      "rotation": 3
    },
    {
      "x": -18,
      "y": 20,
      "z": 14,
      "name": "Rock_Volcanic_Cobble",
      "rotation": 3
    },
    {
      "x": -18,
      "y": 24,
      "z": 14,
      "name": "Rock_Volcanic_Cobble",
      "rotation": 3
    },
    {
      "x": -18,
      "y": 20,
      "z": 15,
      "name": "Rock_Volcanic_Cobble",
      "rotation": 3
    },
    {
      "x": -18,
      "y": 24,
      "z": 15,
      "name": "Rock_Volcanic_Cobble",
      "rotation": 3
    },
    {
      "x": -18,
      "y": 20,
      "z": 16,
      "name": "Rock_Volcanic_Cobble",
      "rotation": 3
    },
    {
      "x": -18,
      "y": 24,
      "z": 16,
      "name": "Rock_Volcanic_Cobble",
      "rotation": 3
    },
    {
      "x": -18,
      "y": 20,
      "z": 17,
      "name": "Rock_Volcanic_Cobble",
      "rotation": 3
    },
    {
      "x": -18,
      "y": 24,
      "z": 17,
      "name": "Rock_Volcanic_Cobble",
      "rotation": 3
    },
    {
      "x": -18,
      "y": 20,
      "z": 18,
      "name": "Rock_Volcanic_Cobble",
      "rotation": 3
    },
    {
      "x": -18,
      "y": 24,
      "z": 18,
      "name": "Rock_Volcanic_Cobble",
      "rotation": 3
    },
    {
      "x": -18,
      "y": 20,
      "z": 19,
      "name": "Rock_Volcanic_Cobble",
      "rotation": 3
    },
    {
      "x": -18,
      "y": 24,
      "z": 19,
      "name": "Rock_Volcanic_Cobble",
      "rotation": 3
    },
    {
      "x": -18,
      "y": 20,
      "z": 20,
      "name": "Rock_Volcanic_Cobble",
      "rotation": 3
    },
    {
      "x": -18,
      "y": 24,
      "z": 20,
      "name": "Rock_Volcanic_Cobble",
      "rotation": 3
    },
    {
      "x": -18,
      "y": 0,
      "z": 21,
      "name": "Rock_Volcanic_Cobble",
      "rotation": 3
    },
    {
      "x": -18,
      "y": 1,
      "z": 21,
      "name": "Rock_Volcanic_Cobble",
      "rotation": 3
    },
    {
      "x": -18,
      "y": 2,
      "z": 21,
      "name": "Rock_Volcanic_Brick",
      "rotation": 3
    },
    {
      "x": -18,
      "y": 3,
      "z": 21,
      "name": "Rock_Volcanic_Cobble",
      "rotation": 3
    },
    {
      "x": -18,
      "y": 4,
      "z": 21,
      "name": "Rock_Volcanic_Brick",
      "rotation": 3
    },
    {
      "x": -18,
      "y": 5,
      "z": 21,
      "name": "Rock_Volcanic_Brick",
      "rotation": 3
    },
    {
      "x": -18,
      "y": 6,
      "z": 21,
      "name": "Rock_Volcanic_Brick",
      "rotation": 3
    },
    {
      "x": -18,
      "y": 7,
      "z": 21,
      "name": "Rock_Volcanic_Brick",
      "rotation": 3
    },
    {
      "x": -18,
      "y": 8,
      "z": 21,
      "name": "Rock_Volcanic_Brick",
      "rotation": 3
    },
    {
      "x": -18,
      "y": 9,
      "z": 21,
      "name": "Rock_Volcanic_Brick",
      "rotation": 3
    },
    {
      "x": -18,
      "y": 10,
      "z": 21,
      "name": "Rock_Volcanic_Cobble",
      "rotation": 3
    },
    {
      "x": -18,
      "y": 11,
      "z": 21,
      "name": "Rock_Volcanic_Cobble",
      "rotation": 3
    },
    {
      "x": -18,
      "y": 12,
      "z": 21,
      "name": "Rock_Volcanic_Brick",
      "rotation": 3
    },
    {
      "x": -18,
      "y": 13,
      "z": 21,
      "name": "Rock_Volcanic_Cobble",
      "rotation": 3
    },
    {
      "x": -18,
      "y": 14,
      "z": 21,
      "name": "Rock_Volcanic_Cobble",
      "rotation": 3
    },
    {
      "x": -18,
      "y": 15,
      "z": 21,
      "name": "Rock_Volcanic_Cobble",
      "rotation": 3
    },
    {
      "x": -18,
      "y": 16,
      "z": 21,
      "name": "Rock_Volcanic_Brick",
      "rotation": 3
    },
    {
      "x": -18,
      "y": 17,
      "z": 21,
      "name": "Rock_Volcanic_Cobble",
      "rotation": 3
    },
    {
      "x": -18,
      "y": 18,
      "z": 21,
      "name": "Rock_Volcanic_Brick",
      "rotation": 3
    },
    {
      "x": -18,
      "y": 19,
      "z": 21,
      "name": "Rock_Volcanic_Brick",
      "rotation": 3
    },
    {
      "x": -18,
      "y": 20,
      "z": 21,
      "name": "Rock_Volcanic_Brick",
      "rotation": 3
    },
    {
      "x": -18,
      "y": 21,
      "z": 21,
      "name": "Rock_Volcanic_Cobble",
      "rotation": 3
    },
    {
      "x": -18,
      "y": 22,
      "z": 21,
      "name": "Rock_Volcanic_Brick",
      "rotation": 3
    },
    {
      "x": -18,
      "y": 23,
      "z": 21,
      "name": "Rock_Volcanic_Brick",
      "rotation": 3
    },
    {
      "x": -18,
      "y": 24,
      "z": 21,
      "name": "Rock_Volcanic_Brick",
      "rotation": 3
    },
    {
      "x": -18,
      "y": 19,
      "z": 22,
      "name": "Rock_Volcanic_Brick",
      "rotation": 3
    },
    {
      "x": -18,
      "y": 24,
      "z": 22,
      "name": "*Rock_Volcanic_Brick_Stairs_State_Definitions_Inverted_Corner_Left",
      "rotation": 10
    },
    {
      "x": -18,
      "y": 25,
      "z": 22,
      "name": "Rock_Volcanic_Brick_Wall",
      "rotation": 2
    },
    {
      "x": -18,
      "y": 24,
      "z": 23,
      "name": "Rock_Volcanic_Brick_Stairs",
      "rotation": 9
    },
    {
      "x": -17,
      "y": 19,
      "z": -22,
      "name": "Rock_Volcanic_Brick_Smooth_Half",
      "rotation": 6
    },
    {
      "x": -17,
      "y": 23,
      "z": -22,
      "name": "Rock_Volcanic_Brick_Stairs",
      "rotation": 8
    },
    {
      "x": -17,
      "y": 24,
      "z": -22,
      "name": "Rock_Volcanic_Brick",
      "rotation": 2
    },
    {
      "x": -17,
      "y": 25,
      "z": -22,
      "name": "Rock_Volcanic_Brick",
      "rotation": 2
    },
    {
      "x": -17,
      "y": 26,
      "z": -22,
      "name": "Rock_Volcanic_Brick_Stairs",
      "rotation": 2
    },
    {
      "x": -17,
      "y": 0,
      "z": -21,
      "name": "Rock_Volcanic_Cobble",
      "rotation": 2
    },
    {
      "x": -17,
      "y": 1,
      "z": -21,
      "name": "Rock_Volcanic_Cobble",
      "rotation": 2
    },
    {
      "x": -17,
      "y": 2,
      "z": -21,
      "name": "Rock_Volcanic_Brick",
      "rotation": 2
    },
    {
      "x": -17,
      "y": 3,
      "z": -21,
      "name": "Rock_Volcanic_Cobble",
      "rotation": 2
    },
    {
      "x": -17,
      "y": 4,
      "z": -21,
      "name": "Rock_Volcanic_Cobble",
      "rotation": 2
    },
    {
      "x": -17,
      "y": 5,
      "z": -21,
      "name": "Rock_Volcanic_Brick",
      "rotation": 2
    },
    {
      "x": -17,
      "y": 6,
      "z": -21,
      "name": "Rock_Volcanic_Cobble",
      "rotation": 2
    },
    {
      "x": -17,
      "y": 7,
      "z": -21,
      "name": "Rock_Volcanic_Cobble",
      "rotation": 2
    },
    {
      "x": -17,
      "y": 8,
      "z": -21,
      "name": "Rock_Volcanic_Brick",
      "rotation": 2
    },
    {
      "x": -17,
      "y": 9,
      "z": -21,
      "name": "Rock_Volcanic_Cobble",
      "rotation": 2
    },
    {
      "x": -17,
      "y": 10,
      "z": -21,
      "name": "Rock_Volcanic_Brick",
      "rotation": 2
    },
    {
      "x": -17,
      "y": 11,
      "z": -21,
      "name": "Rock_Volcanic_Brick",
      "rotation": 2
    },
    {
      "x": -17,
      "y": 12,
      "z": -21,
      "name": "Rock_Volcanic_Brick",
      "rotation": 2
    },
    {
      "x": -17,
      "y": 13,
      "z": -21,
      "name": "Rock_Volcanic_Brick",
      "rotation": 2
    },
    {
      "x": -17,
      "y": 14,
      "z": -21,
      "name": "Rock_Volcanic_Brick",
      "rotation": 2
    },
    {
      "x": -17,
      "y": 15,
      "z": -21,
      "name": "Rock_Volcanic_Brick",
      "rotation": 2
    },
    {
      "x": -17,
      "y": 16,
      "z": -21,
      "name": "Rock_Volcanic_Brick",
      "rotation": 2
    },
    {
      "x": -17,
      "y": 17,
      "z": -21,
      "name": "Rock_Volcanic_Brick",
      "rotation": 2
    },
    {
      "x": -17,
      "y": 18,
      "z": -21,
      "name": "Rock_Volcanic_Cobble",
      "rotation": 2
    },
    {
      "x": -17,
      "y": 19,
      "z": -21,
      "name": "Rock_Volcanic_Cobble",
      "rotation": 2
    },
    {
      "x": -17,
      "y": 20,
      "z": -21,
      "name": "Rock_Volcanic_Brick",
      "rotation": 2
    },
    {
      "x": -17,
      "y": 21,
      "z": -21,
      "name": "Rock_Volcanic_Cobble",
      "rotation": 2
    },
    {
      "x": -17,
      "y": 22,
      "z": -21,
      "name": "Rock_Volcanic_Cobble",
      "rotation": 2
    },
    {
      "x": -17,
      "y": 23,
      "z": -21,
      "name": "Rock_Volcanic_Brick",
      "rotation": 2
    },
    {
      "x": -17,
      "y": 24,
      "z": -21,
      "name": "Rock_Volcanic_Brick",
      "rotation": 2
    },
    {
      "x": -17,
      "y": 25,
      "z": -21,
      "name": "Rock_Volcanic_Brick_Stairs"
    },
    {
      "x": -17,
      "y": 0,
      "z": -20,
      "name": "Rock_Volcanic_Cobble",
      "rotation": 2
    },
    {
      "x": -17,
      "y": 1,
      "z": -20,
      "name": "Rock_Volcanic_Cobble",
      "rotation": 2
    },
    {
      "x": -17,
      "y": 2,
      "z": -20,
      "name": "Rock_Volcanic_Brick",
      "rotation": 2
    },
    {
      "x": -17,
      "y": 3,
      "z": -20,
      "name": "Rock_Volcanic_Cobble",
      "rotation": 2
    },
    {
      "x": -17,
      "y": 4,
      "z": -20,
      "name": "Rock_Volcanic_Brick",
      "rotation": 2
    },
    {
      "x": -17,
      "y": 5,
      "z": -20,
      "name": "Rock_Volcanic_Cobble",
      "rotation": 2
    },
    {
      "x": -17,
      "y": 6,
      "z": -20,
      "name": "Rock_Volcanic_Cobble",
      "rotation": 2
    },
    {
      "x": -17,
      "y": 7,
      "z": -20,
      "name": "Rock_Volcanic_Cobble",
      "rotation": 2
    },
    {
      "x": -17,
      "y": 8,
      "z": -20,
      "name": "Rock_Volcanic_Cobble",
      "rotation": 2
    },
    {
      "x": -17,
      "y": 9,
      "z": -20,
      "name": "Rock_Volcanic_Brick",
      "rotation": 2
    },
    {
      "x": -17,
      "y": 10,
      "z": -20,
      "name": "Rock_Volcanic_Cobble",
      "rotation": 2
    },
    {
      "x": -17,
      "y": 11,
      "z": -20,
      "name": "Rock_Volcanic_Cobble",
      "rotation": 2
    },
    {
      "x": -17,
      "y": 12,
      "z": -20,
      "name": "Rock_Volcanic_Cobble",
      "rotation": 2
    },
    {
      "x": -17,
      "y": 13,
      "z": -20,
      "name": "Rock_Volcanic_Brick",
      "rotation": 2
    },
    {
      "x": -17,
      "y": 14,
      "z": -20,
      "name": "Rock_Volcanic_Brick",
      "rotation": 2
    },
    {
      "x": -17,
      "y": 15,
      "z": -20,
      "name": "Rock_Volcanic_Brick",
      "rotation": 2
    },
    {
      "x": -17,
      "y": 16,
      "z": -20,
      "name": "Rock_Volcanic_Cobble",
      "rotation": 2
    },
    {
      "x": -17,
      "y": 17,
      "z": -20,
      "name": "Rock_Volcanic_Cobble",
      "rotation": 2
    },
    {
      "x": -17,
      "y": 18,
      "z": -20,
      "name": "Rock_Volcanic_Brick",
      "rotation": 2
    },
    {
      "x": -17,
      "y": 19,
      "z": -20,
      "name": "Rock_Volcanic_Cobble",
      "rotation": 2
    },
    {
      "x": -17,
      "y": 20,
      "z": -20,
      "name": "Rock_Volcanic_Brick",
      "rotation": 2
    },
    {
      "x": -17,
      "y": 21,
      "z": -20,
      "name": "Rock_Volcanic_Brick",
      "rotation": 2
    },
    {
      "x": -17,
      "y": 22,
      "z": -20,
      "name": "Rock_Volcanic_Brick",
      "rotation": 2
    },
    {
      "x": -17,
      "y": 23,
      "z": -20,
      "name": "Rock_Volcanic_Cobble",
      "rotation": 2
    },
    {
      "x": -17,
      "y": 24,
      "z": -20,
      "name": "Rock_Volcanic_Brick",
      "rotation": 2
    },
    {
      "x": -17,
      "y": 20,
      "z": -19,
      "name": "Rock_Volcanic_Cobble",
      "rotation": 2
    },
    {
      "x": -17,
      "y": 24,
      "z": -19,
      "name": "Rock_Volcanic_Cobble",
      "rotation": 2
    },
    {
      "x": -17,
      "y": 20,
      "z": -18,
      "name": "Rock_Volcanic_Cobble",
      "rotation": 2
    },
    {
      "x": -17,
      "y": 24,
      "z": -18,
      "name": "Rock_Volcanic_Cobble",
      "rotation": 2
    },
    {
      "x": -17,
      "y": 20,
      "z": -17,
      "name": "Rock_Volcanic_Cobble",
      "rotation": 2
    },
    {
      "x": -17,
      "y": 24,
      "z": -17,
      "name": "Deco_Iron_Bars_Platforms",
      "rotation": 3
    },
    {
      "x": -17,
      "y": 20,
      "z": -16,
      "name": "Rock_Volcanic_Cobble",
      "rotation": 2
    },
    {
      "x": -17,
      "y": 24,
      "z": -16,
      "name": "Deco_Iron_Bars_Platforms",
      "rotation": 3
    },
    {
      "x": -17,
      "y": 20,
      "z": -15,
      "name": "Rock_Volcanic_Cobble",
      "rotation": 2
    },
    {
      "x": -17,
      "y": 24,
      "z": -15,
      "name": "Deco_Iron_Bars_Platforms",
      "rotation": 3
    },
    {
      "x": -17,
      "y": 20,
      "z": -14,
      "name": "Rock_Volcanic_Cobble",
      "rotation": 2
    },
    {
      "x": -17,
      "y": 24,
      "z": -14,
      "name": "Rock_Volcanic_Cobble",
      "rotation": 2
    },
    {
      "x": -17,
      "y": 20,
      "z": -13,
      "name": "Rock_Volcanic_Cobble",
      "rotation": 2
    },
    {
      "x": -17,
      "y": 24,
      "z": -13,
      "name": "Rock_Volcanic_Cobble",
      "rotation": 2
    },
    {
      "x": -17,
      "y": 0,
      "z": -12,
      "name": "Rock_Volcanic_Brick",
      "rotation": 2
    },
    {
      "x": -17,
      "y": 1,
      "z": -12,
      "name": "Rock_Volcanic_Cobble",
      "rotation": 2
    },
    {
      "x": -17,
      "y": 2,
      "z": -12,
      "name": "Rock_Volcanic_Cobble",
      "rotation": 2
    },
    {
      "x": -17,
      "y": 3,
      "z": -12,
      "name": "Rock_Volcanic_Brick",
      "rotation": 2
    },
    {
      "x": -17,
      "y": 4,
      "z": -12,
      "name": "Rock_Volcanic_Cobble",
      "rotation": 2
    },
    {
      "x": -17,
      "y": 5,
      "z": -12,
      "name": "Rock_Volcanic_Cobble",
      "rotation": 2
    },
    {
      "x": -17,
      "y": 6,
      "z": -12,
      "name": "Rock_Volcanic_Brick",
      "rotation": 2
    },
    {
      "x": -17,
      "y": 7,
      "z": -12,
      "name": "Rock_Volcanic_Brick",
      "rotation": 2
    },
    {
      "x": -17,
      "y": 8,
      "z": -12,
      "name": "Rock_Volcanic_Cobble",
      "rotation": 2
    },
    {
      "x": -17,
      "y": 9,
      "z": -12,
      "name": "Rock_Volcanic_Cobble",
      "rotation": 2
    },
    {
      "x": -17,
      "y": 10,
      "z": -12,
      "name": "Rock_Volcanic_Brick",
      "rotation": 2
    },
    {
      "x": -17,
      "y": 11,
      "z": -12,
      "name": "Rock_Volcanic_Cobble",
      "rotation": 2
    },
    {
      "x": -17,
      "y": 12,
      "z": -12,
      "name": "Rock_Volcanic_Brick",
      "rotation": 2
    },
    {
      "x": -17,
      "y": 13,
      "z": -12,
      "name": "Rock_Volcanic_Cobble",
      "rotation": 2
    },
    {
      "x": -17,
      "y": 14,
      "z": -12,
      "name": "Rock_Volcanic_Cobble",
      "rotation": 2
    },
    {
      "x": -17,
