{
  "version": 8,
  "blockIdVersion": 11,
  "anchorX": 0,
  "anchorY": 0,
  "anchorZ": 0,
  "blocks": [
    {
      "x": -27,
      "y": -4,
      "z": -26,
      "name": "Soil_Roots_Poisoned"
    },
    {
      "x": -27,
      "y": -4,
      "z": -25,
      "name": "Soil_Dirt_Poisoned"
    },
    {
      "x": -27,
      "y": -3,
      "z": -25,
      "name": "Soil_Roots_Poisoned"
    },
    {
      "x": -27,
      "y": -4,
      "z": -24,
      "name": "Soil_Roots_Poisoned"
    },
    {
      "x": -27,
      "y": -3,
      "z": -24,
      "name": "Soil_Dirt_Poisoned"
    },
    {
      "x": -27,
      "y": -4,
      "z": -23,
      "name": "Soil_Dirt_Poisoned"
    },
    {
      "x": -27,
      "y": -3,
      "z": -23,
      "name": "Soil_Roots_Poisoned"
    },
    {
      "x": -27,
      "y": -4,
      "z": -22,
      "name": "Soil_Roots_Poisoned"
    },
    {
      "x": -27,
      "y": -3,
      "z": -22,
      "name": "Soil_Roots_Poisoned"
    },
    {
      "x": -27,
      "y": -4,
      "z": -21,
      "name": "Soil_Roots_Poisoned"
    },
    {
      "x": -27,
      "y": -3,
      "z": -21,
      "name": "Soil_Roots_Poisoned"
    },
    {
      "x": -27,
      "y": -4,
      "z": -20,
      "name": "Soil_Roots_Poisoned"
    },
    {
      "x": -27,
      "y": -3,
      "z": -20,
      "name": "Soil_Roots_Poisoned"
    },
    {
      "x": -27,
      "y": -4,
      "z": -19,
      "name": "Soil_Dirt_Poisoned"
    },
    {
      "x": -27,
      "y": -3,
      "z": -19,
      "name": "Soil_Roots_Poisoned"
    },
    {
      "x": -27,
      "y": -4,
      "z": -18,
      "name": "Soil_Roots_Poisoned"
    },
    {
      "x": -27,
      "y": -3,
      "z": -18,
      "name": "Soil_Roots_Poisoned"
    },
    {
      "x": -27,
      "y": -4,
      "z": -17,
      "name": "Soil_Roots_Poisoned"
    },
    {
      "x": -27,
      "y": -3,
      "z": -17,
      "name": "Soil_Roots_Poisoned"
    },
    {
      "x": -27,
      "y": -4,
      "z": -16,
      "name": "Soil_Roots_Poisoned"
    },
    {
      "x": -27,
      "y": -3,
      "z": -16,
      "name": "Soil_Dirt_Poisoned"
    },
    {
      "x": -27,
      "y": -4,
      "z": -15,
      "name": "Soil_Roots_Poisoned"
    },
    {
      "x": -27,
      "y": -3,
      "z": -15,
      "name": "Soil_Roots_Poisoned"
    },
    {
      "x": -27,
      "y": -4,
      "z": -14,
      "name": "Soil_Dirt_Poisoned"
    },
    {
      "x": -27,
      "y": -3,
      "z": -14,
      "name": "Soil_Roots_Poisoned"
    },
    {
      "x": -27,
      "y": -2,
      "z": -14,
      "name": "Soil_Roots_Poisoned"
    },
    {
      "x": -27,
      "y": -4,
      "z": -13,
      "name": "Soil_Dirt_Poisoned"
    },
    {
      "x": -27,
      "y": -3,
      "z": -13,
      "name": "Soil_Roots_Poisoned"
    },
    {
      "x": -27,
      "y": -2,
      "z": -13,
      "name": "Soil_Dirt_Poisoned"
    },
    {
      "x": -27,
      "y": -4,
      "z": -12,
      "name": "Soil_Dirt_Poisoned"
    },
    {
      "x": -27,
      "y": -3,
      "z": -12,
      "name": "Soil_Roots_Poisoned"
    },
    {
      "x": -27,
      "y": -2,
      "z": -12,
      "name": "Soil_Roots_Poisoned"
    },
    {
      "x": -27,
      "y": -4,
      "z": -11,
      "name": "Soil_Dirt_Poisoned"
    },
    {
      "x": -27,
      "y": -3,
      "z": -11,
      "name": "Soil_Dirt_Poisoned"
    },
    {
      "x": -27,
      "y": -2,
      "z": -11,
      "name": "Soil_Dirt_Poisoned"
    },
    {
      "x": -27,
      "y": -1,
      "z": -11,
      "name": "Soil_Dirt_Poisoned"
    },
    {
      "x": -27,
      "y": -4,
      "z": -10,
      "name": "Soil_Roots_Poisoned"
    },
    {
      "x": -27,
      "y": -3,
      "z": -10,
      "name": "Soil_Dirt_Poisoned"
    },
    {
      "x": -27,
      "y": -2,
      "z": -10,
      "name": "Soil_Dirt_Poisoned"
    },
    {
      "x": -27,
      "y": -1,
      "z": -10,
      "name": "Soil_Roots_Poisoned"
    },
    {
      "x": -27,
      "y": -4,
      "z": -9,
      "name": "Soil_Dirt_Poisoned"
    },
    {
      "x": -27,
      "y": -3,
      "z": -9,
      "name": "Soil_Dirt_Poisoned"
    },
    {
      "x": -27,
      "y": -2,
      "z": -9,
      "name": "Soil_Roots_Poisoned"
    },
    {
      "x": -27,
      "y": -4,
      "z": -8,
      "name": "Soil_Roots_Poisoned"
    },
    {
      "x": -27,
      "y": -3,
      "z": -8,
      "name": "Soil_Dirt_Poisoned"
    },
    {
      "x": -27,
      "y": -4,
      "z": -7,
      "name": "Soil_Dirt_Poisoned"
    },
    {
      "x": -27,
      "y": -4,
      "z": -6,
      "name": "Soil_Dirt_Poisoned"
    },
    {
      "x": -27,
      "y": -4,
      "z": -5,
      "name": "Soil_Dirt_Poisoned"
    },
    {
      "x": -27,
      "y": -4,
      "z": -4,
      "name": "Soil_Dirt_Poisoned"
    },
    {
      "x": -27,
      "y": -4,
      "z": -3,
      "name": "Soil_Roots_Poisoned"
    },
    {
      "x": -27,
      "y": -4,
      "z": -2,
      "name": "Soil_Dirt_Poisoned"
    },
    {
      "x": -27,
      "y": -4,
      "z": -1,
      "name": "Soil_Dirt_Poisoned"
    },
    {
      "x": -27,
      "y": -4,
      "z": 0,
      "name": "Soil_Roots_Poisoned"
    },
    {
      "x": -27,
      "y": -4,
      "z": 1,
      "name": "Soil_Dirt_Poisoned"
    },
    {
      "x": -27,
      "y": -4,
      "z": 2,
      "name": "Soil_Dirt_Poisoned"
    },
    {
      "x": -27,
      "y": -4,
      "z": 3,
      "name": "Soil_Roots_Poisoned"
    },
    {
      "x": -27,
      "y": -4,
      "z": 4,
      "name": "Soil_Dirt_Poisoned"
    },
    {
      "x": -27,
      "y": -4,
      "z": 5,
      "name": "Soil_Roots_Poisoned"
    },
    {
      "x": -27,
      "y": -4,
      "z": 6,
      "name": "Soil_Dirt_Poisoned"
    },
    {
      "x": -27,
      "y": -4,
      "z": 7,
      "name": "Soil_Roots_Poisoned"
    },
    {
      "x": -27,
      "y": -4,
      "z": 8,
      "name": "Soil_Roots_Poisoned"
    },
    {
      "x": -27,
      "y": -4,
      "z": 9,
      "name": "Soil_Roots_Poisoned"
    },
    {
      "x": -27,
      "y": -4,
      "z": 10,
      "name": "Soil_Dirt_Poisoned"
    },
    {
      "x": -27,
      "y": -4,
      "z": 11,
      "name": "Soil_Roots_Poisoned"
    },
    {
      "x": -27,
      "y": -4,
      "z": 12,
      "name": "Soil_Roots_Poisoned"
    },
    {
      "x": -27,
      "y": -3,
      "z": 12,
      "name": "Soil_Roots_Poisoned"
    },
    {
      "x": -27,
      "y": -4,
      "z": 13,
      "name": "Soil_Roots_Poisoned"
    },
    {
      "x": -27,
      "y": -3,
      "z": 13,
      "name": "Soil_Roots_Poisoned"
    },
    {
      "x": -27,
      "y": -4,
      "z": 14,
      "name": "Soil_Roots_Poisoned"
    },
    {
      "x": -27,
      "y": -3,
      "z": 14,
      "name": "Soil_Roots_Poisoned"
    },
    {
      "x": -27,
      "y": -4,
      "z": 15,
      "name": "Soil_Dirt_Poisoned"
    },
    {
      "x": -27,
      "y": -3,
      "z": 15,
      "name": "Soil_Roots_Poisoned"
    },
    {
      "x": -27,
      "y": -4,
      "z": 16,
      "name": "Soil_Dirt_Poisoned"
    },
    {
      "x": -27,
      "y": -3,
      "z": 16,
      "name": "Soil_Dirt_Poisoned"
    },
    {
      "x": -27,
      "y": -4,
      "z": 17,
      "name": "Soil_Dirt_Poisoned"
    },
    {
      "x": -27,
      "y": -3,
      "z": 17,
      "name": "Soil_Roots_Poisoned"
    },
    {
      "x": -27,
      "y": -2,
      "z": 17,
      "name": "Soil_Roots_Poisoned"
    },
    {
      "x": -27,
      "y": -4,
      "z": 18,
      "name": "Soil_Roots_Poisoned"
    },
    {
      "x": -27,
      "y": -3,
      "z": 18,
      "name": "Soil_Dirt_Poisoned"
    },
    {
      "x": -27,
      "y": -2,
      "z": 18,
      "name": "Soil_Dirt_Poisoned"
    },
    {
      "x": -27,
      "y": -4,
      "z": 19,
      "name": "Soil_Dirt_Poisoned"
    },
    {
      "x": -27,
      "y": -3,
      "z": 19,
      "name": "Soil_Roots_Poisoned"
    },
    {
      "x": -27,
      "y": -2,
      "z": 19,
      "name": "Soil_Roots_Poisoned"
    },
    {
      "x": -27,
      "y": -4,
      "z": 20,
      "name": "Soil_Dirt_Poisoned"
    },
    {
      "x": -27,
      "y": -3,
      "z": 20,
      "name": "Soil_Roots_Poisoned"
    },
    {
      "x": -27,
      "y": -2,
      "z": 20,
      "name": "Soil_Dirt_Poisoned"
    },
    {
      "x": -27,
      "y": -4,
      "z": 21,
      "name": "Soil_Dirt_Poisoned"
    },
    {
      "x": -27,
      "y": -3,
      "z": 21,
      "name": "Soil_Roots_Poisoned"
    },
    {
      "x": -27,
      "y": -2,
      "z": 21,
      "name": "Soil_Dirt_Poisoned"
    },
    {
      "x": -27,
      "y": -4,
      "z": 22,
      "name": "Soil_Dirt_Poisoned"
    },
    {
      "x": -27,
      "y": -3,
      "z": 22,
      "name": "Soil_Roots_Poisoned"
    },
    {
      "x": -27,
      "y": -4,
      "z": 23,
      "name": "Soil_Roots_Poisoned"
    },
    {
      "x": -27,
      "y": -3,
      "z": 23,
      "name": "Soil_Roots_Poisoned"
    },
    {
      "x": -27,
      "y": -4,
      "z": 24,
      "name": "Soil_Roots_Poisoned"
    },
    {
      "x": -27,
      "y": -3,
      "z": 24,
      "name": "Soil_Dirt_Poisoned"
    },
    {
      "x": -27,
      "y": -4,
      "z": 25,
      "name": "Soil_Roots_Poisoned"
    },
    {
      "x": -27,
      "y": -3,
      "z": 25,
      "name": "Soil_Roots_Poisoned"
    },
    {
      "x": -27,
      "y": -4,
      "z": 26,
      "name": "Soil_Roots_Poisoned"
    },
    {
      "x": -27,
      "y": -3,
      "z": 26,
      "name": "Soil_Roots_Poisoned"
    },
    {
      "x": -27,
      "y": -4,
      "z": 27,
      "name": "Soil_Roots_Poisoned"
    },
    {
      "x": -27,
      "y": -3,
      "z": 27,
      "name": "Soil_Roots_Poisoned"
    },
    {
      "x": -27,
      "y": -4,
      "z": 28,
      "name": "Soil_Dirt_Poisoned"
    },
    {
      "x": -27,
      "y": -4,
      "z": 29,
      "name": "Soil_Roots_Poisoned"
    },
    {
      "x": -27,
      "y": -4,
      "z": 30,
      "name": "Soil_Roots_Poisoned"
    },
    {
      "x": -27,
      "y": -3,
      "z": 30,
      "name": "Soil_Roots_Poisoned"
    },
    {
      "x": -27,
      "y": -4,
      "z": 31,
      "name": "Soil_Roots_Poisoned"
    },
    {
      "x": -27,
      "y": -3,
      "z": 31,
      "name": "Soil_Dirt_Poisoned"
    },
    {
      "x": -27,
      "y": -2,
      "z": 31,
      "name": "Soil_Roots_Poisoned"
    },
    {
      "x": -26,
      "y": -4,
      "z": -27,
      "name": "Soil_Dirt_Poisoned"
    },
    {
      "x": -26,
      "y": -4,
      "z": -26,
      "name": "Soil_Roots_Poisoned"
    },
    {
      "x": -26,
      "y": -3,
      "z": -26,
      "name": "Soil_Dirt_Poisoned"
    },
    {
      "x": -26,
      "y": -4,
      "z": -25,
      "name": "Soil_Roots_Poisoned"
    },
    {
      "x": -26,
      "y": -3,
      "z": -25,
      "name": "Soil_Roots_Poisoned"
    },
    {
      "x": -26,
      "y": -4,
      "z": -24,
      "name": "Soil_Roots_Poisoned"
    },
    {
      "x": -26,
      "y": -3,
      "z": -24,
      "name": "Soil_Roots_Poisoned"
    },
    {
      "x": -26,
      "y": -2,
      "z": -24,
      "name": "Soil_Roots_Poisoned"
    },
    {
      "x": -26,
      "y": -4,
      "z": -23,
      "name": "Soil_Dirt_Poisoned"
    },
    {
      "x": -26,
      "y": -3,
      "z": -23,
      "name": "Soil_Roots_Poisoned"
    },
    {
      "x": -26,
      "y": -2,
      "z": -23,
      "name": "Soil_Roots_Poisoned"
    },
    {
      "x": -26,
      "y": -4,
      "z": -22,
      "name": "Soil_Dirt_Poisoned"
    },
    {
      "x": -26,
      "y": -3,
      "z": -22,
      "name": "Soil_Roots_Poisoned"
    },
    {
      "x": -26,
      "y": -2,
      "z": -22,
      "name": "Soil_Roots_Poisoned"
    },
    {
      "x": -26,
      "y": -4,
      "z": -21,
      "name": "Soil_Dirt_Poisoned"
    },
    {
      "x": -26,
      "y": -3,
      "z": -21,
      "name": "Soil_Roots_Poisoned"
    },
    {
      "x": -26,
      "y": -2,
      "z": -21,
      "name": "Soil_Dirt_Poisoned"
    },
    {
      "x": -26,
      "y": -4,
      "z": -20,
      "name": "Soil_Roots_Poisoned"
    },
    {
      "x": -26,
      "y": -3,
      "z": -20,
      "name": "Soil_Roots_Poisoned"
    },
    {
      "x": -26,
      "y": -2,
      "z": -20,
      "name": "Soil_Roots_Poisoned"
    },
    {
      "x": -26,
      "y": -4,
      "z": -19,
      "name": "Soil_Roots_Poisoned"
    },
    {
      "x": -26,
      "y": -3,
      "z": -19,
      "name": "Soil_Roots_Poisoned"
    },
    {
      "x": -26,
      "y": -2,
      "z": -19,
      "name": "Soil_Dirt_Poisoned"
    },
    {
      "x": -26,
      "y": -1,
      "z": -19,
      "name": "Soil_Roots_Poisoned"
    },
    {
      "x": -26,
      "y": -4,
      "z": -18,
      "name": "Soil_Dirt_Poisoned"
    },
    {
      "x": -26,
      "y": -3,
      "z": -18,
      "name": "Soil_Roots_Poisoned"
    },
    {
      "x": -26,
      "y": -2,
      "z": -18,
      "name": "Soil_Dirt_Poisoned"
    },
    {
      "x": -26,
      "y": -1,
      "z": -18,
      "name": "Soil_Dirt_Poisoned"
    },
    {
      "x": -26,
      "y": -4,
      "z": -17,
      "name": "Soil_Dirt_Poisoned"
    },
    {
      "x": -26,
      "y": -3,
      "z": -17,
      "name": "Soil_Roots_Poisoned"
    },
    {
      "x": -26,
      "y": -2,
      "z": -17,
      "name": "Soil_Dirt_Poisoned"
    },
    {
      "x": -26,
      "y": -1,
      "z": -17,
      "name": "Soil_Roots_Poisoned"
    },
    {
      "x": -26,
      "y": -4,
      "z": -16,
      "name": "Soil_Dirt_Poisoned"
    },
    {
      "x": -26,
      "y": -3,
      "z": -16,
      "name": "Soil_Dirt_Poisoned"
    },
    {
      "x": -26,
      "y": -2,
      "z": -16,
      "name": "Soil_Dirt_Poisoned"
    },
    {
      "x": -26,
      "y": -1,
      "z": -16,
      "name": "Soil_Roots_Poisoned"
    },
    {
      "x": -26,
      "y": -4,
      "z": -15,
      "name": "Soil_Dirt_Poisoned"
    },
    {
      "x": -26,
      "y": -3,
      "z": -15,
      "name": "Soil_Dirt_Poisoned"
    },
    {
      "x": -26,
      "y": -2,
      "z": -15,
      "name": "Soil_Dirt_Poisoned"
    },
    {
      "x": -26,
      "y": -1,
      "z": -15,
      "name": "Soil_Roots_Poisoned"
    },
    {
      "x": -26,
      "y": -4,
      "z": -14,
      "name": "Soil_Dirt_Poisoned"
    },
    {
      "x": -26,
      "y": -3,
      "z": -14,
      "name": "Soil_Roots_Poisoned"
    },
    {
      "x": -26,
      "y": -2,
      "z": -14,
      "name": "Soil_Roots_Poisoned"
    },
    {
      "x": -26,
      "y": -1,
      "z": -14,
      "name": "Soil_Dirt_Poisoned"
    },
    {
      "x": -26,
      "y": -4,
      "z": -13,
      "name": "Soil_Roots_Poisoned"
    },
    {
      "x": -26,
      "y": -3,
      "z": -13,
      "name": "Soil_Dirt_Poisoned"
    },
    {
      "x": -26,
      "y": -2,
      "z": -13,
      "name": "Soil_Dirt_Poisoned"
    },
    {
      "x": -26,
      "y": -1,
      "z": -13,
      "name": "Soil_Roots_Poisoned"
    },
    {
      "x": -26,
      "y": -4,
      "z": -12,
      "name": "Soil_Roots_Poisoned"
    },
    {
      "x": -26,
      "y": -3,
      "z": -12,
      "name": "Soil_Roots_Poisoned"
    },
    {
      "x": -26,
      "y": -2,
      "z": -12,
      "name": "Soil_Dirt_Poisoned"
    },
    {
      "x": -26,
      "y": -1,
      "z": -12,
      "name": "Soil_Dirt_Poisoned"
    },
    {
      "x": -26,
      "y": -4,
      "z": -11,
      "name": "Soil_Dirt_Poisoned"
    },
    {
      "x": -26,
      "y": -3,
      "z": -11,
      "name": "Soil_Roots_Poisoned"
    },
    {
      "x": -26,
      "y": -2,
      "z": -11,
      "name": "Soil_Dirt_Poisoned"
    },
    {
      "x": -26,
      "y": -1,
      "z": -11,
      "name": "Soil_Dirt_Poisoned"
    },
    {
      "x": -26,
      "y": -4,
      "z": -10,
      "name": "Soil_Roots_Poisoned"
    },
    {
      "x": -26,
      "y": -3,
      "z": -10,
      "name": "Soil_Dirt_Poisoned"
    },
    {
      "x": -26,
      "y": -2,
      "z": -10,
      "name": "Soil_Roots_Poisoned"
    },
    {
      "x": -26,
      "y": -1,
      "z": -10,
      "name": "Soil_Dirt_Poisoned"
    },
    {
      "x": -26,
      "y": -4,
      "z": -9,
      "name": "Soil_Roots_Poisoned"
    },
    {
      "x": -26,
      "y": -3,
      "z": -9,
      "name": "Soil_Roots_Poisoned"
    },
    {
      "x": -26,
      "y": -2,
      "z": -9,
      "name": "Soil_Dirt_Poisoned"
    },
    {
      "x": -26,
      "y": -1,
      "z": -9,
      "name": "Soil_Roots_Poisoned"
    },
    {
      "x": -26,
      "y": -4,
      "z": -8,
      "name": "Soil_Dirt_Poisoned"
    },
    {
      "x": -26,
      "y": -3,
      "z": -8,
      "name": "Soil_Dirt_Poisoned"
    },
    {
      "x": -26,
      "y": -2,
      "z": -8,
      "name": "Soil_Dirt_Poisoned"
    },
    {
      "x": -26,
      "y": -4,
      "z": -7,
      "name": "Soil_Dirt_Poisoned"
    },
    {
      "x": -26,
      "y": -3,
      "z": -7,
      "name": "Soil_Dirt_Poisoned"
    },
    {
      "x": -26,
      "y": -2,
      "z": -7,
      "name": "Soil_Dirt_Poisoned"
    },
    {
      "x": -26,
      "y": -4,
      "z": -6,
      "name": "Soil_Roots_Poisoned"
    },
    {
      "x": -26,
      "y": -3,
      "z": -6,
      "name": "Soil_Dirt_Poisoned"
    },
    {
      "x": -26,
      "y": -2,
      "z": -6,
      "name": "Soil_Roots_Poisoned"
    },
    {
      "x": -26,
      "y": -4,
      "z": -5,
      "name": "Soil_Roots_Poisoned"
    },
    {
      "x": -26,
      "y": -3,
      "z": -5,
      "name": "Soil_Roots_Poisoned"
    },
    {
      "x": -26,
      "y": -2,
      "z": -5,
      "name": "Soil_Dirt_Poisoned"
    },
    {
      "x": -26,
      "y": -4,
      "z": -4,
      "name": "Soil_Dirt_Poisoned"
    },
    {
      "x": -26,
      "y": -3,
      "z": -4,
      "name": "Soil_Roots_Poisoned"
    },
    {
      "x": -26,
      "y": -2,
      "z": -4,
      "name": "Soil_Dirt_Poisoned"
    },
    {
      "x": -26,
      "y": -4,
      "z": -3,
      "name": "Soil_Roots_Poisoned"
    },
    {
      "x": -26,
      "y": -3,
      "z": -3,
      "name": "Soil_Dirt_Poisoned"
    },
    {
      "x": -26,
      "y": -2,
      "z": -3,
      "name": "Soil_Dirt_Poisoned"
    },
    {
      "x": -26,
      "y": -4,
      "z": -2,
      "name": "Soil_Roots_Poisoned"
    },
    {
      "x": -26,
      "y": -3,
      "z": -2,
      "name": "Soil_Roots_Poisoned"
    },
    {
      "x": -26,
      "y": -2,
      "z": -2,
      "name": "Soil_Dirt_Poisoned"
    },
    {
      "x": -26,
      "y": -4,
      "z": -1,
      "name": "Soil_Dirt_Poisoned"
    },
    {
      "x": -26,
      "y": -3,
      "z": -1,
      "name": "Soil_Dirt_Poisoned"
    },
    {
      "x": -26,
      "y": -2,
      "z": -1,
      "name": "Soil_Dirt_Poisoned"
    },
    {
      "x": -26,
      "y": -4,
      "z": 0,
      "name": "Soil_Dirt_Poisoned"
    },
    {
      "x": -26,
      "y": -3,
      "z": 0,
      "name": "Soil_Dirt_Poisoned"
    },
    {
      "x": -26,
      "y": -2,
      "z": 0,
      "name": "Soil_Roots_Poisoned"
    },
    {
      "x": -26,
      "y": -4,
      "z": 1,
      "name": "Soil_Roots_Poisoned"
    },
    {
      "x": -26,
      "y": -3,
      "z": 1,
      "name": "Soil_Roots_Poisoned"
    },
    {
      "x": -26,
      "y": -2,
      "z": 1,
      "name": "Soil_Roots_Poisoned"
    },
    {
      "x": -26,
      "y": -4,
      "z": 2,
      "name": "Soil_Roots_Poisoned"
    },
    {
      "x": -26,
      "y": -3,
      "z": 2,
      "name": "Soil_Dirt_Poisoned"
    },
    {
      "x": -26,
      "y": -2,
      "z": 2,
      "name": "Soil_Dirt_Poisoned"
    },
    {
      "x": -26,
      "y": -4,
      "z": 3,
      "name": "Soil_Roots_Poisoned"
    },
    {
      "x": -26,
      "y": -3,
      "z": 3,
      "name": "Soil_Roots_Poisoned"
    },
    {
      "x": -26,
      "y": -2,
      "z": 3,
      "name": "Soil_Roots_Poisoned"
    },
    {
      "x": -26,
      "y": -4,
      "z": 4,
      "name": "Soil_Dirt_Poisoned"
    },
    {
      "x": -26,
      "y": -3,
      "z": 4,
      "name": "Soil_Roots_Poisoned"
    },
    {
      "x": -26,
      "y": -2,
      "z": 4,
      "name": "Soil_Roots_Poisoned"
    },
    {
      "x": -26,
      "y": -4,
      "z": 5,
      "name": "Soil_Roots_Poisoned"
    },
    {
      "x": -26,
      "y": -3,
      "z": 5,
      "name": "Soil_Roots_Poisoned"
    },
    {
      "x": -26,
      "y": -2,
      "z": 5,
      "name": "Soil_Dirt_Poisoned"
    },
    {
      "x": -26,
      "y": -4,
      "z": 6,
      "name": "Soil_Roots_Poisoned"
    },
    {
      "x": -26,
      "y": -3,
      "z": 6,
      "name": "Soil_Roots_Poisoned"
    },
    {
      "x": -26,
      "y": -2,
      "z": 6,
      "name": "Soil_Roots_Poisoned"
    },
    {
      "x": -26,
      "y": -4,
      "z": 7,
      "name": "Soil_Roots_Poisoned"
    },
    {
      "x": -26,
      "y": -3,
      "z": 7,
      "name": "Soil_Roots_Poisoned"
    },
    {
      "x": -26,
      "y": -2,
      "z": 7,
      "name": "Soil_Roots_Poisoned"
    },
    {
      "x": -26,
      "y": -4,
      "z": 8,
      "name": "Soil_Dirt_Poisoned"
    },
    {
      "x": -26,
      "y": -3,
      "z": 8,
      "name": "Soil_Roots_Poisoned"
    },
    {
      "x": -26,
      "y": -2,
      "z": 8,
      "name": "Soil_Roots_Poisoned"
    },
    {
      "x": -26,
      "y": -4,
      "z": 9,
      "name": "Soil_Roots_Poisoned"
    },
    {
      "x": -26,
      "y": -3,
      "z": 9,
      "name": "Soil_Dirt_Poisoned"
    },
    {
      "x": -26,
      "y": -2,
      "z": 9,
      "name": "Soil_Dirt_Poisoned"
    },
    {
      "x": -26,
      "y": -4,
      "z": 10,
      "name": "Soil_Dirt_Poisoned"
    },
    {
      "x": -26,
      "y": -3,
      "z": 10,
      "name": "Soil_Dirt_Poisoned"
    },
    {
      "x": -26,
      "y": -2,
      "z": 10,
      "name": "Soil_Roots_Poisoned"
    },
    {
      "x": -26,
      "y": -4,
      "z": 11,
      "name": "Soil_Roots_Poisoned"
    },
    {
      "x": -26,
      "y": -3,
      "z": 11,
      "name": "Soil_Roots_Poisoned"
    },
    {
      "x": -26,
      "y": -2,
      "z": 11,
      "name": "Soil_Roots_Poisoned"
    },
    {
      "x": -26,
      "y": -4,
      "z": 12,
      "name": "Soil_Dirt_Poisoned"
    },
    {
      "x": -26,
      "y": -3,
      "z": 12,
      "name": "Soil_Roots_Poisoned"
    },
    {
      "x": -26,
      "y": -2,
      "z": 12,
      "name": "Soil_Dirt_Poisoned"
    },
    {
      "x": -26,
      "y": -4,
      "z": 13,
      "name": "Soil_Dirt_Poisoned"
    },
    {
      "x": -26,
      "y": -3,
      "z": 13,
      "name": "Soil_Roots_Poisoned"
    },
    {
      "x": -26,
      "y": -2,
      "z": 13,
      "name": "Soil_Roots_Poisoned"
    },
    {
      "x": -26,
      "y": -4,
      "z": 14,
      "name": "Soil_Dirt_Poisoned"
    },
    {
      "x": -26,
      "y": -3,
      "z": 14,
      "name": "Soil_Roots_Poisoned"
    },
    {
      "x": -26,
      "y": -2,
      "z": 14,
      "name": "Soil_Dirt_Poisoned"
    },
    {
      "x": -26,
      "y": -4,
      "z": 15,
      "name": "Soil_Dirt_Poisoned"
    },
    {
      "x": -26,
      "y": -3,
      "z": 15,
      "name": "Soil_Roots_Poisoned"
    },
    {
      "x": -26,
      "y": -2,
      "z": 15,
      "name": "Soil_Roots_Poisoned"
    },
    {
      "x": -26,
      "y": -4,
      "z": 16,
      "name": "Soil_Dirt_Poisoned"
    },
    {
      "x": -26,
      "y": -3,
      "z": 16,
      "name": "Soil_Roots_Poisoned"
    },
    {
      "x": -26,
      "y": -2,
      "z": 16,
      "name": "Soil_Dirt_Poisoned"
    },
    {
      "x": -26,
      "y": -4,
      "z": 17,
      "name": "Soil_Dirt_Poisoned"
    },
    {
      "x": -26,
      "y": -3,
      "z": 17,
      "name": "Soil_Dirt_Poisoned"
    },
    {
      "x": -26,
      "y": -2,
      "z": 17,
      "name": "Soil_Dirt_Poisoned"
    },
    {
      "x": -26,
      "y": -4,
      "z": 18,
      "name": "Soil_Dirt_Poisoned"
    },
    {
      "x": -26,
      "y": -3,
      "z": 18,
      "name": "Soil_Roots_Poisoned"
    },
    {
      "x": -26,
      "y": -2,
      "z": 18,
      "name": "Soil_Roots_Poisoned"
    },
    {
      "x": -26,
      "y": -4,
      "z": 19,
      "name": "Soil_Roots_Poisoned"
    },
    {
      "x": -26,
      "y": -3,
      "z": 19,
      "name": "Soil_Dirt_Poisoned"
    },
    {
      "x": -26,
      "y": -2,
      "z": 19,
      "name": "Soil_Dirt_Poisoned"
    },
    {
      "x": -26,
      "y": -1,
      "z": 19,
      "name": "Soil_Roots_Poisoned"
    },
    {
      "x": -26,
      "y": -4,
      "z": 20,
      "name": "Soil_Dirt_Poisoned"
    },
    {
      "x": -26,
      "y": -3,
      "z": 20,
      "name": "Soil_Dirt_Poisoned"
    },
    {
      "x": -26,
      "y": -2,
      "z": 20,
      "name": "Soil_Dirt_Poisoned"
    },
    {
      "x": -26,
      "y": -4,
      "z": 21,
      "name": "Soil_Dirt_Poisoned"
    },
    {
      "x": -26,
      "y": -3,
      "z": 21,
      "name": "Soil_Dirt_Poisoned"
    },
    {
      "x": -26,
      "y": -2,
      "z": 21,
      "name": "Soil_Roots_Poisoned"
    },
    {
      "x": -26,
      "y": -1,
      "z": 21,
      "name": "Soil_Roots_Poisoned"
    },
    {
      "x": -26,
      "y": -4,
      "z": 22,
      "name": "Soil_Dirt_Poisoned"
    },
    {
      "x": -26,
      "y": -3,
      "z": 22,
      "name": "Soil_Roots_Poisoned"
    },
    {
      "x": -26,
      "y": -2,
      "z": 22,
      "name": "Soil_Dirt_Poisoned"
    },
    {
      "x": -26,
      "y": -4,
      "z": 23,
      "name": "Soil_Roots_Poisoned"
    },
    {
      "x": -26,
      "y": -3,
      "z": 23,
      "name": "Soil_Dirt_Poisoned"
    },
    {
      "x": -26,
      "y": -2,
      "z": 23,
      "name": "Soil_Roots_Poisoned"
    },
    {
      "x": -26,
      "y": -4,
      "z": 24,
      "name": "Soil_Dirt_Poisoned"
    },
    {
      "x": -26,
      "y": -3,
      "z": 24,
      "name": "Soil_Dirt_Poisoned"
    },
    {
      "x": -26,
      "y": -2,
      "z": 24,
      "name": "Soil_Roots_Poisoned"
    },
    {
      "x": -26,
      "y": -4,
      "z": 25,
      "name": "Soil_Dirt_Poisoned"
    },
    {
      "x": -26,
      "y": -3,
      "z": 25,
      "name": "Soil_Roots_Poisoned"
    },
    {
      "x": -26,
      "y": -2,
      "z": 25,
      "name": "Soil_Roots_Poisoned"
    },
    {
      "x": -26,
      "y": -4,
      "z": 26,
      "name": "Soil_Dirt_Poisoned"
    },
    {
      "x": -26,
      "y": -3,
      "z": 26,
      "name": "Soil_Dirt_Poisoned"
    },
    {
      "x": -26,
      "y": -4,
      "z": 27,
      "name": "Soil_Roots_Poisoned"
    },
    {
      "x": -26,
      "y": -3,
      "z": 27,
      "name": "Soil_Dirt_Poisoned"
    },
    {
      "x": -26,
      "y": -4,
      "z": 28,
      "name": "Soil_Roots_Poisoned"
    },
    {
      "x": -26,
      "y": -3,
      "z": 28,
      "name": "Soil_Dirt_Poisoned"
    },
    {
      "x": -26,
      "y": -4,
      "z": 29,
      "name": "Soil_Roots_Poisoned"
    },
    {
      "x": -26,
      "y": -3,
      "z": 29,
      "name": "Soil_Roots_Poisoned"
    },
    {
      "x": -26,
      "y": -4,
      "z": 30,
      "name": "Soil_Dirt_Poisoned"
    },
    {
      "x": -26,
      "y": -4,
      "z": 31,
      "name": "Soil_Dirt_Poisoned"
    },
    {
      "x": -26,
      "y": -3,
      "z": 31,
      "name": "Soil_Roots_Poisoned"
    },
    {
      "x": -25,
      "y": -4,
      "z": -28,
      "name": "Soil_Roots_Poisoned"
    },
    {
      "x": -25,
      "y": -4,
      "z": -27,
      "name": "Soil_Dirt_Poisoned"
    },
    {
      "x": -25,
      "y": -3,
      "z": -27,
      "name": "Soil_Roots_Poisoned"
    },
    {
      "x": -25,
      "y": -4,
      "z": -26,
      "name": "Soil_Roots_Poisoned"
    },
    {
      "x": -25,
      "y": -3,
      "z": -26,
      "name": "Soil_Roots_Poisoned"
    },
    {
      "x": -25,
      "y": -2,
      "z": -26,
      "name": "Soil_Dirt_Poisoned"
    },
    {
      "x": -25,
      "y": -4,
      "z": -25,
      "name": "Soil_Dirt_Poisoned"
    },
    {
      "x": -25,
      "y": -3,
      "z": -25,
      "name": "Soil_Roots_Poisoned"
    },
    {
      "x": -25,
      "y": -2,
      "z": -25,
      "name": "Soil_Roots_Poisoned"
    },
    {
      "x": -25,
      "y": -4,
      "z": -24,
      "name": "Soil_Roots_Poisoned"
    },
    {
      "x": -25,
      "y": -3,
      "z": -24,
      "name": "Soil_Roots_Poisoned"
    },
    {
      "x": -25,
      "y": -2,
      "z": -24,
      "name": "Soil_Roots_Poisoned"
    },
    {
      "x": -25,
      "y": -1,
      "z": -24,
      "name": "Soil_Roots_Poisoned"
    },
    {
      "x": -25,
      "y": -4,
      "z": -23,
      "name": "Soil_Dirt_Poisoned"
    },
    {
      "x": -25,
      "y": -3,
      "z": -23,
      "name": "Soil_Roots_Poisoned"
    },
    {
      "x": -25,
      "y": -2,
      "z": -23,
      "name": "Soil_Roots_Poisoned"
    },
    {
      "x": -25,
      "y": -1,
      "z": -23,
      "name": "Soil_Roots_Poisoned"
    },
    {
      "x": -25,
      "y": -4,
      "z": -22,
      "name": "Soil_Roots_Poisoned"
    },
    {
      "x": -25,
      "y": -3,
      "z": -22,
      "name": "Soil_Roots_Poisoned"
    },
    {
      "x": -25,
      "y": -2,
      "z": -22,
      "name": "Soil_Roots_Poisoned"
    },
    {
      "x": -25,
      "y": -1,
      "z": -22,
      "name": "Soil_Roots_Poisoned"
    },
    {
      "x": -25,
      "y": -4,
      "z": -21,
      "name": "Soil_Roots_Poisoned"
    },
    {
      "x": -25,
      "y": -3,
      "z": -21,
      "name": "Soil_Dirt_Poisoned"
    },
    {
      "x": -25,
      "y": -2,
      "z": -21,
      "name": "Soil_Roots_Poisoned"
    },
    {
      "x": -25,
      "y": -1,
      "z": -21,
      "name": "Soil_Roots_Poisoned"
    },
    {
      "x": -25,
      "y": -4,
      "z": -20,
      "name": "Soil_Roots_Poisoned"
    },
    {
      "x": -25,
      "y": -3,
      "z": -20,
      "name": "Soil_Roots_Poisoned"
    },
    {
      "x": -25,
      "y": -2,
      "z": -20,
      "name": "Soil_Roots_Poisoned"
    },
    {
      "x": -25,
      "y": -1,
      "z": -20,
      "name": "Soil_Roots_Poisoned"
    },
    {
      "x": -25,
      "y": 0,
      "z": -20,
      "name": "Soil_Roots_Poisoned"
    },
    {
      "x": -25,
      "y": -4,
      "z": -19,
      "name": "Soil_Roots_Poisoned"
    },
    {
      "x": -25,
      "y": -3,
      "z": -19,
      "name": "Soil_Roots_Poisoned"
    },
    {
      "x": -25,
      "y": -2,
      "z": -19,
      "name": "Soil_Roots_Poisoned"
    },
    {
      "x": -25,
      "y": -1,
      "z": -19,
      "name": "Soil_Roots_Poisoned"
    },
    {
      "x": -25,
      "y": 0,
      "z": -19,
      "name": "Soil_Roots_Poisoned"
    },
    {
      "x": -25,
      "y": -4,
      "z": -18,
      "name": "Soil_Roots_Poisoned"
    },
    {
      "x": -25,
      "y": -3,
      "z": -18,
      "name": "Soil_Roots_Poisoned"
    },
    {
      "x": -25,
      "y": -2,
      "z": -18,
      "name": "Soil_Roots_Poisoned"
    },
    {
      "x": -25,
      "y": -1,
      "z": -18,
      "name": "Soil_Dirt_Poisoned"
    },
    {
      "x": -25,
      "y": 0,
      "z": -18,
      "name": "Soil_Roots_Poisoned"
    },
    {
      "x": -25,
      "y": -4,
      "z": -17,
      "name": "Soil_Roots_Poisoned"
    },
    {
      "x": -25,
      "y": -3,
      "z": -17,
      "name": "Soil_Roots_Poisoned"
    },
    {
      "x": -25,
      "y": -2,
      "z": -17,
      "name": "Soil_Roots_Poisoned"
    },
    {
      "x": -25,
      "y": -1,
      "z": -17,
      "name": "Soil_Dirt_Poisoned"
    },
    {
      "x": -25,
      "y": 0,
      "z": -17,
      "name": "Soil_Roots_Poisoned"
    },
    {
      "x": -25,
      "y": -4,
      "z": -16,
      "name": "Soil_Roots_Poisoned"
    },
    {
      "x": -25,
      "y": -3,
      "z": -16,
      "name": "Soil_Roots_Poisoned"
    },
    {
      "x": -25,
      "y": -2,
      "z": -16,
      "name": "Soil_Roots_Poisoned"
    },
    {
      "x": -25,
      "y": -1,
      "z": -16,
      "name": "Soil_Roots_Poisoned"
    },
    {
      "x": -25,
      "y": 0,
      "z": -16,
      "name": "Soil_Roots_Poisoned"
    },
    {
      "x": -25,
      "y": -4,
      "z": -15,
      "name": "Soil_Dirt_Poisoned"
    },
    {
      "x": -25,
      "y": -3,
      "z": -15,
      "name": "Soil_Roots_Poisoned"
    },
    {
      "x": -25,
      "y": -2,
      "z": -15,
      "name": "Soil_Roots_Poisoned"
    },
    {
      "x": -25,
      "y": -1,
      "z": -15,
      "name": "Soil_Roots_Poisoned"
    },
    {
      "x": -25,
      "y": 0,
      "z": -15,
      "name": "Soil_Dirt_Poisoned"
    },
    {
      "x": -25,
      "y": 1,
      "z": -15,
      "name": "Soil_Dirt_Poisoned"
    },
    {
      "x": -25,
      "y": -4,
      "z": -14,
      "name": "Soil_Roots_Poisoned"
    },
    {
      "x": -25,
      "y": -3,
      "z": -14,
      "name": "Soil_Roots_Poisoned"
    },
    {
      "x": -25,
      "y": -2,
      "z": -14,
      "name": "Soil_Dirt_Poisoned"
    },
    {
      "x": -25,
      "y": -1,
      "z": -14,
      "name": "Soil_Roots_Poisoned"
    },
    {
      "x": -25,
      "y": 0,
      "z": -14,
      "name": "Soil_Roots_Poisoned"
    },
    {
      "x": -25,
      "y": -4,
      "z": -13,
      "name": "Soil_Dirt_Poisoned"
    },
    {
      "x": -25,
      "y": -3,
      "z": -13,
      "name": "Soil_Dirt_Poisoned"
    },
    {
      "x": -25,
      "y": -2,
      "z": -13,
      "name": "Soil_Roots_Poisoned"
    },
    {
      "x": -25,
      "y": -1,
      "z": -13,
      "name": "Soil_Roots_Poisoned"
    },
    {
      "x": -25,
      "y": 0,
      "z": -13,
      "name": "Soil_Roots_Poisoned"
    },
    {
      "x": -25,
      "y": -4,
      "z": -12,
      "name": "Soil_Roots_Poisoned"
    },
    {
      "x": -25,
      "y": -3,
      "z": -12,
      "name": "Soil_Dirt_Poisoned"
    },
    {
      "x": -25,
      "y": -2,
      "z": -12,
      "name": "Soil_Dirt_Poisoned"
    },
    {
      "x": -25,
      "y": -1,
      "z": -12,
      "name": "Soil_Roots_Poisoned"
    },
    {
      "x": -25,
      "y": 0,
      "z": -12,
      "name": "Soil_Roots_Poisoned"
    },
    {
      "x": -25,
      "y": -4,
      "z": -11,
      "name": "Soil_Dirt_Poisoned"
    },
    {
      "x": -25,
      "y": -3,
      "z": -11,
      "name": "Soil_Roots_Poisoned"
    },
    {
      "x": -25,
      "y": -2,
      "z": -11,
      "name": "Soil_Dirt_Poisoned"
    },
    {
      "x": -25,
      "y": -1,
      "z": -11,
      "name": "Soil_Roots_Poisoned"
    },
    {
      "x": -25,
      "y": 0,
      "z": -11,
      "name": "Soil_Roots_Poisoned"
    },
    {
      "x": -25,
      "y": -4,
      "z": -10,
      "name": "Soil_Dirt_Poisoned"
    },
    {
      "x": -25,
      "y": -3,
      "z": -10,
      "name": "Soil_Dirt_Poisoned"
    },
    {
      "x": -25,
      "y": -2,
      "z": -10,
      "name": "Soil_Dirt_Poisoned"
    },
    {
      "x": -25,
      "y": -1,
      "z": -10,
      "name": "Soil_Dirt_Poisoned"
    },
    {
      "x": -25,
      "y": 0,
      "z": -10,
      "name": "Soil_Dirt_Poisoned"
    },
    {
      "x": -25,
      "y": -4,
      "z": -9,
      "name": "Soil_Dirt_Poisoned"
    },
    {
      "x": -25,
      "y": -3,
      "z": -9,
      "name": "Soil_Dirt_Poisoned"
    },
    {
      "x": -25,
      "y": -2,
      "z": -9,
      "name": "Soil_Dirt_Poisoned"
    },
    {
      "x": -25,
      "y": -1,
      "z": -9,
      "name": "Soil_Dirt_Poisoned"
    },
    {
      "x": -25,
      "y": -4,
      "z": -8,
      "name": "Soil_Dirt_Poisoned"
    },
    {
      "x": -25,
      "y": -3,
      "z": -8,
      "name": "Soil_Dirt_Poisoned"
    },
    {
      "x": -25,
      "y": -2,
      "z": -8,
      "name": "Soil_Dirt_Poisoned"
    },
    {
      "x": -25,
      "y": -1,
      "z": -8,
      "name": "Soil_Dirt_Poisoned"
    },
    {
      "x": -25,
      "y": -4,
      "z": -7,
      "name": "Soil_Dirt_Poisoned"
    },
    {
      "x": -25,
      "y": -3,
      "z": -7,
      "name": "Soil_Dirt_Poisoned"
    },
    {
      "x": -25,
      "y": -2,
      "z": -7,
      "name": "Soil_Dirt_Poisoned"
    },
    {
      "x": -25,
      "y": -1,
      "z": -7,
      "name": "Soil_Dirt_Poisoned"
    },
    {
      "x": -25,
      "y": -4,
      "z": -6,
      "name": "Soil_Dirt_Poisoned"
    },
    {
      "x": -25,
      "y": -3,
      "z": -6,
      "name": "Soil_Dirt_Poisoned"
    },
    {
      "x": -25,
      "y": -2,
      "z": -6,
      "name": "Soil_Dirt_Poisoned"
    },
    {
      "x": -25,
      "y": -1,
      "z": -6,
      "name": "Soil_Dirt_Poisoned"
    },
    {
      "x": -25,
      "y": -4,
      "z": -5,
      "name": "Soil_Roots_Poisoned"
    },
    {
      "x": -25,
      "y": -3,
      "z": -5,
      "name": "Soil_Dirt_Poisoned"
    },
    {
      "x": -25,
      "y": -2,
      "z": -5,
      "name": "Soil_Roots_Poisoned"
    },
    {
      "x": -25,
      "y": -1,
      "z": -5,
      "name": "Soil_Dirt_Poisoned"
    },
    {
      "x": -25,
      "y": -4,
      "z": -4,
      "name": "Soil_Dirt_Poisoned"
    },
    {
      "x": -25,
      "y": -3,
      "z": -4,
      "name": "Soil_Roots_Poisoned"
    },
    {
      "x": -25,
      "y": -2,
      "z": -4,
      "name": "Soil_Roots_Poisoned"
    },
    {
      "x": -25,
      "y": -1,
      "z": -4,
      "name": "Soil_Roots_Poisoned"
    },
    {
      "x": -25,
      "y": -4,
      "z": -3,
      "name": "Soil_Dirt_Poisoned"
    },
    {
      "x": -25,
      "y": -3,
      "z": -3,
      "name": "Soil_Roots_Poisoned"
    },
    {
      "x": -25,
      "y": -2,
      "z": -3,
      "name": "Soil_Roots_Poisoned"
    },
    {
      "x": -25,
      "y": -1,
      "z": -3,
      "name": "Soil_Dirt_Poisoned"
    },
    {
      "x": -25,
      "y": -4,
      "z": -2,
      "name": "Soil_Dirt_Poisoned"
    },
    {
      "x": -25,
      "y": -3,
      "z": -2,
      "name": "Soil_Dirt_Poisoned"
    },
    {
      "x": -25,
      "y": -2,
      "z": -2,
      "name": "Soil_Dirt_Poisoned"
    },
    {
      "x": -25,
      "y": -1,
      "z": -2,
      "name": "Soil_Dirt_Poisoned"
    },
    {
      "x": -25,
      "y": -4,
      "z": -1,
      "name": "Soil_Dirt_Poisoned"
    },
    {
      "x": -25,
      "y": -3,
      "z": -1,
      "name": "Soil_Dirt_Poisoned"
    },
    {
      "x": -25,
      "y": -2,
      "z": -1,
      "name": "Soil_Dirt_Poisoned"
    },
    {
      "x": -25,
      "y": -1,
      "z": -1,
      "name": "Soil_Roots_Poisoned"
    },
    {
      "x": -25,
      "y": -4,
      "z": 0,
      "name": "Soil_Dirt_Poisoned"
    },
    {
      "x": -25,
      "y": -3,
      "z": 0,
      "name": "Soil_Dirt_Poisoned"
    },
    {
      "x": -25,
      "y": -2,
      "z": 0,
      "name": "Soil_Dirt_Poisoned"
    },
    {
      "x": -25,
      "y": -1,
      "z": 0,
      "name": "Soil_Dirt_Poisoned"
    },
    {
      "x": -25,
      "y": -4,
      "z": 1,
      "name": "Soil_Dirt_Poisoned"
    },
    {
      "x": -25,
      "y": -3,
      "z": 1,
      "name": "Soil_Dirt_Poisoned"
    },
    {
      "x": -25,
      "y": -2,
      "z": 1,
      "name": "Soil_Dirt_Poisoned"
    },
    {
      "x": -25,
      "y": -1,
      "z": 1,
      "name": "Soil_Roots_Poisoned"
    },
    {
      "x": -25,
      "y": -4,
      "z": 2,
      "name": "Soil_Roots_Poisoned"
    },
    {
      "x": -25,
      "y": -3,
      "z": 2,
      "name": "Soil_Dirt_Poisoned"
    },
    {
      "x": -25,
      "y": -2,
      "z": 2,
      "name": "Soil_Dirt_Poisoned"
    },
    {
      "x": -25,
      "y": -1,
      "z": 2,
      "name": "Soil_Dirt_Poisoned"
    },
    {
      "x": -25,
      "y": -4,
      "z": 3,
      "name": "Soil_Roots_Poisoned"
    },
    {
      "x": -25,
      "y": -3,
      "z": 3,
      "name": "Soil_Dirt_Poisoned"
    },
    {
      "x": -25,
      "y": -2,
      "z": 3,
      "name": "Soil_Roots_Poisoned"
    },
    {
      "x": -25,
      "y": -1,
      "z": 3,
      "name": "Soil_Roots_Poisoned"
    },
    {
      "x": -25,
      "y": -4,
      "z": 4,
      "name": "Soil_Roots_Poisoned"
    },
    {
      "x": -25,
      "y": -3,
      "z": 4,
      "name": "Soil_Roots_Poisoned"
    },
    {
      "x": -25,
      "y": -2,
      "z": 4,
      "name": "Soil_Roots_Poisoned"
    },
    {
      "x": -25,
      "y": -1,
      "z": 4,
      "name": "Soil_Roots_Poisoned"
    },
    {
      "x": -25,
      "y": -4,
      "z": 5,
      "name": "Soil_Roots_Poisoned"
    },
    {
      "x": -25,
      "y": -3,
      "z": 5,
      "name": "Soil_Roots_Poisoned"
    },
    {
      "x": -25,
      "y": -2,
      "z": 5,
      "name": "Soil_Roots_Poisoned"
    },
    {
      "x": -25,
      "y": -1,
      "z": 5,
      "name": "Soil_Roots_Poisoned"
    },
    {
      "x": -25,
      "y": -4,
      "z": 6,
      "name": "Soil_Roots_Poisoned"
    },
    {
      "x": -25,
      "y": -3,
      "z": 6,
      "name": "Soil_Roots_Poisoned"
    },
    {
      "x": -25,
      "y": -2,
      "z": 6,
      "name": "Soil_Roots_Poisoned"
    },
    {
      "x": -25,
      "y": -1,
      "z": 6,
      "name": "Soil_Roots_Poisoned"
    },
    {
      "x": -25,
      "y": -4,
      "z": 7,
      "name": "Soil_Dirt_Poisoned"
    },
    {
      "x": -25,
      "y": -3,
      "z": 7,
      "name": "Soil_Roots_Poisoned"
    },
    {
      "x": -25,
      "y": -2,
      "z": 7,
      "name": "Soil_Roots_Poisoned"
    },
    {
      "x": -25,
      "y": -1,
      "z": 7,
      "name": "Soil_Dirt_Poisoned"
    },
    {
      "x": -25,
      "y": -4,
      "z": 8,
      "name": "Soil_Roots_Poisoned"
    },
    {
      "x": -25,
      "y": -3,
      "z": 8,
      "name": "Soil_Roots_Poisoned"
    },
    {
      "x": -25,
      "y": -2,
      "z": 8,
      "name": "Soil_Dirt_Poisoned"
    },
    {
      "x": -25,
      "y": -1,
      "z": 8,
      "name": "Soil_Dirt_Poisoned"
    },
    {
      "x": -25,
      "y": -4,
      "z": 9,
      "name": "Soil_Roots_Poisoned"
    },
    {
      "x": -25,
      "y": -3,
      "z": 9,
      "name": "Soil_Dirt_Poisoned"
    },
    {
      "x": -25,
      "y": -2,
      "z": 9,
      "name": "Soil_Dirt_Poisoned"
    },
    {
      "x": -25,
      "y": -1,
      "z": 9,
      "name": "Soil_Dirt_Poisoned"
    },
    {
      "x": -25,
      "y": -4,
      "z": 10,
      "name": "Soil_Roots_Poisoned"
    },
    {
      "x": -25,
      "y": -3,
      "z": 10,
      "name": "Soil_Roots_Poisoned"
    },
    {
      "x": -25,
      "y": -2,
      "z": 10,
      "name": "Soil_Dirt_Poisoned"
    },
    {
      "x": -25,
      "y": -1,
      "z": 10,
      "name": "Soil_Dirt_Poisoned"
    },
    {
      "x": -25,
      "y": -4,
      "z": 11,
      "name": "Soil_Roots_Poisoned"
    },
    {
      "x": -25,
      "y": -3,
      "z": 11,
      "name": "Soil_Roots_Poisoned"
    },
    {
      "x": -25,
      "y": -2,
      "z": 11,
      "name": "Soil_Dirt_Poisoned"
    },
    {
      "x": -25,
      "y": -1,
      "z": 11,
      "name": "Soil_Dirt_Poisoned"
    },
    {
      "x": -25,
      "y": -4,
      "z": 12,
      "name": "Soil_Dirt_Poisoned"
    },
    {
      "x": -25,
      "y": -3,
      "z": 12,
      "name": "Soil_Roots_Poisoned"
    },
    {
      "x": -25,
      "y": -2,
      "z": 12,
      "name": "Soil_Roots_Poisoned"
    },
    {
      "x": -25,
      "y": -1,
      "z": 12,
      "name": "Soil_Roots_Poisoned"
    },
    {
      "x": -25,
      "y": -4,
      "z": 13,
      "name": "Soil_Dirt_Poisoned"
    },
    {
      "x": -25,
      "y": -3,
      "z": 13,
      "name": "Soil_Roots_Poisoned"
    },
    {
      "x": -25,
      "y": -2,
      "z": 13,
      "name": "Soil_Roots_Poisoned"
    },
    {
      "x": -25,
      "y": -1,
      "z": 13,
      "name": "Soil_Roots_Poisoned"
    },
    {
      "x": -25,
      "y": -4,
      "z": 14,
      "name": "Soil_Roots_Poisoned"
    },
    {
      "x": -25,
      "y": -3,
      "z": 14,
      "name": "Soil_Roots_Poisoned"
    },
    {
      "x": -25,
      "y": -2,
      "z": 14,
      "name": "Soil_Roots_Poisoned"
    },
    {
      "x": -25,
      "y": -1,
      "z": 14,
      "name": "Soil_Roots_Poisoned"
    },
    {
      "x": -25,
      "y": -4,
      "z": 15,
      "name": "Soil_Roots_Poisoned"
    },
    {
      "x": -25,
      "y": -3,
      "z": 15,
      "name": "Soil_Roots_Poisoned"
    },
    {
      "x": -25,
      "y": -2,
      "z": 15,
      "name": "Soil_Roots_Poisoned"
    },
    {
      "x": -25,
      "y": -1,
      "z": 15,
      "name": "Soil_Roots_Poisoned"
    },
    {
      "x": -25,
      "y": -4,
      "z": 16,
      "name": "Soil_Dirt_Poisoned"
    },
    {
      "x": -25,
      "y": -3,
      "z": 16,
      "name": "Soil_Roots_Poisoned"
    },
    {
      "x": -25,
      "y": -2,
      "z": 16,
      "name": "Soil_Roots_Poisoned"
    },
    {
      "x": -25,
      "y": -1,
      "z": 16,
      "name": "Soil_Roots_Poisoned"
    },
    {
      "x": -25,
      "y": -4,
      "z": 17,
      "name": "Soil_Roots_Poisoned"
    },
    {
      "x": -25,
      "y": -3,
      "z": 17,
      "name": "Soil_Roots_Poisoned"
    },
    {
      "x": -25,
      "y": -2,
      "z": 17,
      "name": "Soil_Roots_Poisoned"
    },
    {
      "x": -25,
      "y": -1,
      "z": 17,
      "name": "Soil_Roots_Poisoned"
    },
    {
      "x": -25,
      "y": -4,
      "z": 18,
      "name": "Soil_Dirt_Poisoned"
    },
    {
      "x": -25,
      "y": -3,
      "z": 18,
      "name": "Soil_Dirt_Poisoned"
    },
    {
      "x": -25,
      "y": -2,
      "z": 18,
      "name": "Soil_Roots_Poisoned"
    },
    {
      "x": -25,
      "y": -1,
      "z": 18,
      "name": "Soil_Roots_Poisoned"
    },
    {
      "x": -25,
      "y": -4,
      "z": 19,
      "name": "Soil_Roots_Poisoned"
    },
    {
      "x": -25,
      "y": -3,
      "z": 19,
      "name": "Soil_Dirt_Poisoned"
    },
    {
      "x": -25,
      "y": -2,
      "z": 19,
      "name": "Soil_Roots_Poisoned"
    },
    {
      "x": -25,
      "y": -1,
      "z": 19,
      "name": "Soil_Roots_Poisoned"
    },
    {
      "x": -25,
      "y": -4,
      "z": 20,
      "name": "Soil_Roots_Poisoned"
    },
    {
      "x": -25,
      "y": -3,
      "z": 20,
      "name": "Soil_Dirt_Poisoned"
    },
    {
      "x": -25,
      "y": -2,
      "z": 20,
      "name": "Soil_Roots_Poisoned"
    },
    {
      "x": -25,
      "y": -1,
      "z": 20,
      "name": "Soil_Roots_Poisoned"
    },
    {
      "x": -25,
      "y": -4,
      "z": 21,
      "name": "Soil_Dirt_Poisoned"
    },
    {
      "x": -25,
      "y": -3,
      "z": 21,
      "name": "Soil_Dirt_Poisoned"
    },
    {
      "x": -25,
      "y": -2,
      "z": 21,
      "name": "Soil_Roots_Poisoned"
    },
    {
      "x": -25,
      "y": -1,
      "z": 21,
      "name": "Soil_Roots_Poisoned"
    },
    {
      "x": -25,
      "y": -4,
      "z": 22,
      "name": "Soil_Roots_Poisoned"
    },
    {
      "x": -25,
      "y": -3,
      "z": 22,
      "name": "Soil_Roots_Poisoned"
    },
    {
      "x": -25,
      "y": -2,
      "z": 22,
      "name": "Soil_Roots_Poisoned"
    },
    {
      "x": -25,
      "y": -1,
      "z": 22,
      "name": "Soil_Roots_Poisoned"
    },
    {
      "x": -25,
      "y": -4,
      "z": 23,
      "name": "Soil_Dirt_Poisoned"
    },
    {
      "x": -25,
      "y": -3,
      "z": 23,
      "name": "Soil_Roots_Poisoned"
    },
    {
      "x": -25,
      "y": -2,
      "z": 23,
      "name": "Soil_Roots_Poisoned"
    },
    {
      "x": -25,
      "y": -1,
      "z": 23,
      "name": "Soil_Roots_Poisoned"
    },
    {
      "x": -25,
      "y": -4,
      "z": 24,
      "name": "Soil_Dirt_Poisoned"
    },
    {
      "x": -25,
      "y": -3,
      "z": 24,
      "name": "Soil_Roots_Poisoned"
    },
    {
      "x": -25,
      "y": -2,
      "z": 24,
      "name": "Soil_Roots_Poisoned"
    },
    {
      "x": -25,
      "y": -1,
      "z": 24,
      "name": "Soil_Dirt_Poisoned"
    },
    {
      "x": -25,
      "y": -4,
      "z": 25,
      "name": "Soil_Roots_Poisoned"
    },
    {
      "x": -25,
      "y": -3,
      "z": 25,
      "name": "Soil_Dirt_Poisoned"
    },
    {
      "x": -25,
      "y": -2,
      "z": 25,
      "name": "Soil_Dirt_Poisoned"
    },
    {
      "x": -25,
      "y": -1,
      "z": 25,
      "name": "Soil_Roots_Poisoned"
    },
    {
      "x": -25,
      "y": -4,
      "z": 26,
      "name": "Soil_Dirt_Poisoned"
    },
    {
      "x": -25,
      "y": -3,
      "z": 26,
      "name": "Soil_Roots_Poisoned"
    },
    {
      "x": -25,
      "y": -2,
      "z": 26,
      "name": "Soil_Roots_Poisoned"
    },
    {
      "x": -25,
      "y": -4,
      "z": 27,
      "name": "Soil_Dirt_Poisoned"
    },
    {
      "x": -25,
      "y": -3,
      "z": 27,
      "name": "Soil_Dirt_Poisoned"
    },
    {
      "x": -25,
      "y": -2,
      "z": 27,
      "name": "Soil_Dirt_Poisoned"
    },
    {
      "x": -25,
      "y": -4,
      "z": 28,
      "name": "Soil_Dirt_Poisoned"
    },
    {
      "x": -25,
      "y": -3,
      "z": 28,
      "name": "Soil_Dirt_Poisoned"
    },
    {
      "x": -25,
      "y": -2,
      "z": 28,
      "name": "Soil_Dirt_Poisoned"
    },
    {
      "x": -25,
      "y": -4,
      "z": 29,
      "name": "Soil_Dirt_Poisoned"
    },
    {
      "x": -25,
      "y": -3,
      "z": 29,
      "name": "Soil_Dirt_Poisoned"
    },
    {
      "x": -25,
      "y": -4,
      "z": 30,
      "name": "Soil_Dirt_Poisoned"
    },
    {
      "x": -25,
      "y": -3,
      "z": 30,
      "name": "Soil_Roots_Poisoned"
    },
    {
      "x": -25,
      "y": -4,
      "z": 31,
      "name": "Soil_Roots_Poisoned"
    },
    {
      "x": -24,
      "y": -4,
      "z": -28,
      "name": "Soil_Roots_Poisoned"
    },
    {
      "x": -24,
      "y": -3,
      "z": -28,
      "name": "Soil_Dirt_Poisoned"
    },
    {
      "x": -24,
      "y": -4,
      "z": -27,
      "name": "Soil_Dirt_Poisoned"
    },
    {
      "x": -24,
      "y": -3,
      "z": -27,
      "name": "Soil_Dirt_Poisoned"
    },
    {
      "x": -24,
      "y": -2,
      "z": -27,
      "name": "Soil_Dirt_Poisoned"
    },
    {
      "x": -24,
      "y": -4,
      "z": -26,
      "name": "Soil_Dirt_Poisoned"
    },
    {
      "x": -24,
      "y": -3,
      "z": -26,
      "name": "Soil_Roots_Poisoned"
    },
    {
      "x": -24,
      "y": -2,
      "z": -26,
      "name": "Soil_Roots_Poisoned"
    },
    {
      "x": -24,
      "y": -4,
      "z": -25,
      "name": "Soil_Dirt_Poisoned"
    },
    {
      "x": -24,
      "y": -3,
      "z": -25,
      "name": "Soil_Dirt_Poisoned"
    },
    {
      "x": -24,
      "y": -2,
      "z": -25,
      "name": "Soil_Roots_Poisoned"
    },
    {
      "x": -24,
      "y": -1,
      "z": -25,
      "name": "Soil_Roots_Poisoned"
    },
    {
      "x": -24,
      "y": -4,
      "z": -24,
      "name": "Soil_Roots_Poisoned"
    },
    {
      "x": -24,
      "y": -3,
      "z": -24,
      "name": "Soil_Roots_Poisoned"
    },
    {
      "x": -24,
      "y": -2,
      "z": -24,
      "name": "Soil_Roots_Poisoned"
    },
    {
      "x": -24,
      "y": -1,
      "z": -24,
      "name": "Soil_Roots_Poisoned"
    },
    {
      "x": -24,
      "y": -4,
      "z": -23,
      "name": "Soil_Dirt_Poisoned"
    },
    {
      "x": -24,
      "y": -3,
      "z": -23,
      "name": "Soil_Roots_Poisoned"
    },
    {
      "x": -24,
      "y": -2,
      "z": -23,
      "name": "Soil_Roots_Poisoned"
    },
    {
      "x": -24,
      "y": -1,
      "z": -23,
      "name": "Soil_Roots_Poisoned"
    },
    {
      "x": -24,
      "y": -4,
      "z": -22,
      "name": "Soil_Roots_Poisoned"
    },
    {
      "x": -24,
      "y": -3,
      "z": -22,
      "name": "Soil_Dirt_Poisoned"
    },
    {
      "x": -24,
      "y": -2,
      "z": -22,
      "name": "Soil_Roots_Poisoned"
    },
    {
      "x": -24,
      "y": -1,
      "z": -22,
      "name": "Soil_Roots_Poisoned"
    },
    {
      "x": -24,
      "y": 0,
      "z": -22,
      "name": "Soil_Dirt_Poisoned"
    },
    {
      "x": -24,
      "y": -4,
      "z": -21,
      "name": "Soil_Dirt_Poisoned"
    },
    {
      "x": -24,
      "y": -3,
      "z": -21,
      "name": "Soil_Dirt_Poisoned"
    },
    {
      "x": -24,
      "y": -2,
      "z": -21,
      "name": "Soil_Roots_Poisoned"
    },
    {
      "x": -24,
      "y": -1,
      "z": -21,
      "name": "Soil_Roots_Poisoned"
    },
    {
      "x": -24,
      "y": 0,
      "z": -21,
      "name": "Soil_Roots_Poisoned"
    },
    {
      "x": -24,
      "y": -4,
      "z": -20,
      "name": "Soil_Roots_Poisoned"
    },
    {
      "x": -24,
      "y": -3,
      "z": -20,
      "name": "Soil_Roots_Poisoned"
    },
    {
      "x": -24,
      "y": -2,
      "z": -20,
      "name": "Soil_Roots_Poisoned"
    },
    {
      "x": -24,
      "y": -1,
      "z": -20,
      "name": "Soil_Roots_Poisoned"
    },
    {
      "x": -24,
      "y": 0,
      "z": -20,
      "name": "Soil_Dirt_Poisoned"
    },
    {
      "x": -24,
      "y": -4,
      "z": -19,
      "name": "Soil_Dirt_Poisoned"
    },
    {
      "x": -24,
      "y": -3,
      "z": -19,
      "name": "Soil_Roots_Poisoned"
    },
    {
      "x": -24,
      "y": -2,
      "z": -19,
      "name": "Soil_Dirt_Poisoned"
    },
    {
      "x": -24,
      "y": -1,
      "z": -19,
      "name": "Soil_Roots_Poisoned"
    },
    {
      "x": -24,
      "y": 0,
      "z": -19,
      "name": "Soil_Dirt_Poisoned"
    },
    {
      "x": -24,
      "y": -4,
      "z": -18,
      "name": "Soil_Roots_Poisoned"
    },
    {
      "x": -24,
      "y": -3,
      "z": -18,
      "name": "Soil_Dirt_Poisoned"
    },
    {
      "x": -24,
      "y": -2,
      "z": -18,
      "name": "Soil_Roots_Poisoned"
    },
    {
      "x": -24,
      "y": -1,
      "z": -18,
      "name": "Soil_Roots_Poisoned"
    },
    {
      "x": -24,
      "y": 0,
      "z": -18,
      "name": "Soil_Roots_Poisoned"
    },
    {
      "x": -24,
      "y": 1,
      "z": -18,
      "name": "Soil_Dirt_Poisoned"
    },
    {
      "x": -24,
      "y": -4,
      "z": -17,
      "name": "Soil_Roots_Poisoned"
    },
    {
      "x": -24,
      "y": -3,
      "z": -17,
      "name": "Soil_Dirt_Poisoned"
    },
    {
      "x": -24,
      "y": -2,
      "z": -17,
      "name": "Soil_Dirt_Poisoned"
    },
    {
      "x": -24,
      "y": -1,
      "z": -17,
      "name": "Soil_Roots_Poisoned"
    },
    {
      "x": -24,
      "y": 0,
      "z": -17,
      "name": "Soil_Dirt_Poisoned"
    },
    {
      "x": -24,
      "y": 1,
      "z": -17,
      "name": "Soil_Roots_Poisoned"
    },
    {
      "x": -24,
      "y": -4,
      "z": -16,
      "name": "Soil_Dirt_Poisoned"
    },
    {
      "x": -24,
      "y": -3,
      "z": -16,
      "name": "Soil_Roots_Poisoned"
    },
    {
      "x": -24,
      "y": -2,
      "z": -16,
      "name": "Soil_Roots_Poisoned"
    },
    {
      "x": -24,
      "y": -1,
      "z": -16,
      "name": "Soil_Roots_Poisoned"
    },
    {
      "x": -24,
      "y": 0,
      "z": -16,
      "name": "Soil_Dirt_Poisoned"
    },
    {
      "x": -24,
      "y": 1,
      "z": -16,
      "name": "Soil_Roots_Poisoned"
    },
    {
      "x": -24,
      "y": -4,
      "z": -15,
      "name": "Soil_Roots_Poisoned"
    },
    {
      "x": -24,
      "y": -3,
      "z": -15,
      "name": "Soil_Dirt_Poisoned"
    },
    {
      "x": -24,
      "y": -2,
      "z": -15,
      "name": "Soil_Roots_Poisoned"
    },
    {
      "x": -24,
      "y": -1,
      "z": -15,
      "name": "Soil_Roots_Poisoned"
    },
    {
      "x": -24,
      "y": 0,
      "z": -15,
      "name": "Soil_Roots_Poisoned"
    },
    {
      "x": -24,
      "y": 1,
      "z": -15,
      "name": "Soil_Dirt_Poisoned"
    },
    {
      "x": -24,
      "y": -4,
      "z": -14,
      "name": "Soil_Roots_Poisoned"
    },
    {
      "x": -24,
      "y": -3,
      "z": -14,
      "name": "Soil_Dirt_Poisoned"
    },
    {
      "x": -24,
      "y": -2,
      "z": -14,
      "name": "Soil_Roots_Poisoned"
    },
    {
      "x": -24,
      "y": -1,
      "z": -14,
      "name": "Soil_Dirt_Poisoned"
    },
    {
      "x": -24,
      "y": 0,
      "z": -14,
      "name": "Soil_Roots_Poisoned"
    },
    {
      "x": -24,
      "y": 1,
      "z": -14,
      "name": "Soil_Roots_Poisoned"
    },
    {
      "x": -24,
      "y": -4,
      "z": -13,
      "name": "Soil_Roots_Poisoned"
    },
    {
      "x": -24,
      "y": -3,
      "z": -13,
      "name": "Soil_Dirt_Poisoned"
    },
    {
      "x": -24,
      "y": -2,
      "z": -13,
      "name": "Soil_Dirt_Poisoned"
    },
    {
      "x": -24,
      "y": -1,
      "z": -13,
      "name": "Soil_Roots_Poisoned"
    },
    {
      "x": -24,
      "y": 0,
      "z": -13,
      "name": "Soil_Roots_Poisoned"
    },
    {
      "x": -24,
      "y": 1,
      "z": -13,
      "name": "Soil_Dirt_Poisoned"
    },
    {
      "x": -24,
      "y": -4,
      "z": -12,
      "name": "Soil_Roots_Poisoned"
    },
    {
      "x": -24,
      "y": -3,
      "z": -12,
      "name": "Soil_Dirt_Poisoned"
    },
    {
      "x": -24,
      "y": -2,
      "z": -12,
      "name": "Soil_Dirt_Poisoned"
    },
    {
      "x": -24,
      "y": -1,
      "z": -12,
      "name": "Soil_Dirt_Poisoned"
    },
    {
      "x": -24,
      "y": 0,
      "z": -12,
      "name": "Soil_Roots_Poisoned"
    },
    {
      "x": -24,
      "y": 1,
      "z": -12,
      "name": "Soil_Roots_Poisoned"
    },
    {
      "x": -24,
      "y": -4,
      "z": -11,
      "name": "Soil_Dirt_Poisoned"
    },
    {
      "x": -24,
      "y": -3,
      "z": -11,
      "name": "Soil_Roots_Poisoned"
    },
    {
      "x": -24,
      "y": -2,
      "z": -11,
      "name": "Soil_Roots_Poisoned"
    },
    {
      "x": -24,
      "y": -1,
      "z": -11,
      "name": "Soil_Roots_Poisoned"
    },
    {
      "x": -24,
      "y": 0,
      "z": -11,
      "name": "Soil_Roots_Poisoned"
    },
    {
      "x": -24,
      "y": 1,
      "z": -11,
      "name": "Soil_Dirt_Poisoned"
    },
    {
      "x": -24,
      "y": -4,
      "z": -10,
      "name": "Soil_Dirt_Poisoned"
    },
    {
      "x": -24,
      "y": -3,
      "z": -10,
      "name": "Soil_Roots_Poisoned"
    },
    {
      "x": -24,
      "y": -2,
      "z": -10,
      "name": "Soil_Dirt_Poisoned"
    },
    {
      "x": -24,
      "y": -1,
      "z": -10,
      "name": "Soil_Roots_Poisoned"
    },
    {
      "x": -24,
      "y": 0,
      "z": -10,
      "name": "Soil_Dirt_Poisoned"
    },
    {
      "x": -24,
      "y": -4,
      "z": -9,
      "name": "Soil_Roots_Poisoned"
    },
    {
      "x": -24,
      "y": -3,
      "z": -9,
      "name": "Soil_Dirt_Poisoned"
    },
    {
      "x": -24,
      "y": -2,
      "z": -9,
      "name": "Soil_Dirt_Poisoned"
    },
    {
      "x": -24,
      "y": -1,
      "z": -9,
      "name": "Soil_Roots_Poisoned"
    },
    {
      "x": -24,
      "y": 0,
      "z": -9,
      "name": "Soil_Dirt_Poisoned"
    },
    {
      "x": -24,
      "y": -4,
      "z": -8,
      "name": "Soil_Roots_Poisoned"
    },
    {
      "x": -24,
      "y": -3,
      "z": -8,
      "name": "Soil_Dirt_Poisoned"
    },
    {
      "x": -24,
      "y": -2,
      "z": -8,
      "name": "Soil_Dirt_Poisoned"
    },
    {
      "x": -24,
      "y": -1,
      "z": -8,
      "name": "Soil_Dirt_Poisoned"
    },
    {
      "x": -24,
      "y": 0,
      "z": -8,
      "name": "Soil_Roots_Poisoned"
    },
    {
      "x": -24,
      "y": -4,
      "z": -7,
      "name": "Soil_Dirt_Poisoned"
    },
    {
      "x": -24,
      "y": -3,
      "z": -7,
      "name": "Soil_Dirt_Poisoned"
    },
    {
      "x": -24,
      "y": -2,
      "z": -7,
      "name": "Soil_Dirt_Poisoned"
    },
    {
      "x": -24,
      "y": -1,
      "z": -7,
      "name": "Soil_Dirt_Poisoned"
    },
    {
      "x": -24,
      "y": 0,
      "z": -7,
      "name": "Soil_Roots_Poisoned"
    },
    {
      "x": -24,
      "y": -4,
      "z": -6,
      "name": "Soil_Roots_Poisoned"
    },
    {
      "x": -24,
      "y": -3,
      "z": -6,
      "name": "Soil_Roots_Poisoned"
    },
    {
      "x": -24,
      "y": -2,
      "z": -6,
      "name": "Soil_Roots_Poisoned"
    },
    {
      "x": -24,
      "y": -1,
      "z": -6,
      "name": "Soil_Roots_Poisoned"
    },
    {
      "x": -24,
      "y": 0,
      "z": -6,
      "name": "Soil_Dirt_Poisoned"
    },
    {
      "x": -24,
      "y": -4,
      "z": -5,
      "name": "Soil_Roots_Poisoned"
    },
    {
      "x": -24,
      "y": -3,
      "z": -5,
      "name": "Soil_Roots_Poisoned"
    },
    {
      "x": -24,
      "y": -2,
      "z": -5,
      "name": "Soil_Roots_Poisoned"
    },
    {
      "x": -24,
      "y": -1,
      "z": -5,
      "name": "Soil_Roots_Poisoned"
    },
    {
      "x": -24,
      "y": 0,
      "z": -5,
      "name": "Soil_Roots_Poisoned"
    },
    {
      "x": -24,
      "y": -4,
      "z": -4,
      "name": "Soil_Roots_Poisoned"
    },
    {
      "x": -24,
      "y": -3,
      "z": -4,
      "name": "Soil_Roots_Poisoned"
    },
    {
      "x": -24,
      "y": -2,
      "z": -4,
      "name": "Soil_Roots_Poisoned"
    },
    {
      "x": -24,
      "y": -1,
      "z": -4,
      "name": "Soil_Roots_Poisoned"
    },
    {
      "x": -24,
      "y": 0,
      "z": -4,
      "name": "Soil_Roots_Poisoned"
    },
    {
      "x": -24,
      "y": -4,
      "z": -3,
      "name": "Soil_Roots_Poisoned"
    },
    {
      "x": -24,
      "y": -3,
      "z": -3,
      "name": "Soil_Roots_Poisoned"
    },
    {
      "x": -24,
      "y": -2,
      "z": -3,
      "name": "Soil_Roots_Poisoned"
    },
    {
      "x": -24,
      "y": -1,
      "z": -3,
      "name": "Soil_Roots_Poisoned"
    },
    {
      "x": -24,
      "y": 0,
      "z": -3,
      "name": "Soil_Dirt_Poisoned"
    },
    {
      "x": -24,
      "y": -4,
      "z": -2,
      "name": "Soil_Roots_Poisoned"
    },
    {
      "x": -24,
      "y": -3,
      "z": -2,
      "name": "Soil_Dirt_Poisoned"
    },
    {
      "x": -24,
      "y": -2,
      "z": -2,
      "name": "Soil_Dirt_Poisoned"
    },
    {
      "x": -24,
      "y": -1,
      "z": -2,
      "name": "Soil_Dirt_Poisoned"
    },
    {
      "x": -24,
      "y": 0,
      "z": -2,
      "name": "Soil_Dirt_Poisoned"
    },
    {
      "x": -24,
      "y": -4,
      "z": -1,
      "name": "Soil_Dirt_Poisoned"
    },
    {
      "x": -24,
      "y": -3,
      "z": -1,
      "name": "Soil_Dirt_Poisoned"
    },
    {
      "x": -24,
      "y": -2,
      "z": -1,
      "name": "Soil_Dirt_Poisoned"
    },
    {
      "x": -24,
      "y": -1,
      "z": -1,
      "name": "Soil_Roots_Poisoned"
    },
    {
      "x": -24,
      "y": 0,
      "z": -1,
      "name": "Soil_Dirt_Poisoned"
    },
    {
      "x": -24,
      "y": -4,
      "z": 0,
      "name": "Soil_Dirt_Poisoned"
    },
    {
      "x": -24,
      "y": -3,
      "z": 0,
      "name": "Soil_Dirt_Poisoned"
    },
    {
      "x": -24,
      "y": -2,
      "z": 0,
      "name": "Soil_Dirt_Poisoned"
    },
    {
      "x": -24,
      "y": -1,
      "z": 0,
      "name": "Soil_Dirt_Poisoned"
    },
    {
      "x": -24,
      "y": 0,
      "z": 0,
      "name": "Soil_Dirt_Poisoned"
    },
    {
      "x": -24,
      "y": -4,
      "z": 1,
      "name": "Soil_Roots_Poisoned"
    },
    {
      "x": -24,
      "y": -3,
      "z": 1,
      "name": "Soil_Dirt_Poisoned"
    },
    {
      "x": -24,
      "y": -2,
      "z": 1,
      "name": "Soil_Dirt_Poisoned"
    },
    {
      "x": -24,
      "y": -1,
      "z": 1,
      "name": "Soil_Dirt_Poisoned"
    },
    {
      "x": -24,
      "y": 0,
      "z": 1,
      "name": "Soil_Dirt_Poisoned"
    },
    {
      "x": -24,
      "y": -4,
      "z": 2,
      "name": "Soil_Dirt_Poisoned"
    },
    {
      "x": -24,
      "y": -3,
      "z": 2,
      "name": "Soil_Dirt_Poisoned"
    },
    {
      "x": -24,
      "y": -2,
      "z": 2,
      "name": "Soil_Dirt_Poisoned"
    },
    {
      "x": -24,
      "y": -1,
      "z": 2,
      "name": "Soil_Dirt_Poisoned"
    },
    {
      "x": -24,
      "y": 0,
      "z": 2,
      "name": "Soil_Dirt_Poisoned"
    },
    {
      "x": -24,
      "y": -4,
      "z": 3,
      "name": "Soil_Roots_Poisoned"
    },
    {
      "x": -24,
      "y": -3,
      "z": 3,
      "name": "Soil_Roots_Poisoned"
    },
    {
      "x": -24,
      "y": -2,
      "z": 3,
      "name": "Soil_Roots_Poisoned"
    },
    {
      "x": -24,
      "y": -1,
      "z": 3,
      "name": "Soil_Dirt_Poisoned"
    },
    {
      "x": -24,
      "y": 0,
      "z": 3,
      "name": "Soil_Roots_Poisoned"
    },
    {
      "x": -24,
      "y": -4,
      "z": 4,
      "name": "Soil_Dirt_Poisoned"
    },
    {
      "x": -24,
      "y": -3,
      "z": 4,
      "name": "Soil_Roots_Poisoned"
    },
    {
      "x": -24,
      "y": -2,
      "z": 4,
      "name": "Soil_Roots_Poisoned"
    },
    {
      "x": -24,
      "y": -1,
      "z": 4,
      "name": "Soil_Roots_Poisoned"
    },
    {
      "x": -24,
      "y": 0,
      "z": 4,
      "name": "Soil_Dirt_Poisoned"
    },
    {
      "x": -24,
      "y": -4,
      "z": 5,
      "name": "Soil_Roots_Poisoned"
    },
    {
      "x": -24,
      "y": -3,
      "z": 5,
      "name": "Soil_Roots_Poisoned"
    },
    {
      "x": -24,
      "y": -2,
      "z": 5,
      "name": "Soil_Roots_Poisoned"
    },
    {
      "x": -24,
      "y": -1,
      "z": 5,
      "name": "Soil_Roots_Poisoned"
    },
    {
      "x": -24,
      "y": 0,
      "z": 5,
      "name": "Soil_Dirt_Poisoned"
    },
    {
      "x": -24,
      "y": -4,
      "z": 6,
      "name": "Soil_Dirt_Poisoned"
    },
    {
      "x": -24,
      "y": -3,
      "z": 6,
      "name": "Soil_Roots_Poisoned"
    },
    {
      "x": -24,
      "y": -2,
      "z": 6,
      "name": "Soil_Roots_Poisoned"
    },
    {
      "x": -24,
      "y": -1,
      "z": 6,
      "name": "Soil_Roots_Poisoned"
    },
    {
      "x": -24,
      "y": 0,
      "z": 6,
      "name": "Soil_Roots_Poisoned"
    },
    {
      "x": -24,
      "y": -4,
      "z": 7,
      "name": "Soil_Dirt_Poisoned"
    },
    {
      "x": -24,
      "y": -3,
      "z": 7,
      "name": "Soil_Roots_Poisoned"
    },
    {
      "x": -24,
      "y": -2,
      "z": 7,
      "name": "Soil_Roots_Poisoned"
    },
    {
      "x": -24,
      "y": -1,
      "z": 7,
      "name": "Soil_Dirt_Poisoned"
    },
    {
      "x": -24,
      "y": 0,
      "z": 7,
      "name": "Soil_Dirt_Poisoned"
    },
    {
      "x": -24,
      "y": -4,
      "z": 8,
      "name": "Soil_Dirt_Poisoned"
    },
    {
      "x": -24,
      "y": -3,
      "z": 8,
      "name": "Soil_Roots_Poisoned"
    },
    {
      "x": -24,
      "y": -2,
      "z": 8,
      "name": "Soil_Roots_Poisoned"
    },
    {
      "x": -24,
      "y": -1,
      "z": 8,
      "name": "Soil_Dirt_Poisoned"
    },
    {
      "x": -24,
      "y": 0,
      "z": 8,
      "name": "Soil_Roots_Poisoned"
    },
    {
      "x": -24,
      "y": -4,
      "z": 9,
      "name": "Soil_Roots_Poisoned"
    },
    {
      "x": -24,
      "y": -3,
      "z": 9,
      "name": "Soil_Roots_Poisoned"
    },
    {
      "x": -24,
      "y": -2,
      "z": 9,
      "name": "Soil_Roots_Poisoned"
    },
    {
      "x": -24,
      "y": -1,
      "z": 9,
      "name": "Soil_Dirt_Poisoned"
    },
    {
      "x": -24,
      "y": 0,
      "z": 9,
      "name": "Soil_Roots_Poisoned"
    },
    {
      "x": -24,
      "y": -4,
      "z": 10,
      "name": "Soil_Roots_Poisoned"
    },
    {
      "x": -24,
      "y": -3,
      "z": 10,
      "name": "Soil_Roots_Poisoned"
    },
    {
      "x": -24,
      "y": -2,
      "z": 10,
      "name": "Soil_Roots_Poisoned"
    },
    {
      "x": -24,
      "y": -1,
      "z": 10,
      "name": "Soil_Dirt_Poisoned"
    },
    {
      "x": -24,
      "y": 0,
      "z": 10,
      "name": "Soil_Roots_Poisoned"
    },
    {
      "x": -24,
      "y": -4,
      "z": 11,
      "name": "Soil_Roots_Poisoned"
    },
    {
      "x": -24,
      "y": -3,
      "z": 11,
      "name": "Soil_Dirt_Poisoned"
    },
    {
      "x": -24,
      "y": -2,
      "z": 11,
      "name": "Soil_Roots_Poisoned"
    },
    {
      "x": -24,
      "y": -1,
      "z": 11,
      "name": "Soil_Roots_Poisoned"
    },
    {
      "x": -24,
      "y": 0,
      "z": 11,
      "name": "Soil_Dirt_Poisoned"
    },
    {
      "x": -24,
      "y": -4,
      "z": 12,
      "name": "Soil_Roots_Poisoned"
    },
    {
      "x": -24,
      "y": -3,
      "z": 12,
      "name": "Soil_Roots_Poisoned"
    },
    {
      "x": -24,
      "y": -2,
      "z": 12,
      "name": "Soil_Roots_Poisoned"
    },
    {
      "x": -24,
      "y": -1,
      "z": 12,
      "name": "Soil_Roots_Poisoned"
    },
    {
      "x": -24,
      "y": 0,
      "z": 12,
      "name": "Soil_Roots_Poisoned"
    },
    {
      "x": -24,
      "y": -4,
      "z": 13,
      "name": "Soil_Roots_Poisoned"
    },
    {
      "x": -24,
      "y": -3,
      "z": 13,
      "name": "Soil_Roots_Poisoned"
    },
    {
      "x": -24,
      "y": -2,
      "z": 13,
      "name": "Soil_Roots_Poisoned"
    },
    {
      "x": -24,
      "y": -1,
      "z": 13,
      "name": "Soil_Roots_Poisoned"
    },
    {
      "x": -24,
      "y": 0,
      "z": 13,
      "name": "Soil_Dirt_Poisoned"
    },
    {
      "x": -24,
      "y": -4,
      "z": 14,
      "name": "Soil_Dirt_Poisoned"
    },
    {
      "x": -24,
      "y": -3,
      "z": 14,
      "name": "Soil_Roots_Poisoned"
    },
    {
      "x": -24,
      "y": -2,
      "z": 14,
      "name": "Soil_Roots_Poisoned"
    },
    {
      "x": -24,
      "y": -1,
      "z": 14,
      "name": "Soil_Roots_Poisoned"
    },
    {
      "x": -24,
      "y": 0,
      "z": 14,
      "name": "Soil_Dirt_Poisoned"
    },
    {
      "x": -24,
      "y": -4,
      "z": 15,
      "name": "Soil_Dirt_Poisoned"
    },
    {
      "x": -24,
      "y": -3,
      "z": 15,
      "name": "Soil_Roots_Poisoned"
    },
    {
      "x": -24,
      "y": -2,
      "z": 15,
      "name": "Soil_Roots_Poisoned"
    },
    {
      "x": -24,
      "y": -1,
      "z": 15,
      "name": "Soil_Roots_Poisoned"
    },
    {
      "x": -24,
      "y": 0,
      "z": 15,
      "name": "Soil_Dirt_Poisoned"
    },
    {
      "x": -24,
      "y": -4,
      "z": 16,
      "name": "Soil_Roots_Poisoned"
    },
    {
      "x": -24,
      "y": -3,
      "z": 16,
      "name": "Soil_Roots_Poisoned"
    },
    {
      "x": -24,
      "y": -2,
      "z": 16,
      "name": "Soil_Roots_Poisoned"
    },
    {
      "x": -24,
      "y": -1,
      "z": 16,
      "name": "Soil_Roots_Poisoned"
    },
    {
      "x": -24,
      "y": 0,
      "z": 16,
      "name": "Soil_Roots_Poisoned"
    },
    {
      "x": -24,
      "y": -4,
      "z": 17,
      "name": "Soil_Dirt_Poisoned"
    },
    {
      "x": -24,
      "y": -3,
      "z": 17,
      "name": "Soil_Dirt_Poisoned"
    },
    {
      "x": -24,
      "y": -2,
      "z": 17,
      "name": "Soil_Roots_Poisoned"
    },
    {
      "x": -24,
      "y": -1,
      "z": 17,
      "name": "Soil_Roots_Poisoned"
    },
    {
      "x": -24,
      "y": 0,
      "z": 17,
      "name": "Soil_Roots_Poisoned"
    },
    {
      "x": -24,
      "y": -4,
      "z": 18,
      "name": "Soil_Roots_Poisoned"
    },
    {
      "x": -24,
      "y": -3,
      "z": 18,
      "name": "Soil_Roots_Poisoned"
    },
    {
      "x": -24,
      "y": -2,
      "z": 18,
      "name": "Soil_Roots_Poisoned"
    },
    {
      "x": -24,
      "y": -1,
      "z": 18,
      "name": "Soil_Roots_Poisoned"
    },
    {
      "x": -24,
      "y": 0,
      "z": 18,
      "name": "Soil_Dirt_Poisoned"
    },
    {
      "x": -24,
      "y": -4,
      "z": 19,
      "name": "Soil_Roots_Poisoned"
    },
    {
      "x": -24,
      "y": -3,
      "z": 19,
      "name": "Soil_Roots_Poisoned"
    },
    {
      "x": -24,
      "y": -2,
      "z": 19,
      "name": "Soil_Roots_Poisoned"
    },
    {
      "x": -24,
      "y": -1,
      "z": 19,
      "name": "Soil_Roots_Poisoned"
    },
    {
      "x": -24,
      "y": 0,
      "z": 19,
      "name": "Soil_Roots_Poisoned"
    },
    {
      "x": -24,
      "y": -4,
      "z": 20,
      "name": "Soil_Dirt_Poisoned"
    },
    {
      "x": -24,
      "y": -3,
      "z": 20,
      "name": "Soil_Roots_Poisoned"
    },
    {
      "x": -24,
      "y": -2,
      "z": 20,
      "name": "Soil_Roots_Poisoned"
    },
    {
      "x": -24,
      "y": -1,
      "z": 20,
      "name": "Soil_Roots_Poisoned"
    },
    {
      "x": -24,
      "y": 0,
      "z": 20,
      "name": "Soil_Dirt_Poisoned"
    },
    {
      "x": -24,
      "y": -4,
      "z": 21,
      "name": "Soil_Roots_Poisoned"
    },
    {
      "x": -24,
      "y": -3,
      "z": 21,
      "name": "Soil_Dirt_Poisoned"
    },
    {
      "x": -24,
      "y": -2,
      "z": 21,
      "name": "Soil_Roots_Poisoned"
    },
    {
      "x": -24,
      "y": -1,
      "z": 21,
      "name": "Soil_Roots_Poisoned"
    },
    {
      "x": -24,
      "y": 0,
      "z": 21,
      "name": "Soil_Dirt_Poisoned"
    },
    {
      "x": -24,
      "y": -4,
      "z": 22,
      "name": "Soil_Roots_Poisoned"
    },
    {
      "x": -24,
      "y": -3,
      "z": 22,
      "name": "Soil_Dirt_Poisoned"
    },
    {
      "x": -24,
      "y": -2,
      "z": 22,
      "name": "Soil_Roots_Poisoned"
    },
    {
      "x": -24,
      "y": -1,
      "z": 22,
      "name": "Soil_Roots_Poisoned"
    },
    {
      "x": -24,
      "y": 0,
      "z": 22,
      "name": "Soil_Roots_Poisoned"
    },
    {
      "x": -24,
      "y": -4,
      "z": 23,
      "name": "Soil_Dirt_Poisoned"
    },
    {
      "x": -24,
      "y": -3,
      "z": 23,
      "name": "Soil_Roots_Poisoned"
    },
    {
      "x": -24,
      "y": -2,
      "z": 23,
      "name": "Soil_Roots_Poisoned"
    },
    {
      "x": -24,
      "y": -1,
      "z": 23,
      "name": "Soil_Dirt_Poisoned"
    },
    {
      "x": -24,
      "y": -4,
      "z": 24,
      "name": "Soil_Roots_Poisoned"
    },
    {
      "x": -24,
      "y": -3,
      "z": 24,
      "name": "Soil_Dirt_Poisoned"
    },
    {
      "x": -24,
      "y": -2,
      "z": 24,
      "name": "Soil_Roots_Poisoned"
    },
    {
      "x": -24,
      "y": -1,
      "z": 24,
      "name": "Soil_Roots_Poisoned"
    },
    {
      "x": -24,
      "y": -4,
      "z": 25,
      "name": "Soil_Roots_Poisoned"
    },
    {
      "x": -24,
      "y": -3,
      "z": 25,
      "name": "Soil_Dirt_Poisoned"
    },
    {
      "x": -24,
      "y": -2,
      "z": 25,
      "name": "Soil_Dirt_Poisoned"
    },
    {
      "x": -24,
      "y": -1,
      "z": 25,
      "name": "Soil_Roots_Poisoned"
    },
    {
      "x": -24,
      "y": -4,
      "z": 26,
      "name": "Soil_Dirt_Poisoned"
    },
    {
      "x": -24,
      "y": -3,
      "z": 26,
      "name": "Soil_Dirt_Poisoned"
    },
    {
      "x": -24,
      "y": -2,
      "z": 26,
      "name": "Soil_Dirt_Poisoned"
    },
    {
      "x": -24,
      "y": -1,
      "z": 26,
      "name": "Soil_Roots_Poisoned"
    },
    {
      "x": -24,
      "y": -4,
      "z": 27,
      "name": "Soil_Dirt_Poisoned"
    },
    {
      "x": -24,
      "y": -3,
      "z": 27,
      "name": "Soil_Dirt_Poisoned"
    },
    {
      "x": -24,
      "y": -2,
      "z": 27,
      "name": "Soil_Dirt_Poisoned"
    },
    {
      "x": -24,
      "y": -1,
      "z": 27,
      "name": "Soil_Dirt_Poisoned"
    },
    {
      "x": -24,
      "y": -4,
      "z": 28,
      "name": "Soil_Dirt_Poisoned"
    },
    {
      "x": -24,
      "y": -3,
      "z": 28,
      "name": "Soil_Dirt_Poisoned"
    },
    {
      "x": -24,
      "y": -2,
      "z": 28,
      "name": "Soil_Dirt_Poisoned"
    },
    {
      "x": -24,
      "y": -4,
      "z": 29,
      "name": "Soil_Dirt_Poisoned"
    },
    {
      "x": -24,
      "y": -3,
      "z": 29,
      "name": "Soil_Roots_Poisoned"
    },
    {
      "x": -24,
      "y": -2,
      "z": 29,
      "name": "Soil_Dirt_Poisoned"
    },
    {
      "x": -24,
      "y": -4,
      "z": 30,
      "name": "Soil_Dirt_Poisoned"
    },
    {
      "x": -24,
      "y": -3,
      "z": 30,
      "name": "Soil_Roots_Poisoned"
    },
    {
      "x": -24,
      "y": -4,
      "z": 31,
      "name": "Soil_Roots_Poisoned"
    },
    {
      "x": -24,
      "y": -3,
      "z": 31,
      "name": "Soil_Roots_Poisoned"
    },
    {
      "x": -23,
      "y": -4,
      "z": -28,
      "name": "Soil_Dirt_Poisoned"
    },
    {
      "x": -23,
      "y": -3,
      "z": -28,
      "name": "Soil_Dirt_Poisoned"
    },
    {
      "x": -23,
      "y": -4,
      "z": -27,
      "name": "Soil_Roots_Poisoned"
    },
    {
      "x": -23,
      "y": -3,
      "z": -27,
      "name": "Soil_Dirt_Poisoned"
    },
    {
      "x": -23,
      "y": -2,
      "z": -27,
      "name": "Soil_Roots_Poisoned"
    },
    {
      "x": -23,
      "y": -4,
      "z": -26,
      "name": "Soil_Roots_Poisoned"
    },
    {
      "x": -23,
      "y": -3,
      "z": -26,
      "name": "Soil_Dirt_Poisoned"
    },
    {
      "x": -23,
      "y": -2,
      "z": -26,
      "name": "Soil_Roots_Poisoned"
    },
    {
      "x": -23,
      "y": -1,
      "z": -26,
      "name": "Soil_Roots_Poisoned"
    },
    {
      "x": -23,
      "y": -4,
      "z": -25,
      "name": "Soil_Roots_Poisoned"
    },
    {
      "x": -23,
      "y": -3,
      "z": -25,
      "name": "Soil_Dirt_Poisoned"
    },
    {
      "x": -23,
      "y": -2,
      "z": -25,
      "name": "Soil_Roots_Poisoned"
    },
    {
      "x": -23,
      "y": -1,
      "z": -25,
      "name": "Soil_Roots_Poisoned"
    },
    {
      "x": -23,
      "y": 0,
      "z": -25,
      "name": "Soil_Roots_Poisoned"
    },
    {
      "x": -23,
      "y": -4,
      "z": -24,
      "name": "Soil_Dirt_Poisoned"
    },
    {
      "x": -23,
      "y": -3,
      "z": -24,
      "name": "Soil_Roots_Poisoned"
    },
    {
      "x": -23,
      "y": -2,
      "z": -24,
      "name": "Soil_Roots_Poisoned"
    },
    {
      "x": -23,
      "y": -1,
      "z": -24,
      "name": "Soil_Roots_Poisoned"
    },
    {
      "x": -23,
      "y": 0,
      "z": -24,
      "name": "Soil_Dirt_Poisoned"
    },
    {
      "x": -23,
      "y": -4,
      "z": -23,
      "name": "Soil_Dirt_Poisoned"
    },
    {
      "x": -23,
      "y": -3,
      "z": -23,
      "name": "Soil_Dirt_Poisoned"
    },
    {
      "x": -23,
      "y": -2,
      "z": -23,
      "name": "Soil_Dirt_Poisoned"
    },
    {
      "x": -23,
      "y": -1,
      "z": -23,
      "name": "Soil_Roots_Poisoned"
    },
    {
      "x": -23,
      "y": 0,
      "z": -23,
      "name": "Soil_Roots_Poisoned"
    },
    {
      "x": -23,
      "y": -4,
      "z": -22,
      "name": "Soil_Roots_Poisoned"
    },
    {
      "x": -23,
      "y": -3,
      "z": -22,
      "name": "Soil_Roots_Poisoned"
    },
    {
      "x": -23,
      "y": -2,
      "z": -22,
      "name": "Soil_Roots_Poisoned"
    },
    {
      "x": -23,
      "y": -1,
      "z": -22,
      "name": "Soil_Roots_Poisoned"
    },
    {
      "x": -23,
      "y": 0,
      "z": -22,
      "name": "Soil_Dirt_Poisoned"
    },
    {
      "x": -23,
      "y": -4,
      "z": -21,
      "name": "Soil_Roots_Poisoned"
    },
    {
      "x": -23,
      "y": -3,
      "z": -21,
      "name": "Soil_Dirt_Poisoned"
    },
    {
      "x": -23,
      "y": -2,
      "z": -21,
      "name": "Soil_Roots_Poisoned"
    },
    {
      "x": -23,
      "y": -1,
      "z": -21,
      "name": "Soil_Roots_Poisoned"
    },
    {
      "x": -23,
      "y": 0,
      "z": -21,
      "name": "Soil_Roots_Poisoned"
    },
    {
      "x": -23,
      "y": 1,
      "z": -21,
      "name": "Soil_Roots_Poisoned"
    },
    {
      "x": -23,
      "y": -4,
      "z": -20,
      "name": "Soil_Roots_Poisoned"
    },
    {
      "x": -23,
      "y": -3,
      "z": -20,
      "name": "Soil_Dirt_Poisoned"
    },
    {
      "x": -23,
      "y": -2,
      "z": -20,
      "name": "Soil_Dirt_Poisoned"
    },
    {
      "x": -23,
      "y": -1,
      "z": -20,
      "name": "Soil_Roots_Poisoned"
    },
    {
      "x": -23,
      "y": 0,
      "z": -20,
      "name": "Soil_Roots_Poisoned"
    },
    {
      "x": -23,
      "y": 1,
      "z": -20,
      "name": "Soil_Dirt_Poisoned"
    },
    {
      "x": -23,
      "y": -4,
      "z": -19,
      "name": "Soil_Roots_Poisoned"
    },
    {
      "x": -23,
      "y": -3,
      "z": -19,
      "name": "Soil_Roots_Poisoned"
    },
    {
      "x": -23,
      "y": -2,
      "z": -19,
      "name": "Soil_Dirt_Poisoned"
    },
    {
      "x": -23,
      "y": -1,
      "z": -19,
      "name": "Soil_Dirt_Poisoned"
    },
    {
      "x": -23,
      "y": 0,
      "z": -19,
      "name": "Soil_Roots_Poisoned"
    },
    {
      "x": -23,
      "y": 1,
      "z": -19,
      "name": "Soil_Roots_Poisoned"
    },
    {
      "x": -23,
      "y": -4,
      "z": -18,
      "name": "Soil_Dirt_Poisoned"
    },
    {
      "x": -23,
      "y": -3,
      "z": -18,
      "name": "Soil_Roots_Poisoned"
    },
    {
      "x": -23,
      "y": -2,
      "z": -18,
      "name": "Soil_Roots_Poisoned"
    },
    {
      "x": -23,
      "y": -1,
      "z": -18,
      "name": "Soil_Dirt_Poisoned"
    },
    {
      "x": -23,
      "y": 0,
      "z": -18,
      "name": "Soil_Dirt_Poisoned"
    },
    {
      "x": -23,
      "y": 1,
      "z": -18,
      "name": "Soil_Dirt_Poisoned"
    },
    {
      "x": -23,
      "y": -4,
      "z": -17,
      "name": "Soil_Roots_Poisoned"
    },
    {
      "x": -23,
      "y": -3,
      "z": -17,
      "name": "Soil_Dirt_Poisoned"
    },
    {
      "x": -23,
      "y": -2,
      "z": -17,
      "name": "Soil_Dirt_Poisoned"
    },
    {
      "x": -23,
      "y": -1,
      "z": -17,
      "name": "Soil_Dirt_Poisoned"
    },
    {
      "x": -23,
      "y": 0,
      "z": -17,
      "name": "Soil_Roots_Poisoned"
    },
    {
      "x": -23,
      "y": 1,
      "z": -17,
      "name": "Soil_Roots_Poisoned"
    },
    {
      "x": -23,
      "y": -4,
      "z": -16,
      "name": "Soil_Roots_Poisoned"
    },
    {
      "x": -23,
      "y": -3,
      "z": -16,
      "name": "Soil_Roots_Poisoned"
    },
    {
      "x": -23,
      "y": -2,
      "z": -16,
      "name": "Soil_Dirt_Poisoned"
    },
    {
      "x": -23,
      "y": -1,
      "z": -16,
      "name": "Soil_Roots_Poisoned"
    },
    {
      "x": -23,
      "y": 0,
      "z": -16,
      "name": "Soil_Dirt_Poisoned"
    },
    {
      "x": -23,
      "y": 1,
      "z": -16,
      "name": "Soil_Dirt_Poisoned"
    },
    {
      "x": -23,
      "y": -4,
      "z": -15,
      "name": "Soil_Roots_Poisoned"
    },
    {
      "x": -23,
      "y": -3,
      "z": -15,
      "name": "Soil_Roots_Poisoned"
    },
    {
      "x": -23,
      "y": -2,
      "z": -15,
      "name": "Soil_Dirt_Poisoned"
    },
    {
      "x": -23,
      "y": -1,
      "z": -15,
      "name": "Soil_Roots_Poisoned"
    },
    {
      "x": -23,
      "y": 0,
      "z": -15,
      "name": "Soil_Roots_Poisoned"
    },
    {
      "x": -23,
      "y": 1,
      "z": -15,
      "name": "Soil_Roots_Poisoned"
    },
    {
      "x": -23,
      "y": -4,
      "z": -14,
      "name": "Soil_Roots_Poisoned"
    },
    {
      "x": -23,
      "y": -3,
      "z": -14,
      "name": "Soil_Dirt_Poisoned"
    },
    {
      "x": -23,
      "y": -2,
      "z": -14,
      "name": "Soil_Dirt_Poisoned"
    },
    {
      "x": -23,
      "y": -1,
      "z": -14,
      "name": "Soil_Roots_Poisoned"
    },
    {
      "x": -23,
      "y": 0,
      "z": -14,
      "name": "Soil_Roots_Poisoned"
    },
    {
      "x": -23,
      "y": 1,
      "z": -14,
      "name": "Soil_Roots_Poisoned"
    },
    {
      "x": -23,
      "y": -4,
      "z": -13,
      "name": "Soil_Roots_Poisoned"
    },
    {
      "x": -23,
      "y": -3,
      "z": -13,
      "name": "Soil_Roots_Poisoned"
    },
    {
      "x": -23,
      "y": -2,
      "z": -13,
      "name": "Soil_Roots_Poisoned"
    },
    {
      "x": -23,
      "y": -1,
      "z": -13,
      "name": "Soil_Dirt_Poisoned"
    },
    {
      "x": -23,
      "y": 0,
      "z": -13,
      "name": "Soil_Roots_Poisoned"
    },
    {
      "x": -23,
      "y": 1,
      "z": -13,
      "name": "Soil_Roots_Poisoned"
    },
    {
      "x": -23,
      "y": -4,
      "z": -12,
      "name": "Soil_Dirt_Poisoned"
    },
    {
      "x": -23,
      "y": -3,
      "z": -12,
      "name": "Soil_Dirt_Poisoned"
    },
    {
      "x": -23,
      "y": -2,
      "z": -12,
      "name": "Soil_Roots_Poisoned"
    },
    {
      "x": -23,
      "y": -1,
      "z": -12,
      "name": "Soil_Roots_Poisoned"
    },
    {
      "x": -23,
      "y": 0,
      "z": -12,
      "name": "Soil_Roots_Poisoned"
    },
    {
      "x": -23,
      "y": 1,
      "z": -12,
      "name": "Soil_Roots_Poisoned"
    },
    {
      "x": -23,
      "y": -4,
      "z": -11,
      "name": "Soil_Dirt_Poisoned"
    },
    {
      "x": -23,
      "y": -3,
      "z": -11,
      "name": "Soil_Dirt_Poisoned"
    },
    {
      "x": -23,
      "y": -2,
      "z": -11,
      "name": "Soil_Roots_Poisoned"
    },
    {
      "x": -23,
      "y": -1,
      "z": -11,
      "name": "Soil_Dirt_Poisoned"
    },
    {
      "x": -23,
      "y": 0,
      "z": -11,
      "name": "Soil_Roots_Poisoned"
    },
    {
      "x": -23,
      "y": 1,
      "z": -11,
      "name": "Soil_Dirt_Poisoned"
    },
    {
      "x": -23,
      "y": -4,
      "z": -10,
      "name": "Soil_Dirt_Poisoned"
    },
    {
      "x": -23,
      "y": -3,
      "z": -10,
      "name": "Soil_Roots_Poisoned"
    },
    {
      "x": -23,
      "y": -2,
      "z": -10,
      "name": "Soil_Roots_Poisoned"
    },
    {
      "x": -23,
      "y": -1,
      "z": -10,
      "name": "Soil_Roots_Poisoned"
    },
    {
      "x": -23,
      "y": 0,
      "z": -10,
      "name": "Soil_Roots_Poisoned"
    },
    {
      "x": -23,
      "y": 1,
      "z": -10,
      "name": "Soil_Roots_Poisoned"
    },
    {
      "x": -23,
      "y": -4,
      "z": -9,
      "name": "Soil_Dirt_Poisoned"
    },
    {
      "x": -23,
      "y": -3,
      "z": -9,
      "name": "Soil_Dirt_Poisoned"
    },
    {
      "x": -23,
      "y": -2,
      "z": -9,
      "name": "Soil_Roots_Poisoned"
    },
    {
      "x": -23,
      "y": -1,
      "z": -9,
      "name": "Soil_Dirt_Poisoned"
    },
    {
      "x": -23,
      "y": 0,
      "z": -9,
      "name": "Soil_Roots_Poisoned"
    },
    {
      "x": -23,
      "y": 1,
      "z": -9,
      "name": "Soil_Dirt_Poisoned"
    },
    {
      "x": -23,
      "y": -4,
      "z": -8,
      "name": "Soil_Dirt_Poisoned"
    },
    {
      "x": -23,
      "y": -3,
      "z": -8,
      "name": "Soil_Dirt_Poisoned"
    },
    {
      "x": -23,
      "y": -2,
      "z": -8,
      "name": "Soil_Dirt_Poisoned"
    },
    {
      "x": -23,
      "y": -1,
      "z": -8,
      "name": "Soil_Dirt_Poisoned"
    },
    {
      "x": -23,
      "y": 0,
      "z": -8,
      "name": "Soil_Dirt_Poisoned"
    },
    {
      "x": -23,
      "y": -4,
      "z": -7,
      "name": "Soil_Roots_Poisoned"
    },
    {
      "x": -23,
      "y": -3,
      "z": -7,
      "name": "Soil_Dirt_Poisoned"
    },
    {
      "x": -23,
      "y": -2,
      "z": -7,
      "name": "Soil_Dirt_Poisoned"
    },
    {
      "x": -23,
      "y": -1,
      "z": -7,
      "name": "Soil_Roots_Poisoned"
    },
    {
      "x": -23,
      "y": 0,
      "z": -7,
      "name": "Soil_Dirt_Poisoned"
    },
    {
      "x": -23,
      "y": -4,
      "z": -6,
      "name": "Soil_Roots_Poisoned"
    },
    {
      "x": -23,
      "y": -3,
      "z": -6,
      "name": "Soil_Dirt_Poisoned"
    },
    {
      "x": -23,
      "y": -2,
      "z": -6,
      "name": "Soil_Roots_Poisoned"
    },
    {
      "x": -23,
      "y": -1,
      "z": -6,
      "name": "Soil_Roots_Poisoned"
    },
    {
      "x": -23,
      "y": 0,
      "z": -6,
      "name": "Soil_Roots_Poisoned"
    },
    {
      "x": -23,
      "y": -4,
      "z": -5,
      "name": "Soil_Roots_Poisoned"
    },
    {
      "x": -23,
      "y": -3,
      "z": -5,
      "name": "Soil_Dirt_Poisoned"
    },
    {
      "x": -23,
      "y": -2,
      "z": -5,
      "name": "Soil_Roots_Poisoned"
    },
    {
      "x": -23,
      "y": -1,
      "z": -5,
      "name": "Soil_Roots_Poisoned"
    },
    {
      "x": -23,
      "y": 0,
      "z": -5,
      "name": "Soil_Dirt_Poisoned"
    },
    {
      "x": -23,
      "y": -4,
      "z": -4,
      "name": "Soil_Dirt_Poisoned"
    },
    {
      "x": -23,
      "y": -3,
      "z": -4,
      "name": "Soil_Dirt_Poisoned"
    },
    {
      "x": -23,
      "y": -2,
      "z": -4,
      "name": "Soil_Roots_Poisoned"
    },
    {
      "x": -23,
      "y": -1,
      "z": -4,
      "name": "Soil_Roots_Poisoned"
    },
    {
      "x": -23,
      "y": 0,
      "z": -4,
      "name": "Soil_Roots_Poisoned"
    },
    {
      "x": -23,
      "y": -4,
      "z": -3,
      "name": "Soil_Roots_Poisoned"
    },
    {
      "x": -23,
      "y": -3,
      "z": -3,
      "name": "Soil_Roots_Poisoned"
    },
    {
      "x": -23,
      "y": -2,
      "z": -3,
      "name": "Soil_Roots_Poisoned"
    },
    {
      "x": -23,
      "y": -1,
      "z": -3,
      "name": "Soil_Roots_Poisoned"
    },
    {
      "x": -23,
      "y": 0,
      "z": -3,
      "name": "Soil_Roots_Poisoned"
    },
    {
      "x": -23,
      "y": -4,
      "z": -2,
      "name": "Soil_Dirt_Poisoned"
    },
    {
      "x": -23,
      "y": -3,
      "z": -2,
      "name": "Soil_Roots_Poisoned"
    },
    {
      "x": -23,
      "y": -2,
      "z": -2,
      "name": "Soil_Dirt_Poisoned"
    },
    {
      "x": -23,
      "y": -1,
      "z": -2,
      "name": "Soil_Roots_Poisoned"
    },
    {
      "x": -23,
      "y": 0,
      "z": -2,
      "name": "Soil_Roots_Poisoned"
    },
    {
      "x": -23,
      "y": -4,
      "z": -1,
      "name": "Soil_Roots_Poisoned"
    },
    {
      "x": -23,
      "y": -3,
      "z": -1,
      "name": "Soil_Roots_Poisoned"
    },
    {
      "x": -23,
      "y": -2,
      "z": -1,
      "name": "Soil_Dirt_Poisoned"
    },
    {
      "x": -23,
      "y": -1,
      "z": -1,
      "name": "Soil_Dirt_Poisoned"
    },
    {
      "x": -23,
      "y": 0,
      "z": -1,
      "name": "Soil_Dirt_Poisoned"
    },
    {
      "x": -23,
      "y": -4,
      "z": 0,
      "name": "Soil_Dirt_Poisoned"
    },
    {
      "x": -23,
      "y": -3,
      "z": 0,
      "name": "Soil_Roots_Poisoned"
    },
    {
      "x": -23,
      "y": -2,
      "z": 0,
      "name": "Soil_Dirt_Poisoned"
    },
    {
      "x": -23,
      "y": -1,
      "z": 0,
      "name": "Soil_Dirt_Poisoned"
    },
    {
      "x": -23,
      "y": 0,
      "z": 0,
      "name": "Soil_Roots_Poisoned"
    },
    {
      "x": -23,
      "y": -4,
      "z": 1,
      "name": "Soil_Roots_Poisoned"
    },
    {
      "x": -23,
      "y": -3,
      "z": 1,
      "name": "Soil_Dirt_Poisoned"
    },
    {
      "x": -23,
      "y": -2,
      "z": 1,
      "name": "Soil_Dirt_Poisoned"
    },
    {
      "x": -23,
      "y": -1,
      "z": 1,
      "name": "Soil_Dirt_Poisoned"
    },
    {
      "x": -23,
      "y": 0,
      "z": 1,
      "name": "Soil_Roots_Poisoned"
    },
    {
      "x": -23,
      "y": -4,
      "z": 2,
      "name": "Soil_Dirt_Poisoned"
    },
    {
      "x": -23,
      "y": -3,
      "z": 2,
      "name": "Soil_Dirt_Poisoned"
    },
    {
      "x": -23,
      "y": -2,
      "z": 2,
      "name": "Soil_Dirt_Poisoned"
    },
    {
      "x": -23,
      "y": -1,
      "z": 2,
      "name": "Soil_Dirt_Poisoned"
    },
    {
      "x": -23,
      "y": 0,
      "z": 2,
      "name": "Soil_Roots_Poisoned"
    },
    {
      "x": -23,
      "y": -4,
      "z": 3,
      "name": "Soil_Roots_Poisoned"
    },
    {
      "x": -23,
      "y": -3,
      "z": 3,
      "name": "Soil_Roots_Poisoned"
    },
    {
      "x": -23,
      "y": -2,
      "z": 3,
      "name": "Soil_Dirt_Poisoned"
    },
    {
      "x": -23,
      "y": -1,
      "z": 3,
      "name": "Soil_Dirt_Poisoned"
    },
    {
      "x": -23,
      "y": 0,
      "z": 3,
      "name": "Soil_Dirt_Poisoned"
    },
    {
      "x": -23,
      "y": -4,
      "z": 4,
      "name": "Soil_Dirt_Poisoned"
    },
    {
      "x": -23,
      "y": -3,
      "z": 4,
      "name": "Soil_Roots_Poisoned"
    },
    {
      "x": -23,
      "y": -2,
      "z": 4,
      "name": "Soil_Dirt_Poisoned"
    },
    {
      "x": -23,
      "y": -1,
      "z": 4,
      "name": "Soil_Roots_Poisoned"
    },
    {
      "x": -23,
      "y": 0,
      "z": 4,
      "name": "Soil_Dirt_Poisoned"
    },
    {
      "x": -23,
      "y": -4,
      "z": 5,
      "name": "Soil_Roots_Poisoned"
    },
    {
      "x": -23,
      "y": -3,
      "z": 5,
      "name": "Soil_Dirt_Poisoned"
    },
    {
      "x": -23,
      "y": -2,
      "z": 5,
      "name": "Soil_Roots_Poisoned"
    },
    {
      "x": -23,
      "y": -1,
      "z": 5,
      "name": "Soil_Roots_Poisoned"
    },
    {
      "x": -23,
      "y": 0,
      "z": 5,
      "name": "Soil_Roots_Poisoned"
    },
    {
      "x": -23,
      "y": -4,
      "z": 6,
      "name": "Soil_Roots_Poisoned"
    },
    {
      "x": -23,
      "y": -3,
      "z": 6,
      "name": "Soil_Roots_Poisoned"
    },
    {
      "x": -23,
      "y": -2,
      "z": 6,
      "name": "Soil_Roots_Poisoned"
    },
    {
      "x": -23,
      "y": -1,
      "z": 6,
      "name": "Soil_Roots_Poisoned"
    },
    {
      "x": -23,
      "y": 0,
      "z": 6,
      "name": "Soil_Dirt_Poisoned"
    },
    {
      "x": -23,
      "y": -4,
      "z": 7,
      "name": "Soil_Dirt_Poisoned"
    },
    {
      "x": -23,
      "y": -3,
      "z": 7,
      "name": "Soil_Roots_Poisoned"
    },
    {
      "x": -23,
      "y": -2,
      "z": 7,
      "name": "Soil_Roots_Poisoned"
    },
    {
      "x": -23,
      "y": -1,
      "z": 7,
      "name": "Soil_Roots_Poisoned"
    },
    {
      "x": -23,
      "y": 0,
      "z": 7,
      "name": "Soil_Dirt_Poisoned"
    },
    {
      "x": -23,
      "y": -4,
      "z": 8,
      "name": "Soil_Roots_Poisoned"
    },
    {
      "x": -23,
      "y": -3,
      "z": 8,
      "name": "Soil_Dirt_Poisoned"
    },
    {
      "x": -23,
      "y": -2,
      "z": 8,
      "name": "Soil_Roots_Poisoned"
    },
    {
      "x": -23,
      "y": -1,
      "z": 8,
      "name": "Soil_Roots_Poisoned"
    },
    {
      "x": -23,
      "y": 0,
      "z": 8,
      "name": "Soil_Dirt_Poisoned"
    },
    {
      "x": -23,
      "y": -4,
      "z": 9,
      "name": "Soil_Roots_Poisoned"
    },
    {
      "x": -23,
      "y": -3,
      "z": 9,
      "name": "Soil_Dirt_Poisoned"
    },
    {
      "x": -23,
      "y": -2,
      "z": 9,
      "name": "Soil_Roots_Poisoned"
    },
    {
      "x": -23,
      "y": -1,
      "z": 9,
      "name": "Soil_Roots_Poisoned"
    },
    {
      "x": -23,
      "y": 0,
      "z": 9,
      "name": "Soil_Roots_Poisoned"
    },
    {
      "x": -23,
      "y": -4,
      "z": 10,
      "name": "Soil_Dirt_Poisoned"
    },
    {
      "x": -23,
      "y": -3,
      "z": 10,
      "name": "Soil_Dirt_Poisoned"
    },
    {
      "x": -23,
      "y": -2,
      "z": 10,
      "name": "Soil_Roots_Poisoned"
    },
    {
      "x": -23,
      "y": -1,
      "z": 10,
      "name": "Soil_Roots_Poisoned"
    },
    {
      "x": -23,
      "y": 0,
      "z": 10,
      "name": "Soil_Dirt_Poisoned"
    },
    {
      "x": -23,
      "y": -4,
      "z": 11,
      "name": "Soil_Dirt_Poisoned"
    },
    {
      "x": -23,
      "y": -3,
      "z": 11,
      "name": "Soil_Dirt_Poisoned"
    },
    {
      "x": -23,
      "y": -2,
      "z": 11,
      "name": "Soil_Roots_Poisoned"
    },
    {
      "x": -23,
      "y": -1,
      "z": 11,
      "name": "Soil_Roots_Poisoned"
    },
    {
      "x": -23,
      "y": 0,
      "z": 11,
      "name": "Soil_Roots_Poisoned"
    },
    {
      "x": -23,
      "y": -4,
      "z": 12,
      "name": "Soil_Dirt_Poisoned"
    },
    {
      "x": -23,
      "y": -3,
      "z": 12,
      "name": "Soil_Dirt_Poisoned"
    },
    {
      "x": -23,
      "y": -2,
      "z": 12,
      "name": "Soil_Dirt_Poisoned"
    },
    {
      "x": -23,
      "y": -1,
      "z": 12,
      "name": "Soil_Roots_Poisoned"
    },
    {
      "x": -23,
      "y": 0,
      "z": 12,
      "name": "Soil_Roots_Poisoned"
    },
    {
      "x": -23,
      "y": -4,
      "z": 13,
      "name": "Soil_Dirt_Poisoned"
    },
    {
      "x": -23,
      "y": -3,
      "z": 13,
      "name": "Soil_Dirt_Poisoned"
    },
    {
      "x": -23,
      "y": -2,
      "z": 13,
      "name": "Soil_Roots_Poisoned"
    },
    {
      "x": -23,
      "y": -1,
      "z": 13,
      "name": "Soil_Roots_Poisoned"
    },
    {
      "x": -23,
      "y": 0,
      "z": 13,
      "name": "Soil_Roots_Poisoned"
    },
    {
      "x": -23,
      "y": -4,
      "z": 14,
      "name": "Soil_Dirt_Poisoned"
    },
    {
      "x": -23,
      "y": -3,
      "z": 14,
      "name": "Soil_Dirt_Poisoned"
    },
    {
      "x": -23,
      "y": -2,
      "z": 14,
      "name": "Soil_Roots_Poisoned"
    },
    {
      "x": -23,
      "y": -1,
      "z": 14,
      "name": "Soil_Roots_Poisoned"
    },
    {
      "x": -23,
      "y": 0,
      "z": 14,
      "name": "Soil_Roots_Poisoned"
    },
    {
      "x": -23,
      "y": -4,
      "z": 15,
      "name": "Soil_Roots_Poisoned"
    },
    {
      "x": -23,
      "y": -3,
      "z": 15,
      "name": "Soil_Roots_Poisoned"
    },
    {
      "x": -23,
      "y": -2,
      "z": 15,
      "name": "Soil_Roots_Poisoned"
    },
    {
      "x": -23,
      "y": -1,
      "z": 15,
      "name": "Soil_Roots_Poisoned"
    },
    {
      "x": -23,
      "y": 0,
      "z": 15,
      "name": "Soil_Roots_Poisoned"
    },
    {
      "x": -23,
      "y": -4,
      "z": 16,
      "name": "Soil_Dirt_Poisoned"
    },
    {
      "x": -23,
      "y": -3,
      "z": 16,
      "name": "Soil_Roots_Poisoned"
    },
    {
      "x": -23,
      "y": -2,
      "z": 16,
      "name": "Soil_Roots_Poisoned"
    },
    {
      "x": -23,
      "y": -1,
      "z": 16,
      "name": "Soil_Roots_Poisoned"
    },
    {
      "x": -23,
      "y": 0,
      "z": 16,
      "name": "Soil_Roots_Poisoned"
    },
    {
      "x": -23,
      "y": 1,
      "z": 16,
      "name": "Soil_Roots_Poisoned"
    },
    {
      "x": -23,
      "y": -4,
      "z": 17,
      "name": "Soil_Roots_Poisoned"
    },
    {
      "x": -23,
      "y": -3,
      "z": 17,
      "name": "Soil_Dirt_Poisoned"
    },
    {
      "x": -23,
      "y": -2,
      "z": 17,
      "name": "Soil_Roots_Poisoned"
    },
    {
      "x": -23,
      "y": -1,
      "z": 17,
      "name": "Soil_Roots_Poisoned"
    },
    {
      "x": -23,
      "y": 0,
      "z": 17,
      "name": "Soil_Roots_Poisoned"
    },
    {
      "x": -23,
      "y": 1,
      "z": 17,
      "name": "Soil_Dirt_Poisoned"
    },
    {
      "x": -23,
      "y": -4,
      "z": 18,
      "name": "Soil_Roots_Poisoned"
    },
    {
      "x": -23,
      "y": -3,
      "z": 18,
      "name": "Soil_Roots_Poisoned"
    },
    {
      "x": -23,
      "y": -2,
      "z": 18,
      "name": "Soil_Roots_Poisoned"
    },
    {
      "x": -23,
      "y": -1,
      "z": 18,
      "name": "Soil_Roots_Poisoned"
    },
    {
      "x": -23,
      "y": 0,
      "z": 18,
      "name": "Soil_Roots_Poisoned"
    },
    {
      "x": -23,
      "y": 1,
      "z": 18,
      "name": "Soil_Roots_Poisoned"
    },
    {
      "x": -23,
      "y": -4,
      "z": 19,
      "name": "Soil_Dirt_Poisoned"
    },
    {
      "x": -23,
      "y": -3,
      "z": 19,
      "name": "Soil_Roots_Poisoned"
    },
    {
      "x": -23,
      "y": -2,
      "z": 19,
      "name": "Soil_Roots_Poisoned"
    },
    {
      "x": -23,
      "y": -1,
      "z": 19,
      "name": "Soil_Roots_Poisoned"
    },
    {
      "x": -23,
      "y": 0,
      "z": 19,
      "name": "Soil_Roots_Poisoned"
    },
    {
      "x": -23,
      "y": 1,
